Workbook
Name DataRef: Listas!$A$3
Name dem_q4_conclusao: LBE_Modelo!$B$54
Name dem_q4_melhoria: LBE_Modelo!$B$52
Name dom_x1_max: LBE_Modelo!$F$33
Name dom_x1_min: LBE_Modelo!$E$33
Name dom_x2_max: LBE_Modelo!$F$34
Name dom_x2_min: LBE_Modelo!$E$34
Name lbe_a: LBE_Modelo!$B$5
Name lbe_b1: LBE_Modelo!$B$6
Name lbe_b2: LBE_Modelo!$B$7
Name lbe_base_pct: LBE_Modelo!$B$20
Name lbe_cv: LBE_Modelo!$B$16
Name lbe_df: LBE_Modelo!$B$13
Name lbe_f: LBE_Modelo!$B$12
Name lbe_limite: LBE_Modelo!$B$19
Name lbe_nmbe: LBE_Modelo!$B$17
Name lbe_pf: LBE_Modelo!$B$14
Name lbe_r2: LBE_Modelo!$B$10
Name lbe_sey: LBE_Modelo!$B$11
Name lbe_t: LBE_Modelo!$B$18
Name lbe_ymed: LBE_Modelo!$B$15
Name lst_DataReferencia: Listas!$A$3:$A$3
Name lst_EstadoLBE: Listas!$F$3:$F$5
Name lst_EstadoPlano: Listas!$E$3:$E$7
Name lst_Funcao: Listas!$B$3:$B$24
Name lst_Periodo: Listas!$D$3:$D$4
Name lst_Polaridade: Listas!$C$3:$C$4
Name lst_TipoIDE: Listas!$G$3:$G$12
Name preco_medio: Parametros!$B$5

Sheet 00_LEIA-ME
A1: RG-SGE-05 — IDE, Linhas de Base Energéticas, Normalização, Objetivos, Metas e Planos de Ação
A2: Sistema de Gestão da Energia NP EN ISO 50001:2019 (ISO 50001:2018 + Amd 1:2024) · Plasticom — Unidade 1 (Marinha Grande, Portugal) · Registo do SGE (fábrica simulada)
A4: CONTROLO DO DOCUMENTO (7.5 — informação documentada)
A5: Código do registo | B5: RG-SGE-05
A6: Título | B6: IDE, Linhas de Base Energéticas, Normalização, Objetivos, Metas e Planos de Ação
A7: Versão / Revisão | B7: 01
A8: Data de emissão | B8: 46387
A9: Elaborado por | B9: Gestor(a) de Energia
A10: Aprovado por | B10: Diretor Geral
A11: Estado | B11: Em vigor
A12: Retenção | B12: 5 anos após substituição
A13: Localização | B13: Repositório controlado do SGE > Registos_SGE_Plasticom (a versão eletrónica é a controlada; cópias impressas são não controladas). Controlo da informação documentada comum ao SGI: PR-SGA-08 (7.5.3 — distribuição, acesso, versão, retenção).
A15: FINALIDADE E ÂMBITO
A16: Finalidade | B16: Base mensal de energia 2025-03 a 2026-12 (fonte única RG-SGA-13) com as variáveis relevantes; modelo estatístico da LBE-01 calculado por LINEST sobre 2025-03–2026-02 com testes de validade; IDE mensais por fórmula (esperado, diferença, CUSUM, domínio de validade); catálogo de IDE; registo das LBE e das suas alterações; fatores estáticos; objetivos, metas energéticas e planos de ação ligados aos IDE.
A17: Utilização / atividades | B17: Definir os indicadores de desempenho energético e as linhas de base; normalizar pelas variáveis relevantes; comparar os IDE com as LBE todos os meses; demonstrar (ou não) a melhoria do desempenho energético; estabelecer objetivos, metas energéticas e planos de ação.
A18: Requisitos ISO 50001:2018 | B18: 6.2.1 objetivos e metas energéticas; 6.2.2 a)–h) (reter); 6.2.3 planos de ação (o quê, recursos, quem, quando, como avaliar, método de verificação — reter); 6.4 IDE (metodologia mantida; valores retidos; considerar variáveis relevantes); 6.5 LBE (normalização; revisão nos casos a)–c); reter LBE, variáveis e modificações); 9.1.1 (melhoria avaliada comparando IDE com LBE); 5.1 l) (IDE representam o desempenho); 10.2 (demonstrar melhoria contínua do desempenho energético).
A20: NORMAS DE ORIENTAÇÃO E REFERÊNCIAS APLICADAS (orientação — não são requisitos auditáveis da ISO 50001)
A21: ISO 50006:2023 §5.2–5.3 e tabela 1 | B21: Utilizadores e fronteira de cada IDE (colunas Utilizadores e Fronteira do tbl_kpi).
A22: ISO 50006:2023 §6.2 (tipos de IDE) | B22: Valor medido (IDE-09), rácio (IDE-02 a 04, 06 a 08, 10) e modelo estatístico (IDE-01, IDE-05).
A23: ISO 50006:2023 §7.2 (período de referência) | B23: 12 meses (mar/2025–fev/2026) para cobrir o ciclo completo da temperatura; termina antes dos compressores VSD.
A24: ISO 50006:2023 §8 e anexos D–F (normalização) | B24: Energia esperada = modelo da LBE aplicado às variáveis do mês; comparação sob condições equivalentes.
A25: ISO 50006:2023 §9.2 (fatores estáticos) | B25: Ajuste não rotineiro ALE-01 (4 máquinas novas em 07/2026) e tbl_fatores_estaticos.
A26: ISO 50006:2023 §10.3 (demonstrar melhoria) | B26: Soma do período de reporte dentro do domínio, comparada com a incerteza do modelo.
A27: LBNL — EnPI Lite 'Valid model requirements' / 50001 Ready M&V Protocol | B27: R² ≥ 0,5; p < 0,2 em todas as variáveis e < 0,1 em pelo menos uma; teste F com p < 0,1 (folha LBE_Modelo).
A28: ASHRAE Guideline 14 (dados mensais) | B28: CV(RMSE) ≤ 15% e NMBE ±5%; R² recomendado > 0,75; incerteza da poupança a 95%.
A29: EVO — IPMVP Core Concepts (opções A–D) | B29: Método de verificação de cada plano de ação (6.2.3) e ajustes não rotineiros.
A30: Kent, R. — Energy Management in Plastics Processing (BPF/Tangram) | B30: 'Impressão digital' energética: carga de base (IDE-05, típico 20–40%) + consumo proporcional à produção; o SEC mensal engana quando a produção varia.
A32: REQUISITOS LEGAIS E OUTROS REQUISITOS APLICADOS (4.2, 9.1.2 — lista completa no RG-SGE-11)
A33: DL 71/2008 (SGCIE) — LEG-08 | B33: Consumo específico e intensidade energética são indicadores do PREn (RG-SGE-10); o IDE-02 e o IDE-09 alimentam-nos.
A35: ESTRUTURA DO FICHEIRO
A36: Base_Mensal | B36: Base mensal de energia e variáveis relevantes (RG-SGA-13, dataset, RG-SGA-19).
A37: IDE_Mensal | B37: IDE mensais calculados por fórmula: energia esperada pela LBE, diferença, CUSUM, melhoria normalizada, domínio de validade e rácios.
A38: LBE_Modelo | B38: Modelo estatístico da LBE-01 calculado por LINEST, testes de validade, domínio e demonstração da melhoria no período de reporte.
A39: Variaveis_Relevantes | B39: Seleção das variáveis relevantes (6.4, 6.5; ISO 50006 §5.5 e anexo D).
A40: Catalogo_IDE | B40: Catálogo de IDE e KPI do SGE: tipo, fronteira, variáveis, normalização, LBE, dono e utilizadores (6.4; ISO 50006 §5–6).
A41: Registo_LBE | B41: Registo das LBE (6.5 — reter as LBE, os dados das variáveis relevantes e as modificações).
A42: Alteracoes_LBE | B42: Modificações às LBE e ajustes não rotineiros (6.5 — reter).
A43: Fatores_Estaticos | B43: Fatores estáticos monitorizados para decidir revisões da LBE (6.5 b).
A44: Parametros | B44: Parâmetros usados nos cálculos deste registo (mesma estrutura do RG-SGA-13 tbl_parametros).
A45: Objetivos_Energeticos | B45: Objetivos energéticos e do SGE (6.2.1, 6.2.2 a–h) — mesmas colunas do RG-SGA-05 tbl_objetivos.
...

Sheet Base_Mensal
A1: BASE MENSAL DE ENERGIA E VARIÁVEIS RELEVANTES
A2: 2025-03-01 a 2026-12-31 · Eletricidade: RG-SGA-13 (fonte única, mar/2025–dez/2026) · Referência = 12 primeiros meses · Reporte = mar–dez/2026
A4: Mes | B4: Periodo | C4: Qualidade_Producao | D4: Fonte_Energia | E4: Dias_Calendario | F4: Dias_Uteis | G4: Temp_Media_C | H4: CDD_15 | I4: kWh_Total | J4: kWh_SOP | K4: kWh_INJ | L4: kWh_UTL_AR | M4: kWh_UTL_FRIO | N4: kWh_GER | O4: kWh_SER | P4: kWh_HFS | Q4: Unid_INJ | R4: Unid_SOP | S4: Unid_SER | T4: Unid_HFS | U4: Horas_INJ | V4: Horas_SOP | W4: Horas_SER | X4: Horas_HFS | Y4: Unid_Maquinas_Novas | Z4: kWh_Maquinas_Novas | AA4: L_Gasoleo_Frota | AB4: L_Gasoleo_Gerador | AC4: Verif_Soma_Usos | AD4: Energia_Final_MWh
A5: 45717 | B5: Referência (LBE) | C5: Reconstruído (pré-dataset) | D5: RG-SGA-13 (fatura) | E5: 31 | F5: 21 | G5: 13.2 | H5: 0 | I5: 568941 | J5: 233780 | K5: 150493 | L5: 78797 | M5: 34765 | N5: 45887 | O5: 12915 | P5: 12304 | Q5: 3127150 | R5: 2074828 | S5: 373701 | T5: 622911 | U5: 3398.2 | V5: 4230.2 | W5: 745.8 | X5: 1330 | Y5: 0 | Z5: 0 | AA5: 255.2 | AB5: 20.9 | AC5: =IF(A5="","",J5+K5+L5+M5+N5+O5+P5-I5) -> 0 | AD5: =IF(A5="","",(I5+(AA5+AB5)*10)/1000) -> 571.702
A6: 45748 | B6: Referência (LBE) | C6: Reconstruído (pré-dataset) | D6: RG-SGA-13 (fatura) | E6: 30 | F6: 20 | G6: 15.2 | H6: 6 | I6: 545354 | J6: 218570 | K6: 148146 | L6: 75062 | M6: 36654 | N6: 43909 | O6: 12953 | P6: 10060 | Q6: 2949838 | R6: 1917166 | S6: 352528 | T6: 532950 | U6: 3205.5 | V6: 3908.8 | W6: 703.6 | X6: 1137.9 | Y6: 0 | Z6: 0 | AA6: 270.5 | AB6: 20.4 | AC6: =IF(A6="","",J6+K6+L6+M6+N6+O6+P6-I6) -> 0 | AD6: =IF(A6="","",(I6+(AA6+AB6)*10)/1000) -> 548.263
A7: 45778 | B7: Referência (LBE) | C7: Reconstruído (pré-dataset) | D7: RG-SGA-13 (fatura) | E7: 31 | F7: 21 | G7: 16.8 | H7: 55.8 | I7: 538026 | J7: 212282 | K7: 147778 | L7: 72249 | M7: 39448 | N7: 41507 | O7: 13269 | P7: 11493 | Q7: 3081721 | R7: 1948876 | S7: 376251 | T7: 583006 | U7: 3348.8 | V7: 3973.4 | W7: 750.9 | X7: 1244.8 | Y7: 0 | Z7: 0 | AA7: 254.1 | AB7: 19.6 | AC7: =IF(A7="","",J7+K7+L7+M7+N7+O7+P7-I7) -> 0 | AD7: =IF(A7="","",(I7+(AA7+AB7)*10)/1000) -> 540.763
A8: 45809 | B8: Referência (LBE) | C8: Reconstruído (pré-dataset) | D8: RG-SGA-13 (fatura) | E8: 30 | F8: 19 | G8: 21.2 | H8: 186 | I8: 515423 | J8: 209893 | K8: 127528 | L8: 68734 | M8: 43262 | N8: 43471 | O8: 12590 | P8: 9946 | Q8: 2676526 | R8: 1867421 | S8: 336762 | T8: 521560 | U8: 2908.5 | V8: 3807.3 | W8: 672.1 | X8: 1113.6 | Y8: 0 | Z8: 0 | AA8: 227.4 | AB8: 19.2 | AC8: =IF(A8="","",J8+K8+L8+M8+N8+O8+P8-I8) -> 1 | AD8: =IF(A8="","",(I8+(AA8+AB8)*10)/1000) -> 517.889
A9: 45839 | B9: Referência (LBE) | C9: Dataset | D9: RG-SGA-13 (fatura) | E9: 31 | F9: 23 | G9: 22.2 | H9: 223.2 | I9: 620886 | J9: 255934 | K9: 155542 | L9: 83129 | M9: 54774 | N9: 42982 | O9: 15942 | P9: 12584 | Q9: 3036460 | R9: 2236614 | S9: 443480 | T9: 634114 | U9: 3407.4 | V9: 4527.4 | W9: 881.9 | X9: 1354.2 | Y9: 0 | Z9: 0 | AA9: 244.8 | AB9: 16.9 | AC9: =IF(A9="","",J9+K9+L9+M9+N9+O9+P9-I9) -> 1 | AD9: =IF(A9="","",(I9+(AA9+AB9)*10)/1000) -> 623.503
A10: 45870 | B10: Referência (LBE) | C10: Dataset | D10: RG-SGA-13 (fatura) | E10: 31 | F10: 20 | G10: 23.1 | H10: 251.1 | I10: 586901 | J10: 232060 | K10: 150415 | L10: 77888 | M10: 54405 | N10: 50669 | O10: 8255 | P10: 13210 | Q10: 3305389 | R10: 2138267 | S10: 237760 | T10: 681799 | U10: 3440.7 | V10: 4257.9 | W10: 480.2 | X10: 1453.3 | Y10: 0 | Z10: 0 | AA10: 263.4 | AB10: 17.3 | AC10: =IF(A10="","",J10+K10+L10+M10+N10+O10+P10-I10) -> 1 | AD10: =IF(A10="","",(I10+(AA10+AB10)*10)/1000) -> 589.708
A11: 45901 | B11: Referência (LBE) | C11: Dataset | D11: RG-SGA-13 (fatura) | E11: 30 | F11: 22 | G11: 20.9 | H11: 177 | I11: 569448 | J11: 224732 | K11: 151543 | L11: 76055 | M11: 48367 | N11: 45651 | O11: 11963 | P11: 11136 | Q11: 3070042 | R11: 1992851 | S11: 372292 | T11: 572466 | U11: 3317.5 | V11: 4102.8 | W11: 718.5 | X11: 1223.7 | Y11: 0 | Z11: 0 | AA11: 290.2 | AB11: 15.8 | AC11: =IF(A11="","",J11+K11+L11+M11+N11+O11+P11-I11) -> -1 | AD11: =IF(A11="","",(I11+(AA11+AB11)*10)/1000) -> 572.508
A12: 45931 | B12: Referência (LBE) | C12: Dataset | D12: RG-SGA-13 (fatura) | E12: 31 | F12: 22 | G12: 18.1 | H12: 96.1 | I12: 568762 | J12: 231621 | K12: 150121 | L12: 76437 | M12: 43597 | N12: 41407 | O12: 15408 | P12: 10171 | Q12: 3063889 | R12: 2094836 | S12: 431440 | T12: 550527 | U12: 3377.9 | V12: 4346.1 | W12: 875.3 | X12: 1166 | Y12: 0 | Z12: 0 | AA12: 231.1 | AB12: 20.2 | AC12: =IF(A12="","",J12+K12+L12+M12+N12+O12+P12-I12) -> 0 | AD12: =IF(A12="","",(I12+(AA12+AB12)*10)/1000) -> 571.275
A13: 45962 | B13: Referência (LBE) | C13: Dataset | D13: RG-SGA-13 (fatura) | E13: 30 | F13: 19 | G13: 13.3 | H13: 0 | I13: 561643 | J13: 230406 | K13: 147075 | L13: 76392 | M13: 34544 | N13: 46470 | O13: 16262 | P13: 10494 | Q13: 2975801 | R13: 1998289 | S13: 448497 | T13: 548163 | U13: 3276.5 | V13: 4159.3 | W13: 886.9 | X13: 1168.5 | Y13: 0 | Z13: 0 | AA13: 231.2 | AB13: 16.6 | AC13: =IF(A13="","",J13+K13+L13+M13+N13+O13+P13-I13) -> 0 | AD13: =IF(A13="","",(I13+(AA13+AB13)*10)/1000) -> 564.121
A14: 45992 | B14: Referência (LBE) | C14: Dataset | D14: RG-SGA-13 (fatura) | E14: 31 | F14: 20 | G14: 11.4 | H14: 0 | I14: 582602 | J14: 246048 | K14: 151639 | L14: 77790 | M14: 34150 | N14: 49348 | O14: 12466 | P14: 11162 | Q14: 3058510 | R14: 2163430 | S14: 338785 | T14: 572203 | U14: 3294.6 | V14: 4345.2 | W14: 692.1 | X14: 1233.9 | Y14: 0 | Z14: 0 | AA14: 229.3 | AB14: 17.1 | AC14: =IF(A14="","",J14+K14+L14+M14+N14+O14+P14-I14) -> 1 | AD14: =IF(A14="","",(I14+(AA14+AB14)*10)/1000) -> 585.066
A15: 46023 | B15: Referência (LBE) | C15: Dataset | D15: RG-SGA-13 (fatura) | E15: 31 | F15: 21 | G15: 9.6 | H15: 0 | I15: 567251 | J15: 238387 | K15: 154580 | L15: 78622 | M15: 28266 | N15: 48208 | O15: 10220 | P15: 8969 | Q15: 3226809 | R15: 2045475 | S15: 296927 | T15: 469263 | U15: 3454.1 | V15: 4280.6 | W15: 578.5 | X15: 998.2 | Y15: 0 | Z15: 0 | AA15: 283.3 | AB15: 18.1 | AC15: =IF(A15="","",J15+K15+L15+M15+N15+O15+P15-I15) -> 1 | AD15: =IF(A15="","",(I15+(AA15+AB15)*10)/1000) -> 570.265
A16: 46054 | B16: Referência (LBE) | C16: Dataset | D16: RG-SGA-13 (fatura) | E16: 28 | F16: 20 | G16: 11.9 | H16: 0 | I16: 527749 | J16: 219236 | K16: 138364 | L16: 71532 | M16: 30720 | N16: 47297 | O16: 10672 | P16: 9929 | Q16: 2776640 | R16: 1980694 | S16: 295268 | T16: 526979 | U16: 3055.7 | V16: 3951 | W16: 587.8 | X16: 1110.5 | Y16: 0 | Z16: 0 | AA16: 288.8 | AB16: 17.9 | AC16: =IF(A16="","",J16+K16+L16+M16+N16+O16+P16-I16) -> 1 | AD16: =IF(A16="","",(I16+(AA16+AB16)*10)/1000) -> 530.816
... A26: 46357 | B26: Reporte | C26: Dataset | D26: RG-SGA-13 (fatura) | E26: 31 | F26: 20 | G26: 11.1 | H26: 0 | I26: 675973 | J26: 286521 | K26: 197345 | L26: 79474 | M26: 38953 | N26: 49119 | O26: 13206 | P26: 11356 | Q26: 4306092 | R26: 2608256 | S26: 359103 | T26: 589367 | U26: 4791.1 | V26: 5342.6 | W26: 729.8 | X26: 1245.6 | Y26: 1847309 | Z26: 162411 | AA26: 234.8 | AB26: 18.9 | AC26: =IF(A26="","",J26+K26+L26+M26+N26+O26+P26-I26) -> 1 | AD26: =IF(A26="","",(I26+(AA26+AB26)*10)/1000) -> 678.51

Sheet IDE_Mensal
A1: IDE MENSAIS — COMPARAÇÃO COM A LBE (ISO 50001 9.1.1; ISO 50006 §8 e §10)
A2: Tudo calculado · kWh_Esperado = LBE-01 aplicada às variáveis do mês · Fora do domínio = variáveis fora do intervalo da referência (não usar para demonstrar melhoria)
A4: Mes | B4: Periodo | C4: Y_kWh_Ajustado | D4: X1_Unid_mil | E4: X2_CDD | F4: kWh_Esperado | G4: Diferenca_kWh | H4: CUSUM_kWh | I4: Melhoria_Pct | J4: Dentro_Dominio | K4: Estado_IDE01 | L4: SEC_Real | M4: SEC_SOP | N4: SEC_INJ | O4: Carga_Base_Pct | P4: Racio_Frio | Q4: Racio_Ar | R4: Energia_Final_MWh
A5: 45717 | B5: =IF(A5="","",INDEX(tbl_base_energia[Periodo],MATCH(A5,tbl_base_energia[Mes],0))) -> Referência (LBE) | C5: =IF(A5="","",INDEX(tbl_base_energia[kWh_Total],MATCH(A5,tbl_base_energia[Mes],0))-INDEX(tbl_base_energia[kWh_Maquinas_Novas],MATCH(A5,tbl_base_energia[Mes],0))) -> 568941 | D5: =IF(A5="","",(INDEX(tbl_base_energia[Unid_INJ],MATCH(A5,tbl_base_energia[Mes],0))+INDEX(tbl_base_energia[Unid_SOP],MATCH(A5,tbl_base_energia[Mes],0))-INDEX(tbl_base_energia[Unid_Maquinas_Novas],MATCH(A5,tbl_base_energia[Mes],0)))/1000) -> 5201.978 | E5: =IF(A5="","",INDEX(tbl_base_energia[CDD_15],MATCH(A5,tbl_base_energia[Mes],0))) -> 0 | F5: =IF(A5="","",lbe_a+lbe_b1*D5+lbe_b2*E5) -> 570403.97 | G5: =IF(A5="","",C5-F5) -> -1462.974 | H5: =IF(A5="","",SUM($G$5:G5)) -> -1462.974 | I5: =IF(A5="","",-G5/F5) -> 0.0025648033 | J5: =IF(A5="","",IF(AND(D5>=dom_x1_min,D5<=dom_x1_max,E5>=dom_x2_min,E5<=dom_x2_max),"Sim","Não")) -> Sim | K5: =IF(A5="","",IF(B5="Referência (LBE)","Referência",IF(J5="Não","Fora do domínio",IF(G5>lbe_limite,"Desvio significativo",IF(G5<-lbe_limite,"Melhoria significativa","Dentro da incerteza"))))) -> Referência | L5: =IF(A5="","",INDEX(tbl_base_energia[kWh_Total],MATCH(A5,tbl_base_energia[Mes],0))/(INDEX(tbl_base_energia[Unid_INJ],MATCH(A5,tbl_base_energia[Mes],0))+INDEX(tbl_base_energia[Unid_SOP],MATCH(A5,tbl_base_energia[Mes],0)))*1000) -> 109.37013 | M5: =IF(A5="","",INDEX(tbl_base_energia[kWh_SOP],MATCH(A5,tbl_base_energia[Mes],0))/INDEX(tbl_base_energia[Unid_SOP],MATCH(A5,tbl_base_energia[Mes],0))*1000) -> 112.6744 | N5: =IF(A5="","",INDEX(tbl_base_energia[kWh_INJ],MATCH(A5,tbl_base_energia[Mes],0))/INDEX(tbl_base_energia[Unid_INJ],MATCH(A5,tbl_base_energia[Mes],0))*1000) -> 48.12465 | O5: =IF(A5="","",lbe_a/C5) -> 0.16499257 | P5: =IF(A5="","",INDEX(tbl_base_energia[kWh_UTL_FRIO],MATCH(A5,tbl_base_energia[Mes],0))/(INDEX(tbl_base_energia[kWh_INJ],MATCH(A5,tbl_base_energia[Mes],0))+INDEX(tbl_base_energia[kWh_SOP],MATCH(A5,tbl_base_energia[Mes],0)))) -> 0.090469536 | Q5: =IF(A5="","",INDEX(tbl_base_energia[kWh_UTL_AR],MATCH(A5,tbl_base_energia[Mes],0))/(INDEX(tbl_base_energia[kWh_INJ],MATCH(A5,tbl_base_energia[Mes],0))+INDEX(tbl_base_energia[kWh_SOP],MATCH(A5,tbl_base_energia[Mes],0))+INDEX(tbl_base_energia[kWh_SER],MATCH(A5,tbl_base_energia[Mes],0))+INDEX(tbl_base_energia[kWh_HFS],MATCH(A5,tbl_base_energia[Mes],0)))) -> 0.19242623 | R5: =IF(A5="","",INDEX(tbl_base_energia[Energia_Final_MWh],MATCH(A5,tbl_base_energia[Mes],0))) -> 571.702
A6: 45748 | B6: =IF(A6="","",INDEX(tbl_base_energia[Periodo],MATCH(A6,tbl_base_energia[Mes],0))) -> Referência (LBE) | C6: =IF(A6="","",INDEX(tbl_base_energia[kWh_Total],MATCH(A6,tbl_base_energia[Mes],0))-INDEX(tbl_base_energia[kWh_Maquinas_Novas],MATCH(A6,tbl_base_energia[Mes],0))) -> 545354 | D6: =IF(A6="","",(INDEX(tbl_base_energia[Unid_INJ],MATCH(A6,tbl_base_energia[Mes],0))+INDEX(tbl_base_energia[Unid_SOP],MATCH(A6,tbl_base_energia[Mes],0))-INDEX(tbl_base_energia[Unid_Maquinas_Novas],MATCH(A6,tbl_base_energia[Mes],0)))/1000) -> 4867.004 | E6: =IF(A6="","",INDEX(tbl_base_energia[CDD_15],MATCH(A6,tbl_base_energia[Mes],0))) -> 6 | F6: =IF(A6="","",lbe_a+lbe_b1*D6+lbe_b2*E6) -> 540057.1 | G6: =IF(A6="","",C6-F6) -> 5296.9026 | H6: =IF(A6="","",SUM($G$5:G6)) -> 3833.9287 | I6: =IF(A6="","",-G6/F6) -> -0.0098080419 | J6: =IF(A6="","",IF(AND(D6>=dom_x1_min,D6<=dom_x1_max,E6>=dom_x2_min,E6<=dom_x2_max),"Sim","Não")) -> Sim | K6: =IF(A6="","",IF(B6="Referência (LBE)","Referência",IF(J6="Não","Fora do domínio",IF(G6>lbe_limite,"Desvio significativo",IF(G6<-lbe_limite,"Melhoria significativa","Dentro da incerteza"))))) -> Referência | L6: =IF(A6="","",INDEX(tbl_base_energia[kWh_Total],MATCH(A6,tbl_base_energia[Mes],0))/(INDEX(tbl_base_energia[Unid_INJ],MATCH(A6,tbl_base_energia[Mes],0))+INDEX(tbl_base_energia[Unid_SOP],MATCH(A6,tbl_base_energia[Mes],0)))*1000) -> 112.05127 | M6: =IF(A6="","",INDEX(tbl_base_energia[kWh_SOP],MATCH(A6,tbl_base_energia[Mes],0))/INDEX(tbl_base_energia[Unid_SOP],MATCH(A6,tbl_base_energia[Mes],0))*1000) -> 114.00682 | N6: =IF(A6="","",INDEX(tbl_base_energia[kWh_INJ],MATCH(A6,tbl_base_energia[Mes],0))/INDEX(tbl_base_energia[Unid_INJ],MATCH(A6,tbl_base_energia[Mes],0))*1000) -> 50.221741 | O6: =IF(A6="","",lbe_a/C6) -> 0.17212863 | P6: =IF(A6="","",INDEX(tbl_base_energia[kWh_UTL_FRIO],MATCH(A6,tbl_base_energia[Mes],0))/(INDEX(tbl_base_energia[kWh_INJ],MATCH(A6,tbl_base_energia[Mes],0))+INDEX(tbl_base_energia[kWh_SOP],MATCH(A6,tbl_base_energia[Mes],0)))) -> 0.099952006 | Q6: =IF(A6="","",INDEX(tbl_base_energia[kWh_UTL_AR],MATCH(A6,tbl_base_energia[Mes],0))/(INDEX(tbl_base_energia[kWh_INJ],MATCH(A6,tbl_base_energia[Mes],0))+INDEX(tbl_base_energia[kWh_SOP],MATCH(A6,tbl_base_energia[Mes],0))+INDEX(tbl_base_energia[kWh_SER],MATCH(A6,tbl_base_energia[Mes],0))+INDEX(tbl_base_energia[kWh_HFS],MATCH(A6,tbl_base_energia[Mes],0)))) -> 0.1926005 | R6: =IF(A6="","",INDEX(tbl_base_energia[Energia_Final_MWh],MATCH(A6,tbl_base_energia[Mes],0))) -> 548.263
A7: 45778 | B7: =IF(A7="","",INDEX(tbl_base_energia[Periodo],MATCH(A7,tbl_base_energia[Mes],0))) -> Referência (LBE) | C7: =IF(A7="","",INDEX(tbl_base_energia[kWh_Total],MATCH(A7,tbl_base_energia[Mes],0))-INDEX(tbl_base_energia[kWh_Maquinas_Novas],MATCH(A7,tbl_base_energia[Mes],0))) -> 538026 | D7: =IF(A7="","",(INDEX(tbl_base_energia[Unid_INJ],MATCH(A7,tbl_base_energia[Mes],0))+INDEX(tbl_base_energia[Unid_SOP],MATCH(A7,tbl_base_energia[Mes],0))-INDEX(tbl_base_energia[Unid_Maquinas_Novas],MATCH(A7,tbl_base_energia[Mes],0)))/1000) -> 5030.597 | E7: =IF(A7="","",INDEX(tbl_base_energia[CDD_15],MATCH(A7,tbl_base_energia[Mes],0))) -> 55.8 | F7: =IF(A7="","",lbe_a+lbe_b1*D7+lbe_b2*E7) -> 557855.14 | G7: =IF(A7="","",C7-F7) -> -19829.142 | H7: =IF(A7="","",SUM($G$5:G7)) -> -15995.214 | I7: =IF(A7="","",-G7/F7) -> 0.035545325 | J7: =IF(A7="","",IF(AND(D7>=dom_x1_min,D7<=dom_x1_max,E7>=dom_x2_min,E7<=dom_x2_max),"Sim","Não")) -> Sim | K7: =IF(A7="","",IF(B7="Referência (LBE)","Referência",IF(J7="Não","Fora do domínio",IF(G7>lbe_limite,"Desvio significativo",IF(G7<-lbe_limite,"Melhoria significativa","Dentro da incerteza"))))) -> Referência | L7: =IF(A7="","",INDEX(tbl_base_energia[kWh_Total],MATCH(A7,tbl_base_energia[Mes],0))/(INDEX(tbl_base_energia[Unid_INJ],MATCH(A7,tbl_base_energia[Mes],0))+INDEX(tbl_base_energia[Unid_SOP],MATCH(A7,tbl_base_energia[Mes],0)))*1000) -> 106.95073 | M7: =IF(A7="","",INDEX(tbl_base_energia[kWh_SOP],MATCH(A7,tbl_base_energia[Mes],0))/INDEX(tbl_base_energia[Unid_SOP],MATCH(A7,tbl_base_energia[Mes],0))*1000) -> 108.92535 | N7: =IF(A7="","",INDEX(tbl_base_energia[kWh_INJ],MATCH(A7,tbl_base_energia[Mes],0))/INDEX(tbl_base_energia[Unid_INJ],MATCH(A7,tbl_base_energia[Mes],0))*1000) -> 47.953076 | O7: =IF(A7="","",lbe_a/C7) -> 0.17447305 | P7: =IF(A7="","",INDEX(tbl_base_energia[kWh_UTL_FRIO],MATCH(A7,tbl_base_energia[Mes],0))/(INDEX(tbl_base_energia[kWh_INJ],MATCH(A7,tbl_base_energia[Mes],0))+INDEX(tbl_base_energia[kWh_SOP],MATCH(A7,tbl_base_energia[Mes],0)))) -> 0.10955952 | Q7: =IF(A7="","",INDEX(tbl_base_energia[kWh_UTL_AR],MATCH(A7,tbl_base_energia[Mes],0))/(INDEX(tbl_base_energia[kWh_INJ],MATCH(A7,tbl_base_energia[Mes],0))+INDEX(tbl_base_energia[kWh_SOP],MATCH(A7,tbl_base_energia[Mes],0))+INDEX(tbl_base_energia[kWh_SER],MATCH(A7,tbl_base_energia[Mes],0))+INDEX(tbl_base_energia[kWh_HFS],MATCH(A7,tbl_base_energia[Mes],0)))) -> 0.18774654 | R7: =IF(A7="","",INDEX(tbl_base_energia[Energia_Final_MWh],MATCH(A7,tbl_base_energia[Mes],0))) -> 540.763
A8: 45809 | B8: =IF(A8="","",INDEX(tbl_base_energia[Periodo],MATCH(A8,tbl_base_energia[Mes],0))) -> Referência (LBE) | C8: =IF(A8="","",INDEX(tbl_base_energia[kWh_Total],MATCH(A8,tbl_base_energia[Mes],0))-INDEX(tbl_base_energia[kWh_Maquinas_Novas],MATCH(A8,tbl_base_energia[Mes],0))) -> 515423 | D8: =IF(A8="","",(INDEX(tbl_base_energia[Unid_INJ],MATCH(A8,tbl_base_energia[Mes],0))+INDEX(tbl_base_energia[Unid_SOP],MATCH(A8,tbl_base_energia[Mes],0))-INDEX(tbl_base_energia[Unid_Maquinas_Novas],MATCH(A8,tbl_base_energia[Mes],0)))/1000) -> 4543.947 | E8: =IF(A8="","",INDEX(tbl_base_energia[CDD_15],MATCH(A8,tbl_base_energia[Mes],0))) -> 186 | F8: =IF(A8="","",lbe_a+lbe_b1*D8+lbe_b2*E8) -> 520626.7 | G8: =IF(A8="","",C8-F8) -> -5203.6979 | H8: =IF(A8="","",SUM($G$5:G8)) -> -21198.912 | I8: =IF(A8="","",-G8/F8) -> 0.0099950654 | J8: =IF(A8="","",IF(AND(D8>=dom_x1_min,D8<=dom_x1_max,E8>=dom_x2_min,E8<=dom_x2_max),"Sim","Não")) -> Sim | K8: =IF(A8="","",IF(B8="Referência (LBE)","Referência",IF(J8="Não","Fora do domínio",IF(G8>lbe_limite,"Desvio significativo",IF(G8<-lbe_limite,"Melhoria significativa","Dentro da incerteza"))))) -> Referência | L8: =IF(A8="","",INDEX(tbl_base_energia[kWh_Total],MATCH(A8,tbl_base_energia[Mes],0))/(INDEX(tbl_base_energia[Unid_INJ],MATCH(A8,tbl_base_energia[Mes],0))+INDEX(tbl_base_energia[Unid_SOP],MATCH(A8,tbl_base_energia[Mes],0)))*1000) -> 113.43068 | M8: =IF(A8="","",INDEX(tbl_base_energia[kWh_SOP],MATCH(A8,tbl_base_energia[Mes],0))/INDEX(tbl_base_energia[Unid_SOP],MATCH(A8,tbl_base_energia[Mes],0))*1000) -> 112.39726 | N8: =IF(A8="","",INDEX(tbl_base_energia[kWh_INJ],MATCH(A8,tbl_base_energia[Mes],0))/INDEX(tbl_base_energia[Unid_INJ],MATCH(A8,tbl_base_energia[Mes],0))*1000) -> 47.646838 | O8: =IF(A8="","",lbe_a/C8) -> 0.18212427 | P8: =IF(A8="","",INDEX(tbl_base_energia[kWh_UTL_FRIO],MATCH(A8,tbl_base_energia[Mes],0))/(INDEX(tbl_base_energia[kWh_INJ],MATCH(A8,tbl_base_energia[Mes],0))+INDEX(tbl_base_energia[kWh_SOP],MATCH(A8,tbl_base_energia[Mes],0)))) -> 0.12821372 | Q8: =IF(A8="","",INDEX(tbl_base_energia[kWh_UTL_AR],MATCH(A8,tbl_base_energia[Mes],0))/(INDEX(tbl_base_energia[kWh_INJ],MATCH(A8,tbl_base_energia[Mes],0))+INDEX(tbl_base_energia[kWh_SOP],MATCH(A8,tbl_base_energia[Mes],0))+INDEX(tbl_base_energia[kWh_SER],MATCH(A8,tbl_base_energia[Mes],0))+INDEX(tbl_base_energia[kWh_HFS],MATCH(A8,tbl_base_energia[Mes],0)))) -> 0.19095059 | R8: =IF(A8="","",INDEX(tbl_base_energia[Energia_Final_MWh],MATCH(A8,tbl_base_energia[Mes],0))) -> 517.889
A9: 45839 | B9: =IF(A9="","",INDEX(tbl_base_energia[Periodo],MATCH(A9,tbl_base_energia[Mes],0))) -> Referência (LBE) | C9: =IF(A9="","",INDEX(tbl_base_energia[kWh_Total],MATCH(A9,tbl_base_energia[Mes],0))-INDEX(tbl_base_energia[kWh_Maquinas_Novas],MATCH(A9,tbl_base_energia[Mes],0))) -> 620886 | D9: =IF(A9="","",(INDEX(tbl_base_energia[Unid_INJ],MATCH(A9,tbl_base_energia[Mes],0))+INDEX(tbl_base_energia[Unid_SOP],MATCH(A9,tbl_base_energia[Mes],0))-INDEX(tbl_base_energia[Unid_Maquinas_Novas],MATCH(A9,tbl_base_energia[Mes],0)))/1000) -> 5273.074 | E9: =IF(A9="","",INDEX(tbl_base_energia[CDD_15],MATCH(A9,tbl_base_energia[Mes],0))) -> 223.2 | F9: =IF(A9="","",lbe_a+lbe_b1*D9+lbe_b2*E9) -> 589519.66 | G9: =IF(A9="","",C9-F9) -> 31366.342 | H9: =IF(A9="","",SUM($G$5:G9)) -> 10167.431 | I9: =IF(A9="","",-G9/F9) -> -0.05320661 | J9: =IF(A9="","",IF(AND(D9>=dom_x1_min,D9<=dom_x1_max,E9>=dom_x2_min,E9<=dom_x2_max),"Sim","Não")) -> Sim | K9: =IF(A9="","",IF(B9="Referência (LBE)","Referência",IF(J9="Não","Fora do domínio",IF(G9>lbe_limite,"Desvio significativo",IF(G9<-lbe_limite,"Melhoria significativa","Dentro da incerteza"))))) -> Referência | L9: =IF(A9="","",INDEX(tbl_base_energia[kWh_Total],MATCH(A9,tbl_base_energia[Mes],0))/(INDEX(tbl_base_energia[Unid_INJ],MATCH(A9,tbl_base_energia[Mes],0))+INDEX(tbl_base_energia[Unid_SOP],MATCH(A9,tbl_base_energia[Mes],0)))*1000) -> 117.7465 | M9: =IF(A9="","",INDEX(tbl_base_energia[kWh_SOP],MATCH(A9,tbl_base_energia[Mes],0))/INDEX(tbl_base_energia[Unid_SOP],MATCH(A9,tbl_base_energia[Mes],0))*1000) -> 114.42922 | N9: =IF(A9="","",INDEX(tbl_base_energia[kWh_INJ],MATCH(A9,tbl_base_energia[Mes],0))/INDEX(tbl_base_energia[Unid_INJ],MATCH(A9,tbl_base_energia[Mes],0))*1000) -> 51.224781 | O9: =IF(A9="","",lbe_a/C9) -> 0.15118884 | P9: =IF(A9="","",INDEX(tbl_base_energia[kWh_UTL_FRIO],MATCH(A9,tbl_base_energia[Mes],0))/(INDEX(tbl_base_energia[kWh_INJ],MATCH(A9,tbl_base_energia[Mes],0))+INDEX(tbl_base_energia[kWh_SOP],MATCH(A9,tbl_base_energia[Mes],0)))) -> 0.1331159 | Q9: =IF(A9="","",INDEX(tbl_base_energia[kWh_UTL_AR],MATCH(A9,tbl_base_energia[Mes],0))/(INDEX(tbl_base_energia[kWh_INJ],MATCH(A9,tbl_base_energia[Mes],0))+INDEX(tbl_base_energia[kWh_SOP],MATCH(A9,tbl_base_energia[Mes],0))+INDEX(tbl_base_energia[kWh_SER],MATCH(A9,tbl_base_energia[Mes],0))+INDEX(tbl_base_energia[kWh_HFS],MATCH(A9,tbl_base_energia[Mes],0)))) -> 0.18892869 | R9: =IF(A9="","",INDEX(tbl_base_energia[Energia_Final_MWh],MATCH(A9,tbl_base_energia[Mes],0))) -> 623.503
A10: 45870 | B10: =IF(A10="","",INDEX(tbl_base_energia[Periodo],MATCH(A10,tbl_base_energia[Mes],0))) -> Referência (LBE) | C10: =IF(A10="","",INDEX(tbl_base_energia[kWh_Total],MATCH(A10,tbl_base_energia[Mes],0))-INDEX(tbl_base_energia[kWh_Maquinas_Novas],MATCH(A10,tbl_base_energia[Mes],0))) -> 586901 | D10: =IF(A10="","",(INDEX(tbl_base_energia[Unid_INJ],MATCH(A10,tbl_base_energia[Mes],0))+INDEX(tbl_base_energia[Unid_SOP],MATCH(A10,tbl_base_energia[Mes],0))-INDEX(tbl_base_energia[Unid_Maquinas_Novas],MATCH(A10,tbl_base_energia[Mes],0)))/1000) -> 5443.656 | E10: =IF(A10="","",INDEX(tbl_base_energia[CDD_15],MATCH(A10,tbl_base_energia[Mes],0))) -> 251.1 | F10: =IF(A10="","",lbe_a+lbe_b1*D10+lbe_b2*E10) -> 606721.37 | G10: =IF(A10="","",C10-F10) -> -19820.367 | H10: =IF(A10="","",SUM($G$5:G10)) -> -9652.9363 | I10: =IF(A10="","",-G10/F10) -> 0.032667989 | J10: =IF(A10="","",IF(AND(D10>=dom_x1_min,D10<=dom_x1_max,E10>=dom_x2_min,E10<=dom_x2_max),"Sim","Não")) -> Sim | K10: =IF(A10="","",IF(B10="Referência (LBE)","Referência",IF(J10="Não","Fora do domínio",IF(G10>lbe_limite,"Desvio significativo",IF(G10<-lbe_limite,"Melhoria significativa","Dentro da incerteza"))))) -> Referência | L10: =IF(A10="","",INDEX(tbl_base_energia[kWh_Total],MATCH(A10,tbl_base_energia[Mes],0))/(INDEX(tbl_base_energia[Unid_INJ],MATCH(A10,tbl_base_energia[Mes],0))+INDEX(tbl_base_energia[Unid_SOP],MATCH(A10,tbl_base_energia[Mes],0)))*1000) -> 107.81376 | M10: =IF(A10="","",INDEX(tbl_base_energia[kWh_SOP],MATCH(A10,tbl_base_energia[Mes],0))/INDEX(tbl_base_energia[Unid_SOP],MATCH(A10,tbl_base_energia[Mes],0))*1000) -> 108.52714 | N10: =IF(A10="","",INDEX(tbl_base_energia[kWh_INJ],MATCH(A10,tbl_base_energia[Mes],0))/INDEX(tbl_base_energia[Unid_INJ],MATCH(A10,tbl_base_energia[Mes],0))*1000) -> 45.50599 | O10: =IF(A10="","",lbe_a/C10) -> 0.15994356 | P10: =IF(A10="","",INDEX(tbl_base_energia[kWh_UTL_FRIO],MATCH(A10,tbl_base_energia[Mes],0))/(INDEX(tbl_base_energia[kWh_INJ],MATCH(A10,tbl_base_energia[Mes],0))+INDEX(tbl_base_energia[kWh_SOP],MATCH(A10,tbl_base_energia[Mes],0)))) -> 0.14224459 | Q10: =IF(A10="","",INDEX(tbl_base_energia[kWh_UTL_AR],MATCH(A10,tbl_base_energia[Mes],0))/(INDEX(tbl_base_energia[kWh_INJ],MATCH(A10,tbl_base_energia[Mes],0))+INDEX(tbl_base_energia[kWh_SOP],MATCH(A10,tbl_base_energia[Mes],0))+INDEX(tbl_base_energia[kWh_SER],MATCH(A10,tbl_base_energia[Mes],0))+INDEX(tbl_base_energia[kWh_HFS],MATCH(A10,tbl_base_energia[Mes],0)))) -> 0.19282072 | R10: =IF(A10="","",INDEX(tbl_base_energia[Energia_Final_MWh],MATCH(A10,tbl_base_energia[Mes],0))) -> 589.708
A11: 45901 | B11: =IF(A11="","",INDEX(tbl_base_energia[Periodo],MATCH(A11,tbl_base_energia[Mes],0))) -> Referência (LBE) | C11: =IF(A11="","",INDEX(tbl_base_energia[kWh_Total],MATCH(A11,tbl_base_energia[Mes],0))-INDEX(tbl_base_energia[kWh_Maquinas_Novas],MATCH(A11,tbl_base_energia[Mes],0))) -> 569448 | D11: =IF(A11="","",(INDEX(tbl_base_energia[Unid_INJ],MATCH(A11,tbl_base_energia[Mes],0))+INDEX(tbl_base_energia[Unid_SOP],MATCH(A11,tbl_base_energia[Mes],0))-INDEX(tbl_base_energia[Unid_Maquinas_Novas],MATCH(A11,tbl_base_energia[Mes],0)))/1000) -> 5062.893 | E11: =IF(A11="","",INDEX(tbl_base_energia[CDD_15],MATCH(A11,tbl_base_energia[Mes],0))) -> 177 | F11: =IF(A11="","",lbe_a+lbe_b1*D11+lbe_b2*E11) -> 567657.14 | G11: =IF(A11="","",C11-F11) -> 1790.8606 | H11: =IF(A11="","",SUM($G$5:G11)) -> -7862.0757 | I11: =IF(A11="","",-G11/F11) -> -0.0031548279 | J11: =IF(A11="","",IF(AND(D11>=dom_x1_min,D11<=dom_x1_max,E11>=dom_x2_min,E11<=dom_x2_max),"Sim","Não")) -> Sim | K11: =IF(A11="","",IF(B11="Referência (LBE)","Referência",IF(J11="Não","Fora do domínio",IF(G11>lbe_limite,"Desvio significativo",IF(G11<-lbe_limite,"Melhoria significativa","Dentro da incerteza"))))) -> Referência | L11: =IF(A11="","",INDEX(tbl_base_energia[kWh_Total],MATCH(A11,tbl_base_energia[Mes],0))/(INDEX(tbl_base_energia[Unid_INJ],MATCH(A11,tbl_base_energia[Mes],0))+INDEX(tbl_base_energia[Unid_SOP],MATCH(A11,tbl_base_energia[Mes],0)))*1000) -> 112.47482 | M11: =IF(A11="","",INDEX(tbl_base_energia[kWh_SOP],MATCH(A11,tbl_base_energia[Mes],0))/INDEX(tbl_base_energia[Unid_SOP],MATCH(A11,tbl_base_energia[Mes],0))*1000) -> 112.76909 | N11: =IF(A11="","",INDEX(tbl_base_energia[kWh_INJ],MATCH(A11,tbl_base_energia[Mes],0))/INDEX(tbl_base_energia[Unid_INJ],MATCH(A11,tbl_base_energia[Mes],0))*1000) -> 49.361865 | O11: =IF(A11="","",lbe_a/C11) -> 0.16484567 | P11: =IF(A11="","",INDEX(tbl_base_energia[kWh_UTL_FRIO],MATCH(A11,tbl_base_energia[Mes],0))/(INDEX(tbl_base_energia[kWh_INJ],MATCH(A11,tbl_base_energia[Mes],0))+INDEX(tbl_base_energia[kWh_SOP],MATCH(A11,tbl_base_energia[Mes],0)))) -> 0.12854163 | Q11: =IF(A11="","",INDEX(tbl_base_energia[kWh_UTL_AR],MATCH(A11,tbl_base_energia[Mes],0))/(INDEX(tbl_base_energia[kWh_INJ],MATCH(A11,tbl_base_energia[Mes],0))+INDEX(tbl_base_energia[kWh_SOP],MATCH(A11,tbl_base_energia[Mes],0))+INDEX(tbl_base_energia[kWh_SER],MATCH(A11,tbl_base_energia[Mes],0))+INDEX(tbl_base_energia[kWh_HFS],MATCH(A11,tbl_base_energia[Mes],0)))) -> 0.19043553 | R11: =IF(A11="","",INDEX(tbl_base_energia[Energia_Final_MWh],MATCH(A11,tbl_base_energia[Mes],0))) -> 572.508
A12: 45931 | B12: =IF(A12="","",INDEX(tbl_base_energia[Periodo],MATCH(A12,tbl_base_energia[Mes],0))) -> Referência (LBE) | C12: =IF(A12="","",INDEX(tbl_base_energia[kWh_Total],MATCH(A12,tbl_base_energia[Mes],0))-INDEX(tbl_base_energia[kWh_Maquinas_Novas],MATCH(A12,tbl_base_energia[Mes],0))) -> 568762 | D12: =IF(A12="","",(INDEX(tbl_base_energia[Unid_INJ],MATCH(A12,tbl_base_energia[Mes],0))+INDEX(tbl_base_energia[Unid_SOP],MATCH(A12,tbl_base_energia[Mes],0))-INDEX(tbl_base_energia[Unid_Maquinas_Novas],MATCH(A12,tbl_base_energia[Mes],0)))/1000) -> 5158.725 | E12: =IF(A12="","",INDEX(tbl_base_energia[CDD_15],MATCH(A12,tbl_base_energia[Mes],0))) -> 96.1 | F12: =IF(A12="","",lbe_a+lbe_b1*D12+lbe_b2*E12) -> 571867.96 | G12: =IF(A12="","",C12-F12) -> -3105.9649 | H12: =IF(A12="","",SUM($G$5:G12)) -> -10968.041 | I12: =IF(A12="","",-G12/F12) -> 0.0054312622 | J12: =IF(A12="","",IF(AND(D12>=dom_x1_min,D12<=dom_x1_max,E12>=dom_x2_min,E12<=dom_x2_max),"Sim","Não")) -> Sim | K12: =IF(A12="","",IF(B12="Referência (LBE)","Referência",IF(J12="Não","Fora do domínio",IF(G12>lbe_limite,"Desvio significativo",IF(G12<-lbe_limite,"Melhoria significativa","Dentro da incerteza"))))) -> Referência | L12: =IF(A12="","",INDEX(tbl_base_energia[kWh_Total],MATCH(A12,tbl_base_energia[Mes],0))/(INDEX(tbl_base_energia[Unid_INJ],MATCH(A12,tbl_base_energia[Mes],0))+INDEX(tbl_base_energia[Unid_SOP],MATCH(A12,tbl_base_energia[Mes],0)))*1000) -> 110.25244 | M12: =IF(A12="","",INDEX(tbl_base_energia[kWh_SOP],MATCH(A12,tbl_base_energia[Mes],0))/INDEX(tbl_base_energia[Unid_SOP],MATCH(A12,tbl_base_energia[Mes],0))*1000) -> 110.56761 | N12: =IF(A12="","",INDEX(tbl_base_energia[kWh_INJ],MATCH(A12,tbl_base_energia[Mes],0))/INDEX(tbl_base_energia[Unid_INJ],MATCH(A12,tbl_base_energia[Mes],0))*1000) -> 48.996879 | O12: =IF(A12="","",lbe_a/C12) -> 0.16504449 | P12: =IF(A12="","",INDEX(tbl_base_energia[kWh_UTL_FRIO],MATCH(A12,tbl_base_energia[Mes],0))/(INDEX(tbl_base_energia[kWh_INJ],MATCH(A12,tbl_base_energia[Mes],0))+INDEX(tbl_base_energia[kWh_SOP],MATCH(A12,tbl_base_energia[Mes],0)))) -> 0.11420541 | Q12: =IF(A12="","",INDEX(tbl_base_energia[kWh_UTL_AR],MATCH(A12,tbl_base_energia[Mes],0))/(INDEX(tbl_base_energia[kWh_INJ],MATCH(A12,tbl_base_energia[Mes],0))+INDEX(tbl_base_energia[kWh_SOP],MATCH(A12,tbl_base_energia[Mes],0))+INDEX(tbl_base_energia[kWh_SER],MATCH(A12,tbl_base_energia[Mes],0))+INDEX(tbl_base_energia[kWh_HFS],MATCH(A12,tbl_base_energia[Mes],0)))) -> 0.18765789 | R12: =IF(A12="","",INDEX(tbl_base_energia[Energia_Final_MWh],MATCH(A12,tbl_base_energia[Mes],0))) -> 571.275
A13: 45962 | B13: =IF(A13="","",INDEX(tbl_base_energia[Periodo],MATCH(A13,tbl_base_energia[Mes],0))) -> Referência (LBE) | C13: =IF(A13="","",INDEX(tbl_base_energia[kWh_Total],MATCH(A13,tbl_base_energia[Mes],0))-INDEX(tbl_base_energia[kWh_Maquinas_Novas],MATCH(A13,tbl_base_energia[Mes],0))) -> 561643 | D13: =IF(A13="","",(INDEX(tbl_base_energia[Unid_INJ],MATCH(A13,tbl_base_energia[Mes],0))+INDEX(tbl_base_energia[Unid_SOP],MATCH(A13,tbl_base_energia[Mes],0))-INDEX(tbl_base_energia[Unid_Maquinas_Novas],MATCH(A13,tbl_base_energia[Mes],0)))/1000) -> 4974.09 | E13: =IF(A13="","",INDEX(tbl_base_energia[CDD_15],MATCH(A13,tbl_base_energia[Mes],0))) -> 0 | F13: =IF(A13="","",lbe_a+lbe_b1*D13+lbe_b2*E13) -> 549528.04 | G13: =IF(A13="","",C13-F13) -> 12114.958 | H13: =IF(A13="","",SUM($G$5:G13)) -> 1146.9172 | I13: =IF(A13="","",-G13/F13) -> -0.022046114 | J13: =IF(A13="","",IF(AND(D13>=dom_x1_min,D13<=dom_x1_max,E13>=dom_x2_min,E13<=dom_x2_max),"Sim","Não")) -> Sim | K13: =IF(A13="","",IF(B13="Referência (LBE)","Referência",IF(J13="Não","Fora do domínio",IF(G13>lbe_limite,"Desvio significativo",IF(G13<-lbe_limite,"Melhoria significativa","Dentro da incerteza"))))) -> Referência | L13: =IF(A13="","",INDEX(tbl_base_energia[kWh_Total],MATCH(A13,tbl_base_energia[Mes],0))/(INDEX(tbl_base_energia[Unid_INJ],MATCH(A13,tbl_base_energia[Mes],0))+INDEX(tbl_base_energia[Unid_SOP],MATCH(A13,tbl_base_energia[Mes],0)))*1000) -> 112.91372 | M13: =IF(A13="","",INDEX(tbl_base_energia[kWh_SOP],MATCH(A13,tbl_base_energia[Mes],0))/INDEX(tbl_base_energia[Unid_SOP],MATCH(A13,tbl_base_energia[Mes],0))*1000) -> 115.30164 | N13: =IF(A13="","",INDEX(tbl_base_energia[kWh_INJ],MATCH(A13,tbl_base_energia[Mes],0))/INDEX(tbl_base_energia[Unid_INJ],MATCH(A13,tbl_base_energia[Mes],0))*1000) -> 49.423668 | O13: =IF(A13="","",lbe_a/C13) -> 0.16713648 | P13: =IF(A13="","",INDEX(tbl_base_energia[kWh_UTL_FRIO],MATCH(A13,tbl_base_energia[Mes],0))/(INDEX(tbl_base_energia[kWh_INJ],MATCH(A13,tbl_base_energia[Mes],0))+INDEX(tbl_base_energia[kWh_SOP],MATCH(A13,tbl_base_energia[Mes],0)))) -> 0.091511891 | Q13: =IF(A13="","",INDEX(tbl_base_energia[kWh_UTL_AR],MATCH(A13,tbl_base_energia[Mes],0))/(INDEX(tbl_base_energia[kWh_INJ],MATCH(A13,tbl_base_energia[Mes],0))+INDEX(tbl_base_energia[kWh_SOP],MATCH(A13,tbl_base_energia[Mes],0))+INDEX(tbl_base_energia[kWh_SER],MATCH(A13,tbl_base_energia[Mes],0))+INDEX(tbl_base_energia[kWh_HFS],MATCH(A13,tbl_base_energia[Mes],0)))) -> 0.18897825 | R13: =IF(A13="","",INDEX(tbl_base_energia[Energia_Final_MWh],MATCH(A13,tbl_base_energia[Mes],0))) -> 564.121
A14: 45992 | B14: =IF(A14="","",INDEX(tbl_base_energia[Periodo],MATCH(A14,tbl_base_energia[Mes],0))) -> Referência (LBE) | C14: =IF(A14="","",INDEX(tbl_base_energia[kWh_Total],MATCH(A14,tbl_base_energia[Mes],0))-INDEX(tbl_base_energia[kWh_Maquinas_Novas],MATCH(A14,tbl_base_energia[Mes],0))) -> 582602 | D14: =IF(A14="","",(INDEX(tbl_base_energia[Unid_INJ],MATCH(A14,tbl_base_energia[Mes],0))+INDEX(tbl_base_energia[Unid_SOP],MATCH(A14,tbl_base_energia[Mes],0))-INDEX(tbl_base_energia[Unid_Maquinas_Novas],MATCH(A14,tbl_base_energia[Mes],0)))/1000) -> 5221.94 | E14: =IF(A14="","",INDEX(tbl_base_energia[CDD_15],MATCH(A14,tbl_base_energia[Mes],0))) -> 0 | F14: =IF(A14="","",lbe_a+lbe_b1*D14+lbe_b2*E14) -> 572232.62 | G14: =IF(A14="","",C14-F14) -> 10369.385 | H14: =IF(A14="","",SUM($G$5:G14)) -> 11516.302 | I14: =IF(A14="","",-G14/F14) -> -0.018120926 | J14: =IF(A14="","",IF(AND(D14>=dom_x1_min,D14<=dom_x1_max,E14>=dom_x2_min,E14<=dom_x2_max),"Sim","Não")) -> Sim | K14: =IF(A14="","",IF(B14="Referência (LBE)","Referência",IF(J14="Não","Fora do domínio",IF(G14>lbe_limite,"Desvio significativo",IF(G14<-lbe_limite,"Melhoria significativa","Dentro da incerteza"))))) -> Referência | L14: =IF(A14="","",INDEX(tbl_base_energia[kWh_Total],MATCH(A14,tbl_base_energia[Mes],0))/(INDEX(tbl_base_energia[Unid_INJ],MATCH(A14,tbl_base_energia[Mes],0))+INDEX(tbl_base_energia[Unid_SOP],MATCH(A14,tbl_base_energia[Mes],0)))*1000) -> 111.56811 | M14: =IF(A14="","",INDEX(tbl_base_energia[kWh_SOP],MATCH(A14,tbl_base_energia[Mes],0))/INDEX(tbl_base_energia[Unid_SOP],MATCH(A14,tbl_base_energia[Mes],0))*1000) -> 113.73051 | N14: =IF(A14="","",INDEX(tbl_base_energia[kWh_INJ],MATCH(A14,tbl_base_energia[Mes],0))/INDEX(tbl_base_energia[Unid_INJ],MATCH(A14,tbl_base_energia[Mes],0))*1000) -> 49.57937 | O14: =IF(A14="","",lbe_a/C14) -> 0.16112378 | P14: =IF(A14="","",INDEX(tbl_base_energia[kWh_UTL_FRIO],MATCH(A14,tbl_base_energia[Mes],0))/(INDEX(tbl_base_energia[kWh_INJ],MATCH(A14,tbl_base_energia[Mes],0))+INDEX(tbl_base_energia[kWh_SOP],MATCH(A14,tbl_base_energia[Mes],0)))) -> 0.085871552 | Q14: =IF(A14="","",INDEX(tbl_base_energia[kWh_UTL_AR],MATCH(A14,tbl_base_energia[Mes],0))/(INDEX(tbl_base_energia[kWh_INJ],MATCH(A14,tbl_base_energia[Mes],0))+INDEX(tbl_base_energia[kWh_SOP],MATCH(A14,tbl_base_energia[Mes],0))+INDEX(tbl_base_energia[kWh_SER],MATCH(A14,tbl_base_energia[Mes],0))+INDEX(tbl_base_energia[kWh_HFS],MATCH(A14,tbl_base_energia[Mes],0)))) -> 0.1846362 | R14: =IF(A14="","",INDEX(tbl_base_energia[Energia_Final_MWh],MATCH(A14,tbl_base_energia[Mes],0))) -> 585.066
A15: 46023 | B15: =IF(A15="","",INDEX(tbl_base_energia[Periodo],MATCH(A15,tbl_base_energia[Mes],0))) -> Referência (LBE) | C15: =IF(A15="","",INDEX(tbl_base_energia[kWh_Total],MATCH(A15,tbl_base_energia[Mes],0))-INDEX(tbl_base_energia[kWh_Maquinas_Novas],MATCH(A15,tbl_base_energia[Mes],0))) -> 567251 | D15: =IF(A15="","",(INDEX(tbl_base_energia[Unid_INJ],MATCH(A15,tbl_base_energia[Mes],0))+INDEX(tbl_base_energia[Unid_SOP],MATCH(A15,tbl_base_energia[Mes],0))-INDEX(tbl_base_energia[Unid_Maquinas_Novas],MATCH(A15,tbl_base_energia[Mes],0)))/1000) -> 5272.284 | E15: =IF(A15="","",INDEX(tbl_base_energia[CDD_15],MATCH(A15,tbl_base_energia[Mes],0))) -> 0 | F15: =IF(A15="","",lbe_a+lbe_b1*D15+lbe_b2*E15) -> 576844.43 | G15: =IF(A15="","",C15-F15) -> -9593.4327 | H15: =IF(A15="","",SUM($G$5:G15)) -> 1922.8695 | I15: =IF(A15="","",-G15/F15) -> 0.016630884 | J15: =IF(A15="","",IF(AND(D15>=dom_x1_min,D15<=dom_x1_max,E15>=dom_x2_min,E15<=dom_x2_max),"Sim","Não")) -> Sim | K15: =IF(A15="","",IF(B15="Referência (LBE)","Referência",IF(J15="Não","Fora do domínio",IF(G15>lbe_limite,"Desvio significativo",IF(G15<-lbe_limite,"Melhoria significativa","Dentro da incerteza"))))) -> Referência | L15: =IF(A15="","",INDEX(tbl_base_energia[kWh_Total],MATCH(A15,tbl_base_energia[Mes],0))/(INDEX(tbl_base_energia[Unid_INJ],MATCH(A15,tbl_base_energia[Mes],0))+INDEX(tbl_base_energia[Unid_SOP],MATCH(A15,tbl_base_energia[Mes],0)))*1000) -> 107.59113 | M15: =IF(A15="","",INDEX(tbl_base_energia[kWh_SOP],MATCH(A15,tbl_base_energia[Mes],0))/INDEX(tbl_base_energia[Unid_SOP],MATCH(A15,tbl_base_energia[Mes],0))*1000) -> 116.54359 | N15: =IF(A15="","",INDEX(tbl_base_energia[kWh_INJ],MATCH(A15,tbl_base_energia[Mes],0))/INDEX(tbl_base_energia[Unid_INJ],MATCH(A15,tbl_base_energia[Mes],0))*1000) -> 47.904912 | O15: =IF(A15="","",lbe_a/C15) -> 0.16548413 | P15: =IF(A15="","",INDEX(tbl_base_energia[kWh_UTL_FRIO],MATCH(A15,tbl_base_energia[Mes],0))/(INDEX(tbl_base_energia[kWh_INJ],MATCH(A15,tbl_base_energia[Mes],0))+INDEX(tbl_base_energia[kWh_SOP],MATCH(A15,tbl_base_energia[Mes],0)))) -> 0.071929704 | Q15: =IF(A15="","",INDEX(tbl_base_energia[kWh_UTL_AR],MATCH(A15,tbl_base_energia[Mes],0))/(INDEX(tbl_base_energia[kWh_INJ],MATCH(A15,tbl_base_energia[Mes],0))+INDEX(tbl_base_energia[kWh_SOP],MATCH(A15,tbl_base_energia[Mes],0))+INDEX(tbl_base_energia[kWh_SER],MATCH(A15,tbl_base_energia[Mes],0))+INDEX(tbl_base_energia[kWh_HFS],MATCH(A15,tbl_base_energia[Mes],0)))) -> 0.19075787 | R15: =IF(A15="","",INDEX(tbl_base_energia[Energia_Final_MWh],MATCH(A15,tbl_base_energia[Mes],0))) -> 570.265
A16: 46054 | B16: =IF(A16="","",INDEX(tbl_base_energia[Periodo],MATCH(A16,tbl_base_energia[Mes],0))) -> Referência (LBE) | C16: =IF(A16="","",INDEX(tbl_base_energia[kWh_Total],MATCH(A16,tbl_base_energia[Mes],0))-INDEX(tbl_base_energia[kWh_Maquinas_Novas],MATCH(A16,tbl_base_energia[Mes],0))) -> 527749 | D16: =IF(A16="","",(INDEX(tbl_base_energia[Unid_INJ],MATCH(A16,tbl_base_energia[Mes],0))+INDEX(tbl_base_energia[Unid_SOP],MATCH(A16,tbl_base_energia[Mes],0))-INDEX(tbl_base_energia[Unid_Maquinas_Novas],MATCH(A16,tbl_base_energia[Mes],0)))/1000) -> 4757.334 | E16: =IF(A16="","",INDEX(tbl_base_energia[CDD_15],MATCH(A16,tbl_base_energia[Mes],0))) -> 0 | F16: =IF(A16="","",lbe_a+lbe_b1*D16+lbe_b2*E16) -> 529671.87 | G16: =IF(A16="","",C16-F16) -> -1922.8695 | H16: =IF(A16="","",SUM($G$5:G16)) -> -2.910383e-10 | I16: =IF(A16="","",-G16/F16) -> 0.0036303032 | J16: =IF(A16="","",IF(AND(D16>=dom_x1_min,D16<=dom_x1_max,E16>=dom_x2_min,E16<=dom_x2_max),"Sim","Não")) -> Sim | K16: =IF(A16="","",IF(B16="Referência (LBE)","Referência",IF(J16="Não","Fora do domínio",IF(G16>lbe_limite,"Desvio significativo",IF(G16<-lbe_limite,"Melhoria significativa","Dentro da incerteza"))))) -> Referência | L16: =IF(A16="","",INDEX(tbl_base_energia[kWh_Total],MATCH(A16,tbl_base_energia[Mes],0))/(INDEX(tbl_base_energia[Unid_INJ],MATCH(A16,tbl_base_energia[Mes],0))+INDEX(tbl_base_energia[Unid_SOP],MATCH(A16,tbl_base_energia[Mes],0)))*1000) -> 110.93377 | M16: =IF(A16="","",INDEX(tbl_base_energia[kWh_SOP],MATCH(A16,tbl_base_energia[Mes],0))/INDEX(tbl_base_energia[Unid_SOP],MATCH(A16,tbl_base_energia[Mes],0))*1000) -> 110.68646 | N16: =IF(A16="","",INDEX(tbl_base_energia[kWh_INJ],MATCH(A16,tbl_base_energia[Mes],0))/INDEX(tbl_base_energia[Unid_INJ],MATCH(A16,tbl_base_energia[Mes],0))*1000) -> 49.831451 | O16: =IF(A16="","",lbe_a/C16) -> 0.17787061 | P16: =IF(A16="","",INDEX(tbl_base_energia[kWh_UTL_FRIO],MATCH(A16,tbl_base_energia[Mes],0))/(INDEX(tbl_base_energia[kWh_INJ],MATCH(A16,tbl_base_energia[Mes],0))+INDEX(tbl_base_energia[kWh_SOP],MATCH(A16,tbl_base_energia[Mes],0)))) -> 0.08590604 | Q16: =IF(A16="","",INDEX(tbl_base_energia[kWh_UTL_AR],MATCH(A16,tbl_base_energia[Mes],0))/(INDEX(tbl_base_energia[kWh_INJ],MATCH(A16,tbl_base_energia[Mes],0))+INDEX(tbl_base_energia[kWh_SOP],MATCH(A16,tbl_base_energia[Mes],0))+INDEX(tbl_base_energia[kWh_SER],MATCH(A16,tbl_base_energia[Mes],0))+INDEX(tbl_base_energia[kWh_HFS],MATCH(A16,tbl_base_energia[Mes],0)))) -> 0.18913752 | R16: =IF(A16="","",INDEX(tbl_base_energia[Energia_Final_MWh],MATCH(A16,tbl_base_energia[Mes],0))) -> 530.816
... A26: 46357 | B26: =IF(A26="","",INDEX(tbl_base_energia[Periodo],MATCH(A26,tbl_base_energia[Mes],0))) -> Reporte | C26: =IF(A26="","",INDEX(tbl_base_energia[kWh_Total],MATCH(A26,tbl_base_energia[Mes],0))-INDEX(tbl_base_energia[kWh_Maquinas_Novas],MATCH(A26,tbl_base_energia[Mes],0))) -> 513562 | D26: =IF(A26="","",(INDEX(tbl_base_energia[Unid_INJ],MATCH(A26,tbl_base_energia[Mes],0))+INDEX(tbl_base_energia[Unid_SOP],MATCH(A26,tbl_base_energia[Mes],0))-INDEX(tbl_base_energia[Unid_Maquinas_Novas],MATCH(A26,tbl_base_energia[Mes],0)))/1000) -> 5067.039 | E26: =IF(A26="","",INDEX(tbl_base_energia[CDD_15],MATCH(A26,tbl_base_energia[Mes],0))) -> 0 | F26: =IF(A26="","",lbe_a+lbe_b1*D26+lbe_b2*E26) -> 558042.74 | G26: =IF(A26="","",C26-F26) -> -44480.738 | H26: =IF(A26="","",SUM($G$5:G26)) -> -81639.974 | I26: =IF(A26="","",-G26/F26) -> 0.079708479 | J26: =IF(A26="","",IF(AND(D26>=dom_x1_min,D26<=dom_x1_max,E26>=dom_x2_min,E26<=dom_x2_max),"Sim","Não")) -> Sim | K26: =IF(A26="","",IF(B26="Referência (LBE)","Referência",IF(J26="Não","Fora do domínio",IF(G26>lbe_limite,"Desvio significativo",IF(G26<-lbe_limite,"Melhoria significativa","Dentro da incerteza"))))) -> Melhoria significativa | L26: =IF(A26="","",INDEX(tbl_base_energia[kWh_Total],MATCH(A26,tbl_base_energia[Mes],0))/(INDEX(tbl_base_energia[Unid_INJ],MATCH(A26,tbl_base_energia[Mes],0))+INDEX(tbl_base_energia[Unid_SOP],MATCH(A26,tbl_base_energia[Mes],0)))*1000) -> 97.763809 | M26: =IF(A26="","",INDEX(tbl_base_energia[kWh_SOP],MATCH(A26,tbl_base_energia[Mes],0))/INDEX(tbl_base_energia[Unid_SOP],MATCH(A26,tbl_base_energia[Mes],0))*1000) -> 109.85156 | N26: =IF(A26="","",INDEX(tbl_base_energia[kWh_INJ],MATCH(A26,tbl_base_energia[Mes],0))/INDEX(tbl_base_energia[Unid_INJ],MATCH(A26,tbl_base_energia[Mes],0))*1000) -> 45.829258 | O26: =IF(A26="","",lbe_a/C26) -> 0.18278423 | P26: =IF(A26="","",INDEX(tbl_base_energia[kWh_UTL_FRIO],MATCH(A26,tbl_base_energia[Mes],0))/(INDEX(tbl_base_energia[kWh_INJ],MATCH(A26,tbl_base_energia[Mes],0))+INDEX(tbl_base_energia[kWh_SOP],MATCH(A26,tbl_base_energia[Mes],0)))) -> 0.080503693 | Q26: =IF(A26="","",INDEX(tbl_base_energia[kWh_UTL_AR],MATCH(A26,tbl_base_energia[Mes],0))/(INDEX(tbl_base_energia[kWh_INJ],MATCH(A26,tbl_base_energia[Mes],0))+INDEX(tbl_base_energia[kWh_SOP],MATCH(A26,tbl_base_energia[Mes],0))+INDEX(tbl_base_energia[kWh_SER],MATCH(A26,tbl_base_energia[Mes],0))+INDEX(tbl_base_energia[kWh_HFS],MATCH(A26,tbl_base_energia[Mes],0)))) -> 0.15631318 | R26: =IF(A26="","",INDEX(tbl_base_energia[Energia_Final_MWh],MATCH(A26,tbl_base_energia[Mes],0))) -> 678.51

Sheet LBE_Modelo
A1: LBE-01 — MODELO ESTATÍSTICO, VALIDADE E DEMONSTRAÇÃO DA MELHORIA — calculado
A2: kWh ajustado = a + b1 × (mil unidades INJ+SOP) + b2 × CDD₁₅ · Referência 2025-03-01 a 2026-02-28 (12 meses) · LINEST sobre IDE_Mensal
A4: Termo | B4: Coeficiente | C4: Erro-padrão | D4: t | E4: p-valor | F4: Cumpre p < 0,2? | G4: Interpretação
A5: a — carga de base (kWh/mês) | B5: =INDEX(LINEST(IDE_Mensal!$C$5:$C$16,IDE_Mensal!$D$5:$E$16,TRUE,TRUE),1,3) -> 93871.037 | C5: =INDEX(LINEST(IDE_Mensal!$C$5:$C$16,IDE_Mensal!$D$5:$E$16,TRUE,TRUE),2,3) -> 95670.531 | D5: =IFERROR(B5/C5,"") -> 0.98119072 | E5: =IFERROR(TDIST(ABS(D5),lbe_df,2),"") -> 0.35213713 | F5: =IF(E5="","",IF(E5<0.2,"Sim","Não")) -> Não | G5: Energia consumida sem produção nem calor: iluminação, AVAC, utilidades em vazio, máquinas em espera (≈ 'base load' de Kent).
A6: b1 — kWh por mil unidades (INJ+SOP) | B6: =INDEX(LINEST(IDE_Mensal!$C$5:$C$16,IDE_Mensal!$D$5:$E$16,TRUE,TRUE),1,2) -> 91.606104 | C6: =INDEX(LINEST(IDE_Mensal!$C$5:$C$16,IDE_Mensal!$D$5:$E$16,TRUE,TRUE),2,2) -> 18.979981 | D6: =IFERROR(B6/C6,"") -> 4.8264592 | E6: =IFERROR(TDIST(ABS(D6),lbe_df,2),"") -> 0.00093851091 | F6: =IF(E6="","",IF(E6<0.2,"Sim","Não")) -> Sim | G6: Consumo marginal de produção: cada mil unidades adicionais custam b1 kWh.
A7: b2 — kWh por grau-dia de arrefecimento | B7: =INDEX(LINEST(IDE_Mensal!$C$5:$C$16,IDE_Mensal!$D$5:$E$16,TRUE,TRUE),1,1) -> 56.464409 | C7: =INDEX(LINEST(IDE_Mensal!$C$5:$C$16,IDE_Mensal!$D$5:$E$16,TRUE,TRUE),2,1) -> 48.058908 | D7: =IFERROR(B7/C7,"") -> 1.1749 | E7: =IFERROR(TDIST(ABS(D7),lbe_df,2),"") -> 0.27018198 | F7: =IF(E7="","",IF(E7<0.2,"Sim","Não")) -> Não | G7: Efeito do calor no arrefecimento de moldes e no AVAC.
A9: Estatística do modelo | B9: Valor
A10: R² | B10: =INDEX(LINEST(IDE_Mensal!$C$5:$C$16,IDE_Mensal!$D$5:$E$16,TRUE,TRUE),3,1) -> 0.75328415
A11: Erro-padrão da estimativa (kWh) | B11: =INDEX(LINEST(IDE_Mensal!$C$5:$C$16,IDE_Mensal!$D$5:$E$16,TRUE,TRUE),3,2) -> 15599.313
A12: Estatística F | B12: =INDEX(LINEST(IDE_Mensal!$C$5:$C$16,IDE_Mensal!$D$5:$E$16,TRUE,TRUE),4,1) -> 13.739606
A13: Graus de liberdade (n − p − 1) | B13: =INDEX(LINEST(IDE_Mensal!$C$5:$C$16,IDE_Mensal!$D$5:$E$16,TRUE,TRUE),4,2) -> 9
A14: p-valor do teste F | B14: =FDIST(lbe_f,2,lbe_df) -> 0.0018402921
A15: Média de Y na referência (kWh) | B15: =AVERAGE(IDE_Mensal!$C$5:$C$16) -> 562748.83
A16: CV(RMSE) | B16: =lbe_sey/lbe_ymed -> 0.02771985
A17: NMBE | B17: =SUM(IDE_Mensal!$G$5:$G$16)/((COUNT(IDE_Mensal!$C$5:$C$16)-3)*lbe_ymed) -> -5.7463628e-17
A18: t(95%; gl) | B18: =TINV(0.05,lbe_df) -> 2.2621572
A19: Limite de desvio significativo mensal (kWh) = t × erro-padrão | B19: =lbe_t*lbe_sey -> 35288.098
A20: Carga de base em % do consumo médio | B20: =lbe_a/lbe_ymed -> 0.16680805
A22: Teste de validade | B22: Valor | C22: Critério | D22: Resultado | F22: Fonte do critério | G22: Leitura
A23: R² (EnPI Lite) | B23: =lbe_r2 -> 0.75328415 | C23: ≥ 0,50 | D23: =IF(lbe_r2>=0.5,"Cumpre","Não cumpre") -> Cumpre | F23: LBNL EnPI Lite / 50001 Ready M&V | G23: Fração da variação mensal explicada pelas variáveis.
A24: R² (ASHRAE 14, recomendado) | B24: =lbe_r2 -> 0.75328415 | C24: > 0,75 | D24: =IF(lbe_r2>0.75,"Cumpre","Não cumpre") -> Cumpre | F24: ASHRAE Guideline 14 | G24: Recomendação para modelos mensais; valores perto do limite pedem mais dados medidos.
A25: p-valor de todas as variáveis | B25: =MAX(E6:E7) -> 0.27018198 | C25: < 0,20 | D25: =IF(MAX(E6:E7)<0.2,"Cumpre","Não cumpre") -> Não cumpre | F25: LBNL EnPI Lite | G25: Cada variável relevante tem efeito estatisticamente distinguível.
A26: p-valor de pelo menos uma variável | B26: =MIN(E6:E7) -> 0.00093851091 | C26: < 0,10 | D26: =IF(MIN(E6:E7)<0.1,"Cumpre","Não cumpre") -> Cumpre | F26: LBNL EnPI Lite
A27: p-valor do teste F | B27: =lbe_pf -> 0.0018402921 | C27: < 0,10 | D27: =IF(lbe_pf<0.1,"Cumpre","Não cumpre") -> Cumpre | F27: LBNL EnPI Lite | G27: O modelo no seu conjunto é significativo.
A28: CV(RMSE) | B28: =lbe_cv -> 0.02771985 | C28: ≤ 15% | D28: =IF(lbe_cv<=0.15,"Cumpre","Não cumpre") -> Cumpre | F28: ASHRAE Guideline 14 (mensal) | G28: Dispersão do modelo face à média — base da incerteza da poupança.
A29: NMBE | B29: =lbe_nmbe -> -5.7463628e-17 | C29: entre −5% e +5% | D29: =IF(ABS(lbe_nmbe)<=0.05,"Cumpre","Não cumpre") -> Cumpre | F29: ASHRAE Guideline 14 | G29: Sem enviesamento sistemático (≈ 0 por construção em mínimos quadrados).
A30: Modelo válido para a LBE-01? | B30: =IF(COUNTIF(D23:D29,"Não cumpre")=0,"Válido",IF(COUNTIF(D23:D29,"Não cumpre")=1,"Válido com reserva","Não válido")) -> Válido com reserva
A32: Domínio de validade (ISO 50006 §8.2) | B32: Mínimo | C32: Máximo | D32: Tolerância | E32: Mín. aceite | F32: Máx. aceite | G32: Nota
A33: X1 — mil unidades INJ+SOP | B33: =MIN(IDE_Mensal!$D$5:$D$16) -> 4543.947 | C33: =MAX(IDE_Mensal!$D$5:$D$16) -> 5443.656 | D33: 0.1 | E33: =B33*(1-D33) -> 4089.5523 | F33: =C33*(1+D33) -> 5988.0216 | G33: Fora destes limites o modelo extrapola: o mês não entra na demonstração da melhoria.
A34: X2 — CDD₁₅ | B34: =MIN(IDE_Mensal!$E$5:$E$16) -> 0 | C34: =MAX(IDE_Mensal!$E$5:$E$16) -> 251.1 | D34: 0.1 | E34: =B34*(1-D34) -> 0 | F34: =C34*(1+D34) -> 276.21 | G34: Com CDD = 0 no inverno, o mínimo aceite é 0.
A37: Demonstração da melhoria (ISO 50001 9.1.1 e 10.2; ISO 50006 §10.3) | B37: Valor | G37: Leitura
A38: Meses de reporte | B38: =COUNTIF(tbl_ide_mensal[Periodo],"Reporte") -> 10
A39: Meses de reporte dentro do domínio (m) | B39: =COUNTIFS(tbl_ide_mensal[Periodo],"Reporte",tbl_ide_mensal[Dentro_Dominio],"Sim") -> 9 | G39: Só estes meses servem para demonstrar melhoria.
A40: Σ kWh esperado (dentro do domínio) | B40: =SUMIFS(tbl_ide_mensal[kWh_Esperado],tbl_ide_mensal[Periodo],"Reporte",tbl_ide_mensal[Dentro_Dominio],"Sim") -> 5146702.1
A41: Σ kWh real ajustado (dentro do domínio) | B41: =SUMIFS(tbl_ide_mensal[Y_kWh_Ajustado],tbl_ide_mensal[Periodo],"Reporte",tbl_ide_mensal[Dentro_Dominio],"Sim") -> 5047066
A42: Poupança normalizada (kWh) = esperado − real | B42: =B40-B41 -> 99636.085 | G42: Positivo = melhoria; negativo = piorou.
A43: Melhoria do desempenho energético (%) | B43: =IFERROR(B42/B40,"") -> 0.01935921 | G43: IDE-01 agregado no período de reporte.
A44: Incerteza a 95% (kWh) ≈ t × erro-padrão × √m | B44: =lbe_t*lbe_sey*SQRT(B39) -> 105864.29 | G44: Aproximação da ASHRAE 14 sem termos de alavancagem (conservadora para m pequeno).
A45: Conclusão | B45: =IF(B39=0,"Sem meses válidos",IF(B42>B44,"Melhoria DEMONSTRADA (estatisticamente significativa)",IF(B42<-B44,"Piorou (desvio significativo)","Melhoria NÃO demonstrada: diferença dentro da incerteza do modelo"))) -> Melhoria NÃO demonstrada: diferença dentro da incerteza do modelo | G45: Para a certificação (ISO 50003:2021) a melhoria tem de ser demonstrada; ver RG-SGE-11 (M&V por ação) e PA-E-01 (submedição).
A47: Após as ações de standby e ar comprimido (out–dez/2026) | B47: Valor | G47: Leitura
...

Sheet Variaveis_Relevantes
A1: VARIÁVEIS RELEVANTES CANDIDATAS — SELEÇÃO (ISO 50006 §5.5)
A2: Correlação calculada nos 12 meses de referência · Critério de relevância: significativa no modelo (p < 0,2) e com explicação física
A4: ID_Variavel | B4: Variavel | C4: Coluna_Base | D4: Fonte | E4: Unidade | F4: Correlacao_com_kWh | G4: R2_Simples | H4: Decisao | I4: Justificacao
A5: VAR-01 | B5: Unidades produzidas INJ + SOP | C5: Unid_INJ | D5: Dataset (MES) | E5: un | F5: =SUMPRODUCT((Base_Mensal!$Q$5:$Q$16+Base_Mensal!$R$5:$R$16-AVERAGE(Base_Mensal!$Q$5:$Q$16)-AVERAGE(Base_Mensal!$R$5:$R$16))*(Base_Mensal!$I$5:$I$16-AVERAGE(Base_Mensal!$I$5:$I$16)))/SQRT(SUMPRODUCT((Base_Mensal!$Q$5:$Q$16+Base_Mensal!$R$5:$R$16-AVERAGE(Base_Mensal!$Q$5:$Q$16)-AVERAGE(Base_Mensal!$R$5:$R$16))^2)*SUMPRODUCT((Base_Mensal!$I$5:$I$16-AVERAGE(Base_Mensal!$I$5:$I$16))^2)) -> 0.84583905 | G5: =IF(A5="","",IFERROR(F5^2,"")) -> 0.71544369 | H5: Relevante | I5: Maior correlação com sentido físico; variável de negócio que a produção controla. Entra como X1 (soma INJ+SOP, milhares).
A6: VAR-02 | B6: Graus-dia de arrefecimento (base 15 °C) | C6: CDD_15 | D6: IPMA (via RG-SGA-13) | E6: °C·dia | F6: =CORREL(Base_Mensal!$I$5:$I$16,Base_Mensal!$H$5:$H$16) -> 0.33868759 | G6: =IF(A6="","",IFERROR(F6^2,"")) -> 0.11470929 | H6: Relevante (com reserva) | I6: Explica fisicamente o arrefecimento e o AVAC no verão e reduz o erro nos meses quentes, mas p ≈ 0,27 (> 0,2) com 12 meses de rateio. Mantida com reserva registada (LBE válida com reserva); reavaliar com os dados medidos dos analisadores (ALE-03).
A7: VAR-03 | B7: Horas de marcha da injeção | C7: Horas_INJ | D7: Dataset (MES) | E7: h | F7: =CORREL(Base_Mensal!$I$5:$I$16,Base_Mensal!$U$5:$U$16) -> 0.76162037 | G7: =IF(A7="","",IFERROR(F7^2,"")) -> 0.58006558 | H7: Redundante | I7: Muito correlacionada com as unidades (a energia do rateio é horas × kW). Não se usam as duas: preferidas as unidades (saída útil).
A8: VAR-04 | B8: Horas de marcha do sopro | C8: Horas_SOP | D8: Dataset (MES) | E8: h | F8: =CORREL(Base_Mensal!$I$5:$I$16,Base_Mensal!$V$5:$V$16) -> 0.93019174 | G8: =IF(A8="","",IFERROR(F8^2,"")) -> 0.86525667 | H8: Redundante | I8: Correlação mais alta que as unidades (a energia do rateio é horas × kW) e um modelo horas + CDD teria R² ≈ 0,86 — rejeitado: normalizar por horas esconderia as perdas de produtividade (marcha lenta, microparagens) que são desperdício de energia. A ISO 50006 recomenda variáveis de saída útil quando possível.
A9: VAR-05 | B9: Dias úteis | C9: Dias_Uteis | D9: Calendário | E9: dias | F9: =CORREL(Base_Mensal!$I$5:$I$16,Base_Mensal!$F$5:$F$16) -> 0.60898591 | G9: =IF(A9="","",IFERROR(F9^2,"")) -> 0.37086384 | H9: Excluída | I9: Efeito já captado pelas unidades produzidas; correlação fraca isoladamente.
A10: VAR-06 | B10: Temperatura média exterior | C10: Temp_Media_C | D10: IPMA | E10: °C | F10: =CORREL(Base_Mensal!$I$5:$I$16,Base_Mensal!$G$5:$G$16) -> 0.23025918 | G10: =IF(A10="","",IFERROR(F10^2,"")) -> 0.053019289 | H10: Redundante | I10: Substituída pelos graus-dia (relação não linear: só acima de 15 °C há carga de arrefecimento).

Sheet Catalogo_IDE
A1: CATÁLOGO DE INDICADORES DE DESEMPENHO ENERGÉTICO (6.4) — ISO 50006
A2: Mesmas colunas do RG-SGA-05 tbl_kpi nas primeiras 12 posições · Baseline e valor de reporte calculados a partir de IDE_Mensal
A4: ID_KPI | B4: Nome | C4: Formula_Calculo | D4: Unidade | E4: Polaridade | F4: Tipo_IDE_ISO50006 | G4: Frequencia | H4: Fonte_Dados | I4: Responsavel | J4: Baseline | K4: ID_OBJ | L4: ID_MED | M4: Fronteira | N4: ID_USE | O4: Variaveis_Relevantes | P4: Fatores_Estaticos | Q4: Normalizacao | R4: ID_LBE | S4: Utilizadores | T4: Coluna_Mensal | U4: Meta | V4: Valor_LBE_Externo | W4: Valor_Reporte_Externo | X4: Valor_Reporte | Y4: Variacao_vs_LBE | Z4: Estado | AA4: Ligacao_SGI | AB4: Qualidade_Dados
A5: IDE-01 | B5: Melhoria do desempenho energético da instalação (consumo normalizado) | C5: (kWh esperado pelo modelo da LBE − kWh real ajustado) ÷ kWh esperado | D5: % | E5: Maior | F5: Modelo estatístico (regressão linear múltipla) | G5: Mensal | H5: RG-SGA-13 (fatura) + dataset de produção + IPMA | I5: Gestor(a) de Energia (líder da equipa de gestão de energia) | J5: =IF(OR(A5="",T5="—"),V5,IFERROR(AVERAGE(INDEX(IDE_Mensal!$A$5:$R$16,0,MATCH(T5,IDE_Mensal!$A$4:$R$4,0))),"")) -> 0 | K5: OBJ-E-01 | L5: DAD-01; DAD-02; DAD-06 | M5: Instalação da Unidade 1 sem as 4 máquinas novas de 07/2026 (ajuste não rotineiro ALE-01) | N5: Todos | O5: Unidades INJ+SOP (mil); graus-dia de arrefecimento base 15 °C | P5: N.º de máquinas; turnos 3×8 em 5 dias; mix de produto; área; tipo de energia | Q5: Sim — modelo da LBE aplicado às condições do mês (ISO 50006 §8) | R5: LBE-01 | S5: Gestão de topo; equipa de gestão de energia; auditores do SGE; certificação ISO 50003 | T5: — | U5: 0.05 | V5: 0 | W5: =LBE_Modelo!$B$43 -> 0.01935921 | X5: =IF(A5="","",IF(T5="—",W5,IFERROR(AVERAGE(INDEX(IDE_Mensal!$A$17:$R$26,0,MATCH(T5,IDE_Mensal!$A$4:$R$4,0))),""))) -> 0.01935921 | Y5: =IF(OR(A5="",NOT(ISNUMBER(X5)),NOT(ISNUMBER(J5))),"",IF(ABS(J5)<0.000001,"",(X5-J5)/ABS(J5))) | Z5: =IF(A5="","",IF(OR(U5="",NOT(ISNUMBER(X5))),"Sem meta / sem dado",IF(E5="Maior",IF(X5>=U5,"Cumpre","Não cumpre"),IF(X5<=U5,"Cumpre","Não cumpre")))) -> Não cumpre | AA5: SGA OBJ-01 (mesma intenção; SGE mede normalizado) | AB5: Medido (fatura) + variáveis medidas
