Workbook
Name DataRef: Listas!$A$3
Name lst_DataReferencia: Listas!$A$3:$A$3
Name lst_Escala13: Listas!$B$3:$B$5
Name lst_Fase: Listas!$D$3:$D$13
Name lst_Funcao: Listas!$C$3:$C$24
Name lst_ResultadoSim: Listas!$E$3:$E$6

Sheet 00_LEIA-ME
A1: RG-SGA-12 — Preparação e Resposta a Emergências Ambientais
A2: Sistema de Gestão Ambiental NP EN ISO 14001:2026 · Plasticom — Unidade 1 (Marinha Grande, Portugal) · Registo do SGA (fábrica simulada)
A4: CONTROLO DO DOCUMENTO (7.5 — informação documentada)
A5: Código do registo | B5: RG-SGA-12
A6: Título | B6: Preparação e Resposta a Emergências Ambientais
A7: Versão / Revisão | B7: 01
A8: Data de emissão | B8: 46387
A9: Elaborado por | B9: Gestor(a) do SGA / EHS
A10: Aprovado por | B10: Diretor Geral
A11: Estado | B11: Em vigor
A12: Retenção | B12: 5 anos após substituição
A13: Localização | B13: Repositório controlado do SGA > Registos_SGA_Plasticom (versão eletrónica é a versão controlada; cópias impressas são não controladas)
A15: FINALIDADE E ÂMBITO
A16: Finalidade | B16: Identificar os cenários de emergência ambiental credíveis, avaliá-los, definir prevenção, meios e resposta (instrução de trabalho passo a passo com tempos-alvo), inventariar os meios críticos e registar simulacros com tempos reais para avaliar a eficácia.
A17: Atividades do curso | B17: Atividade 4.5 — Definição de Cenário de Emergência e Resposta: cenário EMG-01 (derrame de produtos químicos), Instrução de Trabalho IT-SGA-01 rev. 01 e equipamento crítico (kit antipoluição).
A18: Requisitos ISO 14001:2026 | B18: 8.2 Preparação e resposta a emergências (alinhada com 6.1.2 — situações de emergência potenciais, ISO 14001:2026); 7.2; 7.4
A20: ESTRUTURA DO FICHEIRO
A21: Cenarios | B21: Cenários de emergência ambiental avaliados (P × G) com meios, IT e alerta de simulacro.
A22: IT_Passos | B22: Passos da IT-SGA-01 rev. 01 em formato de tabela (base da instrução impressa).
A23: Meios_Resposta | B23: Inventário de meios críticos de resposta e estado da última verificação.
A24: Simulacros | B24: Registo de simulacros com tempos medidos (eficácia da resposta).
A25: IT-SGA-01_Derrames | B25: Instrução de Trabalho IT-SGA-01 rev. 01 — Resposta a derrames de produtos químicos (formato de impressão/fórum).
A26: Listas | B26: Domínios (listas de valores) usados na validação de dados das tabelas.
A27: Dicionario_Dados | B27: Descrição de cada coluna de cada tabela: tipo, origem (entrada/calculado), domínio, obrigatoriedade e chaves.
A29: CONVENÇÕES (prontas para análise de dados e machine learning)
A30: Tabelas | B30: Cada registo é uma Tabela Excel com nome próprio (tbl_*): uma linha = um registo, cabeçalho único, sem células mescladas. Ler com pandas (pd.read_excel(ficheiro, sheet_name=folha, header=<linha do cabeçalho - 1>)) ou Power BI (Obter Dados > Tabela).
A31: Cabeçalho cinzento | B31: Coluna CALCULADA por fórmula — não escrever por cima. As restantes colunas são de entrada.
A32: Validação | B32: Colunas com lista controlada só aceitam valores da folha Listas (evita categorias duplicadas por grafia diferente).
A33: Chaves | B33: IDs estáveis e únicos (PK) e referências a IDs de outros registos (FK) permitem juntar tabelas entre ficheiros — ver SGA-00_Indice_Modelo_Dados.xlsx.
A34: Datas e unidades | B34: Datas em formato data (aaaa-mm-dd); números como números; a unidade está no nome da coluna ou no dicionário. Data de referência do SGA: 2026-12-31 (fecho do ano).
A35: Dados simulados | B35: Fábrica simulada Plasticom. Dados operacionais derivados do dataset do projeto (datasets/silver); dados ambientais e de conformidade são simulação didática — confirmar aplicabilidade legal e números antes de uso real.
A37: LIGAÇÕES A OUTROS REGISTOS
A38: RG-SGA-03 Aspetos | B38: Aspetos em condição de emergência (AA-005, AA-017, AA-034...).
A39: RG-SGA-07 NC | B39: NC-SGA-26-03 (kit) e NC-SGA-26-09 (simulacros) originaram a revisão 01 da IT-SGA-01.

Sheet Cenarios
A1: CENÁRIOS DE EMERGÊNCIA AMBIENTAL — PLASTICOM
A2: Criticidade = Probabilidade × Gravidade · Alerta calculado face à frequência de simulacro
A4: ID_Cenario | B4: Cenario | C4: Local | D4: Causas | E4: Impacte_Potencial | F4: IDs_Aspetos | G4: Probabilidade | H4: Gravidade | I4: Criticidade | J4: Prioridade | K4: Prevencao | L4: Meios_Resposta | M4: Instrucao_Trabalho | N4: Responsavel | O4: Comunicacao | P4: Freq_Simulacro | Q4: Ultimo_Simulacro | R4: Alerta | S4: Selecionado_Atv_4_5
A5: EMG-01 | B5: Derrame de produtos químicos (tintas, solventes, óleos) | C5: Armazém de químicos; serigrafia; oficina | D5: Queda na movimentação; rotura de embalagem; trasfega sem bacia | E5: Contaminação do solo e da água (rede pluvial → rio Lis); emissão de COV; resíduo perigoso | F5: AA-005; AA-017 | G5: 2 | H5: 3 | I5: =G5*H5 -> 6 | J5: =IF(I5>=6,"Alta",IF(I5>=3,"Média","Baixa")) -> Alta | K5: Bacias de retenção; recipientes fechados; kits selados; formação FOR-03 | L5: Kits antipoluição KIT-01 a KIT-05; tampões de sarjeta; EPI | M5: IT-SGA-01 | N5: Chefe de turno + Gestor do SGA | O5: Interna imediata; entidade gestora e APA se atingir a rede | P5: Semestral | Q5: =IFERROR(IF(_xlfn.MAXIFS(tbl_simulacros[Data],tbl_simulacros[ID_Cenario],A5,tbl_simulacros[Resultado],"<>Planeado")=0,"",_xlfn.MAXIFS(tbl_simulacros[Data],tbl_simulacros[ID_Cenario],A5,tbl_simulacros[Resultado],"<>Planeado")),"") -> 46352 | R5: =IF(P5="—","",IF(OR(Q5="",Q5=0),"Nunca testado",IF(DataRef-Q5>IF(P5="Semestral",183,365),"Simulacro em atraso","OK"))) -> OK | S5: Sim
A6: EMG-02 | B6: Incêndio no armazém de matérias-primas / granulado | C6: Armazém de MP e silos | D6: Curto-circuito; trabalho a quente; propagação de incêndio rural | E6: Fumos tóxicos; águas de combate contaminadas; dano à floresta envolvente | F6: AA-034 | G6: 1 | H6: 3 | I6: =G6*H6 -> 3 | J6: =IF(I6>=6,"Alta",IF(I6>=3,"Média","Baixa")) -> Média | K6: Deteção automática; SCIE; faixa de gestão de combustível; licença de trabalhos a quente | L6: Extintores; RIA; válvula de corte pluvial VC-01; bacia de retenção de águas de combate | M6: IT-SGA-02 | N6: Chefe de emergência | O6: 112 / bombeiros; ANEPC; vizinhos; APA | P6: Anual | Q6: =IFERROR(IF(_xlfn.MAXIFS(tbl_simulacros[Data],tbl_simulacros[ID_Cenario],A6,tbl_simulacros[Resultado],"<>Planeado")=0,"",_xlfn.MAXIFS(tbl_simulacros[Data],tbl_simulacros[ID_Cenario],A6,tbl_simulacros[Resultado],"<>Planeado")),"") -> 46367 | R6: =IF(P6="—","",IF(OR(Q6="",Q6=0),"Nunca testado",IF(DataRef-Q6>IF(P6="Semestral",183,365),"Simulacro em atraso","OK"))) -> OK | S6: Não
A7: EMG-03 | B7: Fuga de óleo hidráulico em máquina | C7: Injeção e sopro (ISBM-005) | D7: Mangueira envelhecida; vedante; sobrepressão | E7: Contaminação do solo; resíduo perigoso | F7: AA-009; AA-013 | G7: 2 | H7: 2 | I7: =G7*H7 -> 4 | J7: =IF(I7>=6,"Alta",IF(I7>=3,"Média","Baixa")) -> Média | K7: Manutenção por horas de operação; tabuleiros de retenção | L7: Absorventes; tabuleiro; kit KIT-02 | M7: IT-SGA-01 | N7: Técnico de Manutenção | O7: Interna | P7: Anual | Q7: =IFERROR(IF(_xlfn.MAXIFS(tbl_simulacros[Data],tbl_simulacros[ID_Cenario],A7,tbl_simulacros[Resultado],"<>Planeado")=0,"",_xlfn.MAXIFS(tbl_simulacros[Data],tbl_simulacros[ID_Cenario],A7,tbl_simulacros[Resultado],"<>Planeado")),"") | R7: =IF(P7="—","",IF(OR(Q7="",Q7=0),"Nunca testado",IF(DataRef-Q7>IF(P7="Semestral",183,365),"Simulacro em atraso","OK"))) -> Nunca testado | S7: Não
A8: EMG-04 | B8: Fuga de gás fluorado (chiller CH-01) | C8: Utilidades | D8: Corrosão; vibração; falha de brasagem | E8: Emissão de GEE (R410A, GWP 2088) | F8: AA-025 | G8: 1 | H8: 2 | I8: =G8*H8 -> 2 | J8: =IF(I8>=6,"Alta",IF(I8>=3,"Média","Baixa")) -> Baixa | K8: Controlo de fugas semestral por técnico certificado | L8: Detetor de fugas; contacto do técnico certificado | M8: — | N8: Gerente de Manutenção | O8: Interna; registo do equipamento | P8: — | Q8: =IFERROR(IF(_xlfn.MAXIFS(tbl_simulacros[Data],tbl_simulacros[ID_Cenario],A8,tbl_simulacros[Resultado],"<>Planeado")=0,"",_xlfn.MAXIFS(tbl_simulacros[Data],tbl_simulacros[ID_Cenario],A8,tbl_simulacros[Resultado],"<>Planeado")),"") | R8: =IF(P8="—","",IF(OR(Q8="",Q8=0),"Nunca testado",IF(DataRef-Q8>IF(P8="Semestral",183,365),"Simulacro em atraso","OK"))) | S8: Não
A9: EMG-05 | B9: Descarga anómala de efluente (biocida da torre) | C9: Torre de arrefecimento TR-01 | D9: Sobredosagem de biocida; purga descontrolada | E9: Contaminação do coletor e da ETAR municipal | F9: AA-024 | G9: 1 | H9: 2 | I9: =G9*H9 -> 2 | J9: =IF(I9>=6,"Alta",IF(I9>=3,"Média","Baixa")) -> Baixa | K9: Dosagem automática com alarme | L9: Válvula de fecho da purga; recipientes para amostra | M9: — | N9: Técnico de Utilidades | O9: Entidade gestora da drenagem | P9: Anual | Q9: =IFERROR(IF(_xlfn.MAXIFS(tbl_simulacros[Data],tbl_simulacros[ID_Cenario],A9,tbl_simulacros[Resultado],"<>Planeado")=0,"",_xlfn.MAXIFS(tbl_simulacros[Data],tbl_simulacros[ID_Cenario],A9,tbl_simulacros[Resultado],"<>Planeado")),"") | R9: =IF(P9="—","",IF(OR(Q9="",Q9=0),"Nunca testado",IF(DataRef-Q9>IF(P9="Semestral",183,365),"Simulacro em atraso","OK"))) -> Nunca testado | S9: Não
A10: EMG-06 | B10: Perda massiva de granulado (big bag rasgado no exterior) | C10: Zona de descarga de big bags | D10: Rasgo do big bag; manobra de empilhador | E10: Microplásticos na rede pluvial e no meio aquático | F10: AA-003 | G10: 2 | H10: 2 | I10: =G10*H10 -> 4 | J10: =IF(I10>=6,"Alta",IF(I10>=3,"Média","Baixa")) -> Média | K10: Tabuleiros de descarga; filtros de sarjeta | L10: Aspirador industrial; vassouras; tampões de sarjeta | M10: IT-SGA-01 | N10: Operador de Armazém / Empilhador | O10: Interna | P10: Anual | Q10: =IFERROR(IF(_xlfn.MAXIFS(tbl_simulacros[Data],tbl_simulacros[ID_Cenario],A10,tbl_simulacros[Resultado],"<>Planeado")=0,"",_xlfn.MAXIFS(tbl_simulacros[Data],tbl_simulacros[ID_Cenario],A10,tbl_simulacros[Resultado],"<>Planeado")),"") -> 46101 | R10: =IF(P10="—","",IF(OR(Q10="",Q10=0),"Nunca testado",IF(DataRef-Q10>IF(P10="Semestral",183,365),"Simulacro em atraso","OK"))) -> OK | S10: Não

Sheet IT_Passos
A1: ID_IT | B1: Passo | C1: Fase | D1: Acao | E1: Responsavel | F1: Tempo_Alvo_min | G1: Recurso
A2: IT-SGA-01 | B2: 1 | C2: 1. Alerta | D2: Dar o alerta: gritar 'DERRAME!' e avisar o chefe de turno (ext. 222). Se houver fogo, cheiro forte ou feridos, ligar 112 e ativar o alarme. | E2: Quem deteta | F2: 1 | G2: Telefone interno / botoneira
A3: IT-SGA-01 | B3: 2 | C3: 2. Proteção | D3: Afastar pessoas e fontes de ignição (parar máquinas próximas, não fumar, não usar telemóvel junto a solventes). Consultar a FDS do produto. | E3: Quem deteta + chefe de turno | F3: 2 | G3: FDS no ponto de uso
A4: IT-SGA-01 | B4: 3 | C4: 3. Proteção | D4: Vestir o EPI do kit: luvas nitrílicas, óculos, máscara se o produto for volátil. | E4: Equipa de 1.ª intervenção | F4: 2 | G4: EPI do kit antipoluição
A5: IT-SGA-01 | B5: 4 | C5: 4. Parar a fonte | D5: Se for seguro: levantar o recipiente, fechar a válvula ou colocar o recipiente danificado dentro de uma bacia. | E5: Equipa de 1.ª intervenção | F5: 3 | G5: Bacia de retenção móvel
A6: IT-SGA-01 | B6: 5 | C6: 5. Contenção | D6: Tapar as sarjetas e ralos próximos com o tampão do kit e rodear o derrame com as barreiras absorventes (do exterior para o interior). | E6: Equipa de 1.ª intervenção | F6: 5 | G6: Tampões de sarjeta; barreiras
A7: IT-SGA-01 | B7: 6 | C7: 6. Absorção | D7: Cobrir o líquido com almofadas/granulado absorvente até não haver líquido livre. Não usar água. | E7: Equipa de 1.ª intervenção | F7: 10 | G7: Almofadas e granulado absorvente
A8: IT-SGA-01 | B8: 7 | C8: 7. Recolha | D8: Recolher o absorvente com a pá antifaísca para o saco/contentor do kit; fechar e etiquetar como LER 15 02 02* (ou 08 03 12* para tinta). | E8: Equipa de 1.ª intervenção | F8: 20 | G8: Pá antifaísca; sacos; etiquetas LER
A9: IT-SGA-01 | B9: 8 | C9: 8. Encaminhamento | D9: Colocar o contentor no parque de resíduos perigosos (em bacia, fechado) e informar o Responsável de Armazém. | E9: Operador + Responsável de Armazém | F9: 30 | G9: Parque de resíduos perigosos
A10: IT-SGA-01 | B10: 9 | C10: 9. Comunicação | D10: Se o produto chegou à rede pluvial ou ao solo não impermeável: fechar a válvula de corte VC-01, avisar o Gestor do SGA, que comunica à entidade gestora/APA. | E10: Chefe de turno + Gestor do SGA | F10: 30 | G10: Válvula de corte VC-01; lista de contactos
A11: IT-SGA-01 | B11: 10 | C11: 10. Pós-uso (obrigatório) | D11: Registar o incidente (formulário INC), pedir a reposição do kit ao armazém e voltar a selar o kit com selo numerado. O kit nunca fica incompleto. | E11: Quem usou o kit + Responsável de Armazém | F11: 60 | G11: Formulário INC; stock mínimo de 2 kits; selos numerados
A12: IT-SGA-01 | B12: 11 | C12: 11. Investigação | D12: O Gestor do SGA investiga a causa (5 Porquês) e abre ação no PAM se necessário. | E12: Gestor do SGA | F12: 2880 | G12: RG-SGA-07 / RG-SGA-06

Sheet Meios_Resposta
A1: ID_Meio | B1: Descricao | C1: Localizacao | D1: ID_Cenario | E1: Ultima_Verificacao | F1: Estado | G1: Dias_desde_Verif | H1: Alerta
A2: KIT-01 | B2: Kit antipoluição 120 L | C2: Armazém de químicos | D2: EMG-01 | E2: 46370 | F2: Completo e selado (selo 00412) | G2: =DataRef-E2 -> 17 | H2: =IF(G2>31,"Verificar","OK") -> OK
A3: KIT-02 | B3: Kit antipoluição 60 L | C3: Oficina de manutenção | D3: EMG-03 | E3: 46370 | F3: Completo e selado (selo 00413) | G3: =DataRef-E3 -> 17 | H3: =IF(G3>31,"Verificar","OK") -> OK
A4: KIT-03 | B4: Kit antipoluição 60 L | C4: Zona injeção/serigrafia | D4: EMG-01 | E4: 46370 | F4: Completo e selado (selo 00447); verificação mensal com registo pós-uso (IT-SGA-01 rev. 01) | G4: =DataRef-E4 -> 17 | H4: =IF(G4>31,"Verificar","OK") -> OK
A5: KIT-04 | B5: Kit antipoluição 60 L | C5: Serigrafia SS-002 | D5: EMG-01 | E5: 46370 | F5: Completo e selado (selo 00415) | G5: =DataRef-E5 -> 17 | H5: =IF(G5>31,"Verificar","OK") -> OK
A6: KIT-05 | B6: Kit antipoluição 60 L | C6: Parque de resíduos | D6: EMG-01 | E6: 46370 | F6: Completo e selado (selo 00416) | G6: =DataRef-E6 -> 17 | H6: =IF(G6>31,"Verificar","OK") -> OK
A7: VC-01 | B7: Válvula de corte da rede pluvial | C7: Caixa de saída pluvial (portão sul) | D7: EMG-02 | E7: 46367 | F7: Operacional; manobra em 4 min no simulacro de 11/12/2026 | G7: =DataRef-E7 -> 20 | H7: =IF(G7>31,"Verificar","OK") -> OK
A8: BR-01 | B8: Bacia de retenção de águas de combate (300 m³) | C8: Logradouro sul | D8: EMG-02 | E8: 46367 | F8: Seca e limpa | G8: =DataRef-E8 -> 20 | H8: =IF(G8>31,"Verificar","OK") -> OK
A9: TMP-01 | B9: Tampões de sarjeta magnéticos (6 un.) | C9: Armazém de químicos / kits | D9: EMG-01 | E9: 46370 | F9: Em bom estado | G9: =DataRef-E9 -> 17 | H9: =IF(G9>31,"Verificar","OK") -> OK

Sheet Simulacros
A1: ID_Simulacro | B1: Data | C1: ID_Cenario | D1: Descricao | E1: Participantes | F1: Tempo_Evacuacao_min | G1: Tempo_Contencao_min | H1: Licoes_Aprendidas | I1: Resultado | J1: ID_PAM
A2: SIM-2025-01 | B2: 45975 | C2: EMG-02 | D2: Incêndio no armazém de MP | E2: 48 | F2: 6 | G2: 9 | H2: Evacuação em 6 min (meta ≤ 8 min). Válvula de corte fechada em 9 min (meta ≤ 5 min): chave guardada na portaria. | I2: Parcialmente eficaz | J2: PAM-26-21
A3: SIM-2026-01 | B3: 46101 | C3: EMG-06 | D3: Big bag rasgado na zona de descarga | E3: 6 | G3: 25 | H3: Granulado recolhido em 25 min; 1 sarjeta sem filtro. | I3: Parcialmente eficaz | J3: PAM-26-11
A4: SIM-2026-02 | B4: 46352 | C4: EMG-01 | D4: Derrame de 20 L de solvente no armazém de químicos | E4: 14 | G4: 7 | H4: Contenção com o KIT-01 em 7 min (meta ≤ 10 min); tampões de sarjeta colocados; registo pós-uso da IT-SGA-01 rev. 01 cumprido. | I4: Eficaz | J4: PAM-26-21
A5: SIM-2026-03 | B5: 46367 | C5: EMG-02 | D5: Incêndio no armazém de MP com retenção das águas de combate | E5: 52 | F5: 5 | G5: 4 | H5: Evacuação em 5 min; VC-01 fechada em 4 min (meta ≤ 5 min) com a chave na caixa junto à portaria; BR-01 disponível. | I5: Eficaz | J5: PAM-26-21

Sheet IT-SGA-01_Derrames
A1: PLASTICOM | B1: INSTRUÇÃO DE TRABALHO — RESPOSTA A DERRAMES DE PRODUTOS QUÍMICOS | F1: IT-SGA-01 rev. 01
B2: Plasticom — Unidade 1 (Marinha Grande, Portugal) · NP EN ISO 14001:2026 | F2: Rev. 01 · 31/12/2026
A5: Objetivo | C5: Conter, recolher e comunicar qualquer derrame de tinta, solvente, óleo ou outro químico, evitando que chegue ao solo, à rede pluvial ou ao rio Lis.
A6: Âmbito | C6: Armazém de químicos, serigrafia, hot foil, oficina de manutenção, injeção, sopro e parque de resíduos. Derrames até ≈ 200 L; acima disso ou com fogo: ativar o Plano de Emergência Interno (112).
A7: Cenário | C7: EMG-01 — Derrame de produtos químicos (aspetos AA-005 e AA-017, condição de EMERGÊNCIA).
A8: Equipamento crítico | C8: KIT ANTIPOLUIÇÃO (selado): 12 almofadas absorventes, 2 barreiras, granulado absorvente, tampão de sarjeta, pá antifaísca, sacos e etiquetas LER, luvas nitrílicas, óculos, máscara, esta instrução. Localização: KIT-01 a KIT-05 (ver planta).
A9: Alteração rev. 01 | C9: Acrescentado o passo 10 (pós-uso obrigatório: registar, repor, selar) e a verificação semanal do selo e conteúdo — resposta à NC-SGA-26-03.
A11: Passo | B11: Fase | C11: O que fazer | D11: Quem | E11: Até (min) | F11: Recurso
A12: =INDEX(IT_Passos!$B$2:$B$12,1) -> 1 | B12: =INDEX(IT_Passos!$C$2:$C$12,1) -> 1. Alerta | C12: =INDEX(IT_Passos!$D$2:$D$12,1) -> Dar o alerta: gritar 'DERRAME!' e avisar o chefe de turno (ext. 222). Se houver fogo, cheiro forte ou feridos, ligar 112 e ativar o alarme. | D12: =INDEX(IT_Passos!$E$2:$E$12,1) -> Quem deteta | E12: =INDEX(IT_Passos!$F$2:$F$12,1) -> 1 | F12: =INDEX(IT_Passos!$G$2:$G$12,1) -> Telefone interno / botoneira
A13: =INDEX(IT_Passos!$B$2:$B$12,2) -> 2 | B13: =INDEX(IT_Passos!$C$2:$C$12,2) -> 2. Proteção | C13: =INDEX(IT_Passos!$D$2:$D$12,2) -> Afastar pessoas e fontes de ignição (parar máquinas próximas, não fumar, não usar telemóvel junto a solventes). Consultar a FDS do produto. | D13: =INDEX(IT_Passos!$E$2:$E$12,2) -> Quem deteta + chefe de turno | E13: =INDEX(IT_Passos!$F$2:$F$12,2) -> 2 | F13: =INDEX(IT_Passos!$G$2:$G$12,2) -> FDS no ponto de uso
A14: =INDEX(IT_Passos!$B$2:$B$12,3) -> 3 | B14: =INDEX(IT_Passos!$C$2:$C$12,3) -> 3. Proteção | C14: =INDEX(IT_Passos!$D$2:$D$12,3) -> Vestir o EPI do kit: luvas nitrílicas, óculos, máscara se o produto for volátil. | D14: =INDEX(IT_Passos!$E$2:$E$12,3) -> Equipa de 1.ª intervenção | E14: =INDEX(IT_Passos!$F$2:$F$12,3) -> 2 | F14: =INDEX(IT_Passos!$G$2:$G$12,3) -> EPI do kit antipoluição
A15: =INDEX(IT_Passos!$B$2:$B$12,4) -> 4 | B15: =INDEX(IT_Passos!$C$2:$C$12,4) -> 4. Parar a fonte | C15: =INDEX(IT_Passos!$D$2:$D$12,4) -> Se for seguro: levantar o recipiente, fechar a válvula ou colocar o recipiente danificado dentro de uma bacia. | D15: =INDEX(IT_Passos!$E$2:$E$12,4) -> Equipa de 1.ª intervenção | E15: =INDEX(IT_Passos!$F$2:$F$12,4) -> 3 | F15: =INDEX(IT_Passos!$G$2:$G$12,4) -> Bacia de retenção móvel
A16: =INDEX(IT_Passos!$B$2:$B$12,5) -> 5 | B16: =INDEX(IT_Passos!$C$2:$C$12,5) -> 5. Contenção | C16: =INDEX(IT_Passos!$D$2:$D$12,5) -> Tapar as sarjetas e ralos próximos com o tampão do kit e rodear o derrame com as barreiras absorventes (do exterior para o interior). | D16: =INDEX(IT_Passos!$E$2:$E$12,5) -> Equipa de 1.ª intervenção | E16: =INDEX(IT_Passos!$F$2:$F$12,5) -> 5 | F16: =INDEX(IT_Passos!$G$2:$G$12,5) -> Tampões de sarjeta; barreiras
A17: =INDEX(IT_Passos!$B$2:$B$12,6) -> 6 | B17: =INDEX(IT_Passos!$C$2:$C$12,6) -> 6. Absorção | C17: =INDEX(IT_Passos!$D$2:$D$12,6) -> Cobrir o líquido com almofadas/granulado absorvente até não haver líquido livre. Não usar água. | D17: =INDEX(IT_Passos!$E$2:$E$12,6) -> Equipa de 1.ª intervenção | E17: =INDEX(IT_Passos!$F$2:$F$12,6) -> 10 | F17: =INDEX(IT_Passos!$G$2:$G$12,6) -> Almofadas e granulado absorvente
A18: =INDEX(IT_Passos!$B$2:$B$12,7) -> 7 | B18: =INDEX(IT_Passos!$C$2:$C$12,7) -> 7. Recolha | C18: =INDEX(IT_Passos!$D$2:$D$12,7) -> Recolher o absorvente com a pá antifaísca para o saco/contentor do kit; fechar e etiquetar como LER 15 02 02* (ou 08 03 12* para tinta). | D18: =INDEX(IT_Passos!$E$2:$E$12,7) -> Equipa de 1.ª intervenção | E18: =INDEX(IT_Passos!$F$2:$F$12,7) -> 20 | F18: =INDEX(IT_Passos!$G$2:$G$12,7) -> Pá antifaísca; sacos; etiquetas LER
A19: =INDEX(IT_Passos!$B$2:$B$12,8) -> 8 | B19: =INDEX(IT_Passos!$C$2:$C$12,8) -> 8. Encaminhamento | C19: =INDEX(IT_Passos!$D$2:$D$12,8) -> Colocar o contentor no parque de resíduos perigosos (em bacia, fechado) e informar o Responsável de Armazém. | D19: =INDEX(IT_Passos!$E$2:$E$12,8) -> Operador + Responsável de Armazém | E19: =INDEX(IT_Passos!$F$2:$F$12,8) -> 30 | F19: =INDEX(IT_Passos!$G$2:$G$12,8) -> Parque de resíduos perigosos
A20: =INDEX(IT_Passos!$B$2:$B$12,9) -> 9 | B20: =INDEX(IT_Passos!$C$2:$C$12,9) -> 9. Comunicação | C20: =INDEX(IT_Passos!$D$2:$D$12,9) -> Se o produto chegou à rede pluvial ou ao solo não impermeável: fechar a válvula de corte VC-01, avisar o Gestor do SGA, que comunica à entidade gestora/APA. | D20: =INDEX(IT_Passos!$E$2:$E$12,9) -> Chefe de turno + Gestor do SGA | E20: =INDEX(IT_Passos!$F$2:$F$12,9) -> 30 | F20: =INDEX(IT_Passos!$G$2:$G$12,9) -> Válvula de corte VC-01; lista de contactos
A21: =INDEX(IT_Passos!$B$2:$B$12,10) -> 10 | B21: =INDEX(IT_Passos!$C$2:$C$12,10) -> 10. Pós-uso (obrigatório) | C21: =INDEX(IT_Passos!$D$2:$D$12,10) -> Registar o incidente (formulário INC), pedir a reposição do kit ao armazém e voltar a selar o kit com selo numerado. O kit nunca fica incompleto. | D21: =INDEX(IT_Passos!$E$2:$E$12,10) -> Quem usou o kit + Responsável de Armazém | E21: =INDEX(IT_Passos!$F$2:$F$12,10) -> 60 | F21: =INDEX(IT_Passos!$G$2:$G$12,10) -> Formulário INC; stock mínimo de 2 kits; selos numerados
A22: =INDEX(IT_Passos!$B$2:$B$12,11) -> 11 | B22: =INDEX(IT_Passos!$C$2:$C$12,11) -> 11. Investigação | C22: =INDEX(IT_Passos!$D$2:$D$12,11) -> O Gestor do SGA investiga a causa (5 Porquês) e abre ação no PAM se necessário. | D22: =INDEX(IT_Passos!$E$2:$E$12,11) -> Gestor do SGA | E22: =INDEX(IT_Passos!$F$2:$F$12,11) -> 2880 | F22: =INDEX(IT_Passos!$G$2:$G$12,11) -> RG-SGA-07 / RG-SGA-06
A24: NUNCA | C24: Lavar o derrame com água para a sarjeta · deixar o kit incompleto ou sem selo · misturar absorventes contaminados com lixo comum.
A25: Contactos | C25: Chefe de turno ext. 222 · Gestor do SGA 912 000 101 · Portaria (válvula de corte VC-01) ext. 200 · Emergência 112.
A26: Aprovação | C26: Elaborado: Gestor do SGA/EHS · Aprovado: Diretor Industrial · Data: 23/09/2026 · Substitui: rev. 00 (24/05/2024)

Sheet Listas
A1: LISTAS CONTROLADAS (domínios de validação de dados) — editar aqui para alterar opções
A2: DataReferencia | B2: Escala13 | C2: Funcao | D2: Fase | E2: ResultadoSim
A3: 46387 | B3: 1 | C3: Diretor Geral (Gestão de Topo) | D3: 1. Alerta | E3: Eficaz
B4: 2 | C4: Diretor Industrial | D4: 2. Proteção | E4: Parcialmente eficaz
B5: 3 | C5: Gestor do SGA / EHS (Responsável Ambiental) | D5: 3. Proteção | E5: Não eficaz
C6: Gerente de Produção | D6: 4. Parar a fonte | E6: Planeado
C7: Gerente de Manutenção | D7: 5. Contenção
C8: Gerente da Qualidade | D8: 6. Absorção
C9: Responsável de Armazém e Logística | D9: 7. Recolha
C10: Responsável de Compras | D10: 8. Encaminhamento
C11: Responsável de R&D | D11: 9. Comunicação
C12: Responsável de Recursos Humanos | D12: 10. Pós-uso (obrigatório)
C13: Diretor Financeiro | D13: 11. Investigação
C14: Operador de Serigrafia
C15: Operador de Injeção
C16: Operador de Sopro (ISBM)
C17: Operador de Hot Foil
C18: Técnico de Manutenção
C19: Técnico de Utilidades
C20: Operador de Armazém / Empilhador
C21: Chefe de Turno
C22: Auditor Interno do SGA
C23: Representante dos Trabalhadores (SST/Ambiente)
C24: Técnico de Qualidade/Ambiente

Sheet Dicionario_Dados
A1: Folha | B1: Tabela | C1: Coluna | D1: Tipo | E1: Origem | F1: Descricao | G1: Dominio_Unidade | H1: Obrigatorio | I1: Chave
A2: Cenarios | B2: tbl_cenarios | C2: ID_Cenario | D2: Texto | E2: Entrada | F2: Cenário. | H2: Sim | I2: PK
A3: Cenarios | B3: tbl_cenarios | C3: Cenario | D3: Texto | E3: Entrada | F3: Cenário de emergência. | H3: Sim
A4: Cenarios | B4: tbl_cenarios | C4: Local | D4: Texto | E4: Entrada | F4: Onde. | H4: Sim
A5: Cenarios | B5: tbl_cenarios | C5: Causas | D5: Texto | E5: Entrada | F5: Causas prováveis. | H5: Sim
A6: Cenarios | B6: tbl_cenarios | C6: Impacte_Potencial | D6: Texto | E6: Entrada | F6: Impacte ambiental potencial. | H6: Sim
A7: Cenarios | B7: tbl_cenarios | C7: IDs_Aspetos | D7: Texto | E7: Entrada | F7: Aspetos associados. | H7: Sim | I7: FK → RG-SGA-03
A8: Cenarios | B8: tbl_cenarios | C8: Probabilidade | D8: Inteiro | E8: Entrada | F8: 1 remota – 3 frequente. | G8: Lista lst_Escala13 | H8: Sim
A9: Cenarios | B9: tbl_cenarios | C9: Gravidade | D9: Inteiro | E9: Entrada | F9: 1 local/contida – 3 externa/grave. | G9: Lista lst_Escala13 | H9: Sim
A10: Cenarios | B10: tbl_cenarios | C10: Criticidade | D10: Inteiro | E10: Calculado (fórmula) | F10: P × G (1-9). | H10: Sim
A11: Cenarios | B11: tbl_cenarios | C11: Prioridade | D11: Texto | E11: Calculado (fórmula) | F11: Prioridade do cenário. | H11: Sim
A12: Cenarios | B12: tbl_cenarios | C12: Prevencao | D12: Texto | E12: Entrada | F12: Medidas preventivas. | H12: Sim
A13: Cenarios | B13: tbl_cenarios | C13: Meios_Resposta | D13: Texto | E13: Entrada | F13: Meios de resposta. | H13: Sim
A14: Cenarios | B14: tbl_cenarios | C14: Instrucao_Trabalho | D14: Texto | E14: Entrada | F14: IT aplicável. | H14: Sim
A15: Cenarios | B15: tbl_cenarios | C15: Responsavel | D15: Texto | E15: Entrada | F15: Quem coordena. | H15: Sim
A16: Cenarios | B16: tbl_cenarios | C16: Comunicacao | D16: Texto | E16: Entrada | F16: A quem comunicar. | H16: Sim
A17: Cenarios | B17: tbl_cenarios | C17: Freq_Simulacro | D17: Texto | E17: Entrada | F17: Frequência de simulacro. | H17: Sim
A18: Cenarios | B18: tbl_cenarios | C18: Ultimo_Simulacro | D18: Data (aaaa-mm-dd) | E18: Calculado (fórmula) | F18: Data do último simulacro realizado. | H18: Sim
A19: Cenarios | B19: tbl_cenarios | C19: Alerta | D19: Texto | E19: Calculado (fórmula) | F19: Alerta de teste periódico (8.2). | H19: Sim
A20: Cenarios | B20: tbl_cenarios | C20: Selecionado_Atv_4_5 | D20: Texto | E20: Entrada | F20: Cenário da Atividade 4.5. | H20: Sim
A21: IT_Passos | B21: tbl_it_passos | C21: ID_IT | D21: Texto | E21: Entrada | F21: Instrução de trabalho. | H21: Sim | I21: FK
A22: IT_Passos | B22: tbl_it_passos | C22: Passo | D22: Inteiro | E22: Entrada | F22: N.º do passo. | H22: Sim
A23: IT_Passos | B23: tbl_it_passos | C23: Fase | D23: Texto | E23: Entrada | F23: Fase da resposta. | G23: Lista lst_Fase | H23: Sim
A24: IT_Passos | B24: tbl_it_passos | C24: Acao | D24: Texto | E24: Entrada | F24: O que fazer. | H24: Sim
A25: IT_Passos | B25: tbl_it_passos | C25: Responsavel | D25: Texto | E25: Entrada | F25: Quem. | H25: Sim
A26: IT_Passos | B26: tbl_it_passos | C26: Tempo_Alvo_min | D26: Inteiro | E26: Entrada | F26: Tempo-alvo acumulado desde o alerta (min). | H26: Sim
A27: IT_Passos | B27: tbl_it_passos | C27: Recurso | D27: Texto | E27: Entrada | F27: Equipamento/material necessário. | H27: Sim
A28: Meios_Resposta | B28: tbl_meios | C28: ID_Meio | D28: Texto | E28: Entrada | F28: Meio de resposta. | H28: Sim | I28: PK
A29: Meios_Resposta | B29: tbl_meios | C29: Descricao | D29: Texto | E29: Entrada | F29: Equipamento. | H29: Sim
A30: Meios_Resposta | B30: tbl_meios | C30: Localizacao | D30: Texto | E30: Entrada | F30: Onde está. | H30: Sim
A31: Meios_Resposta | B31: tbl_meios | C31: ID_Cenario | D31: Texto | E31: Entrada | F31: Cenário. | H31: Sim | I31: FK → tbl_cenarios
A32: Meios_Resposta | B32: tbl_meios | C32: Ultima_Verificacao | D32: Data (aaaa-mm-dd) | E32: Entrada | F32: Última verificação (ronda). | H32: Sim
A33: Meios_Resposta | B33: tbl_meios | C33: Estado | D33: Texto | E33: Entrada | F33: Estado na última verificação. | H33: Sim
A34: Meios_Resposta | B34: tbl_meios | C34: Dias_desde_Verif | D34: Inteiro | E34: Calculado (fórmula) | F34: Dias desde a verificação. | H34: Sim
A35: Meios_Resposta | B35: tbl_meios | C35: Alerta | D35: Texto | E35: Calculado (fórmula) | F35: Verificação mensal no mínimo. | H35: Sim
A36: Simulacros | B36: tbl_simulacros | C36: ID_Simulacro | D36: Texto | E36: Entrada | F36: Simulacro. | H36: Sim | I36: PK
A37: Simulacros | B37: tbl_simulacros | C37: Data | D37: Data (aaaa-mm-dd) | E37: Entrada | F37: Data. | H37: Sim
A38: Simulacros | B38: tbl_simulacros | C38: ID_Cenario | D38: Texto | E38: Entrada | F38: Cenário. | H38: Sim | I38: FK → tbl_cenarios
A39: Simulacros | B39: tbl_simulacros | C39: Descricao | D39: Texto | E39: Entrada | F39: Situação simulada. | H39: Sim
A40: Simulacros | B40: tbl_simulacros | C40: Participantes | D40: Inteiro | E40: Entrada | F40: N.º participantes. | H40: Não
...
