Workbook
Name DataRef: Listas!$A$3
Name lst_DataReferencia: Listas!$A$3:$A$3
Name lst_Estado: Listas!$H$3:$H$7
Name lst_Frequencia: Listas!$F$3:$F$7
Name lst_Funcao: Listas!$I$3:$I$24
Name lst_MetaTipo: Listas!$G$3:$G$5
Name lst_OrigemTipo: Listas!$C$3:$C$8
Name lst_Polaridade: Listas!$D$3:$D$5
Name lst_Politica: Listas!$B$3:$B$9
Name lst_SimNao: Listas!$J$3:$J$4
Name lst_TipoISO14031: Listas!$E$3:$E$5

Sheet 00_LEIA-ME
A1: RG-SGA-05 — Objetivos Ambientais, Metas e Indicadores (KPI)
A2: Sistema de Gestão Ambiental NP EN ISO 14001:2026 · Plasticom — Unidade 1 (Marinha Grande, Portugal) · Registo do SGA (fábrica simulada)
A4: CONTROLO DO DOCUMENTO (7.5 — informação documentada)
A5: Código do registo | B5: RG-SGA-05
A6: Título | B6: Objetivos Ambientais, Metas e Indicadores (KPI)
A7: Versão / Revisão | B7: 01
A8: Data de emissão | B8: 46387
A9: Elaborado por | B9: Gestor(a) do SGA / EHS
A10: Aprovado por | B10: Diretor Geral
A11: Estado | B11: Em vigor
A12: Retenção | B12: 5 anos após substituição
A13: Localização | B13: Repositório controlado do SGA > Registos_SGA_Plasticom (versão eletrónica é a versão controlada; cópias impressas são não controladas)
A15: FINALIDADE E ÂMBITO
A16: Finalidade | B16: Transformar aspetos significativos, riscos e requisitos legais em objetivos SMART, com indicador (a 'régua'), baseline medida, meta numérica, prazo, recursos e responsável; acompanhar a trajetória até à meta. O catálogo de KPI segue a tipologia da ISO 14031 (indicadores de desempenho operacional, de gestão e de condição ambiental).
A17: Atividades do curso | B17: Atividade 3.4 — Planeamento de Objetivos Ambientais e Definição de KPIs (objetivos SMART OBJ-01 a OBJ-06; ficha da atividade com OBJ-01, OBJ-03 e OBJ-04).
A18: Requisitos ISO 14001:2026 | B18: 6.2.1 Objetivos ambientais; 6.2.2 Planeamento de ações para atingir os objetivos; 9.1.1 (indicadores); 5.2 (ligação à política)
A20: ESTRUTURA DO FICHEIRO
A21: Politica | B21: Compromissos da Política Ambiental (5.2) que dão origem aos objetivos.
A22: Catalogo_KPI | B22: Catálogo de indicadores ambientais (definição operacional de cada 'régua').
A23: Objetivos_SMART | B23: Registo de objetivos ambientais SMART (1 linha por objetivo) com validação automática SMART e progresso.
A24: Acompanhamento_Mensal | B24: Série mensal dos KPI dos objetivos (formato longo) com desvio, média móvel e sinal — base para gráficos e previsão.
A25: Resumo_Atividade_3_4 | B25: Ficha da Atividade 3.4 com os campos do enunciado para OBJ-01, OBJ-03 e OBJ-04 (calculada).
A26: Listas | B26: Domínios (listas de valores) usados na validação de dados das tabelas.
A27: Dicionario_Dados | B27: Descrição de cada coluna de cada tabela: tipo, origem (entrada/calculado), domínio, obrigatoriedade e chaves.
A29: CONVENÇÕES (prontas para análise de dados e machine learning)
A30: Tabelas | B30: Cada registo é uma Tabela Excel com nome próprio (tbl_*): uma linha = um registo, cabeçalho único, sem células mescladas. Ler com pandas (pd.read_excel(ficheiro, sheet_name=folha, header=<linha do cabeçalho - 1>)) ou Power BI (Obter Dados > Tabela).
A31: Cabeçalho cinzento | B31: Coluna CALCULADA por fórmula — não escrever por cima. As restantes colunas são de entrada.
A32: Validação | B32: Colunas com lista controlada só aceitam valores da folha Listas (evita categorias duplicadas por grafia diferente).
A33: Chaves | B33: IDs estáveis e únicos (PK) e referências a IDs de outros registos (FK) permitem juntar tabelas entre ficheiros — ver SGA-00_Indice_Modelo_Dados.xlsx.
A34: Datas e unidades | B34: Datas em formato data (aaaa-mm-dd); números como números; a unidade está no nome da coluna ou no dicionário. Data de referência do SGA: 2026-12-31 (fecho do ano).
A35: Dados simulados | B35: Fábrica simulada Plasticom. Dados operacionais derivados do dataset do projeto (datasets/silver); dados ambientais e de conformidade são simulação didática — confirmar aplicabilidade legal e números antes de uso real.
A37: LIGAÇÕES A OUTROS REGISTOS
A38: RG-SGA-02 / RG-SGA-03 / RG-SGA-04 | B38: Origem_IDs aponta para riscos (RO), aspetos (AA) e requisitos legais (LEG).
A39: RG-SGA-06 PAM | B39: Acoes_PAM lista as ações do programa para atingir cada objetivo.
A40: RG-SGA-13 Monitorização | B40: Baselines calculadas com os dados mensais do RG-SGA-13 (set/2025–ago/2026).

Sheet Politica
A1: ID_Politica | B1: Compromisso | C1: N_Objetivos
A2: POL-01 | B2: Proteger o ambiente e prevenir a poluição, incluindo a perda de granulado de plástico e os derrames de produtos químicos. | C2: =COUNTIF(tbl_objetivos[ID_Politica],A2) -> 1
A3: POL-02 | B3: Cumprir (meet) as obrigações de conformidade legais e os requisitos ambientais assumidos com clientes. | C3: =COUNTIF(tbl_objetivos[ID_Politica],A3) -> 1
A4: POL-03 | B4: Usar de forma eficiente a energia, a água e os materiais e reduzir as emissões de gases com efeito de estufa. | C4: =COUNTIF(tbl_objetivos[ID_Politica],A4) -> 2
A5: POL-04 | B5: Aplicar a perspetiva de ciclo de vida: embalagens concebidas para a reciclagem, com conteúdo reciclado e menos material. | C5: =COUNTIF(tbl_objetivos[ID_Politica],A5) -> 2
A6: POL-05 | B6: Melhorar continuamente o SGA e o desempenho ambiental, com decisões baseadas em dados. | C6: =COUNTIF(tbl_objetivos[ID_Politica],A6) -> 0
A7: POL-06 | B7: Proteger a biodiversidade e a saúde dos ecossistemas envolventes (Pinhal de Leiria, rio Lis, costa). | C7: =COUNTIF(tbl_objetivos[ID_Politica],A7) -> 1
A8: POL-07 | B8: Envolver trabalhadores, fornecedores e clientes na melhoria ambiental. | C8: =COUNTIF(tbl_objetivos[ID_Politica],A8) -> 0

Sheet Catalogo_KPI
A1: ID_KPI | B1: Nome | C1: Formula_Calculo | D1: Unidade | E1: Polaridade | F1: Tipo_ISO14031 | G1: Frequencia | H1: Fonte_Dados | I1: Responsavel | J1: Baseline | K1: ID_OBJ | L1: ID_MED
A2: KPI-01 | B2: Intensidade energética | C2: Eletricidade total (kWh) ÷ unidades produzidas em injeção + sopro (milhares) | D2: kWh/1.000 un | E2: Menor é melhor | F2: ODI — desempenho operacional | G2: Mensal | H2: Fatura + dataset de produção | I2: Gerente de Manutenção | J2: 110.4918 | K2: OBJ-01 | L2: MED-01
A3: KPI-02 | B3: Intensidade hídrica | C3: Água de rede (m³) ÷ unidades produzidas (milhares) | D3: m³/1.000 un | E3: Menor é melhor | F3: ODI — desempenho operacional | G3: Mensal | H3: Fatura da água + produção | I3: Gerente de Manutenção | J3: 0.1429 | K3: OBJ-05 | L3: MED-08
A4: KPI-03 | B4: Intensidade de scrap | C4: Scrap gerado (kg) ÷ unidades produzidas (milhares) | D4: kg/1.000 un | E4: Menor é melhor | F4: ODI — desempenho operacional | G4: Mensal | H4: Pesagens + produção | I4: Gerente de Produção | J4: 0.4812 | K4: OBJ-02 | L4: MED-03
A5: KPI-04 | B5: Taxa de reintegração de scrap | C5: Scrap reintegrado (kg) ÷ scrap gerado (kg) | D5: % | E5: Maior é melhor | F5: ODI — desempenho operacional | G5: Mensal | H5: Pesagens nos moinhos | I5: Gerente de Produção | K5: OBJ-02 | L5: MED-03
A6: KPI-05 | B6: Taxa de valorização de resíduos | C6: Resíduos com operação R (kg) ÷ resíduos totais (kg) | D6: % | E6: Maior é melhor | F6: ODI — desempenho operacional | G6: Mensal | H6: e-GAR / pesagens | I6: Gestor do SGA / EHS (Responsável Ambiental) | L6: MED-04
A7: KPI-06 | B7: Solvente de limpeza na serigrafia | C7: Solvente consumido (kg) ÷ peças serigrafadas (milhares) | D7: kg/1.000 peças | E7: Menor é melhor | F7: ODI — desempenho operacional | G7: Mensal | H7: Inventário de solvente + produção SER | I7: Gestor do SGA / EHS (Responsável Ambiental) | J7: 0.1605 | K7: OBJ-03 | L7: MED-06
A8: KPI-07 | B8: Resíduos perigosos | C8: Soma dos resíduos com código LER * (kg) | D8: kg/mês | E8: Menor é melhor | F8: ODI — desempenho operacional | G8: Mensal | H8: Pesagens / e-GAR | I8: Gestor do SGA / EHS (Responsável Ambiental) | L8: MED-04
A9: KPI-08 | B9: Emissões GEE do âmbito 2 | C9: kWh × fator de emissão da rede | D9: tCO2e | E9: Menor é melhor | F9: ODI — desempenho operacional | G9: Mensal | H9: RG-SGA-13 Indicadores_Mensais (kWh) × FE-01 do RG-SGA-19; total anual oficial no RG-SGA-19 tbl_inventario_gee | I9: Gestor do SGA / EHS (Responsável Ambiental) | K9: OBJ-01 | L9: MED-01
A10: KPI-09 | B10: Quota de energia renovável | C10: kWh renováveis ÷ kWh totais | D10: % | E10: Maior é melhor | F10: ODI — desempenho operacional | G10: Anual | H10: Rótulo de energia | I10: Diretor Financeiro | J10: 0.55 | L10: MED-01
A11: KPI-10 | B11: Conformidade das rondas ambientais | C11: Pontos conformes ÷ pontos verificados | D11: % | E11: Maior é melhor | F11: MPI — desempenho de gestão | G11: Mensal | H11: RG-SGA-10 | I11: Gestor do SGA / EHS (Responsável Ambiental) | L11: MED-10
A12: KPI-11 | B12: Incidentes ambientais | C12: N.º de derrames, fugas e perdas de contenção registados | D12: n.º/mês | E12: Zero é o alvo | F12: MPI — desempenho de gestão | G12: Mensal | H12: Registo de incidentes | I12: Gestor do SGA / EHS (Responsável Ambiental) | L12: MED-10
A13: KPI-12 | B13: Famílias com conformidade PPWR | C13: Famílias com documentação técnica e declaração UE ÷ total de famílias | D13: % | E13: Maior é melhor | F13: MPI — desempenho de gestão | G13: Mensal | H13: Dossier de produto | I13: Responsável de R&D | J13: 0.4091 | K13: OBJ-04 | L13: MED-12
A14: KPI-13 | B14: Pontos críticos de granulado com contenção | C14: Pontos com contenção ÷ pontos críticos (14) | D14: % | E14: Maior é melhor | F14: MPI — desempenho de gestão | G14: Mensal | H14: Autoavaliação OCS | I14: Gestor do SGA / EHS (Responsável Ambiental) | J14: 0.4286 | K14: OBJ-06 | L14: MED-09
A15: KPI-14 | B15: Taxa de conformidade legal | C15: Requisitos conformes ÷ requisitos aplicáveis | D15: % | E15: Maior é melhor | F15: MPI — desempenho de gestão | G15: Anual | H15: RG-SGA-04 | I15: Gestor do SGA / EHS (Responsável Ambiental)
A16: KPI-15 | B16: Ações do PAM no prazo | C16: Ações concluídas no prazo ÷ ações com prazo vencido | D16: % | E16: Maior é melhor | F16: MPI — desempenho de gestão | G16: Mensal | H16: RG-SGA-06 | I16: Gestor do SGA / EHS (Responsável Ambiental)
A17: KPI-17 | B17: SKUs com avaliação de reciclabilidade | C17: SKUs de frascos e potes com autoavaliação RecyClass ÷ SKUs ativos | D17: % | E17: Maior é melhor | F17: MPI — desempenho de gestão | G17: Anual | H17: RG-SGA-20 tbl_recyclass | I17: Responsável de R&D | J17: 1
A18: KPI-18 | B18: SKUs com grau PPWR indicativo A–C | C18: SKUs não isentos com grau A, B ou C ÷ SKUs não isentos | D18: % | E18: Maior é melhor | F18: ODI — desempenho operacional | G18: Anual | H18: RG-SGA-20 tbl_recyclass | I18: Responsável de R&D | J18: 0.6636 | K18: OBJ-07
A19: KPI-19 | B19: Conteúdo reciclado no polímero | C19: Polímero reciclado pós-consumo (kg) ÷ polímero consumido (kg) | D19: % | E19: Maior é melhor | F19: ODI — desempenho operacional | G19: Mensal | H19: RG-SGA-13 PCR_KG / POLIMERO_KG; RG-SGA-20 | I19: Responsável de Compras | J19: 0.1134
A20: KPI-20 | B20: Massa vendida com grau PPWR A–C | C20: Massa de corpos vendida com grau A–C ÷ massa vendida (não isentos) | D20: % | E20: Maior é melhor | F20: ODI — desempenho operacional | G20: Anual | H20: RG-SGA-20 tbl_recyclass | I20: Responsável de R&D | J20: 0.5975 | K20: OBJ-07
A21: KPI-21 | B21: Certificados de reciclado válidos | C21: Materiais com PCR com certificado EN 15343 válido ÷ materiais com PCR | D21: % | E21: Maior é melhor | F21: MPI — desempenho de gestão | G21: Mensal | H21: RG-SGA-20 tbl_certificados_pcr | I21: Responsável de Compras | J21: 0.6667
A22: KPI-16 | B22: Temperatura média exterior | C22: Média mensal (°C) — variável explicativa de energia e água | D22: °C | E22: Menor é melhor | F22: ECI — condição ambiental | G22: Mensal | H22: IPMA (estação mais próxima) | I22: Gestor do SGA / EHS (Responsável Ambiental)

Sheet Objetivos_SMART
A1: OBJETIVOS AMBIENTAIS SMART — PLASTICOM 2026-2027
A2: Objetivo = resultado pretendido · Indicador = régua com que se mede · Validação SMART calculada · Valor_Atual: média out–dez/2026 (fecho do ano)
A4: ID_OBJ | B4: ID_Politica | C4: Origem_Tipo | D4: Origem_IDs | E4: Origem_Descricao | F4: Declaracao_Objetivo | G4: ID_KPI | H4: Indicador_KPI | I4: Baseline | J4: Meta_Tipo | K4: Meta_Valor | L4: Meta_Numerica | M4: Prazo | N4: Recursos_Humanos | O4: Recursos_Materiais | P4: Recursos_Financeiros_EUR | Q4: Responsavel | R4: Acoes_PAM | S4: Estado | T4: Valor_Atual | U4: Progresso | V4: Dias_ate_Prazo | W4: S_Especifico | X4: M_Mensuravel | Y4: A_Atingivel | Z4: R_Relevante | AA4: T_Temporal | AB4: Validacao_SMART | AC4: Data_Aprovacao
A5: OBJ-01 | B5: POL-03 | C5: Aspeto moderado | D5: AA-007; AA-010; AA-021; RO-02; LEG-08 | E5: Consumo elevado de energia elétrica (≈ 7,8 GWh em 2026, 1.º custo ambiental) nos processos de injeção, sopro e ar comprimido. | F5: Reduzir o consumo específico de eletricidade (kWh por 1.000 unidades produzidas) em 8% até 31/12/2027, face à média set/2025–ago/2026. | G5: KPI-01 | H5: =IFERROR(INDEX(tbl_kpi[Nome],MATCH(G5,tbl_kpi[ID_KPI],0))&" ("&INDEX(tbl_kpi[Unidade],MATCH(G5,tbl_kpi[ID_KPI],0))&")","") -> Intensidade energética (kWh/1.000 un) | I5: =IFERROR(INDEX(tbl_kpi[Baseline],MATCH(G5,tbl_kpi[ID_KPI],0)),"") -> 110.4918 | J5: Redução relativa | K5: -0.08 | L5: =IF(J5="Valor absoluto",K5,IF(I5="","",I5*(1+K5))) -> 101.65246 | M5: 46752 | N5: Gerente de Manutenção (líder), técnico de utilidades (0,2 ETI), equipa Kaizen de turno. | O5: Detetor ultrassónico de fugas, 6 analisadores de energia, variador de velocidade no compressor CMP-02. | P5: 42000 | Q5: Gerente de Manutenção | R5: PAM-26-01; PAM-26-02; PAM-26-06 | S5: Em curso | T5: 99.976 | U5: =IF(OR(T5="",L5="",I5=""),"",IF(L5=I5,"",MAX(-1,MIN(1,(T5-I5)/(L5-I5))))) -> 1 | V5: =M5-DataRef -> 365 | W5: =IF(AND(LEN(F5)>40,G5<>""),"✔","✘") -> ✔ | X5: =IF(ISNUMBER(K5),"✔","✘") -> ✔ | Y5: =IF(AND(P5>0,Q5<>"",R5<>""),"✔","✘") -> ✔ | Z5: =IF(AND(D5<>"",B5<>""),"✔","✘") -> ✔ | AA5: =IF(ISNUMBER(M5),"✔","✘") -> ✔ | AB5: =IF((W5="✔")+(X5="✔")+(Y5="✔")+(Z5="✔")+(AA5="✔")=5,"SMART","Rever") -> SMART | AC5: 46188
A6: OBJ-02 | B6: POL-04 | C6: Aspeto moderado | D6: AA-008; AA-011; AA-020; RO-11 | E6: Scrap plástico ≈ 31 t/ano; taxa de reintegração interna de apenas ≈ 37%. | F6: Reduzir o scrap gerado (kg por 1.000 unidades) em 12% até 30/06/2027, mantendo a taxa de rejeição ≤ 2,0%. | G6: KPI-03 | H6: =IFERROR(INDEX(tbl_kpi[Nome],MATCH(G6,tbl_kpi[ID_KPI],0))&" ("&INDEX(tbl_kpi[Unidade],MATCH(G6,tbl_kpi[ID_KPI],0))&")","") -> Intensidade de scrap (kg/1.000 un) | I6: =IFERROR(INDEX(tbl_kpi[Baseline],MATCH(G6,tbl_kpi[ID_KPI],0)),"") -> 0.4812 | J6: Redução relativa | K6: -0.12 | L6: =IF(J6="Valor absoluto",K6,IF(I6="","",I6*(1+K6))) -> 0.423456 | M6: 46568 | N6: Gerente de Produção, Eng.ª de Processo (DOE), chefes de turno. | O6: Caixas coloridas para segregar scrap por cor/polímero, receitas de arranque validadas. | P6: 8500 | Q6: Gerente de Produção | R6: PAM-26-12 | S6: Em curso | T6: 0.4444 | U6: =IF(OR(T6="",L6="",I6=""),"",IF(L6=I6,"",MAX(-1,MIN(1,(T6-I6)/(L6-I6))))) -> 0.63729565 | V6: =M6-DataRef -> 181 | W6: =IF(AND(LEN(F6)>40,G6<>""),"✔","✘") -> ✔ | X6: =IF(ISNUMBER(K6),"✔","✘") -> ✔ | Y6: =IF(AND(P6>0,Q6<>"",R6<>""),"✔","✘") -> ✔ | Z6: =IF(AND(D6<>"",B6<>""),"✔","✘") -> ✔ | AA6: =IF(ISNUMBER(M6),"✔","✘") -> ✔ | AB6: =IF((W6="✔")+(X6="✔")+(Y6="✔")+(Z6="✔")+(AA6="✔")=5,"SMART","Rever") -> SMART | AC6: 46188
A7: OBJ-03 | B7: POL-01 | C7: Aspeto significativo (AAS) | D7: AA-014; AA-006; LEG-04; LEG-12 | E7: Emissão difusa de COV na limpeza de ecrãs da serigrafia (AAS, IRA 40) e subida recente do consumo de solvente. | F7: Reduzir o consumo de solvente de limpeza na serigrafia (kg por 1.000 peças serigrafadas) em 20% até 30/06/2027, face à média set/2025–mai/2026. | G7: KPI-06 | H7: =IFERROR(INDEX(tbl_kpi[Nome],MATCH(G7,tbl_kpi[ID_KPI],0))&" ("&INDEX(tbl_kpi[Unidade],MATCH(G7,tbl_kpi[ID_KPI],0))&")","") -> Solvente de limpeza na serigrafia (kg/1.000 peças) | I7: =IFERROR(INDEX(tbl_kpi[Baseline],MATCH(G7,tbl_kpi[ID_KPI],0)),"") -> 0.1605 | J7: Redução relativa | K7: -0.2 | L7: =IF(J7="Valor absoluto",K7,IF(I7="","",I7*(1+K7))) -> 0.1284 | M7: 46568 | N7: Gestor do SGA/EHS, chefe da serigrafia, operadores SS-001/SS-002 (formação de 2 h). | O7: Dispensadores de segurança com tampa, panos pré-dosados, unidade de recuperação de solvente (destilador). | P7: 18500 | Q7: Gestor do SGA / EHS (Responsável Ambiental) | R7: PAM-26-07; PAM-26-08; PAM-26-13 | S7: Em curso | T7: 0.1635 | U7: =IF(OR(T7="",L7="",I7=""),"",IF(L7=I7,"",MAX(-1,MIN(1,(T7-I7)/(L7-I7))))) -> -0.093457944 | V7: =M7-DataRef -> 181 | W7: =IF(AND(LEN(F7)>40,G7<>""),"✔","✘") -> ✔ | X7: =IF(ISNUMBER(K7),"✔","✘") -> ✔ | Y7: =IF(AND(P7>0,Q7<>"",R7<>""),"✔","✘") -> ✔ | Z7: =IF(AND(D7<>"",B7<>""),"✔","✘") -> ✔ | AA7: =IF(ISNUMBER(M7),"✔","✘") -> ✔ | AB7: =IF((W7="✔")+(X7="✔")+(Y7="✔")+(Z7="✔")+(AA7="✔")=5,"SMART","Rever") -> SMART | AC7: 46188
A8: OBJ-04 | B8: POL-02 | C8: Risco legal | D8: LEG-09; RO-06; AA-038 | E8: PPWR (Reg. (UE) 2025/40) aplicável desde 12/08/2026: só 9 de 22 famílias têm documentação técnica e declaração UE de conformidade (NC legal). | F8: Garantir que 100% das famílias de embalagem têm documentação técnica e declaração UE de conformidade PPWR até 31/12/2026. | G8: KPI-12 | H8: =IFERROR(INDEX(tbl_kpi[Nome],MATCH(G8,tbl_kpi[ID_KPI],0))&" ("&INDEX(tbl_kpi[Unidade],MATCH(G8,tbl_kpi[ID_KPI],0))&")","") -> Famílias com conformidade PPWR (%) | I8: =IFERROR(INDEX(tbl_kpi[Baseline],MATCH(G8,tbl_kpi[ID_KPI],0)),"") -> 0.4091 | J8: Valor absoluto | K8: 1 | L8: =IF(J8="Valor absoluto",K8,IF(I8="","",I8*(1+K8))) -> 1 | M8: 46387 | N8: Responsável de R&D, técnico de qualidade/ambiente (0,5 ETI), consultor externo PPWR. | O8: Ensaios de metais pesados por família em laboratório acreditado; modelo de dossier técnico. | P8: 26000 | Q8: Responsável de R&D | R8: PAM-26-10 | S8: Em curso | T8: 0.7727 | U8: =IF(OR(T8="",L8="",I8=""),"",IF(L8=I8,"",MAX(-1,MIN(1,(T8-I8)/(L8-I8))))) -> 0.61533254 | V8: =M8-DataRef -> 0 | W8: =IF(AND(LEN(F8)>40,G8<>""),"✔","✘") -> ✔ | X8: =IF(ISNUMBER(K8),"✔","✘") -> ✔ | Y8: =IF(AND(P8>0,Q8<>"",R8<>""),"✔","✘") -> ✔ | Z8: =IF(AND(D8<>"",B8<>""),"✔","✘") -> ✔ | AA8: =IF(ISNUMBER(M8),"✔","✘") -> ✔ | AB8: =IF((W8="✔")+(X8="✔")+(Y8="✔")+(Z8="✔")+(AA8="✔")=5,"SMART","Rever") -> SMART | AC8: 46188
A9: OBJ-05 | B9: POL-03 | C9: Risco | D9: AA-023; RO-04; PES-08; PES-09 | E9: Consumo de água da torre de arrefecimento (≈ 80% da água) sensível às ondas de calor e à escassez hídrica. | F9: Reduzir o consumo específico de água (m³ por 1.000 unidades) em 10% até 31/12/2027, face à média set/2025–ago/2026. | G9: KPI-02 | H9: =IFERROR(INDEX(tbl_kpi[Nome],MATCH(G9,tbl_kpi[ID_KPI],0))&" ("&INDEX(tbl_kpi[Unidade],MATCH(G9,tbl_kpi[ID_KPI],0))&")","") -> Intensidade hídrica (m³/1.000 un) | I9: =IFERROR(INDEX(tbl_kpi[Baseline],MATCH(G9,tbl_kpi[ID_KPI],0)),"") -> 0.1429 | J9: Redução relativa | K9: -0.1 | L9: =IF(J9="Valor absoluto",K9,IF(I9="","",I9*(1+K9))) -> 0.12861 | M9: 46752 | N9: Diretor Industrial, técnico de utilidades, empresa de tratamento de água. | O9: Controlo automático da purga por condutividade; estudo de torre adiabática em circuito fechado. | P9: 65000 | Q9: Diretor Industrial | R9: PAM-26-14 | S9: Planeado | T9: 0.1388 | U9: =IF(OR(T9="",L9="",I9=""),"",IF(L9=I9,"",MAX(-1,MIN(1,(T9-I9)/(L9-I9))))) -> 0.28691393 | V9: =M9-DataRef -> 365 | W9: =IF(AND(LEN(F9)>40,G9<>""),"✔","✘") -> ✔ | X9: =IF(ISNUMBER(K9),"✔","✘") -> ✔ | Y9: =IF(AND(P9>0,Q9<>"",R9<>""),"✔","✘") -> ✔ | Z9: =IF(AND(D9<>"",B9<>""),"✔","✘") -> ✔ | AA9: =IF(ISNUMBER(M9),"✔","✘") -> ✔ | AB9: =IF((W9="✔")+(X9="✔")+(Y9="✔")+(Z9="✔")+(AA9="✔")=5,"SMART","Rever") -> SMART | AC9: 46188
A10: OBJ-06 | B10: POL-06 | C10: Risco legal | D10: AA-003; RO-07; LEG-10 | E10: Perdas de granulado para a rede pluvial (microplásticos) e regulamento europeu de granulados a aplicar. | F10: Garantir contenção em 100% dos 14 pontos críticos de manuseamento de granulado até 31/03/2027, com zero granulado visível nas sarjetas nas inspeções semanais. | G10: KPI-13 | H10: =IFERROR(INDEX(tbl_kpi[Nome],MATCH(G10,tbl_kpi[ID_KPI],0))&" ("&INDEX(tbl_kpi[Unidade],MATCH(G10,tbl_kpi[ID_KPI],0))&")","") -> Pontos críticos de granulado com contenção (%) | I10: =IFERROR(INDEX(tbl_kpi[Baseline],MATCH(G10,tbl_kpi[ID_KPI],0)),"") -> 0.4286 | J10: Valor absoluto | K10: 1 | L10: =IF(J10="Valor absoluto",K10,IF(I10="","",I10*(1+K10))) -> 1 | M10: 46477 | N10: Gestor do SGA/EHS, operadores de armazém, manutenção. | O10: Filtros de sarjeta, tabuleiros de descarga de big bags, aspirador industrial, kits de recolha. | P10: 14000 | Q10: Gestor do SGA / EHS (Responsável Ambiental) | R10: PAM-26-11 | S10: Em curso | T10: 0.7857 | U10: =IF(OR(T10="",L10="",I10=""),"",IF(L10=I10,"",MAX(-1,MIN(1,(T10-I10)/(L10-I10))))) -> 0.62495625 | V10: =M10-DataRef -> 90 | W10: =IF(AND(LEN(F10)>40,G10<>""),"✔","✘") -> ✔ | X10: =IF(ISNUMBER(K10),"✔","✘") -> ✔ | Y10: =IF(AND(P10>0,Q10<>"",R10<>""),"✔","✘") -> ✔ | Z10: =IF(AND(D10<>"",B10<>""),"✔","✘") -> ✔ | AA10: =IF(ISNUMBER(M10),"✔","✘") -> ✔ | AB10: =IF((W10="✔")+(X10="✔")+(Y10="✔")+(Z10="✔")+(AA10="✔")=5,"SMART","Rever") -> SMART | AC10: 46188
A11: OBJ-07 | B11: POL-04 | C11: Risco legal | D11: LEG-09; LEG-21; RO-06 | E11: PPWR art. 6.º: a partir de 2030 só embalagens com grau A–C. A autoavaliação RecyClass (RG-SGA-20) mostra SKUs em classe F (PVC, PETG, preto de carbono) e abaixo de C (decoração direta em PET). | F11: Garantir que 100% dos SKUs de embalagem não isentos têm grau PPWR indicativo A–C até 31/12/2028, eliminando PVC, PETG e preto de carbono e substituindo a decoração direta em PET. | G11: KPI-18 | H11: =IFERROR(INDEX(tbl_kpi[Nome],MATCH(G11,tbl_kpi[ID_KPI],0))&" ("&INDEX(tbl_kpi[Unidade],MATCH(G11,tbl_kpi[ID_KPI],0))&")","") -> SKUs com grau PPWR indicativo A–C (%) | I11: =IFERROR(INDEX(tbl_kpi[Baseline],MATCH(G11,tbl_kpi[ID_KPI],0)),"") -> 0.6636 | J11: Valor absoluto | K11: 1 | L11: =IF(J11="Valor absoluto",K11,IF(I11="","",I11*(1+K11))) -> 1 | M11: 47118 | N11: Responsável de R&D (líder), área comercial, Responsável de Compras, técnico de qualidade. | O11: Moldes de PET/PP para substituir PVC e PETG, masterbatch preto detetável por NIR, rótulos PE/PP, certificação RecyClass das famílias principais. | P11: 85000 | Q11: Responsável de R&D | R11: PAM-26-22; PAM-26-23; PAM-26-24 | S11: Em curso | T11: 0.6636 | U11: =IF(OR(T11="",L11="",I11=""),"",IF(L11=I11,"",MAX(-1,MIN(1,(T11-I11)/(L11-I11))))) -> 0 | V11: =M11-DataRef -> 731 | W11: =IF(AND(LEN(F11)>40,G11<>""),"✔","✘") -> ✔ | X11: =IF(ISNUMBER(K11),"✔","✘") -> ✔ | Y11: =IF(AND(P11>0,Q11<>"",R11<>""),"✔","✘") -> ✔ | Z11: =IF(AND(D11<>"",B11<>""),"✔","✘") -> ✔ | AA11: =IF(ISNUMBER(M11),"✔","✘") -> ✔ | AB11: =IF((W11="✔")+(X11="✔")+(Y11="✔")+(Z11="✔")+(AA11="✔")=5,"SMART","Rever") -> SMART | AC11: 46188

Sheet Acompanhamento_Mensal
A1: ID_OBJ | B1: ID_KPI | C1: Mes | D1: Valor_Real | E1: Baseline | F1: Meta_Final | G1: Desvio_vs_Baseline | H1: Media_Movel_3M | I1: Sinal
A2: OBJ-01 | B2: KPI-01 | C2: 45717 | D2: 109.3702 | E2: 110.4918 | F2: 101.6525 | G2: =IF(E2=0,"",D2/E2-1) -> -0.01015098 | H2: =IF(COUNTIFS($A$2:$A$89,A2,$C$2:$C$89,"<="&C2)<3,"",AVERAGEIFS($D$2:$D$89,$A$2:$A$89,A2,$C$2:$C$89,"<="&C2,$C$2:$C$89,">"&EDATE(C2,-3))) | I2: =IF(G2="","",IF(G2>=0.1,"▲ Alerta (≥+10%)",IF(G2<=0,"▼ Favorável","≈ Estável"))) -> ▼ Favorável
A3: OBJ-01 | B3: KPI-01 | C3: 45748 | D3: 112.0513 | E3: 110.4918 | F3: 101.6525 | G3: =IF(E3=0,"",D3/E3-1) -> 0.01411417 | H3: =IF(COUNTIFS($A$2:$A$89,A3,$C$2:$C$89,"<="&C3)<3,"",AVERAGEIFS($D$2:$D$89,$A$2:$A$89,A3,$C$2:$C$89,"<="&C3,$C$2:$C$89,">"&EDATE(C3,-3))) | I3: =IF(G3="","",IF(G3>=0.1,"▲ Alerta (≥+10%)",IF(G3<=0,"▼ Favorável","≈ Estável"))) -> ≈ Estável
A4: OBJ-01 | B4: KPI-01 | C4: 45778 | D4: 106.9508 | E4: 110.4918 | F4: 101.6525 | G4: =IF(E4=0,"",D4/E4-1) -> -0.032047627 | H4: =IF(COUNTIFS($A$2:$A$89,A4,$C$2:$C$89,"<="&C4)<3,"",AVERAGEIFS($D$2:$D$89,$A$2:$A$89,A4,$C$2:$C$89,"<="&C4,$C$2:$C$89,">"&EDATE(C4,-3))) -> 109.45743 | I4: =IF(G4="","",IF(G4>=0.1,"▲ Alerta (≥+10%)",IF(G4<=0,"▼ Favorável","≈ Estável"))) -> ▼ Favorável
A5: OBJ-01 | B5: KPI-01 | C5: 45809 | D5: 113.4307 | E5: 110.4918 | F5: 101.6525 | G5: =IF(E5=0,"",D5/E5-1) -> 0.026598354 | H5: =IF(COUNTIFS($A$2:$A$89,A5,$C$2:$C$89,"<="&C5)<3,"",AVERAGEIFS($D$2:$D$89,$A$2:$A$89,A5,$C$2:$C$89,"<="&C5,$C$2:$C$89,">"&EDATE(C5,-3))) -> 110.81093 | I5: =IF(G5="","",IF(G5>=0.1,"▲ Alerta (≥+10%)",IF(G5<=0,"▼ Favorável","≈ Estável"))) -> ≈ Estável
A6: OBJ-01 | B6: KPI-01 | C6: 45839 | D6: 117.7465 | E6: 110.4918 | F6: 101.6525 | G6: =IF(E6=0,"",D6/E6-1) -> 0.065658266 | H6: =IF(COUNTIFS($A$2:$A$89,A6,$C$2:$C$89,"<="&C6)<3,"",AVERAGEIFS($D$2:$D$89,$A$2:$A$89,A6,$C$2:$C$89,"<="&C6,$C$2:$C$89,">"&EDATE(C6,-3))) -> 112.70933 | I6: =IF(G6="","",IF(G6>=0.1,"▲ Alerta (≥+10%)",IF(G6<=0,"▼ Favorável","≈ Estável"))) -> ≈ Estável
A7: OBJ-01 | B7: KPI-01 | C7: 45870 | D7: 107.8137 | E7: 110.4918 | F7: 101.6525 | G7: =IF(E7=0,"",D7/E7-1) -> -0.024237998 | H7: =IF(COUNTIFS($A$2:$A$89,A7,$C$2:$C$89,"<="&C7)<3,"",AVERAGEIFS($D$2:$D$89,$A$2:$A$89,A7,$C$2:$C$89,"<="&C7,$C$2:$C$89,">"&EDATE(C7,-3))) -> 112.99697 | I7: =IF(G7="","",IF(G7>=0.1,"▲ Alerta (≥+10%)",IF(G7<=0,"▼ Favorável","≈ Estável"))) -> ▼ Favorável
A8: OBJ-01 | B8: KPI-01 | C8: 45901 | D8: 112.4749 | E8: 110.4918 | F8: 101.6525 | G8: =IF(E8=0,"",D8/E8-1) -> 0.017947938 | H8: =IF(COUNTIFS($A$2:$A$89,A8,$C$2:$C$89,"<="&C8)<3,"",AVERAGEIFS($D$2:$D$89,$A$2:$A$89,A8,$C$2:$C$89,"<="&C8,$C$2:$C$89,">"&EDATE(C8,-3))) -> 112.67837 | I8: =IF(G8="","",IF(G8>=0.1,"▲ Alerta (≥+10%)",IF(G8<=0,"▼ Favorável","≈ Estável"))) -> ≈ Estável
A9: OBJ-01 | B9: KPI-01 | C9: 45931 | D9: 110.2524 | E9: 110.4918 | F9: 101.6525 | G9: =IF(E9=0,"",D9/E9-1) -> -0.0021666766 | H9: =IF(COUNTIFS($A$2:$A$89,A9,$C$2:$C$89,"<="&C9)<3,"",AVERAGEIFS($D$2:$D$89,$A$2:$A$89,A9,$C$2:$C$89,"<="&C9,$C$2:$C$89,">"&EDATE(C9,-3))) -> 110.18033 | I9: =IF(G9="","",IF(G9>=0.1,"▲ Alerta (≥+10%)",IF(G9<=0,"▼ Favorável","≈ Estável"))) -> ▼ Favorável
A10: OBJ-01 | B10: KPI-01 | C10: 45962 | D10: 112.9136 | E10: 110.4918 | F10: 101.6525 | G10: =IF(E10=0,"",D10/E10-1) -> 0.021918369 | H10: =IF(COUNTIFS($A$2:$A$89,A10,$C$2:$C$89,"<="&C10)<3,"",AVERAGEIFS($D$2:$D$89,$A$2:$A$89,A10,$C$2:$C$89,"<="&C10,$C$2:$C$89,">"&EDATE(C10,-3))) -> 111.8803 | I10: =IF(G10="","",IF(G10>=0.1,"▲ Alerta (≥+10%)",IF(G10<=0,"▼ Favorável","≈ Estável"))) -> ≈ Estável
A11: OBJ-01 | B11: KPI-01 | C11: 45992 | D11: 111.5682 | E11: 110.4918 | F11: 101.6525 | G11: =IF(E11=0,"",D11/E11-1) -> 0.0097418994 | H11: =IF(COUNTIFS($A$2:$A$89,A11,$C$2:$C$89,"<="&C11)<3,"",AVERAGEIFS($D$2:$D$89,$A$2:$A$89,A11,$C$2:$C$89,"<="&C11,$C$2:$C$89,">"&EDATE(C11,-3))) -> 111.57807 | I11: =IF(G11="","",IF(G11>=0.1,"▲ Alerta (≥+10%)",IF(G11<=0,"▼ Favorável","≈ Estável"))) -> ≈ Estável
A12: OBJ-01 | B12: KPI-01 | C12: 46023 | D12: 107.5912 | E12: 110.4918 | F12: 101.6525 | G12: =IF(E12=0,"",D12/E12-1) -> -0.026251722 | H12: =IF(COUNTIFS($A$2:$A$89,A12,$C$2:$C$89,"<="&C12)<3,"",AVERAGEIFS($D$2:$D$89,$A$2:$A$89,A12,$C$2:$C$89,"<="&C12,$C$2:$C$89,">"&EDATE(C12,-3))) -> 110.691 | I12: =IF(G12="","",IF(G12>=0.1,"▲ Alerta (≥+10%)",IF(G12<=0,"▼ Favorável","≈ Estável"))) -> ▼ Favorável
A13: OBJ-01 | B13: KPI-01 | C13: 46054 | D13: 110.9337 | E13: 110.4918 | F13: 101.6525 | G13: =IF(E13=0,"",D13/E13-1) -> 0.0039993918 | H13: =IF(COUNTIFS($A$2:$A$89,A13,$C$2:$C$89,"<="&C13)<3,"",AVERAGEIFS($D$2:$D$89,$A$2:$A$89,A13,$C$2:$C$89,"<="&C13,$C$2:$C$89,">"&EDATE(C13,-3))) -> 110.03103 | I13: =IF(G13="","",IF(G13>=0.1,"▲ Alerta (≥+10%)",IF(G13<=0,"▼ Favorável","≈ Estável"))) -> ≈ Estável
... A89: OBJ-05 | B89: KPI-02 | C89: 46357 | D89: 0.1014 | E89: 0.1429 | F89: 0.1286 | G89: =IF(E89=0,"",D89/E89-1) -> -0.29041288 | H89: =IF(COUNTIFS($A$2:$A$89,A89,$C$2:$C$89,"<="&C89)<3,"",AVERAGEIFS($D$2:$D$89,$A$2:$A$89,A89,$C$2:$C$89,"<="&C89,$C$2:$C$89,">"&EDATE(C89,-3))) -> 0.1202 | I89: =IF(G89="","",IF(G89>=0.1,"▲ Alerta (≥+10%)",IF(G89<=0,"▼ Favorável","≈ Estável"))) -> ▼ Favorável

Sheet Resumo_Atividade_3_4
A1: ATIVIDADE 3.4 — OBJETIVOS AMBIENTAIS SMART E KPIs
A2: OBJ-01 nasce de aspetos moderados de energia + risco RO-02; OBJ-03 de um AAS (COV); OBJ-04 de um risco legal (PPWR). Calculado a partir de tbl_objetivos.
A4: Campo | B4: Objetivo 1 | C4: Objetivo 2 | D4: Objetivo 3
A5: ID | B5: OBJ-01 | C5: OBJ-03 | D5: OBJ-04
A6: Origem do Objetivo | B6: =INDEX(Objetivos_SMART!$E$5:$E$11,MATCH(B$5,Objetivos_SMART!$A$5:$A$11,0)) -> Consumo elevado de energia elétrica (≈ 7,8 GWh em 2026, 1.º custo ambiental) nos processos de injeção, sopro e ar comprimido. | C6: =INDEX(Objetivos_SMART!$E$5:$E$11,MATCH(C$5,Objetivos_SMART!$A$5:$A$11,0)) -> Emissão difusa de COV na limpeza de ecrãs da serigrafia (AAS, IRA 40) e subida recente do consumo de solvente. | D6: =INDEX(Objetivos_SMART!$E$5:$E$11,MATCH(D$5,Objetivos_SMART!$A$5:$A$11,0)) -> PPWR (Reg. (UE) 2025/40) aplicável desde 12/08/2026: só 9 de 22 famílias têm documentação técnica e declaração UE de conformidade (NC legal).
A7: IDs de origem | B7: =INDEX(Objetivos_SMART!$D$5:$D$11,MATCH(B$5,Objetivos_SMART!$A$5:$A$11,0)) -> AA-007; AA-010; AA-021; RO-02; LEG-08 | C7: =INDEX(Objetivos_SMART!$D$5:$D$11,MATCH(C$5,Objetivos_SMART!$A$5:$A$11,0)) -> AA-014; AA-006; LEG-04; LEG-12 | D7: =INDEX(Objetivos_SMART!$D$5:$D$11,MATCH(D$5,Objetivos_SMART!$A$5:$A$11,0)) -> LEG-09; RO-06; AA-038
A8: Declaração do Objetivo | B8: =INDEX(Objetivos_SMART!$F$5:$F$11,MATCH(B$5,Objetivos_SMART!$A$5:$A$11,0)) -> Reduzir o consumo específico de eletricidade (kWh por 1.000 unidades produzidas) em 8% até 31/12/2027, face à média set/2025–ago/2026. | C8: =INDEX(Objetivos_SMART!$F$5:$F$11,MATCH(C$5,Objetivos_SMART!$A$5:$A$11,0)) -> Reduzir o consumo de solvente de limpeza na serigrafia (kg por 1.000 peças serigrafadas) em 20% até 30/06/2027, face à média set/2025–mai/2026. | D8: =INDEX(Objetivos_SMART!$F$5:$F$11,MATCH(D$5,Objetivos_SMART!$A$5:$A$11,0)) -> Garantir que 100% das famílias de embalagem têm documentação técnica e declaração UE de conformidade PPWR até 31/12/2026.
A9: Indicador (KPI) | B9: =INDEX(Objetivos_SMART!$H$5:$H$11,MATCH(B$5,Objetivos_SMART!$A$5:$A$11,0)) -> Intensidade energética (kWh/1.000 un) | C9: =INDEX(Objetivos_SMART!$H$5:$H$11,MATCH(C$5,Objetivos_SMART!$A$5:$A$11,0)) -> Solvente de limpeza na serigrafia (kg/1.000 peças) | D9: =INDEX(Objetivos_SMART!$H$5:$H$11,MATCH(D$5,Objetivos_SMART!$A$5:$A$11,0)) -> Famílias com conformidade PPWR (%)
A10: Baseline | B10: =INDEX(Objetivos_SMART!$I$5:$I$11,MATCH(B$5,Objetivos_SMART!$A$5:$A$11,0)) -> 110.4918 | C10: =INDEX(Objetivos_SMART!$I$5:$I$11,MATCH(C$5,Objetivos_SMART!$A$5:$A$11,0)) -> 0.1605 | D10: =INDEX(Objetivos_SMART!$I$5:$I$11,MATCH(D$5,Objetivos_SMART!$A$5:$A$11,0)) -> 0.4091
A11: Meta (Target) | B11: =INDEX(Objetivos_SMART!$L$5:$L$11,MATCH(B$5,Objetivos_SMART!$A$5:$A$11,0)) -> 101.65246 | C11: =INDEX(Objetivos_SMART!$L$5:$L$11,MATCH(C$5,Objetivos_SMART!$A$5:$A$11,0)) -> 0.1284 | D11: =INDEX(Objetivos_SMART!$L$5:$L$11,MATCH(D$5,Objetivos_SMART!$A$5:$A$11,0)) -> 1
A12: Meta (variação) | B12: =INDEX(Objetivos_SMART!$K$5:$K$11,MATCH(B$5,Objetivos_SMART!$A$5:$A$11,0)) -> -0.08 | C12: =INDEX(Objetivos_SMART!$K$5:$K$11,MATCH(C$5,Objetivos_SMART!$A$5:$A$11,0)) -> -0.2 | D12: =INDEX(Objetivos_SMART!$K$5:$K$11,MATCH(D$5,Objetivos_SMART!$A$5:$A$11,0)) -> 1
A13: Prazo | B13: =INDEX(Objetivos_SMART!$M$5:$M$11,MATCH(B$5,Objetivos_SMART!$A$5:$A$11,0)) -> 46752 | C13: =INDEX(Objetivos_SMART!$M$5:$M$11,MATCH(C$5,Objetivos_SMART!$A$5:$A$11,0)) -> 46568 | D13: =INDEX(Objetivos_SMART!$M$5:$M$11,MATCH(D$5,Objetivos_SMART!$A$5:$A$11,0)) -> 46387
A14: Recursos — humanos | B14: =INDEX(Objetivos_SMART!$N$5:$N$11,MATCH(B$5,Objetivos_SMART!$A$5:$A$11,0)) -> Gerente de Manutenção (líder), técnico de utilidades (0,2 ETI), equipa Kaizen de turno. | C14: =INDEX(Objetivos_SMART!$N$5:$N$11,MATCH(C$5,Objetivos_SMART!$A$5:$A$11,0)) -> Gestor do SGA/EHS, chefe da serigrafia, operadores SS-001/SS-002 (formação de 2 h). | D14: =INDEX(Objetivos_SMART!$N$5:$N$11,MATCH(D$5,Objetivos_SMART!$A$5:$A$11,0)) -> Responsável de R&D, técnico de qualidade/ambiente (0,5 ETI), consultor externo PPWR.
A15: Recursos — materiais | B15: =INDEX(Objetivos_SMART!$O$5:$O$11,MATCH(B$5,Objetivos_SMART!$A$5:$A$11,0)) -> Detetor ultrassónico de fugas, 6 analisadores de energia, variador de velocidade no compressor CMP-02. | C15: =INDEX(Objetivos_SMART!$O$5:$O$11,MATCH(C$5,Objetivos_SMART!$A$5:$A$11,0)) -> Dispensadores de segurança com tampa, panos pré-dosados, unidade de recuperação de solvente (destilador). | D15: =INDEX(Objetivos_SMART!$O$5:$O$11,MATCH(D$5,Objetivos_SMART!$A$5:$A$11,0)) -> Ensaios de metais pesados por família em laboratório acreditado; modelo de dossier técnico.
A16: Recursos — financeiros (€) | B16: =INDEX(Objetivos_SMART!$P$5:$P$11,MATCH(B$5,Objetivos_SMART!$A$5:$A$11,0)) -> 42000 | C16: =INDEX(Objetivos_SMART!$P$5:$P$11,MATCH(C$5,Objetivos_SMART!$A$5:$A$11,0)) -> 18500 | D16: =INDEX(Objetivos_SMART!$P$5:$P$11,MATCH(D$5,Objetivos_SMART!$A$5:$A$11,0)) -> 26000
A17: Responsável | B17: =INDEX(Objetivos_SMART!$Q$5:$Q$11,MATCH(B$5,Objetivos_SMART!$A$5:$A$11,0)) -> Gerente de Manutenção | C17: =INDEX(Objetivos_SMART!$Q$5:$Q$11,MATCH(C$5,Objetivos_SMART!$A$5:$A$11,0)) -> Gestor do SGA / EHS (Responsável Ambiental) | D17: =INDEX(Objetivos_SMART!$Q$5:$Q$11,MATCH(D$5,Objetivos_SMART!$A$5:$A$11,0)) -> Responsável de R&D
A18: Ações no PAM | B18: =INDEX(Objetivos_SMART!$R$5:$R$11,MATCH(B$5,Objetivos_SMART!$A$5:$A$11,0)) -> PAM-26-01; PAM-26-02; PAM-26-06 | C18: =INDEX(Objetivos_SMART!$R$5:$R$11,MATCH(C$5,Objetivos_SMART!$A$5:$A$11,0)) -> PAM-26-07; PAM-26-08; PAM-26-13 | D18: =INDEX(Objetivos_SMART!$R$5:$R$11,MATCH(D$5,Objetivos_SMART!$A$5:$A$11,0)) -> PAM-26-10
A19: Validação SMART | B19: =INDEX(Objetivos_SMART!$AB$5:$AB$11,MATCH(B$5,Objetivos_SMART!$A$5:$A$11,0)) -> SMART | C19: =INDEX(Objetivos_SMART!$AB$5:$AB$11,MATCH(C$5,Objetivos_SMART!$A$5:$A$11,0)) -> SMART | D19: =INDEX(Objetivos_SMART!$AB$5:$AB$11,MATCH(D$5,Objetivos_SMART!$A$5:$A$11,0)) -> SMART
A21: S (Específico) | B21: Uma variável, um âmbito e um indicador definidos (ex.: kWh por 1.000 unidades de injeção + sopro).
A22: M (Mensurável) | B22: Meta numérica face a uma baseline medida (não 'a medir').
A23: A (Atingível) | B23: Orçamento aprovado, responsável e ações planeadas no PAM.
A24: R (Relevante) | B24: Nasce de um AAS, de um risco ou de uma obrigação legal e de um compromisso da política.
A25: T (Temporal) | B25: Data limite explícita.
A26: Objetivo vs indicador | B26: O objetivo é o resultado pretendido (ex.: -8% de energia específica); o indicador é a régua (kWh/1.000 un) com que se mede o progresso.

Sheet Listas
A1: LISTAS CONTROLADAS (domínios de validação de dados) — editar aqui para alterar opções
A2: DataReferencia | B2: Politica | C2: OrigemTipo | D2: Polaridade | E2: TipoISO14031 | F2: Frequencia | G2: MetaTipo | H2: Estado | I2: Funcao | J2: SimNao
A3: 46387 | B3: POL-01 | C3: Aspeto significativo (AAS) | D3: Menor é melhor | E3: ODI — desempenho operacional | F3: Mensal | G3: Redução relativa | H3: Planeado | I3: Diretor Geral (Gestão de Topo) | J3: Sim
B4: POL-02 | C4: Aspeto moderado | D4: Maior é melhor | E4: MPI — desempenho de gestão | F4: Trimestral | G4: Aumento relativo | H4: Em curso | I4: Diretor Industrial | J4: Não
B5: POL-03 | C5: Risco legal | D5: Zero é o alvo | E5: ECI — condição ambiental | F5: Semestral | G5: Valor absoluto | H5: Atingido | I5: Gestor do SGA / EHS (Responsável Ambiental)
B6: POL-04 | C6: Risco | F6: Anual | H6: Não atingido | I6: Gerente de Produção
B7: POL-05 | C7: Oportunidade | F7: Por ocorrência | H7: Cancelado | I7: Gerente de Manutenção
B8: POL-06 | C8: Parte interessada | I8: Gerente da Qualidade
B9: POL-07 | I9: Responsável de Armazém e Logística
I10: Responsável de Compras
I11: Responsável de R&D
I12: Responsável de Recursos Humanos
I13: Diretor Financeiro
I14: Operador de Serigrafia
I15: Operador de Injeção
I16: Operador de Sopro (ISBM)
I17: Operador de Hot Foil
I18: Técnico de Manutenção
I19: Técnico de Utilidades
I20: Operador de Armazém / Empilhador
I21: Chefe de Turno
... I24: Técnico de Qualidade/Ambiente

Sheet Dicionario_Dados
A1: Folha | B1: Tabela | C1: Coluna | D1: Tipo | E1: Origem | F1: Descricao | G1: Dominio_Unidade | H1: Obrigatorio | I1: Chave
A2: Politica | B2: tbl_politica | C2: ID_Politica | D2: Texto | E2: Entrada | F2: Compromisso da política ambiental. | H2: Sim | I2: PK
A3: Politica | B3: tbl_politica | C3: Compromisso | D3: Texto | E3: Entrada | F3: Texto do compromisso (Política Ambiental Plasticom, rev. 2026). | H3: Sim
A4: Politica | B4: tbl_politica | C4: N_Objetivos | D4: Inteiro | E4: Calculado (fórmula) | F4: N.º de objetivos que concretizam o compromisso. | H4: Sim
A5: Catalogo_KPI | B5: tbl_kpi | C5: ID_KPI | D5: Texto | E5: Entrada | F5: Identificador do indicador. | H5: Sim | I5: PK
A6: Catalogo_KPI | B6: tbl_kpi | C6: Nome | D6: Texto | E6: Entrada | F6: Nome do indicador. | H6: Sim
A7: Catalogo_KPI | B7: tbl_kpi | C7: Formula_Calculo | D7: Texto | E7: Entrada | F7: Numerador ÷ denominador (definição operacional). | H7: Sim
A8: Catalogo_KPI | B8: tbl_kpi | C8: Unidade | D8: Texto | E8: Entrada | F8: Unidade. | H8: Sim
A9: Catalogo_KPI | B9: tbl_kpi | C9: Polaridade | D9: Texto | E9: Entrada | F9: Sentido desejado. | G9: Lista lst_Polaridade | H9: Sim
A10: Catalogo_KPI | B10: tbl_kpi | C10: Tipo_ISO14031 | D10: Texto | E10: Entrada | F10: Tipologia ISO 14031. | G10: Lista lst_TipoISO14031 | H10: Sim
A11: Catalogo_KPI | B11: tbl_kpi | C11: Frequencia | D11: Texto | E11: Entrada | F11: Frequência de cálculo. | G11: Lista lst_Frequencia | H11: Sim
A12: Catalogo_KPI | B12: tbl_kpi | C12: Fonte_Dados | D12: Texto | E12: Entrada | F12: Origem dos dados. | H12: Sim
A13: Catalogo_KPI | B13: tbl_kpi | C13: Responsavel | D13: Texto | E13: Entrada | F13: Responsável pelo indicador. | G13: Lista lst_Funcao | H13: Sim
A14: Catalogo_KPI | B14: tbl_kpi | C14: Baseline | D14: Decimal | E14: Entrada | F14: Linha de base (média set/2025–ago/2026 salvo indicação). | H14: Não
A15: Catalogo_KPI | B15: tbl_kpi | C15: ID_OBJ | D15: Texto | E15: Entrada | F15: Objetivo que o indicador mede. | H15: Não | I15: FK → tbl_objetivos
A16: Catalogo_KPI | B16: tbl_kpi | C16: ID_MED | D16: Texto | E16: Entrada | F16: Parâmetro do plano de monitorização. | H16: Não | I16: FK → RG-SGA-13
A17: Objetivos_SMART | B17: tbl_objetivos | C17: ID_OBJ | D17: Texto | E17: Entrada | F17: Identificador do objetivo. | H17: Sim | I17: PK
A18: Objetivos_SMART | B18: tbl_objetivos | C18: ID_Politica | D18: Texto | E18: Entrada | F18: Compromisso da política de origem. | G18: Lista lst_Politica | H18: Sim | I18: FK → tbl_politica
A19: Objetivos_SMART | B19: tbl_objetivos | C19: Origem_Tipo | D19: Texto | E19: Entrada | F19: Tipo de origem (AAS, risco legal...). | G19: Lista lst_OrigemTipo | H19: Sim
A20: Objetivos_SMART | B20: tbl_objetivos | C20: Origem_IDs | D20: Texto | E20: Entrada | F20: IDs de aspetos, riscos e requisitos legais de origem. | H20: Sim | I20: FK → RG-SGA-02/03/04
A21: Objetivos_SMART | B21: tbl_objetivos | C21: Origem_Descricao | D21: Texto | E21: Entrada | F21: Origem do objetivo (enunciado: 'Qual o item da Política, Aspeto ou Lei que lhe deu origem?'). | H21: Sim
A22: Objetivos_SMART | B22: tbl_objetivos | C22: Declaracao_Objetivo | D22: Texto | E22: Entrada | F22: Verbo de ação + substantivo + meta + prazo. | H22: Sim
A23: Objetivos_SMART | B23: tbl_objetivos | C23: ID_KPI | D23: Texto | E23: Entrada | F23: Indicador (régua). | H23: Sim | I23: FK → tbl_kpi
A24: Objetivos_SMART | B24: tbl_objetivos | C24: Indicador_KPI | D24: Texto | E24: Calculado (fórmula) | F24: Nome e unidade do KPI. | H24: Sim
A25: Objetivos_SMART | B25: tbl_objetivos | C25: Baseline | D25: Decimal | E25: Calculado (fórmula) | F25: Linha de base (do catálogo de KPI). | H25: Sim
A26: Objetivos_SMART | B26: tbl_objetivos | C26: Meta_Tipo | D26: Texto | E26: Entrada | F26: Tipo de meta. | G26: Lista lst_MetaTipo | H26: Sim
A27: Objetivos_SMART | B27: tbl_objetivos | C27: Meta_Valor | D27: Percentagem (fração 0-1) | E27: Entrada | F27: Variação relativa (ex.: -8%) ou valor absoluto (ex.: 100%). | H27: Sim
A28: Objetivos_SMART | B28: tbl_objetivos | C28: Meta_Numerica | D28: Decimal | E28: Calculado (fórmula) | F28: Valor numérico do KPI a atingir. | H28: Sim
A29: Objetivos_SMART | B29: tbl_objetivos | C29: Prazo | D29: Data (aaaa-mm-dd) | E29: Entrada | F29: Data limite. | H29: Sim
A30: Objetivos_SMART | B30: tbl_objetivos | C30: Recursos_Humanos | D30: Texto | E30: Entrada | F30: Pessoas envolvidas. | H30: Sim
A31: Objetivos_SMART | B31: tbl_objetivos | C31: Recursos_Materiais | D31: Texto | E31: Entrada | F31: Equipamentos e materiais. | H31: Sim
A32: Objetivos_SMART | B32: tbl_objetivos | C32: Recursos_Financeiros_EUR | D32: Moeda (EUR) | E32: Entrada | F32: Orçamento aprovado (CAPEX + OPEX). | H32: Sim
A33: Objetivos_SMART | B33: tbl_objetivos | C33: Responsavel | D33: Texto | E33: Entrada | F33: Responsável pelo objetivo. | G33: Lista lst_Funcao | H33: Sim
A34: Objetivos_SMART | B34: tbl_objetivos | C34: Acoes_PAM | D34: Texto | E34: Entrada | F34: Ações do programa no PAM. | H34: Sim | I34: FK → RG-SGA-06
A35: Objetivos_SMART | B35: tbl_objetivos | C35: Estado | D35: Texto | E35: Entrada | F35: Estado do objetivo. | G35: Lista lst_Estado | H35: Sim
A36: Objetivos_SMART | B36: tbl_objetivos | C36: Valor_Atual | D36: Decimal | E36: Entrada | F36: Último valor do KPI (média out–dez/2026; água: ano civil de 2026 por causa da sazonalidade; PPWR/granulado: situação em 31/12/2026). | H36: Não
A37: Objetivos_SMART | B37: tbl_objetivos | C37: Progresso | D37: Percentagem (fração 0-1) | E37: Calculado (fórmula) | F37: Percentagem do caminho baseline → meta já percorrido (negativo = afastou-se). | H37: Sim
A38: Objetivos_SMART | B38: tbl_objetivos | C38: Dias_ate_Prazo | D38: Inteiro | E38: Calculado (fórmula) | F38: Dias até ao prazo. | H38: Sim
A39: Objetivos_SMART | B39: tbl_objetivos | C39: S_Especifico | D39: Texto | E39: Calculado (fórmula) | F39: S: declaração clara e ligada a um indicador. | H39: Sim
A40: Objetivos_SMART | B40: tbl_objetivos | C40: M_Mensuravel | D40: Texto | E40: Calculado (fórmula) | F40: M: meta numérica. | H40: Sim
...
