Workbook
Name DataRef: Listas!$A$3
Name lst_Cat6M: Listas!$G$3:$G$8
Name lst_Classificacao: Listas!$E$3:$E$5
Name lst_DataReferencia: Listas!$A$3:$A$3
Name lst_Eficacia: Listas!$J$3:$J$5
Name lst_Estado: Listas!$I$3:$I$5
Name lst_Funcao: Listas!$L$3:$L$24
Name lst_INC_Cond: Listas!$O$3:$O$4
Name lst_INC_Estado: Listas!$R$3:$R$5
Name lst_INC_Meio: Listas!$N$3:$N$10
Name lst_INC_SimNao: Listas!$Q$3:$Q$4
Name lst_INC_Tipo: Listas!$M$3:$M$11
Name lst_INC_Turno: Listas!$P$3:$P$5
Name lst_Metodo: Listas!$H$3:$H$6
Name lst_Origem: Listas!$B$3:$B$10
Name lst_Processo: Listas!$C$3:$C$18
Name lst_Severidade: Listas!$F$3:$F$5
Name lst_SimNao: Listas!$K$3:$K$4
Name lst_TipoRegisto: Listas!$D$3:$D$5

Sheet 00_LEIA-ME
A1: RG-SGA-07 — Relatórios de Não Conformidade, Incidentes e Ações Corretivas (RNC)
A2: Sistema de Gestão Ambiental NP EN ISO 14001:2026 · Plasticom — Unidade 1 (Marinha Grande, Portugal) · Registo do SGA (fábrica simulada)
A4: CONTROLO DO DOCUMENTO (7.5 — informação documentada)
A5: Código do registo | B5: RG-SGA-07
A6: Título | B6: Relatórios de Não Conformidade, Incidentes e Ações Corretivas (RNC)
A7: Versão / Revisão | B7: 01
A8: Data de emissão | B8: 46387
A9: Elaborado por | B9: Gestor(a) do SGA / EHS
A10: Aprovado por | B10: Diretor Geral
A11: Estado | B11: Em vigor
A12: Retenção | B12: 5 anos após substituição
A13: Localização | B13: Repositório controlado do SGA > Registos_SGA_Plasticom (versão eletrónica é a versão controlada; cópias impressas são não controladas)
A15: FINALIDADE E ÂMBITO
A16: Finalidade | B16: Registar cada não conformidade e incidente ambiental com evidência objetiva, requisito violado, correção imediata, análise de causa raiz (5 Porquês em formato de tabela), ligação às ações C1/C2 no PAM, prazo, fecho e verificação da eficácia. Inclui histórico de 2025-2026 para análise de tempos de resposta, recorrência e eficácia.
A17: Atividades do curso | B17: Atividade 6.1 — Tarefa 1 (5 Porquês do kit antipoluição, NC-SGA-26-03) e registo das NC originadas nas Atividades 3.3 e 5.3.
A18: Requisitos ISO 14001:2026 | B18: 10.2 Não conformidade e ação corretiva (ISO 14001:2026: reagir, controlar e corrigir, lidar com as consequências, avaliar a necessidade de eliminar a causa, rever a eficácia); 8.2; 9.1.2
A20: ESTRUTURA DO FICHEIRO
A21: Registo_NC | B21: Registo de não conformidades e incidentes ambientais (1 linha por NC).
A22: Cinco_Porques | B22: Análise dos 5 Porquês em formato longo (1 linha por nível) — permite análise de texto e de padrões de causa.
A23: RNC_Formulario | B23: Relatório de Não Conformidade (formato de impressão) da NC selecionada em B5 — por defeito NC-SGA-26-03 (Atividade 6.1).
A24: Indicadores_NC | B24: Indicadores calculados: NC por origem e estado, tempo médio de fecho, eficácia e recorrência.
A25: Registo_Incidentes | B25: Registo de incidentes, quase-incidentes, condições anormais e reclamações ambientais (1 linha por ocorrência).
A26: Listas | B26: Domínios (listas de valores) usados na validação de dados das tabelas.
A27: Dicionario_Dados | B27: Descrição de cada coluna de cada tabela: tipo, origem (entrada/calculado), domínio, obrigatoriedade e chaves.
A29: CONVENÇÕES (prontas para análise de dados e machine learning)
A30: Tabelas | B30: Cada registo é uma Tabela Excel com nome próprio (tbl_*): uma linha = um registo, cabeçalho único, sem células mescladas. Ler com pandas (pd.read_excel(ficheiro, sheet_name=folha, header=<linha do cabeçalho - 1>)) ou Power BI (Obter Dados > Tabela).
A31: Cabeçalho cinzento | B31: Coluna CALCULADA por fórmula — não escrever por cima. As restantes colunas são de entrada.
A32: Validação | B32: Colunas com lista controlada só aceitam valores da folha Listas (evita categorias duplicadas por grafia diferente).
A33: Chaves | B33: IDs estáveis e únicos (PK) e referências a IDs de outros registos (FK) permitem juntar tabelas entre ficheiros — ver SGA-00_Indice_Modelo_Dados.xlsx.
A34: Datas e unidades | B34: Datas em formato data (aaaa-mm-dd); números como números; a unidade está no nome da coluna ou no dicionário. Data de referência do SGA: 2026-12-31 (fecho do ano).
A35: Dados simulados | B35: Fábrica simulada Plasticom. Dados operacionais derivados do dataset do projeto (datasets/silver); dados ambientais e de conformidade são simulação didática — confirmar aplicabilidade legal e números antes de uso real.
A37: LIGAÇÕES A OUTROS REGISTOS
A38: RG-SGA-06 PAM | B38: ID_PAM_C1 / ID_PAM_C2 ligam as ações de correção e corretivas.
A39: RG-SGA-10 Rondas / RG-SGA-14 Auditoria / RG-SGA-04 Legal | B39: ID_Origem indica o registo que detetou a NC.

Sheet Registo_NC
A1: REGISTO DE NÃO CONFORMIDADES E INCIDENTES AMBIENTAIS — PLASTICOM
A2: Reagir → corrigir (C1) → analisar a causa → ação corretiva (C2) → verificar a eficácia · Dias, prazo e controlo de qualidade calculados
A4: ID_NC | B4: Data_Detecao | C4: Origem | D4: ID_Origem | E4: Processo | F4: Local | G4: Tipo_Registo | H4: Classificacao | I4: Requisito_Violado | J4: Descricao | K4: Evidencia_Objetiva | L4: Impacte_Potencial | M4: Severidade | N4: Correcao_C1 | O4: Causa_Raiz | P4: Categoria_6M | Q4: Metodo_Analise | R4: N_Porques | S4: ID_PAM_C1 | T4: ID_PAM_C2 | U4: Responsavel | V4: Prazo | W4: Estado | X4: Data_Fecho | Y4: Dias_Aberta | Z4: No_Prazo | AA4: Eficacia | AB4: Data_Verif_Eficacia | AC4: Recorrente | AD4: Custo_EUR | AE4: Reportado_Por | AF4: Controlo_Qualidade
A5: NC-SGA-25-01 | B5: 45924 | C5: Auditoria interna | D5: AUD-2025-01 | E5: ARQ | F5: Armazém de químicos | G5: Não conformidade | H5: NC Menor | I5: 6.1.3 / REACH-CLP | J5: 5 FDS em falta no ponto de uso da serigrafia. | K5: Dossier de FDS da SS-001 sem as FDS de 5 tintas novas. | L5: Exposição e resposta inadequada em derrame. | M5: Baixa | N5: Imprimir e colocar as 5 FDS no posto. | O5: Receção de novos químicos sem verificação de FDS. | P5: Método | Q5: 5 Porquês | R5: =COUNTIF(tbl_5porques[ID_NC],A5) -> 0 | U5: Responsável de Armazém e Logística | V5: 45961 | W5: Fechada | X5: 45950 | Y5: =IF(X5="",DataRef-B5,X5-B5) -> 26 | Z5: =IF(X5="",IF(V5<DataRef,"Atrasada","Em curso"),IF(X5<=V5,"Sim","Não")) -> Sim | AA5: Eficaz | AB5: 46037 | AC5: Não | AD5: 0 | AE5: Auditor interno | AF5: =IF(AND(H5<>"",O5=""),"FALTA causa raiz",IF(AND(W5="Fechada",AA5="Por avaliar",AB5<DataRef),"FALTA verificar eficácia",IF(AND(W5<>"Fechada",T5="",P5<>""),"FALTA ação corretiva (C2)","OK"))) -> OK
A6: NC-SGA-25-02 | B6: 45944 | C6: Avaliação da conformidade legal | D6: LEG-13 | E6: PRS | F6: Parque de resíduos | G6: Não conformidade | H6: NC Legal | I6: Portaria 145/2017 (e-GAR) | J6: 2 e-GAR de setembro sem confirmação de receção pelo destinatário após 30 dias. | K6: Consulta SILiAmb de 14/10/2025. | L6: Rastreabilidade de resíduos incompleta. | M6: Média | N6: Contactar o operador e obter a confirmação no SILiAmb. | O6: Sem conferência mensal das e-GAR. | P6: Método | Q6: 5 Porquês | R6: =COUNTIF(tbl_5porques[ID_NC],A6) -> 0 | U6: Responsável de Armazém e Logística | V6: 45976 | W6: Fechada | X6: 45966 | Y6: =IF(X6="",DataRef-B6,X6-B6) -> 22 | Z6: =IF(X6="",IF(V6<DataRef,"Atrasada","Em curso"),IF(X6<=V6,"Sim","Não")) -> Sim | AA6: Eficaz | AB6: 46063 | AC6: Não | AD6: 0 | AE6: Gestor do SGA | AF6: =IF(AND(H6<>"",O6=""),"FALTA causa raiz",IF(AND(W6="Fechada",AA6="Por avaliar",AB6<DataRef),"FALTA verificar eficácia",IF(AND(W6<>"Fechada",T6="",P6<>""),"FALTA ação corretiva (C2)","OK"))) -> OK
A7: NC-SGA-25-03 | B7: 45979 | C7: Incidente ambiental | D7: INC-2025-07 | E7: UTL | F7: Chiller CH-01 | G7: Incidente ambiental | H7: NC Menor | I7: 8.1 / Reg. (UE) 2024/573 | J7: Fuga de 3,2 kg de R410A no chiller CH-01 (6,7 tCO2e). | K7: Relatório do técnico certificado de 18/11/2025. | L7: Emissão de gás com efeito de estufa. | M7: Média | N7: Reparação da brasagem e reposição de carga por técnico certificado. | O7: Corrosão de uma brasagem por vibração (suporte sem amortecedor). | P7: Máquina | Q7: Ishikawa | R7: =COUNTIF(tbl_5porques[ID_NC],A7) -> 0 | U7: Gerente de Manutenção | V7: 46006 | W7: Fechada | X7: 46001 | Y7: =IF(X7="",DataRef-B7,X7-B7) -> 22 | Z7: =IF(X7="",IF(V7<DataRef,"Atrasada","Em curso"),IF(X7<=V7,"Sim","Não")) -> Sim | AA7: Eficaz | AB7: 46162 | AC7: Não | AD7: 1450 | AE7: Técnico de manutenção | AF7: =IF(AND(H7<>"",O7=""),"FALTA causa raiz",IF(AND(W7="Fechada",AA7="Por avaliar",AB7<DataRef),"FALTA verificar eficácia",IF(AND(W7<>"Fechada",T7="",P7<>""),"FALTA ação corretiva (C2)","OK"))) -> OK
A8: NC-SGA-26-00 | B8: 46064 | C8: Incidente ambiental | D8: INC-2026-02 | E8: SOP | F8: ISBM-005 | G8: Incidente ambiental | H8: NC Menor | I8: 8.1 | J8: Fuga de ≈ 15 L de óleo hidráulico da ISBM-005 para o pavimento (contida com absorventes). | K8: Registo de incidente e ordem de trabalho de 11/02/2026. | L8: Contaminação do solo (contida). | M8: Média | N8: Contenção com absorventes; limpeza; encaminhamento 15 02 02*. | O8: Mangueira hidráulica envelhecida sem substituição preventiva por horas de operação. | P8: Máquina | Q8: 5 Porquês | R8: =COUNTIF(tbl_5porques[ID_NC],A8) -> 0 | U8: Gerente de Manutenção | V8: 46112 | W8: Fechada | X8: 46101 | Y8: =IF(X8="",DataRef-B8,X8-B8) -> 37 | Z8: =IF(X8="",IF(V8<DataRef,"Atrasada","Em curso"),IF(X8<=V8,"Sim","Não")) -> Sim | AA8: Eficaz | AB8: 46204 | AC8: Não | AD8: 900 | AE8: Operador de sopro | AF8: =IF(AND(H8<>"",O8=""),"FALTA causa raiz",IF(AND(W8="Fechada",AA8="Por avaliar",AB8<DataRef),"FALTA verificar eficácia",IF(AND(W8<>"Fechada",T8="",P8<>""),"FALTA ação corretiva (C2)","OK"))) -> OK
A9: NC-SGA-26-01 | B9: 46275 | C9: Avaliação da conformidade legal | D9: LEG-05 | E9: UTL | F9: Sala de compressores | G9: Não conformidade | H9: NC Legal | I9: DL 9/2007 (RGR); 6.3 | J9: Sem avaliação acústica após a substituição dos compressores (fev/2026). | K9: Último relatório acústico AC-2023-041 (09/2023). | L9: Incomodidade da vizinhança; coima. | M9: Média | N9: Contratar avaliação acústica (PAM-26-03). | O9: Gestão de mudanças sem checklist ambiental/legal. | P9: Método | Q9: 5 Porquês | R9: =COUNTIF(tbl_5porques[ID_NC],A9) -> 4 | S9: PAM-26-03 | T9: PAM-26-17 | U9: Gestor do SGA / EHS (Responsável Ambiental) | V9: 46356 | W9: Fechada | X9: 46351 | Y9: =IF(X9="",DataRef-B9,X9-B9) -> 76 | Z9: =IF(X9="",IF(V9<DataRef,"Atrasada","Em curso"),IF(X9<=V9,"Sim","Não")) -> Sim | AA9: Por avaliar | AB9: 46492 | AC9: Não | AD9: 1800 | AE9: Gestor do SGA | AF9: =IF(AND(H9<>"",O9=""),"FALTA causa raiz",IF(AND(W9="Fechada",AA9="Por avaliar",AB9<DataRef),"FALTA verificar eficácia",IF(AND(W9<>"Fechada",T9="",P9<>""),"FALTA ação corretiva (C2)","OK"))) -> OK
A10: NC-SGA-26-02 | B10: 46275 | C10: Avaliação da conformidade legal | D10: LEG-09 | E10: RD | F10: R&D / Dossier de produto | G10: Não conformidade | H10: NC Legal | I10: Reg. (UE) 2025/40 (PPWR); 6.1.3 | J10: Só 9 de 22 famílias com documentação técnica e declaração UE de conformidade PPWR. | K10: Lista de dossiers de 10/09/2026. | L10: Impossibilidade de colocar no mercado; coima. | M10: Alta | N10: Priorizar as famílias de maior volume. | O10: Vigilância legal sem regulamentos europeus de produto. | P10: Método | Q10: 5 Porquês | R10: =COUNTIF(tbl_5porques[ID_NC],A10) -> 0 | T10: PAM-26-10 | U10: Responsável de R&D | V10: 46568 | W10: Em tratamento | Y10: =IF(X10="",DataRef-B10,X10-B10) -> 112 | Z10: =IF(X10="",IF(V10<DataRef,"Atrasada","Em curso"),IF(X10<=V10,"Sim","Não")) -> Em curso | AA10: Por avaliar | AB10: 46402 | AC10: Não | AD10: 26000 | AE10: Gestor do SGA | AF10: =IF(AND(H10<>"",O10=""),"FALTA causa raiz",IF(AND(W10="Fechada",AA10="Por avaliar",AB10<DataRef),"FALTA verificar eficácia",IF(AND(W10<>"Fechada",T10="",P10<>""),"FALTA ação corretiva (C2)","OK"))) -> OK
A11: NC-SGA-26-03 | B11: 46280 | C11: Ronda ambiental | D11: RON-06 | E11: INJ | F11: Zona entre injeção e serigrafia (kit KIT-03) | G11: Não conformidade | H11: NC Menor | I11: 8.2; 7.2; 7.3 | J11: Kit antipoluição com selo quebrado, praticamente vazio e sem qualquer registo de utilização. | K11: Ronda ambiental mensal de 15/09/2026: KIT-03 com 1 de 12 almofadas absorventes, sem barreiras nem luvas; selo partido; registo de incidentes sem entradas desde 02/2026. | L11: Derrame não contido no próximo evento; derrame anterior não investigado. | M11: Média | N11: Reposição imediata e selagem (PAM-26-04). | O11: IT-SGA-01 sem etapa pós-uso, sem stock mínimo nem responsável pela reposição; formação não cobre o ciclo pós-utilização. | P11: Método | Q11: 5 Porquês | R11: =COUNTIF(tbl_5porques[ID_NC],A11) -> 5 | S11: PAM-26-04 | T11: PAM-26-05 | U11: Gestor do SGA / EHS (Responsável Ambiental) | V11: 46326 | W11: Fechada | X11: 46324 | Y11: =IF(X11="",DataRef-B11,X11-B11) -> 44 | Z11: =IF(X11="",IF(V11<DataRef,"Atrasada","Em curso"),IF(X11<=V11,"Sim","Não")) -> Sim | AA11: Eficaz | AB11: 46371 | AC11: Não | AD11: 1130 | AE11: Gestor do SGA (ronda) | AF11: =IF(AND(H11<>"",O11=""),"FALTA causa raiz",IF(AND(W11="Fechada",AA11="Por avaliar",AB11<DataRef),"FALTA verificar eficácia",IF(AND(W11<>"Fechada",T11="",P11<>""),"FALTA ação corretiva (C2)","OK"))) -> OK
A12: NC-SGA-26-04 | B12: 46281 | C12: Auditoria interna | D12: CONST-01 | E12: ARQ | F12: Armazém de químicos | G12: Não conformidade | H12: NC Menor | I12: 8.1 | J12: 3 bidões de 200 L de óleo hidráulico novo no chão, sem bacia de retenção. | K12: Observação direta na auditoria de 16/09/2026 (fotografia AUD-01-F03). | L12: Contaminação do solo em caso de rotura. | M12: Média | N12: Transferir os bidões para bacia provisória. | O12: Capacidade de retenção não dimensionada para o stock máximo. | P12: Material | Q12: 5 Porquês | R12: =COUNTIF(tbl_5porques[ID_NC],A12) -> 3 | T12: PAM-26-19 | U12: Responsável de Armazém e Logística | V12: 46310 | W12: Fechada | X12: 46315 | Y12: =IF(X12="",DataRef-B12,X12-B12) -> 34 | Z12: =IF(X12="",IF(V12<DataRef,"Atrasada","Em curso"),IF(X12<=V12,"Sim","Não")) -> Não | AA12: Eficaz | AB12: 46361 | AC12: Não | AD12: 1200 | AE12: Auditor interno | AF12: =IF(AND(H12<>"",O12=""),"FALTA causa raiz",IF(AND(W12="Fechada",AA12="Por avaliar",AB12<DataRef),"FALTA verificar eficácia",IF(AND(W12<>"Fechada",T12="",P12<>""),"FALTA ação corretiva (C2)","OK"))) -> OK
A13: NC-SGA-26-05 | B13: 46281 | C13: Auditoria interna | D13: CONST-03 | E13: PRS | F13: Parque de resíduos | G13: Não conformidade | H13: NC Menor | I13: 8.1; DL 102-D/2020 | J13: Contentor de absorventes contaminados (15 02 02*) sem identificação LER e sem tampa. | K13: Observação direta (fotografia AUD-01-F07). | L13: Mistura de resíduos; escorrência em chuva. | M13: Baixa | N13: Colocar tampa e etiqueta provisória. | O13: Sem etiquetas padronizadas nem verificação na ronda. | P13: Material | Q13: 5 Porquês | R13: =COUNTIF(tbl_5porques[ID_NC],A13) -> 0 | T13: PAM-26-15 | U13: Responsável de Armazém e Logística | V13: 46310 | W13: Fechada | X13: 46309 | Y13: =IF(X13="",DataRef-B13,X13-B13) -> 28 | Z13: =IF(X13="",IF(V13<DataRef,"Atrasada","Em curso"),IF(X13<=V13,"Sim","Não")) -> Sim | AA13: Eficaz | AB13: 46361 | AC13: Não | AD13: 400 | AE13: Auditor interno | AF13: =IF(AND(H13<>"",O13=""),"FALTA causa raiz",IF(AND(W13="Fechada",AA13="Por avaliar",AB13<DataRef),"FALTA verificar eficácia",IF(AND(W13<>"Fechada",T13="",P13<>""),"FALTA ação corretiva (C2)","OK"))) -> OK
A14: NC-SGA-26-06 | B14: 46282 | C14: Auditoria interna | D14: CONST-05 | E14: UTL | F14: Manutenção / engenharia | G14: Não conformidade | H14: NC Menor | I14: 6.3 Planeamento de alterações | J14: Substituição dos compressores (fev/2026) sem avaliação de aspetos, requisitos legais e riscos. | K14: Pedido de investimento INV-2026-004 sem análise ambiental. | L14: Novos impactes não avaliados (ruído). | M14: Média | N14: — | O14: Processo de gestão de mudanças inexistente. | P14: Método | Q14: 5 Porquês | R14: =COUNTIF(tbl_5porques[ID_NC],A14) -> 0 | T14: PAM-26-17 | U14: Gestor do SGA / EHS (Responsável Ambiental) | V14: 46356 | W14: Fechada | X14: 46351 | Y14: =IF(X14="",DataRef-B14,X14-B14) -> 69 | Z14: =IF(X14="",IF(V14<DataRef,"Atrasada","Em curso"),IF(X14<=V14,"Sim","Não")) -> Sim | AA14: Por avaliar | AB14: 46492 | AC14: Não | AD14: 0 | AE14: Auditor interno | AF14: =IF(AND(H14<>"",O14=""),"FALTA causa raiz",IF(AND(W14="Fechada",AA14="Por avaliar",AB14<DataRef),"FALTA verificar eficácia",IF(AND(W14<>"Fechada",T14="",P14<>""),"FALTA ação corretiva (C2)","OK"))) -> OK
A15: NC-SGA-26-07 | B15: 46282 | C15: Auditoria interna | D15: CONST-06 | E15: PRS | F15: Parque de resíduos | G15: Não conformidade | H15: NC Menor | I15: 9.1.1 | J15: Balança de plataforma do parque de resíduos sem verificação desde 03/2024. | K15: Etiqueta de verificação de 03/2024; plano de calibração sem o equipamento. | L15: Dados de resíduos (MIRR) pouco fiáveis. | M15: Baixa | N15: Suspender o uso da balança até à verificação (usar a balança da expedição). | O15: Inventário de equipamentos de medição ambiental incompleto. | P15: Medição | Q15: 5 Porquês | R15: =COUNTIF(tbl_5porques[ID_NC],A15) -> 0 | T15: PAM-26-20 | U15: Gerente da Qualidade | V15: 46326 | W15: Fechada | X15: 46318 | Y15: =IF(X15="",DataRef-B15,X15-B15) -> 36 | Z15: =IF(X15="",IF(V15<DataRef,"Atrasada","Em curso"),IF(X15<=V15,"Sim","Não")) -> Sim | AA15: Eficaz | AB15: 46371 | AC15: Não | AD15: 350 | AE15: Auditor interno | AF15: =IF(AND(H15<>"",O15=""),"FALTA causa raiz",IF(AND(W15="Fechada",AA15="Por avaliar",AB15<DataRef),"FALTA verificar eficácia",IF(AND(W15<>"Fechada",T15="",P15<>""),"FALTA ação corretiva (C2)","OK"))) -> OK
A16: NC-SGA-26-08 | B16: 46282 | C16: Auditoria interna | D16: CONST-07 | E16: SER | F16: Serigrafia SS-001 | G16: Não conformidade | H16: NC Menor | I16: 7.2; 7.3 | J16: Operador do turno 2 sem formação na instrução de limpeza de ecrãs; 2 latas de solvente abertas no posto. | K16: Entrevista e observação; matriz de competências sem registo. | L16: Emissões de COV e risco de incêndio. | M16: Média | N16: Fechar as latas; formação imediata no posto. | O16: Integração de operadores temporários sem formação ambiental. | P16: Mão de obra | Q16: 5 Porquês | R16: =COUNTIF(tbl_5porques[ID_NC],A16) -> 0 | T16: PAM-26-08 | U16: Gestor do SGA / EHS (Responsável Ambiental) | V16: 46341 | W16: Fechada | X16: 46336 | Y16: =IF(X16="",DataRef-B16,X16-B16) -> 54 | Z16: =IF(X16="",IF(V16<DataRef,"Atrasada","Em curso"),IF(X16<=V16,"Sim","Não")) -> Sim | AA16: Eficaz | AB16: 46366 | AC16: Sim | AD16: 0 | AE16: Auditor interno | AF16: =IF(AND(H16<>"",O16=""),"FALTA causa raiz",IF(AND(W16="Fechada",AA16="Por avaliar",AB16<DataRef),"FALTA verificar eficácia",IF(AND(W16<>"Fechada",T16="",P16<>""),"FALTA ação corretiva (C2)","OK"))) -> OK
A17: NC-SGA-26-09 | B17: 46282 | C17: Auditoria interna | D17: CONST-10 | E17: GER | F17: Plano de emergência | G17: Não conformidade | H17: NC Menor | I17: 8.2 | J17: Nunca foi feito simulacro de derrame; no simulacro de incêndio a válvula de corte pluvial demorou 9 min (meta ≤ 5 min). | K17: Relatório de simulacro de 14/11/2025; plano de simulacros 2026. | L17: Resposta ineficaz a emergência ambiental. | M17: Média | N17: — | O17: Plano de simulacros só cobre requisitos SCIE (incêndio). | P17: Método | Q17: 5 Porquês | R17: =COUNTIF(tbl_5porques[ID_NC],A17) -> 0 | T17: PAM-26-21 | U17: Gestor do SGA / EHS (Responsável Ambiental) | V17: 46371 | W17: Fechada | X17: 46367 | Y17: =IF(X17="",DataRef-B17,X17-B17) -> 85 | Z17: =IF(X17="",IF(V17<DataRef,"Atrasada","Em curso"),IF(X17<=V17,"Sim","Não")) -> Sim | AA17: Eficaz | AB17: 46367 | AC17: Não | AD17: 800 | AE17: Auditor interno | AF17: =IF(AND(H17<>"",O17=""),"FALTA causa raiz",IF(AND(W17="Fechada",AA17="Por avaliar",AB17<DataRef),"FALTA verificar eficácia",IF(AND(W17<>"Fechada",T17="",P17<>""),"FALTA ação corretiva (C2)","OK"))) -> OK
A18: NC-SGA-26-10 | B18: 46332 | C18: Incidente ambiental | D18: INC-2026-12 | E18: INJ | F18: Injetora IM-004 | G18: Não conformidade | H18: NC Menor | I18: 8.1; 8.2 | J18: Fuga de ≈ 8 L de óleo hidráulico da IM-004 para o pavimento, sem tabuleiro de retenção sob a unidade hidráulica. | K18: Ronda do turno 1 de 06/11/2026; fotografias; OT-2026-24. | L18: Contaminação do solo / rede pluvial se não contida. | M18: Média | N18: Contenção com o KIT-02, limpeza e resíduo 15 02 02* (OT-2026-24). | O18: Mangueiras hidráulicas das injetoras antigas fora do plano de substituição por horas (só a ISBM-005 tinha plano) e unidade hidráulica sem tabuleiro. | P18: Máquina | Q18: 5 Porquês | R18: =COUNTIF(tbl_5porques[ID_NC],A18) -> 0 | U18: Gerente de Manutenção | V18: 46371 | W18: Fechada | X18: 46360 | Y18: =IF(X18="",DataRef-B18,X18-B18) -> 28 | Z18: =IF(X18="",IF(V18<DataRef,"Atrasada","Em curso"),IF(X18<=V18,"Sim","Não")) -> Sim | AA18: Eficaz | AB18: 46374 | AC18: Sim | AD18: 1300 | AE18: Operador de Injeção | AF18: =IF(AND(H18<>"",O18=""),"FALTA causa raiz",IF(AND(W18="Fechada",AA18="Por avaliar",AB18<DataRef),"FALTA verificar eficácia",IF(AND(W18<>"Fechada",T18="",P18<>""),"FALTA ação corretiva (C2)","OK"))) -> OK
A19: NC-SGA-26-11 | B19: 46345 | C19: Auditoria interna | D19: CONST-14 | E19: CMP | F19: Compras / R&D | G19: Não conformidade | H19: NC Menor | I19: 8.1; 9.1.1; ISO 14021 | J19: Lotes de rPET de jul a out/2026 recebidos com o certificado EN 15343 expirado e contados como reciclado no KPI e nas fichas técnicas. | K19: AUD-2026-02: CERT-03 expirado a 30/06/2026; 6 lotes de rPET sem prova. | L19: Alegação de conteúdo reciclado sem prova perante clientes. | M19: Média | N19: Lotes reclassificados como virgem no KPI; clientes afetados informados (2). | O19: O controlo de validade dos certificados não bloqueava a receção (verificação só anual). | P19: Método | Q19: 5 Porquês | R19: =COUNTIF(tbl_5porques[ID_NC],A19) -> 0 | T19: PAM-26-25 | U19: Responsável de Compras | V19: 46387 | W19: Fechada | X19: 46374 | Y19: =IF(X19="",DataRef-B19,X19-B19) -> 29 | Z19: =IF(X19="",IF(V19<DataRef,"Atrasada","Em curso"),IF(X19<=V19,"Sim","Não")) -> Sim | AA19: Por avaliar | AB19: 46477 | AC19: Não | AD19: 400 | AE19: Auditor externo | AF19: =IF(AND(H19<>"",O19=""),"FALTA causa raiz",IF(AND(W19="Fechada",AA19="Por avaliar",AB19<DataRef),"FALTA verificar eficácia",IF(AND(W19<>"Fechada",T19="",P19<>""),"FALTA ação corretiva (C2)","OK"))) -> OK

Sheet Cinco_Porques
A1: ID_NC | B1: Nivel | C1: Chave | D1: Pergunta_Porque | E1: Resposta | F1: Evidencia | G1: E_Causa_Raiz
A2: NC-SGA-26-03 | B2: 1 | C2: =A2&"|"&B2 -> NC-SGA-26-03|1 | D2: Porque é que o kit está vazio? | E2: Porque alguém o usou para conter um derrame (provavelmente óleo ou tinta na zona injeção/serigrafia, em agosto) e o conteúdo não foi reposto. | F2: Selo partido; absorventes em falta; manchas de óleo junto à IM-006. | G2: Não
A3: NC-SGA-26-03 | B3: 2 | C3: =A3&"|"&B3 -> NC-SGA-26-03|2 | D3: Porque é que não foi reposto? | E3: Porque quem o usou não avisou o armazém nem o Gestor do SGA e ninguém ficou responsável por repor. | F3: Nenhum pedido de material nem registo de incidente em ago–set/2026. | G3: Não
A4: NC-SGA-26-03 | B4: 3 | C4: =A4&"|"&B4 -> NC-SGA-26-03|3 | D4: Porque é que não avisou? | E4: Porque a IT-SGA-01 (derrames) termina na limpeza: não diz que é obrigatório registar o incidente, pedir reposição e voltar a selar. | F4: IT-SGA-01 rev. 00, passos 1 a 6. | G4: Não
A5: NC-SGA-26-03 | B5: 4 | C5: =A5&"|"&B5 -> NC-SGA-26-03|4 | D5: Porque é que a instrução não prevê o pós-uso? | E5: Porque foi escrita apenas para a resposta imediata; não existe stock mínimo de kits nem responsável pela reposição. | F5: Sem artigo 'kit de derrame' no stock do armazém. | G5: Não
A6: NC-SGA-26-03 | B6: 5 | C6: =A6&"|"&B6 -> NC-SGA-26-03|5 | D6: Porque é que a falha não foi detetada mais cedo? | E6: Porque a ronda só verificava se o kit estava no lugar (não o selo nem o conteúdo) e a formação de derrames ensinou a usar o kit, não o ciclo pós-utilização. | F6: Checklist RON-06 antigo: 'kit presente? S/N'; plano de formação 2025. | G6: Sim
A7: NC-SGA-26-01 | B7: 1 | C7: =A7&"|"&B7 -> NC-SGA-26-01|1 | D7: Porque não existe avaliação acústica recente? | E7: Ninguém a pediu após a troca dos compressores. | F7: Pedido de investimento INV-2026-004. | G7: Não
A8: NC-SGA-26-01 | B8: 2 | C8: =A8&"|"&B8 -> NC-SGA-26-01|2 | D8: Porque ninguém a pediu? | E8: A alteração foi tratada só como investimento técnico. | F8: Aprovação pela Direção Industrial sem parecer do SGA. | G8: Não
A9: NC-SGA-26-01 | B9: 3 | C9: =A9&"|"&B9 -> NC-SGA-26-01|3 | D9: Porque não houve parecer do SGA? | E9: O pedido de alteração não tem checklist ambiental/legal. | F9: Formulário de investimento em vigor. | G9: Não
A10: NC-SGA-26-01 | B10: 4 | C10: =A10&"|"&B10 -> NC-SGA-26-01|4 | D10: Porque não tem checklist? | E10: O processo de planeamento de alterações (6.3 da ISO 14001:2026) ainda não foi implementado. | F10: Lista mestra de documentos sem procedimento de mudanças. | G10: Sim
A11: NC-SGA-26-04 | B11: 1 | C11: =A11&"|"&B11 -> NC-SGA-26-04|1 | D11: Porque estão os bidões no chão? | E11: As bacias existentes estavam cheias. | F11: 2 bacias com 4 bidões; 3 bidões fora. | G11: Não
A12: NC-SGA-26-04 | B12: 2 | C12: =A12&"|"&B12 -> NC-SGA-26-04|2 | D12: Porque estavam cheias? | E12: A compra de óleo passou a ser feita em lotes de 5 bidões por causa do desconto. | F12: Encomenda de 08/2026. | G12: Não
A13: NC-SGA-26-04 | B13: 3 | C13: =A13&"|"&B13 -> NC-SGA-26-04|3 | D13: Porque não se ajustou a contenção? | E13: O processo de compras não considera a capacidade de armazenagem com retenção. | F13: Procedimento de compras sem critério de armazenagem. | G13: Sim

Sheet RNC_Formulario
A1: PLASTICOM | B1: RELATÓRIO DE NÃO CONFORMIDADE (RNC) | F1: Mod. RNC-SGA
B2: Plasticom — Unidade 1 (Marinha Grande, Portugal) · NP EN ISO 14001:2026 | F2: Rev. 01 · 31/12/2026
A5: N.º da NC (escolher) | B5: NC-SGA-26-03
A6: Data de deteção | B6: =INDEX(Registo_NC!$B$5:$B$19,MATCH($B$5,Registo_NC!$A$5:$A$19,0)) -> 46280
A7: Origem / referência | B7: =INDEX(Registo_NC!$C$5:$C$19,MATCH($B$5,Registo_NC!$A$5:$A$19,0))&" — "&INDEX(Registo_NC!$D$5:$D$19,MATCH($B$5,Registo_NC!$A$5:$A$19,0)) -> Ronda ambiental — RON-06
A8: Local | B8: =INDEX(Registo_NC!$F$5:$F$19,MATCH($B$5,Registo_NC!$A$5:$A$19,0)) -> Zona entre injeção e serigrafia (kit KIT-03)
A9: Classificação | B9: =INDEX(Registo_NC!$H$5:$H$19,MATCH($B$5,Registo_NC!$A$5:$A$19,0)) -> NC Menor
A10: Requisito violado | B10: =INDEX(Registo_NC!$I$5:$I$19,MATCH($B$5,Registo_NC!$A$5:$A$19,0)) -> 8.2; 7.2; 7.3
A11: Descrição | B11: =INDEX(Registo_NC!$J$5:$J$19,MATCH($B$5,Registo_NC!$A$5:$A$19,0)) -> Kit antipoluição com selo quebrado, praticamente vazio e sem qualquer registo de utilização.
A12: Evidência objetiva | B12: =INDEX(Registo_NC!$K$5:$K$19,MATCH($B$5,Registo_NC!$A$5:$A$19,0)) -> Ronda ambiental mensal de 15/09/2026: KIT-03 com 1 de 12 almofadas absorventes, sem barreiras nem luvas; selo partido; registo de incidentes sem entradas desde 02/2026.
A13: Impacte potencial | B13: =INDEX(Registo_NC!$L$5:$L$19,MATCH($B$5,Registo_NC!$A$5:$A$19,0)) -> Derrame não contido no próximo evento; derrame anterior não investigado.
A14: Correção imediata (C1) | B14: =INDEX(Registo_NC!$N$5:$N$19,MATCH($B$5,Registo_NC!$A$5:$A$19,0)) -> Reposição imediata e selagem (PAM-26-04).
A16: INVESTIGAÇÃO — 5 PORQUÊS
A17: Nível | B17: Pergunta | D17: Resposta | F17: Evidência
A18: =IFERROR(IF(INDEX(Cinco_Porques!$G$2:$G$13,MATCH($B$5&"|1",Cinco_Porques!$C$2:$C$13,0))="Sim","1 ► causa raiz","1"),"") -> 1 | B18: =IFERROR(INDEX(Cinco_Porques!$D$2:$D$13,MATCH($B$5&"|1",Cinco_Porques!$C$2:$C$13,0)),"") -> Porque é que o kit está vazio? | D18: =IFERROR(INDEX(Cinco_Porques!$E$2:$E$13,MATCH($B$5&"|1",Cinco_Porques!$C$2:$C$13,0)),"") -> Porque alguém o usou para conter um derrame (provavelmente óleo ou tinta na zona injeção/serigrafia, em agosto) e o conteúdo não foi reposto. | F18: =IFERROR(INDEX(Cinco_Porques!$F$2:$F$13,MATCH($B$5&"|1",Cinco_Porques!$C$2:$C$13,0)),"") -> Selo partido; absorventes em falta; manchas de óleo junto à IM-006.
A19: =IFERROR(IF(INDEX(Cinco_Porques!$G$2:$G$13,MATCH($B$5&"|2",Cinco_Porques!$C$2:$C$13,0))="Sim","2 ► causa raiz","2"),"") -> 2 | B19: =IFERROR(INDEX(Cinco_Porques!$D$2:$D$13,MATCH($B$5&"|2",Cinco_Porques!$C$2:$C$13,0)),"") -> Porque é que não foi reposto? | D19: =IFERROR(INDEX(Cinco_Porques!$E$2:$E$13,MATCH($B$5&"|2",Cinco_Porques!$C$2:$C$13,0)),"") -> Porque quem o usou não avisou o armazém nem o Gestor do SGA e ninguém ficou responsável por repor. | F19: =IFERROR(INDEX(Cinco_Porques!$F$2:$F$13,MATCH($B$5&"|2",Cinco_Porques!$C$2:$C$13,0)),"") -> Nenhum pedido de material nem registo de incidente em ago–set/2026.
A20: =IFERROR(IF(INDEX(Cinco_Porques!$G$2:$G$13,MATCH($B$5&"|3",Cinco_Porques!$C$2:$C$13,0))="Sim","3 ► causa raiz","3"),"") -> 3 | B20: =IFERROR(INDEX(Cinco_Porques!$D$2:$D$13,MATCH($B$5&"|3",Cinco_Porques!$C$2:$C$13,0)),"") -> Porque é que não avisou? | D20: =IFERROR(INDEX(Cinco_Porques!$E$2:$E$13,MATCH($B$5&"|3",Cinco_Porques!$C$2:$C$13,0)),"") -> Porque a IT-SGA-01 (derrames) termina na limpeza: não diz que é obrigatório registar o incidente, pedir reposição e voltar a selar. | F20: =IFERROR(INDEX(Cinco_Porques!$F$2:$F$13,MATCH($B$5&"|3",Cinco_Porques!$C$2:$C$13,0)),"") -> IT-SGA-01 rev. 00, passos 1 a 6.
A21: =IFERROR(IF(INDEX(Cinco_Porques!$G$2:$G$13,MATCH($B$5&"|4",Cinco_Porques!$C$2:$C$13,0))="Sim","4 ► causa raiz","4"),"") -> 4 | B21: =IFERROR(INDEX(Cinco_Porques!$D$2:$D$13,MATCH($B$5&"|4",Cinco_Porques!$C$2:$C$13,0)),"") -> Porque é que a instrução não prevê o pós-uso? | D21: =IFERROR(INDEX(Cinco_Porques!$E$2:$E$13,MATCH($B$5&"|4",Cinco_Porques!$C$2:$C$13,0)),"") -> Porque foi escrita apenas para a resposta imediata; não existe stock mínimo de kits nem responsável pela reposição. | F21: =IFERROR(INDEX(Cinco_Porques!$F$2:$F$13,MATCH($B$5&"|4",Cinco_Porques!$C$2:$C$13,0)),"") -> Sem artigo 'kit de derrame' no stock do armazém.
A22: =IFERROR(IF(INDEX(Cinco_Porques!$G$2:$G$13,MATCH($B$5&"|5",Cinco_Porques!$C$2:$C$13,0))="Sim","5 ► causa raiz","5"),"") -> 5 ► causa raiz | B22: =IFERROR(INDEX(Cinco_Porques!$D$2:$D$13,MATCH($B$5&"|5",Cinco_Porques!$C$2:$C$13,0)),"") -> Porque é que a falha não foi detetada mais cedo? | D22: =IFERROR(INDEX(Cinco_Porques!$E$2:$E$13,MATCH($B$5&"|5",Cinco_Porques!$C$2:$C$13,0)),"") -> Porque a ronda só verificava se o kit estava no lugar (não o selo nem o conteúdo) e a formação de derrames ensinou a usar o kit, não o ciclo pós-utilização. | F22: =IFERROR(INDEX(Cinco_Porques!$F$2:$F$13,MATCH($B$5&"|5",Cinco_Porques!$C$2:$C$13,0)),"") -> Checklist RON-06 antigo: 'kit presente? S/N'; plano de formação 2025.
A24: CAUSA RAIZ | B24: =INDEX(Registo_NC!$O$5:$O$19,MATCH($B$5,Registo_NC!$A$5:$A$19,0))&"" -> IT-SGA-01 sem etapa pós-uso, sem stock mínimo nem responsável pela reposição; formação não cobre o ciclo pós-utilização.
A25: Categoria (6M) | B25: =INDEX(Registo_NC!$P$5:$P$19,MATCH($B$5,Registo_NC!$A$5:$A$19,0))&"" -> Método
A26: Ação de correção (PAM) | B26: =INDEX(Registo_NC!$S$5:$S$19,MATCH($B$5,Registo_NC!$A$5:$A$19,0))&"" -> PAM-26-04
A27: Ação corretiva (PAM) | B27: =INDEX(Registo_NC!$T$5:$T$19,MATCH($B$5,Registo_NC!$A$5:$A$19,0))&"" -> PAM-26-05
A28: Responsável | B28: =INDEX(Registo_NC!$U$5:$U$19,MATCH($B$5,Registo_NC!$A$5:$A$19,0))&"" -> Gestor do SGA / EHS (Responsável Ambiental)
A29: Prazo | B29: =INDEX(Registo_NC!$V$5:$V$19,MATCH($B$5,Registo_NC!$A$5:$A$19,0)) -> 46326
A30: Estado | B30: =INDEX(Registo_NC!$W$5:$W$19,MATCH($B$5,Registo_NC!$A$5:$A$19,0))&"" -> Fechada
A31: Verificação de eficácia prevista | B31: =INDEX(Registo_NC!$AB$5:$AB$19,MATCH($B$5,Registo_NC!$A$5:$A$19,0)) -> 46371
A33: Elaborado: Gestor(a) do SGA/EHS | D33: Aprovado: Diretor Industrial

Sheet Indicadores_NC
A1: INDICADORES DE NÃO CONFORMIDADES — calculado
A3: Origem | B3: Total | C3: Abertas / em tratamento | D3: Fechadas | E3: Dias médios (fechadas)
A4: Ronda ambiental | B4: =COUNTIF(Registo_NC!$C$5:$C$19,"Ronda ambiental") -> 1 | C4: =COUNTIFS(Registo_NC!$C$5:$C$19,"Ronda ambiental",Registo_NC!$W$5:$W$19,"<>Fechada") -> 0 | D4: =COUNTIFS(Registo_NC!$C$5:$C$19,"Ronda ambiental",Registo_NC!$W$5:$W$19,"Fechada") -> 1 | E4: =IFERROR(AVERAGEIFS(Registo_NC!$Y$5:$Y$19,Registo_NC!$C$5:$C$19,"Ronda ambiental",Registo_NC!$W$5:$W$19,"Fechada"),"") -> 44
A5: Auditoria interna | B5: =COUNTIF(Registo_NC!$C$5:$C$19,"Auditoria interna") -> 8 | C5: =COUNTIFS(Registo_NC!$C$5:$C$19,"Auditoria interna",Registo_NC!$W$5:$W$19,"<>Fechada") -> 0 | D5: =COUNTIFS(Registo_NC!$C$5:$C$19,"Auditoria interna",Registo_NC!$W$5:$W$19,"Fechada") -> 8 | E5: =IFERROR(AVERAGEIFS(Registo_NC!$Y$5:$Y$19,Registo_NC!$C$5:$C$19,"Auditoria interna",Registo_NC!$W$5:$W$19,"Fechada"),"") -> 45.125
A6: Auditoria externa | B6: =COUNTIF(Registo_NC!$C$5:$C$19,"Auditoria externa") -> 0 | C6: =COUNTIFS(Registo_NC!$C$5:$C$19,"Auditoria externa",Registo_NC!$W$5:$W$19,"<>Fechada") -> 0 | D6: =COUNTIFS(Registo_NC!$C$5:$C$19,"Auditoria externa",Registo_NC!$W$5:$W$19,"Fechada") -> 0 | E6: =IFERROR(AVERAGEIFS(Registo_NC!$Y$5:$Y$19,Registo_NC!$C$5:$C$19,"Auditoria externa",Registo_NC!$W$5:$W$19,"Fechada"),"")
A7: Avaliação da conformidade legal | B7: =COUNTIF(Registo_NC!$C$5:$C$19,"Avaliação da conformidade legal") -> 3 | C7: =COUNTIFS(Registo_NC!$C$5:$C$19,"Avaliação da conformidade legal",Registo_NC!$W$5:$W$19,"<>Fechada") -> 1 | D7: =COUNTIFS(Registo_NC!$C$5:$C$19,"Avaliação da conformidade legal",Registo_NC!$W$5:$W$19,"Fechada") -> 2 | E7: =IFERROR(AVERAGEIFS(Registo_NC!$Y$5:$Y$19,Registo_NC!$C$5:$C$19,"Avaliação da conformidade legal",Registo_NC!$W$5:$W$19,"Fechada"),"") -> 49
A8: Monitorização e medição | B8: =COUNTIF(Registo_NC!$C$5:$C$19,"Monitorização e medição") -> 0 | C8: =COUNTIFS(Registo_NC!$C$5:$C$19,"Monitorização e medição",Registo_NC!$W$5:$W$19,"<>Fechada") -> 0 | D8: =COUNTIFS(Registo_NC!$C$5:$C$19,"Monitorização e medição",Registo_NC!$W$5:$W$19,"Fechada") -> 0 | E8: =IFERROR(AVERAGEIFS(Registo_NC!$Y$5:$Y$19,Registo_NC!$C$5:$C$19,"Monitorização e medição",Registo_NC!$W$5:$W$19,"Fechada"),"")
A9: Incidente ambiental | B9: =COUNTIF(Registo_NC!$C$5:$C$19,"Incidente ambiental") -> 3 | C9: =COUNTIFS(Registo_NC!$C$5:$C$19,"Incidente ambiental",Registo_NC!$W$5:$W$19,"<>Fechada") -> 0 | D9: =COUNTIFS(Registo_NC!$C$5:$C$19,"Incidente ambiental",Registo_NC!$W$5:$W$19,"Fechada") -> 3 | E9: =IFERROR(AVERAGEIFS(Registo_NC!$Y$5:$Y$19,Registo_NC!$C$5:$C$19,"Incidente ambiental",Registo_NC!$W$5:$W$19,"Fechada"),"") -> 29
A10: Reclamação de parte interessada | B10: =COUNTIF(Registo_NC!$C$5:$C$19,"Reclamação de parte interessada") -> 0 | C10: =COUNTIFS(Registo_NC!$C$5:$C$19,"Reclamação de parte interessada",Registo_NC!$W$5:$W$19,"<>Fechada") -> 0 | D10: =COUNTIFS(Registo_NC!$C$5:$C$19,"Reclamação de parte interessada",Registo_NC!$W$5:$W$19,"Fechada") -> 0 | E10: =IFERROR(AVERAGEIFS(Registo_NC!$Y$5:$Y$19,Registo_NC!$C$5:$C$19,"Reclamação de parte interessada",Registo_NC!$W$5:$W$19,"Fechada"),"")
A11: Simulacro | B11: =COUNTIF(Registo_NC!$C$5:$C$19,"Simulacro") -> 0 | C11: =COUNTIFS(Registo_NC!$C$5:$C$19,"Simulacro",Registo_NC!$W$5:$W$19,"<>Fechada") -> 0 | D11: =COUNTIFS(Registo_NC!$C$5:$C$19,"Simulacro",Registo_NC!$W$5:$W$19,"Fechada") -> 0 | E11: =IFERROR(AVERAGEIFS(Registo_NC!$Y$5:$Y$19,Registo_NC!$C$5:$C$19,"Simulacro",Registo_NC!$W$5:$W$19,"Fechada"),"")
A13: Taxa de eficácia (fechadas verificadas) | B13: =IFERROR(COUNTIF(Registo_NC!$AA$5:$AA$19,"Eficaz")/COUNTIFS(Registo_NC!$AA$5:$AA$19,"<>Por avaliar"),"") -> 1
A14: NC recorrentes | B14: =COUNTIF(Registo_NC!$AC$5:$AC$19,"Sim") -> 2
A15: Custo total das NC (€) | B15: =SUM(Registo_NC!$AD$5:$AD$19) -> 35730

Sheet Registo_Incidentes
A1: REGISTO DE INCIDENTES E QUASE-INCIDENTES AMBIENTAIS
A2: Todos os incidentes são registados; os que exigem ação corretiva abrem NC (ID_NC) · Condição anormal ≠ emergência (ISO 14001:2026 6.1.2)
A4: ID_Incidente | B4: Data | C4: Ano_Mes | D4: Tipo | E4: Processo | F4: Local | G4: Descricao | H4: Substancia | I4: Quantidade | J4: Unidade | K4: Meio_Afetado | L4: Contido_no_Local | M4: Severidade_1a5 | N4: Condicao | O4: Comunicado_Autoridade | P4: ID_Cenario_EMG | Q4: ID_Aspeto | R4: Resposta_Imediata | S4: ID_NC | T4: Custo_EUR | U4: Reportado_Por | V4: Turno | W4: Estado | X4: Classe_Gravidade
A5: INC-2025-01 | B5: 45734 | C5: =IF(B5="","",YEAR(B5)*100+MONTH(B5)) -> 202503 | D5: Quase-incidente | E5: ARQ | F5: Armazém de químicos | G5: Bidão de solvente de 25 L tombado por empilhador; tampa fechada, sem derrame. | H5: Solvente de limpeza | I5: 0 | J5: L | K5: Nenhum | L5: Sim | M5: 1 | N5: Anormal | O5: Não | P5: EMG-01 | Q5: AA-005 | R5: Bidão recolocado em bacia; corredor sinalizado. | T5: 0 | U5: Operador de Armazém / Empilhador | V5: 1 | W5: Fechado | X5: =IF(M5="","",IF(M5>=4,"Grave",IF(M5=3,"Moderado","Leve"))) -> Leve
A6: INC-2025-02 | B6: 45769 | C6: =IF(B6="","",YEAR(B6)*100+MONTH(B6)) -> 202504 | D6: Derrame | E6: SER | F6: Serigrafia SS-001 | G6: Derrame de tinta durante a mudança de cor. | H6: Tinta de serigrafia | I6: 2 | J6: L | K6: Pavimento (contido) | L6: Sim | M6: 2 | N6: Anormal | O6: Não | P6: EMG-01 | Q6: AA-017 | R6: Absorvente do KIT-04; resíduo 15 02 02*. | T6: 60 | U6: Operador de Serigrafia | V6: 2 | W6: Fechado | X6: =IF(M6="","",IF(M6>=4,"Grave",IF(M6=3,"Moderado","Leve"))) -> Leve
A7: INC-2025-03 | B7: 45807 | C7: =IF(B7="","",YEAR(B7)*100+MONTH(B7)) -> 202505 | D7: Perda de granulado | E7: REC | F7: Zona de descarga de big bags | G7: Big bag rasgado; parte do granulado arrastado pela chuva para a sarjeta. | H7: Granulado PP | I7: 5 | J7: kg | K7: Rede pluvial | L7: Não | M7: 2 | N7: Anormal | O7: Não | P7: EMG-06 | Q7: AA-003 | R7: Varrimento e aspiração da sarjeta. | T7: 120 | U7: Chefe de Turno | V7: 1 | W7: Fechado | X7: =IF(M7="","",IF(M7>=4,"Grave",IF(M7=3,"Moderado","Leve"))) -> Leve
A8: INC-2025-04 | B8: 45834 | C8: =IF(B8="","",YEAR(B8)*100+MONTH(B8)) -> 202506 | D8: Reclamação externa | E8: SER | F8: Envolvente (vizinho a norte) | G8: Reclamação de odor a solvente durante a onda de calor. | H8: COV | K8: Ar | L8: Sim | M8: 2 | N8: Anormal | O8: Não | Q8: AA-014 | R8: Recipientes fechados; exaustão verificada; resposta ao reclamante (COM-EXT-2025-03). | T8: 0 | U8: Comunidade / vizinhança | W8: Fechado | X8: =IF(M8="","",IF(M8>=4,"Grave",IF(M8=3,"Moderado","Leve"))) -> Leve
A9: INC-2025-05 | B9: 45853 | C9: =IF(B9="","",YEAR(B9)*100+MONTH(B9)) -> 202507 | D9: Fuga de óleo | E9: INJ | F9: IM-003 | G9: Fuga de óleo hidráulico no tabuleiro da máquina. | H9: Óleo hidráulico | I9: 5 | J9: L | K9: Pavimento (contido) | L9: Sim | M9: 1 | N9: Anormal | O9: Não | P9: EMG-03 | Q9: AA-009 | R9: Tabuleiro esvaziado; óleo 13 01 10*. | T9: 40 | U9: Operador de Injeção | V9: 3 | W9: Fechado | X9: =IF(M9="","",IF(M9>=4,"Grave",IF(M9=3,"Moderado","Leve"))) -> Leve
A10: INC-2025-06 | B10: 45881 | C10: =IF(B10="","",YEAR(B10)*100+MONTH(B10)) -> 202508 | D10: Descarga anómala | E10: UTL | F10: Torre de arrefecimento TR-01 | G10: Bomba doseadora avariada: sobredosagem de biocida na purga para o coletor. | H10: Biocida (isotiazolinona) | I10: 40 | J10: L | K10: Coletor municipal | L10: Não | M10: 3 | N10: Emergência | O10: Sim | P10: EMG-05 | Q10: AA-024 | R10: Purga fechada; entidade gestora notificada (COM-EXT-2025-05); bomba substituída (OT-2025-14). | T10: 850 | U10: Técnico de Utilidades | V10: 2 | W10: Fechado | X10: =IF(M10="","",IF(M10>=4,"Grave",IF(M10=3,"Moderado","Leve"))) -> Moderado
A11: INC-2025-07 | B11: 45979 | C11: =IF(B11="","",YEAR(B11)*100+MONTH(B11)) -> 202511 | D11: Fuga de gás fluorado | E11: UTL | F11: Chiller CH-01 | G11: Fuga de R410A detetada no controlo de fugas. | H11: R410A | I11: 3.2 | J11: kg | K11: Ar | L11: Não | M11: 3 | N11: Emergência | O11: Não | P11: EMG-04 | Q11: AA-025 | R11: Reparação da brasagem e recarga por técnico certificado (OT-2025-19). | S11: NC-SGA-25-03 | T11: 1450 | U11: Técnico de Manutenção | V11: 1 | W11: Fechado | X11: =IF(M11="","",IF(M11>=4,"Grave",IF(M11=3,"Moderado","Leve"))) -> Moderado
A12: INC-2025-08 | B12: 46000 | C12: =IF(B12="","",YEAR(B12)*100+MONTH(B12)) -> 202512 | D12: Quase-incidente | E12: PRS | F12: Parque de resíduos | G12: Contentor de tinta residual (08 03 12*) sem tampa sob chuva, detetado em ronda. | H12: Tinta residual | I12: 0 | J12: L | K12: Nenhum | L12: Sim | M12: 1 | N12: Anormal | O12: Não | P12: EMG-01 | Q12: AA-027 | R12: Tampa colocada; reforço na ronda RON-08. | T12: 0 | U12: Auditor Interno do SGA | V12: 1 | W12: Fechado | X12: =IF(M12="","",IF(M12>=4,"Grave",IF(M12=3,"Moderado","Leve"))) -> Leve
A13: INC-2026-01 | B13: 46042 | C13: =IF(B13="","",YEAR(B13)*100+MONTH(B13)) -> 202601 | D13: Derrame | E13: MAN | F13: Oficina de manutenção | G13: Derrame durante a mudança de óleo de um redutor. | H13: Óleo mineral | I13: 3 | J13: L | K13: Pavimento (contido) | L13: Sim | M13: 1 | N13: Anormal | O13: Não | P13: EMG-03 | Q13: AA-026 | R13: Absorvente do KIT-02. | T13: 30 | U13: Técnico de Manutenção | V13: 1 | W13: Fechado | X13: =IF(M13="","",IF(M13>=4,"Grave",IF(M13=3,"Moderado","Leve"))) -> Leve
A14: INC-2026-02 | B14: 46064 | C14: =IF(B14="","",YEAR(B14)*100+MONTH(B14)) -> 202602 | D14: Fuga de óleo | E14: SOP | F14: ISBM-005 | G14: Fuga de ≈ 15 L de óleo hidráulico para o pavimento (mangueira envelhecida). | H14: Óleo hidráulico | I14: 15 | J14: L | K14: Pavimento (contido) | L14: Sim | M14: 2 | N14: Emergência | O14: Não | P14: EMG-03 | Q14: AA-013 | R14: Contenção com absorventes; mangueira substituída (OT-2026-04). | S14: NC-SGA-26-00 | T14: 900 | U14: Operador de Sopro (ISBM) | V14: 2 | W14: Fechado | X14: =IF(M14="","",IF(M14>=4,"Grave",IF(M14=3,"Moderado","Leve"))) -> Leve
A15: INC-2026-03 | B15: 46086 | C15: =IF(B15="","",YEAR(B15)*100+MONTH(B15)) -> 202603 | D15: Perda de granulado | E15: REC | F15: Zona dos silos | G15: Perda na trasfega pneumática; sarjeta sem filtro recebeu granulado. | H15: Granulado HDPE | I15: 8 | J15: kg | K15: Rede pluvial | L15: Não | M15: 2 | N15: Anormal | O15: Não | P15: EMG-06 | Q15: AA-003 | R15: Aspiração; pedido de filtros de sarjeta (PAM-26-11). | T15: 150 | U15: Chefe de Turno | V15: 1 | W15: Fechado | X15: =IF(M15="","",IF(M15>=4,"Grave",IF(M15=3,"Moderado","Leve"))) -> Leve
A16: INC-2026-04 | B16: 46129 | C16: =IF(B16="","",YEAR(B16)*100+MONTH(B16)) -> 202604 | D16: Quase-incidente | E16: REC | F16: Armazém de MP | G16: Garfo do empilhador perfurou um big bag no interior; recolhido sem perdas para o exterior. | H16: Granulado PET | I16: 1 | J16: kg | K16: Pavimento (contido) | L16: Sim | M16: 1 | N16: Anormal | O16: Não | P16: EMG-06 | Q16: AA-003 | R16: Recolha; formação de manobra. | T16: 20 | U16: Operador de Armazém / Empilhador | V16: 2 | W16: Fechado | X16: =IF(M16="","",IF(M16>=4,"Grave",IF(M16=3,"Moderado","Leve"))) -> Leve
A17: INC-2026-05 | B17: 46170 | C17: =IF(B17="","",YEAR(B17)*100+MONTH(B17)) -> 202605 | D17: Derrame | E17: SER | F17: Serigrafia SS-002 | G17: Derrame de solvente na limpeza de ecrãs. | H17: Solvente de limpeza | I17: 1 | J17: L | K17: Pavimento (contido) | L17: Sim | M17: 1 | N17: Anormal | O17: Não | P17: EMG-01 | Q17: AA-014 | R17: Absorvente; recipiente de segurança com fecho automático pedido. | T17: 15 | U17: Operador de Serigrafia | V17: 3 | W17: Fechado | X17: =IF(M17="","",IF(M17>=4,"Grave",IF(M17=3,"Moderado","Leve"))) -> Leve
A18: INC-2026-06 | B18: 46196 | C18: =IF(B18="","",YEAR(B18)*100+MONTH(B18)) -> 202606 | D18: Reclamação externa | E18: UTL | F18: Envolvente (habitações a sul) | G18: Reclamação de ruído noturno após a instalação dos compressores novos. | H18: Ruído | K18: Ruído | L18: Não | M18: 2 | N18: Anormal | O18: Não | Q18: AA-022 | R18: Resposta ao reclamante (COM-EXT-2026-08); medição indicativa interna. | S18: NC-SGA-26-01 | T18: 0 | U18: Comunidade / vizinhança | W18: Fechado | X18: =IF(M18="","",IF(M18>=4,"Grave",IF(M18=3,"Moderado","Leve"))) -> Leve
A19: INC-2026-07 | B19: 46211 | C19: =IF(B19="","",YEAR(B19)*100+MONTH(B19)) -> 202607 | D19: Reclamação externa | E19: UTL | F19: Envolvente (habitações a sul) | G19: Segunda reclamação de ruído noturno (mesmo recetor). | H19: Ruído | K19: Ruído | L19: Não | M19: 2 | N19: Anormal | O19: Não | Q19: AA-022 | R19: Avaliação acústica acreditada contratada (PAM-26-03); conforme em 28/10/2026. | S19: NC-SGA-26-01 | T19: 0 | U19: Comunidade / vizinhança | W19: Fechado | X19: =IF(M19="","",IF(M19>=4,"Grave",IF(M19=3,"Moderado","Leve"))) -> Leve
A20: INC-2026-08 | B20: 46224 | C20: =IF(B20="","",YEAR(B20)*100+MONTH(B20)) -> 202607 | D20: Condição anormal | E20: UTL | F20: Torre de arrefecimento TR-01 | G20: Onda de calor: reposição de água +35% e alarme de temperatura dos moldes. | H20: Água de rede | I20: 95 | J20: m³ | K20: Recurso (água/energia) | L20: Sim | M20: 1 | N20: Anormal | O20: Não | Q20: AA-023 | R20: Redução de carga no pico; revisão do OBJ-05. | T20: 0 | U20: Técnico de Utilidades | V20: 2 | W20: Fechado | X20: =IF(M20="","",IF(M20>=4,"Grave",IF(M20=3,"Moderado","Leve"))) -> Leve
A21: INC-2026-09 | B21: 46238 | C21: =IF(B21="","",YEAR(B21)*100+MONTH(B21)) -> 202608 | D21: Perda de granulado | E21: REC | F21: Zona de descarga de big bags | G21: Big bag rasgado; 1 sarjeta sem filtro — granulado na rede pluvial. | H21: Granulado PP | I21: 12 | J21: kg | K21: Rede pluvial | L21: Não | M21: 3 | N21: Emergência | O21: Não | P21: EMG-06 | Q21: AA-003 | R21: Aspiração da caixa pluvial; prioridade ao PAM-26-11. | T21: 380 | U21: Chefe de Turno | V21: 1 | W21: Fechado | X21: =IF(M21="","",IF(M21>=4,"Grave",IF(M21=3,"Moderado","Leve"))) -> Moderado
A22: INC-2026-10 | B22: 46253 | C22: =IF(B22="","",YEAR(B22)*100+MONTH(B22)) -> 202608 | D22: Condição anormal | E22: UTL | F22: Rede de ar comprimido | G22: Fuga em mangueira de ar comprimido (≈ 4 kW de perdas) sinalizada na ronda. | H22: Ar comprimido | K22: Recurso (água/energia) | L22: Sim | M22: 1 | N22: Anormal | O22: Não | Q22: AA-021 | R22: Mangueira substituída (OT-2026-17). | T22: 45 | U22: Técnico de Utilidades | V22: 2 | W22: Fechado | X22: =IF(M22="","",IF(M22>=4,"Grave",IF(M22=3,"Moderado","Leve"))) -> Leve
A23: INC-2026-11 | B23: 46277 | C23: =IF(B23="","",YEAR(B23)*100+MONTH(B23)) -> 202609 | D23: Derrame | E23: INJ | F23: Zona entre injeção e serigrafia | G23: Derrame de tinta com o KIT-03 incompleto (absorventes em falta). | H23: Tinta de serigrafia | I23: 4 | J23: L | K23: Pavimento (contido) | L23: Sim | M23: 2 | N23: Emergência | O23: Não | P23: EMG-01 | Q23: AA-005 | R23: Absorvente de outro kit; KIT-03 reposto em 16/09. | S23: NC-SGA-26-03 | T23: 90 | U23: Chefe de Turno | V23: 2 | W23: Fechado | X23: =IF(M23="","",IF(M23>=4,"Grave",IF(M23=3,"Moderado","Leve"))) -> Leve
A24: INC-2026-12 | B24: 46332 | C24: =IF(B24="","",YEAR(B24)*100+MONTH(B24)) -> 202611 | D24: Fuga de óleo | E24: INJ | F24: Injetora IM-004 | G24: Rutura de mangueira hidráulica: ≈ 8 L de óleo no pavimento sem tabuleiro de retenção sob a unidade hidráulica. | H24: Óleo hidráulico | I24: 8 | J24: L | K24: Pavimento (contido) | L24: Sim | M24: 2 | N24: Anormal | O24: Não | P24: EMG-03 | Q24: AA-009 | R24: Contenção com o KIT-02; mangueira substituída (OT-2026-24). | S24: NC-SGA-26-10 | T24: 260 | U24: Operador de Injeção | V24: 1 | W24: Fechado | X24: =IF(M24="","",IF(M24>=4,"Grave",IF(M24=3,"Moderado","Leve"))) -> Leve
A25: INC-2026-13 | B25: 46373 | C25: =IF(B25="","",YEAR(B25)*100+MONTH(B25)) -> 202612 | D25: Quase-incidente | E25: ARQ | F25: Armazém de químicos | G25: Empilhador tocou num IBC de óleo durante a arrumação; sem rutura. | H25: Óleo hidráulico | K25: Nenhum | L25: Sim | M25: 1 | N25: Anormal | O25: Não | P25: EMG-01 | Q25: AA-005 | R25: Marcação de corredor e batente de proteção instalados. | T25: 120 | U25: Operador de Armazém / Empilhador | V25: 2 | W25: Fechado | X25: =IF(M25="","",IF(M25>=4,"Grave",IF(M25=3,"Moderado","Leve"))) -> Leve
C26: =IF(B26="","",YEAR(B26)*100+MONTH(B26)) | X26: =IF(M26="","",IF(M26>=4,"Grave",IF(M26=3,"Moderado","Leve")))
C27: =IF(B27="","",YEAR(B27)*100+MONTH(B27)) | X27: =IF(M27="","",IF(M27>=4,"Grave",IF(M27=3,"Moderado","Leve")))
C28: =IF(B28="","",YEAR(B28)*100+MONTH(B28)) | X28: =IF(M28="","",IF(M28>=4,"Grave",IF(M28=3,"Moderado","Leve")))
C29: =IF(B29="","",YEAR(B29)*100+MONTH(B29)) | X29: =IF(M29="","",IF(M29>=4,"Grave",IF(M29=3,"Moderado","Leve")))
C30: =IF(B30="","",YEAR(B30)*100+MONTH(B30)) | X30: =IF(M30="","",IF(M30>=4,"Grave",IF(M30=3,"Moderado","Leve")))
C31: =IF(B31="","",YEAR(B31)*100+MONTH(B31)) | X31: =IF(M31="","",IF(M31>=4,"Grave",IF(M31=3,"Moderado","Leve")))
C32: =IF(B32="","",YEAR(B32)*100+MONTH(B32)) | X32: =IF(M32="","",IF(M32>=4,"Grave",IF(M32=3,"Moderado","Leve")))
C33: =IF(B33="","",YEAR(B33)*100+MONTH(B33)) | X33: =IF(M33="","",IF(M33>=4,"Grave",IF(M33=3,"Moderado","Leve")))
C34: =IF(B34="","",YEAR(B34)*100+MONTH(B34)) | X34: =IF(M34="","",IF(M34>=4,"Grave",IF(M34=3,"Moderado","Leve")))
C35: =IF(B35="","",YEAR(B35)*100+MONTH(B35)) | X35: =IF(M35="","",IF(M35>=4,"Grave",IF(M35=3,"Moderado","Leve")))
C36: =IF(B36="","",YEAR(B36)*100+MONTH(B36)) | X36: =IF(M36="","",IF(M36>=4,"Grave",IF(M36=3,"Moderado","Leve")))
C37: =IF(B37="","",YEAR(B37)*100+MONTH(B37)) | X37: =IF(M37="","",IF(M37>=4,"Grave",IF(M37=3,"Moderado","Leve")))
... C65: =IF(B65="","",YEAR(B65)*100+MONTH(B65)) | X65: =IF(M65="","",IF(M65>=4,"Grave",IF(M65=3,"Moderado","Leve")))

Sheet Listas
A1: LISTAS CONTROLADAS (domínios de validação de dados) — editar aqui para alterar opções
A2: DataReferencia | B2: Origem | C2: Processo | D2: TipoRegisto | E2: Classificacao | F2: Severidade | G2: Cat6M | H2: Metodo | I2: Estado | J2: Eficacia | K2: SimNao | L2: Funcao | M2: INC_Tipo | N2: INC_Meio | O2: INC_Cond | P2: INC_Turno | Q2: INC_SimNao | R2: INC_Estado
A3: 46387 | B3: Ronda ambiental | C3: REC | D3: Não conformidade | E3: NC Maior | F3: Baixa | G3: Método | H3: 5 Porquês | I3: Aberta | J3: Por avaliar | K3: Sim | L3: Diretor Geral (Gestão de Topo) | M3: Derrame | N3: Pavimento (contido) | O3: Anormal | P3: 1 | Q3: Sim | R3: Aberto
B4: Auditoria interna | C4: ARQ | D4: Incidente ambiental | E4: NC Menor | F4: Média | G4: Máquina | H4: Ishikawa | I4: Em tratamento | J4: Eficaz | K4: Não | L4: Diretor Industrial | M4: Fuga de óleo | N4: Solo | O4: Emergência | P4: 2 | Q4: Não | R4: Em análise
B5: Auditoria externa | C5: INJ | D5: Reclamação | E5: NC Legal | F5: Alta | G5: Material | H5: 5 Porquês + Ishikawa | I5: Fechada | J5: Não eficaz | L5: Gestor do SGA / EHS (Responsável Ambiental) | M5: Fuga de gás fluorado | N5: Rede pluvial | P5: 3 | R5: Fechado
B6: Avaliação da conformidade legal | C6: SOP | G6: Mão de obra | H6: Análise de árvore de falhas | L6: Gerente de Produção | M6: Perda de granulado | N6: Coletor municipal
B7: Monitorização e medição | C7: SER | G7: Medição | L7: Gerente de Manutenção | M7: Descarga anómala | N7: Ar
B8: Incidente ambiental | C8: HFS | G8: Meio ambiente | L8: Gerente da Qualidade | M8: Emissão / odor | N8: Ruído
B9: Reclamação de parte interessada | C9: MOA | L9: Responsável de Armazém e Logística | M9: Reclamação externa | N9: Recurso (água/energia)
B10: Simulacro | C10: UTL | L10: Responsável de Compras | M10: Quase-incidente | N10: Nenhum
C11: MAN | L11: Responsável de R&D | M11: Condição anormal
C12: PRS | L12: Responsável de Recursos Humanos
C13: EXP | L13: Diretor Financeiro
C14: LAB | L14: Operador de Serigrafia
C15: RD | L15: Operador de Injeção
C16: CMP | L16: Operador de Sopro (ISBM)
C17: ADM | L17: Operador de Hot Foil
C18: GER | L18: Técnico de Manutenção
L19: Técnico de Utilidades
L20: Operador de Armazém / Empilhador
L21: Chefe de Turno
L22: Auditor Interno do SGA
L23: Representante dos Trabalhadores (SST/Ambiente)
L24: Técnico de Qualidade/Ambiente

Sheet Dicionario_Dados
A1: Folha | B1: Tabela | C1: Coluna | D1: Tipo | E1: Origem | F1: Descricao | G1: Dominio_Unidade | H1: Obrigatorio | I1: Chave
A2: Registo_NC | B2: tbl_nc | C2: ID_NC | D2: Texto | E2: Entrada | F2: Identificador da NC/incidente. | G2: NC-SGA-AA-nn | H2: Sim | I2: PK
A3: Registo_NC | B3: tbl_nc | C3: Data_Detecao | D3: Data (aaaa-mm-dd) | E3: Entrada | F3: Data de deteção. | H3: Sim
A4: Registo_NC | B4: tbl_nc | C4: Origem | D4: Texto | E4: Entrada | F4: Como foi detetada. | G4: Lista lst_Origem | H4: Sim
A5: Registo_NC | B5: tbl_nc | C5: ID_Origem | D5: Texto | E5: Entrada | F5: ID da ronda, constatação, requisito ou incidente. | H5: Sim | I5: FK
A6: Registo_NC | B6: tbl_nc | C6: Processo | D6: Texto | E6: Entrada | F6: Processo. | G6: Lista lst_Processo | H6: Sim | I6: FK → dim processo
A7: Registo_NC | B7: tbl_nc | C7: Local | D7: Texto | E7: Entrada | F7: Local exato. | H7: Sim
A8: Registo_NC | B8: tbl_nc | C8: Tipo_Registo | D8: Texto | E8: Entrada | F8: NC, incidente ou reclamação. | G8: Lista lst_TipoRegisto | H8: Sim
A9: Registo_NC | B9: tbl_nc | C9: Classificacao | D9: Texto | E9: Entrada | F9: NC Maior / Menor / Legal. | G9: Lista lst_Classificacao | H9: Sim
A10: Registo_NC | B10: tbl_nc | C10: Requisito_Violado | D10: Texto | E10: Entrada | F10: Cláusula ISO 14001:2026 e/ou diploma legal. | H10: Sim
A11: Registo_NC | B11: tbl_nc | C11: Descricao | D11: Texto | E11: Entrada | F11: Descrição da NC. | H11: Sim
A12: Registo_NC | B12: tbl_nc | C12: Evidencia_Objetiva | D12: Texto | E12: Entrada | F12: Evidência (o que se viu, documento, data). | H12: Sim
A13: Registo_NC | B13: tbl_nc | C13: Impacte_Potencial | D13: Texto | E13: Entrada | F13: Consequência ambiental/legal potencial. | H13: Sim
A14: Registo_NC | B14: tbl_nc | C14: Severidade | D14: Texto | E14: Entrada | F14: Severidade. | G14: Lista lst_Severidade | H14: Sim
A15: Registo_NC | B15: tbl_nc | C15: Correcao_C1 | D15: Texto | E15: Entrada | F15: Correção imediata (controlar e corrigir; lidar com as consequências). | H15: Sim
A16: Registo_NC | B16: tbl_nc | C16: Causa_Raiz | D16: Texto | E16: Entrada | F16: Causa raiz identificada. | H16: Sim
A17: Registo_NC | B17: tbl_nc | C17: Categoria_6M | D17: Texto | E17: Entrada | F17: Categoria Ishikawa. | G17: Lista lst_Cat6M | H17: Sim
A18: Registo_NC | B18: tbl_nc | C18: Metodo_Analise | D18: Texto | E18: Entrada | F18: Método de análise de causa. | G18: Lista lst_Metodo | H18: Sim
A19: Registo_NC | B19: tbl_nc | C19: N_Porques | D19: Inteiro | E19: Calculado (fórmula) | F19: N.º de níveis de 'porquê' registados na tabela 5 Porquês. | H19: Sim
A20: Registo_NC | B20: tbl_nc | C20: ID_PAM_C1 | D20: Texto | E20: Entrada | F20: Ação de correção no PAM. | H20: Não | I20: FK → RG-SGA-06
A21: Registo_NC | B21: tbl_nc | C21: ID_PAM_C2 | D21: Texto | E21: Entrada | F21: Ação corretiva no PAM. | H21: Não | I21: FK → RG-SGA-06
A22: Registo_NC | B22: tbl_nc | C22: Responsavel | D22: Texto | E22: Entrada | F22: Responsável. | G22: Lista lst_Funcao | H22: Sim
A23: Registo_NC | B23: tbl_nc | C23: Prazo | D23: Data (aaaa-mm-dd) | E23: Entrada | F23: Prazo de tratamento. | H23: Sim
A24: Registo_NC | B24: tbl_nc | C24: Estado | D24: Texto | E24: Entrada | F24: Estado. | G24: Lista lst_Estado | H24: Sim
A25: Registo_NC | B25: tbl_nc | C25: Data_Fecho | D25: Data (aaaa-mm-dd) | E25: Entrada | F25: Data de fecho. | H25: Não
A26: Registo_NC | B26: tbl_nc | C26: Dias_Aberta | D26: Inteiro | E26: Calculado (fórmula) | F26: Dias entre deteção e fecho (ou até à data de referência). | H26: Sim
A27: Registo_NC | B27: tbl_nc | C27: No_Prazo | D27: Texto | E27: Calculado (fórmula) | F27: Fechada dentro do prazo? | H27: Sim
A28: Registo_NC | B28: tbl_nc | C28: Eficacia | D28: Texto | E28: Entrada | F28: Resultado da verificação de eficácia. | G28: Lista lst_Eficacia | H28: Sim
A29: Registo_NC | B29: tbl_nc | C29: Data_Verif_Eficacia | D29: Data (aaaa-mm-dd) | E29: Entrada | F29: Data da verificação de eficácia. | H29: Sim
A30: Registo_NC | B30: tbl_nc | C30: Recorrente | D30: Texto | E30: Entrada | F30: Repetição de NC anterior. | G30: Lista lst_SimNao | H30: Sim
A31: Registo_NC | B31: tbl_nc | C31: Custo_EUR | D31: Moeda (EUR) | E31: Entrada | F31: Custo associado (correção + ações). | H31: Sim
A32: Registo_NC | B32: tbl_nc | C32: Reportado_Por | D32: Texto | E32: Entrada | F32: Quem detetou. | H32: Sim
A33: Registo_NC | B33: tbl_nc | C33: Controlo_Qualidade | D33: Texto | E33: Calculado (fórmula) | F33: Regras de qualidade do registo. | H33: Sim
A34: Cinco_Porques | B34: tbl_5porques | C34: ID_NC | D34: Texto | E34: Entrada | F34: NC analisada. | H34: Sim | I34: FK → tbl_nc
A35: Cinco_Porques | B35: tbl_5porques | C35: Nivel | D35: Inteiro | E35: Entrada | F35: Nível do porquê (1 a 5). | H35: Sim
A36: Cinco_Porques | B36: tbl_5porques | C36: Chave | D36: Texto | E36: Calculado (fórmula) | F36: Chave técnica (NC|nível). | H36: Sim
A37: Cinco_Porques | B37: tbl_5porques | C37: Pergunta_Porque | D37: Texto | E37: Entrada | F37: Pergunta 'Porquê...?'. | H37: Sim
A38: Cinco_Porques | B38: tbl_5porques | C38: Resposta | D38: Texto | E38: Entrada | F38: Resposta. | H38: Sim
A39: Cinco_Porques | B39: tbl_5porques | C39: Evidencia | D39: Texto | E39: Entrada | F39: Evidência que confirma a resposta. | H39: Sim
A40: Cinco_Porques | B40: tbl_5porques | C40: E_Causa_Raiz | D40: Texto | E40: Entrada | F40: Sim no nível que é a causa raiz. | G40: Lista lst_SimNao | H40: Sim
...
