Workbook
Name DataRef: Listas!$A$3
Name lst_Categoria: Listas!$D$3:$D$11
Name lst_Condicao: Listas!$F$3:$F$5
Name lst_DataReferencia: Listas!$A$3:$A$3
Name lst_F15: Listas!$I$3:$I$7
Name lst_Fase: Listas!$C$3:$C$8
Name lst_G: Listas!$K$3:$K$9
Name lst_Impacte: Listas!$H$3:$H$14
Name lst_L: Listas!$L$3:$L$4
Name lst_M15: Listas!$J$3:$J$7
Name lst_Processo: Listas!$B$3:$B$18
Name lst_SimNao: Listas!$M$3:$M$4
Name lst_Temporalidade: Listas!$G$3:$G$5
Name lst_TipoAspeto: Listas!$E$3:$E$4

Sheet 00_LEIA-ME
A1: RG-SGA-03 — Matriz de Identificação e Avaliação de Aspetos e Impactes Ambientais (Mod.G.07.00)
A2: Sistema de Gestão Ambiental NP EN ISO 14001:2026 · Plasticom — Unidade 1 (Marinha Grande, Portugal) · Registo do SGA (fábrica simulada)
A4: CONTROLO DO DOCUMENTO (7.5 — informação documentada)
A5: Código do registo | B5: RG-SGA-03
A6: Título | B6: Matriz de Identificação e Avaliação de Aspetos e Impactes Ambientais (Mod.G.07.00)
A7: Versão / Revisão | B7: 01
A8: Data de emissão | B8: 46387
A9: Elaborado por | B9: Gestor(a) do SGA / EHS
A10: Aprovado por | B10: Diretor Geral
A11: Estado | B11: Em vigor
A12: Retenção | B12: 5 anos após substituição
A13: Localização | B13: Repositório controlado do SGA > Registos_SGA_Plasticom (versão eletrónica é a versão controlada; cópias impressas são não controladas)
A15: FINALIDADE E ÂMBITO
A16: Finalidade | B16: Identificar, para todas as atividades da Plasticom e em todas as fases do ciclo de vida, os aspetos ambientais (causa) e os impactes (efeito), e avaliar a significância pelo IRA = (F + M) × G × L segundo o PR.G.01.01. Ponto de partida: folha 03_Aspectos_Impactes do Plasticom_SGA_ISO14001_2026_ESG_com_Dupla_Materialidade.xlsx, revista e alargada.
A17: Atividades do curso | B17: Atividade 3.2 — Identificação e Avaliação de Aspetos e Impactes Ambientais (aspetos selecionados: AA-005 e AA-014).
A18: Requisitos ISO 14001:2026 | B18: 6.1.2 Aspetos ambientais (perspetiva de ciclo de vida; situações de emergência distinguidas das anormais — ISO 14001:2026); 6.1.5; 8.1; 8.2
A20: ESTRUTURA DO FICHEIRO
A21: Impactes | B21: Catálogo de impactes ambientais (dimensão).
A22: Aspetos_Impactes | B22: Registo de aspetos e impactes (1 linha por aspeto) com avaliação IRA e gestão.
A23: Aspeto_Impacte | B23: Relação N:N aspeto × impacte (formato longo, para análise e para os 'X' da matriz Mod.G.07.00).
A24: Mod.G.07.00_Matriz | B24: Matriz no formato do modelo do curso (Mod.G.07.00), com 'X' calculados a partir das tabelas. Para impressão; editar em Aspetos_Impactes.
A25: Resumo_Atividade_3_2 | B25: Ficha dos 2 aspetos selecionados para a Atividade 3.2 (campos do enunciado, calculados).
A26: Analise | B26: Distribuição dos aspetos por classificação, processo, condição e fase (calculado).
A27: Criterios | B27: Critérios F, M, G, L e tabela de significância (PR.G.01.01).
A28: Listas | B28: Domínios (listas de valores) usados na validação de dados das tabelas.
A29: Dicionario_Dados | B29: Descrição de cada coluna de cada tabela: tipo, origem (entrada/calculado), domínio, obrigatoriedade e chaves.
A31: CONVENÇÕES (prontas para análise de dados e machine learning)
A32: Tabelas | B32: Cada registo é uma Tabela Excel com nome próprio (tbl_*): uma linha = um registo, cabeçalho único, sem células mescladas. Ler com pandas (pd.read_excel(ficheiro, sheet_name=folha, header=<linha do cabeçalho - 1>)) ou Power BI (Obter Dados > Tabela).
A33: Cabeçalho cinzento | B33: Coluna CALCULADA por fórmula — não escrever por cima. As restantes colunas são de entrada.
A34: Validação | B34: Colunas com lista controlada só aceitam valores da folha Listas (evita categorias duplicadas por grafia diferente).
A35: Chaves | B35: IDs estáveis e únicos (PK) e referências a IDs de outros registos (FK) permitem juntar tabelas entre ficheiros — ver SGA-00_Indice_Modelo_Dados.xlsx.
A36: Datas e unidades | B36: Datas em formato data (aaaa-mm-dd); números como números; a unidade está no nome da coluna ou no dicionário. Data de referência do SGA: 2026-12-31 (fecho do ano).
A37: Dados simulados | B37: Fábrica simulada Plasticom. Dados operacionais derivados do dataset do projeto (datasets/silver); dados ambientais e de conformidade são simulação didática — confirmar aplicabilidade legal e números antes de uso real.
A39: LIGAÇÕES A OUTROS REGISTOS
A40: RG-SGA-04 Requisitos legais | B40: ID_Legal liga o aspeto à obrigação de conformidade.
A41: RG-SGA-05 Objetivos | B41: ID_Objetivo liga aspetos significativos a objetivos.
A42: RG-SGA-06 PAM | B42: ID_PAM liga a ação de controlo/melhoria.
A43: RG-SGA-13 Monitorização | B43: ID_Monitorizacao liga ao plano de medição (MED-xx). Quantidade_Anual vem dos dados de monitorização ano civil de 2026.

Sheet Impactes
A1: ID_Impacte | B1: Impacte | C1: Natureza | D1: N_Aspetos | E1: N_AAS
A2: IMP-01 | B2: Esgotamento de Recursos Naturais / Recursos | C2: Adverso | D2: =COUNTIF(tbl_aspeto_impacte[ID_Impacte],A2) -> 17 | E2: =COUNTIFS(tbl_aspeto_impacte[ID_Impacte],A2,tbl_aspeto_impacte[Classificacao],"ASPETO*") -> 1
A3: IMP-02 | B3: Contaminação do Solo e/ou Recursos Hídricos | C3: Adverso | D3: =COUNTIF(tbl_aspeto_impacte[ID_Impacte],A3) -> 13 | E3: =COUNTIFS(tbl_aspeto_impacte[ID_Impacte],A3,tbl_aspeto_impacte[Classificacao],"ASPETO*") -> 0
A4: IMP-03 | B4: Poluição do Ar | C4: Adverso | D4: =COUNTIF(tbl_aspeto_impacte[ID_Impacte],A4) -> 8 | E4: =COUNTIFS(tbl_aspeto_impacte[ID_Impacte],A4,tbl_aspeto_impacte[Classificacao],"ASPETO*") -> 1
A5: IMP-04 | B5: Mudanças Climáticas | C5: Adverso | D5: =COUNTIF(tbl_aspeto_impacte[ID_Impacte],A5) -> 13 | E5: =COUNTIFS(tbl_aspeto_impacte[ID_Impacte],A5,tbl_aspeto_impacte[Classificacao],"ASPETO*") -> 2
A6: IMP-05 | B6: Incomodidade da Vizinhança | C6: Adverso | D6: =COUNTIF(tbl_aspeto_impacte[ID_Impacte],A6) -> 2 | E6: =COUNTIFS(tbl_aspeto_impacte[ID_Impacte],A6,tbl_aspeto_impacte[Classificacao],"ASPETO*") -> 1
A7: IMP-06 | B7: Perturbação da Fauna / Flora / Paisagem | C7: Adverso | D7: =COUNTIF(tbl_aspeto_impacte[ID_Impacte],A7) -> 4 | E7: =COUNTIFS(tbl_aspeto_impacte[ID_Impacte],A7,tbl_aspeto_impacte[Classificacao],"ASPETO*") -> 0
A8: IMP-07 | B8: Redução da vida útil de aterros e passivos ambientais | C8: Adverso | D8: =COUNTIF(tbl_aspeto_impacte[ID_Impacte],A8) -> 14 | E8: =COUNTIFS(tbl_aspeto_impacte[ID_Impacte],A8,tbl_aspeto_impacte[Classificacao],"ASPETO*") -> 1
A9: IMP-08 | B9: Degradação da saúde dos ecossistemas aquáticos (microplásticos) | C9: Adverso | D9: =COUNTIF(tbl_aspeto_impacte[ID_Impacte],A9) -> 2 | E9: =COUNTIFS(tbl_aspeto_impacte[ID_Impacte],A9,tbl_aspeto_impacte[Classificacao],"ASPETO*") -> 0
A10: IMP-09 | B10: Promoção da Eficiência Hídrica e Circularidade (valorização interna de resíduos/águas) | C10: Benéfico | D10: =COUNTIF(tbl_aspeto_impacte[ID_Impacte],A10) -> 1 | E10: =COUNTIFS(tbl_aspeto_impacte[ID_Impacte],A10,tbl_aspeto_impacte[Classificacao],"ASPETO*") -> 0
A11: IMP-10 | B11: Otimização do Consumo de Matérias-Primas (poupança ou geração de novos recursos) | C11: Benéfico | D11: =COUNTIF(tbl_aspeto_impacte[ID_Impacte],A11) -> 2 | E11: =COUNTIFS(tbl_aspeto_impacte[ID_Impacte],A11,tbl_aspeto_impacte[Classificacao],"ASPETO*") -> 0
A12: IMP-11 | B12: Extensão do ciclo de vida de materiais (conversão de resíduos em subprodutos) | C12: Benéfico | D12: =COUNTIF(tbl_aspeto_impacte[ID_Impacte],A12) -> 2 | E12: =COUNTIFS(tbl_aspeto_impacte[ID_Impacte],A12,tbl_aspeto_impacte[Classificacao],"ASPETO*") -> 0
A13: IMP-12 | B13: Minimização da Pressão Ecológica (materiais recicláveis ou de origem sustentável) | C13: Benéfico | D13: =COUNTIF(tbl_aspeto_impacte[ID_Impacte],A13) -> 3 | E13: =COUNTIFS(tbl_aspeto_impacte[ID_Impacte],A13,tbl_aspeto_impacte[Classificacao],"ASPETO*") -> 1

Sheet Aspetos_Impactes
A1: MATRIZ DE AVALIAÇÃO DE ASPETOS E IMPACTES AMBIENTAIS — PLASTICOM (registo de dados)
A2: IRA = (F + M) × G × L · AAS se IRA ≥ 40 ou L = 2 · Moderado 20-39 · Não significativo 0-19 · Oportunidade tática -1 a -14 · AAS benéfico ≤ -15 · Filtrar Selecionado_Atv_3_2 = Sim
A4: ID_Aspeto | B4: Processo | C4: Area_Atividade | D4: Atividade | E4: Fase_Ciclo_Vida | F4: Categoria_Aspeto | G4: Descricao_Aspeto | H4: Tipo_Aspeto | I4: Condicao_Operacao | J4: Temporalidade | K4: ID_Impacte_Principal | L4: Impacte_Principal | M4: IDs_Impactes_Secundarios | N4: F | O4: M | P4: G | Q4: L | R4: Tipo_Efeito | S4: IRA | T4: Classificacao | U4: Motivo_Classificacao | V4: Ranking_IRA | W4: Acao_Plano_Melhoria | X4: Medidas_Controlo_Acao | Y4: Controlo_Existente | Z4: Quantidade_Anual | AA4: Unidade_Quantidade | AB4: Fonte_Dado | AC4: Justificacao_Criterios | AD4: ID_Legal | AE4: ID_RO | AF4: ID_Objetivo | AG4: ID_PAM | AH4: ID_Monitorizacao | AI4: Verificacao_Gestao | AJ4: Selecionado_Atv_3_2 | AK4: Data_Avaliacao | AL4: Proxima_Revisao | AM4: Avaliador
A5: AA-001 | B5: CMP | C5: Compras e fornecedores | D5: Aquisição de polímeros (PP, HDPE, PET) | E5: Aquisição | F5: Consumo de recursos | G5: Consumo de polímeros virgens de origem fóssil | H5: Indireto | I5: Normal | J5: Presente | K5: IMP-01 | L5: =IFERROR(INDEX(tbl_impactes[Impacte],MATCH(K5,tbl_impactes[ID_Impacte],0)),"") -> Esgotamento de Recursos Naturais / Recursos | M5: IMP-04 | N5: 5 | O5: 5 | P5: 2 | Q5: 1 | R5: =IF(P5="","",IF(P5<0,"(-) Benéfico","(+) Adverso")) -> (+) Adverso | S5: =IF(COUNT(N5,O5,P5,Q5)<4,"",(N5+O5)*P5*Q5) -> 20 | T5: =IF(S5="","",IF(OR(Q5=2,S5>=40),"ASPETO AMBIENTAL SIGNIFICATIVO (AAS)",IF(S5>=20,"Moderado",IF(S5>=0,"Não Significativo",IF(S5>=-14,"Oportunidade Tática","ASPETO AMBIENTAL SIGNIFICATIVO (AAS) BENÉFICO"))))) -> Moderado | U5: =IF(S5="","",IF(Q5=2,"Regra de ouro (L=2)",IF(S5>=40,"IRA ≥ 40",IF(S5>=20,"IRA 20-39",IF(S5>=0,"IRA 0-19",IF(S5>=-14,"IRA -1 a -14","IRA ≤ -15")))))) -> IRA 20-39 | V5: =IF(S5="","",RANK(S5,$S$5:$S$47,0)) -> 24 | W5: =IF(T5="","",IF(OR(T5="ASPETO AMBIENTAL SIGNIFICATIVO (AAS)",T5="Moderado"),"SIM","NÃO")) -> SIM | X5: Critérios de compra com conteúdo reciclado certificado; lightweighting. | Y5: Especificação técnica de compra. | Z5: 782.9 | AA5: t/ano | AB5: Inventário de matérias-primas (12 meses) | AC5: F5 contínuo; M5 maior fluxo de matéria da fábrica; G2 material inerte mas não renovável. | AE5: RO-05 | AF5: OBJ-02 | AG5: PAM-26-16 | AH5: MED-05 | AI5: =IF(W5="SIM",IF(X5="","FALTA medida de controlo",IF(AND(LEFT(T5,6)="ASPETO",Q5=2,AG5=""),"FALTA ação corretiva (L=2)",IF(AND(LEFT(T5,6)="ASPETO",AH5=""),"Sugestão: definir monitorização","OK"))),"OK") -> OK | AJ5: Não | AK5: 46162 | AL5: =IF(AK5="","",EDATE(AK5,12)) -> 46527 | AM5: Gestor do SGA + responsável do setor
A6: AA-002 | B6: CMP | C6: Compras e fornecedores | D6: Transporte de matérias-primas pelos fornecedores | E6: Aquisição | F6: Emissões atmosféricas | G6: Emissões de gases de escape (CO2, NOx, partículas) no transporte rodoviário e marítimo de resinas | H6: Indireto | I6: Normal | J6: Presente | K6: IMP-04 | L6: =IFERROR(INDEX(tbl_impactes[Impacte],MATCH(K6,tbl_impactes[ID_Impacte],0)),"") -> Mudanças Climáticas | M6: IMP-03 | N6: 4 | O6: 4 | P6: 3 | Q6: 1 | R6: =IF(P6="","",IF(P6<0,"(-) Benéfico","(+) Adverso")) -> (+) Adverso | S6: =IF(COUNT(N6,O6,P6,Q6)<4,"",(N6+O6)*P6*Q6) -> 24 | T6: =IF(S6="","",IF(OR(Q6=2,S6>=40),"ASPETO AMBIENTAL SIGNIFICATIVO (AAS)",IF(S6>=20,"Moderado",IF(S6>=0,"Não Significativo",IF(S6>=-14,"Oportunidade Tática","ASPETO AMBIENTAL SIGNIFICATIVO (AAS) BENÉFICO"))))) -> Moderado | U6: =IF(S6="","",IF(Q6=2,"Regra de ouro (L=2)",IF(S6>=40,"IRA ≥ 40",IF(S6>=20,"IRA 20-39",IF(S6>=0,"IRA 0-19",IF(S6>=-14,"IRA -1 a -14","IRA ≤ -15")))))) -> IRA 20-39 | V6: =IF(S6="","",RANK(S6,$S$5:$S$47,0)) -> 18 | W6: =IF(T6="","",IF(OR(T6="ASPETO AMBIENTAL SIGNIFICATIVO (AAS)",T6="Moderado"),"SIM","NÃO")) -> SIM | X6: Preferir fornecedores ibéricos e cargas completas. | Y6: — | AB6: Guias de remessa; origem dos fornecedores | AC6: F4 entregas diárias; M4 ≈ 810 t/ano transportadas; G3 poluente convencional. | AI6: =IF(W6="SIM",IF(X6="","FALTA medida de controlo",IF(AND(LEFT(T6,6)="ASPETO",Q6=2,AG6=""),"FALTA ação corretiva (L=2)",IF(AND(LEFT(T6,6)="ASPETO",AH6=""),"Sugestão: definir monitorização","OK"))),"OK") -> OK | AJ6: Não | AK6: 46162 | AL6: =IF(AK6="","",EDATE(AK6,12)) -> 46527 | AM6: Gestor do SGA + responsável do setor
A7: AA-003 | B7: REC | C7: Receção e silos | D7: Descarga de big bags e transferência pneumática para silos | E7: Produção | F7: Perdas de granulado | G7: Perda de granulado de plástico para o pavimento e a rede de águas pluviais | H7: Direto | I7: Normal | J7: Presente | K7: IMP-08 | L7: =IFERROR(INDEX(tbl_impactes[Impacte],MATCH(K7,tbl_impactes[ID_Impacte],0)),"") -> Degradação da saúde dos ecossistemas aquáticos (microplásticos) | M7: IMP-02; IMP-06 | N7: 4 | O7: 3 | P7: 4 | Q7: 1 | R7: =IF(P7="","",IF(P7<0,"(-) Benéfico","(+) Adverso")) -> (+) Adverso | S7: =IF(COUNT(N7,O7,P7,Q7)<4,"",(N7+O7)*P7*Q7) -> 28 | T7: =IF(S7="","",IF(OR(Q7=2,S7>=40),"ASPETO AMBIENTAL SIGNIFICATIVO (AAS)",IF(S7>=20,"Moderado",IF(S7>=0,"Não Significativo",IF(S7>=-14,"Oportunidade Tática","ASPETO AMBIENTAL SIGNIFICATIVO (AAS) BENÉFICO"))))) -> Moderado | U7: =IF(S7="","",IF(Q7=2,"Regra de ouro (L=2)",IF(S7>=40,"IRA ≥ 40",IF(S7>=20,"IRA 20-39",IF(S7>=0,"IRA 0-19",IF(S7>=-14,"IRA -1 a -14","IRA ≤ -15")))))) -> IRA 20-39 | V7: =IF(S7="","",RANK(S7,$S$5:$S$47,0)) -> 9 | W7: =IF(T7="","",IF(OR(T7="ASPETO AMBIENTAL SIGNIFICATIVO (AAS)",T7="Moderado"),"SIM","NÃO")) -> SIM | X7: Operation Clean Sweep: filtros nas sarjetas, tabuleiros de descarga, aspiração, inspeção semanal. | Y7: Varrimento diário. | Z7: 100 | AA7: kg/ano recolhidos | AB7: Pesagem do granulado recolhido | AC7: F4 diário; M3 perdas de kg/mês; G4 microplásticos persistentes e nocivos para a fauna aquática. | AD7: LEG-10 | AE7: RO-07 | AF7: OBJ-06 | AG7: PAM-26-11 | AH7: MED-09 | AI7: =IF(W7="SIM",IF(X7="","FALTA medida de controlo",IF(AND(LEFT(T7,6)="ASPETO",Q7=2,AG7=""),"FALTA ação corretiva (L=2)",IF(AND(LEFT(T7,6)="ASPETO",AH7=""),"Sugestão: definir monitorização","OK"))),"OK") -> OK | AJ7: Não | AK7: 46162 | AL7: =IF(AK7="","",EDATE(AK7,12)) -> 46527 | AM7: Gestor do SGA + responsável do setor
A8: AA-004 | B8: REC | C8: Receção e silos | D8: Desembalagem de matérias-primas | E8: Produção | F8: Resíduos | G8: Geração de resíduos de embalagem de matérias-primas (big bags, sacos, paletes, cartão) | H8: Direto | I8: Normal | J8: Presente | K8: IMP-07 | L8: =IFERROR(INDEX(tbl_impactes[Impacte],MATCH(K8,tbl_impactes[ID_Impacte],0)),"") -> Redução da vida útil de aterros e passivos ambientais | M8: IMP-01 | N8: 4 | O8: 3 | P8: 2 | Q8: 1 | R8: =IF(P8="","",IF(P8<0,"(-) Benéfico","(+) Adverso")) -> (+) Adverso | S8: =IF(COUNT(N8,O8,P8,Q8)<4,"",(N8+O8)*P8*Q8) -> 14 | T8: =IF(S8="","",IF(OR(Q8=2,S8>=40),"ASPETO AMBIENTAL SIGNIFICATIVO (AAS)",IF(S8>=20,"Moderado",IF(S8>=0,"Não Significativo",IF(S8>=-14,"Oportunidade Tática","ASPETO AMBIENTAL SIGNIFICATIVO (AAS) BENÉFICO"))))) -> Não Significativo | U8: =IF(S8="","",IF(Q8=2,"Regra de ouro (L=2)",IF(S8>=40,"IRA ≥ 40",IF(S8>=20,"IRA 20-39",IF(S8>=0,"IRA 0-19",IF(S8>=-14,"IRA -1 a -14","IRA ≤ -15")))))) -> IRA 0-19 | V8: =IF(S8="","",RANK(S8,$S$5:$S$47,0)) -> 34 | W8: =IF(T8="","",IF(OR(T8="ASPETO AMBIENTAL SIGNIFICATIVO (AAS)",T8="Moderado"),"SIM","NÃO")) -> NÃO | X8: Segregação por fluxo; big bags retornáveis com fornecedor. | Y8: Contentores identificados no parque de resíduos. | AB8: Pesagens por código LER | AC8: F4 diário; M3; G2 resíduos não perigosos recicláveis. | AD8: LEG-01 | AH8: MED-04 | AI8: =IF(W8="SIM",IF(X8="","FALTA medida de controlo",IF(AND(LEFT(T8,6)="ASPETO",Q8=2,AG8=""),"FALTA ação corretiva (L=2)",IF(AND(LEFT(T8,6)="ASPETO",AH8=""),"Sugestão: definir monitorização","OK"))),"OK") -> OK | AJ8: Não | AK8: 46162 | AL8: =IF(AK8="","",EDATE(AK8,12)) -> 46527 | AM8: Gestor do SGA + responsável do setor
A9: AA-005 | B9: ARQ | C9: Armazém de químicos | D9: Armazenagem de tintas, solventes e óleos | E9: Produção | F9: Contaminação do solo | G9: Derrame acidental de tintas, solventes ou óleos (rutura de embalagem, queda na movimentação) | H9: Direto | I9: Emergência | J9: Futuro | K9: IMP-02 | L9: =IFERROR(INDEX(tbl_impactes[Impacte],MATCH(K9,tbl_impactes[ID_Impacte],0)),"") -> Contaminação do Solo e/ou Recursos Hídricos | M9: IMP-03 | N9: 1 | O9: 3 | P9: 5 | Q9: 1 | R9: =IF(P9="","",IF(P9<0,"(-) Benéfico","(+) Adverso")) -> (+) Adverso | S9: =IF(COUNT(N9,O9,P9,Q9)<4,"",(N9+O9)*P9*Q9) -> 20 | T9: =IF(S9="","",IF(OR(Q9=2,S9>=40),"ASPETO AMBIENTAL SIGNIFICATIVO (AAS)",IF(S9>=20,"Moderado",IF(S9>=0,"Não Significativo",IF(S9>=-14,"Oportunidade Tática","ASPETO AMBIENTAL SIGNIFICATIVO (AAS) BENÉFICO"))))) -> Moderado | U9: =IF(S9="","",IF(Q9=2,"Regra de ouro (L=2)",IF(S9>=40,"IRA ≥ 40",IF(S9>=20,"IRA 20-39",IF(S9>=0,"IRA 0-19",IF(S9>=-14,"IRA -1 a -14","IRA ≤ -15")))))) -> IRA 20-39 | V9: =IF(S9="","",RANK(S9,$S$5:$S$47,0)) -> 24 | W9: =IF(T9="","",IF(OR(T9="ASPETO AMBIENTAL SIGNIFICATIVO (AAS)",T9="Moderado"),"SIM","NÃO")) -> SIM | X9: Bacias de retenção, kits de derrame completos e selados, IT-SGA-01, simulacro semestral. | Y9: Kits de derrame; FDS; parte dos bidões em bacia. | AB9: Inventário do armazém (≈ 1,5 m³ de líquidos perigosos) | AC9: F1 emergência improvável; M3 até 200 L; G5 solventes com H336/H225 e tintas com H411. | AD9: LEG-06 | AE9: RO-10 | AG9: PAM-26-05 | AH9: MED-10 | AI9: =IF(W9="SIM",IF(X9="","FALTA medida de controlo",IF(AND(LEFT(T9,6)="ASPETO",Q9=2,AG9=""),"FALTA ação corretiva (L=2)",IF(AND(LEFT(T9,6)="ASPETO",AH9=""),"Sugestão: definir monitorização","OK"))),"OK") -> OK | AJ9: Sim | AK9: 46162 | AL9: =IF(AK9="","",EDATE(AK9,12)) -> 46527 | AM9: Gestor do SGA + responsável do setor
A10: AA-006 | B10: ARQ | C10: Armazém de químicos | D10: Manuseamento e trasfega de solventes | E10: Produção | F10: Emissões atmosféricas | G10: Evaporação de COV de recipientes abertos ou mal fechados | H10: Direto | I10: Anormal | J10: Presente | K10: IMP-03 | L10: =IFERROR(INDEX(tbl_impactes[Impacte],MATCH(K10,tbl_impactes[ID_Impacte],0)),"") -> Poluição do Ar | M10: IMP-04 | N10: 3 | O10: 2 | P10: 5 | Q10: 1 | R10: =IF(P10="","",IF(P10<0,"(-) Benéfico","(+) Adverso")) -> (+) Adverso | S10: =IF(COUNT(N10,O10,P10,Q10)<4,"",(N10+O10)*P10*Q10) -> 25 | T10: =IF(S10="","",IF(OR(Q10=2,S10>=40),"ASPETO AMBIENTAL SIGNIFICATIVO (AAS)",IF(S10>=20,"Moderado",IF(S10>=0,"Não Significativo",IF(S10>=-14,"Oportunidade Tática","ASPETO AMBIENTAL SIGNIFICATIVO (AAS) BENÉFICO"))))) -> Moderado | U10: =IF(S10="","",IF(Q10=2,"Regra de ouro (L=2)",IF(S10>=40,"IRA ≥ 40",IF(S10>=20,"IRA 20-39",IF(S10>=0,"IRA 0-19",IF(S10>=-14,"IRA -1 a -14","IRA ≤ -15")))))) -> IRA 20-39 | V10: =IF(S10="","",RANK(S10,$S$5:$S$47,0)) -> 17 | W10: =IF(T10="","",IF(OR(T10="ASPETO AMBIENTAL SIGNIFICATIVO (AAS)",T10="Moderado"),"SIM","NÃO")) -> SIM | X10: Recipientes fechados, dispensadores de segurança, regra 'tampa fechada'. | Y10: Instrução verbal. | AB10: Ronda ambiental | AC10: F3 semanal; M2 pequenas quantidades; G5 COV sem tratamento. | AD10: LEG-06 | AF10: OBJ-03 | AG10: PAM-26-08 | AH10: MED-06 | AI10: =IF(W10="SIM",IF(X10="","FALTA medida de controlo",IF(AND(LEFT(T10,6)="ASPETO",Q10=2,AG10=""),"FALTA ação corretiva (L=2)",IF(AND(LEFT(T10,6)="ASPETO",AH10=""),"Sugestão: definir monitorização","OK"))),"OK") -> OK | AJ10: Não | AK10: 46162 | AL10: =IF(AK10="","",EDATE(AK10,12)) -> 46527 | AM10: Gestor do SGA + responsável do setor
A11: AA-007 | B11: INJ | C11: Injeção de tampas | D11: Moldação por injeção (IM-001 a IM-009) | E11: Produção | F11: Consumo de recursos | G11: Consumo de energia elétrica (aquecimento do canhão, hidráulica, extração) | H11: Direto | I11: Normal | J11: Presente | K11: IMP-01 | L11: =IFERROR(INDEX(tbl_impactes[Impacte],MATCH(K11,tbl_impactes[ID_Impacte],0)),"") -> Esgotamento de Recursos Naturais / Recursos | M11: IMP-04 | N11: 5 | O11: 5 | P11: 3 | Q11: 1 | R11: =IF(P11="","",IF(P11<0,"(-) Benéfico","(+) Adverso")) -> (+) Adverso | S11: =IF(COUNT(N11,O11,P11,Q11)<4,"",(N11+O11)*P11*Q11) -> 30 | T11: =IF(S11="","",IF(OR(Q11=2,S11>=40),"ASPETO AMBIENTAL SIGNIFICATIVO (AAS)",IF(S11>=20,"Moderado",IF(S11>=0,"Não Significativo",IF(S11>=-14,"Oportunidade Tática","ASPETO AMBIENTAL SIGNIFICATIVO (AAS) BENÉFICO"))))) -> Moderado | U11: =IF(S11="","",IF(Q11=2,"Regra de ouro (L=2)",IF(S11>=40,"IRA ≥ 40",IF(S11>=20,"IRA 20-39",IF(S11>=0,"IRA 0-19",IF(S11>=-14,"IRA -1 a -14","IRA ≤ -15")))))) -> IRA 20-39 | V11: =IF(S11="","",RANK(S11,$S$5:$S$47,0)) -> 5 | W11: =IF(T11="","",IF(OR(T11="ASPETO AMBIENTAL SIGNIFICATIVO (AAS)",T11="Moderado"),"SIM","NÃO")) -> SIM | X11: Standby nas pausas (Kaizen KZ-01), manutenção de resistências e isolamento do canhão, submedição. | Y11: Manutenção preventiva. | Z11: 2186.1 | AA11: MWh/ano | AB11: Rateio da fatura por horas de marcha (sem submedição) | AC11: F5 contínuo; M5 um dos maiores consumos; G3 emissões indiretas convencionais. | AD11: LEG-08 | AE11: RO-02 | AF11: OBJ-01 | AG11: PAM-26-06 | AH11: MED-01 | AI11: =IF(W11="SIM",IF(X11="","FALTA medida de controlo",IF(AND(LEFT(T11,6)="ASPETO",Q11=2,AG11=""),"FALTA ação corretiva (L=2)",IF(AND(LEFT(T11,6)="ASPETO",AH11=""),"Sugestão: definir monitorização","OK"))),"OK") -> OK | AJ11: Não | AK11: 46162 | AL11: =IF(AK11="","",EDATE(AK11,12)) -> 46527 | AM11: Gestor do SGA + responsável do setor
A12: AA-008 | B12: INJ | C12: Injeção de tampas | D12: Moldação por injeção (IM-001 a IM-009) | E12: Produção | F12: Resíduos | G12: Geração de scrap plástico (peças rejeitadas, jitos e purgas de arranque) | H12: Direto | I12: Normal | J12: Presente | K12: IMP-01 | L12: =IFERROR(INDEX(tbl_impactes[Impacte],MATCH(K12,tbl_impactes[ID_Impacte],0)),"") -> Esgotamento de Recursos Naturais / Recursos | M12: IMP-07 | N12: 5 | O12: 3 | P12: 3 | Q12: 1 | R12: =IF(P12="","",IF(P12<0,"(-) Benéfico","(+) Adverso")) -> (+) Adverso | S12: =IF(COUNT(N12,O12,P12,Q12)<4,"",(N12+O12)*P12*Q12) -> 24 | T12: =IF(S12="","",IF(OR(Q12=2,S12>=40),"ASPETO AMBIENTAL SIGNIFICATIVO (AAS)",IF(S12>=20,"Moderado",IF(S12>=0,"Não Significativo",IF(S12>=-14,"Oportunidade Tática","ASPETO AMBIENTAL SIGNIFICATIVO (AAS) BENÉFICO"))))) -> Moderado | U12: =IF(S12="","",IF(Q12=2,"Regra de ouro (L=2)",IF(S12>=40,"IRA ≥ 40",IF(S12>=20,"IRA 20-39",IF(S12>=0,"IRA 0-19",IF(S12>=-14,"IRA -1 a -14","IRA ≤ -15")))))) -> IRA 20-39 | V12: =IF(S12="","",RANK(S12,$S$5:$S$47,0)) -> 18 | W12: =IF(T12="","",IF(OR(T12="ASPETO AMBIENTAL SIGNIFICATIVO (AAS)",T12="Moderado"),"SIM","NÃO")) -> SIM | X12: Controlo de processo (DOE IM-002), segregação por cor e reintegração. | Y12: Moinhos junto às máquinas. | AB12: Pesagem de scrap | AC12: F5 contínuo; M3; G3 resíduo não perigoso em grande quantidade. | AD12: LEG-01 | AE12: RO-11 | AF12: OBJ-02 | AH12: MED-03 | AI12: =IF(W12="SIM",IF(X12="","FALTA medida de controlo",IF(AND(LEFT(T12,6)="ASPETO",Q12=2,AG12=""),"FALTA ação corretiva (L=2)",IF(AND(LEFT(T12,6)="ASPETO",AH12=""),"Sugestão: definir monitorização","OK"))),"OK") -> OK | AJ12: Não | AK12: 46162 | AL12: =IF(AK12="","",EDATE(AK12,12)) -> 46527 | AM12: Gestor do SGA + responsável do setor
A13: AA-009 | B13: INJ | C13: Injeção de tampas | D13: Mudança de óleo hidráulico e fugas em mangueiras | E13: Produção | F13: Contaminação do solo | G13: Fuga de óleo hidráulico durante manutenção ou por rotura de mangueira | H13: Direto | I13: Anormal | J13: Presente | K13: IMP-02 | L13: =IFERROR(INDEX(tbl_impactes[Impacte],MATCH(K13,tbl_impactes[ID_Impacte],0)),"") -> Contaminação do Solo e/ou Recursos Hídricos | N13: 2 | O13: 2 | P13: 4 | Q13: 1 | R13: =IF(P13="","",IF(P13<0,"(-) Benéfico","(+) Adverso")) -> (+) Adverso | S13: =IF(COUNT(N13,O13,P13,Q13)<4,"",(N13+O13)*P13*Q13) -> 16 | T13: =IF(S13="","",IF(OR(Q13=2,S13>=40),"ASPETO AMBIENTAL SIGNIFICATIVO (AAS)",IF(S13>=20,"Moderado",IF(S13>=0,"Não Significativo",IF(S13>=-14,"Oportunidade Tática","ASPETO AMBIENTAL SIGNIFICATIVO (AAS) BENÉFICO"))))) -> Não Significativo | U13: =IF(S13="","",IF(Q13=2,"Regra de ouro (L=2)",IF(S13>=40,"IRA ≥ 40",IF(S13>=20,"IRA 20-39",IF(S13>=0,"IRA 0-19",IF(S13>=-14,"IRA -1 a -14","IRA ≤ -15")))))) -> IRA 0-19 | V13: =IF(S13="","",RANK(S13,$S$5:$S$47,0)) -> 28 | W13: =IF(T13="","",IF(OR(T13="ASPETO AMBIENTAL SIGNIFICATIVO (AAS)",T13="Moderado"),"SIM","NÃO")) -> NÃO | X13: Tabuleiros de retenção sob a hidráulica; inspeção de mangueiras. | Y13: Absorventes na oficina. | AB13: Registos de manutenção | AC13: F2 trimestral; M2 litros; G4 óleo usado (resíduo perigoso standard). | AD13: LEG-01 | AE13: RO-10 | AI13: =IF(W13="SIM",IF(X13="","FALTA medida de controlo",IF(AND(LEFT(T13,6)="ASPETO",Q13=2,AG13=""),"FALTA ação corretiva (L=2)",IF(AND(LEFT(T13,6)="ASPETO",AH13=""),"Sugestão: definir monitorização","OK"))),"OK") -> OK | AJ13: Não | AK13: 46162 | AL13: =IF(AK13="","",EDATE(AK13,12)) -> 46527 | AM13: Gestor do SGA + responsável do setor
A14: AA-010 | B14: SOP | C14: Sopro de frascos (ISBM) | D14: Moldação por injeção-sopro (ISBM-001 a 010) | E14: Produção | F14: Consumo de recursos | G14: Consumo de energia elétrica (aquecimento de pré-formas, sopro, hidráulica) | H14: Direto | I14: Normal | J14: Presente | K14: IMP-01 | L14: =IFERROR(INDEX(tbl_impactes[Impacte],MATCH(K14,tbl_impactes[ID_Impacte],0)),"") -> Esgotamento de Recursos Naturais / Recursos | M14: IMP-04 | N14: 5 | O14: 5 | P14: 3 | Q14: 1 | R14: =IF(P14="","",IF(P14<0,"(-) Benéfico","(+) Adverso")) -> (+) Adverso | S14: =IF(COUNT(N14,O14,P14,Q14)<4,"",(N14+O14)*P14*Q14) -> 30 | T14: =IF(S14="","",IF(OR(Q14=2,S14>=40),"ASPETO AMBIENTAL SIGNIFICATIVO (AAS)",IF(S14>=20,"Moderado",IF(S14>=0,"Não Significativo",IF(S14>=-14,"Oportunidade Tática","ASPETO AMBIENTAL SIGNIFICATIVO (AAS) BENÉFICO"))))) -> Moderado | U14: =IF(S14="","",IF(Q14=2,"Regra de ouro (L=2)",IF(S14>=40,"IRA ≥ 40",IF(S14>=20,"IRA 20-39",IF(S14>=0,"IRA 0-19",IF(S14>=-14,"IRA -1 a -14","IRA ≤ -15")))))) -> IRA 20-39 | V14: =IF(S14="","",RANK(S14,$S$5:$S$47,0)) -> 5 | W14: =IF(T14="","",IF(OR(T14="ASPETO AMBIENTAL SIGNIFICATIVO (AAS)",T14="Moderado"),"SIM","NÃO")) -> SIM | X14: Submedição, ajuste de temperaturas de condicionamento, standby nas pausas. | Y14: Manutenção preventiva. | Z14: 3137.2 | AA14: MWh/ano | AB14: Rateio da fatura por horas de marcha (sem submedição) | AC14: F5 contínuo; M5 maior consumo de energia; G3. | AD14: LEG-08 | AE14: RO-02 | AF14: OBJ-01 | AG14: PAM-26-02 | AH14: MED-01 | AI14: =IF(W14="SIM",IF(X14="","FALTA medida de controlo",IF(AND(LEFT(T14,6)="ASPETO",Q14=2,AG14=""),"FALTA ação corretiva (L=2)",IF(AND(LEFT(T14,6)="ASPETO",AH14=""),"Sugestão: definir monitorização","OK"))),"OK") -> OK | AJ14: Não | AK14: 46162 | AL14: =IF(AK14="","",EDATE(AK14,12)) -> 46527 | AM14: Gestor do SGA + responsável do setor
A15: AA-011 | B15: SOP | C15: Sopro de frascos (ISBM) | D15: Moldação por injeção-sopro (ISBM-001 a 010) | E15: Produção | F15: Resíduos | G15: Geração de scrap plástico (frascos rejeitados e purgas) | H15: Direto | I15: Normal | J15: Presente | K15: IMP-01 | L15: =IFERROR(INDEX(tbl_impactes[Impacte],MATCH(K15,tbl_impactes[ID_Impacte],0)),"") -> Esgotamento de Recursos Naturais / Recursos | M15: IMP-07 | N15: 5 | O15: 4 | P15: 3 | Q15: 1 | R15: =IF(P15="","",IF(P15<0,"(-) Benéfico","(+) Adverso")) -> (+) Adverso | S15: =IF(COUNT(N15,O15,P15,Q15)<4,"",(N15+O15)*P15*Q15) -> 27 | T15: =IF(S15="","",IF(OR(Q15=2,S15>=40),"ASPETO AMBIENTAL SIGNIFICATIVO (AAS)",IF(S15>=20,"Moderado",IF(S15>=0,"Não Significativo",IF(S15>=-14,"Oportunidade Tática","ASPETO AMBIENTAL SIGNIFICATIVO (AAS) BENÉFICO"))))) -> Moderado | U15: =IF(S15="","",IF(Q15=2,"Regra de ouro (L=2)",IF(S15>=40,"IRA ≥ 40",IF(S15>=20,"IRA 20-39",IF(S15>=0,"IRA 0-19",IF(S15>=-14,"IRA -1 a -14","IRA ≤ -15")))))) -> IRA 20-39 | V15: =IF(S15="","",RANK(S15,$S$5:$S$47,0)) -> 12 | W15: =IF(T15="","",IF(OR(T15="ASPETO AMBIENTAL SIGNIFICATIVO (AAS)",T15="Moderado"),"SIM","NÃO")) -> SIM | X15: Controlo da espessura de parede (ISBM-003), manutenção de moldes, reintegração. | Y15: Cartas de controlo. | Z15: 33.6 | AA15: t/ano (todos os processos) | AB15: Pesagem de scrap | AC15: F5; M4 maior fluxo de scrap; G3. | AD15: LEG-01 | AE15: RO-11 | AF15: OBJ-02 | AH15: MED-03 | AI15: =IF(W15="SIM",IF(X15="","FALTA medida de controlo",IF(AND(LEFT(T15,6)="ASPETO",Q15=2,AG15=""),"FALTA ação corretiva (L=2)",IF(AND(LEFT(T15,6)="ASPETO",AH15=""),"Sugestão: definir monitorização","OK"))),"OK") -> OK | AJ15: Não | AK15: 46162 | AL15: =IF(AK15="","",EDATE(AK15,12)) -> 46527 | AM15: Gestor do SGA + responsável do setor
A16: AA-012 | B16: SOP | C16: Sopro de frascos (ISBM) | D16: Arranque e paragem de máquinas / mudança de molde | E16: Produção | F16: Resíduos | G16: Purgas e peças de arranque após mudança de molde ou paragem | H16: Direto | I16: Anormal | J16: Presente | K16: IMP-01 | L16: =IFERROR(INDEX(tbl_impactes[Impacte],MATCH(K16,tbl_impactes[ID_Impacte],0)),"") -> Esgotamento de Recursos Naturais / Recursos | M16: IMP-07 | N16: 4 | O16: 3 | P16: 3 | Q16: 1 | R16: =IF(P16="","",IF(P16<0,"(-) Benéfico","(+) Adverso")) -> (+) Adverso | S16: =IF(COUNT(N16,O16,P16,Q16)<4,"",(N16+O16)*P16*Q16) -> 21 | T16: =IF(S16="","",IF(OR(Q16=2,S16>=40),"ASPETO AMBIENTAL SIGNIFICATIVO (AAS)",IF(S16>=20,"Moderado",IF(S16>=0,"Não Significativo",IF(S16>=-14,"Oportunidade Tática","ASPETO AMBIENTAL SIGNIFICATIVO (AAS) BENÉFICO"))))) -> Moderado | U16: =IF(S16="","",IF(Q16=2,"Regra de ouro (L=2)",IF(S16>=40,"IRA ≥ 40",IF(S16>=20,"IRA 20-39",IF(S16>=0,"IRA 0-19",IF(S16>=-14,"IRA -1 a -14","IRA ≤ -15")))))) -> IRA 20-39 | V16: =IF(S16="","",RANK(S16,$S$5:$S$47,0)) -> 22 | W16: =IF(T16="","",IF(OR(T16="ASPETO AMBIENTAL SIGNIFICATIVO (AAS)",T16="Moderado"),"SIM","NÃO")) -> SIM | X16: SMED e receitas de arranque validadas. | Y16: Setup padrão. | AB16: Registos de setup | AC16: F4 diário; M3; G3. | AF16: OBJ-02 | AH16: MED-03 | AI16: =IF(W16="SIM",IF(X16="","FALTA medida de controlo",IF(AND(LEFT(T16,6)="ASPETO",Q16=2,AG16=""),"FALTA ação corretiva (L=2)",IF(AND(LEFT(T16,6)="ASPETO",AH16=""),"Sugestão: definir monitorização","OK"))),"OK") -> OK | AJ16: Não | AK16: 46162 | AL16: =IF(AK16="","",EDATE(AK16,12)) -> 46527 | AM16: Gestor do SGA + responsável do setor
A17: AA-013 | B17: SOP | C17: Sopro de frascos (ISBM) | D17: Hidráulica envelhecida da ISBM-005 | E17: Produção | F17: Contaminação do solo | G17: Fugas de óleo hidráulico na ISBM-005 (paragens não planeadas 2,3× a média) | H17: Direto | I17: Anormal | J17: Presente | K17: IMP-02 | L17: =IFERROR(INDEX(tbl_impactes[Impacte],MATCH(K17,tbl_impactes[ID_Impacte],0)),"") -> Contaminação do Solo e/ou Recursos Hídricos | N17: 4 | O17: 2 | P17: 4 | Q17: 1 | R17: =IF(P17="","",IF(P17<0,"(-) Benéfico","(+) Adverso")) -> (+) Adverso | S17: =IF(COUNT(N17,O17,P17,Q17)<4,"",(N17+O17)*P17*Q17) -> 24 | T17: =IF(S17="","",IF(OR(Q17=2,S17>=40),"ASPETO AMBIENTAL SIGNIFICATIVO (AAS)",IF(S17>=20,"Moderado",IF(S17>=0,"Não Significativo",IF(S17>=-14,"Oportunidade Tática","ASPETO AMBIENTAL SIGNIFICATIVO (AAS) BENÉFICO"))))) -> Moderado | U17: =IF(S17="","",IF(Q17=2,"Regra de ouro (L=2)",IF(S17>=40,"IRA ≥ 40",IF(S17>=20,"IRA 20-39",IF(S17>=0,"IRA 0-19",IF(S17>=-14,"IRA -1 a -14","IRA ≤ -15")))))) -> IRA 20-39 | V17: =IF(S17="","",RANK(S17,$S$5:$S$47,0)) -> 18 | W17: =IF(T17="","",IF(OR(T17="ASPETO AMBIENTAL SIGNIFICATIVO (AAS)",T17="Moderado"),"SIM","NÃO")) -> SIM | X17: Plano de manutenção por horas de operação; tabuleiro de retenção. | Y17: Absorventes. | AB17: fact_downtime (ISBM-005) | AC17: F4 semanal; M2; G4 óleo. | AD17: LEG-01 | AE17: RO-10 | AI17: =IF(W17="SIM",IF(X17="","FALTA medida de controlo",IF(AND(LEFT(T17,6)="ASPETO",Q17=2,AG17=""),"FALTA ação corretiva (L=2)",IF(AND(LEFT(T17,6)="ASPETO",AH17=""),"Sugestão: definir monitorização","OK"))),"OK") -> OK | AJ17: Não | AK17: 46162 | AL17: =IF(AK17="","",EDATE(AK17,12)) -> 46527 | AM17: Gestor do SGA + responsável do setor
A18: AA-014 | B18: SER | C18: Serigrafia | D18: Limpeza de ecrãs e rodos com solvente | E18: Produção | F18: Emissões atmosféricas | G18: Emissão difusa de COV na limpeza de ecrãs e rodos com solvente | H18: Direto | I18: Normal | J18: Presente | K18: IMP-03 | L18: =IFERROR(INDEX(tbl_impactes[Impacte],MATCH(K18,tbl_impactes[ID_Impacte],0)),"") -> Poluição do Ar | M18: IMP-04 | N18: 5 | O18: 3 | P18: 5 | Q18: 1 | R18: =IF(P18="","",IF(P18<0,"(-) Benéfico","(+) Adverso")) -> (+) Adverso | S18: =IF(COUNT(N18,O18,P18,Q18)<4,"",(N18+O18)*P18*Q18) -> 40 | T18: =IF(S18="","",IF(OR(Q18=2,S18>=40),"ASPETO AMBIENTAL SIGNIFICATIVO (AAS)",IF(S18>=20,"Moderado",IF(S18>=0,"Não Significativo",IF(S18>=-14,"Oportunidade Tática","ASPETO AMBIENTAL SIGNIFICATIVO (AAS) BENÉFICO"))))) -> ASPETO AMBIENTAL SIGNIFICATIVO (AAS) | U18: =IF(S18="","",IF(Q18=2,"Regra de ouro (L=2)",IF(S18>=40,"IRA ≥ 40",IF(S18>=20,"IRA 20-39",IF(S18>=0,"IRA 0-19",IF(S18>=-14,"IRA -1 a -14","IRA ≤ -15")))))) -> IRA ≥ 40 | V18: =IF(S18="","",RANK(S18,$S$5:$S$47,0)) -> 2 | W18: =IF(T18="","",IF(OR(T18="ASPETO AMBIENTAL SIGNIFICATIVO (AAS)",T18="Moderado"),"SIM","NÃO")) -> SIM | X18: Dispensadores de segurança, panos pré-dosados, limpeza por necessidade, avaliação de solvente de menor volatilidade. | Y18: Exaustão localizada; FDS no posto. | Z18: 759 | AA18: kg solvente/ano | AB18: Inventário de solvente (compras - stock) | AC18: F5 em cada mudança de cor/turno; M3; G5 COV sem tratamento (PR.G.01.01). | AD18: LEG-04 | AF18: OBJ-03 | AG18: PAM-26-08 | AH18: MED-06 | AI18: =IF(W18="SIM",IF(X18="","FALTA medida de controlo",IF(AND(LEFT(T18,6)="ASPETO",Q18=2,AG18=""),"FALTA ação corretiva (L=2)",IF(AND(LEFT(T18,6)="ASPETO",AH18=""),"Sugestão: definir monitorização","OK"))),"OK") -> OK | AJ18: Sim | AK18: 46162 | AL18: =IF(AK18="","",EDATE(AK18,12)) -> 46527 | AM18: Gestor do SGA + responsável do setor
A19: AA-015 | B19: SER | C19: Serigrafia | D19: Impressão serigráfica (SS-001, SS-002) | E19: Produção | F19: Consumo de recursos | G19: Consumo de tintas de serigrafia | H19: Direto | I19: Normal | J19: Presente | K19: IMP-01 | L19: =IFERROR(INDEX(tbl_impactes[Impacte],MATCH(K19,tbl_impactes[ID_Impacte],0)),"") -> Esgotamento de Recursos Naturais / Recursos | M19: IMP-03 | N19: 5 | O19: 3 | P19: 4 | Q19: 1 | R19: =IF(P19="","",IF(P19<0,"(-) Benéfico","(+) Adverso")) -> (+) Adverso | S19: =IF(COUNT(N19,O19,P19,Q19)<4,"",(N19+O19)*P19*Q19) -> 32 | T19: =IF(S19="","",IF(OR(Q19=2,S19>=40),"ASPETO AMBIENTAL SIGNIFICATIVO (AAS)",IF(S19>=20,"Moderado",IF(S19>=0,"Não Significativo",IF(S19>=-14,"Oportunidade Tática","ASPETO AMBIENTAL SIGNIFICATIVO (AAS) BENÉFICO"))))) -> Moderado | U19: =IF(S19="","",IF(Q19=2,"Regra de ouro (L=2)",IF(S19>=40,"IRA ≥ 40",IF(S19>=20,"IRA 20-39",IF(S19>=0,"IRA 0-19",IF(S19>=-14,"IRA -1 a -14","IRA ≤ -15")))))) -> IRA 20-39 | V19: =IF(S19="","",RANK(S19,$S$5:$S$47,0)) -> 3 | W19: =IF(T19="","",IF(OR(T19="ASPETO AMBIENTAL SIGNIFICATIVO (AAS)",T19="Moderado"),"SIM","NÃO")) -> SIM | X19: Dosagem controlada; recuperação de tinta do ecrã. | Y19: — | Z19: 1099 | AA19: kg/ano | AB19: Inventário | AC19: F5; M3; G4 tintas classificadas. | AD19: LEG-06 | AF19: OBJ-03 | AH19: MED-06 | AI19: =IF(W19="SIM",IF(X19="","FALTA medida de controlo",IF(AND(LEFT(T19,6)="ASPETO",Q19=2,AG19=""),"FALTA ação corretiva (L=2)",IF(AND(LEFT(T19,6)="ASPETO",AH19=""),"Sugestão: definir monitorização","OK"))),"OK") -> OK | AJ19: Não | AK19: 46162 | AL19: =IF(AK19="","",EDATE(AK19,12)) -> 46527 | AM19: Gestor do SGA + responsável do setor
A20: AA-016 | B20: SER | C20: Serigrafia | D20: Limpeza e troca de tintas | E20: Produção | F20: Resíduos | G20: Resíduos perigosos: tinta residual (08 03 12*), panos/absorventes (15 02 02*) e embalagens contaminadas (15 01 10*) | H20: Direto | I20: Normal | J20: Presente | K20: IMP-02 | L20: =IFERROR(INDEX(tbl_impactes[Impacte],MATCH(K20,tbl_impactes[ID_Impacte],0)),"") -> Contaminação do Solo e/ou Recursos Hídricos | M20: IMP-07 | N20: 4 | O20: 3 | P20: 4 | Q20: 1 | R20: =IF(P20="","",IF(P20<0,"(-) Benéfico","(+) Adverso")) -> (+) Adverso | S20: =IF(COUNT(N20,O20,P20,Q20)<4,"",(N20+O20)*P20*Q20) -> 28 | T20: =IF(S20="","",IF(OR(Q20=2,S20>=40),"ASPETO AMBIENTAL SIGNIFICATIVO (AAS)",IF(S20>=20,"Moderado",IF(S20>=0,"Não Significativo",IF(S20>=-14,"Oportunidade Tática","ASPETO AMBIENTAL SIGNIFICATIVO (AAS) BENÉFICO"))))) -> Moderado | U20: =IF(S20="","",IF(Q20=2,"Regra de ouro (L=2)",IF(S20>=40,"IRA ≥ 40",IF(S20>=20,"IRA 20-39",IF(S20>=0,"IRA 0-19",IF(S20>=-14,"IRA -1 a -14","IRA ≤ -15")))))) -> IRA 20-39 | V20: =IF(S20="","",RANK(S20,$S$5:$S$47,0)) -> 9 | W20: =IF(T20="","",IF(OR(T20="ASPETO AMBIENTAL SIGNIFICATIVO (AAS)",T20="Moderado"),"SIM","NÃO")) -> SIM | X20: Recipientes fechados e identificados; encaminhamento por operador licenciado; e-GAR. | Y20: Contentores na área. | Z20: 2145 | AA20: kg/ano (todos os perigosos) | AB20: Pesagens e e-GAR | AC20: F4; M3; G4 resíduos perigosos standard. | AD20: LEG-01 | AE20: RO-10 | AH20: MED-04 | AI20: =IF(W20="SIM",IF(X20="","FALTA medida de controlo",IF(AND(LEFT(T20,6)="ASPETO",Q20=2,AG20=""),"FALTA ação corretiva (L=2)",IF(AND(LEFT(T20,6)="ASPETO",AH20=""),"Sugestão: definir monitorização","OK"))),"OK") -> OK | AJ20: Não | AK20: 46162 | AL20: =IF(AK20="","",EDATE(AK20,12)) -> 46527 | AM20: Gestor do SGA + responsável do setor
A21: AA-017 | B21: SER | C21: Serigrafia | D21: Mudança de tinta na linha | E21: Produção | F21: Contaminação do solo | G21: Derrame de tinta ou solvente na linha de serigrafia | H21: Direto | I21: Emergência | J21: Futuro | K21: IMP-02 | L21: =IFERROR(INDEX(tbl_impactes[Impacte],MATCH(K21,tbl_impactes[ID_Impacte],0)),"") -> Contaminação do Solo e/ou Recursos Hídricos | M21: IMP-03 | N21: 1 | O21: 2 | P21: 5 | Q21: 1 | R21: =IF(P21="","",IF(P21<0,"(-) Benéfico","(+) Adverso")) -> (+) Adverso | S21: =IF(COUNT(N21,O21,P21,Q21)<4,"",(N21+O21)*P21*Q21) -> 15 | T21: =IF(S21="","",IF(OR(Q21=2,S21>=40),"ASPETO AMBIENTAL SIGNIFICATIVO (AAS)",IF(S21>=20,"Moderado",IF(S21>=0,"Não Significativo",IF(S21>=-14,"Oportunidade Tática","ASPETO AMBIENTAL SIGNIFICATIVO (AAS) BENÉFICO"))))) -> Não Significativo | U21: =IF(S21="","",IF(Q21=2,"Regra de ouro (L=2)",IF(S21>=40,"IRA ≥ 40",IF(S21>=20,"IRA 20-39",IF(S21>=0,"IRA 0-19",IF(S21>=-14,"IRA -1 a -14","IRA ≤ -15")))))) -> IRA 0-19 | V21: =IF(S21="","",RANK(S21,$S$5:$S$47,0)) -> 33 | W21: =IF(T21="","",IF(OR(T21="ASPETO AMBIENTAL SIGNIFICATIVO (AAS)",T21="Moderado"),"SIM","NÃO")) -> NÃO | X21: Kit de derrame junto à linha; IT-SGA-01. | Y21: Kit de derrame. | AB21: Registo de incidentes | AC21: F1; M2 poucos litros; G5. | AD21: LEG-06 | AE21: RO-10 | AG21: PAM-26-05 | AI21: =IF(W21="SIM",IF(X21="","FALTA medida de controlo",IF(AND(LEFT(T21,6)="ASPETO",Q21=2,AG21=""),"FALTA ação corretiva (L=2)",IF(AND(LEFT(T21,6)="ASPETO",AH21=""),"Sugestão: definir monitorização","OK"))),"OK") -> OK | AJ21: Não | AK21: 46162 | AL21: =IF(AK21="","",EDATE(AK21,12)) -> 46527 | AM21: Gestor do SGA + responsável do setor
A22: AA-018 | B22: HFS | C22: Hot foil stamping | D22: Decoração por hot foil (HF-001, HF-002) | E22: Produção | F22: Resíduos | G22: Resíduo de foil (filme de suporte com restos de metalização) | H22: Direto | I22: Normal | J22: Presente | K22: IMP-07 | L22: =IFERROR(INDEX(tbl_impactes[Impacte],MATCH(K22,tbl_impactes[ID_Impacte],0)),"") -> Redução da vida útil de aterros e passivos ambientais | M22: IMP-01 | N22: 5 | O22: 3 | P22: 2 | Q22: 1 | R22: =IF(P22="","",IF(P22<0,"(-) Benéfico","(+) Adverso")) -> (+) Adverso | S22: =IF(COUNT(N22,O22,P22,Q22)<4,"",(N22+O22)*P22*Q22) -> 16 | T22: =IF(S22="","",IF(OR(Q22=2,S22>=40),"ASPETO AMBIENTAL SIGNIFICATIVO (AAS)",IF(S22>=20,"Moderado",IF(S22>=0,"Não Significativo",IF(S22>=-14,"Oportunidade Tática","ASPETO AMBIENTAL SIGNIFICATIVO (AAS) BENÉFICO"))))) -> Não Significativo | U22: =IF(S22="","",IF(Q22=2,"Regra de ouro (L=2)",IF(S22>=40,"IRA ≥ 40",IF(S22>=20,"IRA 20-39",IF(S22>=0,"IRA 0-19",IF(S22>=-14,"IRA -1 a -14","IRA ≤ -15")))))) -> IRA 0-19 | V22: =IF(S22="","",RANK(S22,$S$5:$S$47,0)) -> 28 | W22: =IF(T22="","",IF(OR(T22="ASPETO AMBIENTAL SIGNIFICATIVO (AAS)",T22="Moderado"),"SIM","NÃO")) -> NÃO | X22: Otimizar passo do foil; valorizar filme como plástico. | Y22: — | AB22: Pesagens | AC22: F5; M3; G2 não perigoso. | AD22: LEG-01 | AH22: MED-04 | AI22: =IF(W22="SIM",IF(X22="","FALTA medida de controlo",IF(AND(LEFT(T22,6)="ASPETO",Q22=2,AG22=""),"FALTA ação corretiva (L=2)",IF(AND(LEFT(T22,6)="ASPETO",AH22=""),"Sugestão: definir monitorização","OK"))),"OK") -> OK | AJ22: Não | AK22: 46162 | AL22: =IF(AK22="","",EDATE(AK22,12)) -> 46527 | AM22: Gestor do SGA + responsável do setor
A23: AA-019 | B23: HFS | C23: Hot foil stamping | D23: Decoração por hot foil (HF-001, HF-002) | E23: Produção | F23: Consumo de recursos | G23: Consumo de energia elétrica (placas aquecidas) | H23: Direto | I23: Normal | J23: Presente | K23: IMP-01 | L23: =IFERROR(INDEX(tbl_impactes[Impacte],MATCH(K23,tbl_impactes[ID_Impacte],0)),"") -> Esgotamento de Recursos Naturais / Recursos | M23: IMP-04 | N23: 5 | O23: 2 | P23: 3 | Q23: 1 | R23: =IF(P23="","",IF(P23<0,"(-) Benéfico","(+) Adverso")) -> (+) Adverso | S23: =IF(COUNT(N23,O23,P23,Q23)<4,"",(N23+O23)*P23*Q23) -> 21 | T23: =IF(S23="","",IF(OR(Q23=2,S23>=40),"ASPETO AMBIENTAL SIGNIFICATIVO (AAS)",IF(S23>=20,"Moderado",IF(S23>=0,"Não Significativo",IF(S23>=-14,"Oportunidade Tática","ASPETO AMBIENTAL SIGNIFICATIVO (AAS) BENÉFICO"))))) -> Moderado | U23: =IF(S23="","",IF(Q23=2,"Regra de ouro (L=2)",IF(S23>=40,"IRA ≥ 40",IF(S23>=20,"IRA 20-39",IF(S23>=0,"IRA 0-19",IF(S23>=-14,"IRA -1 a -14","IRA ≤ -15")))))) -> IRA 20-39 | V23: =IF(S23="","",RANK(S23,$S$5:$S$47,0)) -> 22 | W23: =IF(T23="","",IF(OR(T23="ASPETO AMBIENTAL SIGNIFICATIVO (AAS)",T23="Moderado"),"SIM","NÃO")) -> SIM | X23: Desligar placas nas paragens. | Y23: — | Z23: 120.1 | AA23: MWh/ano | AB23: Rateio da fatura | AC23: F5; M2; G3. | AF23: OBJ-01 | AH23: MED-01 | AI23: =IF(W23="SIM",IF(X23="","FALTA medida de controlo",IF(AND(LEFT(T23,6)="ASPETO",Q23=2,AG23=""),"FALTA ação corretiva (L=2)",IF(AND(LEFT(T23,6)="ASPETO",AH23=""),"Sugestão: definir monitorização","OK"))),"OK") -> OK | AJ23: Não | AK23: 46162 | AL23: =IF(AK23="","",EDATE(AK23,12)) -> 46527 | AM23: Gestor do SGA + responsável do setor
A24: AA-020 | B24: MOA | C24: Moagem de scrap | D24: Moagem e reintegração de rebarbas | E24: Produção | F24: Consumo de recursos | G24: Reintegração de scrap limpo (regrind) em substituição de polímero novo | H24: Direto | I24: Normal | J24: Presente | K24: IMP-10 | L24: =IFERROR(INDEX(tbl_impactes[Impacte],MATCH(K24,tbl_impactes[ID_Impacte],0)),"") -> Otimização do Consumo de Matérias-Primas (poupança ou geração de novos recursos) | M24: IMP-09 | N24: 5 | O24: 4 | P24: -1 | Q24: 1 | R24: =IF(P24="","",IF(P24<0,"(-) Benéfico","(+) Adverso")) -> (-) Benéfico | S24: =IF(COUNT(N24,O24,P24,Q24)<4,"",(N24+O24)*P24*Q24) -> -9 | T24: =IF(S24="","",IF(OR(Q24=2,S24>=40),"ASPETO AMBIENTAL SIGNIFICATIVO (AAS)",IF(S24>=20,"Moderado",IF(S24>=0,"Não Significativo",IF(S24>=-14,"Oportunidade Tática","ASPETO AMBIENTAL SIGNIFICATIVO (AAS) BENÉFICO"))))) -> Oportunidade Tática | U24: =IF(S24="","",IF(Q24=2,"Regra de ouro (L=2)",IF(S24>=40,"IRA ≥ 40",IF(S24>=20,"IRA 20-39",IF(S24>=0,"IRA 0-19",IF(S24>=-14,"IRA -1 a -14","IRA ≤ -15")))))) -> IRA -1 a -14 | V24: =IF(S24="","",RANK(S24,$S$5:$S$47,0)) -> 41 | W24: =IF(T24="","",IF(OR(T24="ASPETO AMBIENTAL SIGNIFICATIVO (AAS)",T24="Moderado"),"SIM","NÃO")) -> NÃO | X24: Segregar por polímero/cor para aumentar a taxa. | Y24: Moinhos junto às máquinas. | Z24: 12.8 | AA24: t/ano | AB24: Pesagem nos moinhos | AC24: Aspeto benéfico: G -1 circularidade interna (evita compra de matéria-prima). | AE24: RO-11 | AF24: OBJ-02 | AH24: MED-03 | AI24: =IF(W24="SIM",IF(X24="","FALTA medida de controlo",IF(AND(LEFT(T24,6)="ASPETO",Q24=2,AG24=""),"FALTA ação corretiva (L=2)",IF(AND(LEFT(T24,6)="ASPETO",AH24=""),"Sugestão: definir monitorização","OK"))),"OK") -> OK | AJ24: Não | AK24: 46162 | AL24: =IF(AK24="","",EDATE(AK24,12)) -> 46527 | AM24: Gestor do SGA + responsável do setor
A25: AA-021 | B25: UTL | C25: Utilidades | D25: Produção de ar comprimido (CMP-01/02) | E25: Produção | F25: Consumo de recursos | G25: Consumo de energia dos compressores, agravado por fugas na rede de ar comprimido | H25: Direto | I25: Normal | J25: Presente | K25: IMP-01 | L25: =IFERROR(INDEX(tbl_impactes[Impacte],MATCH(K25,tbl_impactes[ID_Impacte],0)),"") -> Esgotamento de Recursos Naturais / Recursos | M25: IMP-04 | N25: 5 | O25: 4 | P25: 3 | Q25: 1 | R25: =IF(P25="","",IF(P25<0,"(-) Benéfico","(+) Adverso")) -> (+) Adverso | S25: =IF(COUNT(N25,O25,P25,Q25)<4,"",(N25+O25)*P25*Q25) -> 27 | T25: =IF(S25="","",IF(OR(Q25=2,S25>=40),"ASPETO AMBIENTAL SIGNIFICATIVO (AAS)",IF(S25>=20,"Moderado",IF(S25>=0,"Não Significativo",IF(S25>=-14,"Oportunidade Tática","ASPETO AMBIENTAL SIGNIFICATIVO (AAS) BENÉFICO"))))) -> Moderado | U25: =IF(S25="","",IF(Q25=2,"Regra de ouro (L=2)",IF(S25>=40,"IRA ≥ 40",IF(S25>=20,"IRA 20-39",IF(S25>=0,"IRA 0-19",IF(S25>=-14,"IRA -1 a -14","IRA ≤ -15")))))) -> IRA 20-39 | V25: =IF(S25="","",RANK(S25,$S$5:$S$47,0)) -> 12 | W25: =IF(T25="","",IF(OR(T25="ASPETO AMBIENTAL SIGNIFICATIVO (AAS)",T25="Moderado"),"SIM","NÃO")) -> SIM | X25: Caça a fugas por ultrassom; reduzir pressão de 7,5 para 6,8 bar. | Y25: Manutenção dos compressores. | Z25: 1035.2 | AA25: MWh/ano | AB25: Rateio da fatura | AC25: F5; M4; G3. | AD25: LEG-08 | AE25: RO-02 | AF25: OBJ-01 | AG25: PAM-26-01 | AH25: MED-02 | AI25: =IF(W25="SIM",IF(X25="","FALTA medida de controlo",IF(AND(LEFT(T25,6)="ASPETO",Q25=2,AG25=""),"FALTA ação corretiva (L=2)",IF(AND(LEFT(T25,6)="ASPETO",AH25=""),"Sugestão: definir monitorização","OK"))),"OK") -> OK | AJ25: Não | AK25: 46162 | AL25: =IF(AK25="","",EDATE(AK25,12)) -> 46527 | AM25: Gestor do SGA + responsável do setor
A26: AA-022 | B26: UTL | C26: Utilidades | D26: Operação dos compressores novos (2026) | E26: Produção | F26: Ruído e vibrações | G26: Emissão de ruído para o exterior pelos compressores e torre de arrefecimento | H26: Direto | I26: Normal | J26: Presente | K26: IMP-05 | L26: =IFERROR(INDEX(tbl_impactes[Impacte],MATCH(K26,tbl_impactes[ID_Impacte],0)),"") -> Incomodidade da Vizinhança | N26: 5 | O26: 3 | P26: 2 | Q26: 2 | R26: =IF(P26="","",IF(P26<0,"(-) Benéfico","(+) Adverso")) -> (+) Adverso | S26: =IF(COUNT(N26,O26,P26,Q26)<4,"",(N26+O26)*P26*Q26) -> 32 | T26: =IF(S26="","",IF(OR(Q26=2,S26>=40),"ASPETO AMBIENTAL SIGNIFICATIVO (AAS)",IF(S26>=20,"Moderado",IF(S26>=0,"Não Significativo",IF(S26>=-14,"Oportunidade Tática","ASPETO AMBIENTAL SIGNIFICATIVO (AAS) BENÉFICO"))))) -> ASPETO AMBIENTAL SIGNIFICATIVO (AAS) | U26: =IF(S26="","",IF(Q26=2,"Regra de ouro (L=2)",IF(S26>=40,"IRA ≥ 40",IF(S26>=20,"IRA 20-39",IF(S26>=0,"IRA 0-19",IF(S26>=-14,"IRA -1 a -14","IRA ≤ -15")))))) -> Regra de ouro (L=2) | V26: =IF(S26="","",RANK(S26,$S$5:$S$47,0)) -> 3 | W26: =IF(T26="","",IF(OR(T26="ASPETO AMBIENTAL SIGNIFICATIVO (AAS)",T26="Moderado"),"SIM","NÃO")) -> SIM | X26: Avaliação acústica por laboratório acreditado; atenuadores se necessário. | Y26: Compressores em sala fechada. | AB26: Última avaliação acústica: 2023 (antes da troca de compressores) | AC26: L2: falta a medição obrigatória após alteração (RGR) → AAS pela regra de ouro. | AD26: LEG-05 | AE26: RO-12 | AG26: PAM-26-03 | AH26: MED-07 | AI26: =IF(W26="SIM",IF(X26="","FALTA medida de controlo",IF(AND(LEFT(T26,6)="ASPETO",Q26=2,AG26=""),"FALTA ação corretiva (L=2)",IF(AND(LEFT(T26,6)="ASPETO",AH26=""),"Sugestão: definir monitorização","OK"))),"OK") -> OK | AJ26: Não | AK26: 46162 | AL26: =IF(AK26="","",EDATE(AK26,12)) -> 46527 | AM26: Gestor do SGA + responsável do setor
A27: AA-023 | B27: UTL | C27: Utilidades | D27: Torre de arrefecimento TR-01 | E27: Produção | F27: Consumo de recursos | G27: Consumo de água de rede para reposição da torre de arrefecimento (evaporação e purga) | H27: Direto | I27: Normal | J27: Presente | K27: IMP-01 | L27: =IFERROR(INDEX(tbl_impactes[Impacte],MATCH(K27,tbl_impactes[ID_Impacte],0)),"") -> Esgotamento de Recursos Naturais / Recursos | N27: 5 | O27: 4 | P27: 3 | Q27: 1 | R27: =IF(P27="","",IF(P27<0,"(-) Benéfico","(+) Adverso")) -> (+) Adverso | S27: =IF(COUNT(N27,O27,P27,Q27)<4,"",(N27+O27)*P27*Q27) -> 27 | T27: =IF(S27="","",IF(OR(Q27=2,S27>=40),"ASPETO AMBIENTAL SIGNIFICATIVO (AAS)",IF(S27>=20,"Moderado",IF(S27>=0,"Não Significativo",IF(S27>=-14,"Oportunidade Tática","ASPETO AMBIENTAL SIGNIFICATIVO (AAS) BENÉFICO"))))) -> Moderado | U27: =IF(S27="","",IF(Q27=2,"Regra de ouro (L=2)",IF(S27>=40,"IRA ≥ 40",IF(S27>=20,"IRA 20-39",IF(S27>=0,"IRA 0-19",IF(S27>=-14,"IRA -1 a -14","IRA ≤ -15")))))) -> IRA 20-39 | V27: =IF(S27="","",RANK(S27,$S$5:$S$47,0)) -> 12 | W27: =IF(T27="","",IF(OR(T27="ASPETO AMBIENTAL SIGNIFICATIVO (AAS)",T27="Moderado"),"SIM","NÃO")) -> SIM | X27: Circuito fechado / torre adiabática; controlo da purga por condutividade. | Y27: Tratamento de água da torre. | Z27: 8330 | AA27: m³/ano | AB27: Balanço da fatura de água | AC27: F5; M4 principal consumo de água; G3. | AD27: LEG-03 | AE27: RO-04 | AF27: OBJ-05 | AG27: PAM-26-14 | AH27: MED-08 | AI27: =IF(W27="SIM",IF(X27="","FALTA medida de controlo",IF(AND(LEFT(T27,6)="ASPETO",Q27=2,AG27=""),"FALTA ação corretiva (L=2)",IF(AND(LEFT(T27,6)="ASPETO",AH27=""),"Sugestão: definir monitorização","OK"))),"OK") -> OK | AJ27: Não | AK27: 46162 | AL27: =IF(AK27="","",EDATE(AK27,12)) -> 46527 | AM27: Gestor do SGA + responsável do setor
A28: AA-024 | B28: UTL | C28: Utilidades | D28: Purga da torre de arrefecimento | E28: Produção | F28: Efluentes | G28: Descarga da purga da torre (com biocida e anti-incrustante) no coletor municipal | H28: Direto | I28: Normal | J28: Presente | K28: IMP-02 | L28: =IFERROR(INDEX(tbl_impactes[Impacte],MATCH(K28,tbl_impactes[ID_Impacte],0)),"") -> Contaminação do Solo e/ou Recursos Hídricos | N28: 4 | O28: 3 | P28: 4 | Q28: 1 | R28: =IF(P28="","",IF(P28<0,"(-) Benéfico","(+) Adverso")) -> (+) Adverso | S28: =IF(COUNT(N28,O28,P28,Q28)<4,"",(N28+O28)*P28*Q28) -> 28 | T28: =IF(S28="","",IF(OR(Q28=2,S28>=40),"ASPETO AMBIENTAL SIGNIFICATIVO (AAS)",IF(S28>=20,"Moderado",IF(S28>=0,"Não Significativo",IF(S28>=-14,"Oportunidade Tática","ASPETO AMBIENTAL SIGNIFICATIVO (AAS) BENÉFICO"))))) -> Moderado | U28: =IF(S28="","",IF(Q28=2,"Regra de ouro (L=2)",IF(S28>=40,"IRA ≥ 40",IF(S28>=20,"IRA 20-39",IF(S28>=0,"IRA 0-19",IF(S28>=-14,"IRA -1 a -14","IRA ≤ -15")))))) -> IRA 20-39 | V28: =IF(S28="","",RANK(S28,$S$5:$S$47,0)) -> 9 | W28: =IF(T28="","",IF(OR(T28="ASPETO AMBIENTAL SIGNIFICATIVO (AAS)",T28="Moderado"),"SIM","NÃO")) -> SIM | X28: Dosagem automática; análises; limites do regulamento municipal. | Y28: Autorização de descarga. | AB28: Análises semestrais do efluente | AC28: F4; M3; G4 biocida (H400). | AD28: LEG-03 | AH28: MED-11 | AI28: =IF(W28="SIM",IF(X28="","FALTA medida de controlo",IF(AND(LEFT(T28,6)="ASPETO",Q28=2,AG28=""),"FALTA ação corretiva (L=2)",IF(AND(LEFT(T28,6)="ASPETO",AH28=""),"Sugestão: definir monitorização","OK"))),"OK") -> OK | AJ28: Não | AK28: 46162 | AL28: =IF(AK28="","",EDATE(AK28,12)) -> 46527 | AM28: Gestor do SGA + responsável do setor
A29: AA-025 | B29: UTL | C29: Utilidades | D29: Chiller CH-01 (R410A) | E29: Produção | F29: Fugas | G29: Fuga de gás fluorado R410A do chiller | H29: Direto | I29: Emergência | J29: Passado | K29: IMP-04 | L29: =IFERROR(INDEX(tbl_impactes[Impacte],MATCH(K29,tbl_impactes[ID_Impacte],0)),"") -> Mudanças Climáticas | N29: 1 | O29: 1 | P29: 5 | Q29: 1 | R29: =IF(P29="","",IF(P29<0,"(-) Benéfico","(+) Adverso")) -> (+) Adverso | S29: =IF(COUNT(N29,O29,P29,Q29)<4,"",(N29+O29)*P29*Q29) -> 10 | T29: =IF(S29="","",IF(OR(Q29=2,S29>=40),"ASPETO AMBIENTAL SIGNIFICATIVO (AAS)",IF(S29>=20,"Moderado",IF(S29>=0,"Não Significativo",IF(S29>=-14,"Oportunidade Tática","ASPETO AMBIENTAL SIGNIFICATIVO (AAS) BENÉFICO"))))) -> Não Significativo | U29: =IF(S29="","",IF(Q29=2,"Regra de ouro (L=2)",IF(S29>=40,"IRA ≥ 40",IF(S29>=20,"IRA 20-39",IF(S29>=0,"IRA 0-19",IF(S29>=-14,"IRA -1 a -14","IRA ≤ -15")))))) -> IRA 0-19 | V29: =IF(S29="","",RANK(S29,$S$5:$S$47,0)) -> 37 | W29: =IF(T29="","",IF(OR(T29="ASPETO AMBIENTAL SIGNIFICATIVO (AAS)",T29="Moderado"),"SIM","NÃO")) -> NÃO | X29: Controlo de fugas conforme carga em tCO2e; técnico certificado. | Y29: Registo do equipamento. | Z29: 3.2 | AA29: kg R410A (fuga nov/2025) | AB29: Relatório do técnico certificado | AC29: F1; M1; G5 (GWP 2088). Ocorrência passada em nov/2025. | AD29: LEG-07 | AI29: =IF(W29="SIM",IF(X29="","FALTA medida de controlo",IF(AND(LEFT(T29,6)="ASPETO",Q29=2,AG29=""),"FALTA ação corretiva (L=2)",IF(AND(LEFT(T29,6)="ASPETO",AH29=""),"Sugestão: definir monitorização","OK"))),"OK") -> OK | AJ29: Não | AK29: 46162 | AL29: =IF(AK29="","",EDATE(AK29,12)) -> 46527 | AM29: Gestor do SGA + responsável do setor
A30: AA-026 | B30: MAN | C30: Manutenção | D30: Manutenção mecânica e elétrica | E30: Produção | F30: Resíduos | G30: Geração de óleos usados (13 02 05*), lâmpadas (20 01 21*) e sucata metálica | H30: Direto | I30: Anormal | J30: Presente | K30: IMP-02 | L30: =IFERROR(INDEX(tbl_impactes[Impacte],MATCH(K30,tbl_impactes[ID_Impacte],0)),"") -> Contaminação do Solo e/ou Recursos Hídricos | M30: IMP-07 | N30: 2 | O30: 3 | P30: 4 | Q30: 1 | R30: =IF(P30="","",IF(P30<0,"(-) Benéfico","(+) Adverso")) -> (+) Adverso | S30: =IF(COUNT(N30,O30,P30,Q30)<4,"",(N30+O30)*P30*Q30) -> 20 | T30: =IF(S30="","",IF(OR(Q30=2,S30>=40),"ASPETO AMBIENTAL SIGNIFICATIVO (AAS)",IF(S30>=20,"Moderado",IF(S30>=0,"Não Significativo",IF(S30>=-14,"Oportunidade Tática","ASPETO AMBIENTAL SIGNIFICATIVO (AAS) BENÉFICO"))))) -> Moderado | U30: =IF(S30="","",IF(Q30=2,"Regra de ouro (L=2)",IF(S30>=40,"IRA ≥ 40",IF(S30>=20,"IRA 20-39",IF(S30>=0,"IRA 0-19",IF(S30>=-14,"IRA -1 a -14","IRA ≤ -15")))))) -> IRA 20-39 | V30: =IF(S30="","",RANK(S30,$S$5:$S$47,0)) -> 24 | W30: =IF(T30="","",IF(OR(T30="ASPETO AMBIENTAL SIGNIFICATIVO (AAS)",T30="Moderado"),"SIM","NÃO")) -> SIM | X30: Recolha por operadores licenciados; armazenagem em bacia. | Y30: Bidão de óleo usado em bacia. | AB30: Pesagens e e-GAR | AC30: F2 trimestral; M3; G4. | AD30: LEG-01 | AH30: MED-04 | AI30: =IF(W30="SIM",IF(X30="","FALTA medida de controlo",IF(AND(LEFT(T30,6)="ASPETO",Q30=2,AG30=""),"FALTA ação corretiva (L=2)",IF(AND(LEFT(T30,6)="ASPETO",AH30=""),"Sugestão: definir monitorização","OK"))),"OK") -> OK | AJ30: Não | AK30: 46162 | AL30: =IF(AK30="","",EDATE(AK30,12)) -> 46527 | AM30: Gestor do SGA + responsável do setor
A31: AA-027 | B31: PRS | C31: Parque de resíduos | D31: Armazenagem temporária de resíduos | E31: Fim de Vida | F31: Contaminação do solo | G31: Escorrência de resíduos perigosos armazenados para a rede pluvial em dia de chuva | H31: Direto | I31: Anormal | J31: Presente | K31: IMP-02 | L31: =IFERROR(INDEX(tbl_impactes[Impacte],MATCH(K31,tbl_impactes[ID_Impacte],0)),"") -> Contaminação do Solo e/ou Recursos Hídricos | N31: 2 | O31: 2 | P31: 4 | Q31: 1 | R31: =IF(P31="","",IF(P31<0,"(-) Benéfico","(+) Adverso")) -> (+) Adverso | S31: =IF(COUNT(N31,O31,P31,Q31)<4,"",(N31+O31)*P31*Q31) -> 16 | T31: =IF(S31="","",IF(OR(Q31=2,S31>=40),"ASPETO AMBIENTAL SIGNIFICATIVO (AAS)",IF(S31>=20,"Moderado",IF(S31>=0,"Não Significativo",IF(S31>=-14,"Oportunidade Tática","ASPETO AMBIENTAL SIGNIFICATIVO (AAS) BENÉFICO"))))) -> Não Significativo | U31: =IF(S31="","",IF(Q31=2,"Regra de ouro (L=2)",IF(S31>=40,"IRA ≥ 40",IF(S31>=20,"IRA 20-39",IF(S31>=0,"IRA 0-19",IF(S31>=-14,"IRA -1 a -14","IRA ≤ -15")))))) -> IRA 0-19 | V31: =IF(S31="","",RANK(S31,$S$5:$S$47,0)) -> 28 | W31: =IF(T31="","",IF(OR(T31="ASPETO AMBIENTAL SIGNIFICATIVO (AAS)",T31="Moderado"),"SIM","NÃO")) -> NÃO | X31: Cobertura e bacia no ponto de resíduos perigosos. | Y31: Contentores fechados. | AB31: Ronda ambiental | AC31: F2; M2; G4. | AD31: LEG-01 | AE31: RO-10 | AH31: MED-10 | AI31: =IF(W31="SIM",IF(X31="","FALTA medida de controlo",IF(AND(LEFT(T31,6)="ASPETO",Q31=2,AG31=""),"FALTA ação corretiva (L=2)",IF(AND(LEFT(T31,6)="ASPETO",AH31=""),"Sugestão: definir monitorização","OK"))),"OK") -> OK | AJ31: Não | AK31: 46162 | AL31: =IF(AK31="","",EDATE(AK31,12)) -> 46527 | AM31: Gestor do SGA + responsável do setor
A32: AA-028 | B32: PRS | C32: Parque de resíduos | D32: Encaminhamento de resíduos | E32: Fim de Vida | F32: Resíduos | G32: Envio de scrap sujo e embalagens para reciclagem por operador licenciado (R3) | H32: Indireto | I32: Normal | J32: Presente | K32: IMP-11 | L32: =IFERROR(INDEX(tbl_impactes[Impacte],MATCH(K32,tbl_impactes[ID_Impacte],0)),"") -> Extensão do ciclo de vida de materiais (conversão de resíduos em subprodutos) | M32: IMP-12 | N32: 4 | O32: 3 | P32: -1 | Q32: 1 | R32: =IF(P32="","",IF(P32<0,"(-) Benéfico","(+) Adverso")) -> (-) Benéfico | S32: =IF(COUNT(N32,O32,P32,Q32)<4,"",(N32+O32)*P32*Q32) -> -7 | T32: =IF(S32="","",IF(OR(Q32=2,S32>=40),"ASPETO AMBIENTAL SIGNIFICATIVO (AAS)",IF(S32>=20,"Moderado",IF(S32>=0,"Não Significativo",IF(S32>=-14,"Oportunidade Tática","ASPETO AMBIENTAL SIGNIFICATIVO (AAS) BENÉFICO"))))) -> Oportunidade Tática | U32: =IF(S32="","",IF(Q32=2,"Regra de ouro (L=2)",IF(S32>=40,"IRA ≥ 40",IF(S32>=20,"IRA 20-39",IF(S32>=0,"IRA 0-19",IF(S32>=-14,"IRA -1 a -14","IRA ≤ -15")))))) -> IRA -1 a -14 | V32: =IF(S32="","",RANK(S32,$S$5:$S$47,0)) -> 40 | W32: =IF(T32="","",IF(OR(T32="ASPETO AMBIENTAL SIGNIFICATIVO (AAS)",T32="Moderado"),"SIM","NÃO")) -> NÃO | X32: Aumentar a segregação para subir a taxa de valorização. | Y32: Contratos com operadores. | AB32: e-GAR | AC32: Aspeto benéfico: G -1 (resíduo convertido em matéria-prima secundária). | AD32: LEG-01 | AH32: MED-04 | AI32: =IF(W32="SIM",IF(X32="","FALTA medida de controlo",IF(AND(LEFT(T32,6)="ASPETO",Q32=2,AG32=""),"FALTA ação corretiva (L=2)",IF(AND(LEFT(T32,6)="ASPETO",AH32=""),"Sugestão: definir monitorização","OK"))),"OK") -> OK | AJ32: Não | AK32: 46162 | AL32: =IF(AK32="","",EDATE(AK32,12)) -> 46527 | AM32: Gestor do SGA + responsável do setor
A33: AA-029 | B33: GER | C33: Geral | D33: Funcionamento geral da instalação | E33: Produção | F33: Resíduos | G33: Resíduos indiferenciados (20 03 01) enviados para aterro | H33: Direto | I33: Normal | J33: Presente | K33: IMP-07 | L33: =IFERROR(INDEX(tbl_impactes[Impacte],MATCH(K33,tbl_impactes[ID_Impacte],0)),"") -> Redução da vida útil de aterros e passivos ambientais | N33: 5 | O33: 3 | P33: 2 | Q33: 1 | R33: =IF(P33="","",IF(P33<0,"(-) Benéfico","(+) Adverso")) -> (+) Adverso | S33: =IF(COUNT(N33,O33,P33,Q33)<4,"",(N33+O33)*P33*Q33) -> 16 | T33: =IF(S33="","",IF(OR(Q33=2,S33>=40),"ASPETO AMBIENTAL SIGNIFICATIVO (AAS)",IF(S33>=20,"Moderado",IF(S33>=0,"Não Significativo",IF(S33>=-14,"Oportunidade Tática","ASPETO AMBIENTAL SIGNIFICATIVO (AAS) BENÉFICO"))))) -> Não Significativo | U33: =IF(S33="","",IF(Q33=2,"Regra de ouro (L=2)",IF(S33>=40,"IRA ≥ 40",IF(S33>=20,"IRA 20-39",IF(S33>=0,"IRA 0-19",IF(S33>=-14,"IRA -1 a -14","IRA ≤ -15")))))) -> IRA 0-19 | V33: =IF(S33="","",RANK(S33,$S$5:$S$47,0)) -> 28 | W33: =IF(T33="","",IF(OR(T33="ASPETO AMBIENTAL SIGNIFICATIVO (AAS)",T33="Moderado"),"SIM","NÃO")) -> NÃO | X33: Reduzir contaminação dos fluxos recicláveis. | Y33: Ecopontos. | AB33: Pesagens / e-GAR | AC33: F5; M3; G2. | AD33: LEG-01 | AH33: MED-04 | AI33: =IF(W33="SIM",IF(X33="","FALTA medida de controlo",IF(AND(LEFT(T33,6)="ASPETO",Q33=2,AG33=""),"FALTA ação corretiva (L=2)",IF(AND(LEFT(T33,6)="ASPETO",AH33=""),"Sugestão: definir monitorização","OK"))),"OK") -> OK | AJ33: Não | AK33: 46162 | AL33: =IF(AK33="","",EDATE(AK33,12)) -> 46527 | AM33: Gestor do SGA + responsável do setor
