Workbook
Name DataRef: Listas!$A$3
Name lst_Categoria: Listas!$B$3:$B$7
Name lst_DataReferencia: Listas!$A$3:$A$3
Name lst_Funcao: Listas!$D$3:$D$24
Name lst_MA_Exec: Listas!$H$3:$H$4
Name lst_MA_Res: Listas!$I$3:$I$5
Name lst_MA_SimNao: Listas!$J$3:$J$4
Name lst_MA_Tipo: Listas!$G$3:$G$8
Name lst_Processo: Listas!$C$3:$C$18
Name lst_Resultado: Listas!$E$3:$E$5
Name lst_SimNao: Listas!$F$3:$F$4

Sheet 00_LEIA-ME
A1: RG-SGA-10 — Controlo Operacional — Checklist de Supervisão e Registo de Rondas Ambientais
A2: Sistema de Gestão Ambiental NP EN ISO 14001:2026 · Plasticom — Unidade 1 (Marinha Grande, Portugal) · Registo do SGA (fábrica simulada)
A4: CONTROLO DO DOCUMENTO (7.5 — informação documentada)
A5: Código do registo | B5: RG-SGA-10
A6: Título | B6: Controlo Operacional — Checklist de Supervisão e Registo de Rondas Ambientais
A7: Versão / Revisão | B7: 01
A8: Data de emissão | B8: 46387
A9: Elaborado por | B9: Gestor(a) do SGA / EHS
A10: Aprovado por | B10: Diretor Geral
A11: Estado | B11: Em vigor
A12: Retenção | B12: 5 anos após substituição
A13: Localização | B13: Repositório controlado do SGA > Registos_SGA_Plasticom (versão eletrónica é a versão controlada; cópias impressas são não controladas)
A15: FINALIDADE E ÂMBITO
A16: Finalidade | B16: Definir os pontos de controlo com critério de aceitação objetivo (quando está OK?) e registar cada ronda ponto a ponto, com evidência e ligação às NC. O histórico semanal de 2026 permite medir a taxa de conformidade por ponto, área e mês e prever onde os desvios vão ocorrer.
A17: Atividades do curso | B17: Atividade 4.3 — Criação de Checklist de Supervisão Operacional (Ronda Ambiental): 4 categorias × 2 pontos de controlo (+ 2 pontos extra).
A18: Requisitos ISO 14001:2026 | B18: 8.1 Planeamento e controlo operacional; 8.2 (meios de emergência); 9.1.1 (monitorização)
A20: ESTRUTURA DO FICHEIRO
A21: Pontos_Controlo | B21: Checklist de supervisão: pontos de controlo e critérios de aceitação, com desempenho calculado.
A22: Execucao_Rondas | B22: Registo das rondas (1 linha por ronda × ponto) — série temporal para análise.
A23: Indicadores_Mensais | B23: Taxa de conformidade mensal por categoria (calculada) — KPI-10.
A24: Checklist_Ronda_Impressao | B24: Checklist de ronda para imprimir e levar para o terreno (pontos e critérios calculados a partir da tabela).
A25: Manutencao_Ambiental | B25: Manutenção de equipamentos com relevância ambiental: controlo de fugas F-gas, torre (Legionella), compressores, exaustão, meios de emergência (7.1, 8.1).
A26: Listas | B26: Domínios (listas de valores) usados na validação de dados das tabelas.
A27: Dicionario_Dados | B27: Descrição de cada coluna de cada tabela: tipo, origem (entrada/calculado), domínio, obrigatoriedade e chaves.
A29: CONVENÇÕES (prontas para análise de dados e machine learning)
A30: Tabelas | B30: Cada registo é uma Tabela Excel com nome próprio (tbl_*): uma linha = um registo, cabeçalho único, sem células mescladas. Ler com pandas (pd.read_excel(ficheiro, sheet_name=folha, header=<linha do cabeçalho - 1>)) ou Power BI (Obter Dados > Tabela).
A31: Cabeçalho cinzento | B31: Coluna CALCULADA por fórmula — não escrever por cima. As restantes colunas são de entrada.
A32: Validação | B32: Colunas com lista controlada só aceitam valores da folha Listas (evita categorias duplicadas por grafia diferente).
A33: Chaves | B33: IDs estáveis e únicos (PK) e referências a IDs de outros registos (FK) permitem juntar tabelas entre ficheiros — ver SGA-00_Indice_Modelo_Dados.xlsx.
A34: Datas e unidades | B34: Datas em formato data (aaaa-mm-dd); números como números; a unidade está no nome da coluna ou no dicionário. Data de referência do SGA: 2026-12-31 (fecho do ano).
A35: Dados simulados | B35: Fábrica simulada Plasticom. Dados operacionais derivados do dataset do projeto (datasets/silver); dados ambientais e de conformidade são simulação didática — confirmar aplicabilidade legal e números antes de uso real.
A37: LIGAÇÕES A OUTROS REGISTOS
A38: RG-SGA-03 Aspetos | B38: ID_Aspeto: aspeto que o ponto controla.
A39: RG-SGA-07 NC | B39: ID_NC: não conformidade aberta a partir da ronda.

Sheet Pontos_Controlo
A1: CHECKLIST DE SUPERVISÃO OPERACIONAL (RONDA AMBIENTAL) — PLASTICOM
A2: Categoria → Ponto de controlo (o que verificar?) → Critério de aceitação (quando está OK?) · Desempenho calculado a partir das rondas de 2026
A4: ID_Ponto | B4: Categoria | C4: Area | D4: Ponto_Controlo | E4: Criterio_Aceitacao | F4: Metodo | G4: Frequencia | H4: Responsavel | I4: ID_Aspeto | J4: Clausula | K4: Selecionado_Atv_4_3 | L4: N_Verificacoes | M4: Taxa_Conformidade | N4: Taxa_Ultimas_8 | O4: Tendencia
A5: RON-01 | B5: 1. Gestão de Produtos Químicos | C5: SER | D5: Recipientes de tinta e solvente no posto de serigrafia. | E5: Todos os recipientes fechados quando não estão em uso imediato; rótulo CLP legível; solvente só em dispensador de segurança. | F5: Observação direta | G5: Semanal | H5: Gestor do SGA / EHS (Responsável Ambiental) | I5: AA-014 | J5: 8.1 | K5: Sim | L5: =COUNTIF(tbl_execucao_rondas[ID_Ponto],A5) -> 52 | M5: =IFERROR(COUNTIFS(tbl_execucao_rondas[ID_Ponto],A5,tbl_execucao_rondas[Resultado],"Conforme")/L5,"") -> 0.84615385 | N5: =IFERROR(COUNTIFS(tbl_execucao_rondas[ID_Ponto],A5,tbl_execucao_rondas[Resultado],"Conforme",tbl_execucao_rondas[Data],">="&(DataRef-56))/COUNTIFS(tbl_execucao_rondas[ID_Ponto],A5,tbl_execucao_rondas[Data],">="&(DataRef-56)),"") -> 1 | O5: =IF(OR(N5="",M5=""),"",IF(N5-M5>=0.05,"▲ Melhoria",IF(M5-N5>=0.05,"▼ Degradação","≈ Estável"))) -> ▲ Melhoria
A6: RON-02 | B6: 1. Gestão de Produtos Químicos | C6: ARQ | D6: Armazenagem de bidões e embalagens de químicos no armazém. | E6: 100% dos recipientes > 20 L sobre bacia de retenção (capacidade ≥ maior recipiente); incompatíveis separados; FDS acessíveis. | F6: Observação + contagem | G6: Semanal | H6: Responsável de Armazém e Logística | I6: AA-005 | J6: 8.1 | K6: Sim | L6: =COUNTIF(tbl_execucao_rondas[ID_Ponto],A6) -> 52 | M6: =IFERROR(COUNTIFS(tbl_execucao_rondas[ID_Ponto],A6,tbl_execucao_rondas[Resultado],"Conforme")/L6,"") -> 0.76923077 | N6: =IFERROR(COUNTIFS(tbl_execucao_rondas[ID_Ponto],A6,tbl_execucao_rondas[Resultado],"Conforme",tbl_execucao_rondas[Data],">="&(DataRef-56))/COUNTIFS(tbl_execucao_rondas[ID_Ponto],A6,tbl_execucao_rondas[Data],">="&(DataRef-56)),"") -> 0.75 | O6: =IF(OR(N6="",M6=""),"",IF(N6-M6>=0.05,"▲ Melhoria",IF(M6-N6>=0.05,"▼ Degradação","≈ Estável"))) -> ≈ Estável
A7: RON-03 | B7: 2. Eficiência e Manutenção | C7: UTL | D7: Rede de ar comprimido (ligações rápidas, mangueiras, purgadores). | E7: Sem silvos (fugas audíveis); cada fuga detetada tem etiqueta e ordem de trabalho com prazo ≤ 15 dias. | F7: Escuta + detetor ultrassónico mensal | G7: Semanal | H7: Técnico de Manutenção | I7: AA-021 | J7: 8.1 | K7: Sim | L7: =COUNTIF(tbl_execucao_rondas[ID_Ponto],A7) -> 52 | M7: =IFERROR(COUNTIFS(tbl_execucao_rondas[ID_Ponto],A7,tbl_execucao_rondas[Resultado],"Conforme")/L7,"") -> 0.86538462 | N7: =IFERROR(COUNTIFS(tbl_execucao_rondas[ID_Ponto],A7,tbl_execucao_rondas[Resultado],"Conforme",tbl_execucao_rondas[Data],">="&(DataRef-56))/COUNTIFS(tbl_execucao_rondas[ID_Ponto],A7,tbl_execucao_rondas[Data],">="&(DataRef-56)),"") -> 1 | O7: =IF(OR(N7="",M7=""),"",IF(N7-M7>=0.05,"▲ Melhoria",IF(M7-N7>=0.05,"▼ Degradação","≈ Estável"))) -> ▲ Melhoria
A8: RON-04 | B8: 2. Eficiência e Manutenção | C8: INJ | D8: Máquinas de injeção/sopro: fugas de óleo e água e registos de manutenção. | E8: Piso seco sob as máquinas; tabuleiros de retenção sem óleo acumulado; plano de manutenção preventiva sem atrasos > 7 dias. | F8: Observação + consulta do registo de manutenção | G8: Semanal | H8: Técnico de Manutenção | I8: AA-009 | J8: 8.1 | K8: Sim | L8: =COUNTIF(tbl_execucao_rondas[ID_Ponto],A8) -> 52 | M8: =IFERROR(COUNTIFS(tbl_execucao_rondas[ID_Ponto],A8,tbl_execucao_rondas[Resultado],"Conforme")/L8,"") -> 0.96153846 | N8: =IFERROR(COUNTIFS(tbl_execucao_rondas[ID_Ponto],A8,tbl_execucao_rondas[Resultado],"Conforme",tbl_execucao_rondas[Data],">="&(DataRef-56))/COUNTIFS(tbl_execucao_rondas[ID_Ponto],A8,tbl_execucao_rondas[Data],">="&(DataRef-56)),"") -> 0.875 | O8: =IF(OR(N8="",M8=""),"",IF(N8-M8>=0.05,"▲ Melhoria",IF(M8-N8>=0.05,"▼ Degradação","≈ Estável"))) -> ▼ Degradação
A9: RON-05 | B9: 3. Emergência | C9: GER | D9: Válvula de corte da rede pluvial e sarjetas. | E9: Válvula acessível, sinalizada e operacional (manobra de teste); sarjetas sem obstrução; bacias de retenção secas, limpas e sem lixo. | F9: Manobra de teste + observação | G9: Mensal | H9: Técnico de Utilidades | I9: AA-034 | J9: 8.2 | K9: Sim | L9: =COUNTIF(tbl_execucao_rondas[ID_Ponto],A9) -> 13 | M9: =IFERROR(COUNTIFS(tbl_execucao_rondas[ID_Ponto],A9,tbl_execucao_rondas[Resultado],"Conforme")/L9,"") -> 0.92307692 | N9: =IFERROR(COUNTIFS(tbl_execucao_rondas[ID_Ponto],A9,tbl_execucao_rondas[Resultado],"Conforme",tbl_execucao_rondas[Data],">="&(DataRef-56))/COUNTIFS(tbl_execucao_rondas[ID_Ponto],A9,tbl_execucao_rondas[Data],">="&(DataRef-56)),"") -> 1 | O9: =IF(OR(N9="",M9=""),"",IF(N9-M9>=0.05,"▲ Melhoria",IF(M9-N9>=0.05,"▼ Degradação","≈ Estável"))) -> ▲ Melhoria
A10: RON-06 | B10: 3. Emergência | C10: GER | D10: Kits antipoluição (KIT-01 a KIT-05). | E10: Selo intacto com n.º registado; conteúdo completo (12 almofadas, 2 barreiras, luvas, óculos, sacos, instrução IT-SGA-01); acessível e sinalizado. | F10: Verificação do selo e do conteúdo | G10: Semanal (mensal até set/2026) | H10: Responsável de Armazém e Logística | I10: AA-005 | J10: 8.2 | K10: Sim | L10: =COUNTIF(tbl_execucao_rondas[ID_Ponto],A10) -> 13 | M10: =IFERROR(COUNTIFS(tbl_execucao_rondas[ID_Ponto],A10,tbl_execucao_rondas[Resultado],"Conforme")/L10,"") -> 0.92307692 | N10: =IFERROR(COUNTIFS(tbl_execucao_rondas[ID_Ponto],A10,tbl_execucao_rondas[Resultado],"Conforme",tbl_execucao_rondas[Data],">="&(DataRef-56))/COUNTIFS(tbl_execucao_rondas[ID_Ponto],A10,tbl_execucao_rondas[Data],">="&(DataRef-56)),"") -> 1 | O10: =IF(OR(N10="",M10=""),"",IF(N10-M10>=0.05,"▲ Melhoria",IF(M10-N10>=0.05,"▼ Degradação","≈ Estável"))) -> ▲ Melhoria
A11: RON-07 | B11: 4. Gestão de Resíduos | C11: PRS | D11: Segregação e identificação dos resíduos no parque e nas áreas. | E11: Cada contentor com etiqueta de código LER; sem mistura de fluxos; scrap limpo separado por cor/polímero. | F11: Observação | G11: Semanal | H11: Responsável de Armazém e Logística | I11: AA-029 | J11: 8.1 | K11: Sim | L11: =COUNTIF(tbl_execucao_rondas[ID_Ponto],A11) -> 52 | M11: =IFERROR(COUNTIFS(tbl_execucao_rondas[ID_Ponto],A11,tbl_execucao_rondas[Resultado],"Conforme")/L11,"") -> 0.90384615 | N11: =IFERROR(COUNTIFS(tbl_execucao_rondas[ID_Ponto],A11,tbl_execucao_rondas[Resultado],"Conforme",tbl_execucao_rondas[Data],">="&(DataRef-56))/COUNTIFS(tbl_execucao_rondas[ID_Ponto],A11,tbl_execucao_rondas[Data],">="&(DataRef-56)),"") -> 0.875 | O11: =IF(OR(N11="",M11=""),"",IF(N11-M11>=0.05,"▲ Melhoria",IF(M11-N11>=0.05,"▼ Degradação","≈ Estável"))) -> ≈ Estável
A12: RON-08 | B12: 4. Gestão de Resíduos | C12: PRS | D12: Acondicionamento dos resíduos perigosos. | E12: Contentores fechados com tampa, identificados, em bacia e sob cobertura; zona limpa; e-GAR do último envio confirmada. | F12: Observação + SILiAmb | G12: Semanal | H12: Responsável de Armazém e Logística | I12: AA-016 | J12: 8.1 | K12: Sim | L12: =COUNTIF(tbl_execucao_rondas[ID_Ponto],A12) -> 52 | M12: =IFERROR(COUNTIFS(tbl_execucao_rondas[ID_Ponto],A12,tbl_execucao_rondas[Resultado],"Conforme")/L12,"") -> 1 | N12: =IFERROR(COUNTIFS(tbl_execucao_rondas[ID_Ponto],A12,tbl_execucao_rondas[Resultado],"Conforme",tbl_execucao_rondas[Data],">="&(DataRef-56))/COUNTIFS(tbl_execucao_rondas[ID_Ponto],A12,tbl_execucao_rondas[Data],">="&(DataRef-56)),"") -> 1 | O12: =IF(OR(N12="",M12=""),"",IF(N12-M12>=0.05,"▲ Melhoria",IF(M12-N12>=0.05,"▼ Degradação","≈ Estável"))) -> ≈ Estável
A13: RON-09 | B13: 5. Perdas de granulado e energia (extra) | C13: REC | D13: Perdas de granulado nos silos, zona de descarga e sarjetas exteriores. | E13: Sem grânulos visíveis no pavimento exterior nem nos filtros das sarjetas; tabuleiros de descarga em uso. | F13: Observação | G13: Semanal | H13: Operador de Armazém / Empilhador | I13: AA-003 | J13: 8.1 | K13: Não | L13: =COUNTIF(tbl_execucao_rondas[ID_Ponto],A13) -> 52 | M13: =IFERROR(COUNTIFS(tbl_execucao_rondas[ID_Ponto],A13,tbl_execucao_rondas[Resultado],"Conforme")/L13,"") -> 0.61538462 | N13: =IFERROR(COUNTIFS(tbl_execucao_rondas[ID_Ponto],A13,tbl_execucao_rondas[Resultado],"Conforme",tbl_execucao_rondas[Data],">="&(DataRef-56))/COUNTIFS(tbl_execucao_rondas[ID_Ponto],A13,tbl_execucao_rondas[Data],">="&(DataRef-56)),"") -> 1 | O13: =IF(OR(N13="",M13=""),"",IF(N13-M13>=0.05,"▲ Melhoria",IF(M13-N13>=0.05,"▼ Degradação","≈ Estável"))) -> ▲ Melhoria
A14: RON-11 | B14: 1. Gestão de Produtos Químicos | C14: GER | D14: Armazenagem de químicos fora do armazém (torre TR-01, oficina, parque de gases, depósito de gasóleo, laboratório, sala de baterias). | E14: Recipientes em bacia com capacidade suficiente; incompatíveis separados (hipoclorito × ácidos; oxigénio × gases inflamáveis); kit acessível; FDS disponíveis; sem fugas. | F14: Observação + contagem (locais ARM-04 a ARM-09 do RG-SGA-21) | G14: Mensal | H14: Responsável de Armazém e Logística | I14: AA-005 | J14: 8.1 | K14: Não | L14: =COUNTIF(tbl_execucao_rondas[ID_Ponto],A14) -> 13 | M14: =IFERROR(COUNTIFS(tbl_execucao_rondas[ID_Ponto],A14,tbl_execucao_rondas[Resultado],"Conforme")/L14,"") -> 1 | N14: =IFERROR(COUNTIFS(tbl_execucao_rondas[ID_Ponto],A14,tbl_execucao_rondas[Resultado],"Conforme",tbl_execucao_rondas[Data],">="&(DataRef-56))/COUNTIFS(tbl_execucao_rondas[ID_Ponto],A14,tbl_execucao_rondas[Data],">="&(DataRef-56)),"") -> 1 | O14: =IF(OR(N14="",M14=""),"",IF(N14-M14>=0.05,"▲ Melhoria",IF(M14-N14>=0.05,"▼ Degradação","≈ Estável"))) -> ≈ Estável
A15: RON-10 | B15: 5. Perdas de granulado e energia (extra) | C15: INJ | D15: Máquinas e iluminação em paragens. | E15: Máquinas paradas > 30 min em standby; iluminação desligada em zonas sem atividade. | F15: Observação | G15: Semanal | H15: Chefe de Turno | I15: AA-007 | J15: 8.1 | K15: Não | L15: =COUNTIF(tbl_execucao_rondas[ID_Ponto],A15) -> 52 | M15: =IFERROR(COUNTIFS(tbl_execucao_rondas[ID_Ponto],A15,tbl_execucao_rondas[Resultado],"Conforme")/L15,"") -> 0.82692308 | N15: =IFERROR(COUNTIFS(tbl_execucao_rondas[ID_Ponto],A15,tbl_execucao_rondas[Resultado],"Conforme",tbl_execucao_rondas[Data],">="&(DataRef-56))/COUNTIFS(tbl_execucao_rondas[ID_Ponto],A15,tbl_execucao_rondas[Data],">="&(DataRef-56)),"") -> 1 | O15: =IF(OR(N15="",M15=""),"",IF(N15-M15>=0.05,"▲ Melhoria",IF(M15-N15>=0.05,"▼ Degradação","≈ Estável"))) -> ▲ Melhoria

Sheet Execucao_Rondas
A1: ID_Ronda | B1: Data | C1: Ano_Mes | D1: Turno | E1: ID_Ponto | F1: Categoria | G1: Resultado | H1: Observacao | I1: Acao_Imediata | J1: ID_NC | K1: Evidencia_Foto | L1: Verificador | M1: NC_Flag
A2: RND-26-01 | B2: 46027 | C2: =YEAR(B2)*100+MONTH(B2) -> 202601 | D2: 1 | E2: RON-01 | F2: =IFERROR(INDEX(tbl_pontos[Categoria],MATCH(E2,tbl_pontos[ID_Ponto],0)),"") -> 1. Gestão de Produtos Químicos | G2: Conforme | L2: Gestor do SGA / EHS (Responsável Ambiental) | M2: =IF(G2="Não conforme",1,0) -> 0
A3: RND-26-01 | B3: 46027 | C3: =YEAR(B3)*100+MONTH(B3) -> 202601 | D3: 3 | E3: RON-02 | F3: =IFERROR(INDEX(tbl_pontos[Categoria],MATCH(E3,tbl_pontos[ID_Ponto],0)),"") -> 1. Gestão de Produtos Químicos | G3: Conforme | L3: Gestor do SGA / EHS (Responsável Ambiental) | M3: =IF(G3="Não conforme",1,0) -> 0
A4: RND-26-01 | B4: 46027 | C4: =YEAR(B4)*100+MONTH(B4) -> 202601 | D4: 2 | E4: RON-03 | F4: =IFERROR(INDEX(tbl_pontos[Categoria],MATCH(E4,tbl_pontos[ID_Ponto],0)),"") -> 2. Eficiência e Manutenção | G4: Conforme | L4: Gestor do SGA / EHS (Responsável Ambiental) | M4: =IF(G4="Não conforme",1,0) -> 0
A5: RND-26-01 | B5: 46027 | C5: =YEAR(B5)*100+MONTH(B5) -> 202601 | D5: 2 | E5: RON-04 | F5: =IFERROR(INDEX(tbl_pontos[Categoria],MATCH(E5,tbl_pontos[ID_Ponto],0)),"") -> 2. Eficiência e Manutenção | G5: Conforme | L5: Gestor do SGA / EHS (Responsável Ambiental) | M5: =IF(G5="Não conforme",1,0) -> 0
A6: RND-26-01 | B6: 46027 | C6: =YEAR(B6)*100+MONTH(B6) -> 202601 | D6: 1 | E6: RON-05 | F6: =IFERROR(INDEX(tbl_pontos[Categoria],MATCH(E6,tbl_pontos[ID_Ponto],0)),"") -> 3. Emergência | G6: Conforme | L6: Gestor do SGA / EHS (Responsável Ambiental) | M6: =IF(G6="Não conforme",1,0) -> 0
A7: RND-26-01 | B7: 46027 | C7: =YEAR(B7)*100+MONTH(B7) -> 202601 | D7: 1 | E7: RON-06 | F7: =IFERROR(INDEX(tbl_pontos[Categoria],MATCH(E7,tbl_pontos[ID_Ponto],0)),"") -> 3. Emergência | G7: Conforme | L7: Gestor do SGA / EHS (Responsável Ambiental) | M7: =IF(G7="Não conforme",1,0) -> 0
A8: RND-26-01 | B8: 46027 | C8: =YEAR(B8)*100+MONTH(B8) -> 202601 | D8: 1 | E8: RON-07 | F8: =IFERROR(INDEX(tbl_pontos[Categoria],MATCH(E8,tbl_pontos[ID_Ponto],0)),"") -> 4. Gestão de Resíduos | G8: Conforme | L8: Gestor do SGA / EHS (Responsável Ambiental) | M8: =IF(G8="Não conforme",1,0) -> 0
A9: RND-26-01 | B9: 46027 | C9: =YEAR(B9)*100+MONTH(B9) -> 202601 | D9: 1 | E9: RON-08 | F9: =IFERROR(INDEX(tbl_pontos[Categoria],MATCH(E9,tbl_pontos[ID_Ponto],0)),"") -> 4. Gestão de Resíduos | G9: Conforme | L9: Gestor do SGA / EHS (Responsável Ambiental) | M9: =IF(G9="Não conforme",1,0) -> 0
A10: RND-26-01 | B10: 46027 | C10: =YEAR(B10)*100+MONTH(B10) -> 202601 | D10: 2 | E10: RON-09 | F10: =IFERROR(INDEX(tbl_pontos[Categoria],MATCH(E10,tbl_pontos[ID_Ponto],0)),"") -> 5. Perdas de granulado e energia (extra) | G10: Conforme | L10: Gestor do SGA / EHS (Responsável Ambiental) | M10: =IF(G10="Não conforme",1,0) -> 0
A11: RND-26-01 | B11: 46027 | C11: =YEAR(B11)*100+MONTH(B11) -> 202601 | D11: 1 | E11: RON-10 | F11: =IFERROR(INDEX(tbl_pontos[Categoria],MATCH(E11,tbl_pontos[ID_Ponto],0)),"") -> 5. Perdas de granulado e energia (extra) | G11: Não conforme | H11: Máquina parada sem standby. | I11: Corrigido no momento | K11: RND-26-01-RON-10.jpg | L11: Gestor do SGA / EHS (Responsável Ambiental) | M11: =IF(G11="Não conforme",1,0) -> 1
A12: RND-26-02 | B12: 46034 | C12: =YEAR(B12)*100+MONTH(B12) -> 202601 | D12: 1 | E12: RON-01 | F12: =IFERROR(INDEX(tbl_pontos[Categoria],MATCH(E12,tbl_pontos[ID_Ponto],0)),"") -> 1. Gestão de Produtos Químicos | G12: Conforme | L12: Chefe de Turno | M12: =IF(G12="Não conforme",1,0) -> 0
A13: RND-26-02 | B13: 46034 | C13: =YEAR(B13)*100+MONTH(B13) -> 202601 | D13: 2 | E13: RON-02 | F13: =IFERROR(INDEX(tbl_pontos[Categoria],MATCH(E13,tbl_pontos[ID_Ponto],0)),"") -> 1. Gestão de Produtos Químicos | G13: Conforme | L13: Chefe de Turno | M13: =IF(G13="Não conforme",1,0) -> 0
A14: RND-26-02 | B14: 46034 | C14: =YEAR(B14)*100+MONTH(B14) -> 202601 | D14: 1 | E14: RON-03 | F14: =IFERROR(INDEX(tbl_pontos[Categoria],MATCH(E14,tbl_pontos[ID_Ponto],0)),"") -> 2. Eficiência e Manutenção | G14: Conforme | L14: Chefe de Turno | M14: =IF(G14="Não conforme",1,0) -> 0
A15: RND-26-02 | B15: 46034 | C15: =YEAR(B15)*100+MONTH(B15) -> 202601 | D15: 3 | E15: RON-04 | F15: =IFERROR(INDEX(tbl_pontos[Categoria],MATCH(E15,tbl_pontos[ID_Ponto],0)),"") -> 2. Eficiência e Manutenção | G15: Conforme | L15: Chefe de Turno | M15: =IF(G15="Não conforme",1,0) -> 0
A16: RND-26-02 | B16: 46034 | C16: =YEAR(B16)*100+MONTH(B16) -> 202601 | D16: 1 | E16: RON-07 | F16: =IFERROR(INDEX(tbl_pontos[Categoria],MATCH(E16,tbl_pontos[ID_Ponto],0)),"") -> 4. Gestão de Resíduos | G16: Conforme | L16: Chefe de Turno | M16: =IF(G16="Não conforme",1,0) -> 0
A17: RND-26-02 | B17: 46034 | C17: =YEAR(B17)*100+MONTH(B17) -> 202601 | D17: 1 | E17: RON-08 | F17: =IFERROR(INDEX(tbl_pontos[Categoria],MATCH(E17,tbl_pontos[ID_Ponto],0)),"") -> 4. Gestão de Resíduos | G17: Conforme | L17: Chefe de Turno | M17: =IF(G17="Não conforme",1,0) -> 0
A18: RND-26-02 | B18: 46034 | C18: =YEAR(B18)*100+MONTH(B18) -> 202601 | D18: 2 | E18: RON-09 | F18: =IFERROR(INDEX(tbl_pontos[Categoria],MATCH(E18,tbl_pontos[ID_Ponto],0)),"") -> 5. Perdas de granulado e energia (extra) | G18: Não conforme | H18: Grânulos no pavimento junto aos silos. | I18: Pedido de reposição / ordem de trabalho | K18: RND-26-02-RON-09.jpg | L18: Chefe de Turno | M18: =IF(G18="Não conforme",1,0) -> 1
A19: RND-26-02 | B19: 46034 | C19: =YEAR(B19)*100+MONTH(B19) -> 202601 | D19: 1 | E19: RON-10 | F19: =IFERROR(INDEX(tbl_pontos[Categoria],MATCH(E19,tbl_pontos[ID_Ponto],0)),"") -> 5. Perdas de granulado e energia (extra) | G19: Conforme | L19: Chefe de Turno | M19: =IF(G19="Não conforme",1,0) -> 0
A20: RND-26-03 | B20: 46041 | C20: =YEAR(B20)*100+MONTH(B20) -> 202601 | D20: 1 | E20: RON-01 | F20: =IFERROR(INDEX(tbl_pontos[Categoria],MATCH(E20,tbl_pontos[ID_Ponto],0)),"") -> 1. Gestão de Produtos Químicos | G20: Conforme | L20: Gestor do SGA / EHS (Responsável Ambiental) | M20: =IF(G20="Não conforme",1,0) -> 0
A21: RND-26-03 | B21: 46041 | C21: =YEAR(B21)*100+MONTH(B21) -> 202601 | D21: 1 | E21: RON-02 | F21: =IFERROR(INDEX(tbl_pontos[Categoria],MATCH(E21,tbl_pontos[ID_Ponto],0)),"") -> 1. Gestão de Produtos Químicos | G21: Não conforme | H21: Recipiente fora de bacia. | I21: Pedido de reposição / ordem de trabalho | K21: RND-26-03-RON-02.jpg | L21: Gestor do SGA / EHS (Responsável Ambiental) | M21: =IF(G21="Não conforme",1,0) -> 1
A22: RND-26-03 | B22: 46041 | C22: =YEAR(B22)*100+MONTH(B22) -> 202601 | D22: 1 | E22: RON-03 | F22: =IFERROR(INDEX(tbl_pontos[Categoria],MATCH(E22,tbl_pontos[ID_Ponto],0)),"") -> 2. Eficiência e Manutenção | G22: Conforme | L22: Gestor do SGA / EHS (Responsável Ambiental) | M22: =IF(G22="Não conforme",1,0) -> 0
A23: RND-26-03 | B23: 46041 | C23: =YEAR(B23)*100+MONTH(B23) -> 202601 | D23: 1 | E23: RON-04 | F23: =IFERROR(INDEX(tbl_pontos[Categoria],MATCH(E23,tbl_pontos[ID_Ponto],0)),"") -> 2. Eficiência e Manutenção | G23: Conforme | L23: Gestor do SGA / EHS (Responsável Ambiental) | M23: =IF(G23="Não conforme",1,0) -> 0
A24: RND-26-03 | B24: 46041 | C24: =YEAR(B24)*100+MONTH(B24) -> 202601 | D24: 1 | E24: RON-07 | F24: =IFERROR(INDEX(tbl_pontos[Categoria],MATCH(E24,tbl_pontos[ID_Ponto],0)),"") -> 4. Gestão de Resíduos | G24: Conforme | L24: Gestor do SGA / EHS (Responsável Ambiental) | M24: =IF(G24="Não conforme",1,0) -> 0
A25: RND-26-03 | B25: 46041 | C25: =YEAR(B25)*100+MONTH(B25) -> 202601 | D25: 1 | E25: RON-08 | F25: =IFERROR(INDEX(tbl_pontos[Categoria],MATCH(E25,tbl_pontos[ID_Ponto],0)),"") -> 4. Gestão de Resíduos | G25: Conforme | L25: Gestor do SGA / EHS (Responsável Ambiental) | M25: =IF(G25="Não conforme",1,0) -> 0
A26: RND-26-03 | B26: 46041 | C26: =YEAR(B26)*100+MONTH(B26) -> 202601 | D26: 2 | E26: RON-09 | F26: =IFERROR(INDEX(tbl_pontos[Categoria],MATCH(E26,tbl_pontos[ID_Ponto],0)),"") -> 5. Perdas de granulado e energia (extra) | G26: Conforme | L26: Gestor do SGA / EHS (Responsável Ambiental) | M26: =IF(G26="Não conforme",1,0) -> 0
A27: RND-26-03 | B27: 46041 | C27: =YEAR(B27)*100+MONTH(B27) -> 202601 | D27: 1 | E27: RON-10 | F27: =IFERROR(INDEX(tbl_pontos[Categoria],MATCH(E27,tbl_pontos[ID_Ponto],0)),"") -> 5. Perdas de granulado e energia (extra) | G27: Conforme | L27: Gestor do SGA / EHS (Responsável Ambiental) | M27: =IF(G27="Não conforme",1,0) -> 0
A28: RND-26-04 | B28: 46048 | C28: =YEAR(B28)*100+MONTH(B28) -> 202601 | D28: 2 | E28: RON-01 | F28: =IFERROR(INDEX(tbl_pontos[Categoria],MATCH(E28,tbl_pontos[ID_Ponto],0)),"") -> 1. Gestão de Produtos Químicos | G28: Conforme | L28: Chefe de Turno | M28: =IF(G28="Não conforme",1,0) -> 0
A29: RND-26-04 | B29: 46048 | C29: =YEAR(B29)*100+MONTH(B29) -> 202601 | D29: 1 | E29: RON-02 | F29: =IFERROR(INDEX(tbl_pontos[Categoria],MATCH(E29,tbl_pontos[ID_Ponto],0)),"") -> 1. Gestão de Produtos Químicos | G29: Conforme | L29: Chefe de Turno | M29: =IF(G29="Não conforme",1,0) -> 0
A30: RND-26-04 | B30: 46048 | C30: =YEAR(B30)*100+MONTH(B30) -> 202601 | D30: 2 | E30: RON-03 | F30: =IFERROR(INDEX(tbl_pontos[Categoria],MATCH(E30,tbl_pontos[ID_Ponto],0)),"") -> 2. Eficiência e Manutenção | G30: Não conforme | H30: Fuga audível sem etiqueta. | I30: Pedido de reposição / ordem de trabalho | K30: RND-26-04-RON-03.jpg | L30: Chefe de Turno | M30: =IF(G30="Não conforme",1,0) -> 1
A31: RND-26-04 | B31: 46048 | C31: =YEAR(B31)*100+MONTH(B31) -> 202601 | D31: 3 | E31: RON-04 | F31: =IFERROR(INDEX(tbl_pontos[Categoria],MATCH(E31,tbl_pontos[ID_Ponto],0)),"") -> 2. Eficiência e Manutenção | G31: Conforme | L31: Chefe de Turno | M31: =IF(G31="Não conforme",1,0) -> 0
A32: RND-26-04 | B32: 46048 | C32: =YEAR(B32)*100+MONTH(B32) -> 202601 | D32: 3 | E32: RON-07 | F32: =IFERROR(INDEX(tbl_pontos[Categoria],MATCH(E32,tbl_pontos[ID_Ponto],0)),"") -> 4. Gestão de Resíduos | G32: Não conforme | H32: Contentor sem etiqueta LER / mistura. | I32: Pedido de reposição / ordem de trabalho | K32: RND-26-04-RON-07.jpg | L32: Chefe de Turno | M32: =IF(G32="Não conforme",1,0) -> 1
A33: RND-26-04 | B33: 46048 | C33: =YEAR(B33)*100+MONTH(B33) -> 202601 | D33: 2 | E33: RON-08 | F33: =IFERROR(INDEX(tbl_pontos[Categoria],MATCH(E33,tbl_pontos[ID_Ponto],0)),"") -> 4. Gestão de Resíduos | G33: Conforme | L33: Chefe de Turno | M33: =IF(G33="Não conforme",1,0) -> 0
A34: RND-26-04 | B34: 46048 | C34: =YEAR(B34)*100+MONTH(B34) -> 202601 | D34: 1 | E34: RON-09 | F34: =IFERROR(INDEX(tbl_pontos[Categoria],MATCH(E34,tbl_pontos[ID_Ponto],0)),"") -> 5. Perdas de granulado e energia (extra) | G34: Conforme | L34: Chefe de Turno | M34: =IF(G34="Não conforme",1,0) -> 0
A35: RND-26-04 | B35: 46048 | C35: =YEAR(B35)*100+MONTH(B35) -> 202601 | D35: 1 | E35: RON-10 | F35: =IFERROR(INDEX(tbl_pontos[Categoria],MATCH(E35,tbl_pontos[ID_Ponto],0)),"") -> 5. Perdas de granulado e energia (extra) | G35: Conforme | L35: Chefe de Turno | M35: =IF(G35="Não conforme",1,0) -> 0
A36: RND-26-05 | B36: 46055 | C36: =YEAR(B36)*100+MONTH(B36) -> 202602 | D36: 2 | E36: RON-01 | F36: =IFERROR(INDEX(tbl_pontos[Categoria],MATCH(E36,tbl_pontos[ID_Ponto],0)),"") -> 1. Gestão de Produtos Químicos | G36: Conforme | L36: Gestor do SGA / EHS (Responsável Ambiental) | M36: =IF(G36="Não conforme",1,0) -> 0
A37: RND-26-05 | B37: 46055 | C37: =YEAR(B37)*100+MONTH(B37) -> 202602 | D37: 1 | E37: RON-02 | F37: =IFERROR(INDEX(tbl_pontos[Categoria],MATCH(E37,tbl_pontos[ID_Ponto],0)),"") -> 1. Gestão de Produtos Químicos | G37: Não conforme | H37: Recipiente fora de bacia. | I37: Pedido de reposição / ordem de trabalho | K37: RND-26-05-RON-02.jpg | L37: Gestor do SGA / EHS (Responsável Ambiental) | M37: =IF(G37="Não conforme",1,0) -> 1
A38: RND-26-05 | B38: 46055 | C38: =YEAR(B38)*100+MONTH(B38) -> 202602 | D38: 1 | E38: RON-03 | F38: =IFERROR(INDEX(tbl_pontos[Categoria],MATCH(E38,tbl_pontos[ID_Ponto],0)),"") -> 2. Eficiência e Manutenção | G38: Não conforme | H38: Fuga audível sem etiqueta. | I38: Pedido de reposição / ordem de trabalho | K38: RND-26-05-RON-03.jpg | L38: Gestor do SGA / EHS (Responsável Ambiental) | M38: =IF(G38="Não conforme",1,0) -> 1
A39: RND-26-05 | B39: 46055 | C39: =YEAR(B39)*100+MONTH(B39) -> 202602 | D39: 1 | E39: RON-04 | F39: =IFERROR(INDEX(tbl_pontos[Categoria],MATCH(E39,tbl_pontos[ID_Ponto],0)),"") -> 2. Eficiência e Manutenção | G39: Conforme | L39: Gestor do SGA / EHS (Responsável Ambiental) | M39: =IF(G39="Não conforme",1,0) -> 0
A40: RND-26-05 | B40: 46055 | C40: =YEAR(B40)*100+MONTH(B40) -> 202602 | D40: 1 | E40: RON-05 | F40: =IFERROR(INDEX(tbl_pontos[Categoria],MATCH(E40,tbl_pontos[ID_Ponto],0)),"") -> 3. Emergência | G40: Conforme | L40: Gestor do SGA / EHS (Responsável Ambiental) | M40: =IF(G40="Não conforme",1,0) -> 0
...

Sheet Indicadores_Mensais
A1: TAXA DE CONFORMIDADE DAS RONDAS POR MÊS E CATEGORIA (KPI-10)
A3: Categoria | B3: 2026-01 | C3: 2026-02 | D3: 2026-03 | E3: 2026-04 | F3: 2026-05 | G3: 2026-06 | H3: 2026-07 | I3: 2026-08 | J3: 2026-09 | K3: 2026-10 | L3: 2026-11 | M3: 2026-12 | N3: 2026
A4: 1. Gestão de Produtos Químicos | B4: =IFERROR(COUNTIFS(Execucao_Rondas!$G$2:$G$456,"Conforme",Execucao_Rondas!$F$2:$F$456,"1. Gestão de Produtos Químicos",Execucao_Rondas!$C$2:$C$456,202601)/COUNTIFS(Execucao_Rondas!$G$2:$G$456,"<>Não aplicável",Execucao_Rondas!$F$2:$F$456,"1. Gestão de Produtos Químicos",Execucao_Rondas!$C$2:$C$456,202601),"") -> 0.875 | C4: =IFERROR(COUNTIFS(Execucao_Rondas!$G$2:$G$456,"Conforme",Execucao_Rondas!$F$2:$F$456,"1. Gestão de Produtos Químicos",Execucao_Rondas!$C$2:$C$456,202602)/COUNTIFS(Execucao_Rondas!$G$2:$G$456,"<>Não aplicável",Execucao_Rondas!$F$2:$F$456,"1. Gestão de Produtos Químicos",Execucao_Rondas!$C$2:$C$456,202602),"") -> 0.875 | D4: =IFERROR(COUNTIFS(Execucao_Rondas!$G$2:$G$456,"Conforme",Execucao_Rondas!$F$2:$F$456,"1. Gestão de Produtos Químicos",Execucao_Rondas!$C$2:$C$456,202603)/COUNTIFS(Execucao_Rondas!$G$2:$G$456,"<>Não aplicável",Execucao_Rondas!$F$2:$F$456,"1. Gestão de Produtos Químicos",Execucao_Rondas!$C$2:$C$456,202603),"") -> 0.8 | E4: =IFERROR(COUNTIFS(Execucao_Rondas!$G$2:$G$456,"Conforme",Execucao_Rondas!$F$2:$F$456,"1. Gestão de Produtos Químicos",Execucao_Rondas!$C$2:$C$456,202604)/COUNTIFS(Execucao_Rondas!$G$2:$G$456,"<>Não aplicável",Execucao_Rondas!$F$2:$F$456,"1. Gestão de Produtos Químicos",Execucao_Rondas!$C$2:$C$456,202604),"") -> 0.875 | F4: =IFERROR(COUNTIFS(Execucao_Rondas!$G$2:$G$456,"Conforme",Execucao_Rondas!$F$2:$F$456,"1. Gestão de Produtos Químicos",Execucao_Rondas!$C$2:$C$456,202605)/COUNTIFS(Execucao_Rondas!$G$2:$G$456,"<>Não aplicável",Execucao_Rondas!$F$2:$F$456,"1. Gestão de Produtos Químicos",Execucao_Rondas!$C$2:$C$456,202605),"") -> 0.875 | G4: =IFERROR(COUNTIFS(Execucao_Rondas!$G$2:$G$456,"Conforme",Execucao_Rondas!$F$2:$F$456,"1. Gestão de Produtos Químicos",Execucao_Rondas!$C$2:$C$456,202606)/COUNTIFS(Execucao_Rondas!$G$2:$G$456,"<>Não aplicável",Execucao_Rondas!$F$2:$F$456,"1. Gestão de Produtos Químicos",Execucao_Rondas!$C$2:$C$456,202606),"") -> 0.6 | H4: =IFERROR(COUNTIFS(Execucao_Rondas!$G$2:$G$456,"Conforme",Execucao_Rondas!$F$2:$F$456,"1. Gestão de Produtos Químicos",Execucao_Rondas!$C$2:$C$456,202607)/COUNTIFS(Execucao_Rondas!$G$2:$G$456,"<>Não aplicável",Execucao_Rondas!$F$2:$F$456,"1. Gestão de Produtos Químicos",Execucao_Rondas!$C$2:$C$456,202607),"") -> 0.75 | I4: =IFERROR(COUNTIFS(Execucao_Rondas!$G$2:$G$456,"Conforme",Execucao_Rondas!$F$2:$F$456,"1. Gestão de Produtos Químicos",Execucao_Rondas!$C$2:$C$456,202608)/COUNTIFS(Execucao_Rondas!$G$2:$G$456,"<>Não aplicável",Execucao_Rondas!$F$2:$F$456,"1. Gestão de Produtos Químicos",Execucao_Rondas!$C$2:$C$456,202608),"") -> 0.7 | J4: =IFERROR(COUNTIFS(Execucao_Rondas!$G$2:$G$456,"Conforme",Execucao_Rondas!$F$2:$F$456,"1. Gestão de Produtos Químicos",Execucao_Rondas!$C$2:$C$456,202609)/COUNTIFS(Execucao_Rondas!$G$2:$G$456,"<>Não aplicável",Execucao_Rondas!$F$2:$F$456,"1. Gestão de Produtos Químicos",Execucao_Rondas!$C$2:$C$456,202609),"") -> 0.75 | K4: =IFERROR(COUNTIFS(Execucao_Rondas!$G$2:$G$456,"Conforme",Execucao_Rondas!$F$2:$F$456,"1. Gestão de Produtos Químicos",Execucao_Rondas!$C$2:$C$456,202610)/COUNTIFS(Execucao_Rondas!$G$2:$G$456,"<>Não aplicável",Execucao_Rondas!$F$2:$F$456,"1. Gestão de Produtos Químicos",Execucao_Rondas!$C$2:$C$456,202610),"") -> 0.91666667 | L4: =IFERROR(COUNTIFS(Execucao_Rondas!$G$2:$G$456,"Conforme",Execucao_Rondas!$F$2:$F$456,"1. Gestão de Produtos Químicos",Execucao_Rondas!$C$2:$C$456,202611)/COUNTIFS(Execucao_Rondas!$G$2:$G$456,"<>Não aplicável",Execucao_Rondas!$F$2:$F$456,"1. Gestão de Produtos Químicos",Execucao_Rondas!$C$2:$C$456,202611),"") -> 1 | M4: =IFERROR(COUNTIFS(Execucao_Rondas!$G$2:$G$456,"Conforme",Execucao_Rondas!$F$2:$F$456,"1. Gestão de Produtos Químicos",Execucao_Rondas!$C$2:$C$456,202612)/COUNTIFS(Execucao_Rondas!$G$2:$G$456,"<>Não aplicável",Execucao_Rondas!$F$2:$F$456,"1. Gestão de Produtos Químicos",Execucao_Rondas!$C$2:$C$456,202612),"") -> 0.83333333 | N4: =IFERROR(COUNTIFS(Execucao_Rondas!$G$2:$G$456,"Conforme",Execucao_Rondas!$F$2:$F$456,"1. Gestão de Produtos Químicos")/COUNTIFS(Execucao_Rondas!$G$2:$G$456,"<>Não aplicável",Execucao_Rondas!$F$2:$F$456,"1. Gestão de Produtos Químicos"),"") -> 0.82905983
A5: 2. Eficiência e Manutenção | B5: =IFERROR(COUNTIFS(Execucao_Rondas!$G$2:$G$456,"Conforme",Execucao_Rondas!$F$2:$F$456,"2. Eficiência e Manutenção",Execucao_Rondas!$C$2:$C$456,202601)/COUNTIFS(Execucao_Rondas!$G$2:$G$456,"<>Não aplicável",Execucao_Rondas!$F$2:$F$456,"2. Eficiência e Manutenção",Execucao_Rondas!$C$2:$C$456,202601),"") -> 0.875 | C5: =IFERROR(COUNTIFS(Execucao_Rondas!$G$2:$G$456,"Conforme",Execucao_Rondas!$F$2:$F$456,"2. Eficiência e Manutenção",Execucao_Rondas!$C$2:$C$456,202602)/COUNTIFS(Execucao_Rondas!$G$2:$G$456,"<>Não aplicável",Execucao_Rondas!$F$2:$F$456,"2. Eficiência e Manutenção",Execucao_Rondas!$C$2:$C$456,202602),"") -> 0.875 | D5: =IFERROR(COUNTIFS(Execucao_Rondas!$G$2:$G$456,"Conforme",Execucao_Rondas!$F$2:$F$456,"2. Eficiência e Manutenção",Execucao_Rondas!$C$2:$C$456,202603)/COUNTIFS(Execucao_Rondas!$G$2:$G$456,"<>Não aplicável",Execucao_Rondas!$F$2:$F$456,"2. Eficiência e Manutenção",Execucao_Rondas!$C$2:$C$456,202603),"") -> 0.9 | E5: =IFERROR(COUNTIFS(Execucao_Rondas!$G$2:$G$456,"Conforme",Execucao_Rondas!$F$2:$F$456,"2. Eficiência e Manutenção",Execucao_Rondas!$C$2:$C$456,202604)/COUNTIFS(Execucao_Rondas!$G$2:$G$456,"<>Não aplicável",Execucao_Rondas!$F$2:$F$456,"2. Eficiência e Manutenção",Execucao_Rondas!$C$2:$C$456,202604),"") -> 1 | F5: =IFERROR(COUNTIFS(Execucao_Rondas!$G$2:$G$456,"Conforme",Execucao_Rondas!$F$2:$F$456,"2. Eficiência e Manutenção",Execucao_Rondas!$C$2:$C$456,202605)/COUNTIFS(Execucao_Rondas!$G$2:$G$456,"<>Não aplicável",Execucao_Rondas!$F$2:$F$456,"2. Eficiência e Manutenção",Execucao_Rondas!$C$2:$C$456,202605),"") -> 0.875 | G5: =IFERROR(COUNTIFS(Execucao_Rondas!$G$2:$G$456,"Conforme",Execucao_Rondas!$F$2:$F$456,"2. Eficiência e Manutenção",Execucao_Rondas!$C$2:$C$456,202606)/COUNTIFS(Execucao_Rondas!$G$2:$G$456,"<>Não aplicável",Execucao_Rondas!$F$2:$F$456,"2. Eficiência e Manutenção",Execucao_Rondas!$C$2:$C$456,202606),"") -> 0.8 | H5: =IFERROR(COUNTIFS(Execucao_Rondas!$G$2:$G$456,"Conforme",Execucao_Rondas!$F$2:$F$456,"2. Eficiência e Manutenção",Execucao_Rondas!$C$2:$C$456,202607)/COUNTIFS(Execucao_Rondas!$G$2:$G$456,"<>Não aplicável",Execucao_Rondas!$F$2:$F$456,"2. Eficiência e Manutenção",Execucao_Rondas!$C$2:$C$456,202607),"") -> 1 | I5: =IFERROR(COUNTIFS(Execucao_Rondas!$G$2:$G$456,"Conforme",Execucao_Rondas!$F$2:$F$456,"2. Eficiência e Manutenção",Execucao_Rondas!$C$2:$C$456,202608)/COUNTIFS(Execucao_Rondas!$G$2:$G$456,"<>Não aplicável",Execucao_Rondas!$F$2:$F$456,"2. Eficiência e Manutenção",Execucao_Rondas!$C$2:$C$456,202608),"") -> 0.9 | J5: =IFERROR(COUNTIFS(Execucao_Rondas!$G$2:$G$456,"Conforme",Execucao_Rondas!$F$2:$F$456,"2. Eficiência e Manutenção",Execucao_Rondas!$C$2:$C$456,202609)/COUNTIFS(Execucao_Rondas!$G$2:$G$456,"<>Não aplicável",Execucao_Rondas!$F$2:$F$456,"2. Eficiência e Manutenção",Execucao_Rondas!$C$2:$C$456,202609),"") -> 1 | K5: =IFERROR(COUNTIFS(Execucao_Rondas!$G$2:$G$456,"Conforme",Execucao_Rondas!$F$2:$F$456,"2. Eficiência e Manutenção",Execucao_Rondas!$C$2:$C$456,202610)/COUNTIFS(Execucao_Rondas!$G$2:$G$456,"<>Não aplicável",Execucao_Rondas!$F$2:$F$456,"2. Eficiência e Manutenção",Execucao_Rondas!$C$2:$C$456,202610),"") -> 0.875 | L5: =IFERROR(COUNTIFS(Execucao_Rondas!$G$2:$G$456,"Conforme",Execucao_Rondas!$F$2:$F$456,"2. Eficiência e Manutenção",Execucao_Rondas!$C$2:$C$456,202611)/COUNTIFS(Execucao_Rondas!$G$2:$G$456,"<>Não aplicável",Execucao_Rondas!$F$2:$F$456,"2. Eficiência e Manutenção",Execucao_Rondas!$C$2:$C$456,202611),"") -> 1 | M5: =IFERROR(COUNTIFS(Execucao_Rondas!$G$2:$G$456,"Conforme",Execucao_Rondas!$F$2:$F$456,"2. Eficiência e Manutenção",Execucao_Rondas!$C$2:$C$456,202612)/COUNTIFS(Execucao_Rondas!$G$2:$G$456,"<>Não aplicável",Execucao_Rondas!$F$2:$F$456,"2. Eficiência e Manutenção",Execucao_Rondas!$C$2:$C$456,202612),"") -> 0.875 | N5: =IFERROR(COUNTIFS(Execucao_Rondas!$G$2:$G$456,"Conforme",Execucao_Rondas!$F$2:$F$456,"2. Eficiência e Manutenção")/COUNTIFS(Execucao_Rondas!$G$2:$G$456,"<>Não aplicável",Execucao_Rondas!$F$2:$F$456,"2. Eficiência e Manutenção"),"") -> 0.91346154
A6: 3. Emergência | B6: =IFERROR(COUNTIFS(Execucao_Rondas!$G$2:$G$456,"Conforme",Execucao_Rondas!$F$2:$F$456,"3. Emergência",Execucao_Rondas!$C$2:$C$456,202601)/COUNTIFS(Execucao_Rondas!$G$2:$G$456,"<>Não aplicável",Execucao_Rondas!$F$2:$F$456,"3. Emergência",Execucao_Rondas!$C$2:$C$456,202601),"") -> 1 | C6: =IFERROR(COUNTIFS(Execucao_Rondas!$G$2:$G$456,"Conforme",Execucao_Rondas!$F$2:$F$456,"3. Emergência",Execucao_Rondas!$C$2:$C$456,202602)/COUNTIFS(Execucao_Rondas!$G$2:$G$456,"<>Não aplicável",Execucao_Rondas!$F$2:$F$456,"3. Emergência",Execucao_Rondas!$C$2:$C$456,202602),"") -> 1 | D6: =IFERROR(COUNTIFS(Execucao_Rondas!$G$2:$G$456,"Conforme",Execucao_Rondas!$F$2:$F$456,"3. Emergência",Execucao_Rondas!$C$2:$C$456,202603)/COUNTIFS(Execucao_Rondas!$G$2:$G$456,"<>Não aplicável",Execucao_Rondas!$F$2:$F$456,"3. Emergência",Execucao_Rondas!$C$2:$C$456,202603),"") -> 1 | E6: =IFERROR(COUNTIFS(Execucao_Rondas!$G$2:$G$456,"Conforme",Execucao_Rondas!$F$2:$F$456,"3. Emergência",Execucao_Rondas!$C$2:$C$456,202604)/COUNTIFS(Execucao_Rondas!$G$2:$G$456,"<>Não aplicável",Execucao_Rondas!$F$2:$F$456,"3. Emergência",Execucao_Rondas!$C$2:$C$456,202604),"") -> 1 | F6: =IFERROR(COUNTIFS(Execucao_Rondas!$G$2:$G$456,"Conforme",Execucao_Rondas!$F$2:$F$456,"3. Emergência",Execucao_Rondas!$C$2:$C$456,202605)/COUNTIFS(Execucao_Rondas!$G$2:$G$456,"<>Não aplicável",Execucao_Rondas!$F$2:$F$456,"3. Emergência",Execucao_Rondas!$C$2:$C$456,202605),"") -> 1 | G6: =IFERROR(COUNTIFS(Execucao_Rondas!$G$2:$G$456,"Conforme",Execucao_Rondas!$F$2:$F$456,"3. Emergência",Execucao_Rondas!$C$2:$C$456,202606)/COUNTIFS(Execucao_Rondas!$G$2:$G$456,"<>Não aplicável",Execucao_Rondas!$F$2:$F$456,"3. Emergência",Execucao_Rondas!$C$2:$C$456,202606),"") -> 0.5 | H6: =IFERROR(COUNTIFS(Execucao_Rondas!$G$2:$G$456,"Conforme",Execucao_Rondas!$F$2:$F$456,"3. Emergência",Execucao_Rondas!$C$2:$C$456,202607)/COUNTIFS(Execucao_Rondas!$G$2:$G$456,"<>Não aplicável",Execucao_Rondas!$F$2:$F$456,"3. Emergência",Execucao_Rondas!$C$2:$C$456,202607),"") -> 1 | I6: =IFERROR(COUNTIFS(Execucao_Rondas!$G$2:$G$456,"Conforme",Execucao_Rondas!$F$2:$F$456,"3. Emergência",Execucao_Rondas!$C$2:$C$456,202608)/COUNTIFS(Execucao_Rondas!$G$2:$G$456,"<>Não aplicável",Execucao_Rondas!$F$2:$F$456,"3. Emergência",Execucao_Rondas!$C$2:$C$456,202608),"") -> 1 | J6: =IFERROR(COUNTIFS(Execucao_Rondas!$G$2:$G$456,"Conforme",Execucao_Rondas!$F$2:$F$456,"3. Emergência",Execucao_Rondas!$C$2:$C$456,202609)/COUNTIFS(Execucao_Rondas!$G$2:$G$456,"<>Não aplicável",Execucao_Rondas!$F$2:$F$456,"3. Emergência",Execucao_Rondas!$C$2:$C$456,202609),"") -> 0.75 | K6: =IFERROR(COUNTIFS(Execucao_Rondas!$G$2:$G$456,"Conforme",Execucao_Rondas!$F$2:$F$456,"3. Emergência",Execucao_Rondas!$C$2:$C$456,202610)/COUNTIFS(Execucao_Rondas!$G$2:$G$456,"<>Não aplicável",Execucao_Rondas!$F$2:$F$456,"3. Emergência",Execucao_Rondas!$C$2:$C$456,202610),"") -> 1 | L6: =IFERROR(COUNTIFS(Execucao_Rondas!$G$2:$G$456,"Conforme",Execucao_Rondas!$F$2:$F$456,"3. Emergência",Execucao_Rondas!$C$2:$C$456,202611)/COUNTIFS(Execucao_Rondas!$G$2:$G$456,"<>Não aplicável",Execucao_Rondas!$F$2:$F$456,"3. Emergência",Execucao_Rondas!$C$2:$C$456,202611),"") -> 1 | M6: =IFERROR(COUNTIFS(Execucao_Rondas!$G$2:$G$456,"Conforme",Execucao_Rondas!$F$2:$F$456,"3. Emergência",Execucao_Rondas!$C$2:$C$456,202612)/COUNTIFS(Execucao_Rondas!$G$2:$G$456,"<>Não aplicável",Execucao_Rondas!$F$2:$F$456,"3. Emergência",Execucao_Rondas!$C$2:$C$456,202612),"") -> 1 | N6: =IFERROR(COUNTIFS(Execucao_Rondas!$G$2:$G$456,"Conforme",Execucao_Rondas!$F$2:$F$456,"3. Emergência")/COUNTIFS(Execucao_Rondas!$G$2:$G$456,"<>Não aplicável",Execucao_Rondas!$F$2:$F$456,"3. Emergência"),"") -> 0.92307692
A7: 4. Gestão de Resíduos | B7: =IFERROR(COUNTIFS(Execucao_Rondas!$G$2:$G$456,"Conforme",Execucao_Rondas!$F$2:$F$456,"4. Gestão de Resíduos",Execucao_Rondas!$C$2:$C$456,202601)/COUNTIFS(Execucao_Rondas!$G$2:$G$456,"<>Não aplicável",Execucao_Rondas!$F$2:$F$456,"4. Gestão de Resíduos",Execucao_Rondas!$C$2:$C$456,202601),"") -> 0.875 | C7: =IFERROR(COUNTIFS(Execucao_Rondas!$G$2:$G$456,"Conforme",Execucao_Rondas!$F$2:$F$456,"4. Gestão de Resíduos",Execucao_Rondas!$C$2:$C$456,202602)/COUNTIFS(Execucao_Rondas!$G$2:$G$456,"<>Não aplicável",Execucao_Rondas!$F$2:$F$456,"4. Gestão de Resíduos",Execucao_Rondas!$C$2:$C$456,202602),"") -> 0.875 | D7: =IFERROR(COUNTIFS(Execucao_Rondas!$G$2:$G$456,"Conforme",Execucao_Rondas!$F$2:$F$456,"4. Gestão de Resíduos",Execucao_Rondas!$C$2:$C$456,202603)/COUNTIFS(Execucao_Rondas!$G$2:$G$456,"<>Não aplicável",Execucao_Rondas!$F$2:$F$456,"4. Gestão de Resíduos",Execucao_Rondas!$C$2:$C$456,202603),"") -> 1 | E7: =IFERROR(COUNTIFS(Execucao_Rondas!$G$2:$G$456,"Conforme",Execucao_Rondas!$F$2:$F$456,"4. Gestão de Resíduos",Execucao_Rondas!$C$2:$C$456,202604)/COUNTIFS(Execucao_Rondas!$G$2:$G$456,"<>Não aplicável",Execucao_Rondas!$F$2:$F$456,"4. Gestão de Resíduos",Execucao_Rondas!$C$2:$C$456,202604),"") -> 0.875 | F7: =IFERROR(COUNTIFS(Execucao_Rondas!$G$2:$G$456,"Conforme",Execucao_Rondas!$F$2:$F$456,"4. Gestão de Resíduos",Execucao_Rondas!$C$2:$C$456,202605)/COUNTIFS(Execucao_Rondas!$G$2:$G$456,"<>Não aplicável",Execucao_Rondas!$F$2:$F$456,"4. Gestão de Resíduos",Execucao_Rondas!$C$2:$C$456,202605),"") -> 1 | G7: =IFERROR(COUNTIFS(Execucao_Rondas!$G$2:$G$456,"Conforme",Execucao_Rondas!$F$2:$F$456,"4. Gestão de Resíduos",Execucao_Rondas!$C$2:$C$456,202606)/COUNTIFS(Execucao_Rondas!$G$2:$G$456,"<>Não aplicável",Execucao_Rondas!$F$2:$F$456,"4. Gestão de Resíduos",Execucao_Rondas!$C$2:$C$456,202606),"") -> 1 | H7: =IFERROR(COUNTIFS(Execucao_Rondas!$G$2:$G$456,"Conforme",Execucao_Rondas!$F$2:$F$456,"4. Gestão de Resíduos",Execucao_Rondas!$C$2:$C$456,202607)/COUNTIFS(Execucao_Rondas!$G$2:$G$456,"<>Não aplicável",Execucao_Rondas!$F$2:$F$456,"4. Gestão de Resíduos",Execucao_Rondas!$C$2:$C$456,202607),"") -> 1 | I7: =IFERROR(COUNTIFS(Execucao_Rondas!$G$2:$G$456,"Conforme",Execucao_Rondas!$F$2:$F$456,"4. Gestão de Resíduos",Execucao_Rondas!$C$2:$C$456,202608)/COUNTIFS(Execucao_Rondas!$G$2:$G$456,"<>Não aplicável",Execucao_Rondas!$F$2:$F$456,"4. Gestão de Resíduos",Execucao_Rondas!$C$2:$C$456,202608),"") -> 1 | J7: =IFERROR(COUNTIFS(Execucao_Rondas!$G$2:$G$456,"Conforme",Execucao_Rondas!$F$2:$F$456,"4. Gestão de Resíduos",Execucao_Rondas!$C$2:$C$456,202609)/COUNTIFS(Execucao_Rondas!$G$2:$G$456,"<>Não aplicável",Execucao_Rondas!$F$2:$F$456,"4. Gestão de Resíduos",Execucao_Rondas!$C$2:$C$456,202609),"") -> 1 | K7: =IFERROR(COUNTIFS(Execucao_Rondas!$G$2:$G$456,"Conforme",Execucao_Rondas!$F$2:$F$456,"4. Gestão de Resíduos",Execucao_Rondas!$C$2:$C$456,202610)/COUNTIFS(Execucao_Rondas!$G$2:$G$456,"<>Não aplicável",Execucao_Rondas!$F$2:$F$456,"4. Gestão de Resíduos",Execucao_Rondas!$C$2:$C$456,202610),"") -> 0.875 | L7: =IFERROR(COUNTIFS(Execucao_Rondas!$G$2:$G$456,"Conforme",Execucao_Rondas!$F$2:$F$456,"4. Gestão de Resíduos",Execucao_Rondas!$C$2:$C$456,202611)/COUNTIFS(Execucao_Rondas!$G$2:$G$456,"<>Não aplicável",Execucao_Rondas!$F$2:$F$456,"4. Gestão de Resíduos",Execucao_Rondas!$C$2:$C$456,202611),"") -> 0.9 | M7: =IFERROR(COUNTIFS(Execucao_Rondas!$G$2:$G$456,"Conforme",Execucao_Rondas!$F$2:$F$456,"4. Gestão de Resíduos",Execucao_Rondas!$C$2:$C$456,202612)/COUNTIFS(Execucao_Rondas!$G$2:$G$456,"<>Não aplicável",Execucao_Rondas!$F$2:$F$456,"4. Gestão de Resíduos",Execucao_Rondas!$C$2:$C$456,202612),"") -> 1 | N7: =IFERROR(COUNTIFS(Execucao_Rondas!$G$2:$G$456,"Conforme",Execucao_Rondas!$F$2:$F$456,"4. Gestão de Resíduos")/COUNTIFS(Execucao_Rondas!$G$2:$G$456,"<>Não aplicável",Execucao_Rondas!$F$2:$F$456,"4. Gestão de Resíduos"),"") -> 0.95192308
A8: 5. Perdas de granulado e energia (extra) | B8: =IFERROR(COUNTIFS(Execucao_Rondas!$G$2:$G$456,"Conforme",Execucao_Rondas!$F$2:$F$456,"5. Perdas de granulado e energia (extra)",Execucao_Rondas!$C$2:$C$456,202601)/COUNTIFS(Execucao_Rondas!$G$2:$G$456,"<>Não aplicável",Execucao_Rondas!$F$2:$F$456,"5. Perdas de granulado e energia (extra)",Execucao_Rondas!$C$2:$C$456,202601),"") -> 0.75 | C8: =IFERROR(COUNTIFS(Execucao_Rondas!$G$2:$G$456,"Conforme",Execucao_Rondas!$F$2:$F$456,"5. Perdas de granulado e energia (extra)",Execucao_Rondas!$C$2:$C$456,202602)/COUNTIFS(Execucao_Rondas!$G$2:$G$456,"<>Não aplicável",Execucao_Rondas!$F$2:$F$456,"5. Perdas de granulado e energia (extra)",Execucao_Rondas!$C$2:$C$456,202602),"") -> 0.75 | D8: =IFERROR(COUNTIFS(Execucao_Rondas!$G$2:$G$456,"Conforme",Execucao_Rondas!$F$2:$F$456,"5. Perdas de granulado e energia (extra)",Execucao_Rondas!$C$2:$C$456,202603)/COUNTIFS(Execucao_Rondas!$G$2:$G$456,"<>Não aplicável",Execucao_Rondas!$F$2:$F$456,"5. Perdas de granulado e energia (extra)",Execucao_Rondas!$C$2:$C$456,202603),"") -> 0.5 | E8: =IFERROR(COUNTIFS(Execucao_Rondas!$G$2:$G$456,"Conforme",Execucao_Rondas!$F$2:$F$456,"5. Perdas de granulado e energia (extra)",Execucao_Rondas!$C$2:$C$456,202604)/COUNTIFS(Execucao_Rondas!$G$2:$G$456,"<>Não aplicável",Execucao_Rondas!$F$2:$F$456,"5. Perdas de granulado e energia (extra)",Execucao_Rondas!$C$2:$C$456,202604),"") -> 0.625 | F8: =IFERROR(COUNTIFS(Execucao_Rondas!$G$2:$G$456,"Conforme",Execucao_Rondas!$F$2:$F$456,"5. Perdas de granulado e energia (extra)",Execucao_Rondas!$C$2:$C$456,202605)/COUNTIFS(Execucao_Rondas!$G$2:$G$456,"<>Não aplicável",Execucao_Rondas!$F$2:$F$456,"5. Perdas de granulado e energia (extra)",Execucao_Rondas!$C$2:$C$456,202605),"") -> 0.375 | G8: =IFERROR(COUNTIFS(Execucao_Rondas!$G$2:$G$456,"Conforme",Execucao_Rondas!$F$2:$F$456,"5. Perdas de granulado e energia (extra)",Execucao_Rondas!$C$2:$C$456,202606)/COUNTIFS(Execucao_Rondas!$G$2:$G$456,"<>Não aplicável",Execucao_Rondas!$F$2:$F$456,"5. Perdas de granulado e energia (extra)",Execucao_Rondas!$C$2:$C$456,202606),"") -> 0.6 | H8: =IFERROR(COUNTIFS(Execucao_Rondas!$G$2:$G$456,"Conforme",Execucao_Rondas!$F$2:$F$456,"5. Perdas de granulado e energia (extra)",Execucao_Rondas!$C$2:$C$456,202607)/COUNTIFS(Execucao_Rondas!$G$2:$G$456,"<>Não aplicável",Execucao_Rondas!$F$2:$F$456,"5. Perdas de granulado e energia (extra)",Execucao_Rondas!$C$2:$C$456,202607),"") -> 0.5 | I8: =IFERROR(COUNTIFS(Execucao_Rondas!$G$2:$G$456,"Conforme",Execucao_Rondas!$F$2:$F$456,"5. Perdas de granulado e energia (extra)",Execucao_Rondas!$C$2:$C$456,202608)/COUNTIFS(Execucao_Rondas!$G$2:$G$456,"<>Não aplicável",Execucao_Rondas!$F$2:$F$456,"5. Perdas de granulado e energia (extra)",Execucao_Rondas!$C$2:$C$456,202608),"") -> 0.8 | J8: =IFERROR(COUNTIFS(Execucao_Rondas!$G$2:$G$456,"Conforme",Execucao_Rondas!$F$2:$F$456,"5. Perdas de granulado e energia (extra)",Execucao_Rondas!$C$2:$C$456,202609)/COUNTIFS(Execucao_Rondas!$G$2:$G$456,"<>Não aplicável",Execucao_Rondas!$F$2:$F$456,"5. Perdas de granulado e energia (extra)",Execucao_Rondas!$C$2:$C$456,202609),"") -> 0.75 | K8: =IFERROR(COUNTIFS(Execucao_Rondas!$G$2:$G$456,"Conforme",Execucao_Rondas!$F$2:$F$456,"5. Perdas de granulado e energia (extra)",Execucao_Rondas!$C$2:$C$456,202610)/COUNTIFS(Execucao_Rondas!$G$2:$G$456,"<>Não aplicável",Execucao_Rondas!$F$2:$F$456,"5. Perdas de granulado e energia (extra)",Execucao_Rondas!$C$2:$C$456,202610),"") -> 1 | L8: =IFERROR(COUNTIFS(Execucao_Rondas!$G$2:$G$456,"Conforme",Execucao_Rondas!$F$2:$F$456,"5. Perdas de granulado e energia (extra)",Execucao_Rondas!$C$2:$C$456,202611)/COUNTIFS(Execucao_Rondas!$G$2:$G$456,"<>Não aplicável",Execucao_Rondas!$F$2:$F$456,"5. Perdas de granulado e energia (extra)",Execucao_Rondas!$C$2:$C$456,202611),"") -> 1 | M8: =IFERROR(COUNTIFS(Execucao_Rondas!$G$2:$G$456,"Conforme",Execucao_Rondas!$F$2:$F$456,"5. Perdas de granulado e energia (extra)",Execucao_Rondas!$C$2:$C$456,202612)/COUNTIFS(Execucao_Rondas!$G$2:$G$456,"<>Não aplicável",Execucao_Rondas!$F$2:$F$456,"5. Perdas de granulado e energia (extra)",Execucao_Rondas!$C$2:$C$456,202612),"") -> 1 | N8: =IFERROR(COUNTIFS(Execucao_Rondas!$G$2:$G$456,"Conforme",Execucao_Rondas!$F$2:$F$456,"5. Perdas de granulado e energia (extra)")/COUNTIFS(Execucao_Rondas!$G$2:$G$456,"<>Não aplicável",Execucao_Rondas!$F$2:$F$456,"5. Perdas de granulado e energia (extra)"),"") -> 0.72115385
A9: TOTAL | B9: =IFERROR(COUNTIFS(Execucao_Rondas!$G$2:$G$456,"Conforme",Execucao_Rondas!$C$2:$C$456,202601)/COUNTIFS(Execucao_Rondas!$G$2:$G$456,"<>Não aplicável",Execucao_Rondas!$C$2:$C$456,202601),"") -> 0.85294118 | C9: =IFERROR(COUNTIFS(Execucao_Rondas!$G$2:$G$456,"Conforme",Execucao_Rondas!$C$2:$C$456,202602)/COUNTIFS(Execucao_Rondas!$G$2:$G$456,"<>Não aplicável",Execucao_Rondas!$C$2:$C$456,202602),"") -> 0.85294118 | D9: =IFERROR(COUNTIFS(Execucao_Rondas!$G$2:$G$456,"Conforme",Execucao_Rondas!$C$2:$C$456,202603)/COUNTIFS(Execucao_Rondas!$G$2:$G$456,"<>Não aplicável",Execucao_Rondas!$C$2:$C$456,202603),"") -> 0.80952381 | E9: =IFERROR(COUNTIFS(Execucao_Rondas!$G$2:$G$456,"Conforme",Execucao_Rondas!$C$2:$C$456,202604)/COUNTIFS(Execucao_Rondas!$G$2:$G$456,"<>Não aplicável",Execucao_Rondas!$C$2:$C$456,202604),"") -> 0.85294118 | F9: =IFERROR(COUNTIFS(Execucao_Rondas!$G$2:$G$456,"Conforme",Execucao_Rondas!$C$2:$C$456,202605)/COUNTIFS(Execucao_Rondas!$G$2:$G$456,"<>Não aplicável",Execucao_Rondas!$C$2:$C$456,202605),"") -> 0.79411765 | G9: =IFERROR(COUNTIFS(Execucao_Rondas!$G$2:$G$456,"Conforme",Execucao_Rondas!$C$2:$C$456,202606)/COUNTIFS(Execucao_Rondas!$G$2:$G$456,"<>Não aplicável",Execucao_Rondas!$C$2:$C$456,202606),"") -> 0.73809524 | H9: =IFERROR(COUNTIFS(Execucao_Rondas!$G$2:$G$456,"Conforme",Execucao_Rondas!$C$2:$C$456,202607)/COUNTIFS(Execucao_Rondas!$G$2:$G$456,"<>Não aplicável",Execucao_Rondas!$C$2:$C$456,202607),"") -> 0.82352941 | I9: =IFERROR(COUNTIFS(Execucao_Rondas!$G$2:$G$456,"Conforme",Execucao_Rondas!$C$2:$C$456,202608)/COUNTIFS(Execucao_Rondas!$G$2:$G$456,"<>Não aplicável",Execucao_Rondas!$C$2:$C$456,202608),"") -> 0.85714286 | J9: =IFERROR(COUNTIFS(Execucao_Rondas!$G$2:$G$456,"Conforme",Execucao_Rondas!$C$2:$C$456,202609)/COUNTIFS(Execucao_Rondas!$G$2:$G$456,"<>Não aplicável",Execucao_Rondas!$C$2:$C$456,202609),"") -> 0.86111111 | K9: =IFERROR(COUNTIFS(Execucao_Rondas!$G$2:$G$456,"Conforme",Execucao_Rondas!$C$2:$C$456,202610)/COUNTIFS(Execucao_Rondas!$G$2:$G$456,"<>Não aplicável",Execucao_Rondas!$C$2:$C$456,202610),"") -> 0.92105263 | L9: =IFERROR(COUNTIFS(Execucao_Rondas!$G$2:$G$456,"Conforme",Execucao_Rondas!$C$2:$C$456,202611)/COUNTIFS(Execucao_Rondas!$G$2:$G$456,"<>Não aplicável",Execucao_Rondas!$C$2:$C$456,202611),"") -> 0.9787234 | M9: =IFERROR(COUNTIFS(Execucao_Rondas!$G$2:$G$456,"Conforme",Execucao_Rondas!$C$2:$C$456,202612)/COUNTIFS(Execucao_Rondas!$G$2:$G$456,"<>Não aplicável",Execucao_Rondas!$C$2:$C$456,202612),"") -> 0.92105263 | N9: =IFERROR(COUNTIFS(Execucao_Rondas!$G$2:$G$456,"Conforme")/COUNTIFS(Execucao_Rondas!$G$2:$G$456,"<>Não aplicável"),"") -> 0.85714286

Sheet Checklist_Ronda_Impressao
A1: PLASTICOM | B1: CHECKLIST DE SUPERVISÃO OPERACIONAL — RONDA AMBIENTAL | G1: Mod. RON-SGA
B2: Plasticom — Unidade 1 (Marinha Grande, Portugal) · NP EN ISO 14001:2026 | G2: Rev. 01 · 31/12/2026
A4: Data: ____/____/______ Turno: ____ Verificador: ______________________ Ronda n.º: RND-26-____
A5: Categoria | B5: Ponto de controlo (O que verificar?) | C5: Critério de aceitação (Quando está OK?) | D5: C | E5: NC | F5: NA | G5: Observação / evidência / ação
A6: =INDEX(Pontos_Controlo!$B$5:$B$15,1) -> 1. Gestão de Produtos Químicos | B6: =INDEX(Pontos_Controlo!$D$5:$D$15,1) -> Recipientes de tinta e solvente no posto de serigrafia. | C6: =INDEX(Pontos_Controlo!$E$5:$E$15,1) -> Todos os recipientes fechados quando não estão em uso imediato; rótulo CLP legível; solvente só em dispensador de segurança.
A7: =INDEX(Pontos_Controlo!$B$5:$B$15,2) -> 1. Gestão de Produtos Químicos | B7: =INDEX(Pontos_Controlo!$D$5:$D$15,2) -> Armazenagem de bidões e embalagens de químicos no armazém. | C7: =INDEX(Pontos_Controlo!$E$5:$E$15,2) -> 100% dos recipientes > 20 L sobre bacia de retenção (capacidade ≥ maior recipiente); incompatíveis separados; FDS acessíveis.
A8: =INDEX(Pontos_Controlo!$B$5:$B$15,3) -> 2. Eficiência e Manutenção | B8: =INDEX(Pontos_Controlo!$D$5:$D$15,3) -> Rede de ar comprimido (ligações rápidas, mangueiras, purgadores). | C8: =INDEX(Pontos_Controlo!$E$5:$E$15,3) -> Sem silvos (fugas audíveis); cada fuga detetada tem etiqueta e ordem de trabalho com prazo ≤ 15 dias.
A9: =INDEX(Pontos_Controlo!$B$5:$B$15,4) -> 2. Eficiência e Manutenção | B9: =INDEX(Pontos_Controlo!$D$5:$D$15,4) -> Máquinas de injeção/sopro: fugas de óleo e água e registos de manutenção. | C9: =INDEX(Pontos_Controlo!$E$5:$E$15,4) -> Piso seco sob as máquinas; tabuleiros de retenção sem óleo acumulado; plano de manutenção preventiva sem atrasos > 7 dias.
A10: =INDEX(Pontos_Controlo!$B$5:$B$15,5) -> 3. Emergência | B10: =INDEX(Pontos_Controlo!$D$5:$D$15,5) -> Válvula de corte da rede pluvial e sarjetas. | C10: =INDEX(Pontos_Controlo!$E$5:$E$15,5) -> Válvula acessível, sinalizada e operacional (manobra de teste); sarjetas sem obstrução; bacias de retenção secas, limpas e sem lixo.
A11: =INDEX(Pontos_Controlo!$B$5:$B$15,6) -> 3. Emergência | B11: =INDEX(Pontos_Controlo!$D$5:$D$15,6) -> Kits antipoluição (KIT-01 a KIT-05). | C11: =INDEX(Pontos_Controlo!$E$5:$E$15,6) -> Selo intacto com n.º registado; conteúdo completo (12 almofadas, 2 barreiras, luvas, óculos, sacos, instrução IT-SGA-01); acessível e sinalizado.
A12: =INDEX(Pontos_Controlo!$B$5:$B$15,7) -> 4. Gestão de Resíduos | B12: =INDEX(Pontos_Controlo!$D$5:$D$15,7) -> Segregação e identificação dos resíduos no parque e nas áreas. | C12: =INDEX(Pontos_Controlo!$E$5:$E$15,7) -> Cada contentor com etiqueta de código LER; sem mistura de fluxos; scrap limpo separado por cor/polímero.
A13: =INDEX(Pontos_Controlo!$B$5:$B$15,8) -> 4. Gestão de Resíduos | B13: =INDEX(Pontos_Controlo!$D$5:$D$15,8) -> Acondicionamento dos resíduos perigosos. | C13: =INDEX(Pontos_Controlo!$E$5:$E$15,8) -> Contentores fechados com tampa, identificados, em bacia e sob cobertura; zona limpa; e-GAR do último envio confirmada.
A14: =INDEX(Pontos_Controlo!$B$5:$B$15,9) -> 5. Perdas de granulado e energia (extra) | B14: =INDEX(Pontos_Controlo!$D$5:$D$15,9) -> Perdas de granulado nos silos, zona de descarga e sarjetas exteriores. | C14: =INDEX(Pontos_Controlo!$E$5:$E$15,9) -> Sem grânulos visíveis no pavimento exterior nem nos filtros das sarjetas; tabuleiros de descarga em uso.
A15: =INDEX(Pontos_Controlo!$B$5:$B$15,10) -> 1. Gestão de Produtos Químicos | B15: =INDEX(Pontos_Controlo!$D$5:$D$15,10) -> Armazenagem de químicos fora do armazém (torre TR-01, oficina, parque de gases, depósito de gasóleo, laboratório, sala de baterias). | C15: =INDEX(Pontos_Controlo!$E$5:$E$15,10) -> Recipientes em bacia com capacidade suficiente; incompatíveis separados (hipoclorito × ácidos; oxigénio × gases inflamáveis); kit acessível; FDS disponíveis; sem fugas.
A16: =INDEX(Pontos_Controlo!$B$5:$B$15,11) -> 5. Perdas de granulado e energia (extra) | B16: =INDEX(Pontos_Controlo!$D$5:$D$15,11) -> Máquinas e iluminação em paragens. | C16: =INDEX(Pontos_Controlo!$E$5:$E$15,11) -> Máquinas paradas > 30 min em standby; iluminação desligada em zonas sem atividade.
A18: Regra: qualquer 'NC' exige ação imediata registada e, se não for corrigível no momento, abertura de RNC (RG-SGA-07).

Sheet Manutencao_Ambiental
A1: MANUTENÇÃO DE EQUIPAMENTOS COM RELEVÂNCIA AMBIENTAL (7.1 · 8.1 · F-gas)
A2: Controlo de fugas do CH-01 semestral (Reg. (UE) 2024/573) · Torre TR-01: limpeza/desinfeção semestral e Legionella trimestral (Lei 52/2018)
A4: ID_OT | B4: Data | C4: ID_Equipamento | D4: Equipamento | E4: Tipo_Intervencao | F4: Descricao | G4: Executante | H4: Empresa_Tecnico | I4: Resultado | J4: Fuga_Detetada | K4: Fluido_Recarregado_kg | L4: Horas | M4: Custo_EUR | N4: ID_Legal | O4: ID_Incidente | P4: tCO2e_Fuga | Q4: Proxima_Intervencao
A5: OT-2025-03 | B5: 45797 | C5: CH-01 | D5: Chiller CH-01 (30 kg R410A) | E5: Controlo de fugas F-gas | F5: Controlo semestral de fugas (≥ 50 tCO2e). | G5: Empresa externa | H5: FrioTec — técnico certificado F-gas (cat. I) | I5: Conforme | J5: Não | K5: 0 | L5: 2 | M5: 180 | N5: LEG-07 | P5: =IF(K5="","",ROUND(K5*2088/1000,2)) -> 0 | Q5: =IF(B5="","",IF(E5="Controlo de fugas F-gas",EDATE(B5,6),IF(E5="Limpeza e desinfeção",EDATE(B5,6),IF(E5="Preventiva",EDATE(B5,3),IF(E5="Inspeção",EDATE(B5,12),""))))) -> 45981
A6: OT-2025-04 | B6: 45818 | C6: TR-01 | D6: Torre de arrefecimento TR-01 | E6: Limpeza e desinfeção | F6: Limpeza e desinfeção semestral; análise de Legionella. | G6: Empresa externa | H6: AquaHigiene Lda. | I6: Conforme | J6: Não | K6: 0 | L6: 6 | M6: 950 | N6: LEG-15 | P6: =IF(K6="","",ROUND(K6*2088/1000,2)) -> 0 | Q6: =IF(B6="","",IF(E6="Controlo de fugas F-gas",EDATE(B6,6),IF(E6="Limpeza e desinfeção",EDATE(B6,6),IF(E6="Preventiva",EDATE(B6,3),IF(E6="Inspeção",EDATE(B6,12),""))))) -> 46001
A7: OT-2025-05 | B7: 45826 | C7: CMP-01 | D7: Compressor CMP-01 | E7: Preventiva | F7: Manutenção 4.000 h do compressor antigo. | G7: Empresa externa | H7: Atlas Service PT | I7: Conforme | J7: Não | K7: 0 | L7: 4 | M7: 1200 | P7: =IF(K7="","",ROUND(K7*2088/1000,2)) -> 0 | Q7: =IF(B7="","",IF(E7="Controlo de fugas F-gas",EDATE(B7,6),IF(E7="Limpeza e desinfeção",EDATE(B7,6),IF(E7="Preventiva",EDATE(B7,3),IF(E7="Inspeção",EDATE(B7,12),""))))) -> 45918
A8: OT-2025-07 | B8: 45840 | C8: EX-FP1 | D8: Exaustão / chaminé FP1 da serigrafia | E8: Preventiva | F8: Substituição de filtros da exaustão da serigrafia. | G8: Interno | I8: Conforme | J8: Não | K8: 0 | L8: 3 | M8: 320 | N8: LEG-12 | P8: =IF(K8="","",ROUND(K8*2088/1000,2)) -> 0 | Q8: =IF(B8="","",IF(E8="Controlo de fugas F-gas",EDATE(B8,6),IF(E8="Limpeza e desinfeção",EDATE(B8,6),IF(E8="Preventiva",EDATE(B8,3),IF(E8="Inspeção",EDATE(B8,12),""))))) -> 45932
A9: OT-2025-09 | B9: 45860 | C9: REDE-AR | D9: Rede de ar comprimido | E9: Inspeção | F9: Deteção de fugas por ultrassons (12 fugas etiquetadas). | G9: Interno | I9: Não conforme | J9: Sim | K9: 0 | L9: 6 | M9: 0 | N9: LEG-08 | P9: =IF(K9="","",ROUND(K9*2088/1000,2)) -> 0 | Q9: =IF(B9="","",IF(E9="Controlo de fugas F-gas",EDATE(B9,6),IF(E9="Limpeza e desinfeção",EDATE(B9,6),IF(E9="Preventiva",EDATE(B9,3),IF(E9="Inspeção",EDATE(B9,12),""))))) -> 46225
A10: OT-2025-11 | B10: 45868 | C10: REDE-AR | D10: Rede de ar comprimido | E10: Corretiva | F10: Reparação de 10 das 12 fugas de ar comprimido. | G10: Interno | I10: Corrigido | J10: Não | K10: 0 | L10: 8 | M10: 260 | N10: LEG-08 | P10: =IF(K10="","",ROUND(K10*2088/1000,2)) -> 0 | Q10: =IF(B10="","",IF(E10="Controlo de fugas F-gas",EDATE(B10,6),IF(E10="Limpeza e desinfeção",EDATE(B10,6),IF(E10="Preventiva",EDATE(B10,3),IF(E10="Inspeção",EDATE(B10,12),"")))))
A11: OT-2025-14 | B11: 45881 | C11: DB-01 | D11: Bomba doseadora de biocida DB-01 | E11: Corretiva | F11: Substituição da bomba doseadora avariada (sobredosagem). | G11: Interno | I11: Corrigido | J11: Não | K11: 0 | L11: 3 | M11: 640 | N11: LEG-03 | O11: INC-2025-06 | P11: =IF(K11="","",ROUND(K11*2088/1000,2)) -> 0 | Q11: =IF(B11="","",IF(E11="Controlo de fugas F-gas",EDATE(B11,6),IF(E11="Limpeza e desinfeção",EDATE(B11,6),IF(E11="Preventiva",EDATE(B11,3),IF(E11="Inspeção",EDATE(B11,12),"")))))
A12: OT-2025-15 | B12: 45908 | C12: BR-01 | D12: Bacia de retenção de águas de combate | E12: Inspeção | F12: Inspeção da bacia de retenção (estanquidade e limpeza). | G12: Interno | I12: Conforme | J12: Não | K12: 0 | L12: 2 | M12: 0 | N12: LEG-11 | P12: =IF(K12="","",ROUND(K12*2088/1000,2)) -> 0 | Q12: =IF(B12="","",IF(E12="Controlo de fugas F-gas",EDATE(B12,6),IF(E12="Limpeza e desinfeção",EDATE(B12,6),IF(E12="Preventiva",EDATE(B12,3),IF(E12="Inspeção",EDATE(B12,12),""))))) -> 46273
