Workbook
Name DataRef: Listas!$A$3
Name lst_Cat6M: Listas!$F$3:$F$9
Name lst_DataReferencia: Listas!$A$3:$A$3
Name lst_Eficacia: Listas!$H$3:$H$5
Name lst_Evolucao: Listas!$G$3:$G$7
Name lst_Fonte: Listas!$B$3:$B$15
Name lst_Funcao: Listas!$I$3:$I$24
Name lst_Hierarquia: Listas!$E$3:$E$7
Name lst_SimNao: Listas!$C$3:$C$4
Name lst_TipoAcao: Listas!$D$3:$D$5

Sheet 00_LEIA-ME
A1: RG-SGA-06 — Plano de Ações de Melhoria — PAM 2026 (Mod.G.10.00)
A2: Sistema de Gestão Ambiental NP EN ISO 14001:2026 · Plasticom — Unidade 1 (Marinha Grande, Portugal) · Registo do SGA (fábrica simulada)
A4: CONTROLO DO DOCUMENTO (7.5 — informação documentada)
A5: Código do registo | B5: RG-SGA-06
A6: Título | B6: Plano de Ações de Melhoria — PAM 2026 (Mod.G.10.00)
A7: Versão / Revisão | B7: 01
A8: Data de emissão | B8: 46387
A9: Elaborado por | B9: Gestor(a) do SGA / EHS
A10: Aprovado por | B10: Diretor Geral
A11: Estado | B11: Em vigor
A12: Retenção | B12: 5 anos após substituição
A13: Localização | B13: Repositório controlado do SGA > Registos_SGA_Plasticom (versão eletrónica é a versão controlada; cópias impressas são não controladas)
A15: FINALIDADE E ÂMBITO
A16: Finalidade | B16: Documento mestre de todas as ações do SGA (objetivos, riscos, aspetos, NC, auditorias, revisão pela gestão, Kaizen). Classifica o tipo de ação (C1 correção, C2 ação corretiva, M melhoria), mantém a análise de causas, o responsável, o prazo, a evolução, o impacto nos riscos e a avaliação da eficácia. Estados, atrasos, payback e alertas são calculados.
A17: Atividades do curso | B17: Atividade 3.5 (ações 01/26 e 02/26); Atividade 6.1 Tarefa 2 (04/26 C1 e 05/26 C2); Atividade 6.2 Tarefa 2 (06/26 M); ações de 5.2 (07/26, 08/26), 5.3 (15/26, 17/26) e 5.4 (10/26, 13/26, 18/26).
A18: Requisitos ISO 14001:2026 | B18: 6.1.5 Planeamento de ações; 6.2.2; 10.1 Melhoria contínua; 10.2 Não conformidade e ação corretiva (ISO 14001:2026)
A20: ESTRUTURA DO FICHEIRO
A21: PAM | B21: Plano de Ações de Melhoria (registo mestre, 1 linha por ação).
A22: Mod.G.10.00_Vista | B22: Plano no formato do modelo do curso (Mod.G.10.00), calculado a partir de tbl_pam, para impressão/fórum.
A23: Painel | B23: Indicadores do PAM (calculados): ações por tipo, estado e fonte; custos, poupanças e cumprimento de prazos.
A24: Listas | B24: Domínios (listas de valores) usados na validação de dados das tabelas.
A25: Dicionario_Dados | B25: Descrição de cada coluna de cada tabela: tipo, origem (entrada/calculado), domínio, obrigatoriedade e chaves.
A27: CONVENÇÕES (prontas para análise de dados e machine learning)
A28: Tabelas | B28: Cada registo é uma Tabela Excel com nome próprio (tbl_*): uma linha = um registo, cabeçalho único, sem células mescladas. Ler com pandas (pd.read_excel(ficheiro, sheet_name=folha, header=<linha do cabeçalho - 1>)) ou Power BI (Obter Dados > Tabela).
A29: Cabeçalho cinzento | B29: Coluna CALCULADA por fórmula — não escrever por cima. As restantes colunas são de entrada.
A30: Validação | B30: Colunas com lista controlada só aceitam valores da folha Listas (evita categorias duplicadas por grafia diferente).
A31: Chaves | B31: IDs estáveis e únicos (PK) e referências a IDs de outros registos (FK) permitem juntar tabelas entre ficheiros — ver SGA-00_Indice_Modelo_Dados.xlsx.
A32: Datas e unidades | B32: Datas em formato data (aaaa-mm-dd); números como números; a unidade está no nome da coluna ou no dicionário. Data de referência do SGA: 2026-12-31 (fecho do ano).
A33: Dados simulados | B33: Fábrica simulada Plasticom. Dados operacionais derivados do dataset do projeto (datasets/silver); dados ambientais e de conformidade são simulação didática — confirmar aplicabilidade legal e números antes de uso real.
A35: LIGAÇÕES A OUTROS REGISTOS
A36: Origens | B36: ID_Origem aponta para OBJ (RG-SGA-05), RO (RG-SGA-02), LEG (RG-SGA-04), NC (RG-SGA-07), MED (RG-SGA-13), CONST (RG-SGA-14), RG (RG-SGA-15) e KZ (RG-SGA-16).
A37: Mod.G.10.00 | B37: A folha Mod.G.10.00_Vista reproduz o formato do curso (evolução 25/50/75/100%) a partir da tabela.

Sheet PAM
A1: PLANO DE AÇÕES DE MELHORIA — PAM n.º 01/2026 (Mod.G.10.00) — PLASTICOM
A2: C1 = Correção · C2 = Ação corretiva · M = Melhoria · Estado, atraso, payback e controlo de qualidade calculados · Data de referência 2026-12-31
A4: ID_Acao | B4: N_Acao_Mod | C4: Data_Abertura | D4: Fonte_Doc_Afetado | E4: ID_Origem | F4: Proveniente_Plano_Anterior | G4: NC_Ocorrencia | H4: Investigacao_Causas | I4: Causa_Raiz | J4: Categoria_Causa_6M | K4: Acao_Descricao | L4: Tipo_Acao | M4: Hierarquia_Controlo | N4: Responsavel | O4: Data_Inicio | P4: Prazo | Q4: Evolucao | R4: Data_Fecho | S4: Estado | T4: Dias_para_Prazo | U4: Impacto_Riscos | V4: ID_RO_Afetado | W4: Custo_Previsto_EUR | X4: Poupanca_Anual_EUR | Y4: Payback_Meses | Z4: Beneficio_Ambiental | AA4: Beneficio_Quantidade | AB4: Beneficio_Unidade | AC4: Criterio_Eficacia | AD4: Data_Avaliacao_Eficacia | AE4: Resultado_Eficacia | AF4: Controlo_Qualidade | AG4: Atividade_Curso
A5: PAM-26-01 | B5: 01/26 | C5: 46188 | D5: Objetivos Ambientais | E5: OBJ-01 | F5: Não | G5: Consumo específico de eletricidade elevado (≈ 110 kWh/1.000 un); o ar comprimido representa ≈ 14% da energia, com fugas audíveis e pressão de rede de 7,5 bar. | H5: 1. Porquê consumo alto no ar comprimido? Compressores em carga mesmo com poucas máquinas a trabalhar. 2. Porquê? Fugas na rede ≈ 25% do caudal (teste de vazio ao fim de semana). 3. Porquê não são reparadas? Só se reparam as fugas audíveis, quando alguém se queixa. 4. Porquê? A manutenção preventiva não inclui a rede de ar e não há indicador que mostre a perda. | I5: Ausência de um programa de gestão de fugas e de indicador do ar comprimido. | J5: Método | K5: Campanha trimestral de deteção de fugas por ultrassom (etiquetar e reparar em ≤ 15 dias), reduzir a pressão de 7,5 para 6,8 bar e instalar variador de velocidade no compressor CMP-02. | L5: M | M5: Engenharia | N5: Gerente de Manutenção | O5: 46204 | P5: 46387 | Q5: 1 | R5: 46371 | S5: =IF(Q5>=1,IF(R5>P5,"Concluída com atraso","Concluída"),IF(P5<DataRef,"Atrasada",IF(Q5=0,"Planeada","Em curso"))) -> Concluída | T5: =IF(Q5>=1,"",P5-DataRef) | U5: Sim | V5: RO-02 | W5: 14000 | X5: 24500 | Y5: =IF(OR(X5="",X5=0),"",W5/X5*12) -> 6.8571429 | Z5: Menos energia no ar comprimido | AA5: 175 | AB5: MWh/ano | AC5: Eficaz se as fugas em teste de vazio forem < 10% do caudal e o KPI-01 ≤ 106 kWh/1.000 un em média no 1.º trimestre de 2027. | AD5: 46492 | AE5: Por avaliar | AF5: =IF(AND(L5="C2",I5=""),"FALTA causa raiz (C2)",IF(AC5="","FALTA critério de eficácia",IF(AND(S5="Concluída",AE5="Por avaliar",AD5<DataRef),"Avaliar eficácia","OK"))) -> OK | AG5: 3.5 (ação 1 — objetivo)
A6: PAM-26-02 | B6: 02/26 | C6: 46132 | D6: Matriz de Riscos e Oportunidades | E6: RO-02 | F6: Não | G6: Risco significativo RO-02 (nível -6): sem submedição de energia e água, o desempenho e a eficácia das ações não são demonstráveis. | H6: 1. Porquê não sabemos o consumo por processo? Só há contador geral. 2. Porquê? O projeto elétrico original não previa submedição. 3. Porquê nunca foi instalada? Nunca foi orçamentada. 4. Porquê? O benefício não era visível sem dados (círculo vicioso). | I6: Falta de infraestrutura de medição por processo (decisão de investimento adiada). | J6: Medição | K6: Instalar 6 analisadores de energia (Injeção, Sopro, Decoração, Compressores, Arrefecimento, Geral) e 3 contadores de água com telemetria, ligados ao Power BI; procedimento de validação mensal (fatura vs soma dos submedidores). | L6: M | M6: Engenharia | N6: Gerente de Manutenção | O6: 46174 | P6: 46387 | Q6: 1 | R6: 46371 | S6: =IF(Q6>=1,IF(R6>P6,"Concluída com atraso","Concluída"),IF(P6<DataRef,"Atrasada",IF(Q6=0,"Planeada","Em curso"))) -> Concluída | T6: =IF(Q6>=1,"",P6-DataRef) | U6: Sim | V6: RO-02 | W6: 24000 | Y6: =IF(OR(X6="",X6=0),"",W6/X6*12) | Z6: Dados por processo para gerir energia e água | AC6: Eficaz se ≥ 90% do consumo tiver submedição e a diferença fatura vs soma dos submedidores for ≤ 3% durante 3 meses. | AD6: 46477 | AE6: Por avaliar | AF6: =IF(AND(L6="C2",I6=""),"FALTA causa raiz (C2)",IF(AC6="","FALTA critério de eficácia",IF(AND(S6="Concluída",AE6="Por avaliar",AD6<DataRef),"Avaliar eficácia","OK"))) -> OK | AG6: 3.5 (ação 2 — risco)
A7: PAM-26-03 | B7: 03/26 | C7: 46275 | D7: Tabela de Legislação | E7: LEG-05 | F7: Não | G7: NC legal: não existe avaliação acústica após a substituição dos compressores (fev/2026); a última (2023) já não representa o funcionamento noturno. | H7: 1. Porquê não há avaliação? Ninguém a pediu após a troca dos compressores. 2. Porquê? A alteração foi tratada só como investimento técnico. 3. Porquê? O pedido de alteração não tem checklist ambiental/legal. 4. Porquê? A gestão de mudanças (6.3) ainda não está implementada. | I7: Controlo de mudanças sem avaliação de requisitos ambientais e legais. | J7: Método | K7: Contratar avaliação acústica (critério de incomodidade, período noturno) a laboratório acreditado. | L7: C1 | M7: Administrativa | N7: Gestor do SGA / EHS (Responsável Ambiental) | O7: 46280 | P7: 46326 | Q7: 1 | R7: 46323 | S7: =IF(Q7>=1,IF(R7>P7,"Concluída com atraso","Concluída"),IF(P7<DataRef,"Atrasada",IF(Q7=0,"Planeada","Em curso"))) -> Concluída | T7: =IF(Q7>=1,"",P7-DataRef) | U7: Sim | V7: RO-12 | W7: 1800 | Y7: =IF(OR(X7="",X7=0),"",W7/X7*12) | Z7: Confirmação da conformidade acústica | AC7: Eficaz se o relatório demonstrar o cumprimento do critério de incomodidade noturno ou, se não cumprir, for aberta ação C2 com atenuação. | AD7: 46366 | AE7: Eficaz | AF7: =IF(AND(L7="C2",I7=""),"FALTA causa raiz (C2)",IF(AC7="","FALTA critério de eficácia",IF(AND(S7="Concluída",AE7="Por avaliar",AD7<DataRef),"Avaliar eficácia","OK"))) -> OK | AG7: —
A8: PAM-26-04 | B8: 04/26 | C8: 46280 | D8: Ronda Ambiental Mensal | E8: NC-SGA-26-03 | F8: Não | G8: Kit antipoluição da zona de injeção/serigrafia com selo quebrado, praticamente vazio e sem registo de utilização. | H8: Ver investigação em PAM-26-05 (5 porquês). | I8: Ausência de regra de reporte e reposição após uso do kit. | J8: Método | K8: Repor imediatamente o kit (absorventes, barreiras, luvas, sacos), selar com selo numerado, inspecionar a zona para vestígios de derrame e encaminhar os absorventes usados como 15 02 02*. | L8: C1 | M8: Administrativa | N8: Responsável de Armazém e Logística | O8: 46280 | P8: 46281 | Q8: 1 | R8: 46281 | S8: =IF(Q8>=1,IF(R8>P8,"Concluída com atraso","Concluída"),IF(P8<DataRef,"Atrasada",IF(Q8=0,"Planeada","Em curso"))) -> Concluída | T8: =IF(Q8>=1,"",P8-DataRef) | U8: Sim | V8: RO-10 | W8: 180 | Y8: =IF(OR(X8="",X8=0),"",W8/X8*12) | Z8: Capacidade de resposta a derrames reposta | AC8: Eficaz se o kit estiver completo e selado na verificação de 22/09/2026. | AD8: 46287 | AE8: Eficaz | AF8: =IF(AND(L8="C2",I8=""),"FALTA causa raiz (C2)",IF(AC8="","FALTA critério de eficácia",IF(AND(S8="Concluída",AE8="Por avaliar",AD8<DataRef),"Avaliar eficácia","OK"))) -> OK | AG8: 6.1 (Tarefa 2 — C1)
A9: PAM-26-05 | B9: 05/26 | C9: 46280 | D9: Ronda Ambiental Mensal | E9: NC-SGA-26-03 | F9: Não | G9: Kit antipoluição com selo quebrado, vazio e sem registo de utilização (derrame não reportado). | H9: 1. Porquê o kit está vazio? Foi usado para conter um derrame e não foi reposto. 2. Porquê não foi reposto? O utilizador não informou o armazém nem o SGA. 3. Porquê não informou? A IT-SGA-01 termina na limpeza: não diz que é preciso registar e pedir reposição. 4. Porquê a IT não prevê? Foi escrita só para a resposta; não há responsável pela reposição nem stock mínimo. 5. Porquê não foi detetado antes? A ronda só verificava a presença do kit (não o selo nem o conteúdo) e a formação de derrames só ensinou a usar o kit. | I9: Falha de procedimento (IT-SGA-01 sem etapa pós-uso, sem stock mínimo nem responsável pela reposição) e de formação (ciclo pós-utilização não ensinado). | J9: Método | K9: 1) Rever IT-SGA-01: passo obrigatório pós-uso (registar incidente, pedir reposição, selar). 2) Stock mínimo de 2 kits no armazém com ponto de encomenda. 3) Selo numerado e verificação semanal do conteúdo na ronda (RON-06). 4) Formação toolbox de 15 min nos 3 turnos, com exercício prático. | L9: C2 | M9: Administrativa | N9: Gestor do SGA / EHS (Responsável Ambiental) | O9: 46282 | P9: 46326 | Q9: 1 | R9: 46324 | S9: =IF(Q9>=1,IF(R9>P9,"Concluída com atraso","Concluída"),IF(P9<DataRef,"Atrasada",IF(Q9=0,"Planeada","Em curso"))) -> Concluída | T9: =IF(Q9>=1,"",P9-DataRef) | U9: Sim | V9: RO-10 | W9: 950 | Y9: =IF(OR(X9="",X9=0),"",W9/X9*12) | Z9: Resposta eficaz a derrames; incidentes rastreados | AC9: Eficaz se, em 3 rondas mensais consecutivas, 100% dos kits estiverem completos e selados e 100% das utilizações tiverem registo de incidente. | AD9: 46371 | AE9: Eficaz | AF9: =IF(AND(L9="C2",I9=""),"FALTA causa raiz (C2)",IF(AC9="","FALTA critério de eficácia",IF(AND(S9="Concluída",AE9="Por avaliar",AD9<DataRef),"Avaliar eficácia","OK"))) -> OK | AG9: 6.1 (Tarefa 2 — C2)
A10: PAM-26-06 | B10: 06/26 | C10: 46283 | D10: Caixa de Sugestões / Kaizen | E10: KZ-01 | F10: Não | G10: Oportunidade de melhoria: na pausa de refeição do turno 3 (80 min, sem equipa de rendição) as máquinas de injeção e sopro ficam aquecidas e em vazio. | H10: Hábito: manter a máquina quente para arrancar mais depressa; não existe modo standby padronizado. | I10: Rotina de pausa não padronizada. | J10: Método | K10: 1) Definir o modo standby por máquina (resistências a 60%, bomba hidráulica desligada, chiller em modo eco). 2) Etiqueta 'Pausa 3.º turno' no painel. 3) Checklist de pausa assinado pelo chefe de turno. 4) Medir a poupança com a submedição (PAM-26-02). | L10: M | M10: Administrativa | N10: Gerente de Produção | O10: 46296 | P10: 46356 | Q10: 1 | R10: 46325 | S10: =IF(Q10>=1,IF(R10>P10,"Concluída com atraso","Concluída"),IF(P10<DataRef,"Atrasada",IF(Q10=0,"Planeada","Em curso"))) -> Concluída | T10: =IF(Q10>=1,"",P10-DataRef) | U10: Não | W10: 300 | X10: 3700 | Y10: =IF(OR(X10="",X10=0),"",W10/X10*12) -> 0.97297297 | Z10: Menos energia em vazio (≈ 2,9 tCO2e/ano) | AA10: 26 | AB10: MWh/ano | AC10: Eficaz se ≥ 90% das pausas do turno 3 tiverem standby registado e a poupança medida for ≥ 1.500 kWh/mês. | AD10: 46376 | AE10: Eficaz | AF10: =IF(AND(L10="C2",I10=""),"FALTA causa raiz (C2)",IF(AC10="","FALTA critério de eficácia",IF(AND(S10="Concluída",AE10="Por avaliar",AD10<DataRef),"Avaliar eficácia","OK"))) -> OK | AG10: 6.2 (Tarefa 2 — M)
A11: PAM-26-07 | B11: 07/26 | C11: 46273 | D11: Monitorização e Medição | E11: MED-06 | F11: Não | G11: Desvio: consumo de solvente de limpeza na serigrafia +15% em jun–ago/2026 face a mar–mai/2026, com produção estável. | H11: Hipóteses em RG-SGA-13 (folha Analise_Desvio_5_2). | I11: Em investigação. | J11: Método | K11: Conter e investigar: pesagem diária do solvente por máquina e turno; fechar e identificar todos os recipientes; observar a limpeza nos 3 turnos; conferir inventário e compras de jun–ago. | L11: C1 | M11: Administrativa | N11: Gestor do SGA / EHS (Responsável Ambiental) | O11: 46273 | P11: 46295 | Q11: 1 | R11: 46301 | S11: =IF(Q11>=1,IF(R11>P11,"Concluída com atraso","Concluída"),IF(P11<DataRef,"Atrasada",IF(Q11=0,"Planeada","Em curso"))) -> Concluída com atraso | T11: =IF(Q11>=1,"",P11-DataRef) | U11: Sim | W11: 0 | Y11: =IF(OR(X11="",X11=0),"",W11/X11*12) | Z11: Travar a subida do consumo e das emissões de COV | AC11: Eficaz se as causas forem confirmadas com dados até 30/09/2026 e o consumo diário voltar a ≤ 0,165 kg/1.000 peças. | AD11: 46366 | AE11: Eficaz | AF11: =IF(AND(L11="C2",I11=""),"FALTA causa raiz (C2)",IF(AC11="","FALTA critério de eficácia",IF(AND(S11="Concluída",AE11="Por avaliar",AD11<DataRef),"Avaliar eficácia","OK"))) -> OK | AG11: 5.2 (Parte 1)
A12: PAM-26-08 | B12: 08/26 | C12: 46288 | D12: Monitorização e Medição | E12: MED-06 | F12: Não | G12: Desvio de +15% no solvente de limpeza (confirmado): limpezas com recipiente aberto e aumento de limpezas após o overhaul da SS-001. | H12: Causas confirmadas na investigação PAM-26-07: (1) recipientes abertos no posto → evaporação; (2) após o overhaul de jul/2026, a nova rasqueta exige mais limpezas; (3) limpeza por hábito em cada mudança de turno. | I12: Método de limpeza não normalizado e recipientes inadequados. | J12: Método | K12: Dispensadores de segurança com tampa (2 por máquina); norma de limpeza (quando limpar e volume máximo); afinação da rasqueta da SS-001; formação dos operadores de serigrafia. | L12: C2 | M12: Engenharia | N12: Gestor do SGA / EHS (Responsável Ambiental) | O12: 46289 | P12: 46341 | Q12: 1 | R12: 46336 | S12: =IF(Q12>=1,IF(R12>P12,"Concluída com atraso","Concluída"),IF(P12<DataRef,"Atrasada",IF(Q12=0,"Planeada","Em curso"))) -> Concluída | T12: =IF(Q12>=1,"",P12-DataRef) | U12: Sim | W12: 1600 | X12: 900 | Y12: =IF(OR(X12="",X12=0),"",W12/X12*12) -> 21.333333 | Z12: Menos COV emitidos e menos resíduos perigosos | AA12: 120 | AB12: kg solvente/ano | AC12: Eficaz se o KPI-06 ≤ 0,160 kg/1.000 peças durante 3 meses consecutivos. | AD12: 46366 | AE12: Eficaz | AF12: =IF(AND(L12="C2",I12=""),"FALTA causa raiz (C2)",IF(AC12="","FALTA critério de eficácia",IF(AND(S12="Concluída",AE12="Por avaliar",AD12<DataRef),"Avaliar eficácia","OK"))) -> OK | AG12: 5.2 (Parte 1)
A13: PAM-26-09 | B13: 09/26 | C13: 46132 | D13: Matriz de Riscos e Oportunidades | E13: RO-01 | F13: Não | G13: Oportunidade significativa RO-01 (nível 9): usar a infraestrutura de dados industriais para gestão ambiental. | H13: — | I13: — | J13: — | K13: Painel ambiental em Power BI com energia, água, resíduos (LER), solventes e KPI por máquina/turno/mês; relatório mensal automático para a gestão. | L13: M | M13: Administrativa | N13: Gestor do SGA / EHS (Responsável Ambiental) | O13: 46143 | P13: 46387 | Q13: 1 | R13: 46374 | S13: =IF(Q13>=1,IF(R13>P13,"Concluída com atraso","Concluída"),IF(P13<DataRef,"Atrasada",IF(Q13=0,"Planeada","Em curso"))) -> Concluída | T13: =IF(Q13>=1,"",P13-DataRef) | U13: Sim | V13: RO-01 | W13: 6000 | Y13: =IF(OR(X13="",X13=0),"",W13/X13*12) | Z13: Decisões baseadas em dados | AC13: Eficaz se ≥ 80% dos KPI ambientais tiverem carregamento automático e o painel for usado na reunião mensal durante 3 meses. | AD13: 46477 | AE13: Por avaliar | AF13: =IF(AND(L13="C2",I13=""),"FALTA causa raiz (C2)",IF(AC13="","FALTA critério de eficácia",IF(AND(S13="Concluída",AE13="Por avaliar",AD13<DataRef),"Avaliar eficácia","OK"))) -> OK | AG13: —
A14: PAM-26-10 | B14: 10/26 | C14: 46275 | D14: Tabela de Legislação | E14: LEG-09 | F14: Não | G14: NC legal PPWR: só 9 de 22 famílias com documentação técnica e declaração UE de conformidade (aplicável desde 12/08/2026). | H14: 1. Porquê só 41%? O trabalho começou em junho/2026. 2. Porquê tão tarde? O PPWR não estava na matriz legal até 2026. 3. Porquê? A vigilância legal não acompanhava regulamentos europeus de produto. | I14: Vigilância legal limitada a legislação nacional ambiental de instalação. | J14: Método | K14: Plano de conformidade PPWR: ensaios de metais pesados por família, dossier técnico e declaração UE para as 13 famílias em falta (prioridade por volume); incluir EUR-Lex na vigilância legal mensal. | L14: C2 | M14: Administrativa | N14: Responsável de R&D | O14: 46280 | P14: 46387 | Q14: 1 | R14: 46378 | S14: =IF(Q14>=1,IF(R14>P14,"Concluída com atraso","Concluída"),IF(P14<DataRef,"Atrasada",IF(Q14=0,"Planeada","Em curso"))) -> Concluída | T14: =IF(Q14>=1,"",P14-DataRef) | U14: Sim | V14: RO-06 | W14: 26000 | Y14: =IF(OR(X14="",X14=0),"",W14/X14*12) | Z14: Conformidade legal do produto | AA14: 13 | AB14: famílias | AC14: Eficaz se 100% das famílias tiverem declaração UE de conformidade em 31/12/2026 e a vigilância legal mensal incluir EUR-Lex. | AD14: 46402 | AE14: Por avaliar | AF14: =IF(AND(L14="C2",I14=""),"FALTA causa raiz (C2)",IF(AC14="","FALTA critério de eficácia",IF(AND(S14="Concluída",AE14="Por avaliar",AD14<DataRef),"Avaliar eficácia","OK"))) -> OK | AG14: 5.4 (decisão D2)
A15: PAM-26-11 | B15: 11/26 | C15: 46204 | D15: Objetivos Ambientais | E15: OBJ-06 | F15: Não | G15: Perdas de granulado para a rede pluvial; 6 de 14 pontos críticos com contenção. | H15: — | I15: — | J15: — | K15: Programa Operation Clean Sweep: filtros nas 9 sarjetas, tabuleiros de descarga de big bags, aspirador industrial, kits de recolha e inspeção semanal do perímetro. | L15: M | M15: Engenharia | N15: Gestor do SGA / EHS (Responsável Ambiental) | O15: 46204 | P15: 46477 | Q15: 0.75 | S15: =IF(Q15>=1,IF(R15>P15,"Concluída com atraso","Concluída"),IF(P15<DataRef,"Atrasada",IF(Q15=0,"Planeada","Em curso"))) -> Em curso | T15: =IF(Q15>=1,"",P15-DataRef) -> 90 | U15: Sim | V15: RO-07 | W15: 14000 | Y15: =IF(OR(X15="",X15=0),"",W15/X15*12) | Z15: Menos microplásticos no meio aquático | AC15: Eficaz se 100% dos pontos críticos tiverem contenção e não houver granulado nas sarjetas em 12 inspeções semanais consecutivas. | AD15: 46568 | AE15: Por avaliar | AF15: =IF(AND(L15="C2",I15=""),"FALTA causa raiz (C2)",IF(AC15="","FALTA critério de eficácia",IF(AND(S15="Concluída",AE15="Por avaliar",AD15<DataRef),"Avaliar eficácia","OK"))) -> OK | AG15: —
A16: PAM-26-12 | B16: 12/26 | C16: 46204 | D16: Objetivos Ambientais | E16: OBJ-02 | F16: Não | G16: Scrap ≈ 31 t/ano e taxa de reintegração de ≈ 37% (scrap misturado por cor e polímero). | H16: — | I16: — | J16: — | K16: Segregar o scrap na fonte com caixas coloridas por polímero/cor, receitas de arranque validadas após mudança de molde e Pareto mensal de scrap por máquina. | L16: M | M16: Administrativa | N16: Gerente de Produção | O16: 46204 | P16: 46568 | Q16: 0.5 | S16: =IF(Q16>=1,IF(R16>P16,"Concluída com atraso","Concluída"),IF(P16<DataRef,"Atrasada",IF(Q16=0,"Planeada","Em curso"))) -> Em curso | T16: =IF(Q16>=1,"",P16-DataRef) -> 181 | U16: Sim | V16: RO-11 | W16: 8500 | X16: 15000 | Y16: =IF(OR(X16="",X16=0),"",W16/X16*12) -> 6.8 | Z16: Menos polímero virgem e menos resíduos | AA16: 4 | AB16: t/ano | AC16: Eficaz se o KPI-03 ≤ 0,423 kg/1.000 un e a reintegração ≥ 45% no 2.º trimestre de 2027. | AD16: 46599 | AE16: Por avaliar | AF16: =IF(AND(L16="C2",I16=""),"FALTA causa raiz (C2)",IF(AC16="","FALTA critério de eficácia",IF(AND(S16="Concluída",AE16="Por avaliar",AD16<DataRef),"Avaliar eficácia","OK"))) -> OK | AG16: —
A17: PAM-26-13 | B17: 13/26 | C17: 46288 | D17: Revisão pela Gestão | E17: RG-26-D01 | F17: Não | G17: Consumo de solvente em subida e AAS de COV (IRA 40); o solvente usado é enviado como resíduo perigoso. | H17: — | I17: — | J17: — | K17: Adquirir e instalar uma unidade de recuperação de solvente (destilador de 60 L) na serigrafia, com reutilização do solvente recuperado. | L17: M | M17: Substituição | N17: Gestor do SGA / EHS (Responsável Ambiental) | O17: 46310 | P17: 46477 | Q17: 0.25 | S17: =IF(Q17>=1,IF(R17>P17,"Concluída com atraso","Concluída"),IF(P17<DataRef,"Atrasada",IF(Q17=0,"Planeada","Em curso"))) -> Em curso | T17: =IF(Q17>=1,"",P17-DataRef) -> 90 | U17: Sim | W17: 12500 | X17: 3100 | Y17: =IF(OR(X17="",X17=0),"",W17/X17*12) -> 48.387097 | Z17: Menos compra de solvente e menos resíduo 08 03 12* | AA17: 450 | AB17: kg/ano | AC17: Eficaz se ≥ 60% do solvente usado for recuperado e o resíduo 08 03 12* baixar ≥ 40% no 2.º trimestre de 2027. | AD17: 46599 | AE17: Por avaliar | AF17: =IF(AND(L17="C2",I17=""),"FALTA causa raiz (C2)",IF(AC17="","FALTA critério de eficácia",IF(AND(S17="Concluída",AE17="Por avaliar",AD17<DataRef),"Avaliar eficácia","OK"))) -> OK | AG17: 5.4 (decisão D1)
A18: PAM-26-14 | B18: 14/26 | C18: 46188 | D18: Objetivos Ambientais | E18: OBJ-05 | F18: Não | G18: Água da torre de arrefecimento ≈ 80% do consumo; purga manual por tempo e não por qualidade da água. | H18: — | I18: — | J18: — | K18: Controlo automático da purga da torre por condutividade e estudo de torre adiabática em circuito fechado. | L18: M | M18: Engenharia | N18: Diretor Industrial | O18: 46327 | P18: 46568 | Q18: 0.25 | S18: =IF(Q18>=1,IF(R18>P18,"Concluída com atraso","Concluída"),IF(P18<DataRef,"Atrasada",IF(Q18=0,"Planeada","Em curso"))) -> Em curso | T18: =IF(Q18>=1,"",P18-DataRef) -> 181 | U18: Sim | V18: RO-04 | W18: 65000 | X18: 3800 | Y18: =IF(OR(X18="",X18=0),"",W18/X18*12) -> 205.26316 | Z18: Menos água de rede | AA18: 900 | AB18: m³/ano | AC18: Eficaz se o KPI-02 normalizado pela temperatura baixar ≥ 10% face ao mesmo período do ano anterior. | AD18: 46691 | AE18: Por avaliar | AF18: =IF(AND(L18="C2",I18=""),"FALTA causa raiz (C2)",IF(AC18="","FALTA critério de eficácia",IF(AND(S18="Concluída",AE18="Por avaliar",AD18<DataRef),"Avaliar eficácia","OK"))) -> OK | AG18: —
A19: PAM-26-15 | B19: 15/26 | C19: 46282 | D19: Auditoria Interna | E19: CONST-03 | F19: Não | G19: NC menor de auditoria: contentor de absorventes contaminados (15 02 02*) sem identificação LER e sem tampa no parque de resíduos. | H19: 1. Porquê sem etiqueta? O contentor foi trocado e o novo não foi etiquetado. 2. Porquê? Não há etiquetas LER padronizadas em stock. 3. Porquê não foi detetado? A ronda de resíduos não verifica identificação e tampas dos perigosos. | I19: Ausência de etiquetas padronizadas e de ponto de verificação na ronda. | J19: Material | K19: Etiquetas LER padronizadas para todos os contentores; contentores de perigosos com tampa; incluir verificação no ponto RON-08. | L19: C2 | M19: Administrativa | N19: Responsável de Armazém e Logística | O19: 46283 | P19: 46310 | Q19: 1 | R19: 46309 | S19: =IF(Q19>=1,IF(R19>P19,"Concluída com atraso","Concluída"),IF(P19<DataRef,"Atrasada",IF(Q19=0,"Planeada","Em curso"))) -> Concluída | T19: =IF(Q19>=1,"",P19-DataRef) | U19: Não | W19: 400 | Y19: =IF(OR(X19="",X19=0),"",W19/X19*12) | Z19: Resíduos perigosos corretamente identificados e fechados | AC19: Eficaz se 100% dos contentores de perigosos estiverem identificados e fechados em 3 rondas consecutivas. | AD19: 46361 | AE19: Eficaz | AF19: =IF(AND(L19="C2",I19=""),"FALTA causa raiz (C2)",IF(AC19="","FALTA critério de eficácia",IF(AND(S19="Concluída",AE19="Por avaliar",AD19<DataRef),"Avaliar eficácia","OK"))) -> OK | AG19: 5.3 (Parte 1)
A20: PAM-26-16 | B20: 16/26 | C20: 46132 | D20: Matriz de Riscos e Oportunidades | E20: RO-05 | F20: Não | G20: Risco significativo RO-05: resina fora de especificação e conteúdo reciclado não verificado (SUP-005 e PCR). | H20: — | I20: — | J20: — | K20: Aplicar a avaliação ambiental de fornecedores (RG-SGA-11) aos 10 fornecedores de resina e exigir certificação EuCertPlast/RecyClass para PCR. | L20: M | M20: Administrativa | N20: Responsável de Compras | O20: 46143 | P20: 46387 | Q20: 1 | R20: 46376 | S20: =IF(Q20>=1,IF(R20>P20,"Concluída com atraso","Concluída"),IF(P20<DataRef,"Atrasada",IF(Q20=0,"Planeada","Em curso"))) -> Concluída | T20: =IF(Q20>=1,"",P20-DataRef) | U20: Sim | V20: RO-05 | W20: 2000 | Y20: =IF(OR(X20="",X20=0),"",W20/X20*12) | Z20: Fornecedores avaliados e conteúdo reciclado comprovado | AA20: 10 | AB20: fornecedores | AC20: Eficaz se ≥ 90% das compras de resina forem a fornecedores classificados A ou B. | AD20: 46477 | AE20: Por avaliar | AF20: =IF(AND(L20="C2",I20=""),"FALTA causa raiz (C2)",IF(AC20="","FALTA critério de eficácia",IF(AND(S20="Concluída",AE20="Por avaliar",AD20<DataRef),"Avaliar eficácia","OK"))) -> OK | AG20: —
A21: PAM-26-17 | B21: 17/26 | C21: 46282 | D21: Auditoria Interna | E21: CONST-05 | F21: Não | G21: NC menor de auditoria (6.3): a substituição dos compressores não passou por avaliação de impactes ambientais e requisitos legais. | H21: Ver PAM-26-03: o pedido de alteração não tem checklist ambiental/legal. | I21: Processo de gestão de mudanças (6.3) inexistente. | J21: Método | K21: Criar o formulário de pedido de alteração com checklist ambiental e legal (aspetos, requisitos, riscos, emergência) e aprovação do SGA antes de qualquer alteração de equipamento, processo ou layout. | L21: C2 | M21: Administrativa | N21: Gestor do SGA / EHS (Responsável Ambiental) | O21: 46285 | P21: 46356 | Q21: 1 | R21: 46351 | S21: =IF(Q21>=1,IF(R21>P21,"Concluída com atraso","Concluída"),IF(P21<DataRef,"Atrasada",IF(Q21=0,"Planeada","Em curso"))) -> Concluída | T21: =IF(Q21>=1,"",P21-DataRef) | U21: Sim | V21: RO-12 | W21: 0 | Y21: =IF(OR(X21="",X21=0),"",W21/X21*12) | Z21: Mudanças planeadas sem novos impactes não avaliados | AC21: Eficaz se 100% das alterações de out/2026–mar/2027 tiverem checklist ambiental aprovado antes da execução. | AD21: 46492 | AE21: Por avaliar | AF21: =IF(AND(L21="C2",I21=""),"FALTA causa raiz (C2)",IF(AC21="","FALTA critério de eficácia",IF(AND(S21="Concluída",AE21="Por avaliar",AD21<DataRef),"Avaliar eficácia","OK"))) -> OK | AG21: 5.3 (Parte 1)
A22: PAM-26-18 | B22: 18/26 | C22: 46288 | D22: Revisão pela Gestão | E22: RG-26-D04 | F22: Não | G22: Oportunidade RO-09: autoconsumo fotovoltaico para reduzir emissões do âmbito 2 e o custo de energia. | H22: — | I22: — | J22: — | K22: Estudo de viabilidade de uma UPAC de ≈ 1 MWp na cobertura, com candidatura a financiamento. | L22: M | M22: Substituição | N22: Diretor Financeiro | O22: 46296 | P22: 46477 | Q22: 0.75 | S22: =IF(Q22>=1,IF(R22>P22,"Concluída com atraso","Concluída"),IF(P22<DataRef,"Atrasada",IF(Q22=0,"Planeada","Em curso"))) -> Em curso | T22: =IF(Q22>=1,"",P22-DataRef) -> 90 | U22: Sim | V22: RO-09 | W22: 4000 | Y22: =IF(OR(X22="",X22=0),"",W22/X22*12) | Z22: Decisão de investimento fundamentada | AA22: 1400 | AB22: MWh/ano (potencial) | AC22: Eficaz se o estudo for apresentado à gestão com decisão registada em ata até 31/03/2027. | AD22: 46507 | AE22: Por avaliar | AF22: =IF(AND(L22="C2",I22=""),"FALTA causa raiz (C2)",IF(AC22="","FALTA critério de eficácia",IF(AND(S22="Concluída",AE22="Por avaliar",AD22<DataRef),"Avaliar eficácia","OK"))) -> OK | AG22: 5.4 (decisão D4)
A23: PAM-26-19 | B23: 19/26 | C23: 46282 | D23: Auditoria Interna | E23: CONST-01 | F23: Não | G23: NC menor de auditoria: 3 bidões de 200 L de óleo hidráulico novo pousados no chão do armazém de químicos, sem bacia de retenção (2 bacias para 5 bidões). | H23: 1. Porquê no chão? As bacias existentes estavam cheias. 2. Porquê? A compra de óleo passou a ser feita em lotes maiores (desconto de quantidade). 3. Porquê não se ajustou a contenção? A decisão de compra não considerou a capacidade de armazenagem com retenção. | I23: Capacidade de retenção não dimensionada para o stock máximo; compras sem critério de armazenagem. | J23: Material | K23: Adquirir 2 bacias de retenção de 4 bidões; definir lotação máxima por bacia sinalizada no local; incluir 'capacidade de retenção' no pedido de compra de químicos. | L23: C2 | M23: Engenharia | N23: Responsável de Armazém e Logística | O23: 46283 | P23: 46310 | Q23: 1 | R23: 46315 | S23: =IF(Q23>=1,IF(R23>P23,"Concluída com atraso","Concluída"),IF(P23<DataRef,"Atrasada",IF(Q23=0,"Planeada","Em curso"))) -> Concluída com atraso | T23: =IF(Q23>=1,"",P23-DataRef) | U23: Sim | V23: RO-10 | W23: 1200 | Y23: =IF(OR(X23="",X23=0),"",W23/X23*12) | Z23: Contenção de derrames no armazém | AC23: Eficaz se 100% dos recipientes > 20 L estiverem em bacia em 3 rondas consecutivas. | AD23: 46361 | AE23: Eficaz | AF23: =IF(AND(L23="C2",I23=""),"FALTA causa raiz (C2)",IF(AC23="","FALTA critério de eficácia",IF(AND(S23="Concluída",AE23="Por avaliar",AD23<DataRef),"Avaliar eficácia","OK"))) -> OK | AG23: 5.3 (Parte 1)
A24: PAM-26-20 | B24: 20/26 | C24: 46282 | D24: Auditoria Interna | E24: CONST-06 | F24: Não | G24: NC menor de auditoria (9.1.1): a balança de plataforma do parque de resíduos (EQP-02) não é verificada desde 03/2024 (periodicidade anual). | H24: 1. Porquê não foi verificada? Não constava do plano de calibração. 2. Porquê? Foi comprada pela logística e não foi registada como equipamento de medição ambiental. | I24: Inventário de equipamentos de monitorização incompleto. | J24: Medição | K24: Verificar a balança com massas-padrão (entidade acreditada); registar todos os equipamentos de medição ambiental no RG-SGA-13 com periodicidade e alerta. | L24: C2 | M24: Administrativa | N24: Gerente da Qualidade | O24: 46283 | P24: 46326 | Q24: 1 | R24: 46318 | S24: =IF(Q24>=1,IF(R24>P24,"Concluída com atraso","Concluída"),IF(P24<DataRef,"Atrasada",IF(Q24=0,"Planeada","Em curso"))) -> Concluída | T24: =IF(Q24>=1,"",P24-DataRef) | U24: Não | W24: 350 | Y24: =IF(OR(X24="",X24=0),"",W24/X24*12) | Z24: Dados de resíduos (MIRR) fiáveis | AC24: Eficaz se 100% dos equipamentos do RG-SGA-13 estiverem dentro do prazo de calibração/verificação em 31/12/2026. | AD24: 46346 | AE24: Eficaz | AF24: =IF(AND(L24="C2",I24=""),"FALTA causa raiz (C2)",IF(AC24="","FALTA critério de eficácia",IF(AND(S24="Concluída",AE24="Por avaliar",AD24<DataRef),"Avaliar eficácia","OK"))) -> OK | AG24: 5.3 (Parte 1)
A25: PAM-26-21 | B25: 21/26 | C25: 46282 | D25: Auditoria Interna | E25: CONST-10 | F25: Não | G25: NC menor de auditoria (8.2): nunca foi realizado simulacro de derrame; no simulacro de incêndio (11/2025) a válvula de corte pluvial demorou 9 min (meta ≤ 5 min). | H25: 1. Porquê só simulacro de incêndio? O plano de simulacros cumpre só o SCIE. 2. Porquê? Os cenários ambientais (derrame, águas de combate) não foram incluídos no plano de emergência. | I25: Plano de simulacros não cobre os cenários ambientais de emergência. | J25: Método | K25: Incluir no plano anual 2 simulacros de derrame (armazém de químicos e serigrafia) e treino trimestral de fecho da válvula de corte pelo turno. | L25: C2 | M25: Administrativa | N25: Gestor do SGA / EHS (Responsável Ambiental) | O25: 46285 | P25: 46371 | Q25: 1 | R25: 46367 | S25: =IF(Q25>=1,IF(R25>P25,"Concluída com atraso","Concluída"),IF(P25<DataRef,"Atrasada",IF(Q25=0,"Planeada","Em curso"))) -> Concluída | T25: =IF(Q25>=1,"",P25-DataRef) | U25: Sim | V25: RO-08 | W25: 800 | Y25: =IF(OR(X25="",X25=0),"",W25/X25*12) | Z25: Resposta a emergências ambientais testada | AC25: Eficaz se o simulacro de derrame tiver contenção em ≤ 10 min e a válvula de corte for fechada em ≤ 5 min. | AD25: 46367 | AE25: Eficaz | AF25: =IF(AND(L25="C2",I25=""),"FALTA causa raiz (C2)",IF(AC25="","FALTA critério de eficácia",IF(AND(S25="Concluída",AE25="Por avaliar",AD25<DataRef),"Avaliar eficácia","OK"))) -> OK | AG25: 5.3 (Parte 1)
A26: PAM-26-22 | B26: 22/26 | C26: 46287 | D26: Objetivos Ambientais | E26: OBJ-07 | F26: Não | G26: Autoavaliação RecyClass: 4 SKUs de PVC e 8 de PETG em classe F (sem fluxo de reciclagem) — não poderão ser colocados no mercado a partir de 2030. | H26: — | I26: — | J26: — | K26: Plano de substituição: PVC → PET (moldes FR-007/019/022) e PETG → PET ou PP, validado com os clientes; parar novos projetos em PVC/PETG. | L26: M | M26: Substituição | N26: Responsável de R&D | O26: 46296 | P26: 46752 | Q26: 0.25 | S26: =IF(Q26>=1,IF(R26>P26,"Concluída com atraso","Concluída"),IF(P26<DataRef,"Atrasada",IF(Q26=0,"Planeada","Em curso"))) -> Em curso | T26: =IF(Q26>=1,"",P26-DataRef) -> 365 | U26: Sim | V26: RO-06 | W26: 42000 | Y26: =IF(OR(X26="",X26=0),"",W26/X26*12) | Z26: SKUs recicláveis (grau ≥ C) | AA26: 12 | AB26: SKUs | AC26: Eficaz se 0 SKUs de PVC/PETG estiverem ativos em 31/12/2027 sem perda de clientes. | AD26: 46843 | AE26: Por avaliar | AF26: =IF(AND(L26="C2",I26=""),"FALTA causa raiz (C2)",IF(AC26="","FALTA critério de eficácia",IF(AND(S26="Concluída",AE26="Por avaliar",AD26<DataRef),"Avaliar eficácia","OK"))) -> OK | AG26: —
A27: PAM-26-23 | B27: 23/26 | C27: 46287 | D27: Objetivos Ambientais | E27: OBJ-07 | F27: Não | G27: 7 SKUs com masterbatch preto de negro de carbono (Matte Black) não são detetados por NIR na triagem → classe F. | H27: — | I27: — | J27: — | K27: Substituir o masterbatch preto por pigmento preto detetável por NIR (SUP-008) e validar com ensaio de triagem num reciclador. | L27: M | M27: Substituição | N27: Responsável de Compras | O27: 46310 | P27: 46477 | Q27: 0.5 | S27: =IF(Q27>=1,IF(R27>P27,"Concluída com atraso","Concluída"),IF(P27<DataRef,"Atrasada",IF(Q27=0,"Planeada","Em curso"))) -> Em curso | T27: =IF(Q27>=1,"",P27-DataRef) -> 90 | U27: Sim | V27: RO-06 | W27: 6000 | Y27: =IF(OR(X27="",X27=0),"",W27/X27*12) | Z27: SKUs pretos recicláveis | AA27: 7 | AB27: SKUs | AC27: Eficaz se os 7 SKUs forem identificados corretamente no ensaio de triagem NIR. | AD27: 46507 | AE27: Por avaliar | AF27: =IF(AND(L27="C2",I27=""),"FALTA causa raiz (C2)",IF(AC27="","FALTA critério de eficácia",IF(AND(S27="Concluída",AE27="Por avaliar",AD27<DataRef),"Avaliar eficácia","OK"))) -> OK | AG27: —
A28: PAM-26-24 | B28: 24/26 | C28: 46287 | D28: Objetivos Ambientais | E28: OBJ-07 | F28: Não | G28: SKUs de PET/rPET com serigrafia ou hot foil direto e rótulos com adesivo não lavável ficam abaixo do grau C; a autoavaliação não está certificada. | H28: — | I28: — | J28: — | K28: Redesenhar a decoração de PET (rótulo PE/PP ou tinta destintável validada), exigir adesivo lavável a 80 °C nas especificações de rótulo dos clientes e pedir certificação RecyClass das 3 famílias de maior volume. | L28: M | M28: Substituição | N28: Responsável de R&D | O28: 46327 | P28: 46934 | Q28: 0.25 | S28: =IF(Q28>=1,IF(R28>P28,"Concluída com atraso","Concluída"),IF(P28<DataRef,"Atrasada",IF(Q28=0,"Planeada","Em curso"))) -> Em curso | T28: =IF(Q28>=1,"",P28-DataRef) -> 547 | U28: Sim | V28: RO-06 | W28: 37000 | Y28: =IF(OR(X28="",X28=0),"",W28/X28*12) | Z28: SKUs de PET em grau A–C e certificação | AA28: 17 | AB28: SKUs | AC28: Eficaz se o KPI-18 ≥ 90% em 31/12/2027 e 3 famílias tiverem certificado RecyClass. | AD28: 46783 | AE28: Por avaliar | AF28: =IF(AND(L28="C2",I28=""),"FALTA causa raiz (C2)",IF(AC28="","FALTA critério de eficácia",IF(AND(S28="Concluída",AE28="Por avaliar",AD28<DataRef),"Avaliar eficácia","OK"))) -> OK | AG28: —
A29: PAM-26-25 | B29: 25/26 | C29: 46287 | D29: Matriz de Riscos e Oportunidades | E29: RO-05 | F29: Não | G29: Certificado de rPET do SUP-004 (CERT-03) expirado em 30/06/2026: o conteúdo reciclado declarado não é comprovável; a meta de 35% (art. 7.º) exige mais PCR certificado. | H29: 1. Porquê expirou? O fornecedor não renovou a auditoria EuCertPlast. 2. Porquê não foi detetado? Não havia controlo de validade dos certificados. | I29: Ausência de controlo de validade dos certificados de reciclado. | J29: Método | K29: Controlo mensal de validade (tbl_certificados_pcr); exigir EN 15343 em todos os lotes de PCR; suspender a alegação ALG-05; plano para subir o PCR de 12% para 35% até 2030 (incl. reciclado químico ISCC PLUS para alimentar). | L29: C2 | M29: Administrativa | N29: Responsável de Compras | O29: 46288 | P29: 46387 | Q29: 1 | R29: 46374 | S29: =IF(Q29>=1,IF(R29>P29,"Concluída com atraso","Concluída"),IF(P29<DataRef,"Atrasada",IF(Q29=0,"Planeada","Em curso"))) -> Concluída | T29: =IF(Q29>=1,"",P29-DataRef) | U29: Sim | V29: RO-05 | W29: 1500 | Y29: =IF(OR(X29="",X29=0),"",W29/X29*12) | Z29: Conteúdo reciclado comprovado | AA29: 3 | AB29: certificados | AC29: Eficaz se 100% dos materiais com PCR tiverem certificado válido durante 6 meses seguidos. | AD29: 46568 | AE29: Por avaliar | AF29: =IF(AND(L29="C2",I29=""),"FALTA causa raiz (C2)",IF(AC29="","FALTA critério de eficácia",IF(AND(S29="Concluída",AE29="Por avaliar",AD29<DataRef),"Avaliar eficácia","OK"))) -> OK | AG29: —
A30: PAM-26-26 | B30: 26/26 | C30: 46287 | D30: Tabela de Legislação | E30: LEG-19 | F30: Não | G30: Requisitos por verificar: uso dos frascos alimentares para bebidas (tampas presas), óleos minerais nas tintas (França) e reutilização de paletes (PPWR art. 29.º). | H30: — | I30: — | J30: — | K30: Obter declaração de utilização de CUST-015/016, declaração MOSH/MOAH das tintas e estudo de pool de paletes com retorno para clientes em Portugal. | L30: M | M30: Administrativa | N30: Responsável de R&D | O30: 46288 | P30: 46356 | Q30: 1 | R30: 46360 | S30: =IF(Q30>=1,IF(R30>P30,"Concluída com atraso","Concluída"),IF(P30<DataRef,"Atrasada",IF(Q30=0,"Planeada","Em curso"))) -> Concluída com atraso | T30: =IF(Q30>=1,"",P30-DataRef) | U30: Sim | V30: RO-06 | W30: 1000 | Y30: =IF(OR(X30="",X30=0),"",W30/X30*12) | Z30: Aplicabilidade confirmada | AA30: 3 | AB30: requisitos | AC30: Eficaz se os 3 requisitos tiverem estado confirmado na matriz (tbl_requisitos_emb) até 30/11/2026. | AD30: 46371 | AE30: Por avaliar | AF30: =IF(AND(L30="C2",I30=""),"FALTA causa raiz (C2)",IF(AC30="","FALTA critério de eficácia",IF(AND(S30="Concluída",AE30="Por avaliar",AD30<DataRef),"Avaliar eficácia","OK"))) -> OK | AG30: —
A31: PAM-26-27 | B31: 27/26 | C31: 46287 | D31: Tabela de Legislação | E31: LEG-18 | F31: Não | G31: Alegações no site e catálogo proibidas pela Diretiva 2024/825 a partir de 27/09/2026 ('eco-friendly', '100% recicláveis', 'neutra em carbono'). | H31: 1. Porquê existem? Foram criadas pelo marketing em 2023. 2. Porquê não foram revistas? PR-SGA-14 só foi emitido em 09/2026. | I31: Comunicações comerciais sem validação ambiental. | J31: Método | K31: Retirar ALG-01, 02 e 08 do site e catálogo; suspender ALG-05; formar a área comercial no PR-SGA-14. | L31: C1 | M31: Eliminação | N31: Diretor Geral (Gestão de Topo) | O31: 46288 | P31: 46292 | Q31: 1 | R31: 46294 | S31: =IF(Q31>=1,IF(R31>P31,"Concluída com atraso","Concluída"),IF(P31<DataRef,"Atrasada",IF(Q31=0,"Planeada","Em curso"))) -> Concluída com atraso | T31: =IF(Q31>=1,"",P31-DataRef) | U31: Sim | V31: RO-06 | W31: 500 | Y31: =IF(OR(X31="",X31=0),"",W31/X31*12) | Z31: Sem alegações enganosas | AA31: 4 | AB31: alegações | AC31: Eficaz se, na verificação de 30/09/2026, não existir nenhuma alegação com estado Retirar/Proibida no site e catálogo. | AD31: 46356 | AE31: Eficaz | AF31: =IF(AND(L31="C2",I31=""),"FALTA causa raiz (C2)",IF(AC31="","FALTA critério de eficácia",IF(AND(S31="Concluída",AE31="Por avaliar",AD31<DataRef),"Avaliar eficácia","OK"))) -> OK | AG31: —
A32: PAM-26-28 | B32: 28/26 | C32: 46289 | D32: Tabela de Legislação | E32: LEG-06 | F32: Não | G32: REACH: polímeros importados do Reino Unido (SUP-004) e de Singapura (SUP-005) sem representante único — a Plasticom é importadora sem registo dos monómeros/aditivos ≥ 1 t/ano; PVC spot sem declaração de ftalatos/chumbo. | H32: 1. Porquê sem RU? Nunca foi pedido na qualificação do fornecedor. 2. Porquê? O critério de compra só pedia FDS e certificado de qualidade; o Brexit mudou o estatuto do SUP-004 sem revisão. | I32: Qualificação de fornecedores sem verificação do papel REACH (importador vs utilizador a jusante). | J32: Método | K32: Obter carta de RU (SUP-004) ou comprar via importador UE; manter suspensas as compras spot do SUP-005 e analisar os SKUs de PVC; incluir 'origem EEE / RU' no critério CRIT-07 de fornecedores (RG-SGA-21 tbl_registo_reach). | L32: C2 | M32: Administrativa | N32: Responsável de Compras | O32: 46289 | P32: 46356 | Q32: 0.75 | S32: =IF(Q32>=1,IF(R32>P32,"Concluída com atraso","Concluída"),IF(P32<DataRef,"Atrasada",IF(Q32=0,"Planeada","Em curso"))) -> Atrasada | T32: =IF(Q32>=1,"",P32-DataRef) -> -31 | U32: Sim | V32: RO-05 | W32: 800 | Y32: =IF(OR(X32="",X32=0),"",W32/X32*12) | Z32: Substâncias registadas na cadeia | AA32: 2 | AB32: fornecedores | AC32: Eficaz se 0 lacunas em tbl_registo_reach (RG-SGA-21) em 31/12/2026. | AD32: 46402 | AE32: Por avaliar | AF32: =IF(AND(L32="C2",I32=""),"FALTA causa raiz (C2)",IF(AC32="","FALTA critério de eficácia",IF(AND(S32="Concluída",AE32="Por avaliar",AD32<DataRef),"Avaliar eficácia","OK"))) -> OK | AG32: —
A33: PAM-26-29 | B33: 29/26 | C33: 46289 | D33: Tabela de Legislação | E33: LEG-06 | F33: Não | G33: Tinta UV do ensaio na SS-002 (ALT-2025-01) contém fotoiniciador 71868-10-5 (Repr. 1B, SVHC) — mistura H360FD; sem lista de trabalhadores expostos (DL 301/2000). | H33: 1. Porquê entrou? O ensaio avaliou COV e energia, não a toxicidade. 2. Porquê? A aprovação de químicos novos não tinha verificação de CMR/SVHC (antes do PR-SGA-16). | I33: Aprovação de produtos químicos sem triagem CMR/SVHC. | J33: Material | K33: Substituir por tinta UV sem fotoiniciadores Repr. 1B; até lá: 3 operadores formados, sem grávidas/lactantes, lista de expostos e vigilância da saúde; triagem CMR/SVHC obrigatória na aprovação (PR-SGA-16). | L33: C2 | M33: Substituição | N33: Responsável de R&D | O33: 46289 | P33: 46387 | Q33: 0.5 | S33: =IF(Q33>=1,IF(R33>P33,"Concluída com atraso","Concluída"),IF(P33<DataRef,"Atrasada",IF(Q33=0,"Planeada","Em curso"))) -> Em curso | T33: =IF(Q33>=1,"",P33-DataRef) -> 0 | U33: Sim | V33: RO-10 | W33: 3000 | Y33: =IF(OR(X33="",X33=0),"",W33/X33*12) | Z33: Eliminação de CMR 1A/1B | AA33: 1 | AB33: produtos | AC33: Eficaz se 0 produtos CMR 1A/1B no inventário (RG-SGA-21) em 31/12/2026. | AD33: 46418 | AE33: Por avaliar | AF33: =IF(AND(L33="C2",I33=""),"FALTA causa raiz (C2)",IF(AC33="","FALTA critério de eficácia",IF(AND(S33="Concluída",AE33="Por avaliar",AD33<DataRef),"Avaliar eficácia","OK"))) -> OK | AG33: —
A34: PAM-26-30 | B34: 30/26 | C34: 46289 | D34: Tabela de Legislação | E34: LEG-06 | F34: Não | G34: Limpa-moldes em aerossol com n-hexano (SVHC desde 02/2026; Repr. 2, STOT RE 2) pulverizado sem captação (prioridade P1); uso industrial fora do cenário de exposição do fornecedor. | H34: — | I34: — | J34: — | K34: Substituir por limpa-moldes sem n-hexano (base de ésteres/álcool) validado em 2 moldes; medir n-hexano até à substituição. | L34: C2 | M34: Substituição | N34: Gerente de Manutenção | O34: 46289 | P34: 46371 | Q34: 1 | R34: 46366 | S34: =IF(Q34>=1,IF(R34>P34,"Concluída com atraso","Concluída"),IF(P34<DataRef,"Atrasada",IF(Q34=0,"Planeada","Em curso"))) -> Concluída | T34: =IF(Q34>=1,"",P34-DataRef) | U34: Sim | V34: RO-10 | W34: 600 | Y34: =IF(OR(X34="",X34=0),"",W34/X34*12) | Z34: SVHC eliminada da manutenção | AA34: 1 | AB34: produtos | AC34: Eficaz se o produto for retirado do inventário e dos armários até 15/12/2026. | AD34: 46402 | AE34: Por avaliar | AF34: =IF(AND(L34="C2",I34=""),"FALTA causa raiz (C2)",IF(AC34="","FALTA critério de eficácia",IF(AND(S34="Concluída",AE34="Por avaliar",AD34<DataRef),"Avaliar eficácia","OK"))) -> OK | AG34: —
A35: PAM-26-31 | B35: 31/26 | C35: 46289 | D35: Tabela de Legislação | E35: LEG-06 | F35: Não | G35: Cenários de exposição do solvente de limpeza (CE-01) e do diluente (CE-02) não cumpridos na SS-001: limpeza manual 2 h/turno sem captação; CE-02 com o prazo de 12 meses (art. 39.º) ultrapassado. | H35: 1. Porquê? A SS-001 é a máquina antiga sem mesa aspirante. 2. Porquê não se tratou? Os CE recebidos com as FDS nunca eram comparados com o uso real. | I35: Ausência de verificação dos cenários de exposição. | J35: Método | K35: Instalar mesa aspirante na SS-001; luvas de butilo; verificar cada CE recebido em tbl_ce_reach (RG-SGA-21) no prazo de 12 meses. | L35: C2 | M35: Engenharia | N35: Gerente de Produção | O35: 46289 | P35: 46387 | Q35: 1 | R35: 46373 | S35: =IF(Q35>=1,IF(R35>P35,"Concluída com atraso","Concluída"),IF(P35<DataRef,"Atrasada",IF(Q35=0,"Planeada","Em curso"))) -> Concluída | T35: =IF(Q35>=1,"",P35-DataRef) | U35: Sim | V35: RO-10 | W35: 9500 | Y35: =IF(OR(X35="",X35=0),"",W35/X35*12) | Z35: Exposição a COV reduzida | AC35: Eficaz se a medição de 11/2026 na SS-001 der índice de exposição < 0,1 (teste preliminar NP EN 689). | AD35: 46418 | AE35: Por avaliar | AF35: =IF(AND(L35="C2",I35=""),"FALTA causa raiz (C2)",IF(AC35="","FALTA critério de eficácia",IF(AND(S35="Concluída",AE35="Por avaliar",AD35<DataRef),"Avaliar eficácia","OK"))) -> OK | AG35: —
A36: PAM-26-32 | B36: 32/26 | C36: 46289 | D36: Tabela de Legislação | E36: LEG-06 | F36: Não | G36: Formação obrigatória em falta: 2 operadores de serigrafia sem formação em diisocianatos (anexo XVII, entrada 74) e técnicos de utilidades com formação em biocidas vencida. | H36: 1. Porquê? Os novos operadores começaram antes da formação. 2. Porquê? O acolhimento não bloqueia tarefas que exigem formação legal prévia. | I36: Acolhimento sem verificação de formações obrigatórias por tarefa. | J36: Mão de obra | K36: Formar os 2 operadores antes de usarem a tinta 2K; renovar a formação em biocidas (FOR-12); tornar FOR-13 obrigatória no acolhimento da serigrafia (RG-SGA-08). | L36: C2 | M36: Administrativa | N36: Responsável de Recursos Humanos | O36: 46289 | P36: 46326 | Q36: 1 | R36: 46322 | S36: =IF(Q36>=1,IF(R36>P36,"Concluída com atraso","Concluída"),IF(P36<DataRef,"Atrasada",IF(Q36=0,"Planeada","Em curso"))) -> Concluída | T36: =IF(Q36>=1,"",P36-DataRef) | U36: Não | W36: 900 | Y36: =IF(OR(X36="",X36=0),"",W36/X36*12) | Z36: Trabalhadores formados | AA36: 5 | AB36: trabalhadores | AC36: Eficaz se 0 registos pendentes ou fora de validade de FOR-12 e FOR-13 no RG-SGA-08 em 30/11/2026. | AD36: 46371 | AE36: Eficaz | AF36: =IF(AND(L36="C2",I36=""),"FALTA causa raiz (C2)",IF(AC36="","FALTA critério de eficácia",IF(AND(S36="Concluída",AE36="Por avaliar",AD36<DataRef),"Avaliar eficácia","OK"))) -> OK | AG36: —
A37: PAM-26-33 | B37: 33/26 | C37: 46289 | D37: Tabela de Legislação | E37: LEG-06 | F37: Não | G37: Armazenagem e EPI de químicos: hipoclorito (EUH031) na mesma bacia do anti-incrustante ácido (ARM-04); sala de baterias sem viseira facial (CE-08, prazo do art. 39.º ultrapassado); 6 locais de químicos fora do armazém sem ponto de ronda. | H37: 1. Porquê? Os produtos da torre foram entregues juntos pelo fornecedor. 2. Porquê não se detetou? A ronda só cobria o armazém principal e a serigrafia. | I37: Ronda ambiental sem cobertura dos locais de químicos fora do armazém. | J37: Método | K37: Bacias separadas e sinalização da incompatibilidade na torre; viseira facial na sala de carga; novo ponto de ronda RON-11 (RG-SGA-10) para torre, oficina, gases, gasóleo, laboratório e baterias. | L37: C2 | M37: Engenharia | N37: Gerente de Manutenção | O37: 46289 | P37: 46326 | Q37: 1 | R37: 46325 | S37: =IF(Q37>=1,IF(R37>P37,"Concluída com atraso","Concluída"),IF(P37<DataRef,"Atrasada",IF(Q37=0,"Planeada","Em curso"))) -> Concluída | T37: =IF(Q37>=1,"",P37-DataRef) | U37: Sim | V37: RO-10 | W37: 900 | Y37: =IF(OR(X37="",X37=0),"",W37/X37*12) | Z37: Contenção e segregação de químicos | AA37: 6 | AB37: locais | AC37: Eficaz se as 2 primeiras rondas RON-11 (out. e nov./2026) forem conformes. | AD37: 46371 | AE37: Por avaliar | AF37: =IF(AND(L37="C2",I37=""),"FALTA causa raiz (C2)",IF(AC37="","FALTA critério de eficácia",IF(AND(S37="Concluída",AE37="Por avaliar",AD37<DataRef),"Avaliar eficácia","OK"))) -> Avaliar eficácia | AG37: —
A38: PAM-26-34 | B38: 34/26 | C38: 46289 | D38: Tabela de Legislação | E38: LEG-06 | F38: Não | G38: Informação de fornecedores incompleta: 6 FDS a corrigir ou atualizar (2 de 2021), 7 declarações SVHC desatualizadas ou em falta (lista de 253 entradas), D4/D5/D6 do desmoldante por confirmar e verificação da lista candidata de junho/2026 em atraso (OBR-19). | H38: 1. Porquê? Os pedidos aos fornecedores não tinham prazo nem seguimento. 2. Porquê? Não havia registo da versão da lista coberta por cada declaração. | I38: Gestão da informação de fornecedores sem controlo de versão. | J38: Método | K38: Pedidos formais com prazo de 30 dias; declaração com n.º de entradas da lista coberta (RG-SGA-21 tbl_declaracoes); compras bloqueadas para produtos sem FDS válida; verificação semestral da lista (OBR-19). | L38: C2 | M38: Administrativa | N38: Responsável de Compras | O38: 46289 | P38: 46356 | Q38: 1 | R38: 46353 | S38: =IF(Q38>=1,IF(R38>P38,"Concluída com atraso","Concluída"),IF(P38<DataRef,"Atrasada",IF(Q38=0,"Planeada","Em curso"))) -> Concluída | T38: =IF(Q38>=1,"",P38-DataRef) | U38: Não | W38: 0 | Y38: =IF(OR(X38="",X38=0),"",W38/X38*12) | Z38: Informação REACH completa | AA38: 13 | AB38: documentos | AC38: Eficaz se 0 FDS 'Pedir correção' e 0 declarações 'Desatualizada/Em falta' em 31/12/2026. | AD38: 46402 | AE38: Por avaliar | AF38: =IF(AND(L38="C2",I38=""),"FALTA causa raiz (C2)",IF(AC38="","FALTA critério de eficácia",IF(AND(S38="Concluída",AE38="Por avaliar",AD38<DataRef),"Avaliar eficácia","OK"))) -> OK | AG38: —
A39: PAM-26-35 | B39: 35/26 | C39: 46289 | D39: Tabela de Legislação | E39: LEG-22 | F39: Não | G39: Avaliação de riscos químicos incompleta: 5 produtos perigosos sem avaliação (retardador, removedor de emulsão, trava-roscas, cianoacrilato, anti-incrustante); acetaldeído da purga das ISBM e n-hexano sem medição. | H39: — | I39: — | J39: — | K39: Completar as avaliações (RG-SGA-21 tbl_risco_quimico) e medir acetaldeído e n-hexano com laboratório acreditado (NP EN 689). | L39: C2 | M39: Administrativa | N39: Gestor do SGA / EHS (Responsável Ambiental) | O39: 46289 | P39: 46356 | Q39: 0.75 | S39: =IF(Q39>=1,IF(R39>P39,"Concluída com atraso","Concluída"),IF(P39<DataRef,"Atrasada",IF(Q39=0,"Planeada","Em curso"))) -> Atrasada | T39: =IF(Q39>=1,"",P39-DataRef) -> -31 | U39: Sim | V39: RO-10 | W39: 2500 | Y39: =IF(OR(X39="",X39=0),"",W39/X39*12) | Z39: Riscos químicos avaliados | AA39: 7 | AB39: avaliações/medições | AC39: Eficaz se todos os produtos perigosos tiverem avaliação e as 2 medições tiverem conclusão em 31/12/2026. | AD39: 46402 | AE39: Por avaliar | AF39: =IF(AND(L39="C2",I39=""),"FALTA causa raiz (C2)",IF(AC39="","FALTA critério de eficácia",IF(AND(S39="Concluída",AE39="Por avaliar",AD39<DataRef),"Avaliar eficácia","OK"))) -> OK | AG39: —
A40: PAM-26-36 | B40: 36/26 | C40: 46371 | D40: Matriz de Riscos e Oportunidades | E40: LEG-03 | F40: Não | G40: Risco R32 (RG-SGA-02): título de utilização de recursos hídricos e condições de descarga do efluente ainda não disponibilizados; aplicabilidade a confirmar. | H40: — | I40: — | J40: — | K40: Verificação documental do título de recursos hídricos e das condições de descarga; parecer técnico quando aplicável (antes PAC 202629 no RG-SGA-02). | L40: C2 | M40: Administrativa | N40: Gestor do SGA / EHS (Responsável Ambiental) | O40: 46371 | P40: 46444 | Q40: 0.25 | S40: =IF(Q40>=1,IF(R40>P40,"Concluída com atraso","Concluída"),IF(P40<DataRef,"Atrasada",IF(Q40=0,"Planeada","Em curso"))) -> Em curso | T40: =IF(Q40>=1,"",P40-DataRef) -> 57 | U40: Sim | W40: 1500 | Y40: =IF(OR(X40="",X40=0),"",W40/X40*12) | Z40: Conformidade legal em água | AC40: Eficaz se o título e as condições de descarga estiverem confirmados e arquivados e não houver NC legal em água. | AD40: 46477 | AE40: Por avaliar | AF40: =IF(AND(L40="C2",I40=""),"FALTA causa raiz (C2)",IF(AC40="","FALTA critério de eficácia",IF(AND(S40="Concluída",AE40="Por avaliar",AD40<DataRef),"Avaliar eficácia","OK"))) -> OK | AG40: —
A41: PAM-26-37 | B41: 37/26 | C41: 46371 | D41: Matriz de Riscos e Oportunidades | E41: LEG-01 | F41: Não | G41: Risco R31 (RG-SGA-02): obrigações do RGGR (MIRR/SILiAmb, e-GAR) dependentes de rotina manual; scrap elevado. | H41: — | I41: — | J41: — | K41: Checklist das obrigações de resíduos do calendário RG-SGA-04 (OBR-01, OBR-02) e auditoria trimestral de evidências (antes PAC 202628 no RG-SGA-02). | L41: M | M41: Administrativa | N41: Técnico de Qualidade/Ambiente | O41: 46371 | P41: 46444 | Q41: 0.25 | S41: =IF(Q41>=1,IF(R41>P41,"Concluída com atraso","Concluída"),IF(P41<DataRef,"Atrasada",IF(Q41=0,"Planeada","Em curso"))) -> Em curso | T41: =IF(Q41>=1,"",P41-DataRef) -> 57 | U41: Sim | W41: 0 | Y41: =IF(OR(X41="",X41=0),"",W41/X41*12) | Z41: Obrigações de resíduos cumpridas | AC41: Eficaz se 100% das obrigações de resíduos forem cumpridas no prazo em 2 trimestres seguidos. | AD41: 46568 | AE41: Por avaliar | AF41: =IF(AND(L41="C2",I41=""),"FALTA causa raiz (C2)",IF(AC41="","FALTA critério de eficácia",IF(AND(S41="Concluída",AE41="Por avaliar",AD41<DataRef),"Avaliar eficácia","OK"))) -> OK | AG41: —

Sheet Mod.G.10.00_Vista
A1: PLASTICOM | F1: PLANO DE AÇÕES DE MELHORIA | O1: PM n.º 01/2026
F2: Plasticom — Unidade 1 (Marinha Grande, Portugal) · NP EN ISO 14001:2026 | O2: Rev. 01 · 31/12/2026
I4: Evolução (%)
A5: Nº Ação | B5: Fonte / Doc. Afecto | C5: Proveniente Plano Anterior? | D5: Não conformidade / Ocorrência | E5: Investigação Causas | F5: Ações (Descrição) C1|C2|M | G5: Resp. | H5: Prazo | I5: 25 | J5: 50 | K5: 75 | L5: 100 | M5: Prazo / Data Fecho | N5: Impacto Riscos? | O5: Avaliação da Eficácia
A6: =INDEX(PAM!$B$5:$B$41,1) -> 01/26 | B6: =INDEX(PAM!$D$5:$D$41,1)&" ("&INDEX(PAM!$E$5:$E$41,1)&")" -> Objetivos Ambientais (OBJ-01) | C6: =INDEX(PAM!$F$5:$F$41,1) -> Não | D6: =INDEX(PAM!$G$5:$G$41,1) -> Consumo específico de eletricidade elevado (≈ 110 kWh/1.000 un); o ar comprimido representa ≈ 14% da energia, com fugas audíveis e pressão de rede de 7,5 bar. | E6: =INDEX(PAM!$H$5:$H$41,1)&IF(INDEX(PAM!$I$5:$I$41,1)="—",""," CAUSA RAIZ: "&INDEX(PAM!$I$5:$I$41,1)) -> 1. Porquê consumo alto no ar comprimido? Compressores em carga mesmo com poucas máquinas a trabalhar. 2. Porquê? Fugas na rede ≈ 25% do caudal (teste de vazio ao fim de semana). 3. Porquê não são reparadas? Só se reparam as fugas audíveis, quando alguém se queixa. 4. Porquê? A manutenção preventiva não inclui a rede de ar e não há indicador que mostre a perda. CAUSA RAIZ: Ausência de um programa de gestão de fugas e de indicador do ar comprimido. | F6: ="("&INDEX(PAM!$L$5:$L$41,1)&") "&INDEX(PAM!$K$5:$K$41,1) -> (M) Campanha trimestral de deteção de fugas por ultrassom (etiquetar e reparar em ≤ 15 dias), reduzir a pressão de 7,5 para 6,8 bar e instalar variador de velocidade no compressor CMP-02. | G6: =INDEX(PAM!$N$5:$N$41,1) -> Gerente de Manutenção | H6: =INDEX(PAM!$P$5:$P$41,1) -> 46387 | I6: =IF(INDEX(PAM!$Q$5:$Q$41,1)>=0.25,"X","") -> X | J6: =IF(INDEX(PAM!$Q$5:$Q$41,1)>=0.5,"X","") -> X | K6: =IF(INDEX(PAM!$Q$5:$Q$41,1)>=0.75,"X","") -> X | L6: =IF(INDEX(PAM!$Q$5:$Q$41,1)>=1,"X","") -> X | M6: =IF(INDEX(PAM!$R$5:$R$41,1)="","—",INDEX(PAM!$R$5:$R$41,1)) -> 46371 | N6: =INDEX(PAM!$U$5:$U$41,1) -> Sim | O6: ="A avaliar em: "&TEXT(MONTH(INDEX(PAM!$AD$5:$AD$41,1)),"00")&"/"&YEAR(INDEX(PAM!$AD$5:$AD$41,1))&" — "&INDEX(PAM!$AC$5:$AC$41,1)&" ["&INDEX(PAM!$AE$5:$AE$41,1)&"]" -> A avaliar em: 04/2027 — Eficaz se as fugas em teste de vazio forem < 10% do caudal e o KPI-01 ≤ 106 kWh/1.000 un em média no 1.º trimestre de 2027. [Por avaliar]
A7: =INDEX(PAM!$B$5:$B$41,2) -> 02/26 | B7: =INDEX(PAM!$D$5:$D$41,2)&" ("&INDEX(PAM!$E$5:$E$41,2)&")" -> Matriz de Riscos e Oportunidades (RO-02) | C7: =INDEX(PAM!$F$5:$F$41,2) -> Não | D7: =INDEX(PAM!$G$5:$G$41,2) -> Risco significativo RO-02 (nível -6): sem submedição de energia e água, o desempenho e a eficácia das ações não são demonstráveis. | E7: =INDEX(PAM!$H$5:$H$41,2)&IF(INDEX(PAM!$I$5:$I$41,2)="—",""," CAUSA RAIZ: "&INDEX(PAM!$I$5:$I$41,2)) -> 1. Porquê não sabemos o consumo por processo? Só há contador geral. 2. Porquê? O projeto elétrico original não previa submedição. 3. Porquê nunca foi instalada? Nunca foi orçamentada. 4. Porquê? O benefício não era visível sem dados (círculo vicioso). CAUSA RAIZ: Falta de infraestrutura de medição por processo (decisão de investimento adiada). | F7: ="("&INDEX(PAM!$L$5:$L$41,2)&") "&INDEX(PAM!$K$5:$K$41,2) -> (M) Instalar 6 analisadores de energia (Injeção, Sopro, Decoração, Compressores, Arrefecimento, Geral) e 3 contadores de água com telemetria, ligados ao Power BI; procedimento de validação mensal (fatura vs soma dos submedidores). | G7: =INDEX(PAM!$N$5:$N$41,2) -> Gerente de Manutenção | H7: =INDEX(PAM!$P$5:$P$41,2) -> 46387 | I7: =IF(INDEX(PAM!$Q$5:$Q$41,2)>=0.25,"X","") -> X | J7: =IF(INDEX(PAM!$Q$5:$Q$41,2)>=0.5,"X","") -> X | K7: =IF(INDEX(PAM!$Q$5:$Q$41,2)>=0.75,"X","") -> X | L7: =IF(INDEX(PAM!$Q$5:$Q$41,2)>=1,"X","") -> X | M7: =IF(INDEX(PAM!$R$5:$R$41,2)="","—",INDEX(PAM!$R$5:$R$41,2)) -> 46371 | N7: =INDEX(PAM!$U$5:$U$41,2) -> Sim | O7: ="A avaliar em: "&TEXT(MONTH(INDEX(PAM!$AD$5:$AD$41,2)),"00")&"/"&YEAR(INDEX(PAM!$AD$5:$AD$41,2))&" — "&INDEX(PAM!$AC$5:$AC$41,2)&" ["&INDEX(PAM!$AE$5:$AE$41,2)&"]" -> A avaliar em: 03/2027 — Eficaz se ≥ 90% do consumo tiver submedição e a diferença fatura vs soma dos submedidores for ≤ 3% durante 3 meses. [Por avaliar]
