Workbook
Name DataRef: Listas!$A$3
Name lst_Adesivo: Listas!$G$3:$G$6
Name lst_Aplicabilidade: Listas!$L$3:$L$6
Name lst_Barreira: Listas!$D$3:$D$6
Name lst_Classe: Listas!$J$3:$J$8
Name lst_CorCorpo: Listas!$C$3:$C$8
Name lst_DataReferencia: Listas!$A$3:$A$3
Name lst_Decoracao: Listas!$H$3:$H$6
Name lst_EstadoAlegacao: Listas!$Q$3:$Q$7
Name lst_EstadoAval: Listas!$T$3:$T$5
Name lst_EstadoReq: Listas!$M$3:$M$8
Name lst_Funcao: Listas!$S$3:$S$24
Name lst_Material: Listas!$B$3:$B$16
Name lst_Maturidade: Listas!$R$3:$R$5
Name lst_Natureza: Listas!$K$3:$K$7
Name lst_Risco: Listas!$N$3:$N$5
Name lst_Rotulo: Listas!$F$3:$F$8
Name lst_Segmento: Listas!$I$3:$I$5
Name lst_SimNao: Listas!$P$3:$P$4
Name lst_Vedante: Listas!$E$3:$E$5
Name lst_Verificacao: Listas!$O$3:$O$6
Name SegmentaçãoDeDados_Conforme_PPWR_2030: #N/A
Name SegmentaçãoDeDados_Cor_Corpo: #N/A
Name SegmentaçãoDeDados_Decoracao_Tipo: #N/A
Name SegmentaçãoDeDados_Estrutura_Material: #N/A
Name SegmentaçãoDeDados_Grau_PPWR_Indicativo: #N/A
Name SegmentaçãoDeDados_Segmento: #N/A

Sheet 00_LEIA-ME
A1: RG-SGA-20 — Reciclabilidade e Conformidade de Embalagens (RecyClass / PPWR)
A2: Sistema de Gestão Ambiental NP EN ISO 14001:2026 · Plasticom — Unidade 1 (Marinha Grande, Portugal) · Registo do SGA (fábrica simulada)
A4: CONTROLO DO DOCUMENTO (7.5 — informação documentada)
A5: Código do registo | B5: RG-SGA-20
A6: Título | B6: Reciclabilidade e Conformidade de Embalagens (RecyClass / PPWR)
A7: Versão / Revisão | B7: 00
A8: Data de emissão | B8: 46289
A9: Elaborado por | B9: Gestor(a) do SGA / EHS
A10: Aprovado por | B10: Diretor Geral
A11: Estado | B11: Em vigor
A12: Retenção | B12: 5 anos após substituição
A13: Localização | B13: Repositório controlado do SGA > Registos_SGA_Plasticom (versão eletrónica é a versão controlada; cópias impressas são não controladas)
A15: FINALIDADE E ÂMBITO
A16: Finalidade | B16: Registo de conformidade de produto das embalagens da Plasticom. A folha Avaliacao_RecyClass tem uma linha por SKU com todos os campos a introduzir na ferramenta online da RecyClass e calcula a classe (A–F), a taxa de reciclabilidade em massa e o grau PPWR indicativo com as regras de tbl_regras_dfr. Liga cada SKU aos requisitos legais aplicáveis (tbl_aplicabilidade), às famílias com declaração UE (tbl_familias_ppwr), aos certificados de reciclado e às vendas por país. A classificação é uma AUTOAVALIAÇÃO com regras simplificadas: o resultado oficial só vem da ferramenta RecyClass / certificação e dos atos delegados do PPWR (critérios de DfR previstos até 2028).
A17: Atividades do curso | B17: Complemento — reciclagem e reciclabilidade de embalagens: classificação RecyClass por SKU, graus PPWR, conteúdo reciclado, matriz legal e normativa de produto, países de destino e alegações.
A18: Requisitos ISO 14001:2026 | B18: 4.3 e) e 6.1.2 (perspetiva de ciclo de vida); 6.1.3 e 9.1.2 (obrigações de conformidade de produto); 8.1 (conceção e requisitos para fornecedores); 7.4 (alegações)
A20: ESTRUTURA DO FICHEIRO
A21: Parametros | B21: Parâmetros dos cálculos (limiares PPWR, massas de rótulo e decoração, logística, imposto espanhol, prestações RAP indicativas).
A22: Metas_Art7 | B22: Metas de conteúdo reciclado do PPWR por categoria (média por instalação de fabrico e por ano).
A23: Materiais | B23: Dimensão material: polímero, fluxo de reciclagem, densidade, teor de reciclado e marcação.
A24: Regras_DfR | B24: Regras de design para reciclagem (interpretação simplificada das diretrizes RecyClass para PE/PP rígidos e garrafas de PET).
A25: Tampas | B25: Componentes de fecho (tampas) com material, massa e comportamento na reciclagem.
A26: Avaliacao_RecyClass | B26: Uma linha por SKU: campos da ferramenta RecyClass, classe A–F, taxa de reciclabilidade, grau PPWR, reciclado e mercado.
A27: Compat_Tampas | B27: Compatibilidade de cada tampa com cada fluxo de corpo (guia comercial de combinação frasco + tampa).
A28: Familias_PPWR | B28: Famílias de embalagem para a documentação técnica e declaração UE de conformidade (base do KPI-12).
A29: Requisitos_Embalagem | B29: Matriz legal e normativa integrada de embalagens (UE, contacto alimentar, cosméticos, farmacêutico, ISO/EN, Portugal) com natureza da obrigação, papel da Plasticom, evidência e verificação da resposta do ChatGPT.
A30: Aplicabilidade_Produto | B30: Fact_Aplicabilidade: produto × requisito com aplicabilidade, motivo, estado calculado e evidência.
A31: Vendas_Pais | B31: Plástico colocado no mercado por SKU e país (base para RAP, imposto espanhol e metas do art. 7.º).
A32: Embalagens_Expedicao | B32: Embalagens de expedição colocadas no mercado por mês, país e material — base da declaração RAP (DL 152-D/2017).
... A40: Dicionario_Dados | B40: Descrição de cada coluna de cada tabela: tipo, origem (entrada/calculado), domínio, obrigatoriedade e chaves.
A42: CONVENÇÕES (prontas para análise de dados e machine learning)
A43: Tabelas | B43: Cada registo é uma Tabela Excel com nome próprio (tbl_*): uma linha = um registo, cabeçalho único, sem células mescladas. Ler com pandas (pd.read_excel(ficheiro, sheet_name=folha, header=<linha do cabeçalho - 1>)) ou Power BI (Obter Dados > Tabela).
A44: Cabeçalho cinzento | B44: Coluna CALCULADA por fórmula — não escrever por cima. As restantes colunas são de entrada.
A45: Validação | B45: Colunas com lista controlada só aceitam valores da folha Listas (evita categorias duplicadas por grafia diferente).
A46: Chaves | B46: IDs estáveis e únicos (PK) e referências a IDs de outros registos (FK) permitem juntar tabelas entre ficheiros — ver SGA-00_Indice_Modelo_Dados.xlsx.
A47: Datas e unidades | B47: Datas em formato data (aaaa-mm-dd); números como números; a unidade está no nome da coluna ou no dicionário. Data de referência do SGA: 2026-12-31 (fecho do ano).
A48: Dados simulados | B48: Fábrica simulada Plasticom. Dados operacionais derivados do dataset do projeto (datasets/silver); dados ambientais e de conformidade são simulação didática — confirmar aplicabilidade legal e números antes de uso real.
A50: LIGAÇÕES A OUTROS REGISTOS
A51: RG-SGA-04 Legal | B51: ID_Legal liga os requisitos a tbl_legal (LEG-09, LEG-16 a LEG-21).
A52: RG-SGA-05 KPI | B52: KPI-12 e KPI-17 a KPI-21 são calculados a partir deste registo.
...

Sheet Painel
A1: PAINEL DE RECICLABILIDADE E CONFORMIDADE DE EMBALAGENS — PLASTICOM
A2: Autoavaliação RecyClass (regras simplificadas) e graus PPWR indicativos · vendas de 2026 · atualiza com as tabelas
A4: Indicador | B4: Valor
A5: SKUs avaliados (frascos e potes) | B5: =COUNTA(tbl_recyclass[ProductId]) -> 113
A6: SKUs com grau PPWR A–C (não isentos) — KPI-18 | B6: =COUNTIFS(tbl_recyclass[Conforme_PPWR_2030],"Sim")/(COUNTA(tbl_recyclass[ProductId])-COUNTIF(tbl_recyclass[Segmento],"Farmacêutico")) -> 0.6635514
A7: Massa vendida com grau A–C (não isentos) — KPI-20 | B7: =SUMIFS(tbl_recyclass[Massa_Vendida_kg],tbl_recyclass[Conforme_PPWR_2030],"Sim")/SUMIFS(tbl_recyclass[Massa_Vendida_kg],tbl_recyclass[Segmento],"<>Farmacêutico") -> 0.59745288
A8: SKUs classe F (não recicláveis) | B8: =COUNTIF(tbl_recyclass[Classe_RecyClass],"F") -> 19
A9: SKUs isentos até 2035 (farmacêuticos) | B9: =COUNTIF(tbl_recyclass[Isencao_Art6],"Isento até 2035") -> 6
A10: Taxa média de reciclabilidade ponderada pela massa vendida | B10: =SUMPRODUCT(tbl_recyclass[Taxa_Reciclabilidade],tbl_recyclass[Massa_Vendida_kg])/SUM(tbl_recyclass[Massa_Vendida_kg]) -> 0.84411001
A11: Conteúdo reciclado ponderado (corpos + tampas vendidos) — KPI-19 | B11: =SUM(tbl_vendas_embalagem[Massa_Reciclado_kg])/SUM(tbl_vendas_embalagem[Massa_kg]) -> 0.11877847
A12: Famílias com declaração UE de conformidade — KPI-12 | B12: =COUNTIF(tbl_familias_ppwr[Declaracao_UE],"Sim")/COUNTA(tbl_familias_ppwr[ID_Familia]) -> 0.77272727
A13: Certificados de reciclado válidos — KPI-21 | B13: =(COUNTIF(tbl_certificados_pcr[Estado],"Válido")+COUNTIF(tbl_certificados_pcr[Estado],"Expira*"))/COUNTIFS(tbl_certificados_pcr[Pct_PCR_Declarado],">0") -> 1
A14: Imposto espanhol estimado (pago pelos clientes ES, €/ano) | B14: =SUM(tbl_vendas_embalagem[Imposto_ES_EUR]) -> 39016.803
A15: Requisitos da matriz em lacuna / parcial | B15: =COUNTIF(tbl_requisitos_emb[Estado],"Lacuna")&" / "&COUNTIF(tbl_requisitos_emb[Estado],"Parcial") -> 1 / 23
A16: Checklist de maturidade implementado | B16: =COUNTIF(tbl_maturidade_emb[Estado],"Implementado")/COUNTA(tbl_maturidade_emb[ID_Item]) -> 0.75
A17: Alegações a retirar / proibidas / suspensas | B17: =COUNTIF(tbl_alegacoes[Estado],"Retirar")+COUNTIF(tbl_alegacoes[Estado],"Proibida")+COUNTIF(tbl_alegacoes[Estado],"Suspensa") -> 4
A19: DISTRIBUIÇÃO POR CLASSE RECYCLASS
A20: Classe | B20: N.º SKUs | C20: Massa vendida (kg) | D20: % SKUs | E20: % massa
A21: A | B21: =COUNTIF(tbl_recyclass[Classe_RecyClass],A21) -> 26 | C21: =SUMIFS(tbl_recyclass[Massa_Vendida_kg],tbl_recyclass[Classe_RecyClass],A21) -> 82511.909 | D21: =B21/SUM($B$21:$B$26) -> 0.2300885 | E21: =C21/SUM($C$21:$C$26) -> 0.17634634
A22: B | B22: =COUNTIF(tbl_recyclass[Classe_RecyClass],A22) -> 25 | C22: =SUMIFS(tbl_recyclass[Massa_Vendida_kg],tbl_recyclass[Classe_RecyClass],A22) -> 109345.5 | D22: =B22/SUM($B$21:$B$26) -> 0.22123894 | E22: =C22/SUM($C$21:$C$26) -> 0.23369569
A23: C | B23: =COUNTIF(tbl_recyclass[Classe_RecyClass],A23) -> 26 | C23: =SUMIFS(tbl_recyclass[Massa_Vendida_kg],tbl_recyclass[Classe_RecyClass],A23) -> 92488.846 | D23: =B23/SUM($B$21:$B$26) -> 0.2300885 | E23: =C23/SUM($C$21:$C$26) -> 0.19766927
A24: D | B24: =COUNTIF(tbl_recyclass[Classe_RecyClass],A24) -> 17 | C24: =SUMIFS(tbl_recyclass[Massa_Vendida_kg],tbl_recyclass[Classe_RecyClass],A24) -> 111035.16 | D24: =B24/SUM($B$21:$B$26) -> 0.15044248 | E24: =C24/SUM($C$21:$C$26) -> 0.23730689
A25: E | B25: =COUNTIF(tbl_recyclass[Classe_RecyClass],A25) -> 0 | C25: =SUMIFS(tbl_recyclass[Massa_Vendida_kg],tbl_recyclass[Classe_RecyClass],A25) -> 0 | D25: =B25/SUM($B$21:$B$26) -> 0 | E25: =C25/SUM($C$21:$C$26) -> 0
A26: F | B26: =COUNTIF(tbl_recyclass[Classe_RecyClass],A26) -> 19 | C26: =SUMIFS(tbl_recyclass[Massa_Vendida_kg],tbl_recyclass[Classe_RecyClass],A26) -> 72515.513 | D26: =B26/SUM($B$21:$B$26) -> 0.16814159 | E26: =C26/SUM($C$21:$C$26) -> 0.15498181
A29: GRAU PPWR INDICATIVO × CONFORMIDADE 2030/2038
A30: Grau PPWR | B30: N.º SKUs | C30: Massa vendida (kg)
A31: A | B31: =COUNTIF(tbl_recyclass[Grau_PPWR_Indicativo],A31) -> 26 | C31: =SUMIFS(tbl_recyclass[Massa_Vendida_kg],tbl_recyclass[Grau_PPWR_Indicativo],A31) -> 82511.909
A32: B | B32: =COUNTIF(tbl_recyclass[Grau_PPWR_Indicativo],A32) -> 25 | C32: =SUMIFS(tbl_recyclass[Massa_Vendida_kg],tbl_recyclass[Grau_PPWR_Indicativo],A32) -> 109345.5
A33: C | B33: =COUNTIF(tbl_recyclass[Grau_PPWR_Indicativo],A33) -> 26 | C33: =SUMIFS(tbl_recyclass[Massa_Vendida_kg],tbl_recyclass[Grau_PPWR_Indicativo],A33) -> 92488.846
A34: Abaixo de C | B34: =COUNTIF(tbl_recyclass[Grau_PPWR_Indicativo],A34) -> 17 | C34: =SUMIFS(tbl_recyclass[Massa_Vendida_kg],tbl_recyclass[Grau_PPWR_Indicativo],A34) -> 111035.16
A35: Não reciclável (F) | B35: =COUNTIF(tbl_recyclass[Grau_PPWR_Indicativo],A35) -> 19 | C35: =SUMIFS(tbl_recyclass[Massa_Vendida_kg],tbl_recyclass[Grau_PPWR_Indicativo],A35) -> 72515.513
A38: CONTEÚDO RECICLADO FACE ÀS METAS DO ART. 7.º (média da instalação, ponderada pela massa vendida)
A39: Categoria art. 7.º | B39: Massa vendida (kg) | C39: Reciclado (%) | D39: Meta 2030 | E39: Gap (p.p.)
A40: Sensível ao contacto — PET | B40: =SUMIFS(tbl_recyclass[Massa_Vendida_kg],tbl_recyclass[Categoria_Art7],A40) -> 0 | C40: =IFERROR(SUMPRODUCT((tbl_recyclass[Categoria_Art7]=A40)*tbl_recyclass[Massa_Vendida_kg]*tbl_recyclass[Conteudo_Reciclado_Pct])/B40,"") | D40: =IFERROR(IF(INDEX(tbl_metas_art7[Meta_2030],MATCH(A40,tbl_metas_art7[Categoria_Art7],0))="","",INDEX(tbl_metas_art7[Meta_2030],MATCH(A40,tbl_metas_art7[Categoria_Art7],0))),"") -> 0.3 | E40: =IF(OR(C40="",D40=""),"",MAX(0,D40-C40))
A41: Sensível ao contacto — outros plásticos | B41: =SUMIFS(tbl_recyclass[Massa_Vendida_kg],tbl_recyclass[Categoria_Art7],A41) -> 21019.797 | C41: =IFERROR(SUMPRODUCT((tbl_recyclass[Categoria_Art7]=A41)*tbl_recyclass[Massa_Vendida_kg]*tbl_recyclass[Conteudo_Reciclado_Pct])/B41,"") -> 0 | D41: =IFERROR(IF(INDEX(tbl_metas_art7[Meta_2030],MATCH(A41,tbl_metas_art7[Categoria_Art7],0))="","",INDEX(tbl_metas_art7[Meta_2030],MATCH(A41,tbl_metas_art7[Categoria_Art7],0))),"") -> 0.1 | E41: =IF(OR(C41="",D41=""),"",MAX(0,D41-C41)) -> 0.1
A42: Garrafas de bebidas de utilização única | B42: =SUMIFS(tbl_recyclass[Massa_Vendida_kg],tbl_recyclass[Categoria_Art7],A42) -> 0 | C42: =IFERROR(SUMPRODUCT((tbl_recyclass[Categoria_Art7]=A42)*tbl_recyclass[Massa_Vendida_kg]*tbl_recyclass[Conteudo_Reciclado_Pct])/B42,"") | D42: =IFERROR(IF(INDEX(tbl_metas_art7[Meta_2030],MATCH(A42,tbl_metas_art7[Categoria_Art7],0))="","",INDEX(tbl_metas_art7[Meta_2030],MATCH(A42,tbl_metas_art7[Categoria_Art7],0))),"") -> 0.3 | E42: =IF(OR(C42="",D42=""),"",MAX(0,D42-C42))
A43: Outras embalagens de plástico | B43: =SUMIFS(tbl_recyclass[Massa_Vendida_kg],tbl_recyclass[Categoria_Art7],A43) -> 434953.35 | C43: =IFERROR(SUMPRODUCT((tbl_recyclass[Categoria_Art7]=A43)*tbl_recyclass[Massa_Vendida_kg]*tbl_recyclass[Conteudo_Reciclado_Pct])/B43,"") -> 0.1220339 | D43: =IFERROR(IF(INDEX(tbl_metas_art7[Meta_2030],MATCH(A43,tbl_metas_art7[Categoria_Art7],0))="","",INDEX(tbl_metas_art7[Meta_2030],MATCH(A43,tbl_metas_art7[Categoria_Art7],0))),"") -> 0.35 | E43: =IF(OR(C43="",D43=""),"",MAX(0,D43-C43)) -> 0.2279661
A44: Isenta — medicamentos (art. 7.º) | B44: =SUMIFS(tbl_recyclass[Massa_Vendida_kg],tbl_recyclass[Categoria_Art7],A44) -> 11923.777 | C44: =IFERROR(SUMPRODUCT((tbl_recyclass[Categoria_Art7]=A44)*tbl_recyclass[Massa_Vendida_kg]*tbl_recyclass[Conteudo_Reciclado_Pct])/B44,"") -> 0 | D44: =IFERROR(IF(INDEX(tbl_metas_art7[Meta_2030],MATCH(A44,tbl_metas_art7[Categoria_Art7],0))="","",INDEX(tbl_metas_art7[Meta_2030],MATCH(A44,tbl_metas_art7[Categoria_Art7],0))),"") | E44: =IF(OR(C44="",D44=""),"",MAX(0,D44-C44))
A47: ANÁLISE DINÂMICA (tabela dinâmica e segmentações — atualizar com Dados > Atualizar tudo)
A50: N.º de SKUs | C50: Classe_RecyClass
...

Sheet Parametros
A1: PARÂMETROS DE CÁLCULO
A2: Editar a coluna Valor; as fórmulas das outras folhas atualizam-se
A4: ID_Parametro | B4: Parametro | C4: Valor | D4: Unidade | E4: Fonte
A5: P-01 | B5: Imposto espanhol sobre embalagens de plástico não reutilizáveis (Lei 7/2022) | C5: 0.45 | D5: €/kg de plástico não reciclado | E5: BOE — Ley 7/2022, art. 81.º (confirmar taxa em vigor)
A6: P-02 | B6: Gramagem de rótulo de filme PE/PP/PET | C6: 55 | D6: g/m² | E6: Estimativa técnica (filme 60 µm + adesivo)
A7: P-03 | B7: Gramagem de rótulo de papel | C7: 75 | D7: g/m² | E7: Estimativa técnica
A8: P-04 | B8: Tinta de serigrafia depositada por cor | C8: 0.08 | D8: g/un | E8: RG-SGA-13 (0,24 kg/1.000 peças para ≈ 3 cores)
A9: P-05 | B9: Metalização de hot foil transferida para a peça | C9: 0.03 | D9: g/un | E9: Estimativa (foil consumido 1,9 kg/1.000; filme de suporte vai para resíduo)
A10: P-06 | B10: Limiar do grau PPWR A (taxa de reciclabilidade em massa) | C10: 0.95 | D10: fração | E10: Reg. (UE) 2025/40, anexo II, quadro 3
A11: P-07 | B11: Limiar do grau PPWR B | C11: 0.8 | D11: fração | E11: Reg. (UE) 2025/40, anexo II, quadro 3
A12: P-08 | B12: Limiar do grau PPWR C | C12: 0.7 | D12: fração | E12: Reg. (UE) 2025/40, anexo II, quadro 3
A13: P-09 | B13: Cartão por caixa de expedição | C13: 0.45 | D13: kg/caixa | E13: Especificação logística Plasticom
A14: P-10 | B14: Frascos por caixa | C14: 250 | D14: un/caixa | E14: Especificação logística (média)
A15: P-11 | B15: Tampas por caixa | C15: 1000 | D15: un/caixa | E15: Especificação logística (média)
A16: P-12 | B16: Caixas por palete | C16: 40 | D16: caixas/palete | E16: Especificação logística
... A21: P-17 | B21: Prestação financeira — madeira (embalagens não urbanas, PT) | C21: 0.01 | D21: €/kg | E21: Valor INDICATIVO — substituir pela tabela da entidade gestora em vigor
A23: Metas de teor mínimo de plástico reciclado — PPWR art. 7.º (tabela tbl_metas_art7 na folha Metas_Art7)

Sheet Metas_Art7
A1: Categoria_Art7 | B1: Meta_2030 | C1: Meta_2040 | D1: Base_Legal | E1: Nota
A2: Sensível ao contacto — PET | B2: 0.3 | C2: 0.5 | D2: Art. 7.º, n.º 1, al. a) e n.º 2, al. a) | E2: Inclui embalagens alimentares de PET (exceto garrafas de bebidas).
A3: Sensível ao contacto — outros plásticos | B3: 0.1 | C3: 0.25 | D3: Art. 7.º, n.º 1, al. b) e n.º 2, al. b) | E3: Embalagens alimentares de PE/PP: o reciclado tem de cumprir o Reg. (UE) 2022/1616.
A4: Garrafas de bebidas de utilização única | B4: 0.3 | C4: 0.65 | D4: Art. 7.º, n.º 1, al. c) e n.º 2, al. c) | E4: Sem SKUs atuais (confirmar uso de FA-030/031).
A5: Outras embalagens de plástico | B5: 0.35 | C5: 0.65 | D5: Art. 7.º, n.º 1, al. d) e n.º 2, al. d) | E5: Cosmética e higiene: pressupõe-se que NÃO é 'sensível ao contacto' (confirmar a definição do art. 3.º) — cenário conservador.
A6: Isenta — medicamentos (art. 7.º) | D6: Art. 7.º (isenções) | E6: Embalagem sensível ao contacto de medicamentos para uso humano e veterinário.

Sheet Materiais
A1: Material | B1: Polimero_Base | C1: Fluxo_Reciclagem | D1: Densidade_g_cm3 | E1: Grau | F1: Pct_PCR | G1: Codigo_Identificacao | H1: ID_Fornecedor | I1: N_SKUs_Corpo | J1: Massa_Vendida_kg
A2: HDPE | B2: PE | C2: PE rígido | D2: 0.955 | E2: Virgem | F2: 0 | G2: >PE-HD< (2) | H2: SUP-001 | I2: =COUNTIF(tbl_recyclass[Material_Corpo],A2) -> 19 | J2: =SUMIFS(tbl_recyclass[Massa_Vendida_kg],tbl_recyclass[Material_Corpo],A2) -> 116243.82
A3: HDPE-PCR | B3: PE | C3: PE rígido | D3: 0.96 | E3: Reciclado pós-consumo | F3: 0.3 | G3: >PE-HD< (2) | H3: SUP-004 | I3: =COUNTIF(tbl_recyclass[Material_Corpo],A3) -> 13 | J3: =SUMIFS(tbl_recyclass[Massa_Vendida_kg],tbl_recyclass[Material_Corpo],A3) -> 62714.338
A4: MDPE | B4: PE | C4: PE rígido | D4: 0.935 | E4: Virgem | F4: 0 | G4: >PE-MD< (4) | H4: SUP-001 | I4: =COUNTIF(tbl_recyclass[Material_Corpo],A4) -> 5 | J4: =SUMIFS(tbl_recyclass[Massa_Vendida_kg],tbl_recyclass[Material_Corpo],A4) -> 18154.214
A5: LDPE | B5: PE | C5: PE rígido | D5: 0.92 | E5: Virgem | F5: 0 | G5: >PE-LD< (4) | H5: SUP-007 | I5: =COUNTIF(tbl_recyclass[Material_Corpo],A5) -> 3 | J5: =SUMIFS(tbl_recyclass[Massa_Vendida_kg],tbl_recyclass[Material_Corpo],A5) -> 4869.9023
A6: HDPE-FG | B6: PE | C6: PE rígido | D6: 0.955 | E6: Grau alimentar (FCM) | F6: 0 | G6: >PE-HD< (2) | H6: SUP-010 | I6: =COUNTIF(tbl_recyclass[Material_Corpo],A6) -> 2 | J6: =SUMIFS(tbl_recyclass[Massa_Vendida_kg],tbl_recyclass[Material_Corpo],A6) -> 10553.735
A7: PP | B7: PP | C7: PP rígido | D7: 0.905 | E7: Virgem | F7: 0 | G7: >PP< (5) | H7: SUP-002 | I7: =COUNTIF(tbl_recyclass[Material_Corpo],A7) -> 11 | J7: =SUMIFS(tbl_recyclass[Massa_Vendida_kg],tbl_recyclass[Material_Corpo],A7) -> 25144.037
A8: PP-PCR | B8: PP | C8: PP rígido | D8: 0.91 | E8: Reciclado pós-consumo | F8: 0.3 | G8: >PP< (5) | H8: SUP-002 | I8: =COUNTIF(tbl_recyclass[Material_Corpo],A8) -> 8 | J8: =SUMIFS(tbl_recyclass[Massa_Vendida_kg],tbl_recyclass[Material_Corpo],A8) -> 18727.65
A9: PP-FG | B9: PP | C9: PP rígido | D9: 0.905 | E9: Grau alimentar (FCM) | F9: 0 | G9: >PP< (5) | H9: SUP-010 | I9: =COUNTIF(tbl_recyclass[Material_Corpo],A9) -> 2 | J9: =SUMIFS(tbl_recyclass[Massa_Vendida_kg],tbl_recyclass[Material_Corpo],A9) -> 10466.062
A10: PP-PG | B10: PP | C10: PP rígido | D10: 0.905 | E10: Grau farmacêutico | F10: 0 | G10: >PP< (5) | H10: SUP-009 | I10: =COUNTIF(tbl_recyclass[Material_Corpo],A10) -> 4 | J10: =SUMIFS(tbl_recyclass[Massa_Vendida_kg],tbl_recyclass[Material_Corpo],A10) -> 7385.1153
A11: PET | B11: PET | C11: PET frascos e garrafas | D11: 1.38 | E11: Virgem | F11: 0 | G11: >PET< (1) | H11: SUP-003 | I11: =COUNTIF(tbl_recyclass[Material_Corpo],A11) -> 13 | J11: =SUMIFS(tbl_recyclass[Massa_Vendida_kg],tbl_recyclass[Material_Corpo],A11) -> 76802.716
A12: rPET | B12: PET | C12: PET frascos e garrafas | D12: 1.38 | E12: Reciclado pós-consumo | F12: 0.5 | G12: >PET< (1) | H12: SUP-004 | I12: =COUNTIF(tbl_recyclass[Material_Corpo],A12) -> 19 | J12: =SUMIFS(tbl_recyclass[Massa_Vendida_kg],tbl_recyclass[Material_Corpo],A12) -> 83695.046
A13: PET-PG | B13: PET | C13: PET frascos e garrafas | D13: 1.38 | E13: Grau farmacêutico | F13: 0 | G13: >PET< (1) | H13: SUP-009 | I13: =COUNTIF(tbl_recyclass[Material_Corpo],A13) -> 2 | J13: =SUMIFS(tbl_recyclass[Massa_Vendida_kg],tbl_recyclass[Material_Corpo],A13) -> 4538.6619
... A15: PVC | B15: PVC | C15: Sem fluxo (PVC) | D15: 1.35 | E15: Virgem | F15: 0 | G15: >PVC< (3) | H15: SUP-005 | I15: =COUNTIF(tbl_recyclass[Material_Corpo],A15) -> 4 | J15: =SUMIFS(tbl_recyclass[Massa_Vendida_kg],tbl_recyclass[Material_Corpo],A15) -> 10112.811

Sheet Regras_DfR
A1: REGRAS DE DESIGN PARA RECICLAGEM (DfR) — BASE DO CÁLCULO RECYCLASS
A2: Interpretação simplificada das diretrizes RecyClass (HDPE/PP containers, PET bottles) · Classe final = pior característica · Editar Classe/Fração para recalibrar
A4: Chave | B4: Fluxo | C4: Caracteristica | D4: Valor | E4: Classe | F4: Compatibilidade | G4: Fracao_Reciclavel | H4: Fundamentacao | I4: Recomendacao
A5: =B5&"|"&C5&"|"&D5 -> PE rígido|Fluxo de reciclagem|PE rígido | B5: PE rígido | C5: Fluxo de reciclagem | D5: PE rígido | E5: A | F5: =CHOOSE(MATCH(E5,{"A","B","C","D","E","F"},0),"Totalmente compatível","Compatibilidade limitada","Compatibilidade limitada (afeta a qualidade)","Problemas significativos","Problemas graves","Não reciclável / não compatível") -> Totalmente compatível | G5: 1 | H5: Fluxo de triagem e reciclagem mecânica estabelecido na Europa. | I5: Sem ação — manter.
A6: =B6&"|"&C6&"|"&D6 -> PP rígido|Fluxo de reciclagem|PP rígido | B6: PP rígido | C6: Fluxo de reciclagem | D6: PP rígido | E6: A | F6: =CHOOSE(MATCH(E6,{"A","B","C","D","E","F"},0),"Totalmente compatível","Compatibilidade limitada","Compatibilidade limitada (afeta a qualidade)","Problemas significativos","Problemas graves","Não reciclável / não compatível") -> Totalmente compatível | G6: 1 | H6: Fluxo de triagem e reciclagem mecânica estabelecido na Europa. | I6: Sem ação — manter.
A7: =B7&"|"&C7&"|"&D7 -> PET frascos e garrafas|Fluxo de reciclagem|PET frascos e garrafas | B7: PET frascos e garrafas | C7: Fluxo de reciclagem | D7: PET frascos e garrafas | E7: A | F7: =CHOOSE(MATCH(E7,{"A","B","C","D","E","F"},0),"Totalmente compatível","Compatibilidade limitada","Compatibilidade limitada (afeta a qualidade)","Problemas significativos","Problemas graves","Não reciclável / não compatível") -> Totalmente compatível | G7: 1 | H7: Fluxo de triagem e reciclagem mecânica estabelecido na Europa. | I7: Sem ação — manter.
A8: =B8&"|"&C8&"|"&D8 -> Sem fluxo (PETG)|Fluxo de reciclagem|Sem fluxo (PETG) | B8: Sem fluxo (PETG) | C8: Fluxo de reciclagem | D8: Sem fluxo (PETG) | E8: F | F8: =CHOOSE(MATCH(E8,{"A","B","C","D","E","F"},0),"Totalmente compatível","Compatibilidade limitada","Compatibilidade limitada (afeta a qualidade)","Problemas significativos","Problemas graves","Não reciclável / não compatível") -> Não reciclável / não compatível | G8: 0 | H8: PETG não tem fluxo de reciclagem dedicado; é triado com o PET e perturba o processo (amolece a temperaturas de secagem do PET). | I8: Mudar o corpo para PET (ou PP/PE) — PETG não passa a grau C em 2030.
A9: =B9&"|"&C9&"|"&D9 -> Sem fluxo (PVC)|Fluxo de reciclagem|Sem fluxo (PVC) | B9: Sem fluxo (PVC) | C9: Fluxo de reciclagem | D9: Sem fluxo (PVC) | E9: F | F9: =CHOOSE(MATCH(E9,{"A","B","C","D","E","F"},0),"Totalmente compatível","Compatibilidade limitada","Compatibilidade limitada (afeta a qualidade)","Problemas significativos","Problemas graves","Não reciclável / não compatível") -> Não reciclável / não compatível | G9: 0 | H9: Sem fluxo de reciclagem de embalagens domésticas de PVC; contamina o PET (HCl na extrusão). | I9: Eliminar o PVC do portfólio (substituir por PET ou PP).
A10: =B10&"|"&C10&"|"&D10 -> PE rígido|Cor do corpo|Natural / incolor | B10: PE rígido | C10: Cor do corpo | D10: Natural / incolor | E10: A | F10: =CHOOSE(MATCH(E10,{"A","B","C","D","E","F"},0),"Totalmente compatível","Compatibilidade limitada","Compatibilidade limitada (afeta a qualidade)","Problemas significativos","Problemas graves","Não reciclável / não compatível") -> Totalmente compatível | G10: 1 | H10: Reciclado incolor de maior valor. | I10: Sem ação — manter.
A11: =B11&"|"&C11&"|"&D11 -> PE rígido|Cor do corpo|Branco (TiO2) | B11: PE rígido | C11: Cor do corpo | D11: Branco (TiO2) | E11: A | F11: =CHOOSE(MATCH(E11,{"A","B","C","D","E","F"},0),"Totalmente compatível","Compatibilidade limitada","Compatibilidade limitada (afeta a qualidade)","Problemas significativos","Problemas graves","Não reciclável / não compatível") -> Totalmente compatível | G11: 1 | H11: Cores claras/brancas totalmente compatíveis. | I11: Sem ação — manter.
A12: =B12&"|"&C12&"|"&D12 -> PE rígido|Cor do corpo|Colorido (claro ou transparente) | B12: PE rígido | C12: Cor do corpo | D12: Colorido (claro ou transparente) | E12: B | F12: =CHOOSE(MATCH(E12,{"A","B","C","D","E","F"},0),"Totalmente compatível","Compatibilidade limitada","Compatibilidade limitada (afeta a qualidade)","Problemas significativos","Problemas graves","Não reciclável / não compatível") -> Compatibilidade limitada | G12: 1 | H12: Reciclado de PE colorido — valor e aplicações mais limitados. | I12: Preferir natural, branco ou cores claras.
A13: =B13&"|"&C13&"|"&D13 -> PE rígido|Cor do corpo|Colorido escuro / opaco | B13: PE rígido | C13: Cor do corpo | D13: Colorido escuro / opaco | E13: B | F13: =CHOOSE(MATCH(E13,{"A","B","C","D","E","F"},0),"Totalmente compatível","Compatibilidade limitada","Compatibilidade limitada (afeta a qualidade)","Problemas significativos","Problemas graves","Não reciclável / não compatível") -> Compatibilidade limitada | G13: 1 | H13: Reciclado de PE escuro — só aplicações escuras. | I13: Preferir cores claras.
A14: =B14&"|"&C14&"|"&D14 -> PE rígido|Cor do corpo|Preto (negro de carbono) | B14: PE rígido | C14: Cor do corpo | D14: Preto (negro de carbono) | E14: F | F14: =CHOOSE(MATCH(E14,{"A","B","C","D","E","F"},0),"Totalmente compatível","Compatibilidade limitada","Compatibilidade limitada (afeta a qualidade)","Problemas significativos","Problemas graves","Não reciclável / não compatível") -> Não reciclável / não compatível | G14: 0 | H14: Negro de carbono absorve o infravermelho próximo: a embalagem não é identificada na triagem NIR e vai para refugo. | I14: Substituir o masterbatch por preto detetável por NIR (pigmentos sem negro de carbono).
A15: =B15&"|"&C15&"|"&D15 -> PE rígido|Cor do corpo|Preto detetável por NIR | B15: PE rígido | C15: Cor do corpo | D15: Preto detetável por NIR | E15: B | F15: =CHOOSE(MATCH(E15,{"A","B","C","D","E","F"},0),"Totalmente compatível","Compatibilidade limitada","Compatibilidade limitada (afeta a qualidade)","Problemas significativos","Problemas graves","Não reciclável / não compatível") -> Compatibilidade limitada | G15: 1 | H15: Detetável na triagem; reciclado escuro. | I15: Manter pigmento detetável por NIR e validar com teste de triagem.
A16: =B16&"|"&C16&"|"&D16 -> PE rígido|Densidade do corpo|< 1,0 g/cm³ | B16: PE rígido | C16: Densidade do corpo | D16: < 1,0 g/cm³ | E16: A | F16: =CHOOSE(MATCH(E16,{"A","B","C","D","E","F"},0),"Totalmente compatível","Compatibilidade limitada","Compatibilidade limitada (afeta a qualidade)","Problemas significativos","Problemas graves","Não reciclável / não compatível") -> Totalmente compatível | G16: 1 | H16: Flutua em água: separado corretamente das impurezas no tanque de afunda-flutua. | I16: Sem ação — manter.
... A117: =B117&"|"&C117&"|"&D117 -> PET frascos e garrafas|Decoração direta|Hot foil metalizado | B117: PET frascos e garrafas | C117: Decoração direta | D117: Hot foil metalizado | E117: D | F117: =CHOOSE(MATCH(E117,{"A","B","C","D","E","F"},0),"Totalmente compatível","Compatibilidade limitada","Compatibilidade limitada (afeta a qualidade)","Problemas significativos","Problemas graves","Não reciclável / não compatível") -> Problemas significativos | G117: 0 | H117: Metalização e verniz não removíveis contaminam os flocos. | I117: Rótulo metalizado de PE/PP destacável.

Sheet Tampas
A1: CapId | B1: Descricao | C1: Tipo_Abertura | D1: Material | E1: Polimero_Base | F1: Massa_g | G1: Densidade_g_cm3 | H1: Flutua_Agua | I1: Rosca | J1: Vedante | K1: Pct_PCR | L1: Familia_PPWR | M1: Unid_Vendidas_P12 | N1: Paises_Venda | O1: Massa_Vendida_kg
A2: TR-001-HDPE-24410 | B2: Tampa rosca comum 24/410 HDPE | C2: Screw Cap | D2: HDPE | E2: =IFERROR(INDEX(tbl_materiais[Polimero_Base],MATCH(D2,tbl_materiais[Material],0)),"") -> PE | F2: 11.5 | G2: =IFERROR(INDEX(tbl_materiais[Densidade_g_cm3],MATCH(D2,tbl_materiais[Material],0)),"") -> 0.955 | H2: =IF(G2="","",IF(G2<1,"Sim","Não")) -> Sim | I2: 24/410 | J2: Sem vedante | K2: =IFERROR(INDEX(tbl_materiais[Pct_PCR],MATCH(D2,tbl_materiais[Material],0)),0) -> 0 | L2: FAM-18 | M2: 1595447 | N2: DE; ES; FR; IT; PL; PT | O2: =M2*F2/1000 -> 18347.641
A3: TR-001-PP-24410 | B3: Tampa rosca comum 24/410 PP | C3: Screw Cap | D3: PP | E3: =IFERROR(INDEX(tbl_materiais[Polimero_Base],MATCH(D3,tbl_materiais[Material],0)),"") -> PP | F3: 10.3 | G3: =IFERROR(INDEX(tbl_materiais[Densidade_g_cm3],MATCH(D3,tbl_materiais[Material],0)),"") -> 0.905 | H3: =IF(G3="","",IF(G3<1,"Sim","Não")) -> Sim | I3: 24/410 | J3: Sem vedante | K3: =IFERROR(INDEX(tbl_materiais[Pct_PCR],MATCH(D3,tbl_materiais[Material],0)),0) -> 0 | L3: FAM-16 | M3: 1539973 | N3: DE; ES; FR; IT; PL; PT | O3: =M3*F3/1000 -> 15861.722
A4: TR-001-PP-PCR-24410 | B4: Tampa rosca comum 24/410 PP-PCR | C4: Screw Cap | D4: PP-PCR | E4: =IFERROR(INDEX(tbl_materiais[Polimero_Base],MATCH(D4,tbl_materiais[Material],0)),"") -> PP | F4: 10.3 | G4: =IFERROR(INDEX(tbl_materiais[Densidade_g_cm3],MATCH(D4,tbl_materiais[Material],0)),"") -> 0.91 | H4: =IF(G4="","",IF(G4<1,"Sim","Não")) -> Sim | I4: 24/410 | J4: Sem vedante | K4: =IFERROR(INDEX(tbl_materiais[Pct_PCR],MATCH(D4,tbl_materiais[Material],0)),0) -> 0.3 | L4: FAM-17 | M4: 1197253 | N4: DE; ES; FR; IT; PL; PT | O4: =M4*F4/1000 -> 12331.706
A5: TR-001-PETG-24410 | B5: Tampa rosca comum 24/410 PETG | C5: Screw Cap | D5: PETG | E5: =IFERROR(INDEX(tbl_materiais[Polimero_Base],MATCH(D5,tbl_materiais[Material],0)),"") -> PETG | F5: 12.1 | G5: =IFERROR(INDEX(tbl_materiais[Densidade_g_cm3],MATCH(D5,tbl_materiais[Material],0)),"") -> 1.27 | H5: =IF(G5="","",IF(G5<1,"Sim","Não")) -> Não | I5: 24/410 | J5: Sem vedante | K5: =IFERROR(INDEX(tbl_materiais[Pct_PCR],MATCH(D5,tbl_materiais[Material],0)),0) -> 0 | L5: FAM-19 | M5: 1380640 | N5: DE; ES; FR; IT; PL; PT | O5: =M5*F5/1000 -> 16705.744
A6: TR-002-HDPE-24410 | B6: Tampa rosca comum 24/410 HDPE | C6: Screw Cap | D6: HDPE | E6: =IFERROR(INDEX(tbl_materiais[Polimero_Base],MATCH(D6,tbl_materiais[Material],0)),"") -> PE | F6: 11.5 | G6: =IFERROR(INDEX(tbl_materiais[Densidade_g_cm3],MATCH(D6,tbl_materiais[Material],0)),"") -> 0.955 | H6: =IF(G6="","",IF(G6<1,"Sim","Não")) -> Sim | I6: 24/410 | J6: Sem vedante | K6: =IFERROR(INDEX(tbl_materiais[Pct_PCR],MATCH(D6,tbl_materiais[Material],0)),0) -> 0 | L6: FAM-18 | M6: 617081 | N6: DE; ES; FR; IT; PL; PT | O6: =M6*F6/1000 -> 7096.4315
A7: TR-002-PP-24410 | B7: Tampa rosca comum 24/410 PP | C7: Screw Cap | D7: PP | E7: =IFERROR(INDEX(tbl_materiais[Polimero_Base],MATCH(D7,tbl_materiais[Material],0)),"") -> PP | F7: 10.3 | G7: =IFERROR(INDEX(tbl_materiais[Densidade_g_cm3],MATCH(D7,tbl_materiais[Material],0)),"") -> 0.905 | H7: =IF(G7="","",IF(G7<1,"Sim","Não")) -> Sim | I7: 24/410 | J7: Sem vedante | K7: =IFERROR(INDEX(tbl_materiais[Pct_PCR],MATCH(D7,tbl_materiais[Material],0)),0) -> 0 | L7: FAM-16 | M7: 507368 | N7: DE; ES; FR; IT; PL; PT | O7: =M7*F7/1000 -> 5225.8904
A8: TR-002-PP-PCR-24410 | B8: Tampa rosca comum 24/410 PP-PCR | C8: Screw Cap | D8: PP-PCR | E8: =IFERROR(INDEX(tbl_materiais[Polimero_Base],MATCH(D8,tbl_materiais[Material],0)),"") -> PP | F8: 10.3 | G8: =IFERROR(INDEX(tbl_materiais[Densidade_g_cm3],MATCH(D8,tbl_materiais[Material],0)),"") -> 0.91 | H8: =IF(G8="","",IF(G8<1,"Sim","Não")) -> Sim | I8: 24/410 | J8: Sem vedante | K8: =IFERROR(INDEX(tbl_materiais[Pct_PCR],MATCH(D8,tbl_materiais[Material],0)),0) -> 0.3 | L8: FAM-17 | M8: 488734 | N8: DE; ES; FR; IT; PL; PT | O8: =M8*F8/1000 -> 5033.9602
A9: TR-002-PETG-24410 | B9: Tampa rosca comum 24/410 PETG | C9: Screw Cap | D9: PETG | E9: =IFERROR(INDEX(tbl_materiais[Polimero_Base],MATCH(D9,tbl_materiais[Material],0)),"") -> PETG | F9: 12.1 | G9: =IFERROR(INDEX(tbl_materiais[Densidade_g_cm3],MATCH(D9,tbl_materiais[Material],0)),"") -> 1.27 | H9: =IF(G9="","",IF(G9<1,"Sim","Não")) -> Não | I9: 24/410 | J9: Sem vedante | K9: =IFERROR(INDEX(tbl_materiais[Pct_PCR],MATCH(D9,tbl_materiais[Material],0)),0) -> 0 | L9: FAM-19 | M9: 533504 | N9: DE; ES; FR; IT; PL; PT | O9: =M9*F9/1000 -> 6455.3984
A10: TR-003-HDPE-24415 | B10: Tampa rosca comum 24/415 HDPE | C10: Screw Cap | D10: HDPE | E10: =IFERROR(INDEX(tbl_materiais[Polimero_Base],MATCH(D10,tbl_materiais[Material],0)),"") -> PE | F10: 11.5 | G10: =IFERROR(INDEX(tbl_materiais[Densidade_g_cm3],MATCH(D10,tbl_materiais[Material],0)),"") -> 0.955 | H10: =IF(G10="","",IF(G10<1,"Sim","Não")) -> Sim | I10: 24/415 | J10: Sem vedante | K10: =IFERROR(INDEX(tbl_materiais[Pct_PCR],MATCH(D10,tbl_materiais[Material],0)),0) -> 0 | L10: FAM-18 | M10: 656567 | N10: DE; ES; FR; IT; PL; PT | O10: =M10*F10/1000 -> 7550.5205
A11: TR-003-PP-24415 | B11: Tampa rosca comum 24/415 PP | C11: Screw Cap | D11: PP | E11: =IFERROR(INDEX(tbl_materiais[Polimero_Base],MATCH(D11,tbl_materiais[Material],0)),"") -> PP | F11: 10.3 | G11: =IFERROR(INDEX(tbl_materiais[Densidade_g_cm3],MATCH(D11,tbl_materiais[Material],0)),"") -> 0.905 | H11: =IF(G11="","",IF(G11<1,"Sim","Não")) -> Sim | I11: 24/415 | J11: Sem vedante | K11: =IFERROR(INDEX(tbl_materiais[Pct_PCR],MATCH(D11,tbl_materiais[Material],0)),0) -> 0 | L11: FAM-16 | M11: 668908 | N11: DE; ES; FR; IT; PL; PT | O11: =M11*F11/1000 -> 6889.7524
A12: TR-003-PP-PCR-24415 | B12: Tampa rosca comum 24/415 PP-PCR | C12: Screw Cap | D12: PP-PCR | E12: =IFERROR(INDEX(tbl_materiais[Polimero_Base],MATCH(D12,tbl_materiais[Material],0)),"") -> PP | F12: 10.3 | G12: =IFERROR(INDEX(tbl_materiais[Densidade_g_cm3],MATCH(D12,tbl_materiais[Material],0)),"") -> 0.91 | H12: =IF(G12="","",IF(G12<1,"Sim","Não")) -> Sim | I12: 24/415 | J12: Sem vedante | K12: =IFERROR(INDEX(tbl_materiais[Pct_PCR],MATCH(D12,tbl_materiais[Material],0)),0) -> 0.3 | L12: FAM-17 | M12: 705915 | N12: DE; ES; FR; IT; PL; PT | O12: =M12*F12/1000 -> 7270.9245
A13: TR-003-PETG-24415 | B13: Tampa rosca comum 24/415 PETG | C13: Screw Cap | D13: PETG | E13: =IFERROR(INDEX(tbl_materiais[Polimero_Base],MATCH(D13,tbl_materiais[Material],0)),"") -> PETG | F13: 12.1 | G13: =IFERROR(INDEX(tbl_materiais[Densidade_g_cm3],MATCH(D13,tbl_materiais[Material],0)),"") -> 1.27 | H13: =IF(G13="","",IF(G13<1,"Sim","Não")) -> Não | I13: 24/415 | J13: Sem vedante | K13: =IFERROR(INDEX(tbl_materiais[Pct_PCR],MATCH(D13,tbl_materiais[Material],0)),0) -> 0 | L13: FAM-19 | M13: 775757 | N13: DE; ES; FR; IT; PL; PT | O13: =M13*F13/1000 -> 9386.6597
... A35: TP-013-PP-PG-070 | B35: Tampa de pote 70mm PP-PG | C35: Snap Lid | D35: PP-PG | E35: =IFERROR(INDEX(tbl_materiais[Polimero_Base],MATCH(D35,tbl_materiais[Material],0)),"") -> PP | F35: 16.5 | G35: =IFERROR(INDEX(tbl_materiais[Densidade_g_cm3],MATCH(D35,tbl_materiais[Material],0)),"") -> 0.905 | H35: =IF(G35="","",IF(G35<1,"Sim","Não")) -> Sim | I35: Snap 70mm | J35: Sem vedante | K35: =IFERROR(INDEX(tbl_materiais[Pct_PCR],MATCH(D35,tbl_materiais[Material],0)),0) -> 0 | L35: FAM-20 | M35: 218005 | N35: ES; PT | O35: =M35*F35/1000 -> 3597.0825
A36: TA-014-HDPE-FG-28410 | B36: Tampa rosca alimentícia 28/410 HDPE-FG | C36: Screw Cap | D36: HDPE-FG | E36: =IFERROR(INDEX(tbl_materiais[Polimero_Base],MATCH(D36,tbl_materiais[Material],0)),"") -> PE | F36: 15.9 | G36: =IFERROR(INDEX(tbl_materiais[Densidade_g_cm3],MATCH(D36,tbl_materiais[Material],0)),"") -> 0.955 | H36: =IF(G36="","",IF(G36<1,"Sim","Não")) -> Sim | I36: 28/410 | J36: Sem vedante | K36: =IFERROR(INDEX(tbl_materiais[Pct_PCR],MATCH(D36,tbl_materiais[Material],0)),0) -> 0 | L36: FAM-21 | M36: 0 | O36: =M36*F36/1000 -> 0
A37: TA-014-PP-FG-28410 | B37: Tampa rosca alimentícia 28/410 PP-FG | C37: Screw Cap | D37: PP-FG | E37: =IFERROR(INDEX(tbl_materiais[Polimero_Base],MATCH(D37,tbl_materiais[Material],0)),"") -> PP | F37: 15.9 | G37: =IFERROR(INDEX(tbl_materiais[Densidade_g_cm3],MATCH(D37,tbl_materiais[Material],0)),"") -> 0.905 | H37: =IF(G37="","",IF(G37<1,"Sim","Não")) -> Sim | I37: 28/410 | J37: Sem vedante | K37: =IFERROR(INDEX(tbl_materiais[Pct_PCR],MATCH(D37,tbl_materiais[Material],0)),0) -> 0 | L37: FAM-22 | M37: 0 | O37: =M37*F37/1000 -> 0

Sheet Avaliacao_RecyClass
A1: AVALIAÇÃO DE RECICLABILIDADE POR SKU — MODELO RECYCLASS + GRAU PPWR (AUTOAVALIAÇÃO)
A2: Colunas brancas = campos a introduzir na ferramenta online RecyClass · cinzentas = cálculo · Rótulos: cenário típico do cliente (confirmar) · Massas estimadas · Não substitui a certificação RecyClass
A4: ID_Avaliacao | B4: ProductId | C4: Formato | D4: Segmento | E4: Contacto | F4: Processo_Fabrico | G4: Familia_PPWR | H4: Volume_ml | I4: Dimensao_Max_mm | J4: Material_Corpo | K4: Polimero_Corpo | L4: Fluxo_Reciclagem | M4: Categoria_RecyClass | N4: Cor_Dataset | O4: Cor_Corpo | P4: Masterbatch_Tipo | Q4: Masterbatch_Pct | R4: Densidade_Corpo_g_cm3 | S4: Barreira_Revestimento | T4: Massa_Corpo_g | U4: Origem_Massa | V4: ID_Tampa | W4: Material_Tampa | X4: Polimero_Tampa | Y4: Massa_Tampa_g | Z4: Vedante_Tampa | AA4: Rotulo_Tipo | AB4: Rotulo_Adesivo | AC4: Rotulo_Cobertura_Pct | AD4: Massa_Rotulo_g | AE4: Origem_Rotulo | AF4: Decoracao_Tipo | AG4: Decoracao_N_Cores | AH4: Decoracao_Valor | AI4: Massa_Decoracao_g | AJ4: Classe_Fluxo | AK4: Classe_Cor | AL4: Classe_Densidade | AM4: Classe_Barreira | AN4: Classe_Tampa | AO4: Classe_Vedante | AP4: Classe_Rotulo | AQ4: Classe_Adesivo | AR4: Classe_Cobertura | AS4: Classe_Decoracao | AT4: Classe_N_Max | AU4: Classe_RecyClass | AV4: Regras_em_Falta | AW4: Ponto_Critico | AX4: Recomendacao | AY4: Massa_Total_g | AZ4: Frac_Corpo | BA4: Frac_Tampa | BB4: Frac_Rotulo | BC4: Massa_Reciclavel_g | BD4: Taxa_Reciclabilidade | BE4: Grau_Taxa | BF4: Grau_PPWR_Indicativo | BG4: Isencao_Art6 | BH4: Conforme_PPWR_2030 | BI4: Conforme_PPWR_2038 | BJ4: Pct_PCR_Corpo | BK4: Pct_PCR_Tampa | BL4: Conteudo_Reciclado_Pct | BM4: Categoria_Art7 | BN4: Meta_2030 | BO4: Gap_2030 | BP4: Conforme_Art7_2030 | BQ4: Estrutura_Material | BR4: Unid_Vendidas_P12 | BS4: N_Clientes_P12 | BT4: Paises_Venda | BU4: Massa_Vendida_kg | BV4: N_Requisitos_Aplicaveis | BW4: N_Lacunas | BX4: Data_Avaliacao | BY4: Proxima_Revisao | BZ4: Avaliador | CA4: Estado_Avaliacao | CB4: Metodo
A5: RCA-001 | B5: FR-001-HDPE-300 | C5: Frasco | D5: Cosmética e higiene pessoal | E5: Contacto direto com cosmético/higiene | F5: Injeção-sopro (ISBM) | G5: FAM-01 | H5: 300 | I5: 115 | J5: HDPE | K5: =IFERROR(INDEX(tbl_materiais[Polimero_Base],MATCH(J5,tbl_materiais[Material],0)),"") -> PE | L5: =IFERROR(INDEX(tbl_materiais[Fluxo_Reciclagem],MATCH(J5,tbl_materiais[Material],0)),"") -> PE rígido | M5: =IF(L5="PE rígido","PE rígido — frascos e contentores (HDPE/LDPE)",IF(L5="PP rígido","PP rígido — frascos, potes e contentores",IF(L5="PET frascos e garrafas",IF(O5="Natural / incolor","PET — garrafas/frascos transparentes incolores","PET — garrafas/frascos coloridos ou opacos"),"Sem categoria RecyClass ("&K5&")"))) -> PE rígido — frascos e contentores (HDPE/LDPE) | N5: Cardinal Red | O5: Colorido (claro ou transparente) | P5: Red Masterbatch | Q5: 0.02 | R5: =IFERROR(ROUND(INDEX(tbl_materiais[Densidade_g_cm3],MATCH(J5,tbl_materiais[Material],0))+Q5*1.2,3),"") -> 0.979 | S5: Nenhuma | T5: 22 | U5: Estimada (22 g a 300 ml, escala ^2/3) | V5: TR-001-HDPE-24410 | W5: =IF(V5="","",IFERROR(INDEX(tbl_tampas[Material],MATCH(V5,tbl_tampas[CapId],0)),"")) -> HDPE | X5: =IF(V5="","Sem tampa",IFERROR(INDEX(tbl_materiais[Polimero_Base],MATCH(W5,tbl_materiais[Material],0)),"")) -> PE | Y5: =IF(V5="",0,IFERROR(INDEX(tbl_tampas[Massa_g],MATCH(V5,tbl_tampas[CapId],0)),0)) -> 11.5 | Z5: Sem vedante | AA5: Sem rótulo | AB5: Sem adesivo | AC5: 0 | AD5: 0 | AE5: Sem rótulo (decoração direta Plasticom) | AF5: Serigrafia | AG5: 1 | AH5: =IF(AF5="Serigrafia",IF(AG5>=3,"Serigrafia ≥ 3 cores","Serigrafia 1–2 cores"),AF5) -> Serigrafia 1–2 cores | AI5: 0.08 | AJ5: =IFERROR(INDEX(tbl_regras_dfr[Classe],MATCH(L5&"|Fluxo de reciclagem|"&L5,tbl_regras_dfr[Chave],0)),"Sem regra") -> A | AK5: =IF(LEFT(L5,9)="Sem fluxo","—",IFERROR(INDEX(tbl_regras_dfr[Classe],MATCH(L5&"|Cor do corpo|"&O5,tbl_regras_dfr[Chave],0)),"Sem regra")) -> B | AL5: =IF(LEFT(L5,9)="Sem fluxo","—",IFERROR(INDEX(tbl_regras_dfr[Classe],MATCH(L5&"|Densidade do corpo|"&IF(R5<1,"< 1,0 g/cm³","≥ 1,0 g/cm³"),tbl_regras_dfr[Chave],0)),"Sem regra")) -> A | AM5: =IF(LEFT(L5,9)="Sem fluxo","—",IFERROR(INDEX(tbl_regras_dfr[Classe],MATCH(L5&"|Barreira / revestimento|"&S5,tbl_regras_dfr[Chave],0)),"Sem regra")) -> A | AN5: =IF(LEFT(L5,9)="Sem fluxo","—",IFERROR(INDEX(tbl_regras_dfr[Classe],MATCH(L5&"|Material da tampa|"&X5,tbl_regras_dfr[Chave],0)),"Sem regra")) -> A | AO5: =IF(LEFT(L5,9)="Sem fluxo","—",IFERROR(INDEX(tbl_regras_dfr[Classe],MATCH(L5&"|Vedante / liner|"&Z5,tbl_regras_dfr[Chave],0)),"Sem regra")) -> A | AP5: =IF(LEFT(L5,9)="Sem fluxo","—",IFERROR(INDEX(tbl_regras_dfr[Classe],MATCH(L5&"|Tipo de rótulo|"&AA5,tbl_regras_dfr[Chave],0)),"Sem regra")) -> A | AQ5: =IF(LEFT(L5,9)="Sem fluxo","—",IFERROR(INDEX(tbl_regras_dfr[Classe],MATCH(L5&"|Adesivo do rótulo|"&AB5,tbl_regras_dfr[Chave],0)),"Sem regra")) -> A | AR5: =IF(LEFT(L5,9)="Sem fluxo","—",IFERROR(INDEX(tbl_regras_dfr[Classe],MATCH(L5&"|Cobertura do rótulo|"&IF(AC5>0.7,"> 70% da superfície","≤ 70% da superfície"),tbl_regras_dfr[Chave],0)),"Sem regra")) -> A | AS5: =IF(LEFT(L5,9)="Sem fluxo","—",IFERROR(INDEX(tbl_regras_dfr[Classe],MATCH(L5&"|Decoração direta|"&AH5,tbl_regras_dfr[Chave],0)),"Sem regra")) -> B | AT5: =IF(COUNTIF(AJ5:AS5,"F"),6,IF(COUNTIF(AJ5:AS5,"E"),5,IF(COUNTIF(AJ5:AS5,"D"),4,IF(COUNTIF(AJ5:AS5,"C"),3,IF(COUNTIF(AJ5:AS5,"B"),2,IF(COUNTIF(AJ5:AS5,"A"),1,0)))))) -> 2 | AU5: =IF(AT5=0,"",INDEX({"A","B","C","D","E","F"},AT5)) -> B | AV5: =COUNTIF(AJ5:AS5,"Sem regra") -> 0 | AW5: =IF(OR(AU5="",AU5="A"),"—",SUBSTITUTE(INDEX($AJ$4:$AS$4,MATCH(AU5,AJ5:AS5,0)),"Classe_","")) -> Cor | AX5: =IF(AU5="A","Sem ação — manter o design.",IFERROR(INDEX(tbl_regras_dfr[Recomendacao],MATCH(CHOOSE(MATCH(AU5,AJ5:AS5,0),L5&"|Fluxo de reciclagem|"&L5,L5&"|Cor do corpo|"&O5,L5&"|Densidade do corpo|"&IF(R5<1,"< 1,0 g/cm³","≥ 1,0 g/cm³"),L5&"|Barreira / revestimento|"&S5,L5&"|Material da tampa|"&X5,L5&"|Vedante / liner|"&Z5,L5&"|Tipo de rótulo|"&AA5,L5&"|Adesivo do rótulo|"&AB5,L5&"|Cobertura do rótulo|"&IF(AC5>0.7,"> 70% da superfície","≤ 70% da superfície"),L5&"|Decoração direta|"&AH5),tbl_regras_dfr[Chave],0)),"")) -> Preferir natural, branco ou cores claras. | AY5: =T5+Y5+AD5+AI5 -> 33.58 | AZ5: =MIN(IFERROR(INDEX(tbl_regras_dfr[Fracao_Reciclavel],MATCH(L5&"|Fluxo de reciclagem|"&L5,tbl_regras_dfr[Chave],0)),0),IFERROR(INDEX(tbl_regras_dfr[Fracao_Reciclavel],MATCH(L5&"|Cor do corpo|"&O5,tbl_regras_dfr[Chave],0)),0)) -> 1 | BA5: =IFERROR(INDEX(tbl_regras_dfr[Fracao_Reciclavel],MATCH(L5&"|Material da tampa|"&X5,tbl_regras_dfr[Chave],0)),0) -> 1 | BB5: =IFERROR(INDEX(tbl_regras_dfr[Fracao_Reciclavel],MATCH(L5&"|Tipo de rótulo|"&AA5,tbl_regras_dfr[Chave],0)),0) -> 1 | BC5: =AZ5*(T5+Y5*BA5+AD5*BB5) -> 33.5 | BD5: =IFERROR(BC5/AY5,0) -> 0.99761763 | BE5: =IF(BD5>=INDEX(tbl_param_emb[Valor],MATCH("P-06",tbl_param_emb[ID_Parametro],0)),"A",IF(BD5>=INDEX(tbl_param_emb[Valor],MATCH("P-07",tbl_param_emb[ID_Parametro],0)),"B",IF(BD5>=INDEX(tbl_param_emb[Valor],MATCH("P-08",tbl_param_emb[ID_Parametro],0)),"C","< 70%"))) -> A | BF5: =IF(AU5="F","Não reciclável (F)",INDEX({"A","B","C","Abaixo de C"},MAX(MIN(AT5,4),IF(BE5="A",1,IF(BE5="B",2,IF(BE5="C",3,4)))))) -> B | BG5: =IF(D5="Farmacêutico","Isento até 2035","—") -> — | BH5: =IF(BG5<>"—",BG5,IF(OR(BF5="A",BF5="B",BF5="C"),"Sim","Não")) -> Sim | BI5: =IF(BG5<>"—",BG5,IF(OR(BF5="A",BF5="B"),"Sim","Não")) -> Sim | BJ5: =IFERROR(INDEX(tbl_materiais[Pct_PCR],MATCH(J5,tbl_materiais[Material],0)),0) -> 0 | BK5: =IF(V5="",0,IFERROR(INDEX(tbl_tampas[Pct_PCR],MATCH(V5,tbl_tampas[CapId],0)),0)) -> 0 | BL5: =IFERROR((T5*BJ5+Y5*BK5)/(T5+Y5),0) -> 0 | BM5: =IF(D5="Farmacêutico","Isenta — medicamentos (art. 7.º)",IF(D5="Alimentar",IF(K5="PET","Sensível ao contacto — PET","Sensível ao contacto — outros plásticos"),"Outras embalagens de plástico")) -> Outras embalagens de plástico | BN5: =IFERROR(IF(INDEX(tbl_metas_art7[Meta_2030],MATCH(BM5,tbl_metas_art7[Categoria_Art7],0))="","",INDEX(tbl_metas_art7[Meta_2030],MATCH(BM5,tbl_metas_art7[Categoria_Art7],0))),"") -> 0.35 | BO5: =IF(BN5="","",MAX(0,BN5-BL5)) -> 0.35 | BP5: =IF(BN5="","Isento",IF(BO5=0,"Sim","Não")) -> Não | BQ5: =IF(AND(OR(X5=K5,X5="Sem tampa",AND(OR(X5="PE",X5="PP"),OR(K5="PE",K5="PP"))),OR(AA5="Sem rótulo",AND(ISNUMBER(SEARCH("PE/PP",AA5)),OR(K5="PE",K5="PP")))),"Monomaterial (mesma família)","Multimaterial") -> Monomaterial (mesma família) | BR5: 363211 | BS5: 14 | BT5: DE; ES; FR; IT; PL; PT | BU5: =BR5*T5/1000 -> 7990.642 | BV5: =COUNTIFS(tbl_aplicabilidade[ProductId],B5,tbl_aplicabilidade[Aplicavel],"Sim") -> 12 | BW5: =COUNTIFS(tbl_aplicabilidade[ProductId],B5,tbl_aplicabilidade[Estado_Resumo],"Lacuna")+COUNTIFS(tbl_aplicabilidade[ProductId],B5,tbl_aplicabilidade[Estado_Resumo],"Não conforme") -> 1 | BX5: 46287 | BY5: =EDATE(BX5,12) -> 46652 | BZ5: Responsável de R&D | CA5: Autoavaliação (não certificada) | CB5: Regras simplificadas SGA-20 v1 (diretrizes DfR RecyClass) — confirmar na ferramenta online
A6: RCA-002 | B6: FR-002-HDPE-PCR-300 | C6: Frasco | D6: Cosmética e higiene pessoal | E6: Contacto direto com cosmético/higiene | F6: Injeção-sopro (ISBM) | G6: FAM-02 | H6: 300 | I6: 115 | J6: HDPE-PCR | K6: =IFERROR(INDEX(tbl_materiais[Polimero_Base],MATCH(J6,tbl_materiais[Material],0)),"") -> PE | L6: =IFERROR(INDEX(tbl_materiais[Fluxo_Reciclagem],MATCH(J6,tbl_materiais[Material],0)),"") -> PE rígido | M6: =IF(L6="PE rígido","PE rígido — frascos e contentores (HDPE/LDPE)",IF(L6="PP rígido","PP rígido — frascos, potes e contentores",IF(L6="PET frascos e garrafas",IF(O6="Natural / incolor","PET — garrafas/frascos transparentes incolores","PET — garrafas/frascos coloridos ou opacos"),"Sem categoria RecyClass ("&K6&")"))) -> PE rígido — frascos e contentores (HDPE/LDPE) | N6: Cobalt Blue | O6: Colorido (claro ou transparente) | P6: Blue Masterbatch | Q6: 0.02 | R6: =IFERROR(ROUND(INDEX(tbl_materiais[Densidade_g_cm3],MATCH(J6,tbl_materiais[Material],0))+Q6*1.2,3),"") -> 0.984 | S6: Nenhuma | T6: 22 | U6: Estimada (22 g a 300 ml, escala ^2/3) | V6: TF-005-PP-PCR-24410 | W6: =IF(V6="","",IFERROR(INDEX(tbl_tampas[Material],MATCH(V6,tbl_tampas[CapId],0)),"")) -> PP-PCR | X6: =IF(V6="","Sem tampa",IFERROR(INDEX(tbl_materiais[Polimero_Base],MATCH(W6,tbl_materiais[Material],0)),"")) -> PP | Y6: =IF(V6="",0,IFERROR(INDEX(tbl_tampas[Massa_g],MATCH(V6,tbl_tampas[CapId],0)),0)) -> 13.9 | Z6: Sem vedante | AA6: Autoadesivo PE/PP | AB6: Acrílico permanente | AC6: 0.4 | AD6: 0.46 | AE6: Cenário típico do cliente — confirmar especificação | AF6: Nenhuma | AG6: 0 | AH6: =IF(AF6="Serigrafia",IF(AG6>=3,"Serigrafia ≥ 3 cores","Serigrafia 1–2 cores"),AF6) -> Nenhuma | AI6: 0 | AJ6: =IFERROR(INDEX(tbl_regras_dfr[Classe],MATCH(L6&"|Fluxo de reciclagem|"&L6,tbl_regras_dfr[Chave],0)),"Sem regra") -> A | AK6: =IF(LEFT(L6,9)="Sem fluxo","—",IFERROR(INDEX(tbl_regras_dfr[Classe],MATCH(L6&"|Cor do corpo|"&O6,tbl_regras_dfr[Chave],0)),"Sem regra")) -> B | AL6: =IF(LEFT(L6,9)="Sem fluxo","—",IFERROR(INDEX(tbl_regras_dfr[Classe],MATCH(L6&"|Densidade do corpo|"&IF(R6<1,"< 1,0 g/cm³","≥ 1,0 g/cm³"),tbl_regras_dfr[Chave],0)),"Sem regra")) -> A | AM6: =IF(LEFT(L6,9)="Sem fluxo","—",IFERROR(INDEX(tbl_regras_dfr[Classe],MATCH(L6&"|Barreira / revestimento|"&S6,tbl_regras_dfr[Chave],0)),"Sem regra")) -> A | AN6: =IF(LEFT(L6,9)="Sem fluxo","—",IFERROR(INDEX(tbl_regras_dfr[Classe],MATCH(L6&"|Material da tampa|"&X6,tbl_regras_dfr[Chave],0)),"Sem regra")) -> A | AO6: =IF(LEFT(L6,9)="Sem fluxo","—",IFERROR(INDEX(tbl_regras_dfr[Classe],MATCH(L6&"|Vedante / liner|"&Z6,tbl_regras_dfr[Chave],0)),"Sem regra")) -> A | AP6: =IF(LEFT(L6,9)="Sem fluxo","—",IFERROR(INDEX(tbl_regras_dfr[Classe],MATCH(L6&"|Tipo de rótulo|"&AA6,tbl_regras_dfr[Chave],0)),"Sem regra")) -> A | AQ6: =IF(LEFT(L6,9)="Sem fluxo","—",IFERROR(INDEX(tbl_regras_dfr[Classe],MATCH(L6&"|Adesivo do rótulo|"&AB6,tbl_regras_dfr[Chave],0)),"Sem regra")) -> A | AR6: =IF(LEFT(L6,9)="Sem fluxo","—",IFERROR(INDEX(tbl_regras_dfr[Classe],MATCH(L6&"|Cobertura do rótulo|"&IF(AC6>0.7,"> 70% da superfície","≤ 70% da superfície"),tbl_regras_dfr[Chave],0)),"Sem regra")) -> A | AS6: =IF(LEFT(L6,9)="Sem fluxo","—",IFERROR(INDEX(tbl_regras_dfr[Classe],MATCH(L6&"|Decoração direta|"&AH6,tbl_regras_dfr[Chave],0)),"Sem regra")) -> A | AT6: =IF(COUNTIF(AJ6:AS6,"F"),6,IF(COUNTIF(AJ6:AS6,"E"),5,IF(COUNTIF(AJ6:AS6,"D"),4,IF(COUNTIF(AJ6:AS6,"C"),3,IF(COUNTIF(AJ6:AS6,"B"),2,IF(COUNTIF(AJ6:AS6,"A"),1,0)))))) -> 2 | AU6: =IF(AT6=0,"",INDEX({"A","B","C","D","E","F"},AT6)) -> B | AV6: =COUNTIF(AJ6:AS6,"Sem regra") -> 0 | AW6: =IF(OR(AU6="",AU6="A"),"—",SUBSTITUTE(INDEX($AJ$4:$AS$4,MATCH(AU6,AJ6:AS6,0)),"Classe_","")) -> Cor | AX6: =IF(AU6="A","Sem ação — manter o design.",IFERROR(INDEX(tbl_regras_dfr[Recomendacao],MATCH(CHOOSE(MATCH(AU6,AJ6:AS6,0),L6&"|Fluxo de reciclagem|"&L6,L6&"|Cor do corpo|"&O6,L6&"|Densidade do corpo|"&IF(R6<1,"< 1,0 g/cm³","≥ 1,0 g/cm³"),L6&"|Barreira / revestimento|"&S6,L6&"|Material da tampa|"&X6,L6&"|Vedante / liner|"&Z6,L6&"|Tipo de rótulo|"&AA6,L6&"|Adesivo do rótulo|"&AB6,L6&"|Cobertura do rótulo|"&IF(AC6>0.7,"> 70% da superfície","≤ 70% da superfície"),L6&"|Decoração direta|"&AH6),tbl_regras_dfr[Chave],0)),"")) -> Preferir natural, branco ou cores claras. | AY6: =T6+Y6+AD6+AI6 -> 36.36 | AZ6: =MIN(IFERROR(INDEX(tbl_regras_dfr[Fracao_Reciclavel],MATCH(L6&"|Fluxo de reciclagem|"&L6,tbl_regras_dfr[Chave],0)),0),IFERROR(INDEX(tbl_regras_dfr[Fracao_Reciclavel],MATCH(L6&"|Cor do corpo|"&O6,tbl_regras_dfr[Chave],0)),0)) -> 1 | BA6: =IFERROR(INDEX(tbl_regras_dfr[Fracao_Reciclavel],MATCH(L6&"|Material da tampa|"&X6,tbl_regras_dfr[Chave],0)),0) -> 1 | BB6: =IFERROR(INDEX(tbl_regras_dfr[Fracao_Reciclavel],MATCH(L6&"|Tipo de rótulo|"&AA6,tbl_regras_dfr[Chave],0)),0) -> 1 | BC6: =AZ6*(T6+Y6*BA6+AD6*BB6) -> 36.36 | BD6: =IFERROR(BC6/AY6,0) -> 1 | BE6: =IF(BD6>=INDEX(tbl_param_emb[Valor],MATCH("P-06",tbl_param_emb[ID_Parametro],0)),"A",IF(BD6>=INDEX(tbl_param_emb[Valor],MATCH("P-07",tbl_param_emb[ID_Parametro],0)),"B",IF(BD6>=INDEX(tbl_param_emb[Valor],MATCH("P-08",tbl_param_emb[ID_Parametro],0)),"C","< 70%"))) -> A | BF6: =IF(AU6="F","Não reciclável (F)",INDEX({"A","B","C","Abaixo de C"},MAX(MIN(AT6,4),IF(BE6="A",1,IF(BE6="B",2,IF(BE6="C",3,4)))))) -> B | BG6: =IF(D6="Farmacêutico","Isento até 2035","—") -> — | BH6: =IF(BG6<>"—",BG6,IF(OR(BF6="A",BF6="B",BF6="C"),"Sim","Não")) -> Sim | BI6: =IF(BG6<>"—",BG6,IF(OR(BF6="A",BF6="B"),"Sim","Não")) -> Sim | BJ6: =IFERROR(INDEX(tbl_materiais[Pct_PCR],MATCH(J6,tbl_materiais[Material],0)),0) -> 0.3 | BK6: =IF(V6="",0,IFERROR(INDEX(tbl_tampas[Pct_PCR],MATCH(V6,tbl_tampas[CapId],0)),0)) -> 0.3 | BL6: =IFERROR((T6*BJ6+Y6*BK6)/(T6+Y6),0) -> 0.3 | BM6: =IF(D6="Farmacêutico","Isenta — medicamentos (art. 7.º)",IF(D6="Alimentar",IF(K6="PET","Sensível ao contacto — PET","Sensível ao contacto — outros plásticos"),"Outras embalagens de plástico")) -> Outras embalagens de plástico | BN6: =IFERROR(IF(INDEX(tbl_metas_art7[Meta_2030],MATCH(BM6,tbl_metas_art7[Categoria_Art7],0))="","",INDEX(tbl_metas_art7[Meta_2030],MATCH(BM6,tbl_metas_art7[Categoria_Art7],0))),"") -> 0.35 | BO6: =IF(BN6="","",MAX(0,BN6-BL6)) -> 0.05 | BP6: =IF(BN6="","Isento",IF(BO6=0,"Sim","Não")) -> Não | BQ6: =IF(AND(OR(X6=K6,X6="Sem tampa",AND(OR(X6="PE",X6="PP"),OR(K6="PE",K6="PP"))),OR(AA6="Sem rótulo",AND(ISNUMBER(SEARCH("PE/PP",AA6)),OR(K6="PE",K6="PP")))),"Monomaterial (mesma família)","Multimaterial") -> Monomaterial (mesma família) | BR6: 1236361 | BS6: 14 | BT6: DE; ES; FR; IT; PL; PT | BU6: =BR6*T6/1000 -> 27199.942 | BV6: =COUNTIFS(tbl_aplicabilidade[ProductId],B6,tbl_aplicabilidade[Aplicavel],"Sim") -> 12 | BW6: =COUNTIFS(tbl_aplicabilidade[ProductId],B6,tbl_aplicabilidade[Estado_Resumo],"Lacuna")+COUNTIFS(tbl_aplicabilidade[ProductId],B6,tbl_aplicabilidade[Estado_Resumo],"Não conforme") -> 1 | BX6: 46287 | BY6: =EDATE(BX6,12) -> 46652 | BZ6: Responsável de R&D | CA6: Autoavaliação (não certificada) | CB6: Regras simplificadas SGA-20 v1 (diretrizes DfR RecyClass) — confirmar na ferramenta online
A7: RCA-003 | B7: FR-001-HDPE-PCR-300 | C7: Frasco | D7: Cosmética e higiene pessoal | E7: Contacto direto com cosmético/higiene | F7: Injeção-sopro (ISBM) | G7: FAM-02 | H7: 300 | I7: 115 | J7: HDPE-PCR | K7: =IFERROR(INDEX(tbl_materiais[Polimero_Base],MATCH(J7,tbl_materiais[Material],0)),"") -> PE | L7: =IFERROR(INDEX(tbl_materiais[Fluxo_Reciclagem],MATCH(J7,tbl_materiais[Material],0)),"") -> PE rígido | M7: =IF(L7="PE rígido","PE rígido — frascos e contentores (HDPE/LDPE)",IF(L7="PP rígido","PP rígido — frascos, potes e contentores",IF(L7="PET frascos e garrafas",IF(O7="Natural / incolor","PET — garrafas/frascos transparentes incolores","PET — garrafas/frascos coloridos ou opacos"),"Sem categoria RecyClass ("&K7&")"))) -> PE rígido — frascos e contentores (HDPE/LDPE) | N7: Cardinal Red | O7: Colorido (claro ou transparente) | P7: Red Masterbatch | Q7: 0.02 | R7: =IFERROR(ROUND(INDEX(tbl_materiais[Densidade_g_cm3],MATCH(J7,tbl_materiais[Material],0))+Q7*1.2,3),"") -> 0.984 | S7: Nenhuma | T7: 22 | U7: Estimada (22 g a 300 ml, escala ^2/3) | V7: TR-001-PP-PCR-24410 | W7: =IF(V7="","",IFERROR(INDEX(tbl_tampas[Material],MATCH(V7,tbl_tampas[CapId],0)),"")) -> PP-PCR | X7: =IF(V7="","Sem tampa",IFERROR(INDEX(tbl_materiais[Polimero_Base],MATCH(W7,tbl_materiais[Material],0)),"")) -> PP | Y7: =IF(V7="",0,IFERROR(INDEX(tbl_tampas[Massa_g],MATCH(V7,tbl_tampas[CapId],0)),0)) -> 10.3 | Z7: Sem vedante | AA7: Autoadesivo PE/PP | AB7: Acrílico permanente | AC7: 0.4 | AD7: 0.46 | AE7: Cenário típico do cliente — confirmar especificação | AF7: Nenhuma | AG7: 0 | AH7: =IF(AF7="Serigrafia",IF(AG7>=3,"Serigrafia ≥ 3 cores","Serigrafia 1–2 cores"),AF7) -> Nenhuma | AI7: 0 | AJ7: =IFERROR(INDEX(tbl_regras_dfr[Classe],MATCH(L7&"|Fluxo de reciclagem|"&L7,tbl_regras_dfr[Chave],0)),"Sem regra") -> A | AK7: =IF(LEFT(L7,9)="Sem fluxo","—",IFERROR(INDEX(tbl_regras_dfr[Classe],MATCH(L7&"|Cor do corpo|"&O7,tbl_regras_dfr[Chave],0)),"Sem regra")) -> B | AL7: =IF(LEFT(L7,9)="Sem fluxo","—",IFERROR(INDEX(tbl_regras_dfr[Classe],MATCH(L7&"|Densidade do corpo|"&IF(R7<1,"< 1,0 g/cm³","≥ 1,0 g/cm³"),tbl_regras_dfr[Chave],0)),"Sem regra")) -> A | AM7: =IF(LEFT(L7,9)="Sem fluxo","—",IFERROR(INDEX(tbl_regras_dfr[Classe],MATCH(L7&"|Barreira / revestimento|"&S7,tbl_regras_dfr[Chave],0)),"Sem regra")) -> A | AN7: =IF(LEFT(L7,9)="Sem fluxo","—",IFERROR(INDEX(tbl_regras_dfr[Classe],MATCH(L7&"|Material da tampa|"&X7,tbl_regras_dfr[Chave],0)),"Sem regra")) -> A | AO7: =IF(LEFT(L7,9)="Sem fluxo","—",IFERROR(INDEX(tbl_regras_dfr[Classe],MATCH(L7&"|Vedante / liner|"&Z7,tbl_regras_dfr[Chave],0)),"Sem regra")) -> A | AP7: =IF(LEFT(L7,9)="Sem fluxo","—",IFERROR(INDEX(tbl_regras_dfr[Classe],MATCH(L7&"|Tipo de rótulo|"&AA7,tbl_regras_dfr[Chave],0)),"Sem regra")) -> A | AQ7: =IF(LEFT(L7,9)="Sem fluxo","—",IFERROR(INDEX(tbl_regras_dfr[Classe],MATCH(L7&"|Adesivo do rótulo|"&AB7,tbl_regras_dfr[Chave],0)),"Sem regra")) -> A | AR7: =IF(LEFT(L7,9)="Sem fluxo","—",IFERROR(INDEX(tbl_regras_dfr[Classe],MATCH(L7&"|Cobertura do rótulo|"&IF(AC7>0.7,"> 70% da superfície","≤ 70% da superfície"),tbl_regras_dfr[Chave],0)),"Sem regra")) -> A | AS7: =IF(LEFT(L7,9)="Sem fluxo","—",IFERROR(INDEX(tbl_regras_dfr[Classe],MATCH(L7&"|Decoração direta|"&AH7,tbl_regras_dfr[Chave],0)),"Sem regra")) -> A | AT7: =IF(COUNTIF(AJ7:AS7,"F"),6,IF(COUNTIF(AJ7:AS7,"E"),5,IF(COUNTIF(AJ7:AS7,"D"),4,IF(COUNTIF(AJ7:AS7,"C"),3,IF(COUNTIF(AJ7:AS7,"B"),2,IF(COUNTIF(AJ7:AS7,"A"),1,0)))))) -> 2 | AU7: =IF(AT7=0,"",INDEX({"A","B","C","D","E","F"},AT7)) -> B | AV7: =COUNTIF(AJ7:AS7,"Sem regra") -> 0 | AW7: =IF(OR(AU7="",AU7="A"),"—",SUBSTITUTE(INDEX($AJ$4:$AS$4,MATCH(AU7,AJ7:AS7,0)),"Classe_","")) -> Cor | AX7: =IF(AU7="A","Sem ação — manter o design.",IFERROR(INDEX(tbl_regras_dfr[Recomendacao],MATCH(CHOOSE(MATCH(AU7,AJ7:AS7,0),L7&"|Fluxo de reciclagem|"&L7,L7&"|Cor do corpo|"&O7,L7&"|Densidade do corpo|"&IF(R7<1,"< 1,0 g/cm³","≥ 1,0 g/cm³"),L7&"|Barreira / revestimento|"&S7,L7&"|Material da tampa|"&X7,L7&"|Vedante / liner|"&Z7,L7&"|Tipo de rótulo|"&AA7,L7&"|Adesivo do rótulo|"&AB7,L7&"|Cobertura do rótulo|"&IF(AC7>0.7,"> 70% da superfície","≤ 70% da superfície"),L7&"|Decoração direta|"&AH7),tbl_regras_dfr[Chave],0)),"")) -> Preferir natural, branco ou cores claras. | AY7: =T7+Y7+AD7+AI7 -> 32.76 | AZ7: =MIN(IFERROR(INDEX(tbl_regras_dfr[Fracao_Reciclavel],MATCH(L7&"|Fluxo de reciclagem|"&L7,tbl_regras_dfr[Chave],0)),0),IFERROR(INDEX(tbl_regras_dfr[Fracao_Reciclavel],MATCH(L7&"|Cor do corpo|"&O7,tbl_regras_dfr[Chave],0)),0)) -> 1 | BA7: =IFERROR(INDEX(tbl_regras_dfr[Fracao_Reciclavel],MATCH(L7&"|Material da tampa|"&X7,tbl_regras_dfr[Chave],0)),0) -> 1 | BB7: =IFERROR(INDEX(tbl_regras_dfr[Fracao_Reciclavel],MATCH(L7&"|Tipo de rótulo|"&AA7,tbl_regras_dfr[Chave],0)),0) -> 1 | BC7: =AZ7*(T7+Y7*BA7+AD7*BB7) -> 32.76 | BD7: =IFERROR(BC7/AY7,0) -> 1 | BE7: =IF(BD7>=INDEX(tbl_param_emb[Valor],MATCH("P-06",tbl_param_emb[ID_Parametro],0)),"A",IF(BD7>=INDEX(tbl_param_emb[Valor],MATCH("P-07",tbl_param_emb[ID_Parametro],0)),"B",IF(BD7>=INDEX(tbl_param_emb[Valor],MATCH("P-08",tbl_param_emb[ID_Parametro],0)),"C","< 70%"))) -> A | BF7: =IF(AU7="F","Não reciclável (F)",INDEX({"A","B","C","Abaixo de C"},MAX(MIN(AT7,4),IF(BE7="A",1,IF(BE7="B",2,IF(BE7="C",3,4)))))) -> B | BG7: =IF(D7="Farmacêutico","Isento até 2035","—") -> — | BH7: =IF(BG7<>"—",BG7,IF(OR(BF7="A",BF7="B",BF7="C"),"Sim","Não")) -> Sim | BI7: =IF(BG7<>"—",BG7,IF(OR(BF7="A",BF7="B"),"Sim","Não")) -> Sim | BJ7: =IFERROR(INDEX(tbl_materiais[Pct_PCR],MATCH(J7,tbl_materiais[Material],0)),0) -> 0.3 | BK7: =IF(V7="",0,IFERROR(INDEX(tbl_tampas[Pct_PCR],MATCH(V7,tbl_tampas[CapId],0)),0)) -> 0.3 | BL7: =IFERROR((T7*BJ7+Y7*BK7)/(T7+Y7),0) -> 0.3 | BM7: =IF(D7="Farmacêutico","Isenta — medicamentos (art. 7.º)",IF(D7="Alimentar",IF(K7="PET","Sensível ao contacto — PET","Sensível ao contacto — outros plásticos"),"Outras embalagens de plástico")) -> Outras embalagens de plástico | BN7: =IFERROR(IF(INDEX(tbl_metas_art7[Meta_2030],MATCH(BM7,tbl_metas_art7[Categoria_Art7],0))="","",INDEX(tbl_metas_art7[Meta_2030],MATCH(BM7,tbl_metas_art7[Categoria_Art7],0))),"") -> 0.35 | BO7: =IF(BN7="","",MAX(0,BN7-BL7)) -> 0.05 | BP7: =IF(BN7="","Isento",IF(BO7=0,"Sim","Não")) -> Não | BQ7: =IF(AND(OR(X7=K7,X7="Sem tampa",AND(OR(X7="PE",X7="PP"),OR(K7="PE",K7="PP"))),OR(AA7="Sem rótulo",AND(ISNUMBER(SEARCH("PE/PP",AA7)),OR(K7="PE",K7="PP")))),"Monomaterial (mesma família)","Multimaterial") -> Monomaterial (mesma família) | BR7: 423949 | BS7: 14 | BT7: DE; ES; FR; IT; PL; PT | BU7: =BR7*T7/1000 -> 9326.878 | BV7: =COUNTIFS(tbl_aplicabilidade[ProductId],B7,tbl_aplicabilidade[Aplicavel],"Sim") -> 12 | BW7: =COUNTIFS(tbl_aplicabilidade[ProductId],B7,tbl_aplicabilidade[Estado_Resumo],"Lacuna")+COUNTIFS(tbl_aplicabilidade[ProductId],B7,tbl_aplicabilidade[Estado_Resumo],"Não conforme") -> 1 | BX7: 46287 | BY7: =EDATE(BX7,12) -> 46652 | BZ7: Responsável de R&D | CA7: Autoavaliação (não certificada) | CB7: Regras simplificadas SGA-20 v1 (diretrizes DfR RecyClass) — confirmar na ferramenta online
