Workbook
Name AcaoOport: Critérios!$E$25:$E$28
Name AcaoRisco: Critérios!$D$25:$D$28
Name ApetIdx: Critérios!$I$50:$I$56
Name AudArea: Maturidade_Auditoria!$C$73:$C$80
Name AudData: Maturidade_Auditoria!$B$73:$B$80
Name AudIds: Maturidade_Auditoria!$A$73:$A$80
Name AudPct: Maturidade_Auditoria!$M$73:$M$80
Name BtEf: BowTie!$G$7:$G$86
Name BtId: BowTie!$A$7:$A$86
Name BtSit: BowTie!$N$7:$N$86
Name Ciclo_Atual: Maturidade_Auditoria!$B$5
Name CovMin: Maturidade_Auditoria!$B$9
Name DiasAlerta: Critérios!$C$17
Name FreqDias: Critérios!$N$71:$N$79
Name GrauAud: Maturidade_Auditoria!$C$152:$C$156
Name GrauMin: Maturidade_Auditoria!$E$152:$E$156
Name GrauNome: Maturidade_Auditoria!$A$152:$A$156
Name IdxExige: Critérios!$C$21
Name KriChaves: KRI!$A$7:$A$66
Name KriHoriz: KRI!$E$3
Name KriId: KRI!$B$7:$B$66
Name KriSit: KRI!$R$7:$R$66
Name Limites: Critérios!$C$25:$C$28
Name ListaAcaoOport: Critérios!$E$71:$E$78
Name ListaAcaoRisco: Critérios!$D$71:$D$76
Name ListaAlinh: Critérios!$L$71:$L$73
Name ListaAreas: Critérios!$B$71:$B$90
Name ListaCatOport: Critérios!$B$61:$B$67
Name ListaCatRisco: Critérios!$B$50:$B$56
Name ListaConf: Critérios!$I$71:$I$73
Name ListaEficacia: Critérios!$C$71:$C$74
Name ListaFacil: Critérios!$J$71:$J$73
Name ListaFreq: Critérios!$M$71:$M$79
Name ListaOrigem: Critérios!L71C6:L90C6
Name ListaPartes: Critérios!L71C20:L86C20
Name ListaReducao: Critérios!$K$71:$K$73
Name ListaStatus: Critérios!$G$71:$G$74
Name ListaTipoCtrl: Critérios!$Q$71:$Q$75
Name ListaTipoRisco: Critérios!$H$71:$H$74
Name ListaVeloc: Critérios!$O$71:$O$74
Name ListaVolat: Critérios!$P$71:$P$73
Name LstCrit: Maturidade_Auditoria!$B$175:$B$177
Name LstEficacia: Maturidade_Auditoria!$E$175:$E$178
Name LstMetodo: Maturidade_Auditoria!$D$175:$D$179
Name LstResultado: Maturidade_Auditoria!$C$175:$C$178
Name LstTeste: Maturidade_Auditoria!$A$175:$A$177
Name MatGrau: Maturidade_Auditoria!$B$13
Name MesesRev: Critérios!$H$25:$H$28
Name MetaGrau: Maturidade_Auditoria!$B$8
Name MinIdx: Critérios!$C$20
Name MonSit: Monitoramento!$L$5:$L$64
Name Niveis: Critérios!$B$25:$B$28
Name OportId: Oportunidades!$A$5:$A$154
Name PlanosAbertura: Planos!$I$7:$I$296
Name PlanosCod: Planos!$A$7:$A$296
Name PlanosIdRef: Planos!$B$7:$B$296
Name PlanosPrazo: Planos!$F$7:$F$296
Name PlanosStatus: Planos!$G$7:$G$296
Name PlanoUrl: Critérios!$C$18
Name ProbMedia: Critérios!$R$71:$R$75

Sheet 00_LEIA-ME
A1: RG-SGA-02 — Gestão de Riscos e Oportunidades — registo corporativo multiárea com a matriz do SGA
A2: Sistema de Gestão Ambiental NP EN ISO 14001:2026 · Plasticom — Unidade 1 (Marinha Grande, Portugal) · ficheiro gestao-riscos-oportunidades-v3.6-Plasticom.xlsx (fábrica simulada)
A4: CONTROLO DO DOCUMENTO (7.5 — informação documentada)
A5: Código do registo | B5: RG-SGA-02 (registo corporativo: REG-RISCOS-01 / REG-OPORT-01)
A6: Título | B6: Gestão de Riscos e Oportunidades — Identificação, Avaliação, Tratamento e Monitorização
A7: Versão / Revisão | B7: 02 — integra a Matriz_RO e os critérios do SGA (antes aba própria) e consolida abas
A8: Data de emissão | B8: 46289
A9: Elaborado por | B9: Gestor(a) do SGA / EHS
A10: Aprovado por | B10: Diretor Geral
A11: Estado | B11: Em vigor
A12: Retenção | B12: 5 anos após substituição
A13: Localização | B13: Repositório controlado do SGA > SGA_Sistema-de-gestao-ambiental (versão eletrónica é a versão controlada; cópias impressas são não controladas)
A15: FINALIDADE E ÂMBITO
A16: Finalidade | B16: Registo único de riscos (ameaças) e oportunidades da Plasticom — qualidade, SST, ambiente e negócio. Todos os itens usam a escala 5×5 (probabilidade × impacto/benefício). Os itens do SGA (ISO 14001) têm ainda a avaliação do curso no grupo de colunas 'METODOLOGIA SGA' (Nível = P × S; P 1 a 3; S −1 a −3 para riscos e 1 a 3 para oportunidades), com a decisão e a ação de tratamento.
A17: Atividades do curso | B17: Atividade 3.1 — Aplicação da Matriz de Riscos e Planeamento de Ações: filtrar 'Selecionado Atividade 3.1' = Sim (4 itens da SWOT: RO-01 a RO-04).
A18: Requisitos ISO 14001:2026 | B18: 6.1.1; 6.1.4 Riscos e oportunidades; 6.1.5 Planeamento de ações (numeração ISO 14001:2026)
A19: Itens do SGA migrados | B19: Riscos: RO-02 = R35; RO-05 = R36; RO-07 = R37; RO-08 = R38; RO-12 = R39; consolidados em riscos já existentes: RO-04 = R34; RO-06 = R33; RO-10 = R30. Oportunidades: RO-09 = O15; consolidadas em oportunidades já existentes: RO-01 = O3; RO-03 = O5; RO-11 = O10. O ID original fica na coluna 'ID RO (SGA)'. O risco inerente dos itens novos é simulado (validar).
A21: ESTRUTURA DO FICHEIRO (16 abas)
A22: Riscos | B22: tbRiscos — registo de riscos: identificação, inerente, controlos, risco atual, tratamento, plano, eficácia, residual, monitorização, custo-benefício e, à direita, o grupo METODOLOGIA SGA.
A23: Oportunidades | B23: tbOportunidades — registo de oportunidades: potencial, portfólio, decisão, plano, resultado, retorno e o grupo METODOLOGIA SGA.
A24: Painel | B24: Visão consolidada (calculada): mapas de calor, alertas, planos, KRI e BowTie.
A25: Planos | B25: tbPlanos — espelho dos planos de ação / RNC (PAC ou RNC + nº) ligados por código aos riscos e oportunidades.
A26: KRI | B26: tbKRI — cadastro dos indicadores de risco: limite, sentido, tendência e situação (calculada).
A27: KRI_Coletas | B27: tbKRIColetas — medições dos KRI em formato longo (1 linha = 1 medição).
A28: BowTie | B28: tbBowTie — barreiras preventivas e reativas por risco, eficácia e fatores de intensificação.
A29: Monitoramento | B29: tbMonitoramento — rotinas de monitorização, comunicação e consulta por nível.
A30: Politica_Apetite | B30: Política de gestão de riscos e apetite ao risco (§1). O contexto (PESTEL, SWOT, partes interessadas, 5 forças, TOWS) regista-se só no RG-SGA-01 desde 24/09/2026. Ações ambientais: só no PAM (RG-SGA-06), ligadas pela coluna 'Cód. PAM (RG-SGA-06)'.
A31: Maturidade_Auditoria | B31: Avaliação do processo de gestão de riscos (calculada): A) Maturidade (linha 1), B) Auditoria — tbAuditorias (linha 68), C) Plano ABR — tbPlanoABR (linha 104), D) Guia de avaliação (linha 139). Substitui as abas Maturidade, Auditoria, Plano ABR e Guia_Avaliação.
A32: Maturidade_Registro | B32: tbMat — avaliação de maturidade por critério e ciclo (4 testes de evidência).
A33: Auditoria_Registro | B33: tbAud — constatações de auditoria (1 linha = 1 pergunta avaliada).
... A36: Dicionário_Dados | B36: tbDicionario — uma linha por campo de cada tabela: tipo, formato, valores permitidos e descrição.
A38: CONVENÇÕES (prontas para análise de dados e machine learning)
A39: Tabelas | B39: Cada registo é uma Tabela Excel com nome próprio (tb*): uma linha = um registo, cabeçalho único. Ler com Power BI/Power Query (Obter Dados > Tabela) ou com pandas: Riscos e Oportunidades têm o cabeçalho na linha 4 (pd.read_excel(ficheiro, sheet_name='Riscos', header=3)). As tabelas têm linhas de reserva vazias: filtrar pelo ID não vazio.
A40: Texto azul / fundo cinzento | B40: Azul = entrada; cabeçalho laranja e fundo cinzento = coluna CALCULADA por fórmula (não escrever por cima).
A41: Validação | B41: Colunas com lista controlada só aceitam valores das listas em Critérios (evita categorias duplicadas por grafia diferente).
A42: Chaves | B42: ID (R1…, O1…) é a chave primária; 'ID RO (SGA)' liga ao SGA (RG-SGA-01 contexto, RG-SGA-06 PAM); campos com vários IDs usam ';' — ver SGA-00_Indice_Modelo_Dados.xlsx.
A43: Segmentação | B43: Para filtrar só o SGA: filtro ou segmentação de dados (Tabela > Inserir Segmentação) em 'ID RO (SGA)' não vazio, 'Significância SGA' ou 'Selecionado Atividade 3.1'.
A44: Datas e unidades | B44: Datas em formato data (aaaa-mm-dd); números como números; a unidade está no nome da coluna ou no dicionário.
A45: Dados simulados | B45: Fábrica simulada Plasticom. Dados operacionais derivados do dataset do projeto (datasets/silver); dados ambientais e de conformidade são simulação didática — confirmar aplicabilidade legal e números antes de uso real.
A47: LIGAÇÕES A OUTROS REGISTOS
...

Sheet Riscos
A1: REGISTRO DE RISCOS (AMEAÇAS) — FÁBRICA, USO MULTIÁREA | L1: Registros da Plasticom (fábrica simulada; dados do raio-X analítico) | Texto AZUL = preencher | Fundo CINZA = fórmula (não editar) | Código do plano: PAC 202601 ou RNC 202601 | Passe o mouse nos cabeçalhos: instruções por coluna | Use os botões [–] acima das colunas para recolher blocos
A2: Unidade / fábrica | D2: Plasticom — Unidade 1 (Portugal) | E2: Escopo / período | G2: Todas as áreas — jul/2025 a dez/2026 | I2: Responsável | J2: Coordenação do SGI | L2: Versão | N2: 1/2026 | P2: Atualizado em | R2: 46387 | U2: Cód. documento | W2: REG-RISCOS-01 | Y2: Aprovado por / em | AA2: Direção — 22/12/2026
A3: IDENTIFICAÇÃO | N3: INERENTE (sem considerar controles) | R3: CONTROLES EXISTENTES | T3: RISCO ATUAL (com os controles existentes) | Y3: TRATAMENTO | AI3: VÍNCULO PLANO / RNC | AM3: EFICÁCIA | AP3: RESIDUAL (após o tratamento) | AU3: MONITORAMENTO, REVISÃO E ALERTA | BA3: OUTROS | BD3: COMPLEMENTOS (velocidade, controle, custo-benefício e continuidade) | BM3: METODOLOGIA SGA — ISO 14001:2026 (curso UC00557 · Nível = P × S, escala 3×3; critérios em Critérios › Metodologia do SGA)
A4: ID | B4: Área / processo responsável | C4: Descrição do risco | D4: Origem | E4: Tipo de risco | F4: Nível de análise | G4: Objetivo afetado | H4: Situação vs. análise anterior | I4: Parte interessada afetada | J4: Causa | K4: Causa (6M) | L4: Consequência (impacto) | M4: Categoria de impacto | N4: Prob. inerente | O4: Imp. inerente | P4: Score inerente | Q4: Nível inerente | R4: Controles existentes | S4: Eficácia dos controles | T4: Prob. atual | U4: Imp. atual | V4: Score atual | W4: Nível atual | X4: Confiança da estimativa | Y4: Ação recomendada | Z4: Ação adotada | AA4: Hierarquia do controle principal | AB4: Aceite válido até | AC4: Resumo da ação | AD4: Dono do risco | AE4: Resp. da ação | AF4: Prazo (ação simples) | AG4: Status (ação simples) | AH4: Critério de eficácia (meta) | AI4: Cód. plano de ação / RNC | AJ4: Abrir plano (link) | AK4: Status atual | AL4: Prazo atual | AM4: Verificar eficácia em | AN4: Eficácia do tratamento | AO4: Data aval. eficácia | AP4: Prob. residual | AQ4: Imp. residual | AR4: Score residual | AS4: Nível residual | AT4: Residual aceitável? | AU4: Indicador (KRI) / gatilho de reavaliação | AV4: Ocorrências (últimos 12 meses) | AW4: Avaliado em | AX4: Avaliado por (equipe) | AY4: Próx. revisão | AZ4: Alerta | BA4: Justificativa / evidências / notas | BB4: Riscos / oport. relacionados (IDs) | BC4: Ordem (ranking) | BD4: Velocidade de impacto | BE4: Volatilidade da probabilidade | BF4: Tipo do controle principal | BG4: Custo estimado do tratamento (€) | BH4: Perda potencial se ocorrer (€) | BI4: Perda esperada (€) | BJ4: Leitura custo-benefício | BK4: MAO: parada máx. aceitável (horas) | BL4: Plano de contingência / continuidade (cód. ou link) | BM4: ID RO (SGA) | BN4: Data de identificação (SGA) | BO4: ID de origem (contexto SGA) | BP4: Selecionado Atividade 3.1 | BQ4: Área de gestão (SGA) | BR4: Processo (código SGA) | BS4: Tema (SGA) | BT4: Partes interessadas (SGA) | BU4: Probabilidade SGA | BV4: Severidade SGA | BW4: P (valor SGA) | BX4: S (valor SGA) | BY4: Nível SGA (P×S) | BZ4: Significância SGA | CA4: Aceitabilidade SGA | CB4: Decisão SGA | CC4: Tipo de ação SGA | CD4: Cód. PAM (RG-SGA-06) | CE4: Probabilidade SGA residual | CF4: Severidade SGA residual | CG4: Nível SGA residual | CH4: Significância SGA residual | CI4: Simulação forçada (Atv 3.1)
A5: R1 | B5: Sopro (ISBM) | C5: Instabilidade da espessura de parede na ISBM-003 gera frascos fora de especificação e lotes rejeitados/refeitos | D5: Análise de dados / raio-X analítico | E5: Técnico | F5: Operacional | G5: Cpk ≥ 1,33 nas características críticas | H5: Novo | I5: Clientes de cosmética (marcas UE) | J5: Programação do parison instável: dispersão de espessura (RangeR ≈ 3,0× as demais ISBM) com viés para ombro fino | K5: Máquina | L5: Rejeição e refação de lote (NC-01319), reclamações de frasco deformado/colapsado, custo de refugo e retrabalho | M5: Qualidade / Cliente | N5: 4 | O5: 4 | P5: =IF(COUNT($N5:$O5)=2,$N5*$O5,"") -> 16 | Q5: =IF($P5="","",INDEX(Niveis,MAX(IFERROR(MATCH($P5,Limites,1),1),IF($O5=5,MinIdx,1)))) -> Crítico | R5: Cartas X-barra/R por subgrupo; AQL por lote; inspeção de espessura por turno | S5: Média | T5: 4 | U5: 3 | V5: =IF(COUNT($T5:$U5)=2,$T5*$U5,"") -> 12 | W5: =IF($V5="","",INDEX(Niveis,MAX(IFERROR(MATCH($V5,Limites,1),1),IF($U5=5,MinIdx,1)))) -> Alto | X5: Alta | Y5: =IF(IF($W5<>"",$W5,$Q5)="","",INDEX(AcaoRisco,MATCH(IF($W5<>"",$W5,$Q5),Niveis,0))) -> Mitigar | Z5: Mitigar | AA5: Controle de engenharia | AC5: Verificar programação do parison, atuadores/sensores e cabeçote; comparar Cpk e RangeR antes/depois (RC-01) | AD5: Gerente de Produção | AE5: Eng. de Processo | AH5: RangeR ISBM-003 ≤ 1,3× a média das demais ISBM e Cpk ≥ 1,33 por 3 meses | AI5: PAC 202601 | AJ5: =IF(OR($AI5="",PlanoUrl=""),"",HYPERLINK(SUBSTITUTE(PlanoUrl,"{COD}",SUBSTITUTE($AI5," ","%20")),"↗")) | AK5: =IF($C5="","",IF($AI5="",$AG5&"",IFERROR(IF(INDEX(PlanosStatus,MATCH($AI5,PlanosCod,0))="",$AG5&"",INDEX(PlanosStatus,MATCH($AI5,PlanosCod,0))),$AG5&""))) -> Em andamento | AL5: =IF($C5="","",IF($AI5="",IF($AF5="","",$AF5),IFERROR(IF(INDEX(PlanosPrazo,MATCH($AI5,PlanosCod,0))="",IF($AF5="","",$AF5),INDEX(PlanosPrazo,MATCH($AI5,PlanosCod,0))),IF($AF5="","",$AF5)))) -> 46444 | AM5: 46538 | AP5: 2 | AQ5: 3 | AR5: =IF(COUNT($AP5:$AQ5)=2,$AP5*$AQ5,"") -> 6 | AS5: =IF($AR5="","",INDEX(Niveis,MAX(IFERROR(MATCH($AR5,Limites,1),1),IF($AQ5=5,MinIdx,1)))) -> Baixo | AT5: Sim | AU5: Razão RangeR espessura ISBM-003 ÷ demais ISBM (aba KRI) | AV5: 52 | AW5: 46371 | AX5: Comitê da Qualidade | AY5: =IF(OR($AW5="",IF(AND($AN5="Eficaz",$AS5<>""),$AS5,IF($W5<>"",$W5,$Q5))=""),"",EDATE($AW5,INDEX(MesesRev,MATCH(IF(AND($AN5="Eficaz",$AS5<>""),$AS5,IF($W5<>"",$W5,$Q5)),Niveis,0)))) -> 46461 | AZ5: =IF($C5="","",IF($AD5="","Sem dono",IF($W5="","Falta avaliação",IF(AND($AI5<>"",COUNTIF(PlanosCod,$AI5)=0),"Código não encontrado",IF(AND($AI5<>"",IFERROR(INDEX(PlanosIdRef,MATCH($AI5,PlanosCod,0))&"","")<>"",ISERROR(SEARCH(";"&$A5&";",";"&SUBSTITUTE(SUBSTITUTE(IFERROR(INDEX(PlanosIdRef,MATCH($AI5,PlanosCod,0))&"","")," ",""),",",";")&";"))),"Vínculo divergente",IF(AND(ISNUMBER($P5),ISNUMBER($V5),$V5<$P5,OR($S5="",$S5="Inexistente")),"Redução s/ controle",IF(AND(ISNUMBER($AR5),ISNUMBER($V5),$AR5<$V5,NOT(OR($Z5="Prevenir",$Z5="Mitigar",$Z5="Transferir / compartilhar")),$AC5="",$AI5=""),"Residual s/ tratamento",IF(AND(LEFT($AI5,3)="RNC",N(IFERROR(INDEX(PlanosAbertura,MATCH($AI5,PlanosCod,0)),0))>N($AW5)),"Reavaliar após RNC",IF(AND(N($AV5)>=1,ISNUMBER($T5),$T5<=2),"Recalibrar probabilidade",IF(AND($Z5="Aceitar",$BA5=""),"Aceite sem justificativa",IF(AND($Z5="Aceitar",ISNUMBER($AB5),$AB5<TODAY()),"Aceite vencido",IF(AND(OR($Z5="Aceitar",$Z5="Monitorar"),$Y5<>"Monitorar",$Y5<>""),"Aprovar aceite",IF(AND($Z5<>"Aceitar",$Z5<>"Monitorar",$Z5<>"Aprofundar análise",$AC5="",$AI5="",IFERROR(MATCH(IF($W5<>"",$W5,$Q5),Niveis,0),0)>IF(N(IFERROR(INDEX(ApetIdx,MATCH($M5,ListaCatRisco,0)),0))=0,IdxExige-1,INDEX(ApetIdx,MATCH($M5,ListaCatRisco,0)))),"Sem ação",IF($Z5="Aprofundar análise","Aprofundar análise",IF(AND(OR($Z5="Prevenir",$Z5="Mitigar",$Z5="Transferir / compartilhar"),$AH5=""),"Definir critério de eficácia",IF(AND(OR($Z5="Prevenir",$Z5="Mitigar",$Z5="Transferir / compartilhar"),OR($AA5="Controle administrativo",$AA5="EPI"),IFERROR(MATCH(IF($W5<>"",$W5,$Q5),Niveis,0),0)>=3),"Rever hierarquia de controle",IF(COUNTIFS(KriId,$A5,KriSit,"Estourou")+COUNTIFS(KriId,$A5,KriSit,"Atenção")>0,"KRI em alerta",IF(COUNTIFS(BtId,$A5,BtEf,"Baixa")+COUNTIFS(BtId,$A5,BtEf,"Inexistente")>0,"Barreira fraca",IF($AN5="Não eficaz","Ação ineficaz",IF(AND($AL5<>"",$AL5<TODAY(),$AK5<>"Concluído",$AK5<>"Cancelado"),"Ação vencida",IF(AND($AN5<>"Eficaz",OR($AK5="Concluído",AND(ISNUMBER($AM5),$AM5<TODAY()))),"Avaliar eficácia",IF(AND($AN5="Eficaz",OR($AS5="",$AT5="")),"Concluir residual",IF($AT5="Não","Tratamento adicional",IF(AND($AT5="Sim",$AS5<>"",IFERROR(MATCH($AS5,Niveis,0),0)>IF(N(IFERROR(INDEX(ApetIdx,MATCH($M5,ListaCatRisco,0)),0))=0,IdxExige-1,INDEX(ApetIdx,MATCH($M5,ListaCatRisco,0)))),"Aceite fora do apetite",IF(AND(COUNTIF(BtId,$A5)=0,OR(IFERROR(MATCH(IF($W5<>"",$W5,$Q5),Niveis,0),0)>=3,AND(OR($S5="Baixa",$S5="Inexistente"),IFERROR(MATCH(IF($W5<>"",$W5,$Q5),Niveis,0),0)>=2))),"Sem BowTie",IF(AND($AY5<>"",$AY5<TODAY()),"Revisão vencida",IF(AND($AL5<>"",N($AL5)-TODAY()<=DiasAlerta,$AK5<>"Concluído",$AK5<>"Cancelado"),"Vence em breve","OK"))))))))))))))))))))))))))) -> KRI em alerta | BA5: Evidência: RangeR ISBM-003 ≈ 3,0× pares (18 meses); rejeição da máquina 3,94% vs 2,4% da planta. Causa física a confirmar em campo (RC-01). | BB5: R2;R16 | BC5: =IF($V5="","",1+COUNTIF($V$5:$V$154,">"&$V5)+COUNTIFS($V$5:$V$154,$V5,$U$5:$U$154,">"&$U5)+COUNTIFS($V$4:$V4,$V5,$U$4:$U4,$U5)) -> 7 | BD5: Média — semanas | BE5: Moderada | BF5: Detectivo | BG5: 18000 | BH5: 45000 | BI5: =IF(OR($BH5="",$T5=""),"",IFERROR($BH5*INDEX(ProbMedia,$T5),"")) -> 31500 | BJ5: =IF(OR($BG5="",$BI5=""),"",IF(OR(LEFT($M5,3)="SST",LEFT($M5,5)="Legal",LEFT($M5,8)="Ambienta"),"SST/Ambiental/Legal: custo não justifica aceitar (apetite e ALARP)",IF($BG5>$BI5,"Custo maior que a perda esperada: reter/aceitar é defensável, com justificativa","Custo menor ou igual à perda esperada: tratar compensa"))) -> Custo menor ou igual à perda esperada: tratar compensa | BW5: =IF($BU5="","",IFERROR(INDEX(SgaProbValor,MATCH($BU5,SgaProbNivel,0)),"")) | BX5: =IF($BV5="","",IFERROR(INDEX(SgaSevRiValor,MATCH($BV5,SgaSevRiNivel,0)),"")) | BY5: =IF(COUNT($BW5:$BX5)=2,$BW5*$BX5,"") | BZ5: =IF($BY5="","",IF($BY5<=SgaLimRiSig,"SIGNIFICATIVO",IF($BY5<=SgaLimRiTol,"TOLERÁVEL","BAIXO"))) | CA5: =IF($BZ5="","",IF($BZ5="SIGNIFICATIVO","NÃO ACEITÁVEL","ACEITÁVEL")) | CG5: =IF(OR($CE5="",$CF5=""),"",IFERROR(INDEX(SgaProbValor,MATCH($CE5,SgaProbNivel,0))*INDEX(SgaSevRiValor,MATCH($CF5,SgaSevRiNivel,0)),"")) | CH5: =IF($CG5="","",IF($CG5<=SgaLimRiSig,"SIGNIFICATIVO",IF($CG5<=SgaLimRiTol,"TOLERÁVEL","BAIXO")))
A6: R2 | B6: Sopro (ISBM) | C6: Desgaste acumulado do molde M-SOP-007 (ISBM-001) eleva Flash/Leakage até a reforma | D6: Análise de dados / raio-X analítico | E6: Técnico | F6: Operacional | G6: Taxa de rejeição ≤ 2,0% (baseline 2,39%) | H6: Mantido | I6: Clientes de cosmética (marcas UE) | J6: Desgaste do molde cresce com as unidades acumuladas; sem contador de ciclos desde a reforma, a ação ocorre só após o lote falhar | K6: Máquina | L6: Lote rejeitado/refeito (NC-01321), Flash e vazamento em frascos e reclamações | M6: Qualidade / Cliente | N6: 4 | O6: 4 | P6: =IF(COUNT($N6:$O6)=2,$N6*$O6,"") -> 16 | Q6: =IF($P6="","",INDEX(Niveis,MAX(IFERROR(MATCH($P6,Limites,1),1),IF($O6=5,MinIdx,1)))) -> Crítico | R6: Reforma do molde em 15/06/2026 (PAC 202604); inspeção AQL de Flash/Leakage por lote | S6: Média | T6: 3 | U6: 3 | V6: =IF(COUNT($T6:$U6)=2,$T6*$U6,"") -> 9 | W6: =IF($V6="","",INDEX(Niveis,MAX(IFERROR(MATCH($V6,Limites,1),1),IF($U6=5,MinIdx,1)))) -> Médio | X6: Alta | Y6: =IF(IF($W6<>"",$W6,$Q6)="","",INDEX(AcaoRisco,MATCH(IF($W6<>"",$W6,$Q6),Niveis,0))) -> Mitigar | Z6: Mitigar | AA6: Controle de engenharia | AC6: Criar contador CiclosDesdeReforma com limite de alerta/ação e inspeção por condição (RC-12) | AD6: Gerente de Manutenção | AE6: Eng. de Manutenção | AH6: Nenhum lote rejeitado por Flash/Leakage no M-SOP-007 por 6 meses; reforma acionada por condição | AI6: PAC 202605 | AJ6: =IF(OR($AI6="",PlanoUrl=""),"",HYPERLINK(SUBSTITUTE(PlanoUrl,"{COD}",SUBSTITUTE($AI6," ","%20")),"↗")) | AK6: =IF($C6="","",IF($AI6="",$AG6&"",IFERROR(IF(INDEX(PlanosStatus,MATCH($AI6,PlanosCod,0))="",$AG6&"",INDEX(PlanosStatus,MATCH($AI6,PlanosCod,0))),$AG6&""))) -> Aberto | AL6: =IF($C6="","",IF($AI6="",IF($AF6="","",$AF6),IFERROR(IF(INDEX(PlanosPrazo,MATCH($AI6,PlanosCod,0))="",IF($AF6="","",$AF6),INDEX(PlanosPrazo,MATCH($AI6,PlanosCod,0))),IF($AF6="","",$AF6)))) -> 46477 | AM6: 46568 | AP6: 2 | AQ6: 3 | AR6: =IF(COUNT($AP6:$AQ6)=2,$AP6*$AQ6,"") -> 6 | AS6: =IF($AR6="","",INDEX(Niveis,MAX(IFERROR(MATCH($AR6,Limites,1),1),IF($AQ6=5,MinIdx,1)))) -> Baixo | AT6: Sim | AU6: Unidades desde a reforma e defeitos Flash+Leakage por lote (aba KRI) | AV6: 21 | AW6: 46371 | AX6: Manutenção + Qualidade | AY6: =IF(OR($AW6="",IF(AND($AN6="Eficaz",$AS6<>""),$AS6,IF($W6<>"",$W6,$Q6))=""),"",EDATE($AW6,INDEX(MesesRev,MATCH(IF(AND($AN6="Eficaz",$AS6<>""),$AS6,IF($W6<>"",$W6,$Q6)),Niveis,0)))) -> 46553 | AZ6: =IF($C6="","",IF($AD6="","Sem dono",IF($W6="","Falta avaliação",IF(AND($AI6<>"",COUNTIF(PlanosCod,$AI6)=0),"Código não encontrado",IF(AND($AI6<>"",IFERROR(INDEX(PlanosIdRef,MATCH($AI6,PlanosCod,0))&"","")<>"",ISERROR(SEARCH(";"&$A6&";",";"&SUBSTITUTE(SUBSTITUTE(IFERROR(INDEX(PlanosIdRef,MATCH($AI6,PlanosCod,0))&"","")," ",""),",",";")&";"))),"Vínculo divergente",IF(AND(ISNUMBER($P6),ISNUMBER($V6),$V6<$P6,OR($S6="",$S6="Inexistente")),"Redução s/ controle",IF(AND(ISNUMBER($AR6),ISNUMBER($V6),$AR6<$V6,NOT(OR($Z6="Prevenir",$Z6="Mitigar",$Z6="Transferir / compartilhar")),$AC6="",$AI6=""),"Residual s/ tratamento",IF(AND(LEFT($AI6,3)="RNC",N(IFERROR(INDEX(PlanosAbertura,MATCH($AI6,PlanosCod,0)),0))>N($AW6)),"Reavaliar após RNC",IF(AND(N($AV6)>=1,ISNUMBER($T6),$T6<=2),"Recalibrar probabilidade",IF(AND($Z6="Aceitar",$BA6=""),"Aceite sem justificativa",IF(AND($Z6="Aceitar",ISNUMBER($AB6),$AB6<TODAY()),"Aceite vencido",IF(AND(OR($Z6="Aceitar",$Z6="Monitorar"),$Y6<>"Monitorar",$Y6<>""),"Aprovar aceite",IF(AND($Z6<>"Aceitar",$Z6<>"Monitorar",$Z6<>"Aprofundar análise",$AC6="",$AI6="",IFERROR(MATCH(IF($W6<>"",$W6,$Q6),Niveis,0),0)>IF(N(IFERROR(INDEX(ApetIdx,MATCH($M6,ListaCatRisco,0)),0))=0,IdxExige-1,INDEX(ApetIdx,MATCH($M6,ListaCatRisco,0)))),"Sem ação",IF($Z6="Aprofundar análise","Aprofundar análise",IF(AND(OR($Z6="Prevenir",$Z6="Mitigar",$Z6="Transferir / compartilhar"),$AH6=""),"Definir critério de eficácia",IF(AND(OR($Z6="Prevenir",$Z6="Mitigar",$Z6="Transferir / compartilhar"),OR($AA6="Controle administrativo",$AA6="EPI"),IFERROR(MATCH(IF($W6<>"",$W6,$Q6),Niveis,0),0)>=3),"Rever hierarquia de controle",IF(COUNTIFS(KriId,$A6,KriSit,"Estourou")+COUNTIFS(KriId,$A6,KriSit,"Atenção")>0,"KRI em alerta",IF(COUNTIFS(BtId,$A6,BtEf,"Baixa")+COUNTIFS(BtId,$A6,BtEf,"Inexistente")>0,"Barreira fraca",IF($AN6="Não eficaz","Ação ineficaz",IF(AND($AL6<>"",$AL6<TODAY(),$AK6<>"Concluído",$AK6<>"Cancelado"),"Ação vencida",IF(AND($AN6<>"Eficaz",OR($AK6="Concluído",AND(ISNUMBER($AM6),$AM6<TODAY()))),"Avaliar eficácia",IF(AND($AN6="Eficaz",OR($AS6="",$AT6="")),"Concluir residual",IF($AT6="Não","Tratamento adicional",IF(AND($AT6="Sim",$AS6<>"",IFERROR(MATCH($AS6,Niveis,0),0)>IF(N(IFERROR(INDEX(ApetIdx,MATCH($M6,ListaCatRisco,0)),0))=0,IdxExige-1,INDEX(ApetIdx,MATCH($M6,ListaCatRisco,0)))),"Aceite fora do apetite",IF(AND(COUNTIF(BtId,$A6)=0,OR(IFERROR(MATCH(IF($W6<>"",$W6,$Q6),Niveis,0),0)>=3,AND(OR($S6="Baixa",$S6="Inexistente"),IFERROR(MATCH(IF($W6<>"",$W6,$Q6),Niveis,0),0)>=2))),"Sem BowTie",IF(AND($AY6<>"",$AY6<TODAY()),"Revisão vencida",IF(AND($AL6<>"",N($AL6)-TODAY()<=DiasAlerta,$AK6<>"Concluído",$AK6<>"Cancelado"),"Vence em breve","OK"))))))))))))))))))))))))))) -> KRI em alerta | BA6: Defeitos Flash/Leakage por lote no M-SOP-007: pico de 1,68 em 2026-04, queda após a reforma de 15/06/2026 e nova subida lenta. Limite de ciclos provisório: calibrar pela curva defeito × ciclos. | BB6: R1;R19 | BC6: =IF($V6="","",1+COUNTIF($V$5:$V$154,">"&$V6)+COUNTIFS($V$5:$V$154,$V6,$U$5:$U$154,">"&$U6)+COUNTIFS($V$4:$V5,$V6,$U$4:$U5,$U6)) -> 21 | BD6: Média — semanas | BE6: Moderada | BF6: Preventivo | BG6: 25000 | BH6: 75000 | BI6: =IF(OR($BH6="",$T6=""),"",IFERROR($BH6*INDEX(ProbMedia,$T6),"")) -> 37500 | BJ6: =IF(OR($BG6="",$BI6=""),"",IF(OR(LEFT($M6,3)="SST",LEFT($M6,5)="Legal",LEFT($M6,8)="Ambienta"),"SST/Ambiental/Legal: custo não justifica aceitar (apetite e ALARP)",IF($BG6>$BI6,"Custo maior que a perda esperada: reter/aceitar é defensável, com justificativa","Custo menor ou igual à perda esperada: tratar compensa"))) -> Custo menor ou igual à perda esperada: tratar compensa | BW6: =IF($BU6="","",IFERROR(INDEX(SgaProbValor,MATCH($BU6,SgaProbNivel,0)),"")) | BX6: =IF($BV6="","",IFERROR(INDEX(SgaSevRiValor,MATCH($BV6,SgaSevRiNivel,0)),"")) | BY6: =IF(COUNT($BW6:$BX6)=2,$BW6*$BX6,"") | BZ6: =IF($BY6="","",IF($BY6<=SgaLimRiSig,"SIGNIFICATIVO",IF($BY6<=SgaLimRiTol,"TOLERÁVEL","BAIXO"))) | CA6: =IF($BZ6="","",IF($BZ6="SIGNIFICATIVO","NÃO ACEITÁVEL","ACEITÁVEL")) | CG6: =IF(OR($CE6="",$CF6=""),"",IFERROR(INDEX(SgaProbValor,MATCH($CE6,SgaProbNivel,0))*INDEX(SgaSevRiValor,MATCH($CF6,SgaSevRiNivel,0)),"")) | CH6: =IF($CG6="","",IF($CG6<=SgaLimRiSig,"SIGNIFICATIVO",IF($CG6<=SgaLimRiTol,"TOLERÁVEL","BAIXO")))
A7: R3 | B7: Sopro (ISBM) | C7: Paradas não planejadas recorrentes na ISBM-005 por envelhecimento hidráulico reduzem a disponibilidade | D7: Análise de dados / raio-X analítico | E7: Técnico | F7: Operacional | G7: OEE ≥ 81,1% e Disponibilidade ≥ 90% (baseline 79,1% / 87,4%) | H7: Novo | I7: Acionistas / Direção | J7: Envelhecimento do sistema hidráulico: frequência de paradas ≈ 2,3× a base; sem análise de condição por horas de operação | K7: Máquina | L7: Disponibilidade ≈ 80% (planta 87,4%), perda de capacidade e atraso de ordens; qualidade não é afetada | M7: Produção / Ativos | N7: 5 | O7: 3 | P7: =IF(COUNT($N7:$O7)=2,$N7*$O7,"") -> 15 | Q7: =IF($P7="","",INDEX(Niveis,MAX(IFERROR(MATCH($P7,Limites,1),1),IF($O7=5,MinIdx,1)))) -> Alto | R7: Manutenção preventiva calendarizada; reposição reativa de componentes | S7: Baixa | T7: 4 | U7: 3 | V7: =IF(COUNT($T7:$U7)=2,$T7*$U7,"") -> 12 | W7: =IF($V7="","",INDEX(Niveis,MAX(IFERROR(MATCH($V7,Limites,1),1),IF($U7=5,MinIdx,1)))) -> Alto | X7: Alta | Y7: =IF(IF($W7<>"",$W7,$Q7)="","",INDEX(AcaoRisco,MATCH(IF($W7<>"",$W7,$Q7),Niveis,0))) -> Mitigar | Z7: Mitigar | AA7: Controle de engenharia | AC7: Inspeção hidráulica, histórico de componentes críticos e plano por horas de operação (MTBF/MTTR) (RC-06) | AD7: Gerente de Manutenção | AE7: Eng. de Manutenção | AH7: Paradas não planejadas da ISBM-005 ≤ 80 h/mês e disponibilidade ≥ 85% por 3 meses | AI7: PAC 202611 | AJ7: =IF(OR($AI7="",PlanoUrl=""),"",HYPERLINK(SUBSTITUTE(PlanoUrl,"{COD}",SUBSTITUTE($AI7," ","%20")),"↗")) | AK7: =IF($C7="","",IF($AI7="",$AG7&"",IFERROR(IF(INDEX(PlanosStatus,MATCH($AI7,PlanosCod,0))="",$AG7&"",INDEX(PlanosStatus,MATCH($AI7,PlanosCod,0))),$AG7&""))) -> Em andamento | AL7: =IF($C7="","",IF($AI7="",IF($AF7="","",$AF7),IFERROR(IF(INDEX(PlanosPrazo,MATCH($AI7,PlanosCod,0))="",IF($AF7="","",$AF7),INDEX(PlanosPrazo,MATCH($AI7,PlanosCod,0))),IF($AF7="","",$AF7)))) -> 46461 | AM7: 46568 | AP7: 3 | AQ7: 3 | AR7: =IF(COUNT($AP7:$AQ7)=2,$AP7*$AQ7,"") -> 9 | AS7: =IF($AR7="","",INDEX(Niveis,MAX(IFERROR(MATCH($AR7,Limites,1),1),IF($AQ7=5,MinIdx,1)))) -> Médio | AT7: Sim | AU7: Horas de parada não planejada/mês na ISBM-005 (aba KRI) | AV7: 3946 | AW7: 46371 | AX7: Manutenção + Produção | AY7: =IF(OR($AW7="",IF(AND($AN7="Eficaz",$AS7<>""),$AS7,IF($W7<>"",$W7,$Q7))=""),"",EDATE($AW7,INDEX(MesesRev,MATCH(IF(AND($AN7="Eficaz",$AS7<>""),$AS7,IF($W7<>"",$W7,$Q7)),Niveis,0)))) -> 46461 | AZ7: =IF($C7="","",IF($AD7="","Sem dono",IF($W7="","Falta avaliação",IF(AND($AI7<>"",COUNTIF(PlanosCod,$AI7)=0),"Código não encontrado",IF(AND($AI7<>"",IFERROR(INDEX(PlanosIdRef,MATCH($AI7,PlanosCod,0))&"","")<>"",ISERROR(SEARCH(";"&$A7&";",";"&SUBSTITUTE(SUBSTITUTE(IFERROR(INDEX(PlanosIdRef,MATCH($AI7,PlanosCod,0))&"","")," ",""),",",";")&";"))),"Vínculo divergente",IF(AND(ISNUMBER($P7),ISNUMBER($V7),$V7<$P7,OR($S7="",$S7="Inexistente")),"Redução s/ controle",IF(AND(ISNUMBER($AR7),ISNUMBER($V7),$AR7<$V7,NOT(OR($Z7="Prevenir",$Z7="Mitigar",$Z7="Transferir / compartilhar")),$AC7="",$AI7=""),"Residual s/ tratamento",IF(AND(LEFT($AI7,3)="RNC",N(IFERROR(INDEX(PlanosAbertura,MATCH($AI7,PlanosCod,0)),0))>N($AW7)),"Reavaliar após RNC",IF(AND(N($AV7)>=1,ISNUMBER($T7),$T7<=2),"Recalibrar probabilidade",IF(AND($Z7="Aceitar",$BA7=""),"Aceite sem justificativa",IF(AND($Z7="Aceitar",ISNUMBER($AB7),$AB7<TODAY()),"Aceite vencido",IF(AND(OR($Z7="Aceitar",$Z7="Monitorar"),$Y7<>"Monitorar",$Y7<>""),"Aprovar aceite",IF(AND($Z7<>"Aceitar",$Z7<>"Monitorar",$Z7<>"Aprofundar análise",$AC7="",$AI7="",IFERROR(MATCH(IF($W7<>"",$W7,$Q7),Niveis,0),0)>IF(N(IFERROR(INDEX(ApetIdx,MATCH($M7,ListaCatRisco,0)),0))=0,IdxExige-1,INDEX(ApetIdx,MATCH($M7,ListaCatRisco,0)))),"Sem ação",IF($Z7="Aprofundar análise","Aprofundar análise",IF(AND(OR($Z7="Prevenir",$Z7="Mitigar",$Z7="Transferir / compartilhar"),$AH7=""),"Definir critério de eficácia",IF(AND(OR($Z7="Prevenir",$Z7="Mitigar",$Z7="Transferir / compartilhar"),OR($AA7="Controle administrativo",$AA7="EPI"),IFERROR(MATCH(IF($W7<>"",$W7,$Q7),Niveis,0),0)>=3),"Rever hierarquia de controle",IF(COUNTIFS(KriId,$A7,KriSit,"Estourou")+COUNTIFS(KriId,$A7,KriSit,"Atenção")>0,"KRI em alerta",IF(COUNTIFS(BtId,$A7,BtEf,"Baixa")+COUNTIFS(BtId,$A7,BtEf,"Inexistente")>0,"Barreira fraca",IF($AN7="Não eficaz","Ação ineficaz",IF(AND($AL7<>"",$AL7<TODAY(),$AK7<>"Concluído",$AK7<>"Cancelado"),"Ação vencida",IF(AND($AN7<>"Eficaz",OR($AK7="Concluído",AND(ISNUMBER($AM7),$AM7<TODAY()))),"Avaliar eficácia",IF(AND($AN7="Eficaz",OR($AS7="",$AT7="")),"Concluir residual",IF($AT7="Não","Tratamento adicional",IF(AND($AT7="Sim",$AS7<>"",IFERROR(MATCH($AS7,Niveis,0),0)>IF(N(IFERROR(INDEX(ApetIdx,MATCH($M7,ListaCatRisco,0)),0))=0,IdxExige-1,INDEX(ApetIdx,MATCH($M7,ListaCatRisco,0)))),"Aceite fora do apetite",IF(AND(COUNTIF(BtId,$A7)=0,OR(IFERROR(MATCH(IF($W7<>"",$W7,$Q7),Niveis,0),0)>=3,AND(OR($S7="Baixa",$S7="Inexistente"),IFERROR(MATCH(IF($W7<>"",$W7,$Q7),Niveis,0),0)>=2))),"Sem BowTie",IF(AND($AY7<>"",$AY7<TODAY()),"Revisão vencida",IF(AND($AL7<>"",N($AL7)-TODAY()<=DiasAlerta,$AK7<>"Concluído",$AK7<>"Cancelado"),"Vence em breve","OK"))))))))))))))))))))))))))) -> KRI em alerta | BA7: Parada não planejada ISBM-005: ≈ 116 h/mês vs 70 h/mês na média das demais ISBM (custo ilustrativo € 350/h). Não atacar com mais inspeção de produto. | BB7: R23;R22 | BC7: =IF($V7="","",1+COUNTIF($V$5:$V$154,">"&$V7)+COUNTIFS($V$5:$V$154,$V7,$U$5:$U$154,">"&$U7)+COUNTIFS($V$4:$V6,$V7,$U$4:$U6,$U7)) -> 8 | BD7: Rápida — dias | BE7: Moderada | BF7: Preventivo | BG7: 60000 | BH7: 120000 | BI7: =IF(OR($BH7="",$T7=""),"",IFERROR($BH7*INDEX(ProbMedia,$T7),"")) -> 84000 | BJ7: =IF(OR($BG7="",$BI7=""),"",IF(OR(LEFT($M7,3)="SST",LEFT($M7,5)="Legal",LEFT($M7,8)="Ambienta"),"SST/Ambiental/Legal: custo não justifica aceitar (apetite e ALARP)",IF($BG7>$BI7,"Custo maior que a perda esperada: reter/aceitar é defensável, com justificativa","Custo menor ou igual à perda esperada: tratar compensa"))) -> Custo menor ou igual à perda esperada: tratar compensa | BK7: 24 | BL7: PCN-ISBM-01 (transferir ordens para ISBM-004/006) | BW7: =IF($BU7="","",IFERROR(INDEX(SgaProbValor,MATCH($BU7,SgaProbNivel,0)),"")) | BX7: =IF($BV7="","",IFERROR(INDEX(SgaSevRiValor,MATCH($BV7,SgaSevRiNivel,0)),"")) | BY7: =IF(COUNT($BW7:$BX7)=2,$BW7*$BX7,"") | BZ7: =IF($BY7="","",IF($BY7<=SgaLimRiSig,"SIGNIFICATIVO",IF($BY7<=SgaLimRiTol,"TOLERÁVEL","BAIXO"))) | CA7: =IF($BZ7="","",IF($BZ7="SIGNIFICATIVO","NÃO ACEITÁVEL","ACEITÁVEL")) | CG7: =IF(OR($CE7="",$CF7=""),"",IFERROR(INDEX(SgaProbValor,MATCH($CE7,SgaProbNivel,0))*INDEX(SgaSevRiValor,MATCH($CF7,SgaSevRiNivel,0)),"")) | CH7: =IF($CG7="","",IF($CG7<=SgaLimRiSig,"SIGNIFICATIVO",IF($CG7<=SgaLimRiTol,"TOLERÁVEL","BAIXO")))
A8: R4 | B8: Injeção | C8: Short shot e variação de peso na IM-002 causados por banda de aquecimento marginal e janela de parâmetros inadequada | D8: Análise de dados / raio-X analítico | E8: Técnico | F8: Operacional | G8: Taxa de rejeição ≤ 2,0% (baseline 2,39%) | H8: Novo | I8: Clientes de cosmética (marcas UE) | J8: Banda de aquecimento do canhão marginal: interação temperatura × velocidade de injeção fora da janela ótima | K8: Máquina | L8: Short shot (≈ 13,5 mil DPMO, 3,4× as demais), peças fora de peso, rejeição de lote e reclamações | M8: Qualidade / Cliente | N8: 4 | O8: 4 | P8: =IF(COUNT($N8:$O8)=2,$N8*$O8,"") -> 16 | Q8: =IF($P8="","",INDEX(Niveis,MAX(IFERROR(MATCH($P8,Limites,1),1),IF($O8=5,MinIdx,1)))) -> Crítico | R8: AQL por lote; carta de peso; parâmetros do setup padrão | S8: Média | T8: 4 | U8: 3 | V8: =IF(COUNT($T8:$U8)=2,$T8*$U8,"") -> 12 | W8: =IF($V8="","",INDEX(Niveis,MAX(IFERROR(MATCH($V8,Limites,1),1),IF($U8=5,MinIdx,1)))) -> Alto | X8: Alta | Y8: =IF(IF($W8<>"",$W8,$Q8)="","",INDEX(AcaoRisco,MATCH(IF($W8<>"",$W8,$Q8),Niveis,0))) -> Mitigar | Z8: Mitigar | AA8: Controle de engenharia | AC8: Corrida de confirmação independente do DOE (Short Shot 1,35% → 0,11%), atualizar standard work, plano de controle e FMEA (RC-05) | AD8: Gerente da Qualidade | AE8: Eng. da Qualidade | AH8: Short Shot IM-002 ≤ 1 500 DPMO e Cpk do peso ≥ 1,33 por 3 meses após replicação | AI8: PAC 202602 | AJ8: =IF(OR($AI8="",PlanoUrl=""),"",HYPERLINK(SUBSTITUTE(PlanoUrl,"{COD}",SUBSTITUTE($AI8," ","%20")),"↗")) | AK8: =IF($C8="","",IF($AI8="",$AG8&"",IFERROR(IF(INDEX(PlanosStatus,MATCH($AI8,PlanosCod,0))="",$AG8&"",INDEX(PlanosStatus,MATCH($AI8,PlanosCod,0))),$AG8&""))) -> Em andamento | AL8: =IF($C8="","",IF($AI8="",IF($AF8="","",$AF8),IFERROR(IF(INDEX(PlanosPrazo,MATCH($AI8,PlanosCod,0))="",IF($AF8="","",$AF8),INDEX(PlanosPrazo,MATCH($AI8,PlanosCod,0))),IF($AF8="","",$AF8)))) -> 46430 | AM8: 46538 | AP8: 2 | AQ8: 3 | AR8: =IF(COUNT($AP8:$AQ8)=2,$AP8*$AQ8,"") -> 6 | AS8: =IF($AR8="","",INDEX(Niveis,MAX(IFERROR(MATCH($AR8,Limites,1),1),IF($AQ8=5,MinIdx,1)))) -> Baixo | AT8: Sim | AU8: Short Shot DPMO da IM-002 (aba KRI) | AV8: 65 | AW8: 46371 | AX8: Comitê da Qualidade | AY8: =IF(OR($AW8="",IF(AND($AN8="Eficaz",$AS8<>""),$AS8,IF($W8<>"",$W8,$Q8))=""),"",EDATE($AW8,INDEX(MesesRev,MATCH(IF(AND($AN8="Eficaz",$AS8<>""),$AS8,IF($W8<>"",$W8,$Q8)),Niveis,0)))) -> 46461 | AZ8: =IF($C8="","",IF($AD8="","Sem dono",IF($W8="","Falta avaliação",IF(AND($AI8<>"",COUNTIF(PlanosCod,$AI8)=0),"Código não encontrado",IF(AND($AI8<>"",IFERROR(INDEX(PlanosIdRef,MATCH($AI8,PlanosCod,0))&"","")<>"",ISERROR(SEARCH(";"&$A8&";",";"&SUBSTITUTE(SUBSTITUTE(IFERROR(INDEX(PlanosIdRef,MATCH($AI8,PlanosCod,0))&"","")," ",""),",",";")&";"))),"Vínculo divergente",IF(AND(ISNUMBER($P8),ISNUMBER($V8),$V8<$P8,OR($S8="",$S8="Inexistente")),"Redução s/ controle",IF(AND(ISNUMBER($AR8),ISNUMBER($V8),$AR8<$V8,NOT(OR($Z8="Prevenir",$Z8="Mitigar",$Z8="Transferir / compartilhar")),$AC8="",$AI8=""),"Residual s/ tratamento",IF(AND(LEFT($AI8,3)="RNC",N(IFERROR(INDEX(PlanosAbertura,MATCH($AI8,PlanosCod,0)),0))>N($AW8)),"Reavaliar após RNC",IF(AND(N($AV8)>=1,ISNUMBER($T8),$T8<=2),"Recalibrar probabilidade",IF(AND($Z8="Aceitar",$BA8=""),"Aceite sem justificativa",IF(AND($Z8="Aceitar",ISNUMBER($AB8),$AB8<TODAY()),"Aceite vencido",IF(AND(OR($Z8="Aceitar",$Z8="Monitorar"),$Y8<>"Monitorar",$Y8<>""),"Aprovar aceite",IF(AND($Z8<>"Aceitar",$Z8<>"Monitorar",$Z8<>"Aprofundar análise",$AC8="",$AI8="",IFERROR(MATCH(IF($W8<>"",$W8,$Q8),Niveis,0),0)>IF(N(IFERROR(INDEX(ApetIdx,MATCH($M8,ListaCatRisco,0)),0))=0,IdxExige-1,INDEX(ApetIdx,MATCH($M8,ListaCatRisco,0)))),"Sem ação",IF($Z8="Aprofundar análise","Aprofundar análise",IF(AND(OR($Z8="Prevenir",$Z8="Mitigar",$Z8="Transferir / compartilhar"),$AH8=""),"Definir critério de eficácia",IF(AND(OR($Z8="Prevenir",$Z8="Mitigar",$Z8="Transferir / compartilhar"),OR($AA8="Controle administrativo",$AA8="EPI"),IFERROR(MATCH(IF($W8<>"",$W8,$Q8),Niveis,0),0)>=3),"Rever hierarquia de controle",IF(COUNTIFS(KriId,$A8,KriSit,"Estourou")+COUNTIFS(KriId,$A8,KriSit,"Atenção")>0,"KRI em alerta",IF(COUNTIFS(BtId,$A8,BtEf,"Baixa")+COUNTIFS(BtId,$A8,BtEf,"Inexistente")>0,"Barreira fraca",IF($AN8="Não eficaz","Ação ineficaz",IF(AND($AL8<>"",$AL8<TODAY(),$AK8<>"Concluído",$AK8<>"Cancelado"),"Ação vencida",IF(AND($AN8<>"Eficaz",OR($AK8="Concluído",AND(ISNUMBER($AM8),$AM8<TODAY()))),"Avaliar eficácia",IF(AND($AN8="Eficaz",OR($AS8="",$AT8="")),"Concluir residual",IF($AT8="Não","Tratamento adicional",IF(AND($AT8="Sim",$AS8<>"",IFERROR(MATCH($AS8,Niveis,0),0)>IF(N(IFERROR(INDEX(ApetIdx,MATCH($M8,ListaCatRisco,0)),0))=0,IdxExige-1,INDEX(ApetIdx,MATCH($M8,ListaCatRisco,0)))),"Aceite fora do apetite",IF(AND(COUNTIF(BtId,$A8)=0,OR(IFERROR(MATCH(IF($W8<>"",$W8,$Q8),Niveis,0),0)>=3,AND(OR($S8="Baixa",$S8="Inexistente"),IFERROR(MATCH(IF($W8<>"",$W8,$Q8),Niveis,0),0)>=2))),"Sem BowTie",IF(AND($AY8<>"",$AY8<TODAY()),"Revisão vencida",IF(AND($AL8<>"",N($AL8)-TODAY()<=DiasAlerta,$AK8<>"Concluído",$AK8<>"Cancelado"),"Vence em breve","OK"))))))))))))))))))))))))))) -> KRI em alerta | BA8: Caso de maior evidência causal: MSA adequado, efeito de máquina após controle de mix e DOE (temperatura, velocidade e interação). Ainda sem prova de sustentação em produção. | BB8: R10;R19 | BC8: =IF($V8="","",1+COUNTIF($V$5:$V$154,">"&$V8)+COUNTIFS($V$5:$V$154,$V8,$U$5:$U$154,">"&$U8)+COUNTIFS($V$4:$V7,$V8,$U$4:$U7,$U8)) -> 9 | BD8: Média — semanas | BE8: Moderada | BF8: Preventivo | BG8: 15000 | BH8: 48000 | BI8: =IF(OR($BH8="",$T8=""),"",IFERROR($BH8*INDEX(ProbMedia,$T8),"")) -> 33600 | BJ8: =IF(OR($BG8="",$BI8=""),"",IF(OR(LEFT($M8,3)="SST",LEFT($M8,5)="Legal",LEFT($M8,8)="Ambienta"),"SST/Ambiental/Legal: custo não justifica aceitar (apetite e ALARP)",IF($BG8>$BI8,"Custo maior que a perda esperada: reter/aceitar é defensável, com justificativa","Custo menor ou igual à perda esperada: tratar compensa"))) -> Custo menor ou igual à perda esperada: tratar compensa | BW8: =IF($BU8="","",IFERROR(INDEX(SgaProbValor,MATCH($BU8,SgaProbNivel,0)),"")) | BX8: =IF($BV8="","",IFERROR(INDEX(SgaSevRiValor,MATCH($BV8,SgaSevRiNivel,0)),"")) | BY8: =IF(COUNT($BW8:$BX8)=2,$BW8*$BX8,"") | BZ8: =IF($BY8="","",IF($BY8<=SgaLimRiSig,"SIGNIFICATIVO",IF($BY8<=SgaLimRiTol,"TOLERÁVEL","BAIXO"))) | CA8: =IF($BZ8="","",IF($BZ8="SIGNIFICATIVO","NÃO ACEITÁVEL","ACEITÁVEL")) | CG8: =IF(OR($CE8="",$CF8=""),"",IFERROR(INDEX(SgaProbValor,MATCH($CE8,SgaProbNivel,0))*INDEX(SgaSevRiValor,MATCH($CF8,SgaSevRiNivel,0)),"")) | CH8: =IF($CG8="","",IF($CG8<=SgaLimRiSig,"SIGNIFICATIVO",IF($CG8<=SgaLimRiTol,"TOLERÁVEL","BAIXO")))
A9: R5 | B9: Injeção | C9: Flash crescente na IM-004 em campanhas longas entre trocas de molde (acúmulo de ciclos desde o setup) | D9: Análise de dados / raio-X analítico | E9: Técnico | F9: Operacional | G9: Taxa de rejeição ≤ 2,0% (baseline 2,39%) | H9: Novo | I9: Clientes de cosmética (marcas UE) | J9: Campanhas de até 930 mil unidades sem troca; o desgaste do molde cresce com os ciclos e não há contador nem limite de reação | K9: Máquina | L9: Flash em tampas (≈ 15 mil DPMO, 3,8× as demais), lote rejeitado/refeito (NC-01322/01323) e retrabalho | M9: Qualidade / Cliente | N9: 4 | O9: 4 | P9: =IF(COUNT($N9:$O9)=2,$N9*$O9,"") -> 16 | Q9: =IF($P9="","",INDEX(Niveis,MAX(IFERROR(MATCH($P9,Limites,1),1),IF($O9=5,MinIdx,1)))) -> Crítico | R9: AQL de Flash por lote; troca de molde conforme programação | S9: Baixa | T9: 4 | U9: 3 | V9: =IF(COUNT($T9:$U9)=2,$T9*$U9,"") -> 12 | W9: =IF($V9="","",INDEX(Niveis,MAX(IFERROR(MATCH($V9,Limites,1),1),IF($U9=5,MinIdx,1)))) -> Alto | X9: Média | Y9: =IF(IF($W9<>"",$W9,$Q9)="","",INDEX(AcaoRisco,MATCH(IF($W9<>"",$W9,$Q9),Niveis,0))) -> Mitigar | Z9: Mitigar | AA9: Controle de engenharia | AC9: Criar contador de unidades desde o setup com limite validado e inspeção de condição antes do limite (RC-02) | AD9: Gerente de Produção | AE9: Eng. de Manutenção | AH9: Flash IM-004 ≤ 4 000 DPMO; nenhuma campanha acima do limite técnico validado | AI9: PAC 202603 | AJ9: =IF(OR($AI9="",PlanoUrl=""),"",HYPERLINK(SUBSTITUTE(PlanoUrl,"{COD}",SUBSTITUTE($AI9," ","%20")),"↗")) | AK9: =IF($C9="","",IF($AI9="",$AG9&"",IFERROR(IF(INDEX(PlanosStatus,MATCH($AI9,PlanosCod,0))="",$AG9&"",INDEX(PlanosStatus,MATCH($AI9,PlanosCod,0))),$AG9&""))) -> Aberto | AL9: =IF($C9="","",IF($AI9="",IF($AF9="","",$AF9),IFERROR(IF(INDEX(PlanosPrazo,MATCH($AI9,PlanosCod,0))="",IF($AF9="","",$AF9),INDEX(PlanosPrazo,MATCH($AI9,PlanosCod,0))),IF($AF9="","",$AF9)))) -> 46477 | AM9: 46568 | AP9: 2 | AQ9: 3 | AR9: =IF(COUNT($AP9:$AQ9)=2,$AP9*$AQ9,"") -> 6 | AS9: =IF($AR9="","",INDEX(Niveis,MAX(IFERROR(MATCH($AR9,Limites,1),1),IF($AQ9=5,MinIdx,1)))) -> Baixo | AT9: Sim | AU9: Flash DPMO da IM-004 e unidades desde o último setup (aba KRI) | AV9: 40 | AW9: 46371 | AX9: Comitê da Qualidade | AY9: =IF(OR($AW9="",IF(AND($AN9="Eficaz",$AS9<>""),$AS9,IF($W9<>"",$W9,$Q9))=""),"",EDATE($AW9,INDEX(MesesRev,MATCH(IF(AND($AN9="Eficaz",$AS9<>""),$AS9,IF($W9<>"",$W9,$Q9)),Niveis,0)))) -> 46461 | AZ9: =IF($C9="","",IF($AD9="","Sem dono",IF($W9="","Falta avaliação",IF(AND($AI9<>"",COUNTIF(PlanosCod,$AI9)=0),"Código não encontrado",IF(AND($AI9<>"",IFERROR(INDEX(PlanosIdRef,MATCH($AI9,PlanosCod,0))&"","")<>"",ISERROR(SEARCH(";"&$A9&";",";"&SUBSTITUTE(SUBSTITUTE(IFERROR(INDEX(PlanosIdRef,MATCH($AI9,PlanosCod,0))&"","")," ",""),",",";")&";"))),"Vínculo divergente",IF(AND(ISNUMBER($P9),ISNUMBER($V9),$V9<$P9,OR($S9="",$S9="Inexistente")),"Redução s/ controle",IF(AND(ISNUMBER($AR9),ISNUMBER($V9),$AR9<$V9,NOT(OR($Z9="Prevenir",$Z9="Mitigar",$Z9="Transferir / compartilhar")),$AC9="",$AI9=""),"Residual s/ tratamento",IF(AND(LEFT($AI9,3)="RNC",N(IFERROR(INDEX(PlanosAbertura,MATCH($AI9,PlanosCod,0)),0))>N($AW9)),"Reavaliar após RNC",IF(AND(N($AV9)>=1,ISNUMBER($T9),$T9<=2),"Recalibrar probabilidade",IF(AND($Z9="Aceitar",$BA9=""),"Aceite sem justificativa",IF(AND($Z9="Aceitar",ISNUMBER($AB9),$AB9<TODAY()),"Aceite vencido",IF(AND(OR($Z9="Aceitar",$Z9="Monitorar"),$Y9<>"Monitorar",$Y9<>""),"Aprovar aceite",IF(AND($Z9<>"Aceitar",$Z9<>"Monitorar",$Z9<>"Aprofundar análise",$AC9="",$AI9="",IFERROR(MATCH(IF($W9<>"",$W9,$Q9),Niveis,0),0)>IF(N(IFERROR(INDEX(ApetIdx,MATCH($M9,ListaCatRisco,0)),0))=0,IdxExige-1,INDEX(ApetIdx,MATCH($M9,ListaCatRisco,0)))),"Sem ação",IF($Z9="Aprofundar análise","Aprofundar análise",IF(AND(OR($Z9="Prevenir",$Z9="Mitigar",$Z9="Transferir / compartilhar"),$AH9=""),"Definir critério de eficácia",IF(AND(OR($Z9="Prevenir",$Z9="Mitigar",$Z9="Transferir / compartilhar"),OR($AA9="Controle administrativo",$AA9="EPI"),IFERROR(MATCH(IF($W9<>"",$W9,$Q9),Niveis,0),0)>=3),"Rever hierarquia de controle",IF(COUNTIFS(KriId,$A9,KriSit,"Estourou")+COUNTIFS(KriId,$A9,KriSit,"Atenção")>0,"KRI em alerta",IF(COUNTIFS(BtId,$A9,BtEf,"Baixa")+COUNTIFS(BtId,$A9,BtEf,"Inexistente")>0,"Barreira fraca",IF($AN9="Não eficaz","Ação ineficaz",IF(AND($AL9<>"",$AL9<TODAY(),$AK9<>"Concluído",$AK9<>"Cancelado"),"Ação vencida",IF(AND($AN9<>"Eficaz",OR($AK9="Concluído",AND(ISNUMBER($AM9),$AM9<TODAY()))),"Avaliar eficácia",IF(AND($AN9="Eficaz",OR($AS9="",$AT9="")),"Concluir residual",IF($AT9="Não","Tratamento adicional",IF(AND($AT9="Sim",$AS9<>"",IFERROR(MATCH($AS9,Niveis,0),0)>IF(N(IFERROR(INDEX(ApetIdx,MATCH($M9,ListaCatRisco,0)),0))=0,IdxExige-1,INDEX(ApetIdx,MATCH($M9,ListaCatRisco,0)))),"Aceite fora do apetite",IF(AND(COUNTIF(BtId,$A9)=0,OR(IFERROR(MATCH(IF($W9<>"",$W9,$Q9),Niveis,0),0)>=3,AND(OR($S9="Baixa",$S9="Inexistente"),IFERROR(MATCH(IF($W9<>"",$W9,$Q9),Niveis,0),0)>=2))),"Sem BowTie",IF(AND($AY9<>"",$AY9<TODAY()),"Revisão vencida",IF(AND($AL9<>"",N($AL9)-TODAY()<=DiasAlerta,$AK9<>"Concluído",$AK9<>"Cancelado"),"Vence em breve","OK"))))))))))))))))))))))))))) -> KRI em alerta | BA9: Indicador correto é unidades/ciclos desde o setup, não o mês. Limite técnico não escolhido por conveniência: estimar da curva defeito × ciclos e confirmar em campo. | BB9: R2;R19 | BC9: =IF($V9="","",1+COUNTIF($V$5:$V$154,">"&$V9)+COUNTIFS($V$5:$V$154,$V9,$U$5:$U$154,">"&$U9)+COUNTIFS($V$4:$V8,$V9,$U$4:$U8,$U9)) -> 10 | BD9: Média — semanas | BE9: Moderada | BF9: Detectivo | BG9: 12000 | BH9: 38000 | BI9: =IF(OR($BH9="",$T9=""),"",IFERROR($BH9*INDEX(ProbMedia,$T9),"")) -> 26600 | BJ9: =IF(OR($BG9="",$BI9=""),"",IF(OR(LEFT($M9,3)="SST",LEFT($M9,5)="Legal",LEFT($M9,8)="Ambienta"),"SST/Ambiental/Legal: custo não justifica aceitar (apetite e ALARP)",IF($BG9>$BI9,"Custo maior que a perda esperada: reter/aceitar é defensável, com justificativa","Custo menor ou igual à perda esperada: tratar compensa"))) -> Custo menor ou igual à perda esperada: tratar compensa | BW9: =IF($BU9="","",IFERROR(INDEX(SgaProbValor,MATCH($BU9,SgaProbNivel,0)),"")) | BX9: =IF($BV9="","",IFERROR(INDEX(SgaSevRiValor,MATCH($BV9,SgaSevRiNivel,0)),"")) | BY9: =IF(COUNT($BW9:$BX9)=2,$BW9*$BX9,"") | BZ9: =IF($BY9="","",IF($BY9<=SgaLimRiSig,"SIGNIFICATIVO",IF($BY9<=SgaLimRiTol,"TOLERÁVEL","BAIXO"))) | CA9: =IF($BZ9="","",IF($BZ9="SIGNIFICATIVO","NÃO ACEITÁVEL","ACEITÁVEL")) | CG9: =IF(OR($CE9="",$CF9=""),"",IFERROR(INDEX(SgaProbValor,MATCH($CE9,SgaProbNivel,0))*INDEX(SgaSevRiValor,MATCH($CF9,SgaSevRiNivel,0)),"")) | CH9: =IF($CG9="","",IF($CG9<=SgaLimRiSig,"SIGNIFICATIVO",IF($CG9<=SgaLimRiTol,"TOLERÁVEL","BAIXO")))
A10: R6 | B10: Serigrafia | C10: Pico de falha de adesão de tinta em FR-007-PP-350 (SS-002) ligado a lote de resina PP marginal | D10: RNC / reclamação | E10: Externo | F10: Operacional | G10: Taxa de rejeição ≤ 2,0% (baseline 2,39%) | H10: Mantido | I10: Clientes de cosmética (marcas UE) | J10: Interação entrada × processo: lote de PP do fornecedor SUP-005 na janela marginal + sensibilidade do processo de decoração | K10: Material | L10: Lote rejeitado e refeito (NC-01324), adesão ≈ 1 090 DPMO na janela vs 0 fora dela, reclamações de tinta | M10: Qualidade / Cliente | N10: 3 | O10: 4 | P10: =IF(COUNT($N10:$O10)=2,$N10*$O10,"") -> 12 | Q10: =IF($P10="","",INDEX(Niveis,MAX(IFERROR(MATCH($P10,Limites,1),1),IF($O10=5,MinIdx,1)))) -> Alto | R10: Inspeção de recebimento de PP; AQL de adesão; teste de aderência no setup | S10: Média | T10: 3 | U10: 4 | V10: =IF(COUNT($T10:$U10)=2,$T10*$U10,"") -> 12 | W10: =IF($V10="","",INDEX(Niveis,MAX(IFERROR(MATCH($V10,Limites,1),1),IF($U10=5,MinIdx,1)))) -> Alto | X10: Média | Y10: =IF(IF($W10<>"",$W10,$Q10)="","",INDEX(AcaoRisco,MATCH(IF($W10<>"",$W10,$Q10),Niveis,0))) -> Mitigar | Z10: Mitigar | AA10: Controle de engenharia | AC10: Segregar lotes de risco, confirmar o efeito do lote de PP na adesão e fixar a janela de parâmetros da serigrafia (RC-03) | AD10: Gerente da Qualidade | AE10: Eng. da Qualidade | AH10: Adesão ≤ 300 DPMO por material/lote e nenhum lote de PP liberado sem confirmação | AI10: PAC 202607 | AJ10: =IF(OR($AI10="",PlanoUrl=""),"",HYPERLINK(SUBSTITUTE(PlanoUrl,"{COD}",SUBSTITUTE($AI10," ","%20")),"↗")) | AK10: =IF($C10="","",IF($AI10="",$AG10&"",IFERROR(IF(INDEX(PlanosStatus,MATCH($AI10,PlanosCod,0))="",$AG10&"",INDEX(PlanosStatus,MATCH($AI10,PlanosCod,0))),$AG10&""))) -> Aberto | AL10: =IF($C10="","",IF($AI10="",IF($AF10="","",$AF10),IFERROR(IF(INDEX(PlanosPrazo,MATCH($AI10,PlanosCod,0))="",IF($AF10="","",$AF10),INDEX(PlanosPrazo,MATCH($AI10,PlanosCod,0))),IF($AF10="","",$AF10)))) -> 46461 | AM10: 46538 | AP10: 2 | AQ10: 3 | AR10: =IF(COUNT($AP10:$AQ10)=2,$AP10*$AQ10,"") -> 6 | AS10: =IF($AR10="","",INDEX(Niveis,MAX(IFERROR(MATCH($AR10,Limites,1),1),IF($AQ10=5,MinIdx,1)))) -> Baixo | AT10: Sim | AU10: Adesão DPMO na serigrafia (aba KRI) | AV10: 52 | AW10: 46371 | AX10: Comitê da Qualidade | AY10: =IF(OR($AW10="",IF(AND($AN10="Eficaz",$AS10<>""),$AS10,IF($W10<>"",$W10,$Q10))=""),"",EDATE($AW10,INDEX(MesesRev,MATCH(IF(AND($AN10="Eficaz",$AS10<>""),$AS10,IF($W10<>"",$W10,$Q10)),Niveis,0)))) -> 46461 | AZ10: =IF($C10="","",IF($AD10="","Sem dono",IF($W10="","Falta avaliação",IF(AND($AI10<>"",COUNTIF(PlanosCod,$AI10)=0),"Código não encontrado",IF(AND($AI10<>"",IFERROR(INDEX(PlanosIdRef,MATCH($AI10,PlanosCod,0))&"","")<>"",ISERROR(SEARCH(";"&$A10&";",";"&SUBSTITUTE(SUBSTITUTE(IFERROR(INDEX(PlanosIdRef,MATCH($AI10,PlanosCod,0))&"","")," ",""),",",";")&";"))),"Vínculo divergente",IF(AND(ISNUMBER($P10),ISNUMBER($V10),$V10<$P10,OR($S10="",$S10="Inexistente")),"Redução s/ controle",IF(AND(ISNUMBER($AR10),ISNUMBER($V10),$AR10<$V10,NOT(OR($Z10="Prevenir",$Z10="Mitigar",$Z10="Transferir / compartilhar")),$AC10="",$AI10=""),"Residual s/ tratamento",IF(AND(LEFT($AI10,3)="RNC",N(IFERROR(INDEX(PlanosAbertura,MATCH($AI10,PlanosCod,0)),0))>N($AW10)),"Reavaliar após RNC",IF(AND(N($AV10)>=1,ISNUMBER($T10),$T10<=2),"Recalibrar probabilidade",IF(AND($Z10="Aceitar",$BA10=""),"Aceite sem justificativa",IF(AND($Z10="Aceitar",ISNUMBER($AB10),$AB10<TODAY()),"Aceite vencido",IF(AND(OR($Z10="Aceitar",$Z10="Monitorar"),$Y10<>"Monitorar",$Y10<>""),"Aprovar aceite",IF(AND($Z10<>"Aceitar",$Z10<>"Monitorar",$Z10<>"Aprofundar análise",$AC10="",$AI10="",IFERROR(MATCH(IF($W10<>"",$W10,$Q10),Niveis,0),0)>IF(N(IFERROR(INDEX(ApetIdx,MATCH($M10,ListaCatRisco,0)),0))=0,IdxExige-1,INDEX(ApetIdx,MATCH($M10,ListaCatRisco,0)))),"Sem ação",IF($Z10="Aprofundar análise","Aprofundar análise",IF(AND(OR($Z10="Prevenir",$Z10="Mitigar",$Z10="Transferir / compartilhar"),$AH10=""),"Definir critério de eficácia",IF(AND(OR($Z10="Prevenir",$Z10="Mitigar",$Z10="Transferir / compartilhar"),OR($AA10="Controle administrativo",$AA10="EPI"),IFERROR(MATCH(IF($W10<>"",$W10,$Q10),Niveis,0),0)>=3),"Rever hierarquia de controle",IF(COUNTIFS(KriId,$A10,KriSit,"Estourou")+COUNTIFS(KriId,$A10,KriSit,"Atenção")>0,"KRI em alerta",IF(COUNTIFS(BtId,$A10,BtEf,"Baixa")+COUNTIFS(BtId,$A10,BtEf,"Inexistente")>0,"Barreira fraca",IF($AN10="Não eficaz","Ação ineficaz",IF(AND($AL10<>"",$AL10<TODAY(),$AK10<>"Concluído",$AK10<>"Cancelado"),"Ação vencida",IF(AND($AN10<>"Eficaz",OR($AK10="Concluído",AND(ISNUMBER($AM10),$AM10<TODAY()))),"Avaliar eficácia",IF(AND($AN10="Eficaz",OR($AS10="",$AT10="")),"Concluir residual",IF($AT10="Não","Tratamento adicional",IF(AND($AT10="Sim",$AS10<>"",IFERROR(MATCH($AS10,Niveis,0),0)>IF(N(IFERROR(INDEX(ApetIdx,MATCH($M10,ListaCatRisco,0)),0))=0,IdxExige-1,INDEX(ApetIdx,MATCH($M10,ListaCatRisco,0)))),"Aceite fora do apetite",IF(AND(COUNTIF(BtId,$A10)=0,OR(IFERROR(MATCH(IF($W10<>"",$W10,$Q10),Niveis,0),0)>=3,AND(OR($S10="Baixa",$S10="Inexistente"),IFERROR(MATCH(IF($W10<>"",$W10,$Q10),Niveis,0),0)>=2))),"Sem BowTie",IF(AND($AY10<>"",$AY10<TODAY()),"Revisão vencida",IF(AND($AL10<>"",N($AL10)-TODAY()<=DiasAlerta,$AK10<>"Concluído",$AK10<>"Cancelado"),"Vence em breve","OK"))))))))))))))))))))))))))) -> KRI em alerta | BA10: Janela 2026-02-20 a 2026-03-13. Não concluir que a serigrafia é ruim: a evidência aponta para interação com o lote de resina. Ligado a R13. | BB10: R13;R14 | BC10: =IF($V10="","",1+COUNTIF($V$5:$V$154,">"&$V10)+COUNTIFS($V$5:$V$154,$V10,$U$5:$U$154,">"&$U10)+COUNTIFS($V$4:$V9,$V10,$U$4:$U9,$U10)) -> 3 | BD10: Média — semanas | BE10: Alta — muda rápido | BF10: Detectivo | BG10: 14000 | BH10: 36000 | BI10: =IF(OR($BH10="",$T10=""),"",IFERROR($BH10*INDEX(ProbMedia,$T10),"")) -> 18000 | BJ10: =IF(OR($BG10="",$BI10=""),"",IF(OR(LEFT($M10,3)="SST",LEFT($M10,5)="Legal",LEFT($M10,8)="Ambienta"),"SST/Ambiental/Legal: custo não justifica aceitar (apetite e ALARP)",IF($BG10>$BI10,"Custo maior que a perda esperada: reter/aceitar é defensável, com justificativa","Custo menor ou igual à perda esperada: tratar compensa"))) -> Custo menor ou igual à perda esperada: tratar compensa | BW10: =IF($BU10="","",IFERROR(INDEX(SgaProbValor,MATCH($BU10,SgaProbNivel,0)),"")) | BX10: =IF($BV10="","",IFERROR(INDEX(SgaSevRiValor,MATCH($BV10,SgaSevRiNivel,0)),"")) | BY10: =IF(COUNT($BW10:$BX10)=2,$BW10*$BX10,"") | BZ10: =IF($BY10="","",IF($BY10<=SgaLimRiSig,"SIGNIFICATIVO",IF($BY10<=SgaLimRiTol,"TOLERÁVEL","BAIXO"))) | CA10: =IF($BZ10="","",IF($BZ10="SIGNIFICATIVO","NÃO ACEITÁVEL","ACEITÁVEL")) | CG10: =IF(OR($CE10="",$CF10=""),"",IFERROR(INDEX(SgaProbValor,MATCH($CE10,SgaProbNivel,0))*INDEX(SgaSevRiValor,MATCH($CF10,SgaSevRiNivel,0)),"")) | CH10: =IF($CG10="","",IF($CG10<=SgaLimRiSig,"SIGNIFICATIVO",IF($CG10<=SgaLimRiTol,"TOLERÁVEL","BAIXO")))
A11: R7 | B11: Serigrafia | C11: Degradação de confiabilidade da SS-001 (desgaste de rolete/rasqueta e backlog de manutenção) eleva falhas e tempo de reparo | D11: Análise de dados / raio-X analítico | E11: Técnico | F11: Operacional | G11: OEE ≥ 81,1% e Disponibilidade ≥ 90% (baseline 79,1% / 87,4%) | H11: Alterado | I11: Acionistas / Direção | J11: Desgaste de rolete/rasqueta com backlog de manutenção: MTTR subiu de ≈ 1,7 h para ≈ 3,5 h até jun/2026 | K11: Máquina | L11: Paradas longas, atraso de ordens, lote refeito (NC-01326) e perda de disponibilidade | M11: Produção / Ativos | N11: 4 | O11: 4 | P11: =IF(COUNT($N11:$O11)=2,$N11*$O11,"") -> 16 | Q11: =IF($P11="","",INDEX(Niveis,MAX(IFERROR(MATCH($P11,Limites,1),1),IF($O11=5,MinIdx,1)))) -> Crítico | R11: Overhaul executado em 07/2026 (PAC 202609); PM calendarizada genérica | S11: Média | T11: 3 | U11: 3 | V11: =IF(COUNT($T11:$U11)=2,$T11*$U11,"") -> 9 | W11: =IF($V11="","",INDEX(Niveis,MAX(IFERROR(MATCH($V11,Limites,1),1),IF($U11=5,MinIdx,1)))) -> Médio | X11: Alta | Y11: =IF(IF($W11<>"",$W11,$Q11)="","",INDEX(AcaoRisco,MATCH(IF($W11<>"",$W11,$Q11),Niveis,0))) -> Mitigar | Z11: Mitigar | AA11: Controle de engenharia | AC11: Overhaul concluído; falta PM orientada ao modo de falha e acompanhamento de falhas por 100 h (PAC 202610) | AD11: Gerente de Manutenção | AE11: Eng. de Manutenção | AH11: MTTR SS-001 ≤ 1,5 h por 6 meses após o overhaul | AI11: PAC 202609 | AJ11: =IF(OR($AI11="",PlanoUrl=""),"",HYPERLINK(SUBSTITUTE(PlanoUrl,"{COD}",SUBSTITUTE($AI11," ","%20")),"↗")) | AK11: =IF($C11="","",IF($AI11="",$AG11&"",IFERROR(IF(INDEX(PlanosStatus,MATCH($AI11,PlanosCod,0))="",$AG11&"",INDEX(PlanosStatus,MATCH($AI11,PlanosCod,0))),$AG11&""))) -> Concluído | AL11: =IF($C11="","",IF($AI11="",IF($AF11="","",$AF11),IFERROR(IF(INDEX(PlanosPrazo,MATCH($AI11,PlanosCod,0))="",IF($AF11="","",$AF11),INDEX(PlanosPrazo,MATCH($AI11,PlanosCod,0))),IF($AF11="","",$AF11)))) -> 46223 | AM11: 46371 | AN11: Eficaz | AO11: 46371 | AP11: 2 | AQ11: 3 | AR11: =IF(COUNT($AP11:$AQ11)=2,$AP11*$AQ11,"") -> 6 | AS11: =IF($AR11="","",INDEX(Niveis,MAX(IFERROR(MATCH($AR11,Limites,1),1),IF($AQ11=5,MinIdx,1)))) -> Baixo | AT11: Sim | AU11: MTTR e falhas por 100 h da SS-001 (aba KRI) | AV11: 224 | AW11: 46371 | AX11: Manutenção + Produção | AY11: =IF(OR($AW11="",IF(AND($AN11="Eficaz",$AS11<>""),$AS11,IF($W11<>"",$W11,$Q11))=""),"",EDATE($AW11,INDEX(MesesRev,MATCH(IF(AND($AN11="Eficaz",$AS11<>""),$AS11,IF($W11<>"",$W11,$Q11)),Niveis,0)))) -> 46736 | AZ11: =IF($C11="","",IF($AD11="","Sem dono",IF($W11="","Falta avaliação",IF(AND($AI11<>"",COUNTIF(PlanosCod,$AI11)=0),"Código não encontrado",IF(AND($AI11<>"",IFERROR(INDEX(PlanosIdRef,MATCH($AI11,PlanosCod,0))&"","")<>"",ISERROR(SEARCH(";"&$A11&";",";"&SUBSTITUTE(SUBSTITUTE(IFERROR(INDEX(PlanosIdRef,MATCH($AI11,PlanosCod,0))&"","")," ",""),",",";")&";"))),"Vínculo divergente",IF(AND(ISNUMBER($P11),ISNUMBER($V11),$V11<$P11,OR($S11="",$S11="Inexistente")),"Redução s/ controle",IF(AND(ISNUMBER($AR11),ISNUMBER($V11),$AR11<$V11,NOT(OR($Z11="Prevenir",$Z11="Mitigar",$Z11="Transferir / compartilhar")),$AC11="",$AI11=""),"Residual s/ tratamento",IF(AND(LEFT($AI11,3)="RNC",N(IFERROR(INDEX(PlanosAbertura,MATCH($AI11,PlanosCod,0)),0))>N($AW11)),"Reavaliar após RNC",IF(AND(N($AV11)>=1,ISNUMBER($T11),$T11<=2),"Recalibrar probabilidade",IF(AND($Z11="Aceitar",$BA11=""),"Aceite sem justificativa",IF(AND($Z11="Aceitar",ISNUMBER($AB11),$AB11<TODAY()),"Aceite vencido",IF(AND(OR($Z11="Aceitar",$Z11="Monitorar"),$Y11<>"Monitorar",$Y11<>""),"Aprovar aceite",IF(AND($Z11<>"Aceitar",$Z11<>"Monitorar",$Z11<>"Aprofundar análise",$AC11="",$AI11="",IFERROR(MATCH(IF($W11<>"",$W11,$Q11),Niveis,0),0)>IF(N(IFERROR(INDEX(ApetIdx,MATCH($M11,ListaCatRisco,0)),0))=0,IdxExige-1,INDEX(ApetIdx,MATCH($M11,ListaCatRisco,0)))),"Sem ação",IF($Z11="Aprofundar análise","Aprofundar análise",IF(AND(OR($Z11="Prevenir",$Z11="Mitigar",$Z11="Transferir / compartilhar"),$AH11=""),"Definir critério de eficácia",IF(AND(OR($Z11="Prevenir",$Z11="Mitigar",$Z11="Transferir / compartilhar"),OR($AA11="Controle administrativo",$AA11="EPI"),IFERROR(MATCH(IF($W11<>"",$W11,$Q11),Niveis,0),0)>=3),"Rever hierarquia de controle",IF(COUNTIFS(KriId,$A11,KriSit,"Estourou")+COUNTIFS(KriId,$A11,KriSit,"Atenção")>0,"KRI em alerta",IF(COUNTIFS(BtId,$A11,BtEf,"Baixa")+COUNTIFS(BtId,$A11,BtEf,"Inexistente")>0,"Barreira fraca",IF($AN11="Não eficaz","Ação ineficaz",IF(AND($AL11<>"",$AL11<TODAY(),$AK11<>"Concluído",$AK11<>"Cancelado"),"Ação vencida",IF(AND($AN11<>"Eficaz",OR($AK11="Concluído",AND(ISNUMBER($AM11),$AM11<TODAY()))),"Avaliar eficácia",IF(AND($AN11="Eficaz",OR($AS11="",$AT11="")),"Concluir residual",IF($AT11="Não","Tratamento adicional",IF(AND($AT11="Sim",$AS11<>"",IFERROR(MATCH($AS11,Niveis,0),0)>IF(N(IFERROR(INDEX(ApetIdx,MATCH($M11,ListaCatRisco,0)),0))=0,IdxExige-1,INDEX(ApetIdx,MATCH($M11,ListaCatRisco,0)))),"Aceite fora do apetite",IF(AND(COUNTIF(BtId,$A11)=0,OR(IFERROR(MATCH(IF($W11<>"",$W11,$Q11),Niveis,0),0)>=3,AND(OR($S11="Baixa",$S11="Inexistente"),IFERROR(MATCH(IF($W11<>"",$W11,$Q11),Niveis,0),0)>=2))),"Sem BowTie",IF(AND($AY11<>"",$AY11<TODAY()),"Revisão vencida",IF(AND($AL11<>"",N($AL11)-TODAY()<=DiasAlerta,$AK11<>"Concluído",$AK11<>"Cancelado"),"Vence em breve","OK"))))))))))))))))))))))))))) -> OK | BA11: MTTR unplanned SS-001: 2,82 h (jan–jun/2026) → 1,20 h em média (jul–dez/2026). A média de dez/2026 ainda sobe (1,17 h) — manter monitoramento. A análise de DaysSincePM não provou efeito; isso não prova que PM seja inútil. | BB11: R3 | BC11: =IF($V11="","",1+COUNTIF($V$5:$V$154,">"&$V11)+COUNTIFS($V$5:$V$154,$V11,$U$5:$U$154,">"&$U11)+COUNTIFS($V$4:$V10,$V11,$U$4:$U10,$U11)) -> 22 | BD11: Rápida — dias | BE11: Moderada | BF11: Corretivo | BG11: 35000 | BH11: 100000 | BI11: =IF(OR($BH11="",$T11=""),"",IFERROR($BH11*INDEX(ProbMedia,$T11),"")) -> 50000 | BJ11: =IF(OR($BG11="",$BI11=""),"",IF(OR(LEFT($M11,3)="SST",LEFT($M11,5)="Legal",LEFT($M11,8)="Ambienta"),"SST/Ambiental/Legal: custo não justifica aceitar (apetite e ALARP)",IF($BG11>$BI11,"Custo maior que a perda esperada: reter/aceitar é defensável, com justificativa","Custo menor ou igual à perda esperada: tratar compensa"))) -> Custo menor ou igual à perda esperada: tratar compensa | BK11: 16 | BL11: PCN-SS-01 (redistribuir ordens para SS-002) | BW11: =IF($BU11="","",IFERROR(INDEX(SgaProbValor,MATCH($BU11,SgaProbNivel,0)),"")) | BX11: =IF($BV11="","",IFERROR(INDEX(SgaSevRiValor,MATCH($BV11,SgaSevRiNivel,0)),"")) | BY11: =IF(COUNT($BW11:$BX11)=2,$BW11*$BX11,"") | BZ11: =IF($BY11="","",IF($BY11<=SgaLimRiSig,"SIGNIFICATIVO",IF($BY11<=SgaLimRiTol,"TOLERÁVEL","BAIXO"))) | CA11: =IF($BZ11="","",IF($BZ11="SIGNIFICATIVO","NÃO ACEITÁVEL","ACEITÁVEL")) | CG11: =IF(OR($CE11="",$CF11=""),"",IFERROR(INDEX(SgaProbValor,MATCH($CE11,SgaProbNivel,0))*INDEX(SgaSevRiValor,MATCH($CF11,SgaSevRiNivel,0)),"")) | CH11: =IF($CG11="","",IF($CG11<=SgaLimRiSig,"SIGNIFICATIVO",IF($CG11<=SgaLimRiTol,"TOLERÁVEL","BAIXO")))
