Workbook
Name DataRef: Listas!$A$3
Name lst_Classificacao: Listas!$E$3:$E$5
Name lst_CondicaoAmbiental: Listas!$C$3:$C$8
Name lst_Cruzamento: Listas!$O$3:$O$6
Name lst_DataReferencia: Listas!$A$3:$A$3
Name lst_Dimensao: Listas!$B$3:$B$8
Name lst_Direcao: Listas!$D$3:$D$6
Name lst_Escala13: Listas!$H$3:$H$5
Name lst_ESG: Listas!$M$3:$M$7
Name lst_Funcao: Listas!$N$3:$N$24
Name lst_Horizonte: Listas!$G$3:$G$5
Name lst_PI_Cond: Listas!$Q$3:$Q$8
Name lst_PI_Nivel: Listas!$S$3:$S$5
Name lst_PI_Obrig: Listas!$T$3:$T$5
Name lst_PI_SimNao: Listas!$R$3:$R$4
Name lst_PI_Tipo: Listas!$P$3:$P$4
Name lst_Processo: Listas!$K$3:$K$18
Name lst_Quadrante: Listas!$I$3:$I$6
Name lst_SimNao: Listas!$J$3:$J$4
Name lst_Tema: Listas!$L$3:$L$18
Name lst_Tendencia: Listas!$F$3:$F$5

Sheet 00_LEIA-ME
A1: RG-SGA-01 — Contexto da Organização — PESTEL, SWOT, Partes Interessadas, 5 Forças e TOWS (SGA e SGI)
A2: Sistema de Gestão Ambiental NP EN ISO 14001:2026 · Plasticom — Unidade 1 (Marinha Grande, Portugal) · Registo do SGA (fábrica simulada)
A4: CONTROLO DO DOCUMENTO (7.5 — informação documentada)
A5: Código do registo | B5: RG-SGA-01
A6: Título | B6: Contexto da Organização — PESTEL, SWOT, Partes Interessadas, 5 Forças e TOWS (SGA e SGI)
A7: Versão / Revisão | B7: 01
A8: Data de emissão | B8: 46387
A9: Elaborado por | B9: Gestor(a) do SGA / EHS
A10: Aprovado por | B10: Diretor Geral
A11: Estado | B11: Em vigor
A12: Retenção | B12: 5 anos após substituição
A13: Localização | B13: Repositório controlado do SGA > Registos_SGA_Plasticom (versão eletrónica é a versão controlada; cópias impressas são não controladas)
A15: FINALIDADE E ÂMBITO
A16: Finalidade | B16: Registar as questões externas (PESTEL) e internas/externas (SWOT) relevantes para o SGA, incluindo a dupla perspetiva exigida pela ISO 14001:2026 (condições ambientais afetadas pela organização e que a afetam). Cada fraqueza, oportunidade e ameaça é convertida num risco ou oportunidade do registo RG-SGA-02.
A17: Atividades do curso | B17: Base da Atividade 3.1 (recuperação da SWOT da Atividade 2.1). Contexto 4.1/4.2.
A18: Requisitos ISO 14001:2026 | B18: 4.1 (questões externas/internas e condições ambientais: clima, poluição, recursos naturais, biodiversidade, saúde dos ecossistemas); 4.2; 6.1.4
A20: ESTRUTURA DO FICHEIRO
A21: PESTEL | B21: Registo das questões externas (PESTEL) com a dupla perspetiva ambiental da ISO 14001:2026.
A22: SWOT | B22: Registo SWOT (formato longo: um item por linha). Coluna Selecionado_Atv_3_1 marca os 4 itens da Atividade 3.1.
A23: Matriz_TOWS | B23: Cruzamento estratégico SWOT (TOWS) que liga o contexto aos objetivos ambientais e aos riscos do SGI.
A24: Cinco_Forcas | B24: Cinco forças competitivas (Porter) do sistema integrado, com ligação aos riscos/oportunidades do RG-SGA-02.
A25: Vista_SWOT | B25: Quadro SWOT 2×2 para impressão, calculado por fórmulas a partir de tbl_swot (não editar aqui).
A26: Partes_Interessadas | B26: Partes interessadas, necessidades e expectativas (incl. condições ambientais) e decisão sobre obrigações de conformidade (4.2).
A27: Listas | B27: Domínios (listas de valores) usados na validação de dados das tabelas.
A28: Dicionario_Dados | B28: Descrição de cada coluna de cada tabela: tipo, origem (entrada/calculado), domínio, obrigatoriedade e chaves.
A30: CONVENÇÕES (prontas para análise de dados e machine learning)
A31: Tabelas | B31: Cada registo é uma Tabela Excel com nome próprio (tbl_*): uma linha = um registo, cabeçalho único, sem células mescladas. Ler com pandas (pd.read_excel(ficheiro, sheet_name=folha, header=<linha do cabeçalho - 1>)) ou Power BI (Obter Dados > Tabela).
A32: Cabeçalho cinzento | B32: Coluna CALCULADA por fórmula — não escrever por cima. As restantes colunas são de entrada.
A33: Validação | B33: Colunas com lista controlada só aceitam valores da folha Listas (evita categorias duplicadas por grafia diferente).
A34: Chaves | B34: IDs estáveis e únicos (PK) e referências a IDs de outros registos (FK) permitem juntar tabelas entre ficheiros — ver SGA-00_Indice_Modelo_Dados.xlsx.
A35: Datas e unidades | B35: Datas em formato data (aaaa-mm-dd); números como números; a unidade está no nome da coluna ou no dicionário. Data de referência do SGA: 2026-12-31 (fecho do ano).
A36: Dados simulados | B36: Fábrica simulada Plasticom. Dados operacionais derivados do dataset do projeto (datasets/silver); dados ambientais e de conformidade são simulação didática — confirmar aplicabilidade legal e números antes de uso real.
A38: LIGAÇÕES A OUTROS REGISTOS
A39: RG-SGA-02 Riscos e Oportunidades | B39: Coluna ID_RO liga ao risco ambiental (RO-xx); IDs_Risco_SGI liga aos riscos/oportunidades do registo corporativo (R-nn / O-nn).
A40: Fonte única do contexto | B40: Desde 24/09/2026 o contexto do sistema integrado (qualidade, SST e ambiente) regista-se só aqui; o RG-SGA-02 deixou de ter PESTEL/SWOT/partes interessadas/5 forças/TOWS próprios.
A41: RG-SGA-05 Objetivos | B41: A Matriz TOWS aponta os objetivos ambientais (OBJ-xx) derivados do cruzamento estratégico.

Sheet PESTEL
A1: ID_PESTEL | B1: Dimensao | C1: Fator_Externo | D1: Descricao | E1: Condicao_Ambiental_ISO2026 | F1: Direcao_Efeito | G1: Efeito_no_SGA | H1: Classificacao | I1: Tendencia | J1: Horizonte | K1: Probabilidade_1a3 | L1: Impacto_1a3 | M1: Score | N1: Prioridade | O1: Fonte_Monitorizacao | P1: Resposta_Estrategica | Q1: ID_SWOT | R1: ID_RO | S1: Parte_Interessada | T1: Tema | U1: ESG | V1: Dono | W1: Data_Avaliacao | X1: Proxima_Revisao | Y1: Ambito | Z1: IDs_Risco_SGI
A2: PES-01 | B2: Político | C2: Pacto Ecológico Europeu, Clean Industrial Deal e PNEC 2030 | D2: Metas europeias e nacionais de descarbonização e economia circular aumentam a exigência sobre emissões e eficiência da indústria. | E2: Clima | F2: Bidirecional | G2: Exige inventário de GEE e metas de redução no SGA. | H2: Risco e Oportunidade | I2: Crescente | J2: Médio (1-3 anos) | K2: 3 | L2: 2 | M2: =K2*L2 -> 6 | N2: =IF(M2>=6,"Alta",IF(M2>=3,"Média","Baixa")) -> Alta | O2: Comissão Europeia; APA; associação setorial (APIP) | P2: Inventário GEE âmbitos 1-2 e plano de eficiência energética. | Q2: SWT-F02 | R2: RO-09 | S2: Governo / reguladores | T2: Clima / GEE | U2: E + G | V2: Diretor Geral (Gestão de Topo) | W2: 46097 | X2: =EDATE(W2,12) -> 46462 | Y2: SGA | Z2: R33; O5
A3: PES-02 | B3: Económico | C3: Volatilidade do preço da eletricidade | D3: Injeção e sopro são eletrointensivos (≈ 7 GWh/ano); variações de preço afetam margem e retorno de projetos de eficiência. | E3: Não aplicável | F3: Não aplicável | G3: Aumenta o retorno financeiro das ações de eficiência energética. | H3: Risco | I3: Estável | J3: Curto (<1 ano) | K3: 3 | L3: 3 | M3: =K3*L3 -> 9 | N3: =IF(M3>=6,"Alta",IF(M3>=3,"Média","Baixa")) -> Alta | O3: Faturas; OMIE; Financeiro | P3: Submedição, caça a fugas de ar comprimido e avaliação de PPA/fotovoltaico. | Q3: SWT-W01 | R3: RO-02 | S3: Acionistas / Gerência | T3: Energia | U3: E + G | V3: Diretor Financeiro | W3: 46097 | X3: =EDATE(W3,12) -> 46462 | Y3: SGA | Z3: R25
A4: PES-03 | B4: Económico | C4: Preço e disponibilidade de PCR / rPET | D4: Prémio de preço do reciclado face ao virgem e oferta limitada de PCR de qualidade alimentar. | E4: Recursos naturais | F4: Ambiente → Organização | G4: Condiciona metas de conteúdo reciclado e pode aumentar o scrap. | H4: Risco | I4: Crescente | J4: Médio (1-3 anos) | K4: 3 | L4: 2 | M4: =K4*L4 -> 6 | N4: =IF(M4>=6,"Alta",IF(M4>=3,"Média","Baixa")) -> Alta | O4: Compras; fornecedores SUP-004/SUP-002; índices de mercado | P4: Qualificar múltiplas fontes e ensaios DOE de materiais antes de mudar de fornecedor. | Q4: SWT-T02 | R4: RO-05 | S4: Fornecedores | T4: Materiais e circularidade | U4: E + G | V4: Diretor Financeiro | W4: 46097 | X4: =EDATE(W4,12) -> 46462 | Y4: SGA | Z4: R14
A5: PES-04 | B5: Social | C5: Clientes exigem embalagem circular e dados ambientais | D5: Marcas de cosmética, alimentar e farmacêutica pedem conteúdo reciclado, reciclabilidade, pegada de carbono e respostas a questionários ESG (CSRD/ESRS da cadeia de valor). | E5: Recursos naturais | F5: Organização → Ambiente | G5: Transforma dados ambientais em requisito comercial. | H5: Oportunidade | I5: Crescente | J5: Curto (<1 ano) | K5: 3 | L5: 3 | M5: =K5*L5 -> 9 | N5: =IF(M5>=6,"Alta",IF(M5>=3,"Média","Baixa")) -> Alta | O5: Pedidos de clientes; auditorias de clientes; questionários | P5: Programa Design for Recycling e ficha ambiental por família de produto. | Q5: SWT-O01 | R5: RO-03 | S5: Clientes europeus | T5: Produto / embalagem | U5: E + S + G | V5: Gestor do SGA / EHS (Responsável Ambiental) | W5: 46097 | X5: =EDATE(W5,12) -> 46462 | Y5: SGA | Z5: O5
A6: PES-05 | B6: Social | C6: Sensibilidade da comunidade a ruído e tráfego | D6: Zona industrial de Marinha Grande com habitações a ~250 m; compressores e camiões noturnos são fonte potencial de reclamações. | E6: Poluição | F6: Organização → Ambiente | G6: Exige avaliação acústica e canal de reclamações. | H6: Risco | I6: Estável | J6: Médio (1-3 anos) | K6: 2 | L6: 2 | M6: =K6*L6 -> 4 | N6: =IF(M6>=6,"Alta",IF(M6>=3,"Média","Baixa")) -> Média | O6: Registo de reclamações; Câmara Municipal | P6: Avaliação de ruído no recetor e janelas de expedição. | Q6: SWT-W04 | R6: RO-10 | S6: Vizinhança / comunidade local | T6: Ruído | U6: E + S | V6: Gestor do SGA / EHS (Responsável Ambiental) | W6: 46097 | X6: =EDATE(W6,12) -> 46462 | Y6: SGA
A7: PES-06 | B7: Tecnológico | C7: Monitorização digital, IoT e analytics | D7: Sensores de energia/caudal de baixo custo, integração no BI e IA permitem gestão ambiental em tempo quase real (reforçado pela ISO 14001:2026). | E7: Não aplicável | F7: Não aplicável | G7: Permite medir desempenho e eficácia do SGA (9.1.1). | H7: Oportunidade | I7: Crescente | J7: Curto (<1 ano) | K7: 3 | L7: 2 | M7: =K7*L7 -> 6 | N7: =IF(M7>=6,"Alta",IF(M7>=3,"Média","Baixa")) -> Alta | O7: Fornecedores de automação; Data/TI | P7: Integrar dados ambientais no modelo de dados industrial. | Q7: SWT-F01 | R7: RO-01 | S7: Acionistas / Gerência | T7: Governação e dados | U7: E + G | V7: Diretor Industrial | W7: 46097 | X7: =EDATE(W7,12) -> 46462 | Y7: SGA | Z7: O3; O13
A8: PES-07 | B8: Tecnológico | C8: Design for recycling, monomaterial e redução de peso | D8: Tecnologias de lightweighting e embalagens monomaterial PP/PE facilitam a reciclagem e reduzem polímero por unidade. | E8: Recursos naturais | F8: Organização → Ambiente | G8: Reduz impacte a montante e no fim de vida. | H8: Oportunidade | I8: Crescente | J8: Médio (1-3 anos) | K8: 2 | L8: 3 | M8: =K8*L8 -> 6 | N8: =IF(M8>=6,"Alta",IF(M8>=3,"Média","Baixa")) -> Alta | O8: R&D; RecyClass; clientes | P8: Revisão de design das famílias prioritárias. | Q8: SWT-O01 | R8: RO-03 | S8: Clientes europeus | T8: Produto / embalagem | U8: E + G | V8: Diretor Industrial | W8: 46097 | X8: =EDATE(W8,12) -> 46462 | Y8: SGA
A9: PES-08 | B9: Ambiental | C9: Ondas de calor mais frequentes | D9: Verões mais quentes aumentam a carga térmica dos moldes, o consumo do chiller e a evaporação da torre de arrefecimento. | E9: Clima | F9: Ambiente → Organização | G9: Aumenta consumo de energia e água no verão; risco para qualidade e continuidade. | H9: Risco | I9: Crescente | J9: Médio (1-3 anos) | K9: 3 | L9: 2 | M9: =K9*L9 -> 6 | N9: =IF(M9>=6,"Alta",IF(M9>=3,"Média","Baixa")) -> Alta | O9: IPMA; dados de consumo mensais | P9: Normalizar indicadores pela temperatura e reforçar capacidade de arrefecimento. | Q9: SWT-T01 | R9: RO-04 | S9: Acionistas / Gerência | T9: Clima / GEE | U9: E | V9: Gestor do SGA / EHS (Responsável Ambiental) | W9: 46097 | X9: =EDATE(W9,12) -> 46462 | Y9: SGA | Z9: R34
A10: PES-09 | B10: Ambiental | C10: Seca e escassez hídrica na região Centro | D10: Períodos de seca prolongada podem levar a restrições de uso de água de rede pela entidade gestora. | E10: Recursos naturais | F10: Bidirecional | G10: Exige eficiência hídrica e plano de contingência para água de arrefecimento. | H10: Risco | I10: Crescente | J10: Longo (>3 anos) | K10: 2 | L10: 2 | M10: =K10*L10 -> 4 | N10: =IF(M10>=6,"Alta",IF(M10>=3,"Média","Baixa")) -> Média | O10: APA (monitorização de seca); entidade gestora de água | P10: Circuito fechado de arrefecimento e reservatório de reserva. | Q10: SWT-T01 | R10: RO-04 | S10: Vizinhança / comunidade local | T10: Água e efluentes | U10: E + S | V10: Gestor do SGA / EHS (Responsável Ambiental) | W10: 46097 | X10: =EDATE(W10,12) -> 46462 | Y10: SGA | Z10: R34
A11: PES-10 | B11: Ambiental | C11: Risco de incêndio rural na envolvente florestal | D11: Proximidade ao Pinhal de Leiria (Mata Nacional afetada pelo grande incêndio de 2017); um incêndio na fábrica pode atingir a floresta e vice-versa. | E11: Biodiversidade | F11: Bidirecional | G11: Cenário de emergência com impacte em ecossistemas e continuidade. | H11: Risco | I11: Crescente | J11: Médio (1-3 anos) | K11: 2 | L11: 3 | M11: =K11*L11 -> 6 | N11: =IF(M11>=6,"Alta",IF(M11>=3,"Média","Baixa")) -> Alta | O11: ANEPC; ICNF; Plano de Emergência Interno | P11: Faixa de gestão de combustível, retenção de águas de combate e simulacros. | Q11: SWT-T01 | R11: RO-08 | S11: Vizinhança / comunidade local | T11: Biodiversidade e ecossistemas | U11: E + S | V11: Gestor do SGA / EHS (Responsável Ambiental) | W11: 46097 | X11: =EDATE(W11,12) -> 46462 | Y11: SGA
A12: PES-11 | B12: Ambiental | C12: Poluição por microplásticos (perdas de granulado) | D12: Granulado perdido na descarga de silos e big bags pode chegar à rede pluvial, ao rio Lis e à costa, afetando ecossistemas aquáticos. | E12: Saúde dos ecossistemas | F12: Organização → Ambiente | G12: Novo aspeto ambiental significativo e requisito legal emergente. | H12: Risco | I12: Crescente | J12: Curto (<1 ano) | K12: 2 | L12: 3 | M12: =K12*L12 -> 6 | N12: =IF(M12>=6,"Alta",IF(M12>=3,"Média","Baixa")) -> Alta | O12: ONG; Operation Clean Sweep; regulamento UE sobre granulados | P12: Programa de contenção de granulado (OCS) e inspeção de sarjetas. | Q12: SWT-W04 | R12: RO-07 | S12: Vizinhança / comunidade local | T12: Perdas de granulado (microplásticos) | U12: E + S + G | V12: Gestor do SGA / EHS (Responsável Ambiental) | W12: 46097 | X12: =EDATE(W12,12) -> 46462 | Y12: SGA
A13: PES-12 | B13: Legal | C13: PPWR — Regulamento (UE) 2025/40 aplicável desde 12/08/2026 | D13: Obrigações do fabricante de embalagens: documentação técnica, declaração UE de conformidade, limites de substâncias preocupantes, metas de conteúdo reciclado e reciclabilidade. | E13: Recursos naturais | F13: Organização → Ambiente | G13: Obrigação de conformidade nova com impacto comercial direto. | H13: Risco e Oportunidade | I13: Crescente | J13: Curto (<1 ano) | K13: 3 | L13: 3 | M13: =K13*L13 -> 9 | N13: =IF(M13>=6,"Alta",IF(M13>=3,"Média","Baixa")) -> Alta | O13: EUR-Lex; APA; clientes | P13: Dossier técnico por família e plano de conformidade PPWR. | Q13: SWT-O01 | R13: RO-06 | S13: Clientes europeus | T13: Legal / conformidade | U13: E + G | V13: Gestor do SGA / EHS (Responsável Ambiental) | W13: 46097 | X13: =EDATE(W13,12) -> 46462 | Y13: SGA
A14: PES-13 | B14: Legal | C14: Regulamento da UE sobre prevenção de perdas de granulados de plástico | D14: Adotado em 2025: obrigações de avaliação de risco, plano de gestão, contenção e (para grandes empresas) certificação por terceiros — confirmar n.º e datas de aplicação no EUR-Lex. | E14: Saúde dos ecossistemas | F14: Organização → Ambiente | G14: Antecipar requisitos antes da data de aplicação. | H14: Risco | I14: Crescente | J14: Médio (1-3 anos) | K14: 3 | L14: 2 | M14: =K14*L14 -> 6 | N14: =IF(M14>=6,"Alta",IF(M14>=3,"Média","Baixa")) -> Alta | O14: EUR-Lex; Plastics Europe | P14: Autoavaliação OCS e plano de contenção por ponto crítico. | Q14: SWT-W04 | R14: RO-07 | S14: Governo / reguladores | T14: Perdas de granulado (microplásticos) | U14: E + G | V14: Gestor do SGA / EHS (Responsável Ambiental) | W14: 46097 | X14: =EDATE(W14,12) -> 46462 | Y14: SGA
A15: PES-14 | B15: Legal | C15: Fiscalização de resíduos (RGGR, e-GAR, MIRR) | D15: Fiscalização da IGAMAOT/APA sobre classificação LER, e-GAR e reporte anual MIRR. | E15: Poluição | F15: Organização → Ambiente | G15: Exige rastreabilidade completa dos resíduos. | H15: Risco | I15: Estável | J15: Curto (<1 ano) | K15: 2 | L15: 2 | M15: =K15*L15 -> 4 | N15: =IF(M15>=6,"Alta",IF(M15>=3,"Média","Baixa")) -> Média | O15: APA/SILiAmb; IGAMAOT | P15: Pesagem por código LER e verificação mensal das e-GAR. | Q15: SWT-W04 | R15: RO-10 | S15: Governo / reguladores | T15: Resíduos | U15: E + G | V15: Gestor do SGA / EHS (Responsável Ambiental) | W15: 46097 | X15: =EDATE(W15,12) -> 46462 | Y15: SGA | Z15: R31
A16: PES-15 | B16: Legal | C16: Alegações ambientais (Diretiva (UE) 2024/825) | D16: Proibição de alegações ambientais genéricas não comprovadas; clientes pedem prova de conteúdo reciclado e reciclabilidade. | E16: Não aplicável | F16: Não aplicável | G16: Exige evidência verificável para qualquer declaração ambiental de produto. | H16: Risco | I16: Crescente | J16: Curto (<1 ano) | K16: 2 | L16: 2 | M16: =K16*L16 -> 4 | N16: =IF(M16>=6,"Alta",IF(M16>=3,"Média","Baixa")) -> Média | O16: EUR-Lex; clientes | P16: Só comunicar alegações com certificação (EuCertPlast/RecyClass). | Q16: SWT-W02 | R16: RO-05 | S16: Clientes europeus | T16: Produto / embalagem | U16: G | V16: Gestor do SGA / EHS (Responsável Ambiental) | W16: 46097 | X16: =EDATE(W16,12) -> 46462 | Y16: SGA
A17: PES-16 | B17: Social | C17: Cultura de produtividade e passagem de turno | D17: Pressão por meta, passagem de turno e relato de quase-acidentes ainda fraco no chão de fábrica. | E17: Não aplicável | F17: Não aplicável | G17: Fadiga e handover elevam a rejeição do turno 2 (mais scrap) e escondem quase-acidentes. | H17: Risco | I17: Estável | J17: Curto (<1 ano) | K17: 2 | L17: 2 | M17: =K17*L17 -> 4 | N17: =IF(M17>=6,"Alta",IF(M17>=3,"Média","Baixa")) -> Média | O17: Rejeição por turno; registo de quase-acidentes | P17: Estudo de handover e registo de quase-acidentes sem culpa. | S17: Colaboradores | T17: Governação e dados | U17: S + G | V17: Gestor do SGA / EHS (Responsável Ambiental) | W17: 46097 | X17: =EDATE(W17,12) -> 46462 | Y17: SGI | Z17: R9; R28
A18: PES-17 | B18: Legal | C18: Recursos hídricos, químicos (REACH/CLP) e SST | D18: Títulos de utilização de recursos hídricos, condições de descarga, REACH/CLP e legislação de SST sobre agentes químicos. | E18: Poluição | F18: Organização → Ambiente | G18: Cria obrigações de autorização, controlo e reporte (RG-SGA-04 LEG-03, LEG-06, LEG-22). | H18: Risco | I18: Crescente | J18: Curto (<1 ano) | K18: 3 | L18: 3 | M18: =K18*L18 -> 9 | N18: =IF(M18>=6,"Alta",IF(M18>=3,"Média","Baixa")) -> Alta | O18: Matriz legal (RG-SGA-04); RG-SGA-21 | P18: Calendário de conformidade, verificação documental e gestão de químicos (PR-SGA-16). | Q18: SWT-T03 | R18: RO-10 | S18: APA / CCDR Centro | T18: Legal / conformidade | U18: E + G | V18: Gestor do SGA / EHS (Responsável Ambiental) | W18: 46097 | X18: =EDATE(W18,12) -> 46462 | Y18: SGI | Z18: R29; R30; R32
A19: PES-18 | B19: Legal | C19: Requisitos de clientes (Cpk, rastreabilidade) e normas ISO 9001/14001/45001 | D19: Clientes exigem capacidade de processo demonstrada, rastreabilidade ponta a ponta e sistemas de gestão certificados. | E19: Não aplicável | F19: Não aplicável | G19: Pressão por dados fiáveis e rastreabilidade, que também servem o SGA. | H19: Risco | I19: Crescente | J19: Médio (1-3 anos) | K19: 3 | L19: 2 | M19: =K19*L19 -> 6 | N19: =IF(M19>=6,"Alta",IF(M19>=3,"Média","Baixa")) -> Alta | O19: Contratos; requisitos de clientes; auditorias | P19: Estratificar Cpk por máquina × molde e fechar a rastreabilidade. | Q19: SWT-T04 | S19: Clientes de cosmética (marcas UE) | T19: Governação e dados | U19: S + G | V19: Gestor do SGA / EHS (Responsável Ambiental) | W19: 46097 | X19: =EDATE(W19,12) -> 46462 | Y19: SGI | Z19: R17; R18
A20: PES-19 | B20: Económico | C20: Operação ibérica com clientes na UE (43% da receita fora de Portugal) | D20: Cadeia de abastecimento na Península Ibérica e clientes em vários países da UE com requisitos diferentes. | E20: Não aplicável | F20: Não aplicável | G20: Variação regulatória por país (ex.: RAP de embalagens) e pressão dos requisitos dos clientes. | H20: Risco | I20: Estável | J20: Médio (1-3 anos) | K20: 2 | L20: 2 | M20: =K20*L20 -> 4 | N20: =IF(M20>=6,"Alta",IF(M20>=3,"Média","Baixa")) -> Média | O20: Contratos; RG-SGA-20 tbl_requisitos_pais | P20: Critérios mínimos comuns e análise por país e cliente. | S20: Clientes de cosmética (marcas UE) | T20: Produto / embalagem | U20: E + G | V20: Diretor Financeiro | W20: 46097 | X20: =EDATE(W20,12) -> 46462 | Y20: SGI | Z20: R33; O5
A21: PES-20 | B21: Económico | C21: Sazonalidade da procura (pico set–nov) e concorrência por preço | D21: Procura de cosmética e higiene pessoal com pico previsível em setembro–novembro e margem pressionada (≈ € 0,13/un). | E21: Não aplicável | F21: Não aplicável | G21: O pico de velocidade (+15%) aumenta defeitos e scrap; permite planeamento antecipado. | H21: Risco e Oportunidade | I21: Estável | J21: Curto (<1 ano) | K21: 2 | L21: 2 | M21: =K21*L21 -> 4 | N21: =IF(M21>=6,"Alta",IF(M21>=3,"Média","Baixa")) -> Média | O21: Vendas; histórico de duas temporadas | P21: Planeamento de capacidade e stock de segurança antes do pico. | Q21: SWT-O05 | S21: Acionistas / Direção | T21: Materiais e circularidade | U21: S + G | V21: Diretor Financeiro | W21: 46097 | X21: =EDATE(W21,12) -> 46462 | Y21: SGI | Z21: O14; R15

Sheet SWOT
A1: ID_SWOT | B1: Quadrante | C1: Natureza | D1: Descricao | E1: Evidencia | F1: Implicacao_SGA | G1: Processo | H1: Tema | I1: ID_PESTEL | J1: Converte_em | K1: ID_RO | L1: Selecionado_Atv_3_1 | M1: Estrategia | N1: Indicador | O1: Data_Avaliacao | P1: Chave_Vista | Q1: Ambito | R1: IDs_Risco_SGI
A2: SWT-F01 | B2: Força | C2: =IF(OR(B2="Força",B2="Fraqueza"),"Interno","Externo") -> Interno | D2: Cultura de dados industriais: OEE, SPC, AQL e rastreabilidade lote → ordem em 18 meses de dados (22 máquinas, 3 turnos) já integrados em Power BI. | E2: Dataset do projeto (datasets/silver); dashboards de produção e qualidade. | F2: Permite construir rapidamente indicadores ambientais por máquina, turno e lote. | G2: GER | H2: Governação e dados | I2: PES-06 | J2: Oportunidade | K2: RO-01 | L2: Sim | M2: Integrar consumos de energia, água e resíduos no modelo de dados industrial. | N2: N.º de KPIs ambientais com dados automáticos | O2: 46097 | P2: =B2&"|"&COUNTIF(INDEX($B$2:$B$24,1):B2,B2) -> Força|1 | Q2: SGA | R2: O3
A3: SWT-F02 | B3: Força | C3: =IF(OR(B3="Força",B3="Fraqueza"),"Interno","Externo") -> Interno | D3: Processo 100% elétrico: sem caldeiras nem combustão in situ; empilhadores elétricos. | E3: Inventário de equipamentos; faturas (sem gás natural). | F3: Emissões diretas (âmbito 1) muito baixas; descarbonização depende da eletricidade. | G3: GER | H3: Clima / GEE | I3: PES-01 | J3: Oportunidade | K3: RO-09 | L3: Não | M3: Contratar eletricidade com garantia de origem renovável / fotovoltaico. | N3: % energia renovável | O3: 46097 | P3: =B3&"|"&COUNTIF(INDEX($B$2:$B$24,1):B3,B3) -> Força|2 | Q3: SGA
A4: SWT-F03 | B4: Força | C4: =IF(OR(B4="Força",B4="Fraqueza"),"Interno","Externo") -> Interno | D4: Moinhos junto às máquinas permitem reintegrar rebarbas e jitos (regrind) no próprio processo. | E4: Registos de moagem; boas práticas de produção. | F4: Reduz consumo de polímero virgem e resíduos plásticos enviados para fora. | G4: MOA | H4: Materiais e circularidade | J4: Oportunidade | K4: RO-11 | L4: Não | M4: Segregar scrap limpo por polímero/cor para aumentar a taxa de reintegração. | N4: % scrap reintegrado | O4: 46097 | P4: =B4&"|"&COUNTIF(INDEX($B$2:$B$24,1):B4,B4) -> Força|3 | Q4: SGA
A5: SWT-F04 | B5: Força | C5: =IF(OR(B5="Força",B5="Fraqueza"),"Interno","Externo") -> Interno | D5: Experiência com resinas PCR (HDPE-PCR, rPET) e entrada em mercados alimentar e farmacêutico (2026). | E5: Portefólio FR-002-HDPE-PCR, rPET; clientes CUST-015 a CUST-018. | F5: Base técnica para responder às metas de conteúdo reciclado. | G5: RD | H5: Materiais e circularidade | I5: PES-04 | J5: Oportunidade | K5: RO-03 | L5: Não | M5: Oferecer gama com conteúdo reciclado certificado. | N5: % vendas com PCR | O5: 46097 | P5: =B5&"|"&COUNTIF(INDEX($B$2:$B$24,1):B5,B5) -> Força|4 | Q5: SGA
A6: SWT-F05 | B6: Força | C6: =IF(OR(B6="Força",B6="Fraqueza"),"Interno","Externo") -> Interno | D6: Processos identificados e rastreáveis: 4 processos, 18 máquinas, LotId e ProductBatch consistentes. | E6: Dataset do projeto (lotes e ordens). | F6: Facilita ligar aspetos, riscos e KPI por processo. | G6: GER | H6: Governação e dados | J6: Oportunidade | L6: Não | M6: Matriz aspeto → KPI → ação e rastreabilidade ponta a ponta (O12). | N6: % de aspetos com KPI | O6: 46097 | P6: =B6&"|"&COUNTIF(INDEX($B$2:$B$24,1):B6,B6) -> Força|5 | Q6: SGI | R6: O12
A7: SWT-F06 | B7: Força | C7: =IF(OR(B7="Força",B7="Fraqueza"),"Interno","Externo") -> Interno | D7: Causas-raiz conhecidas com evidência causal forte (IM-002 com MSA e DOE; SS-001 e M-SOP-007 respondem à intervenção). | E7: Estudos DOE/MSA; registo de riscos R1–R8. | F7: Ações de alta confiança reduzem refugo, refação e o desperdício de polímero e energia. | G7: INJ | H7: Materiais e circularidade | J7: Oportunidade | L7: Não | M7: Replicar a janela validada e a manutenção por condição (O1, O2). | N7: Short shot IM-002 (DPMO); lotes refeitos | O7: 46097 | P7: =B7&"|"&COUNTIF(INDEX($B$2:$B$24,1):B7,B7) -> Força|6 | Q7: SGI | R7: O1; O2
A8: SWT-F07 | B8: Força | C8: =IF(OR(B8="Força",B8="Fraqueza"),"Interno","Externo") -> Interno | D8: Base de fornecedores diversificada: 7 de 8 fornecedores de resina com contrato anual ou plurianual. | E8: RG-SGA-11 tbl_fornecedores. | F8: Reduz a dependência do fornecedor spot e facilita exigir dados ambientais. | G8: CMP | H8: Cadeia de valor / fornecedores | J8: Oportunidade | L8: Não | M8: Consolidar contratos e scorecard (O8). | N8: % de lotes não aceites por fornecedor | O8: 46097 | P8: =B8&"|"&COUNTIF(INDEX($B$2:$B$24,1):B8,B8) -> Força|7 | Q8: SGI | R8: O8
A9: SWT-W01 | B9: Fraqueza | C9: =IF(OR(B9="Força",B9="Fraqueza"),"Interno","Externo") -> Interno | D9: Não existe submedição de energia nem de água por processo ou máquina: os consumos só são conhecidos pela fatura global mensal. | E9: Fatura única de eletricidade e água; ausência de contadores parciais. | F9: Impede baselines por processo, metas robustas e prova de eficácia das ações (9.1.1). | G9: UTL | H9: Energia | I9: PES-02 | J9: Risco | K9: RO-02 | L9: Sim | M9: Instalar analisadores de energia e contadores de água nos principais consumidores. | N9: % do consumo com submedição | O9: 46097 | P9: =B9&"|"&COUNTIF(INDEX($B$2:$B$24,1):B9,B9) -> Fraqueza|1 | Q9: SGA | R9: O6; R28; R34
A10: SWT-W02 | B10: Fraqueza | C10: =IF(OR(B10="Força",B10="Fraqueza"),"Interno","Externo") -> Interno | D10: Dependência do fornecedor spot SUP-005 (PP/PVC) com lotes fora de especificação. | E10: Registos de inspeção de receção e reclamações a fornecedores. | F10: Mais scrap, retrabalho e alegações ambientais pouco fiáveis. | G10: CMP | H10: Cadeia de valor / fornecedores | I10: PES-15 | J10: Risco | K10: RO-05 | L10: Não | M10: Avaliação ambiental e de qualidade de fornecedores; migrar volumes para contratos. | N10: % compras a fornecedores avaliados | O10: 46097 | P10: =B10&"|"&COUNTIF(INDEX($B$2:$B$24,1):B10,B10) -> Fraqueza|2 | Q10: SGA | R10: R13; R6
A11: SWT-W03 | B11: Fraqueza | C11: =IF(OR(B11="Força",B11="Fraqueza"),"Interno","Externo") -> Interno | D11: Taxa de rejeição ≈ 2,4% acima da meta de 2,0% e 31% de CAPA não eficazes. | E11: fact_production / fact_capa do projeto. | F11: Cada peça rejeitada desperdiça polímero, energia e água. | G11: GER | H11: Materiais e circularidade | J11: Risco | K11: RO-11 | L11: Não | M11: Ligar a redução de scrap ao objetivo ambiental OBJ-02. | N11: kg scrap / 1.000 un | O11: 46097 | P11: =B11&"|"&COUNTIF(INDEX($B$2:$B$24,1):B11,B11) -> Fraqueza|3 | Q11: SGA | R11: R20
A12: SWT-W04 | B12: Fraqueza | C12: =IF(OR(B12="Força",B12="Fraqueza"),"Interno","Externo") -> Interno | D12: Gestão informal da contenção de químicos, kits de derrame e granulado (sem registo de utilização nem stock mínimo). | E12: Rondas ambientais; NC-SGA-26-03. | F12: Risco de derrame não contido, perdas de granulado e não conformidade legal. | G12: ARQ | H12: Produtos químicos | I12: PES-11 | J12: Risco | K12: RO-07 | L12: Não | M12: Formalizar rondas, stock mínimo de kits e registo de incidentes. | N12: % rondas conformes | O12: 46097 | P12: =B12&"|"&COUNTIF(INDEX($B$2:$B$24,1):B12,B12) -> Fraqueza|4 | Q12: SGA | R12: R30
A13: SWT-W05 | B13: Fraqueza | C13: =IF(OR(B13="Força",B13="Fraqueza"),"Interno","Externo") -> Interno | D13: Dependência de dados de fornecedores: conteúdo reciclado, composição, carbono incorporado e reciclabilidade. | E13: Declarações incompletas (RG-SGA-21 tbl_declaracoes; RG-SGA-20). | F13: Risco de alegações ambientais incompletas e de lacunas PPWR/REACH. | G13: CMP | H13: Cadeia de valor / fornecedores | I13: PES-15 | J13: Risco | K13: RO-05 | L13: Não | M13: Questionário ESG e evidência documental (O7). | N13: % de fornecedores críticos avaliados | O13: 46097 | P13: =B13&"|"&COUNTIF(INDEX($B$2:$B$24,1):B13,B13) -> Fraqueza|5 | Q13: SGI | R13: O7; R33
A14: SWT-W06 | B14: Fraqueza | C14: =IF(OR(B14="Força",B14="Fraqueza"),"Interno","Externo") -> Interno | D14: Parâmetros críticos não registados e capacidade de processo marginal (0% dos 190 grupos com Cpk ≥ 1,33). | E14: Estudo de capacidade 2026. | F14: Impede indicadores antecedentes; mais rejeição = mais polímero e energia desperdiçados. | G14: GER | H14: Governação e dados | J14: Risco | L14: Não | M14: Instrumentar parâmetros e priorizar Cpk por Pareto. | N14: % de ordens com parâmetros registados | O14: 46097 | P14: =B14&"|"&COUNTIF(INDEX($B$2:$B$24,1):B14,B14) -> Fraqueza|6 | Q14: SGI | R14: R19; R17
A15: SWT-W07 | B15: Fraqueza | C15: =IF(OR(B15="Força",B15="Fraqueza"),"Interno","Externo") -> Interno | D15: Disponibilidade abaixo da meta (87,4%): paragens por operador, ar comprimido, matéria-prima e ativos específicos. | E15: OEE do dataset. | F15: Limita a capacidade sem nova máquina; paragens por ar comprimido ligam-se às fugas (energia). | G15: GER | H15: Energia | J15: Risco | L15: Não | M15: Programa integrado de paragens (O4). | N15: Disponibilidade da fábrica (%) | O15: 46097 | P15: =B15&"|"&COUNTIF(INDEX($B$2:$B$24,1):B15,B15) -> Fraqueza|7 | Q15: SGI | R15: R3; R22; R23; R15; O4
A16: SWT-O01 | B16: Oportunidade | C16: =IF(OR(B16="Força",B16="Fraqueza"),"Interno","Externo") -> Externo | D16: PPWR e procura de embalagens recicláveis com conteúdo reciclado por clientes europeus. | E16: Reg. (UE) 2025/40; pedidos de clientes 2026. | F16: Diferenciação comercial se a Plasticom demonstrar conformidade e desempenho. | G16: RD | H16: Produto / embalagem | I16: PES-12 | J16: Oportunidade | K16: RO-03 | L16: Sim | M16: Programa Design for Recycling com dossier técnico por família. | N16: % famílias avaliadas | O16: 46097 | P16: =B16&"|"&COUNTIF(INDEX($B$2:$B$24,1):B16,B16) -> Oportunidade|1 | Q16: SGA | R16: O5; R33
A17: SWT-O02 | B17: Oportunidade | C17: =IF(OR(B17="Força",B17="Fraqueza"),"Interno","Externo") -> Externo | D17: Autoconsumo fotovoltaico na cobertura (≈ 9.000 m² disponíveis) e contratos PPA renováveis. | E17: Estudo preliminar; área de cobertura. | F17: Reduz emissões do âmbito 2 e custo energético. | G17: UTL | H17: Energia | I17: PES-01 | J17: Oportunidade | K17: RO-09 | L17: Não | M17: Estudo de viabilidade de UPAC. | N17: MWh autoproduzidos | O17: 46097 | P17: =B17&"|"&COUNTIF(INDEX($B$2:$B$24,1):B17,B17) -> Oportunidade|2 | Q17: SGA
A18: SWT-O03 | B18: Oportunidade | C18: =IF(OR(B18="Força",B18="Fraqueza"),"Interno","Externo") -> Externo | D18: Financiamento público para eficiência energética e economia circular (Portugal 2030, Fundo Ambiental). | E18: Avisos de candidatura abertos. | F18: Reduz o payback dos investimentos ambientais. | G18: ADM | H18: Governação e dados | I18: PES-01 | J18: Oportunidade | K18: RO-09 | L18: Não | M18: Candidatar submedição + fotovoltaico. | N18: € financiados | O18: 46097 | P18: =B18&"|"&COUNTIF(INDEX($B$2:$B$24,1):B18,B18) -> Oportunidade|3 | Q18: SGA | R18: O6
A19: SWT-O04 | B19: Oportunidade | C19: =IF(OR(B19="Força",B19="Fraqueza"),"Interno","Externo") -> Externo | D19: Visão artificial, dados e rastreabilidade para prevenir perdas em vez de inspecionar. | E19: Business case de visão (RG-SGA-02 O13). | F19: Menos refugo e custo de avaliação. | G19: SER | H19: Governação e dados | I19: PES-06 | J19: Oportunidade | K19: RO-01 | L19: Não | M19: Business case de visão e painel de KRI (O13, O3). | N19: Custo de avaliação (€) | O19: 46097 | P19: =B19&"|"&COUNTIF(INDEX($B$2:$B$24,1):B19,B19) -> Oportunidade|4 | Q19: SGI | R19: O13; O3
A20: SWT-O05 | B20: Oportunidade | C20: =IF(OR(B20="Força",B20="Fraqueza"),"Interno","Externo") -> Externo | D20: Sazonalidade previsível da procura (pico set–nov). | E20: Histórico de vendas de duas temporadas. | F20: Planear capacidade e materiais evita picos de scrap. | G20: GER | H20: Materiais e circularidade | I20: PES-20 | J20: Oportunidade | L20: Não | M20: Planeamento de capacidade e materiais (O14). | N20: OTIF e rejeição em set–nov | O20: 46097 | P20: =B20&"|"&COUNTIF(INDEX($B$2:$B$24,1):B20,B20) -> Oportunidade|5 | Q20: SGI | R20: O14
A21: SWT-T01 | B21: Ameaça | C21: =IF(OR(B21="Força",B21="Fraqueza"),"Interno","Externo") -> Externo | D21: Ondas de calor e escassez hídrica (alterações climáticas) afetam o arrefecimento de moldes, a água técnica e a continuidade. | E21: Dados de consumo de verão; alertas de seca. | F21: Mais consumo de energia e água no verão; risco de paragem e de defeitos. | G21: UTL | H21: Clima / GEE | I21: PES-08 | J21: Risco | K21: RO-04 | L21: Sim | M21: Plano de adaptação climática: arrefecimento eficiente e reserva de água. | N21: m³/1.000 un no verão | O21: 46097 | P21: =B21&"|"&COUNTIF(INDEX($B$2:$B$24,1):B21,B21) -> Ameaça|1 | Q21: SGA | R21: R34
A22: SWT-T02 | B22: Ameaça | C22: =IF(OR(B22="Força",B22="Fraqueza"),"Interno","Externo") -> Externo | D22: Volatilidade de preço e qualidade do PCR/rPET. | E22: Mercado; reclamações a fornecedores. | F22: Pode limitar metas de conteúdo reciclado e aumentar scrap. | G22: CMP | H22: Materiais e circularidade | I22: PES-03 | J22: Risco | K22: RO-05 | L22: Não | M22: Qualificar múltiplas fontes certificadas. | N22: N.º fornecedores PCR qualificados | O22: 46097 | P22: =B22&"|"&COUNTIF(INDEX($B$2:$B$24,1):B22,B22) -> Ameaça|2 | Q22: SGA | R22: R14; R25
A23: SWT-T03 | B23: Ameaça | C23: =IF(OR(B23="Força",B23="Fraqueza"),"Interno","Externo") -> Externo | D23: Aumento da exigência regulatória (PPWR, granulados, resíduos) com risco de coimas e perda de clientes. | E23: Matriz legal RG-SGA-04. | F23: Obrigações novas exigem recursos e evidências. | G23: GER | H23: Legal / conformidade | I23: PES-12 | J23: Risco | K23: RO-06 | L23: Não | M23: Calendário legal e revisão trimestral da conformidade. | N23: % obrigações conformes | O23: 46097 | P23: =B23&"|"&COUNTIF(INDEX($B$2:$B$24,1):B23,B23) -> Ameaça|3 | Q23: SGA | R23: R31; R32; R29
A24: SWT-T04 | B24: Ameaça | C24: =IF(OR(B24="Força",B24="Fraqueza"),"Interno","Externo") -> Externo | D24: Clientes exigem Cpk, rastreabilidade e zero defeito, com risco de reclamação e devolução (CPMU 4,76). | E24: Reclamações de clientes. | F24: Devoluções geram transporte e resíduos adicionais. | G24: GER | H24: Produto / embalagem | I24: PES-18 | J24: Risco | L24: Não | M24: Indicadores antecedentes, Cpk por Pareto e rastreabilidade. | N24: CPMU e % de reclamações rastreáveis | O24: 46097 | P24: =B24&"|"&COUNTIF(INDEX($B$2:$B$24,1):B24,B24) -> Ameaça|4 | Q24: SGI | R24: R16; R17; R18

Sheet Matriz_TOWS
A1: ID_TOWS | B1: Cruzamento | C1: IDs_Origem | D1: Estrategia | E1: ID_Objetivo | F1: Prazo | G1: Dono | H1: KPI | I1: IDs_Risco_SGI
A2: TOWS-01 | B2: SO (Força+Oportunidade) | C2: SWT-F01; SWT-O01; PES-06 | D2: Usar a infraestrutura de dados existente para criar o painel ambiental e o dossier ambiental por família de produto. | E2: OBJ-04 | F2: 46387 | G2: Gestor do SGA / EHS (Responsável Ambiental) | H2: % KPIs ambientais com dados automáticos | I2: O3; O6
A3: TOWS-02 | B3: ST (Força+Ameaça) | C3: SWT-F03; SWT-T02 | D3: Aumentar a reintegração de scrap limpo para reduzir a dependência de PCR/virgem e o custo de material. | E3: OBJ-02 | F3: 46568 | G3: Gerente de Produção | H3: % scrap reintegrado | I3: R24; O10
A4: TOWS-03 | B4: WO (Fraqueza+Oportunidade) | C4: SWT-W01; SWT-O03 | D4: Candidatar a submedição de energia e água a financiamento e usá-la como base das metas de eficiência. | E4: OBJ-01 | F4: 46387 | G4: Gerente de Manutenção | H4: % consumo submedido
A5: TOWS-04 | B5: WT (Fraqueza+Ameaça) | C5: SWT-W04; SWT-T03; PES-13 | D5: Programa de contenção de químicos e granulado (bacias, kits, OCS) antes da aplicação do regulamento de granulados. | E5: OBJ-06 | F5: 46477 | G5: Gestor do SGA / EHS (Responsável Ambiental) | H5: N.º ocorrências de perda de granulado | I5: R30; R29
A6: TOWS-05 | B6: WT (Fraqueza+Ameaça) | C6: SWT-W01; SWT-T01 | D6: Plano de adaptação climática: medir água e energia do arrefecimento e dimensionar reserva de água. | E6: OBJ-05 | F6: 46752 | G6: Diretor Industrial | H6: m³/1.000 un
A7: TOWS-06 | B7: WO (Fraqueza+Oportunidade) | C7: SWT-W05; SWT-O01 | D7: Programa de dados de fornecedores (qualidade e ambientais) para aumentar a rastreabilidade de materiais. | F7: 46660 | G7: Responsável de Compras | H7: % de fornecedores críticos avaliados (≥ 90%) | I7: O7; R33
A8: TOWS-07 | B8: SO (Força+Oportunidade) | C8: SWT-F04; SWT-O01; PES-12 | D8: Programa Design for Recycling para o portfólio: antecipar requisitos europeus e reduzir impactes de fim de vida. | E8: OBJ-07 | F8: 46934 | G8: Responsável de R&D | H8: % das famílias prioritárias avaliadas (100%) | I8: O5; R33
A9: TOWS-08 | B9: WT (Fraqueza+Ameaça) | C9: SWT-W06; SWT-T04 | D9: Tratar primeiro as causas-raiz de maior evidência (IM-002, ISBM-003, SS-001, M-SOP-007, SUP-005): menos refação, scrap e reclamações. | F9: 46477 | G9: Gerente da Qualidade | H9: CPMU e taxa de rejeição | I9: R4; R1; R7; R2; R13

Sheet Cinco_Forcas
A1: CINCO FORÇAS COMPETITIVAS (PORTER)
A2: Contexto externo do SGI · Vindo do RG-SGA-02 (24/09/2026) — registar só aqui
A4: ID_Forca | B4: Forca_Competitiva | C4: Cenario_Evidencias | D4: Tendencia | E4: Impacto_Organizacao | F4: Classificacao | G4: IDs_Risco_SGI | H4: Como_Monitorizar | I4: Data_Avaliacao
A5: CF-01 | B5: Poder negocial dos clientes | C5: Clientes de cosmética e higiene pessoal aumentam a exigência de Cpk, rastreabilidade, zero defeito, PPWR e dados ESG; carteira diversificada. | D5: Crescente | E5: Devoluções e auditorias; a diversificação reduz a dependência de um cliente. | F5: Risco | G5: R16; R17; R18 | H5: Inquérito de satisfação e reunião semestral (RG-SGA-02 Monitoramento: Clientes) | I5: 46097
A6: CF-02 | B6: Poder negocial dos fornecedores | C6: Resinas commodity concentradas em poucos petroquímicos; 1 fornecedor spot com mau desempenho; PCR/rPET com pouca oferta. | D6: Estável | E6: Risco de custo, disponibilidade e qualidade; pouco poder de troca no reciclado. | F6: Risco | G6: R13; R14; R25 | H6: Reunião mensal e scorecard (RG-SGA-11; RG-SGA-02 Monitoramento: Fornecedores) | I6: 46097
A7: CF-03 | B7: Ameaça de novos entrantes | C7: Barreira baixa em frascos simples e alta em decoração (serigrafia, hot foil), qualidade e rastreabilidade. | D7: Estável | E7: Pressão de preço nos produtos padrão; a decoração protege o portfólio. | F7: Risco | H7: Relatório trimestral de mercado | I7: 46097
A8: CF-04 | B8: Ameaça de produtos substitutos | C8: Vidro, alumínio, recargas e embalagens monomaterial/recicladas substituem parte dos frascos. | D8: Crescente | E8: Pressão por design circular e oportunidade de conteúdo reciclado. | F8: Oportunidade | G8: O5 | H8: Relatório trimestral de mercado | I8: 46097
A9: CF-05 | B9: Rivalidade entre concorrentes | C9: Concorrentes disputam preço; margem pressionada (preço unitário médio ≈ € 0,13). | D9: Crescente | E9: Reduzir perdas e refação para preservar margem (menos desperdício = menos impacte). | F9: Oportunidade | G9: O11; O4 | H9: Relatório trimestral de mercado | I9: 46097

Sheet Vista_SWOT
A1: ANÁLISE SWOT — PLASTICOM (vista calculada)
A2: Itens marcados com ► foram selecionados para a Atividade 3.1. Editar a folha SWOT; esta vista atualiza sozinha.
A4: FORÇAS (internas, positivas) | B4: FRAQUEZAS (internas, negativas)
A5: =IFERROR(IF(INDEX(SWOT!$L$2:$L$24,MATCH("Força|1",SWOT!$P$2:$P$24,0))="Sim","► ","• ")&INDEX(SWOT!$A$2:$A$24,MATCH("Força|1",SWOT!$P$2:$P$24,0))&" — "&INDEX(SWOT!$D$2:$D$24,MATCH("Força|1",SWOT!$P$2:$P$24,0)),"") -> ► SWT-F01 — Cultura de dados industriais: OEE, SPC, AQL e rastreabilidade lote → ordem em 18 meses de dados (22 máquinas, 3 turnos) já integrados em Power BI. | B5: =IFERROR(IF(INDEX(SWOT!$L$2:$L$24,MATCH("Fraqueza|1",SWOT!$P$2:$P$24,0))="Sim","► ","• ")&INDEX(SWOT!$A$2:$A$24,MATCH("Fraqueza|1",SWOT!$P$2:$P$24,0))&" — "&INDEX(SWOT!$D$2:$D$24,MATCH("Fraqueza|1",SWOT!$P$2:$P$24,0)),"") -> ► SWT-W01 — Não existe submedição de energia nem de água por processo ou máquina: os consumos só são conhecidos pela fatura global mensal.
A6: =IFERROR(IF(INDEX(SWOT!$L$2:$L$24,MATCH("Força|2",SWOT!$P$2:$P$24,0))="Sim","► ","• ")&INDEX(SWOT!$A$2:$A$24,MATCH("Força|2",SWOT!$P$2:$P$24,0))&" — "&INDEX(SWOT!$D$2:$D$24,MATCH("Força|2",SWOT!$P$2:$P$24,0)),"") -> • SWT-F02 — Processo 100% elétrico: sem caldeiras nem combustão in situ; empilhadores elétricos. | B6: =IFERROR(IF(INDEX(SWOT!$L$2:$L$24,MATCH("Fraqueza|2",SWOT!$P$2:$P$24,0))="Sim","► ","• ")&INDEX(SWOT!$A$2:$A$24,MATCH("Fraqueza|2",SWOT!$P$2:$P$24,0))&" — "&INDEX(SWOT!$D$2:$D$24,MATCH("Fraqueza|2",SWOT!$P$2:$P$24,0)),"") -> • SWT-W02 — Dependência do fornecedor spot SUP-005 (PP/PVC) com lotes fora de especificação.
A7: =IFERROR(IF(INDEX(SWOT!$L$2:$L$24,MATCH("Força|3",SWOT!$P$2:$P$24,0))="Sim","► ","• ")&INDEX(SWOT!$A$2:$A$24,MATCH("Força|3",SWOT!$P$2:$P$24,0))&" — "&INDEX(SWOT!$D$2:$D$24,MATCH("Força|3",SWOT!$P$2:$P$24,0)),"") -> • SWT-F03 — Moinhos junto às máquinas permitem reintegrar rebarbas e jitos (regrind) no próprio processo. | B7: =IFERROR(IF(INDEX(SWOT!$L$2:$L$24,MATCH("Fraqueza|3",SWOT!$P$2:$P$24,0))="Sim","► ","• ")&INDEX(SWOT!$A$2:$A$24,MATCH("Fraqueza|3",SWOT!$P$2:$P$24,0))&" — "&INDEX(SWOT!$D$2:$D$24,MATCH("Fraqueza|3",SWOT!$P$2:$P$24,0)),"") -> • SWT-W03 — Taxa de rejeição ≈ 2,4% acima da meta de 2,0% e 31% de CAPA não eficazes.
A8: =IFERROR(IF(INDEX(SWOT!$L$2:$L$24,MATCH("Força|4",SWOT!$P$2:$P$24,0))="Sim","► ","• ")&INDEX(SWOT!$A$2:$A$24,MATCH("Força|4",SWOT!$P$2:$P$24,0))&" — "&INDEX(SWOT!$D$2:$D$24,MATCH("Força|4",SWOT!$P$2:$P$24,0)),"") -> • SWT-F04 — Experiência com resinas PCR (HDPE-PCR, rPET) e entrada em mercados alimentar e farmacêutico (2026). | B8: =IFERROR(IF(INDEX(SWOT!$L$2:$L$24,MATCH("Fraqueza|4",SWOT!$P$2:$P$24,0))="Sim","► ","• ")&INDEX(SWOT!$A$2:$A$24,MATCH("Fraqueza|4",SWOT!$P$2:$P$24,0))&" — "&INDEX(SWOT!$D$2:$D$24,MATCH("Fraqueza|4",SWOT!$P$2:$P$24,0)),"") -> • SWT-W04 — Gestão informal da contenção de químicos, kits de derrame e granulado (sem registo de utilização nem stock mínimo).
A9: =IFERROR(IF(INDEX(SWOT!$L$2:$L$24,MATCH("Força|5",SWOT!$P$2:$P$24,0))="Sim","► ","• ")&INDEX(SWOT!$A$2:$A$24,MATCH("Força|5",SWOT!$P$2:$P$24,0))&" — "&INDEX(SWOT!$D$2:$D$24,MATCH("Força|5",SWOT!$P$2:$P$24,0)),"") -> • SWT-F05 — Processos identificados e rastreáveis: 4 processos, 18 máquinas, LotId e ProductBatch consistentes. | B9: =IFERROR(IF(INDEX(SWOT!$L$2:$L$24,MATCH("Fraqueza|5",SWOT!$P$2:$P$24,0))="Sim","► ","• ")&INDEX(SWOT!$A$2:$A$24,MATCH("Fraqueza|5",SWOT!$P$2:$P$24,0))&" — "&INDEX(SWOT!$D$2:$D$24,MATCH("Fraqueza|5",SWOT!$P$2:$P$24,0)),"") -> • SWT-W05 — Dependência de dados de fornecedores: conteúdo reciclado, composição, carbono incorporado e reciclabilidade.
A10: =IFERROR(IF(INDEX(SWOT!$L$2:$L$24,MATCH("Força|6",SWOT!$P$2:$P$24,0))="Sim","► ","• ")&INDEX(SWOT!$A$2:$A$24,MATCH("Força|6",SWOT!$P$2:$P$24,0))&" — "&INDEX(SWOT!$D$2:$D$24,MATCH("Força|6",SWOT!$P$2:$P$24,0)),"") -> • SWT-F06 — Causas-raiz conhecidas com evidência causal forte (IM-002 com MSA e DOE; SS-001 e M-SOP-007 respondem à intervenção). | B10: =IFERROR(IF(INDEX(SWOT!$L$2:$L$24,MATCH("Fraqueza|6",SWOT!$P$2:$P$24,0))="Sim","► ","• ")&INDEX(SWOT!$A$2:$A$24,MATCH("Fraqueza|6",SWOT!$P$2:$P$24,0))&" — "&INDEX(SWOT!$D$2:$D$24,MATCH("Fraqueza|6",SWOT!$P$2:$P$24,0)),"") -> • SWT-W06 — Parâmetros críticos não registados e capacidade de processo marginal (0% dos 190 grupos com Cpk ≥ 1,33).
A11: =IFERROR(IF(INDEX(SWOT!$L$2:$L$24,MATCH("Força|7",SWOT!$P$2:$P$24,0))="Sim","► ","• ")&INDEX(SWOT!$A$2:$A$24,MATCH("Força|7",SWOT!$P$2:$P$24,0))&" — "&INDEX(SWOT!$D$2:$D$24,MATCH("Força|7",SWOT!$P$2:$P$24,0)),"") -> • SWT-F07 — Base de fornecedores diversificada: 7 de 8 fornecedores de resina com contrato anual ou plurianual. | B11: =IFERROR(IF(INDEX(SWOT!$L$2:$L$24,MATCH("Fraqueza|7",SWOT!$P$2:$P$24,0))="Sim","► ","• ")&INDEX(SWOT!$A$2:$A$24,MATCH("Fraqueza|7",SWOT!$P$2:$P$24,0))&" — "&INDEX(SWOT!$D$2:$D$24,MATCH("Fraqueza|7",SWOT!$P$2:$P$24,0)),"") -> • SWT-W07 — Disponibilidade abaixo da meta (87,4%): paragens por operador, ar comprimido, matéria-prima e ativos específicos.
A13: OPORTUNIDADES (externas, positivas) | B13: AMEAÇAS (externas, negativas)
A14: =IFERROR(IF(INDEX(SWOT!$L$2:$L$24,MATCH("Oportunidade|1",SWOT!$P$2:$P$24,0))="Sim","► ","• ")&INDEX(SWOT!$A$2:$A$24,MATCH("Oportunidade|1",SWOT!$P$2:$P$24,0))&" — "&INDEX(SWOT!$D$2:$D$24,MATCH("Oportunidade|1",SWOT!$P$2:$P$24,0)),"") -> ► SWT-O01 — PPWR e procura de embalagens recicláveis com conteúdo reciclado por clientes europeus. | B14: =IFERROR(IF(INDEX(SWOT!$L$2:$L$24,MATCH("Ameaça|1",SWOT!$P$2:$P$24,0))="Sim","► ","• ")&INDEX(SWOT!$A$2:$A$24,MATCH("Ameaça|1",SWOT!$P$2:$P$24,0))&" — "&INDEX(SWOT!$D$2:$D$24,MATCH("Ameaça|1",SWOT!$P$2:$P$24,0)),"") -> ► SWT-T01 — Ondas de calor e escassez hídrica (alterações climáticas) afetam o arrefecimento de moldes, a água técnica e a continuidade.
A15: =IFERROR(IF(INDEX(SWOT!$L$2:$L$24,MATCH("Oportunidade|2",SWOT!$P$2:$P$24,0))="Sim","► ","• ")&INDEX(SWOT!$A$2:$A$24,MATCH("Oportunidade|2",SWOT!$P$2:$P$24,0))&" — "&INDEX(SWOT!$D$2:$D$24,MATCH("Oportunidade|2",SWOT!$P$2:$P$24,0)),"") -> • SWT-O02 — Autoconsumo fotovoltaico na cobertura (≈ 9.000 m² disponíveis) e contratos PPA renováveis. | B15: =IFERROR(IF(INDEX(SWOT!$L$2:$L$24,MATCH("Ameaça|2",SWOT!$P$2:$P$24,0))="Sim","► ","• ")&INDEX(SWOT!$A$2:$A$24,MATCH("Ameaça|2",SWOT!$P$2:$P$24,0))&" — "&INDEX(SWOT!$D$2:$D$24,MATCH("Ameaça|2",SWOT!$P$2:$P$24,0)),"") -> • SWT-T02 — Volatilidade de preço e qualidade do PCR/rPET.
A16: =IFERROR(IF(INDEX(SWOT!$L$2:$L$24,MATCH("Oportunidade|3",SWOT!$P$2:$P$24,0))="Sim","► ","• ")&INDEX(SWOT!$A$2:$A$24,MATCH("Oportunidade|3",SWOT!$P$2:$P$24,0))&" — "&INDEX(SWOT!$D$2:$D$24,MATCH("Oportunidade|3",SWOT!$P$2:$P$24,0)),"") -> • SWT-O03 — Financiamento público para eficiência energética e economia circular (Portugal 2030, Fundo Ambiental). | B16: =IFERROR(IF(INDEX(SWOT!$L$2:$L$24,MATCH("Ameaça|3",SWOT!$P$2:$P$24,0))="Sim","► ","• ")&INDEX(SWOT!$A$2:$A$24,MATCH("Ameaça|3",SWOT!$P$2:$P$24,0))&" — "&INDEX(SWOT!$D$2:$D$24,MATCH("Ameaça|3",SWOT!$P$2:$P$24,0)),"") -> • SWT-T03 — Aumento da exigência regulatória (PPWR, granulados, resíduos) com risco de coimas e perda de clientes.
A17: =IFERROR(IF(INDEX(SWOT!$L$2:$L$24,MATCH("Oportunidade|4",SWOT!$P$2:$P$24,0))="Sim","► ","• ")&INDEX(SWOT!$A$2:$A$24,MATCH("Oportunidade|4",SWOT!$P$2:$P$24,0))&" — "&INDEX(SWOT!$D$2:$D$24,MATCH("Oportunidade|4",SWOT!$P$2:$P$24,0)),"") -> • SWT-O04 — Visão artificial, dados e rastreabilidade para prevenir perdas em vez de inspecionar. | B17: =IFERROR(IF(INDEX(SWOT!$L$2:$L$24,MATCH("Ameaça|4",SWOT!$P$2:$P$24,0))="Sim","► ","• ")&INDEX(SWOT!$A$2:$A$24,MATCH("Ameaça|4",SWOT!$P$2:$P$24,0))&" — "&INDEX(SWOT!$D$2:$D$24,MATCH("Ameaça|4",SWOT!$P$2:$P$24,0)),"") -> • SWT-T04 — Clientes exigem Cpk, rastreabilidade e zero defeito, com risco de reclamação e devolução (CPMU 4,76).
A18: =IFERROR(IF(INDEX(SWOT!$L$2:$L$24,MATCH("Oportunidade|5",SWOT!$P$2:$P$24,0))="Sim","► ","• ")&INDEX(SWOT!$A$2:$A$24,MATCH("Oportunidade|5",SWOT!$P$2:$P$24,0))&" — "&INDEX(SWOT!$D$2:$D$24,MATCH("Oportunidade|5",SWOT!$P$2:$P$24,0)),"") -> • SWT-O05 — Sazonalidade previsível da procura (pico set–nov). | B18: =IFERROR(IF(INDEX(SWOT!$L$2:$L$24,MATCH("Ameaça|5",SWOT!$P$2:$P$24,0))="Sim","► ","• ")&INDEX(SWOT!$A$2:$A$24,MATCH("Ameaça|5",SWOT!$P$2:$P$24,0))&" — "&INDEX(SWOT!$D$2:$D$24,MATCH("Ameaça|5",SWOT!$P$2:$P$24,0)),"")
A19: =IFERROR(IF(INDEX(SWOT!$L$2:$L$24,MATCH("Oportunidade|6",SWOT!$P$2:$P$24,0))="Sim","► ","• ")&INDEX(SWOT!$A$2:$A$24,MATCH("Oportunidade|6",SWOT!$P$2:$P$24,0))&" — "&INDEX(SWOT!$D$2:$D$24,MATCH("Oportunidade|6",SWOT!$P$2:$P$24,0)),"") | B19: =IFERROR(IF(INDEX(SWOT!$L$2:$L$24,MATCH("Ameaça|6",SWOT!$P$2:$P$24,0))="Sim","► ","• ")&INDEX(SWOT!$A$2:$A$24,MATCH("Ameaça|6",SWOT!$P$2:$P$24,0))&" — "&INDEX(SWOT!$D$2:$D$24,MATCH("Ameaça|6",SWOT!$P$2:$P$24,0)),"")
A20: =IFERROR(IF(INDEX(SWOT!$L$2:$L$24,MATCH("Oportunidade|7",SWOT!$P$2:$P$24,0))="Sim","► ","• ")&INDEX(SWOT!$A$2:$A$24,MATCH("Oportunidade|7",SWOT!$P$2:$P$24,0))&" — "&INDEX(SWOT!$D$2:$D$24,MATCH("Oportunidade|7",SWOT!$P$2:$P$24,0)),"") | B20: =IFERROR(IF(INDEX(SWOT!$L$2:$L$24,MATCH("Ameaça|7",SWOT!$P$2:$P$24,0))="Sim","► ","• ")&INDEX(SWOT!$A$2:$A$24,MATCH("Ameaça|7",SWOT!$P$2:$P$24,0))&" — "&INDEX(SWOT!$D$2:$D$24,MATCH("Ameaça|7",SWOT!$P$2:$P$24,0)),"")

Sheet Partes_Interessadas
A1: PARTES INTERESSADAS — NECESSIDADES, EXPECTATIVAS E OBRIGAÇÕES DE CONFORMIDADE (4.2)
A2: ISO 14001:2026 4.2 c): quais necessidades se tornam obrigações de conformidade · Obrigações legais ligam ao RG-SGA-04
A4: ID_PI | B4: Parte_Interessada | C4: Tipo | D4: Categoria | E4: Necessidades_Expectativas | F4: Condicao_Ambiental | G4: Relevante | H4: Torna_se_Obrigacao | I4: Tipo_Obrigacao | J4: IDs_Legal | K4: Como_Monitorizar | L4: Frequencia | M4: Influencia | N4: Interesse | O4: Estrategia | P4: ID_RO | Q4: Dono | R4: Data_Revisao | S4: IDs_Risco_SGI | T4: Percepcao_Risco
A5: PI-01 | B5: Colaboradores | C5: Interna | D5: Trabalhadores próprios (≈ 150, 3 turnos) | E5: Ambiente de trabalho sem exposição a solventes; formação; participação na melhoria. | F5: Poluição | G5: Sim | H5: Sim | I5: Legal | J5: LEG-06 | K5: Formação, DDS e comité SST/ambiente; caixa de sugestões Kaizen | L5: Mensal | M5: Média | N5: Alta | O5: =IF(A5="","",IF(AND(M5="Alta",N5="Alta"),"Gerir de perto",IF(M5="Alta","Manter satisfeita",IF(N5="Alta","Manter informada","Monitorizar")))) -> Manter informada | P5: RO-10 | Q5: Responsável de Recursos Humanos | R5: 46289 | S5: R9; R23; R28; R29 | T5: Sentem pressão por meta e produtividade; o quase-acidente raramente é relatado.
A6: PI-02 | B6: Representantes dos trabalhadores (SST/Ambiente) | C6: Interna | D6: Representantes eleitos | E6: Ser consultados sobre alterações com impacto ambiental e de SST. | F6: Não aplicável | G6: Sim | H6: Sim | I6: Voluntária (compromisso assumido) | K6: Consulta formal nas alterações (RG-SGA-18) | L6: Por ocorrência | M6: Média | N6: Média | O6: =IF(A6="","",IF(AND(M6="Alta",N6="Alta"),"Gerir de perto",IF(M6="Alta","Manter satisfeita",IF(N6="Alta","Manter informada","Monitorizar")))) -> Monitorizar | Q6: Responsável de Recursos Humanos | R6: 46289
A7: PI-03 | B7: Acionistas / Direção | C7: Interna | D7: Gestão de topo | E7: Continuidade, conformidade legal, custos de energia controlados, reputação. | F7: Clima | G7: Sim | H7: Não | I7: — | K7: Revisão pela gestão; painel mensal de KPI | L7: Trimestral | M7: Alta | N7: Alta | O7: =IF(A7="","",IF(AND(M7="Alta",N7="Alta"),"Gerir de perto",IF(M7="Alta","Manter satisfeita",IF(N7="Alta","Manter informada","Monitorizar")))) -> Gerir de perto | P7: RO-02 | Q7: Gestor do SGA / EHS (Responsável Ambiental) | R7: 46289 | S7: R24; R25; O3; O4 | T7: Esperam retorno dos investimentos em eficiência e menor custo da não-qualidade.
A8: PI-04 | B8: Clientes de cosmética (marcas UE) | C8: Externa | D8: Clientes B2B | E8: Embalagens recicláveis com PCR, declaração PPWR, pegada de carbono, respostas EcoVadis/CDP. | F8: Recursos naturais | G8: Sim | H8: Sim | I8: Voluntária (compromisso assumido) | J8: LEG-09 | K8: Questionários ESG; reunião semestral de conta | L8: Semestral | M8: Alta | N8: Alta | O8: =IF(A8="","",IF(AND(M8="Alta",N8="Alta"),"Gerir de perto",IF(M8="Alta","Manter satisfeita",IF(N8="Alta","Manter informada","Monitorizar")))) -> Gerir de perto | P8: RO-03 | Q8: Responsável de R&D | R8: 46289 | S8: R16; R17; R18; R21; R33 | T8: Um lote fora de especificação é visto como falha evitável (risco imposto ao cliente).
A9: PI-05 | B9: Clientes alimentar e farmacêutico | C9: Externa | D9: Clientes B2B (novas linhas 2026) | E9: Conformidade de materiais em contacto, rastreabilidade, ausência de PFAS e substâncias restritas. | F9: Poluição | G9: Sim | H9: Sim | I9: Legal | J9: LEG-06; LEG-09 | K9: Auditorias de cliente; especificações | L9: Anual | M9: Alta | N9: Alta | O9: =IF(A9="","",IF(AND(M9="Alta",N9="Alta"),"Gerir de perto",IF(M9="Alta","Manter satisfeita",IF(N9="Alta","Manter informada","Monitorizar")))) -> Gerir de perto | P9: RO-06 | Q9: Gerente da Qualidade | R9: 46289 | S9: R16; R17; R18; R21; R33 | T9: Um lote fora de especificação é visto como falha evitável (risco imposto ao cliente).
A10: PI-06 | B10: Fornecedores de polímero e PCR | C10: Externa | D10: Cadeia de abastecimento | E10: Previsibilidade das encomendas; critérios ambientais claros; prazos de pagamento. | F10: Recursos naturais | G10: Sim | H10: Não | I10: — | K10: Avaliação anual (RG-SGA-11); reunião mensal | L10: Mensal | M10: Média | N10: Média | O10: =IF(A10="","",IF(AND(M10="Alta",N10="Alta"),"Gerir de perto",IF(M10="Alta","Manter satisfeita",IF(N10="Alta","Manter informada","Monitorizar")))) -> Monitorizar | P10: RO-05 | Q10: Responsável de Compras | R10: 46289 | S10: R13; R14; O7; O8 | T10: O fornecedor spot vê a relação como transacional.
A11: PI-07 | B11: Operadores de gestão de resíduos | C11: Externa | D11: Prestadores licenciados | E11: Resíduos segregados, classificados (LER) e com e-GAR corretas. | F11: Poluição | G11: Sim | H11: Sim | I11: Legal | J11: LEG-01; LEG-13 | K11: e-GAR; certificados de destino | L11: Por recolha | M11: Média | N11: Média | O11: =IF(A11="","",IF(AND(M11="Alta",N11="Alta"),"Gerir de perto",IF(M11="Alta","Manter satisfeita",IF(N11="Alta","Manter informada","Monitorizar")))) -> Monitorizar | Q11: Responsável de Armazém e Logística | R11: 46289 | S11: R31; O10 | T11: Valorizam a segregação correta na origem.
A12: PI-08 | B12: APA / CCDR Centro | C12: Externa | D12: Autoridades ambientais | E12: Cumprimento de resíduos, emissões, licenças e comunicação de dados (MIRR, PRTR). | F12: Poluição | G12: Sim | H12: Sim | I12: Legal | J12: LEG-01; LEG-04; LEG-12; LEG-13 | K12: Relatórios legais; SILiAmb | L12: Anual | M12: Alta | N12: Média | O12: =IF(A12="","",IF(AND(M12="Alta",N12="Alta"),"Gerir de perto",IF(M12="Alta","Manter satisfeita",IF(N12="Alta","Manter informada","Monitorizar")))) -> Manter satisfeita | P12: RO-06 | Q12: Diretor Geral (Gestão de Topo) | R12: 46289 | S12: R30; R31; R32 | T12: A não conformidade ambiental é vista como dano à coletividade, sem margem de tolerância.
A13: PI-09 | B13: Câmara Municipal da Marinha Grande | C13: Externa | D13: Autoridade local | E13: Cumprimento do RGR (ruído) e do regulamento municipal de drenagem. | F13: Poluição | G13: Sim | H13: Sim | I13: Legal | J13: LEG-03; LEG-05 | K13: Autorização de descarga; relatórios acústicos | L13: Por ocorrência | M13: Média | N13: Média | O13: =IF(A13="","",IF(AND(M13="Alta",N13="Alta"),"Gerir de perto",IF(M13="Alta","Manter satisfeita",IF(N13="Alta","Manter informada","Monitorizar")))) -> Monitorizar | P13: RO-12 | Q13: Diretor Geral (Gestão de Topo) | R13: 46289
A14: PI-10 | B14: Entidade gestora de água e saneamento | C14: Externa | D14: Serviço público | E14: Descarga dentro dos VLE; uso eficiente de água em seca. | F14: Recursos naturais | G14: Sim | H14: Sim | I14: Legal | J14: LEG-03 | K14: Autocontrolo semestral; comunicação de descargas anómalas | L14: Semestral | M14: Média | N14: Média | O14: =IF(A14="","",IF(AND(M14="Alta",N14="Alta"),"Gerir de perto",IF(M14="Alta","Manter satisfeita",IF(N14="Alta","Manter informada","Monitorizar")))) -> Monitorizar | P14: RO-04 | Q14: Gerente de Manutenção | R14: 46289
A15: PI-11 | B15: Comunidade / vizinhança (≈ 250 m) | C15: Externa | D15: Recetores sensíveis | E15: Sem ruído noturno, odores ou tráfego excessivo; resposta rápida a reclamações. | F15: Saúde dos ecossistemas | G15: Sim | H15: Sim | I15: Voluntária (compromisso assumido) | J15: LEG-05 | K15: Canal de reclamações; reunião anual | L15: Anual | M15: Média | N15: Alta | O15: =IF(A15="","",IF(AND(M15="Alta",N15="Alta"),"Gerir de perto",IF(M15="Alta","Manter satisfeita",IF(N15="Alta","Manter informada","Monitorizar")))) -> Manter informada | P15: RO-12 | Q15: Diretor Geral (Gestão de Topo) | R15: 46289 | S15: R30; R34 | T15: O risco imposto por decisões da empresa gera mais indignação do que um risco voluntário.
A16: PI-12 | B16: Seguradora / banco | C16: Externa | D16: Financiadores | E16: Controlo do risco de incêndio e de danos ambientais; financiamento verde. | F16: Clima | G16: Sim | H16: Sim | I16: Voluntária (compromisso assumido) | J16: LEG-11 | K16: Visita de risco anual; renovação da apólice | L16: Anual | M16: Média | N16: Baixa | O16: =IF(A16="","",IF(AND(M16="Alta",N16="Alta"),"Gerir de perto",IF(M16="Alta","Manter satisfeita",IF(N16="Alta","Manter informada","Monitorizar")))) -> Monitorizar | P16: RO-08 | Q16: Diretor Financeiro | R16: 46289 | S16: R28; R30; R25 | T16: Sensíveis a sinistros e a risco ambiental.
A17: PI-13 | B17: Associação setorial (plásticos) | C17: Externa | D17: Setor | E17: Adesão ao programa Operation Clean Sweep (zero perdas de granulado). | F17: Saúde dos ecossistemas | G17: Sim | H17: Sim | I17: Voluntária (compromisso assumido) | J17: LEG-10 | K17: Relatório anual OCS | L17: Anual | M17: Baixa | N17: Média | O17: =IF(A17="","",IF(AND(M17="Alta",N17="Alta"),"Gerir de perto",IF(M17="Alta","Manter satisfeita",IF(N17="Alta","Manter informada","Monitorizar")))) -> Monitorizar | P17: RO-07 | Q17: Diretor Geral (Gestão de Topo) | R17: 46289
A18: PI-14 | B18: ONG ambientais | C18: Externa | D18: Sociedade civil | E18: Transparência sobre microplásticos e biodiversidade do Pinhal de Leiria. | F18: Biodiversidade | G18: Sim | H18: Não | I18: — | K18: Monitorização de media e redes | L18: Trimestral | M18: Baixa | N18: Média | O18: =IF(A18="","",IF(AND(M18="Alta",N18="Alta"),"Gerir de perto",IF(M18="Alta","Manter satisfeita",IF(N18="Alta","Manter informada","Monitorizar")))) -> Monitorizar | P18: RO-07 | Q18: Diretor Geral (Gestão de Topo) | R18: 46289
A19: PI-15 | B19: Bombeiros / Proteção Civil | C19: Externa | D19: Emergência | E19: Medidas de autoproteção, plantas de emergência e retenção das águas de combate. | F19: Biodiversidade | G19: Sim | H19: Sim | I19: Legal | J19: LEG-11 | K19: Simulacro anual conjunto | L19: Anual | M19: Média | N19: Baixa | O19: =IF(A19="","",IF(AND(M19="Alta",N19="Alta"),"Gerir de perto",IF(M19="Alta","Manter satisfeita",IF(N19="Alta","Manter informada","Monitorizar")))) -> Monitorizar | P19: RO-08 | Q19: Diretor Industrial | R19: 46289
