Workbook
Name DataRef: Listas!$A$3
Name lst_Ambito: Listas!$D$3:$D$8
Name lst_Aplicabilidade: Listas!$E$3:$E$6
Name lst_DataReferencia: Listas!$A$3:$A$3
Name lst_Estado: Listas!$H$3:$H$6
Name lst_Frequencia: Listas!$J$3:$J$11
Name lst_Funcao: Listas!$I$3:$I$24
Name lst_Natureza: Listas!$F$3:$F$7
Name lst_Tema: Listas!$B$3:$B$22
Name lst_TipoDiploma: Listas!$C$3:$C$12
Name lst_TipoEvidencia: Listas!$G$3:$G$12

Sheet 00_LEIA-ME
A1: RG-SGA-04 — Tabela de Identificação de Requisitos Legais e Avaliação da Conformidade (Mod.G.06.02)
A2: Sistema de Gestão Ambiental NP EN ISO 14001:2026 · Plasticom — Unidade 1 (Marinha Grande, Portugal) · Registo do SGA (fábrica simulada)
A4: CONTROLO DO DOCUMENTO (7.5 — informação documentada)
A5: Código do registo | B5: RG-SGA-04
A6: Título | B6: Tabela de Identificação de Requisitos Legais e Avaliação da Conformidade (Mod.G.06.02)
A7: Versão / Revisão | B7: 01
A8: Data de emissão | B8: 46387
A9: Elaborado por | B9: Gestor(a) do SGA / EHS
A10: Aprovado por | B10: Diretor Geral
A11: Estado | B11: Em vigor
A12: Retenção | B12: 5 anos após substituição
A13: Localização | B13: Repositório controlado do SGA > Registos_SGA_Plasticom (versão eletrónica é a versão controlada; cópias impressas são não controladas)
A15: FINALIDADE E ÂMBITO
A16: Finalidade | B16: Identificar a legislação e outros requisitos aplicáveis por tema ambiental, interpretar as obrigações, registar as disposições internas e avaliar a conformidade com evidência objetiva (documento, número, data, valor medido vs limite). Inclui calendário de obrigações recorrentes e histórico de avaliações para análise de tendência.
A17: Atividades do curso | B17: Atividade 3.3 — Identificação de Requisitos Legais e Avaliação da Conformidade (tabela completa; vista para print screen no formato Mod.G.06.02).
A18: Requisitos ISO 14001:2026 | B18: 6.1.3 Obrigações de conformidade; 9.1.2 Avaliação da conformidade; 5.2 (compromisso de cumprir as obrigações de conformidade — ISO 14001:2026: 'meet')
A20: ESTRUTURA DO FICHEIRO
A21: Requisitos_Legais | B21: Registo de requisitos legais e avaliação da conformidade (1 linha por diploma).
A22: Calendario_Obrigacoes | B22: Calendário de obrigações legais recorrentes com estado calculado (compliance calendar).
A23: Historico_Avaliacoes | B23: Histórico das avaliações de conformidade por ciclo (formato longo para análise de tendência).
A24: Mod.G.06.02_Vista | B24: Tabela no formato do enunciado (7 colunas) para print screen no fórum, calculada a partir de tbl_legal.
A25: Listas | B25: Domínios (listas de valores) usados na validação de dados das tabelas.
A26: Dicionario_Dados | B26: Descrição de cada coluna de cada tabela: tipo, origem (entrada/calculado), domínio, obrigatoriedade e chaves.
A28: CONVENÇÕES (prontas para análise de dados e machine learning)
A29: Tabelas | B29: Cada registo é uma Tabela Excel com nome próprio (tbl_*): uma linha = um registo, cabeçalho único, sem células mescladas. Ler com pandas (pd.read_excel(ficheiro, sheet_name=folha, header=<linha do cabeçalho - 1>)) ou Power BI (Obter Dados > Tabela).
A30: Cabeçalho cinzento | B30: Coluna CALCULADA por fórmula — não escrever por cima. As restantes colunas são de entrada.
A31: Validação | B31: Colunas com lista controlada só aceitam valores da folha Listas (evita categorias duplicadas por grafia diferente).
A32: Chaves | B32: IDs estáveis e únicos (PK) e referências a IDs de outros registos (FK) permitem juntar tabelas entre ficheiros — ver SGA-00_Indice_Modelo_Dados.xlsx.
A33: Datas e unidades | B33: Datas em formato data (aaaa-mm-dd); números como números; a unidade está no nome da coluna ou no dicionário. Data de referência do SGA: 2026-12-31 (fecho do ano).
A34: Dados simulados | B34: Fábrica simulada Plasticom. Dados operacionais derivados do dataset do projeto (datasets/silver); dados ambientais e de conformidade são simulação didática — confirmar aplicabilidade legal e números antes de uso real.
A36: LIGAÇÕES A OUTROS REGISTOS
A37: RG-SGA-03 Aspetos | B37: IDs_Aspetos liga cada diploma aos aspetos ambientais que regula.
A38: RG-SGA-06 PAM | B38: NC legal → ação no PAM (ID_PAM).
A39: RG-SGA-07 NC | B39: NC legais são também registadas no registo de não conformidades.

Sheet Requisitos_Legais
A1: TABELA DE IDENTIFICAÇÃO DE REQUISITOS LEGAIS E AVALIAÇÃO DA CONFORMIDADE — PLASTICOM
A2: Evidência objetiva obrigatória (nunca apenas 'Cumpre') · Data de referência para alertas: 2026-12-31 (nome DataRef) · Dados de evidência simulados
A4: ID_Legal | B4: Codigo_Tema | C4: Tema | D4: Diploma_Documento | E4: Tipo_Diploma | F4: Data_Publicacao | G4: Ambito | H4: Entidade_Fiscalizadora | I4: Resumo_Obrigacoes | J4: Aplicabilidade | K4: Justificacao_Aplicabilidade | L4: Processos | M4: IDs_Aspetos | N4: Disposicoes_Internas | O4: Avaliacao_Conformidade_Evidencia | P4: Tipo_Evidencia | Q4: Data_Evidencia | R4: Estado | S4: Data_Avaliacao | T4: Periodicidade_Meses | U4: Proxima_Avaliacao | V4: Idade_Evidencia_Dias | W4: Alerta | X4: ID_PAM | Y4: Responsavel | Z4: Fonte_Oficial | AA4: Natureza_Obrigacao | AB4: Papel_Plasticom | AC4: IDs_Req_Embalagem
A5: LEG-01 | B5: RES | C5: Resíduos industriais | D5: Decreto-Lei n.º 102-D/2020, de 10 de dezembro (RGGR) | E5: Decreto-Lei | F5: 44175 | G5: Nacional | H5: APA / IGAMAOT | I5: Separar na origem, armazenar em condições adequadas, classificar pela Lista Europeia de Resíduos (LER), encaminhar para operadores licenciados e submeter o MIRR anual no SILiAmb até 31 de março. | J5: Sim | K5: Produtor de resíduos não urbanos com mais de 10 trabalhadores e resíduos perigosos. | L5: PRS; SER; MAN; INJ; SOP | M5: AA-004; AA-008; AA-011; AA-016; AA-026; AA-029 | N5: Parque de resíduos com contentores identificados por código LER; balança de plataforma verificada; contratos com 7 operadores licenciados. | O5: Submissão do MIRR 2025 no SILiAmb em 18/03/2026 (comprovativo n.º MIRR-2025-PLA-0417). Amostra de 20 e-GAR de jan–ago/2026: 100% com operador licenciado e código LER coerente com a pesagem interna. | P5: Plataforma / comprovativo | Q5: 46099 | R5: C | S5: 46275 | T5: 12 | U5: =IF(S5="","",EDATE(S5,T5)) -> 46640 | V5: =IF(Q5="","",DataRef-Q5) -> 288 | W5: =IF(AND(R5="NC",X5=""),"NC sem ação no PAM",IF(U5<DataRef,"Avaliação vencida",IF(U5-DataRef<=60,"Avaliar nos próximos 60 dias",IF(R5="NC","NC com ação em curso","OK")))) -> OK | Y5: Gestor do SGA / EHS (Responsável Ambiental) | Z5: https://diariodarepublica.pt/dr/legislacao-consolidada/decreto-lei/2020-150908020 | AA5: Obrigação legal | AB5: Produtor de resíduos | AC5: EU-ENV-006; PT-002
A6: LEG-02 | B6: LIC | C6: Licenciamento industrial | D6: Decreto-Lei n.º 169/2012, de 1 de agosto (SIR), republicado pelo DL 73/2015 | E6: Decreto-Lei | F6: 41122 | G6: Nacional | H6: IAPMEI / CCDR Centro | I6: Explorar o estabelecimento industrial com título válido e comunicar alterações que modifiquem a tipologia ou as condições de exploração. | J6: Sim | K6: Estabelecimento industrial do tipo 2 (transformação de matérias plásticas). | L6: GER | N6: Título Digital de Exploração arquivado; controlo de mudanças avalia alterações de layout e equipamento. | O6: Título Digital de Exploração n.º TDE-2019-0588 válido; comunicação da instalação dos novos compressores submetida em 04/02/2026 (sem alteração de tipologia). | P6: Licença / título | Q6: 46057 | R6: C | S6: 46275 | T6: 12 | U6: =IF(S6="","",EDATE(S6,T6)) -> 46640 | V6: =IF(Q6="","",DataRef-Q6) -> 330 | W6: =IF(AND(R6="NC",X6=""),"NC sem ação no PAM",IF(U6<DataRef,"Avaliação vencida",IF(U6-DataRef<=60,"Avaliar nos próximos 60 dias",IF(R6="NC","NC com ação em curso","OK")))) -> OK | Y6: Diretor Industrial | Z6: Portal ePortugal / SIR | AA6: Obrigação legal | AB6: Estabelecimento industrial (tipo 2)
A7: LEG-03 | B7: AGU | C7: Água e águas residuais | D7: Lei n.º 58/2005 (Lei da Água); Regulamento Municipal de Drenagem de Águas Residuais (Marinha Grande) | E7: Lei / Regulamento | F7: 38715 | G7: Nacional / Municipal | H7: Entidade gestora municipal / APA | I7: Descarregar águas residuais industriais no coletor apenas com autorização e dentro dos valores-limite do regulamento municipal; realizar autocontrolo analítico semestral. | J7: Sim | K7: Descarga da purga da torre de arrefecimento e águas domésticas no coletor municipal. | L7: UTL; GER | M7: AA-023; AA-024; AA-035 | N7: Autorização de descarga n.º AD-112/2021; ponto de amostragem na caixa de visita final; dosagem automática de biocida. | O7: Boletim de análise n.º 26/2410 (laboratório acreditado, 10/12/2026): pH 7,6; CQO 132 mg/L O2; SST 31 mg/L — todos abaixo do VLE municipal (2.º semestre). | P7: Relatório de ensaio | Q7: 46366 | R7: C | S7: 46370 | T7: 6 | U7: =IF(S7="","",EDATE(S7,T7)) -> 46552 | V7: =IF(Q7="","",DataRef-Q7) -> 21 | W7: =IF(AND(R7="NC",X7=""),"NC sem ação no PAM",IF(U7<DataRef,"Avaliação vencida",IF(U7-DataRef<=60,"Avaliar nos próximos 60 dias",IF(R7="NC","NC com ação em curso","OK")))) -> OK | Y7: Gerente de Manutenção | Z7: Regulamento municipal / Diário da República | AA7: Obrigação legal | AB7: Utilizador do coletor municipal
A8: LEG-04 | B8: COV | C8: Ar — COV (solventes) | D8: Decreto-Lei n.º 127/2013, de 30 de agosto — Capítulo V e Anexo VII (instalações que utilizam solventes orgânicos) | E8: Decreto-Lei | F8: 41516 | G8: Nacional | H8: APA / CCDR Centro | I8: Instalações acima do limiar de consumo de solventes (ex.: 5 t/ano para revestimento de plástico; 15 t/ano para impressão) têm VLE, plano de gestão de solventes e registo. Abaixo do limiar: demonstrar anualmente o consumo. | J8: Não | K8: Consumo anual de solventes ≈ 1,2 t (limpeza + fração solvente das tintas) < 5 t/ano. Manter o cálculo anual para confirmar a não aplicabilidade. | L8: SER | M8: AA-014; AA-006 | N8: Balanço anual de solventes a partir do inventário (compras − stock). | O8: Balanço de solventes set/2025–ago/2026: 0,75 t de solvente de limpeza + ≈ 0,43 t na fração solvente das tintas = ≈ 1,2 t/ano (24% do limiar). Registo BAL-SOLV-2026 arquivado. | P8: Registo / cálculo | Q8: 46270 | R8: C | S8: 46275 | T8: 12 | U8: =IF(S8="","",EDATE(S8,T8)) -> 46640 | V8: =IF(Q8="","",DataRef-Q8) -> 117 | W8: =IF(AND(R8="NC",X8=""),"NC sem ação no PAM",IF(U8<DataRef,"Avaliação vencida",IF(U8-DataRef<=60,"Avaliar nos próximos 60 dias",IF(R8="NC","NC com ação em curso","OK")))) -> OK | Y8: Gestor do SGA / EHS (Responsável Ambiental) | Z8: Diário da República — DL 127/2013 | AA8: Obrigação legal | AB8: Operador abaixo do limiar de solventes
A9: LEG-05 | B9: RUI | C9: Ruído ambiente | D9: Decreto-Lei n.º 9/2007, de 17 de janeiro (Regulamento Geral do Ruído) | E9: Decreto-Lei | F9: 39099 | G9: Nacional | H9: Câmara Municipal / IGAMAOT | I9: Cumprir o critério de exposição máxima e o critério de incomodidade junto dos recetores sensíveis; avaliar após alterações que possam aumentar o ruído. | J9: Sim | K9: Habitações a ≈ 250 m; laboração em 3 turnos (período noturno). | L9: UTL | M9: AA-022 | N9: Compressores em sala fechada; última avaliação acústica em 2023, antes da substituição dos compressores (fev/2026). | O9: Relatório AC-2026-112 (28/10/2026, laboratório acreditado): critério de incomodidade noturno cumprido nos 3 recetores após barreira acústica e redução de rotação noturna dos compressores (PAM-26-03). | P9: Relatório de ensaio | Q9: 46323 | R9: C | S9: 46331 | T9: 36 | U9: =IF(S9="","",EDATE(S9,T9)) -> 47427 | V9: =IF(Q9="","",DataRef-Q9) -> 64 | W9: =IF(AND(R9="NC",X9=""),"NC sem ação no PAM",IF(U9<DataRef,"Avaliação vencida",IF(U9-DataRef<=60,"Avaliar nos próximos 60 dias",IF(R9="NC","NC com ação em curso","OK")))) -> OK | X9: PAM-26-03 | Y9: Gestor do SGA / EHS (Responsável Ambiental) | Z9: https://diariodarepublica.pt/dr/detalhe/decreto-lei/9-2007-522807 | AA9: Obrigação legal | AB9: Operador (fonte de ruído)
A10: LEG-06 | B10: QUI | C10: Produtos químicos | D10: Regulamento (CE) n.º 1907/2006 (REACH) e Regulamento (CE) n.º 1272/2008 (CLP) | E10: Regulamento UE | F10: 39069 | G10: UE | H10: IGAMAOT / ACT | I10: Dispor de fichas de dados de segurança (FDS) atualizadas no ponto de uso, recipientes rotulados, e cumprir as condições de utilização segura e de armazenagem. | J10: Sim | K10: Utilizador a jusante de tintas, solventes, óleos e biocidas. | L10: ARQ; SER; UTL; MAN | M10: AA-005; AA-006; AA-015; AA-017 | N10: Registo integrado RG-SGA-21 (inventário de 42 produtos, FDS, cenários de exposição, importação, SVHC, risco químico) e procedimento PR-SGA-16; dossier de FDS no armazém e junto às máquinas; armário de inflamáveis. | O10: Avaliação completa de 24/09/2026 (RG-SGA-21): rotulagem CLP 100% conforme (15 recipientes); FDS em vigor 85% conformes (6 a pedir ao fornecedor, 2 de 2021 pedidas em 03/09/2026); 2 cenários de exposição com o prazo de 12 meses do art. 39.º ultrapassado (CE-02, CE-08); 2 fornecedores extra-UE sem representante único (Plasticom = importador sem registo — SUP-004, SUP-005); tinta UV com fotoiniciador Repr. 1B/SVHC; 2 operadores sem formação em diisocianatos (entrada 74). | P10: Inspeção / registo | Q10: 46289 | R10: NC | S10: 46275 | T10: 12 | U10: =IF(S10="","",EDATE(S10,T10)) -> 46640 | V10: =IF(Q10="","",DataRef-Q10) -> 98 | W10: =IF(AND(R10="NC",X10=""),"NC sem ação no PAM",IF(U10<DataRef,"Avaliação vencida",IF(U10-DataRef<=60,"Avaliar nos próximos 60 dias",IF(R10="NC","NC com ação em curso","OK")))) -> NC com ação em curso | X10: PAM-26-28 | Y10: Responsável de Armazém e Logística | Z10: https://eur-lex.europa.eu/eli/reg/2006/1907/oj | AA10: Obrigação legal | AB10: Utilizador a jusante de misturas; fornecedor de artigos | AC10: EU-ENV-008; EU-ENV-009
A11: LEG-07 | B11: FGA | C11: Gases fluorados | D11: Regulamento (UE) 2024/573 (gases fluorados) e Decreto-Lei n.º 145/2017 | E11: Regulamento UE | F11: 45329 | G11: UE / Nacional | H11: APA / IGAMAOT | I11: Controlo de fugas periódico conforme a carga em tCO2e, por técnico certificado; registos do equipamento; reparação e reposição documentadas; comunicação anual quando aplicável. | J11: Sim | K11: Chiller CH-01 com 30 kg de R410A (≈ 62,6 tCO2e → controlo de fugas semestral). | L11: UTL | M11: AA-025 | N11: Contrato de manutenção com empresa certificada; registo do equipamento CH-01. | O11: Relatórios de controlo de fugas de 05/2026 e 18/11/2026 (sem fugas), assinados por técnico certificado. | P11: Relatório / registo | Q11: 46344 | R11: C | S11: 46346 | T11: 6 | U11: =IF(S11="","",EDATE(S11,T11)) -> 46527 | V11: =IF(Q11="","",DataRef-Q11) -> 43 | W11: =IF(AND(R11="NC",X11=""),"NC sem ação no PAM",IF(U11<DataRef,"Avaliação vencida",IF(U11-DataRef<=60,"Avaliar nos próximos 60 dias",IF(R11="NC","NC com ação em curso","OK")))) -> OK | Y11: Gerente de Manutenção | Z11: https://eur-lex.europa.eu/eli/reg/2024/573/oj | AA11: Obrigação legal | AB11: Operador de equipamento com gases fluorados
A12: LEG-08 | B12: ENE | C12: Energia | D12: Decreto-Lei n.º 71/2008, de 15 de abril (SGCIE — consumidores intensivos de energia) | E12: Decreto-Lei | F12: 39553 | G12: Nacional | H12: DGEG / ADENE | I12: Instalações com consumo ≥ 500 tep/ano: registo, auditoria energética periódica e Plano de Racionalização do Consumo de Energia (PREn) com metas de intensidade energética e relatórios de execução. | J12: Sim | K12: Consumo ≈ 7,8 GWh em 2026 ≈ 1.680 tep/ano (fator 0,215 tep/MWh). | L12: INJ; SOP; UTL; GER | M12: AA-007; AA-010; AA-021; AA-030 | N12: Registo SGCIE; auditoria energética de 2022; ARCE com metas até 2029. | O12: Relatório de execução e progresso do ARCE (2024–2025) submetido na plataforma SGCIE em 28/04/2026; auditoria energética de 2022 válida até 2030. | P12: Plataforma / comprovativo | Q12: 46140 | R12: C | S12: 46275 | T12: 24 | U12: =IF(S12="","",EDATE(S12,T12)) -> 47006 | V12: =IF(Q12="","",DataRef-Q12) -> 247 | W12: =IF(AND(R12="NC",X12=""),"NC sem ação no PAM",IF(U12<DataRef,"Avaliação vencida",IF(U12-DataRef<=60,"Avaliar nos próximos 60 dias",IF(R12="NC","NC com ação em curso","OK")))) -> OK | Y12: Gerente de Manutenção | Z12: Diário da República — DL 71/2008 | AA12: Obrigação legal | AB12: Consumidor intensivo de energia
A13: LEG-09 | B13: EMB | C13: Embalagens (produto) | D13: Regulamento (UE) 2025/40 (PPWR) — aplicável desde 12/08/2026 | E13: Regulamento UE | F13: 45679 | G13: UE | H13: APA / ASAE | I13: Fabricante de embalagens: avaliação da conformidade, documentação técnica e declaração UE de conformidade; limites de chumbo, cádmio, mercúrio e crómio VI; restrições a substâncias preocupantes; preparação para metas de reciclabilidade e conteúdo reciclado. | J13: Sim | K13: A Plasticom fabrica embalagens colocadas no mercado da UE (cosmética, alimentar, farmacêutica). | L13: RD; LAB | M13: AA-037; AA-038; AA-043 | N13: Fichas técnicas de produto; declarações de contacto alimentar (linha alimentar); análise de metais pesados por família. | O13: Em 22/12/2026: documentação técnica e declaração UE de conformidade concluídas para 17 de 22 famílias (77%); as 5 restantes (PP-PG e PET-PG farmacêuticas; PETG e PVC em substituição — PAM-26-22) em 2027. | P13: Registo / dossier | Q13: 46378 | R13: NC | S13: 46378 | T13: 6 | U13: =IF(S13="","",EDATE(S13,T13)) -> 46560 | V13: =IF(Q13="","",DataRef-Q13) -> 9 | W13: =IF(AND(R13="NC",X13=""),"NC sem ação no PAM",IF(U13<DataRef,"Avaliação vencida",IF(U13-DataRef<=60,"Avaliar nos próximos 60 dias",IF(R13="NC","NC com ação em curso","OK")))) -> NC com ação em curso | X13: PAM-26-10 | Y13: Responsável de R&D | Z13: https://eur-lex.europa.eu/eli/reg/2025/40/oj | AA13: Obrigação legal | AB13: Fabricante de embalagens e fornecedor a fabricantes de produtos embalados | AC13: EU-ENV-001; EU-ENV-002; EU-ENV-003; EU-ENV-004; EU-ENV-005; EU-ENV-010; EU-ENV-011; EU-ENV-013; EU-ENV-014; EU-ENV-015; PHAR-006; PT-004
A14: LEG-10 | B14: GRA | C14: Perdas de granulado | D14: Regulamento (UE) 2025/2365 (prevenção de perdas de granulados de plástico) e REACH anexo XVII, entrada 78 (Reg. (UE) 2023/2055 — relatório anual de microplásticos) | E14: Regulamento UE | G14: UE | H14: APA | I14: Evitar perdas de granulado com a hierarquia de medidas e notificar cada instalação à autoridade até 17/12/2027; instalações < 1.500 t/ano: declaração de conformidade (certificação por terceiros só ≥ 1.500 t/ano); relatório anual à ECHA das libertações estimadas até 31/05 (entrada 78). | J14: Futuro | K14: A Plasticom manipula ≈ 865 t/ano de granulado (< 1.500 t): notificação e declaração de conformidade até 17/12/2027; o relatório de microplásticos já é exigível (submetido em 28/05/2026). | L14: REC; INJ; SOP; MOA | M14: AA-003 | N14: Varrimento diário; programa OCS em implementação (PAM-26-11). | O14: Autoavaliação Operation Clean Sweep de 15/12/2026: 11 de 14 pontos críticos com contenção (79%); filtros em todas as sarjetas. | P14: Registo / autoavaliação | Q14: 46371 | R14: Futuro | S14: 46371 | T14: 6 | U14: =IF(S14="","",EDATE(S14,T14)) -> 46553 | V14: =IF(Q14="","",DataRef-Q14) -> 16 | W14: =IF(AND(R14="NC",X14=""),"NC sem ação no PAM",IF(U14<DataRef,"Avaliação vencida",IF(U14-DataRef<=60,"Avaliar nos próximos 60 dias",IF(R14="NC","NC com ação em curso","OK")))) -> OK | X14: PAM-26-11 | Y14: Gestor do SGA / EHS (Responsável Ambiental) | Z14: https://eur-lex.europa.eu/legal-content/EN/TXT/PDF/?uri=OJ:L_202502365 | AA14: Obrigação legal | AB14: Operador que manipula granulado
A15: LEG-11 | B15: SCI | C15: Emergência / segurança contra incêndio | D15: Decreto-Lei n.º 220/2008, de 12 de novembro (RJ-SCIE) e Portaria n.º 1532/2008 | E15: Decreto-Lei | F15: 39764 | G15: Nacional | H15: ANEPC | I15: Implementar medidas de autoproteção, manter meios de 1.ª intervenção, formação e simulacros com a periodicidade da categoria de risco. | J15: Sim | K15: Utilização-tipo XII (industrial), 2.ª categoria de risco. | L15: GER; REC; ARQ | M15: AA-034; AA-005 | N15: Medidas de autoproteção aprovadas; extintores e RIA com manutenção anual; válvula de corte na rede pluvial. | O15: Simulacros de 26/11/2026 (derrame no armazém de químicos) e 11/12/2026 (incêndio com retenção das águas): evacuação em 5 min; VC-01 fechada em 4 min. | P15: Registo / relatório | Q15: 46367 | R15: C | S15: 46367 | T15: 12 | U15: =IF(S15="","",EDATE(S15,T15)) -> 46732 | V15: =IF(Q15="","",DataRef-Q15) -> 20 | W15: =IF(AND(R15="NC",X15=""),"NC sem ação no PAM",IF(U15<DataRef,"Avaliação vencida",IF(U15-DataRef<=60,"Avaliar nos próximos 60 dias",IF(R15="NC","NC com ação em curso","OK")))) -> OK | Y15: Diretor Industrial | Z15: Diário da República — DL 220/2008 | AA15: Obrigação legal | AB15: Utilização-tipo XII (industrial)
A16: LEG-12 | B16: EAR | C16: Ar — fontes pontuais | D16: Decreto-Lei n.º 39/2018, de 11 de junho (prevenção e controlo das emissões para o ar) | E16: Decreto-Lei | F16: 43262 | G16: Nacional | H16: CCDR Centro | I16: Fontes pontuais: chaminé com tomas de amostragem normalizadas, altura adequada e monitorização pontual conforme o caudal mássico; comunicação dos resultados. | J16: Sim | K16: Chaminé da estufa de cura da serigrafia (FP1). | L16: SER | M16: AA-014 | N16: Chaminé FP1 com tomas de amostragem normalizadas; exaustão localizada nas máquinas de serigrafia. | O16: Relatório de ensaio n.º 2026/03-EF (laboratório acreditado, 18/03/2026): COVT 22 mg C/Nm³, caudal mássico 0,04 kg C/h — abaixo do limiar mássico; próxima monitorização em 2029. | P16: Relatório de ensaio | Q16: 46099 | R16: C | S16: 46275 | T16: 36 | U16: =IF(S16="","",EDATE(S16,T16)) -> 47371 | V16: =IF(Q16="","",DataRef-Q16) -> 288 | W16: =IF(AND(R16="NC",X16=""),"NC sem ação no PAM",IF(U16<DataRef,"Avaliação vencida",IF(U16-DataRef<=60,"Avaliar nos próximos 60 dias",IF(R16="NC","NC com ação em curso","OK")))) -> OK | Y16: Gestor do SGA / EHS (Responsável Ambiental) | Z16: Diário da República — DL 39/2018 | AA16: Obrigação legal | AB16: Operador de fonte pontual
A17: LEG-13 | B17: RES | C17: Transporte de resíduos | D17: Portaria n.º 145/2017, de 26 de abril (guias eletrónicas e-GAR) | E17: Portaria | F17: 42851 | G17: Nacional | H17: APA / GNR-SEPNA | I17: Emitir e-GAR antes de cada transporte de resíduos e confirmar a receção pelo destinatário no SILiAmb. | J17: Sim | K17: Todos os envios de resíduos da Plasticom. | L17: PRS | M17: AA-016; AA-026; AA-029 | N17: Emissão de e-GAR pelo Responsável de Armazém; conferência mensal no SILiAmb. | O17: Conferência de novembro/2026: 31 e-GAR emitidas, 31 com receção confirmada (100%). | P17: Plataforma / comprovativo | Q17: 46359 | R17: C | S17: 46359 | T17: 12 | U17: =IF(S17="","",EDATE(S17,T17)) -> 46724 | V17: =IF(Q17="","",DataRef-Q17) -> 28 | W17: =IF(AND(R17="NC",X17=""),"NC sem ação no PAM",IF(U17<DataRef,"Avaliação vencida",IF(U17-DataRef<=60,"Avaliar nos próximos 60 dias",IF(R17="NC","NC com ação em curso","OK")))) -> OK | Y17: Responsável de Armazém e Logística | Z17: Diário da República — Portaria 145/2017 | AA17: Obrigação legal | AB17: Produtor/expedidor de resíduos
A18: LEG-14 | B18: RAM | C18: Responsabilidade ambiental | D18: Decreto-Lei n.º 147/2008, de 29 de julho (regime de responsabilidade por danos ambientais) | E18: Decreto-Lei | F18: 39658 | G18: Nacional | H18: APA | I18: Operadores de atividades do Anexo III: garantia financeira obrigatória e prevenção/reparação de danos ambientais. | J18: Não | K18: Atividade não incluída no Anexo III (sem licença ambiental IED nem gestão de resíduos). A responsabilidade subjetiva geral mantém-se. | L18: GER | N18: Seguro de responsabilidade ambiental voluntário. | O18: Análise de aplicabilidade revista em 10/09/2026: a atividade (CAE 22220) não consta do Anexo III. Apólice voluntária RC-Ambiental n.º 55-0931 válida até 12/2026. | P18: Análise documental | Q18: 46275 | R18: C | S18: 46275 | T18: 12 | U18: =IF(S18="","",EDATE(S18,T18)) -> 46640 | V18: =IF(Q18="","",DataRef-Q18) -> 112 | W18: =IF(AND(R18="NC",X18=""),"NC sem ação no PAM",IF(U18<DataRef,"Avaliação vencida",IF(U18-DataRef<=60,"Avaliar nos próximos 60 dias",IF(R18="NC","NC com ação em curso","OK")))) -> OK | Y18: Diretor Financeiro | Z18: Diário da República — DL 147/2008 | AA18: Obrigação legal | AB18: Operador fora do anexo III
A19: LEG-15 | B19: LEG | C19: Legionella (torres de arrefecimento) | D19: Lei n.º 52/2018, de 20 de agosto (regime de prevenção e controlo da doença dos legionários) | E19: Lei | F19: 43332 | G19: Nacional | H19: DGS / Autoridade de saúde / IGAMAOT | I19: Plano de prevenção e controlo da Legionella para a torre; registo do equipamento; limpeza e desinfeção periódicas; monitorização de Legionella com laboratório acreditado e ação acima do limiar. | J19: Sim | K19: Torre de arrefecimento TR-01 (sistema de arrefecimento com aerossolização). | L19: UTL | M19: AA-023; AA-024 | N19: Plano de prevenção e controlo (AquaHigiene Lda.); limpeza e desinfeção semestral; Legionella trimestral (tbl_analises do RG-SGA-13). | O19: Boletim L26-1207 (07/12/2026): Legionella spp. < 100 UFC/L (limiar de ação 1.000); limpeza e desinfeção semestral a 20/10/2026. | P19: Relatório de ensaio | Q19: 46363 | R19: C | S19: 46364 | T19: 3 | U19: =IF(S19="","",EDATE(S19,T19)) -> 46454 | V19: =IF(Q19="","",DataRef-Q19) -> 24 | W19: =IF(AND(R19="NC",X19=""),"NC sem ação no PAM",IF(U19<DataRef,"Avaliação vencida",IF(U19-DataRef<=60,"Avaliar nos próximos 60 dias",IF(R19="NC","NC com ação em curso","OK")))) -> OK | Y19: Gerente de Manutenção | Z19: Diário da República — Lei 52/2018 | AA19: Obrigação legal | AB19: Proprietário de torre de arrefecimento
A20: LEG-16 | B20: RAP | C20: Embalagens — RAP (responsabilidade alargada do produtor) | D20: Decreto-Lei n.º 152-D/2017, de 11 de dezembro (UNILEX), alterado pelo DL 102-D/2020 — embalagens e resíduos de embalagens | E20: Decreto-Lei | F20: 43080 | G20: Nacional | H20: APA / IGAMAOT | I20: Quem coloca embalagens no mercado nacional (embalador) transfere a responsabilidade pela gestão dos resíduos para um sistema integrado (entidade gestora) ou individual, declara as quantidades e paga a prestação financeira. | J20: Sim | K20: A Plasticom é embaladora das embalagens de expedição (caixas, filme, paletes) enviadas a clientes em Portugal; os clientes são embaladores das embalagens que enchem (a Plasticom fornece-lhes massa e material por SKU). | L20: EXP; ADM | N20: Adesão ao sistema integrado de embalagens não urbanas (contrato NU-2021-0342); massas de expedição por mês, país e material em tbl_emb_expedicao (RG-SGA-20). | O20: Declaração anual de 2025 submetida à entidade gestora em 26/02/2026 e prestação financeira paga; massas de 2026 calculadas a partir das vendas (RG-SGA-20). | P20: Plataforma / comprovativo | Q20: 46079 | R20: C | S20: 46275 | T20: 12 | U20: =IF(S20="","",EDATE(S20,T20)) -> 46640 | V20: =IF(Q20="","",DataRef-Q20) -> 308 | W20: =IF(AND(R20="NC",X20=""),"NC sem ação no PAM",IF(U20<DataRef,"Avaliação vencida",IF(U20-DataRef<=60,"Avaliar nos próximos 60 dias",IF(R20="NC","NC com ação em curso","OK")))) -> OK | Y20: Diretor Financeiro | Z20: https://diariodarepublica.pt/dr/legislacao-consolidada/decreto-lei/2017-114337039 | AA20: Obrigação legal | AB20: Embalador (embalagens de expedição) | AC20: PT-001; PT-003; EU-ENV-016
A21: LEG-17 | B21: FCM | C21: Contacto alimentar (FCM) | D21: Regulamentos (CE) 1935/2004 e 2023/2006 e (UE) 10/2011 e 2022/1616 — materiais plásticos em contacto com alimentos | E21: Regulamento UE | F21: 38287 | G21: UE | H21: ASAE / DGAV | I21: Materiais inertes nas condições de uso; boas práticas de fabrico; só substâncias da lista da União; limites de migração; declaração de conformidade (anexo IV); reciclado só de processos autorizados. | J21: Sim | K21: Linha alimentar (frascos FA-030/031 e tampas TA-014) em HDPE-FG e PP-FG, sem plástico reciclado. | L21: RD; LAB; INJ; SOP | N21: Declarações de conformidade (anexo IV do Reg. 10/2011), ensaios de migração, BPF no sistema de qualidade, declaração PFAS do fornecedor SUP-010. | O21: Ensaios de migração global e específica de 03/2026 (laboratório acreditado) conformes; declaração de conformidade emitida para 4 frascos e 2 tampas; declaração PFAS SUP-010 (07/2026). Falta auditoria interna específica de BPF (Reg. 2023/2006). | P21: Relatório de ensaio | Q21: 46101 | R21: C | S21: 46275 | T21: 12 | U21: =IF(S21="","",EDATE(S21,T21)) -> 46640 | V21: =IF(Q21="","",DataRef-Q21) -> 286 | W21: =IF(AND(R21="NC",X21=""),"NC sem ação no PAM",IF(U21<DataRef,"Avaliação vencida",IF(U21-DataRef<=60,"Avaliar nos próximos 60 dias",IF(R21="NC","NC com ação em curso","OK")))) -> OK | Y21: Gerente da Qualidade | Z21: https://eur-lex.europa.eu/eli/reg/2011/10/oj | AA21: Obrigação legal | AB21: Fabricante de materiais em contacto com alimentos | AC21: FCM-001; FCM-002; FCM-003; FCM-004; FCM-005; EU-ENV-012
A22: LEG-18 | B22: ALE | C22: Alegações ambientais | D22: Diretiva (UE) 2024/825 (capacitação dos consumidores para a transição ecológica) — aplicável a partir de 27/09/2026; confirmar a transposição nacional | E22: Diretiva UE | F22: 45357 | G22: UE / Nacional | H22: DGC / ASAE | I22: Proíbe alegações ambientais genéricas sem desempenho reconhecido, alegações de neutralidade baseadas em compensações e alegações sobre o produto inteiro quando só se aplicam a uma parte. | J22: Futuro | K22: A Plasticom comunica alegações (site, catálogo, fichas técnicas) que chegam ao consumidor através dos clientes. | L22: ADM; RD | N22: PR-SGA-14; registo de alegações tbl_alegacoes (RG-SGA-20) com evidência e estado. | O22: Alegações proibidas retiradas do site e do catálogo a 29/09/2026 (PAM-26-27); formação da equipa comercial a 15/10/2026. | P22: Registo / relatório | Q22: 46310 | R22: Futuro | S22: 46310 | T22: 6 | U22: =IF(S22="","",EDATE(S22,T22)) -> 46492 | V22: =IF(Q22="","",DataRef-Q22) -> 77 | W22: =IF(AND(R22="NC",X22=""),"NC sem ação no PAM",IF(U22<DataRef,"Avaliação vencida",IF(U22-DataRef<=60,"Avaliar nos próximos 60 dias",IF(R22="NC","NC com ação em curso","OK")))) -> OK | X22: PAM-26-27 | Y22: Diretor Geral (Gestão de Topo) | Z22: https://eur-lex.europa.eu/eli/dir/2024/825/oj | AA22: Obrigação legal | AB22: Autor de comunicações comerciais | AC22: EU-ENV-018; COS-005
A23: LEG-19 | B23: SUP | C23: Plásticos de utilização única | D23: Diretiva (UE) 2019/904 (SUP) e Decreto-Lei n.º 78/2021, de 24 de setembro | E23: Decreto-Lei | F23: 44463 | G23: UE / Nacional | H23: APA / ASAE | I23: Recipientes para bebidas até 3 L com tampas de plástico têm de ter tampas presas; recipientes para alimentos de consumo imediato com medidas de redução e RAP. | J23: Condicional | K23: Só se os frascos alimentares FA-030/031 forem usados para bebidas — as tampas TA-014 teriam de ser presas (tethered). | L23: RD | N23: Pedido de declaração de utilização aos clientes CUST-015 e CUST-016. | O23: Declarações de utilização recebidas a 04/12/2026 (PAM-26-26): CUST-015/016 não usam os frascos para bebidas — requisito não aplicável aos SKUs atuais. | P23: Análise documental | Q23: 46360 | R23: C | S23: 46360 | T23: 6 | U23: =IF(S23="","",EDATE(S23,T23)) -> 46542 | V23: =IF(Q23="","",DataRef-Q23) -> 27 | W23: =IF(AND(R23="NC",X23=""),"NC sem ação no PAM",IF(U23<DataRef,"Avaliação vencida",IF(U23-DataRef<=60,"Avaliar nos próximos 60 dias",IF(R23="NC","NC com ação em curso","OK")))) -> OK | X23: PAM-26-26 | Y23: Responsável de R&D | Z23: https://eur-lex.europa.eu/eli/dir/2019/904/oj | AA23: Necessita verificação | AB23: Fabricante de tampas (condicional) | AC23: EU-ENV-007; PT-006
A24: LEG-20 | B24: CLI | C24: Outros requisitos (clientes / voluntários) | D24: Requisitos de clientes: acordos de qualidade farmacêuticos (Diretiva 2001/83/CE, EudraLex vol. 4, guideline EMA de materiais plásticos) e cosméticos (Reg. (CE) 1223/2009) | E24: Requisito de cliente | G24: Contratual | H24: Clientes (auditorias de fornecedor) | I24: Fornecer especificações e composição, notificar alterações de material/processo, permitir auditorias, cumprir a Farmacopeia Europeia (PP-PG, PET-PG) e as especificações de embalagem primária. | J24: Sim | K24: Fornecedor de acondicionamento primário a CUST-017/018 (farmacêutico) e a clientes de cosmética e higiene. | L24: RD; LAB; CMP | N24: Acordos de qualidade; controlo de alterações notificado ao cliente (RG-SGA-18); especificações aprovadas. | O24: Auditoria de CUST-017 (14/05/2026) sem NC maiores; falta a carta de acesso ao DMF do PET-PG (fornecedor SUP-009). | P24: Relatório / registo | Q24: 46156 | R24: C | S24: 46275 | T24: 12 | U24: =IF(S24="","",EDATE(S24,T24)) -> 46640 | V24: =IF(Q24="","",DataRef-Q24) -> 231 | W24: =IF(AND(R24="NC",X24=""),"NC sem ação no PAM",IF(U24<DataRef,"Avaliação vencida",IF(U24-DataRef<=60,"Avaliar nos próximos 60 dias",IF(R24="NC","NC com ação em curso","OK")))) -> OK | Y24: Gerente da Qualidade | Z24: Contratos e acordos de qualidade | AA24: Requisito contratual | AB24: Fornecedor de acondicionamento primário | AC24: COS-001; COS-002; COS-003; COS-004; PHAR-001; PHAR-003; PHAR-004; PHAR-005
A25: LEG-21 | B25: VOL | C25: Outros requisitos (clientes / voluntários) | D25: Compromissos voluntários de produto: diretrizes RecyClass (DfR), EN 15343, ISO 14021, ISO 14067, ISO 11469 (política POL-04) | E25: Norma voluntária | G25: Contratual | H25: Organismos de certificação / clientes | I25: Avaliar a reciclabilidade de todos os SKUs, comprovar o conteúdo reciclado com certificados EN 15343 e só fazer alegações comprovadas. | J25: Sim | K25: Compromisso da política ambiental (POL-04) e pedidos de 7 de 9 grandes clientes. | L25: RD; CMP; ADM | N25: Autoavaliação RecyClass por SKU (RG-SGA-20 tbl_recyclass); certificados dos fornecedores de PCR (tbl_certificados_pcr). | O25: Controlo de 18/12/2026 (PAM-26-25): certificados EN 15343 válidos para 100% dos lotes de PCR em uso; CERT-03 substituído. | P25: Registo / dossier | Q25: 46374 | R25: C | S25: 46374 | T25: 12 | U25: =IF(S25="","",EDATE(S25,T25)) -> 46739 | V25: =IF(Q25="","",DataRef-Q25) -> 13 | W25: =IF(AND(R25="NC",X25=""),"NC sem ação no PAM",IF(U25<DataRef,"Avaliação vencida",IF(U25-DataRef<=60,"Avaliar nos próximos 60 dias",IF(R25="NC","NC com ação em curso","OK")))) -> OK | X25: PAM-26-25 | Y25: Responsável de R&D | Z25: https://recyclass.eu | AA25: Norma voluntária | AB25: Organização (compromisso voluntário) | AC25: ISO-001; ISO-002; ISO-003; ISO-004; ISO-007; ISO-008; ISO-009; ISO-010; ISO-011; ISO-012; ISO-013; ISO-014
A26: LEG-22 | B26: QUI | C26: Produtos químicos | D26: Decreto-Lei n.º 24/2012 (agentes químicos) e Decreto-Lei n.º 301/2000 na redação do DL 102/2024 (cancerígenos, mutagénicos e reprotóxicos) — SST integrada na gestão de químicos | E26: Decreto-Lei | F26: 40945 | G26: Nacional | H26: ACT | I26: Avaliar e registar o risco de todos os agentes químicos (incl. gerados no processo); cumprir VLE e medir quando necessário; substituir CMR/reprotóxicos 1A/1B; lista de trabalhadores expostos; vigilância da saúde; informação e formação. | J26: Sim | K26: Empregador com agentes químicos perigosos (tintas, solventes, aerossóis, biocidas) e uma tinta UV reprotóxica (Repr. 1B). | L26: SER; MAN; UTL; LAB; SOP | M26: AA-014; AA-015 | N26: Avaliação de risco químico por tarefa e medições NP EN 689 no RG-SGA-21 (tbl_risco_quimico, tbl_medicoes_vle); procedimento PR-SGA-16. | O26: Avaliação de 24/09/2026 (RG-SGA-21): 21 tarefas avaliadas, 5 de prioridade P1; 5 produtos perigosos sem avaliação; lista de trabalhadores expostos a reprotóxicos inexistente (tinta UV QUI-002); medições de 11/2025 conformes na SS-002 e inconclusivas na SS-001. | P26: Registo / avaliação | Q26: 46289 | R26: NC | S26: 46275 | T26: 12 | U26: =IF(S26="","",EDATE(S26,T26)) -> 46640 | V26: =IF(Q26="","",DataRef-Q26) -> 98 | W26: =IF(AND(R26="NC",X26=""),"NC sem ação no PAM",IF(U26<DataRef,"Avaliação vencida",IF(U26-DataRef<=60,"Avaliar nos próximos 60 dias",IF(R26="NC","NC com ação em curso","OK")))) -> NC com ação em curso | X26: PAM-26-29 | Y26: Gestor do SGA / EHS (Responsável Ambiental) | Z26: https://diariodarepublica.pt/dr/detalhe/decreto-lei/102-2024-898867718 | AA26: Obrigação legal (SST — gestão integrada de químicos) | AB26: Empregador (agentes químicos e CMR)

Sheet Calendario_Obrigacoes
A1: ID_Obrigacao | B1: ID_Legal | C1: Obrigacao | D1: Frequencia | E1: Prazo_Proximo | F1: Ultimo_Cumprimento | G1: Evidencia | H1: Responsavel | I1: Dias_ate_Prazo | J1: Estado
A2: OBR-01 | B2: LEG-01 | C2: Submeter o MIRR do ano anterior no SILiAmb | D2: Anual | E2: 46477 | F2: 46099 | G2: Comprovativo MIRR-2025-PLA-0417 | H2: Gestor do SGA / EHS (Responsável Ambiental) | I2: =E2-DataRef -> 90 | J2: =IF(I2<0,IF(F2>=E2,"Cumprida em atraso","VENCIDA"),IF(I2<=30,"A vencer (≤30 d)","Em dia")) -> Em dia
A3: OBR-02 | B3: LEG-13 | C3: Emitir e-GAR antes de cada transporte e confirmar receção | D3: Por ocorrência | E3: 46418 | F3: 46374 | G3: e-GAR de dezembro (conferência mensal) | H3: Responsável de Armazém e Logística | I3: =E3-DataRef -> 31 | J3: =IF(I3<0,IF(F3>=E3,"Cumprida em atraso","VENCIDA"),IF(I3<=30,"A vencer (≤30 d)","Em dia")) -> Em dia
A4: OBR-03 | B4: LEG-03 | C4: Autocontrolo analítico semestral do efluente | D4: Semestral | E4: 46550 | F4: 46366 | G4: Boletim 26/2410 | H4: Gerente de Manutenção | I4: =E4-DataRef -> 163 | J4: =IF(I4<0,IF(F4>=E4,"Cumprida em atraso","VENCIDA"),IF(I4<=30,"A vencer (≤30 d)","Em dia")) -> Em dia
A5: OBR-04 | B5: LEG-07 | C5: Controlo de fugas do chiller CH-01 (≥ 50 tCO2e) | D5: Semestral | E5: 46527 | F5: 46344 | G5: Relatório de controlo de fugas 11/2026 (sem fugas) | H5: Gerente de Manutenção | I5: =E5-DataRef -> 140 | J5: =IF(I5<0,IF(F5>=E5,"Cumprida em atraso","VENCIDA"),IF(I5<=30,"A vencer (≤30 d)","Em dia")) -> Em dia
A6: OBR-05 | B6: LEG-08 | C6: Relatório de execução e progresso do ARCE (SGCIE) | D6: Bienal | E6: 46873 | F6: 46140 | G6: Submissão SGCIE 28/04/2026 | H6: Gerente de Manutenção | I6: =E6-DataRef -> 486 | J6: =IF(I6<0,IF(F6>=E6,"Cumprida em atraso","VENCIDA"),IF(I6<=30,"A vencer (≤30 d)","Em dia")) -> Em dia
A7: OBR-06 | B7: LEG-08 | C7: Auditoria energética SGCIE | D7: Octenal | E7: 47664 | F7: 44727 | G7: Relatório de auditoria energética 2022 | H7: Gerente de Manutenção | I7: =E7-DataRef -> 1277 | J7: =IF(I7<0,IF(F7>=E7,"Cumprida em atraso","VENCIDA"),IF(I7<=30,"A vencer (≤30 d)","Em dia")) -> Em dia
A8: OBR-07 | B8: LEG-12 | C8: Monitorização pontual da chaminé FP1 | D8: Trienal | E8: 47195 | F8: 46099 | G8: Relatório 2026/03-EF | H8: Gestor do SGA / EHS (Responsável Ambiental) | I8: =E8-DataRef -> 808 | J8: =IF(I8<0,IF(F8>=E8,"Cumprida em atraso","VENCIDA"),IF(I8<=30,"A vencer (≤30 d)","Em dia")) -> Em dia
A9: OBR-08 | B9: LEG-05 | C9: Avaliação acústica após alteração dos compressores | D9: Por ocorrência | E9: 47419 | F9: 46323 | G9: Relatório AC-2026-112 (conforme) | H9: Gestor do SGA / EHS (Responsável Ambiental) | I9: =E9-DataRef -> 1032 | J9: =IF(I9<0,IF(F9>=E9,"Cumprida em atraso","VENCIDA"),IF(I9<=30,"A vencer (≤30 d)","Em dia")) -> Em dia
A10: OBR-09 | B10: LEG-11 | C10: Simulacro de emergência (medidas de autoproteção) | D10: Anual | E10: 46717 | F10: 46352 | G10: Relatórios de simulacro 26/11 e 11/12/2026 | H10: Diretor Industrial | I10: =E10-DataRef -> 330 | J10: =IF(I10<0,IF(F10>=E10,"Cumprida em atraso","VENCIDA"),IF(I10<=30,"A vencer (≤30 d)","Em dia")) -> Em dia
A11: OBR-10 | B11: LEG-15 | C11: Análise trimestral de Legionella na torre TR-01 | D11: Trimestral | E11: 46454 | F11: 46363 | G11: Boletim L26-1207 | H11: Gerente de Manutenção | I11: =E11-DataRef -> 67 | J11: =IF(I11<0,IF(F11>=E11,"Cumprida em atraso","VENCIDA"),IF(I11<=30,"A vencer (≤30 d)","Em dia")) -> Em dia
A12: OBR-14 | B12: LEG-11 | C12: Manutenção anual de extintores e RIA | D12: Anual | E12: 46461 | F12: 46096 | G12: Relatório da empresa de manutenção | H12: Diretor Industrial | I12: =E12-DataRef -> 74 | J12: =IF(I12<0,IF(F12>=E12,"Cumprida em atraso","VENCIDA"),IF(I12<=30,"A vencer (≤30 d)","Em dia")) -> Em dia
A13: OBR-11 | B13: LEG-06 | C13: Revisão do inventário de químicos e das FDS (e pedido de confirmação das FDS com mais de 36 meses) | D13: Anual | E13: 46632 | F13: 46267 | G13: RG-SGA-21 Inventario e FDS_Verificacao | H13: Responsável de Armazém e Logística | I13: =E13-DataRef -> 245 | J13: =IF(I13<0,IF(F13>=E13,"Cumprida em atraso","VENCIDA"),IF(I13<=30,"A vencer (≤30 d)","Em dia")) -> Em dia
A14: OBR-12 | B14: LEG-09 | C14: Declaração UE de conformidade PPWR por família de embalagem | D14: Por ocorrência | E14: 46246 | G14: Em curso: 17/22 famílias concluídas (PAM-26-10 concluída; 5 famílias em 2027) | H14: Responsável de R&D | I14: =E14-DataRef -> -141 | J14: =IF(I14<0,IF(F14>=E14,"Cumprida em atraso","VENCIDA"),IF(I14<=30,"A vencer (≤30 d)","Em dia")) -> VENCIDA
A15: OBR-13 | B15: LEG-04 | C15: Balanço anual de solventes (confirmar não aplicabilidade) | D15: Anual | E15: 46635 | F15: 46270 | G15: BAL-SOLV-2026 | H15: Gestor do SGA / EHS (Responsável Ambiental) | I15: =E15-DataRef -> 248 | J15: =IF(I15<0,IF(F15>=E15,"Cumprida em atraso","VENCIDA"),IF(I15<=30,"A vencer (≤30 d)","Em dia")) -> Em dia
A16: OBR-15 | B16: LEG-16 | C16: Declaração anual das embalagens de expedição à entidade gestora (SIGRE) | D16: Anual | E16: 46446 | F16: 46079 | G16: Declaração 2025 (26/02/2026) | H16: Diretor Financeiro | I16: =E16-DataRef -> 59 | J16: =IF(I16<0,IF(F16>=E16,"Cumprida em atraso","VENCIDA"),IF(I16<=30,"A vencer (≤30 d)","Em dia")) -> Em dia
A17: OBR-16 | B17: LEG-21 | C17: Reavaliação anual da reciclabilidade por SKU (RecyClass / graus PPWR) | D17: Anual | E17: 46652 | F17: 46287 | G17: RG-SGA-20 tbl_recyclass | H17: Responsável de R&D | I17: =E17-DataRef -> 265 | J17: =IF(I17<0,IF(F17>=E17,"Cumprida em atraso","VENCIDA"),IF(I17<=30,"A vencer (≤30 d)","Em dia")) -> Em dia
A18: OBR-17 | B18: LEG-17 | C18: Rever declarações de conformidade FCM (alteração de material ou legislação) | D18: Anual | E18: 46466 | F18: 46101 | G18: DoC anexo IV + ensaios de migração 03/2026 | H18: Gerente da Qualidade | I18: =E18-DataRef -> 79 | J18: =IF(I18<0,IF(F18>=E18,"Cumprida em atraso","VENCIDA"),IF(I18<=30,"A vencer (≤30 d)","Em dia")) -> Em dia
A19: OBR-18 | B19: LEG-18 | C19: Retirar alegações proibidas antes da aplicação da Diretiva 2024/825 | D19: Por ocorrência | E19: 46292 | F19: 46294 | G19: Alegações retiradas a 29/09/2026 (PAM-26-27) | H19: Diretor Geral (Gestão de Topo) | I19: =E19-DataRef -> -95 | J19: =IF(I19<0,IF(F19>=E19,"Cumprida em atraso","VENCIDA"),IF(I19<=30,"A vencer (≤30 d)","Em dia")) -> Cumprida em atraso
A20: OBR-19 | B20: LEG-06 | C20: Verificar a atualização da lista candidata SVHC (ECHA: janeiro e junho), atualizar o parâmetro P-01 e rever SVHC nas embalagens (art. 33.º / SCIP) | D20: Semestral | E20: 46428 | F20: 46233 | G20: Lista candidata de junho/2026 verificada; P-01 atualizado | H20: Gestor do SGA / EHS (Responsável Ambiental) | I20: =E20-DataRef -> 41 | J20: =IF(I20<0,IF(F20>=E20,"Cumprida em atraso","VENCIDA"),IF(I20<=30,"A vencer (≤30 d)","Em dia")) -> Em dia
A21: OBR-20 | B21: LEG-10 | C21: Relatório anual à ECHA das libertações estimadas de granulado (REACH anexo XVII, entrada 78) | D21: Anual | E21: 46538 | F21: 46170 | G21: Submissão REACH-IT (dados de 2025) | H21: Gestor do SGA / EHS (Responsável Ambiental) | I21: =E21-DataRef -> 151 | J21: =IF(I21<0,IF(F21>=E21,"Cumprida em atraso","VENCIDA"),IF(I21<=30,"A vencer (≤30 d)","Em dia")) -> Em dia
A22: OBR-21 | B22: LEG-06 | C22: Renovar as declarações SVHC/PFAS/metais/BPA/FCM dos fornecedores | D22: Anual | E22: 46451 | F22: 46086 | G22: RG-SGA-21 tbl_declaracoes | H22: Responsável de Compras | I22: =E22-DataRef -> 64 | J22: =IF(I22<0,IF(F22>=E22,"Cumprida em atraso","VENCIDA"),IF(I22<=30,"A vencer (≤30 d)","Em dia")) -> Em dia
A23: OBR-22 | B23: LEG-22 | C23: Rever a avaliação de riscos químicos (e sempre que houver alteração) | D23: Trienal | E23: 46461 | F23: 45366 | G23: RG-SGA-21 tbl_risco_quimico | H23: Gestor do SGA / EHS (Responsável Ambiental) | I23: =E23-DataRef -> 74 | J23: =IF(I23<0,IF(F23>=E23,"Cumprida em atraso","VENCIDA"),IF(I23<=30,"A vencer (≤30 d)","Em dia")) -> Em dia
A24: OBR-23 | B24: LEG-22 | C24: Medição da exposição a COV na serigrafia (NP EN 689) | D24: Anual | E24: 46711 | F24: 46345 | G24: Relatório de medição NP EN 689 (19/11/2026) | H24: Gestor do SGA / EHS (Responsável Ambiental) | I24: =E24-DataRef -> 324 | J24: =IF(I24<0,IF(F24>=E24,"Cumprida em atraso","VENCIDA"),IF(I24<=30,"A vencer (≤30 d)","Em dia")) -> Em dia
A25: OBR-24 | B25: LEG-02 | C25: Verificação Seveso — regra da soma com o stock máximo do inventário (DL 150/2015) | D25: Anual | E25: 46632 | F25: 46267 | G25: RG-SGA-21 Seveso | H25: Gestor do SGA / EHS (Responsável Ambiental) | I25: =E25-DataRef -> 245 | J25: =IF(I25<0,IF(F25>=E25,"Cumprida em atraso","VENCIDA"),IF(I25<=30,"A vencer (≤30 d)","Em dia")) -> Em dia
A26: OBR-25 | B26: LEG-06 | C26: Renovar a formação em diisocianatos (5 anos — anexo XVII, entrada 74) | D26: Quinquenal | E26: 46975 | F26: 45148 | G26: RG-SGA-08 FOR-13 | H26: Responsável de Recursos Humanos | I26: =E26-DataRef -> 588 | J26: =IF(I26<0,IF(F26>=E26,"Cumprida em atraso","VENCIDA"),IF(I26<=30,"A vencer (≤30 d)","Em dia")) -> Em dia
A27: OBR-26 | B27: LEG-10 | C27: Notificar as instalações e emitir a declaração de conformidade (< 1.500 t/ano) — Reg. (UE) 2025/2365 | D27: Por ocorrência | E27: 46738 | G27: PAM-26-11 | H27: Gestor do SGA / EHS (Responsável Ambiental) | I27: =E27-DataRef -> 351 | J27: =IF(I27<0,IF(F27>=E27,"Cumprida em atraso","VENCIDA"),IF(I27<=30,"A vencer (≤30 d)","Em dia")) -> Em dia
A28: OBR-27 | B28: LEG-22 | C28: Vigilância da saúde dos trabalhadores expostos a sensibilizantes e CMR | D28: Anual | E28: 46407 | F28: 46042 | G28: Fichas de aptidão (medicina do trabalho) | H28: Responsável de Recursos Humanos | I28: =E28-DataRef -> 20 | J28: =IF(I28<0,IF(F28>=E28,"Cumprida em atraso","VENCIDA"),IF(I28<=30,"A vencer (≤30 d)","Em dia")) -> A vencer (≤30 d)
A29: OBR-28 | B29: LEG-22 | C29: Criar e rever a lista de trabalhadores expostos a CMR/reprotóxicos (DL 301/2000) | D29: Anual | E29: 46703 | F29: 46338 | G29: Lista de expostos a CMR criada (12/11/2026) | H29: Gestor do SGA / EHS (Responsável Ambiental) | I29: =E29-DataRef -> 316 | J29: =IF(I29<0,IF(F29>=E29,"Cumprida em atraso","VENCIDA"),IF(I29<=30,"A vencer (≤30 d)","Em dia")) -> Em dia
A30: OBR-29 | B30: LEG-06 | C30: Acompanhar prazos CLP (Reg. 2023/707 — novas classes; Reg. 2025/2439 — rótulos) e alterações aos anexos do REACH | D30: Semestral | E30: 46492 | F30: 46309 | G30: Revisão CLP/REACH de 14/10/2026 | H30: Gestor do SGA / EHS (Responsável Ambiental) | I30: =E30-DataRef -> 105 | J30: =IF(I30<0,IF(F30>=E30,"Cumprida em atraso","VENCIDA"),IF(I30<=30,"A vencer (≤30 d)","Em dia")) -> Em dia
A31: OBR-30 | B31: LEG-15 | C31: Confirmar a validade da autorização do biocida da torre (Reg. (UE) 528/2012) | D31: Anual | E31: 46547 | F31: 46182 | G31: RG-SGA-21 FDS-036; rótulo com n.º de autorização | H31: Gerente de Manutenção | I31: =E31-DataRef -> 160 | J31: =IF(I31<0,IF(F31>=E31,"Cumprida em atraso","VENCIDA"),IF(I31<=30,"A vencer (≤30 d)","Em dia")) -> Em dia

Sheet Historico_Avaliacoes
A1: ID_Legal | B1: Ciclo | C1: Data_Avaliacao | D1: Estado
A2: LEG-01 | B2: 2025 | C2: 45912 | D2: C
A3: LEG-01 | B3: 2026 | C3: 46275 | D3: C
A4: LEG-02 | B4: 2025 | C4: 45912 | D4: C
A5: LEG-02 | B5: 2026 | C5: 46275 | D5: C
A6: LEG-03 | B6: 2025 | C6: 45912 | D6: C
A7: LEG-03 | B7: 2026 | C7: 46275 | D7: C
A8: LEG-04 | B8: 2025 | C8: 45912 | D8: C
A9: LEG-04 | B9: 2026 | C9: 46275 | D9: C
A10: LEG-05 | B10: 2025 | C10: 45912 | D10: C
A11: LEG-05 | B11: 2026 | C11: 46275 | D11: NC
A12: LEG-06 | B12: 2025 | C12: 45912 | D12: NC
A13: LEG-06 | B13: 2026 | C13: 46275 | D13: NC
... A45: LEG-22 | B45: 2026 | C45: 46275 | D45: NC

Sheet Mod.G.06.02_Vista
A1: PLASTICOM | B1: TABELA DE IDENTIFICAÇÃO DE REQUISITOS LEGAIS E AVALIAÇÃO DA CONFORMIDADE | G1: Mod. G.06.02
B2: Plasticom — Unidade 1 (Marinha Grande, Portugal) · NP EN ISO 14001:2026 | G2: Rev. 01 · 31/12/2026
A5: Código / Tema | B5: Diploma / Documento | C5: Resumo / Obrigações | D5: Aplicabilidade | E5: Disposições Internas | F5: Avaliação da Conformidade (EVIDÊNCIA) | G5: Estado (C/NC)
A6: =INDEX(Requisitos_Legais!$C$5:$C$26,1) -> Resíduos industriais | B6: =INDEX(Requisitos_Legais!$D$5:$D$26,1) -> Decreto-Lei n.º 102-D/2020, de 10 de dezembro (RGGR) | C6: =INDEX(Requisitos_Legais!$I$5:$I$26,1) -> Separar na origem, armazenar em condições adequadas, classificar pela Lista Europeia de Resíduos (LER), encaminhar para operadores licenciados e submeter o MIRR anual no SILiAmb até 31 de março. | D6: =INDEX(Requisitos_Legais!$J$5:$J$26,1)&IF(INDEX(Requisitos_Legais!$J$5:$J$26,1)="Sim",""," — "&INDEX(Requisitos_Legais!$K$5:$K$26,1)) -> Sim | E6: =INDEX(Requisitos_Legais!$N$5:$N$26,1) -> Parque de resíduos com contentores identificados por código LER; balança de plataforma verificada; contratos com 7 operadores licenciados. | F6: =INDEX(Requisitos_Legais!$O$5:$O$26,1) -> Submissão do MIRR 2025 no SILiAmb em 18/03/2026 (comprovativo n.º MIRR-2025-PLA-0417). Amostra de 20 e-GAR de jan–ago/2026: 100% com operador licenciado e código LER coerente com a pesagem interna. | G6: =INDEX(Requisitos_Legais!$R$5:$R$26,1) -> C
A7: =INDEX(Requisitos_Legais!$C$5:$C$26,2) -> Licenciamento industrial | B7: =INDEX(Requisitos_Legais!$D$5:$D$26,2) -> Decreto-Lei n.º 169/2012, de 1 de agosto (SIR), republicado pelo DL 73/2015 | C7: =INDEX(Requisitos_Legais!$I$5:$I$26,2) -> Explorar o estabelecimento industrial com título válido e comunicar alterações que modifiquem a tipologia ou as condições de exploração. | D7: =INDEX(Requisitos_Legais!$J$5:$J$26,2)&IF(INDEX(Requisitos_Legais!$J$5:$J$26,2)="Sim",""," — "&INDEX(Requisitos_Legais!$K$5:$K$26,2)) -> Sim | E7: =INDEX(Requisitos_Legais!$N$5:$N$26,2) -> Título Digital de Exploração arquivado; controlo de mudanças avalia alterações de layout e equipamento. | F7: =INDEX(Requisitos_Legais!$O$5:$O$26,2) -> Título Digital de Exploração n.º TDE-2019-0588 válido; comunicação da instalação dos novos compressores submetida em 04/02/2026 (sem alteração de tipologia). | G7: =INDEX(Requisitos_Legais!$R$5:$R$26,2) -> C
A8: =INDEX(Requisitos_Legais!$C$5:$C$26,3) -> Água e águas residuais | B8: =INDEX(Requisitos_Legais!$D$5:$D$26,3) -> Lei n.º 58/2005 (Lei da Água); Regulamento Municipal de Drenagem de Águas Residuais (Marinha Grande) | C8: =INDEX(Requisitos_Legais!$I$5:$I$26,3) -> Descarregar águas residuais industriais no coletor apenas com autorização e dentro dos valores-limite do regulamento municipal; realizar autocontrolo analítico semestral. | D8: =INDEX(Requisitos_Legais!$J$5:$J$26,3)&IF(INDEX(Requisitos_Legais!$J$5:$J$26,3)="Sim",""," — "&INDEX(Requisitos_Legais!$K$5:$K$26,3)) -> Sim | E8: =INDEX(Requisitos_Legais!$N$5:$N$26,3) -> Autorização de descarga n.º AD-112/2021; ponto de amostragem na caixa de visita final; dosagem automática de biocida. | F8: =INDEX(Requisitos_Legais!$O$5:$O$26,3) -> Boletim de análise n.º 26/2410 (laboratório acreditado, 10/12/2026): pH 7,6; CQO 132 mg/L O2; SST 31 mg/L — todos abaixo do VLE municipal (2.º semestre). | G8: =INDEX(Requisitos_Legais!$R$5:$R$26,3) -> C
A9: =INDEX(Requisitos_Legais!$C$5:$C$26,4) -> Ar — COV (solventes) | B9: =INDEX(Requisitos_Legais!$D$5:$D$26,4) -> Decreto-Lei n.º 127/2013, de 30 de agosto — Capítulo V e Anexo VII (instalações que utilizam solventes orgânicos) | C9: =INDEX(Requisitos_Legais!$I$5:$I$26,4) -> Instalações acima do limiar de consumo de solventes (ex.: 5 t/ano para revestimento de plástico; 15 t/ano para impressão) têm VLE, plano de gestão de solventes e registo. Abaixo do limiar: demonstrar anualmente o consumo. | D9: =INDEX(Requisitos_Legais!$J$5:$J$26,4)&IF(INDEX(Requisitos_Legais!$J$5:$J$26,4)="Sim",""," — "&INDEX(Requisitos_Legais!$K$5:$K$26,4)) -> Não — Consumo anual de solventes ≈ 1,2 t (limpeza + fração solvente das tintas) < 5 t/ano. Manter o cálculo anual para confirmar a não aplicabilidade. | E9: =INDEX(Requisitos_Legais!$N$5:$N$26,4) -> Balanço anual de solventes a partir do inventário (compras − stock). | F9: =INDEX(Requisitos_Legais!$O$5:$O$26,4) -> Balanço de solventes set/2025–ago/2026: 0,75 t de solvente de limpeza + ≈ 0,43 t na fração solvente das tintas = ≈ 1,2 t/ano (24% do limiar). Registo BAL-SOLV-2026 arquivado. | G9: =INDEX(Requisitos_Legais!$R$5:$R$26,4) -> C
A10: =INDEX(Requisitos_Legais!$C$5:$C$26,5) -> Ruído ambiente | B10: =INDEX(Requisitos_Legais!$D$5:$D$26,5) -> Decreto-Lei n.º 9/2007, de 17 de janeiro (Regulamento Geral do Ruído) | C10: =INDEX(Requisitos_Legais!$I$5:$I$26,5) -> Cumprir o critério de exposição máxima e o critério de incomodidade junto dos recetores sensíveis; avaliar após alterações que possam aumentar o ruído. | D10: =INDEX(Requisitos_Legais!$J$5:$J$26,5)&IF(INDEX(Requisitos_Legais!$J$5:$J$26,5)="Sim",""," — "&INDEX(Requisitos_Legais!$K$5:$K$26,5)) -> Sim | E10: =INDEX(Requisitos_Legais!$N$5:$N$26,5) -> Compressores em sala fechada; última avaliação acústica em 2023, antes da substituição dos compressores (fev/2026). | F10: =INDEX(Requisitos_Legais!$O$5:$O$26,5) -> Relatório AC-2026-112 (28/10/2026, laboratório acreditado): critério de incomodidade noturno cumprido nos 3 recetores após barreira acústica e redução de rotação noturna dos compressores (PAM-26-03). | G10: =INDEX(Requisitos_Legais!$R$5:$R$26,5) -> C
A11: =INDEX(Requisitos_Legais!$C$5:$C$26,6) -> Produtos químicos | B11: =INDEX(Requisitos_Legais!$D$5:$D$26,6) -> Regulamento (CE) n.º 1907/2006 (REACH) e Regulamento (CE) n.º 1272/2008 (CLP) | C11: =INDEX(Requisitos_Legais!$I$5:$I$26,6) -> Dispor de fichas de dados de segurança (FDS) atualizadas no ponto de uso, recipientes rotulados, e cumprir as condições de utilização segura e de armazenagem. | D11: =INDEX(Requisitos_Legais!$J$5:$J$26,6)&IF(INDEX(Requisitos_Legais!$J$5:$J$26,6)="Sim",""," — "&INDEX(Requisitos_Legais!$K$5:$K$26,6)) -> Sim | E11: =INDEX(Requisitos_Legais!$N$5:$N$26,6) -> Registo integrado RG-SGA-21 (inventário de 42 produtos, FDS, cenários de exposição, importação, SVHC, risco químico) e procedimento PR-SGA-16; dossier de FDS no armazém e junto às máquinas; armário de inflamáveis. | F11: =INDEX(Requisitos_Legais!$O$5:$O$26,6) -> Avaliação completa de 24/09/2026 (RG-SGA-21): rotulagem CLP 100% conforme (15 recipientes); FDS em vigor 85% conformes (6 a pedir ao fornecedor, 2 de 2021 pedidas em 03/09/2026); 2 cenários de exposição com o prazo de 12 meses do art. 39.º ultrapassado (CE-02, CE-08); 2 fornecedores extra-UE sem representante único (Plasticom = importador sem registo — SUP-004, SUP-005); tinta UV com fotoiniciador Repr. 1B/SVHC; 2 operadores sem formação em diisocianatos (entrada 74). | G11: =INDEX(Requisitos_Legais!$R$5:$R$26,6) -> NC
A12: =INDEX(Requisitos_Legais!$C$5:$C$26,7) -> Gases fluorados | B12: =INDEX(Requisitos_Legais!$D$5:$D$26,7) -> Regulamento (UE) 2024/573 (gases fluorados) e Decreto-Lei n.º 145/2017 | C12: =INDEX(Requisitos_Legais!$I$5:$I$26,7) -> Controlo de fugas periódico conforme a carga em tCO2e, por técnico certificado; registos do equipamento; reparação e reposição documentadas; comunicação anual quando aplicável. | D12: =INDEX(Requisitos_Legais!$J$5:$J$26,7)&IF(INDEX(Requisitos_Legais!$J$5:$J$26,7)="Sim",""," — "&INDEX(Requisitos_Legais!$K$5:$K$26,7)) -> Sim | E12: =INDEX(Requisitos_Legais!$N$5:$N$26,7) -> Contrato de manutenção com empresa certificada; registo do equipamento CH-01. | F12: =INDEX(Requisitos_Legais!$O$5:$O$26,7) -> Relatórios de controlo de fugas de 05/2026 e 18/11/2026 (sem fugas), assinados por técnico certificado. | G12: =INDEX(Requisitos_Legais!$R$5:$R$26,7) -> C
A13: =INDEX(Requisitos_Legais!$C$5:$C$26,8) -> Energia | B13: =INDEX(Requisitos_Legais!$D$5:$D$26,8) -> Decreto-Lei n.º 71/2008, de 15 de abril (SGCIE — consumidores intensivos de energia) | C13: =INDEX(Requisitos_Legais!$I$5:$I$26,8) -> Instalações com consumo ≥ 500 tep/ano: registo, auditoria energética periódica e Plano de Racionalização do Consumo de Energia (PREn) com metas de intensidade energética e relatórios de execução. | D13: =INDEX(Requisitos_Legais!$J$5:$J$26,8)&IF(INDEX(Requisitos_Legais!$J$5:$J$26,8)="Sim",""," — "&INDEX(Requisitos_Legais!$K$5:$K$26,8)) -> Sim | E13: =INDEX(Requisitos_Legais!$N$5:$N$26,8) -> Registo SGCIE; auditoria energética de 2022; ARCE com metas até 2029. | F13: =INDEX(Requisitos_Legais!$O$5:$O$26,8) -> Relatório de execução e progresso do ARCE (2024–2025) submetido na plataforma SGCIE em 28/04/2026; auditoria energética de 2022 válida até 2030. | G13: =INDEX(Requisitos_Legais!$R$5:$R$26,8) -> C
A14: =INDEX(Requisitos_Legais!$C$5:$C$26,9) -> Embalagens (produto) | B14: =INDEX(Requisitos_Legais!$D$5:$D$26,9) -> Regulamento (UE) 2025/40 (PPWR) — aplicável desde 12/08/2026 | C14: =INDEX(Requisitos_Legais!$I$5:$I$26,9) -> Fabricante de embalagens: avaliação da conformidade, documentação técnica e declaração UE de conformidade; limites de chumbo, cádmio, mercúrio e crómio VI; restrições a substâncias preocupantes; preparação para metas de reciclabilidade e conteúdo reciclado. | D14: =INDEX(Requisitos_Legais!$J$5:$J$26,9)&IF(INDEX(Requisitos_Legais!$J$5:$J$26,9)="Sim",""," — "&INDEX(Requisitos_Legais!$K$5:$K$26,9)) -> Sim | E14: =INDEX(Requisitos_Legais!$N$5:$N$26,9) -> Fichas técnicas de produto; declarações de contacto alimentar (linha alimentar); análise de metais pesados por família. | F14: =INDEX(Requisitos_Legais!$O$5:$O$26,9) -> Em 22/12/2026: documentação técnica e declaração UE de conformidade concluídas para 17 de 22 famílias (77%); as 5 restantes (PP-PG e PET-PG farmacêuticas; PETG e PVC em substituição — PAM-26-22) em 2027. | G14: =INDEX(Requisitos_Legais!$R$5:$R$26,9) -> NC
A15: =INDEX(Requisitos_Legais!$C$5:$C$26,10) -> Perdas de granulado | B15: =INDEX(Requisitos_Legais!$D$5:$D$26,10) -> Regulamento (UE) 2025/2365 (prevenção de perdas de granulados de plástico) e REACH anexo XVII, entrada 78 (Reg. (UE) 2023/2055 — relatório anual de microplásticos) | C15: =INDEX(Requisitos_Legais!$I$5:$I$26,10) -> Evitar perdas de granulado com a hierarquia de medidas e notificar cada instalação à autoridade até 17/12/2027; instalações < 1.500 t/ano: declaração de conformidade (certificação por terceiros só ≥ 1.500 t/ano); relatório anual à ECHA das libertações estimadas até 31/05 (entrada 78). | D15: =INDEX(Requisitos_Legais!$J$5:$J$26,10)&IF(INDEX(Requisitos_Legais!$J$5:$J$26,10)="Sim",""," — "&INDEX(Requisitos_Legais!$K$5:$K$26,10)) -> Futuro — A Plasticom manipula ≈ 865 t/ano de granulado (< 1.500 t): notificação e declaração de conformidade até 17/12/2027; o relatório de microplásticos já é exigível (submetido em 28/05/2026). | E15: =INDEX(Requisitos_Legais!$N$5:$N$26,10) -> Varrimento diário; programa OCS em implementação (PAM-26-11). | F15: =INDEX(Requisitos_Legais!$O$5:$O$26,10) -> Autoavaliação Operation Clean Sweep de 15/12/2026: 11 de 14 pontos críticos com contenção (79%); filtros em todas as sarjetas. | G15: =INDEX(Requisitos_Legais!$R$5:$R$26,10) -> Futuro
A16: =INDEX(Requisitos_Legais!$C$5:$C$26,11) -> Emergência / segurança contra incêndio | B16: =INDEX(Requisitos_Legais!$D$5:$D$26,11) -> Decreto-Lei n.º 220/2008, de 12 de novembro (RJ-SCIE) e Portaria n.º 1532/2008 | C16: =INDEX(Requisitos_Legais!$I$5:$I$26,11) -> Implementar medidas de autoproteção, manter meios de 1.ª intervenção, formação e simulacros com a periodicidade da categoria de risco. | D16: =INDEX(Requisitos_Legais!$J$5:$J$26,11)&IF(INDEX(Requisitos_Legais!$J$5:$J$26,11)="Sim",""," — "&INDEX(Requisitos_Legais!$K$5:$K$26,11)) -> Sim | E16: =INDEX(Requisitos_Legais!$N$5:$N$26,11) -> Medidas de autoproteção aprovadas; extintores e RIA com manutenção anual; válvula de corte na rede pluvial. | F16: =INDEX(Requisitos_Legais!$O$5:$O$26,11) -> Simulacros de 26/11/2026 (derrame no armazém de químicos) e 11/12/2026 (incêndio com retenção das águas): evacuação em 5 min; VC-01 fechada em 4 min. | G16: =INDEX(Requisitos_Legais!$R$5:$R$26,11) -> C
