Workbook
Name DataRef: Listas!$A$3
Name lst_AN_Limite: Listas!$I$3:$I$5
Name lst_AN_Matriz: Listas!$H$3:$H$7
Name lst_AN_SimNao: Listas!$J$3:$J$4
Name lst_Cat6M: Listas!$E$3:$E$8
Name lst_DataReferencia: Listas!$A$3:$A$3
Name lst_EstadoHip: Listas!$D$3:$D$6
Name lst_Funcao: Listas!$C$3:$C$24
Name lst_Processo: Listas!$F$3:$F$20
Name lst_Qualidade: Listas!$G$3:$G$5
Name lst_Tipo: Listas!$B$3:$B$4

Sheet 00_LEIA-ME
A1: RG-SGA-13 — Plano de Monitorização e Medição e Avaliação do Desempenho Ambiental
A2: Sistema de Gestão Ambiental NP EN ISO 14001:2026 · Plasticom — Unidade 1 (Marinha Grande, Portugal) · Registo do SGA (fábrica simulada)
A4: CONTROLO DO DOCUMENTO (7.5 — informação documentada)
A5: Código do registo | B5: RG-SGA-13
A6: Título | B6: Plano de Monitorização e Medição e Avaliação do Desempenho Ambiental
A7: Versão / Revisão | B7: 01
A8: Data de emissão | B8: 46387
A9: Elaborado por | B9: Gestor(a) do SGA / EHS
A10: Aprovado por | B10: Diretor Geral
A11: Estado | B11: Em vigor
A12: Retenção | B12: 5 anos após substituição
A13: Localização | B13: Repositório controlado do SGA > Registos_SGA_Plasticom (versão eletrónica é a versão controlada; cópias impressas são não controladas)
A15: FINALIDADE E ÂMBITO
A16: Finalidade | B16: Base de dados ambiental mensal de mar/2025 a dez/2026 (22 meses) em formato longo, derivada da produção real da fábrica simulada e de fatores documentados; plano de monitorização com responsáveis e frequências; controlo de calibração; indicadores mensais calculados; e análise do desvio do solvente com hipóteses verificadas por dados.
A17: Atividades do curso | B17: Atividade 5.1 — Plano de Monitorização e Medição (o quê, como, quando, quem) e equipamentos a calibrar/verificar. Atividade 5.2 Parte 1 — análise do desvio de +15% no solvente de limpeza da serigrafia (18 meses de dados).
A18: Requisitos ISO 14001:2026 | B18: 9.1.1 Monitorização, medição, análise e avaliação (avaliar o desempenho ambiental E a eficácia do SGA — ISO 14001:2026); 9.1.2; 7.1 (equipamentos calibrados/verificados)
A20: ESTRUTURA DO FICHEIRO
A21: Plano_Monitorizacao | B21: Plano de monitorização e medição (o quê, como, quando, quem) — Atividade 5.1.
A22: Equipamentos_Calibracao | B22: Equipamentos de monitorização que exigem calibração/verificação (Atividade 5.1, ponto 3).
A23: Parametros | B23: Fatores usados para derivar os dados ambientais a partir da produção (transparência do modelo; alterar aqui não recalcula a base de dados).
A24: Dim_Mes | B24: Dimensão mês com temperatura, dias úteis e faturas de eletricidade e água (consumo, preço, custo, emissões do âmbito 2).
A25: Producao_Mensal | B25: Produção mensal por processo (denominadores dos indicadores).
A26: Dados_Ambientais | B26: Base de dados ambiental mensal em formato longo (1 linha = mês × processo × variável) — pronta para análise e ML.
A27: Residuos_Mensais | B27: Resíduos mensais por código LER, destino e operador (base do MIRR).
A28: Indicadores_Mensais | B28: Indicadores mensais calculados com SUMIFS sobre as tabelas de dados (KPI-01 a KPI-08, KPI-16).
A29: Analise_Desvio_5_2 | B29: Atividade 5.2 Parte 1: cenário de desvio do solvente (+15% nos últimos 3 meses com produção estável), comparações calculadas, hipóteses e ações.
A30: Hipoteses_Desvio | B30: Hipóteses (causas prováveis) do desvio do solvente e resultado da verificação com dados.
A31: Pesagem_Solvente | B31: Pesagem diária de solvente por máquina e turno (investigação PAM-26-07 desde 08/09/2026 e acompanhamento das ações até 31/12/2026).
A32: Analises_Laboratoriais | B32: Resultados de monitorização por ensaio (efluente, águas pluviais, torre/Legionella, ruído, emissões) comparados com os limites (9.1.1, 9.1.2).
... A34: Dicionario_Dados | B34: Descrição de cada coluna de cada tabela: tipo, origem (entrada/calculado), domínio, obrigatoriedade e chaves.
A36: CONVENÇÕES (prontas para análise de dados e machine learning)
A37: Tabelas | B37: Cada registo é uma Tabela Excel com nome próprio (tbl_*): uma linha = um registo, cabeçalho único, sem células mescladas. Ler com pandas (pd.read_excel(ficheiro, sheet_name=folha, header=<linha do cabeçalho - 1>)) ou Power BI (Obter Dados > Tabela).
A38: Cabeçalho cinzento | B38: Coluna CALCULADA por fórmula — não escrever por cima. As restantes colunas são de entrada.
A39: Validação | B39: Colunas com lista controlada só aceitam valores da folha Listas (evita categorias duplicadas por grafia diferente).
A40: Chaves | B40: IDs estáveis e únicos (PK) e referências a IDs de outros registos (FK) permitem juntar tabelas entre ficheiros — ver SGA-00_Indice_Modelo_Dados.xlsx.
A41: Datas e unidades | B41: Datas em formato data (aaaa-mm-dd); números como números; a unidade está no nome da coluna ou no dicionário. Data de referência do SGA: 2026-12-31 (fecho do ano).
A42: Dados simulados | B42: Fábrica simulada Plasticom. Dados operacionais derivados do dataset do projeto (datasets/silver); dados ambientais e de conformidade são simulação didática — confirmar aplicabilidade legal e números antes de uso real.
A44: LIGAÇÕES A OUTROS REGISTOS
A45: Dataset da fábrica | B45: Produção, rejeições, horas de marcha e mudanças de molde de datasets/silver (jul/2025–dez/2026); mar–jun/2025 reconstruídos (marcados).
A46: RG-SGA-05 Objetivos | B46: Os KPI (KPI-xx) estão definidos no catálogo do RG-SGA-05.
...

Sheet Plano_Monitorizacao
A1: PLANO DE MONITORIZAÇÃO E MEDIÇÃO — PLASTICOM
A2: Monitorizar = verificar o estado · Medir = obter um valor quantitativo com equipamento calibrado/verificado
A4: ID_MED | B4: O_Que_Medir | C4: Unidade | D4: Tipo | E4: Como_Medir | F4: Equipamentos | G4: Quando_Medir | H4: Quem_Mede | I4: ID_KPI | J4: Criterio_Meta | K4: IDs_Aspetos | L4: Estado_Equipamentos
A5: MED-01 | B5: Eletricidade total e por processo | C5: kWh (total e por processo); kWh/1.000 un; tCO2e | D5: Medir | E5: Leitura do contador geral (fatura) + analisadores de energia por quadro (em serviço desde 15/12/2026; até lá rateio por horas de marcha) | F5: EQP-01; EQP-03 | G5: Mensal, no último dia útil (fatura) e diária (analisadores) | H5: Gerente de Manutenção | I5: KPI-01; KPI-08 | J5: Meta OBJ-01: ≤ 101 kWh/1.000 un até 12/2027 | K5: AA-007; AA-010; AA-030 | L5: =IF(F5="—","Não aplicável",IF(SUMPRODUCT(ISNUMBER(SEARCH(tbl_equipamentos[ID_Equipamento],F5))*(tbl_equipamentos[Estado]<>"Válido"))>0,"Equipamento a regularizar","OK")) -> OK
A6: MED-02 | B6: Ar comprimido: caudal e fugas | C6: Nm³/min; % fugas em teste de vazio | D6: Medir | E6: Medidor de caudal na saída dos compressores; teste de vazio ao domingo; detetor ultrassónico | F6: EQP-04; EQP-05 | G6: Mensal (teste de vazio) e trimestral (campanha ultrassom) | H6: Técnico de Manutenção | I6: KPI-01 | J6: Fugas < 10% do caudal | K6: AA-021 | L6: =IF(F6="—","Não aplicável",IF(SUMPRODUCT(ISNUMBER(SEARCH(tbl_equipamentos[ID_Equipamento],F6))*(tbl_equipamentos[Estado]<>"Válido"))>0,"Equipamento a regularizar","OK")) -> OK
A7: MED-03 | B7: Scrap gerado e reintegrado | C7: kg/mês por processo; kg/1.000 un; % reintegração | D7: Medir | E7: Pesagem das caixas de scrap na balança de piso de cada área e dos moinhos | F7: EQP-06 | G7: Diária (registo por turno), consolidação mensal | H7: Gerente de Produção | I7: KPI-03; KPI-04 | J7: Meta OBJ-02: ≤ 0,423 kg/1.000 un até 06/2027 | K7: AA-008; AA-011; AA-020 | L7: =IF(F7="—","Não aplicável",IF(SUMPRODUCT(ISNUMBER(SEARCH(tbl_equipamentos[ID_Equipamento],F7))*(tbl_equipamentos[Estado]<>"Válido"))>0,"Equipamento a regularizar","OK")) -> OK
A8: MED-04 | B8: Resíduos por código LER e destino | C8: kg/mês por LER; % valorização; kg perigosos | D8: Medir | E8: Pesagem na balança de plataforma do parque antes de cada recolha; conferência com e-GAR | F8: EQP-02 | G8: Em cada recolha; consolidação mensal; MIRR anual | H8: Responsável de Armazém e Logística | I8: KPI-05; KPI-07 | J8: Valorização ≥ 80%; 100% e-GAR confirmadas | K8: AA-004; AA-016; AA-029 | L8: =IF(F8="—","Não aplicável",IF(SUMPRODUCT(ISNUMBER(SEARCH(tbl_equipamentos[ID_Equipamento],F8))*(tbl_equipamentos[Estado]<>"Válido"))>0,"Equipamento a regularizar","OK")) -> OK
A9: MED-05 | B9: Polímero consumido e conteúdo reciclado | C9: kg/mês; % PCR | D9: Medir | E9: Inventário de matérias-primas (entradas − stock) e declarações dos fornecedores | F9: EQP-06 | G9: Mensal | H9: Responsável de Compras | I9: — | J9: % PCR a reportar a clientes | K9: AA-001 | L9: =IF(F9="—","Não aplicável",IF(SUMPRODUCT(ISNUMBER(SEARCH(tbl_equipamentos[ID_Equipamento],F9))*(tbl_equipamentos[Estado]<>"Válido"))>0,"Equipamento a regularizar","OK")) -> OK
A10: MED-06 | B10: Solvente de limpeza na serigrafia | C10: kg/mês; kg/1.000 peças serigrafadas | D10: Medir | E10: Balanço de inventário (compras − stock) e, desde 08/09/2026, pesagem diária dos dispensadores por máquina e turno | F10: EQP-07 | G10: Mensal (inventário) e diária (pesagem) | H10: Gestor do SGA / EHS (Responsável Ambiental) | I10: KPI-06 | J10: Meta OBJ-03: ≤ 0,128 kg/1.000 peças até 06/2027 | K10: AA-014; AA-006 | L10: =IF(F10="—","Não aplicável",IF(SUMPRODUCT(ISNUMBER(SEARCH(tbl_equipamentos[ID_Equipamento],F10))*(tbl_equipamentos[Estado]<>"Válido"))>0,"Equipamento a regularizar","OK")) -> OK
A11: MED-07 | B11: Ruído ambiente no recetor sensível | C11: dB(A); critério de incomodidade | D11: Medir | E11: Ensaio acústico por laboratório acreditado (sonómetro classe 1 calibrado) | F11: EXT-01 | G11: Após alterações e trianual | H11: Gestor do SGA / EHS (Responsável Ambiental) | I11: — | J11: Critério de incomodidade noturno ≤ 3 dB(A) | K11: AA-022 | L11: =IF(F11="—","Não aplicável",IF(SUMPRODUCT(ISNUMBER(SEARCH(tbl_equipamentos[ID_Equipamento],F11))*(tbl_equipamentos[Estado]<>"Válido"))>0,"Equipamento a regularizar","OK")) -> OK
A12: MED-08 | B12: Água de rede e água da torre | C12: m³/mês; m³/1.000 un; condutividade da purga | D12: Medir | E12: Contador geral (fatura) + contadores parciais da torre e sanitária (a partir de 12/2026); condutivímetro da purga | F12: EQP-08; EQP-09 | G12: Mensal (fatura); semanal (leitura dos contadores parciais) | H12: Técnico de Utilidades | I12: KPI-02 | J12: Meta OBJ-05: -10% até 12/2027 (normalizado pela temperatura) | K12: AA-023 | L12: =IF(F12="—","Não aplicável",IF(SUMPRODUCT(ISNUMBER(SEARCH(tbl_equipamentos[ID_Equipamento],F12))*(tbl_equipamentos[Estado]<>"Válido"))>0,"Equipamento a regularizar","OK")) -> OK
A13: MED-09 | B13: Perdas de granulado | C13: kg recolhidos/mês; n.º sarjetas com grânulos | D13: Monitorizar | E13: Inspeção visual semanal das sarjetas e pesagem do granulado recolhido | F13: EQP-06 | G13: Semanal | H13: Gestor do SGA / EHS (Responsável Ambiental) | I13: KPI-13 | J13: 0 sarjetas com grânulos | K13: AA-003 | L13: =IF(F13="—","Não aplicável",IF(SUMPRODUCT(ISNUMBER(SEARCH(tbl_equipamentos[ID_Equipamento],F13))*(tbl_equipamentos[Estado]<>"Válido"))>0,"Equipamento a regularizar","OK")) -> OK
A14: MED-10 | B14: Estado dos controlos operacionais | C14: % pontos conformes nas rondas; n.º incidentes | D14: Monitorizar | E14: Ronda ambiental com checklist (RG-SGA-10) | F14: — | G14: Semanal | H14: Gestor do SGA / EHS (Responsável Ambiental) | I14: KPI-10; KPI-11 | J14: ≥ 90% pontos conformes | K14: AA-005; AA-016 | L14: =IF(F14="—","Não aplicável",IF(SUMPRODUCT(ISNUMBER(SEARCH(tbl_equipamentos[ID_Equipamento],F14))*(tbl_equipamentos[Estado]<>"Válido"))>0,"Equipamento a regularizar","OK")) -> Não aplicável
A15: MED-11 | B15: Qualidade do efluente (purga da torre) | C15: pH, CQO, SST (mg/L) | D15: Medir | E15: Colheita e análise por laboratório acreditado | F15: EXT-02 | G15: Semestral | H15: Gerente de Manutenção | I15: — | J15: Abaixo dos VLE do regulamento municipal | K15: AA-024 | L15: =IF(F15="—","Não aplicável",IF(SUMPRODUCT(ISNUMBER(SEARCH(tbl_equipamentos[ID_Equipamento],F15))*(tbl_equipamentos[Estado]<>"Válido"))>0,"Equipamento a regularizar","OK")) -> Equipamento a regularizar
A16: MED-12 | B16: Conformidade PPWR por família | C16: % famílias com declaração UE | D16: Monitorizar | E16: Revisão do dossier técnico de produto | F16: — | G16: Mensal | H16: Responsável de R&D | I16: KPI-12 | J16: 100% até 31/12/2026 | K16: AA-038 | L16: =IF(F16="—","Não aplicável",IF(SUMPRODUCT(ISNUMBER(SEARCH(tbl_equipamentos[ID_Equipamento],F16))*(tbl_equipamentos[Estado]<>"Válido"))>0,"Equipamento a regularizar","OK")) -> Não aplicável

Sheet Equipamentos_Calibracao
A1: ID_Equipamento | B1: Equipamento | C1: IDs_MED | D1: Tipo_Controlo | E1: Ultima_Calibracao | F1: Periodicidade_Meses | G1: Entidade | H1: Evidencia | I1: Proxima_Calibracao | J1: Estado
A2: EQP-01 | B2: Contador geral de eletricidade (operador de rede) | C2: MED-01 | D2: Verificação metrológica pelo operador de rede | E2: 45422 | F2: 60 | G2: Operador de rede | H2: Certificado do operador | I2: =IF(E2="","",EDATE(E2,F2)) -> 47248 | J2: =IF(E2="","Por verificar",IF(I2<DataRef,"Vencido",IF(I2-DataRef<=45,"A vencer","Válido"))) -> Válido
A3: EQP-02 | B3: Balança de plataforma do parque de resíduos (3.000 kg) | C3: MED-04 | D3: Verificação com massas-padrão | E3: 46318 | F3: 12 | G3: Entidade acreditada | H3: Certificado VB-2026-10 (PAM-26-20; NC-SGA-26-07 fechada) | I3: =IF(E3="","",EDATE(E3,F3)) -> 46683 | J3: =IF(E3="","Por verificar",IF(I3<DataRef,"Vencido",IF(I3-DataRef<=45,"A vencer","Válido"))) -> Válido
A4: EQP-03 | B4: Analisadores de energia (6 un.) | C4: MED-01 | D4: Verificação inicial na instalação | E4: 46371 | F4: 24 | G4: Instalador certificado | H4: Relatório de comissionamento RC-2026-12 (PAM-26-02) | I4: =IF(E4="","",EDATE(E4,F4)) -> 47102 | J4: =IF(E4="","Por verificar",IF(I4<DataRef,"Vencido",IF(I4-DataRef<=45,"A vencer","Válido"))) -> Válido
A5: EQP-04 | B5: Medidor de caudal de ar comprimido | C5: MED-02 | D5: Calibração | E5: 45945 | F5: 24 | G5: Laboratório acreditado | H5: Certificado CAL-2025-331 | I5: =IF(E5="","",EDATE(E5,F5)) -> 46675 | J5: =IF(E5="","Por verificar",IF(I5<DataRef,"Vencido",IF(I5-DataRef<=45,"A vencer","Válido"))) -> Válido
A6: EQP-05 | B6: Detetor ultrassónico de fugas | C6: MED-02 | D6: Verificação funcional | E6: 46204 | F6: 12 | G6: Fornecedor | H6: Relatório de verificação | I6: =IF(E6="","",EDATE(E6,F6)) -> 46569 | J6: =IF(E6="","Por verificar",IF(I6<DataRef,"Vencido",IF(I6-DataRef<=45,"A vencer","Válido"))) -> Válido
A7: EQP-06 | B7: Balanças de piso das áreas (5 un.) | C7: MED-03; MED-05; MED-09 | D7: Verificação com massas-padrão | E7: 46344 | F7: 12 | G7: Entidade acreditada | H7: Certificados VB-2026-11 | I7: =IF(E7="","",EDATE(E7,F7)) -> 46709 | J7: =IF(E7="","Por verificar",IF(I7<DataRef,"Vencido",IF(I7-DataRef<=45,"A vencer","Válido"))) -> Válido
A8: EQP-07 | B8: Balança de bancada da serigrafia (30 kg) | C8: MED-06 | D8: Verificação com massas-padrão | E8: 46270 | F8: 12 | G8: Interna (massas-padrão calibradas) | H8: Registo interno VI-2026-09 | I8: =IF(E8="","",EDATE(E8,F8)) -> 46635 | J8: =IF(E8="","Por verificar",IF(I8<DataRef,"Vencido",IF(I8-DataRef<=45,"A vencer","Válido"))) -> Válido
A9: EQP-08 | B9: Contador geral de água (entidade gestora) | C9: MED-08 | D9: Verificação metrológica pela entidade gestora | E9: 44713 | F9: 96 | G9: Entidade gestora | H9: Selo do contador | I9: =IF(E9="","",EDATE(E9,F9)) -> 47635 | J9: =IF(E9="","Por verificar",IF(I9<DataRef,"Vencido",IF(I9-DataRef<=45,"A vencer","Válido"))) -> Válido
A10: EQP-09 | B10: Condutivímetro da purga da torre | C10: MED-08; MED-11 | D10: Calibração com soluções-padrão | E10: 46365 | F10: 6 | G10: Técnico de Utilidades | H10: Registo CAL-TR-2026-12 | I10: =IF(E10="","",EDATE(E10,F10)) -> 46547 | J10: =IF(E10="","Por verificar",IF(I10<DataRef,"Vencido",IF(I10-DataRef<=45,"A vencer","Válido"))) -> Válido
A11: EXT-01 | B11: Sonómetro classe 1 (laboratório externo) | C11: MED-07 | D11: Calibração (responsabilidade do laboratório) | E11: 46071 | F11: 12 | G11: Laboratório acreditado | H11: Certificado anexo ao relatório de ensaio | I11: =IF(E11="","",EDATE(E11,F11)) -> 46436 | J11: =IF(E11="","Por verificar",IF(I11<DataRef,"Vencido",IF(I11-DataRef<=45,"A vencer","Válido"))) -> Válido
A12: EXT-02 | B12: Equipamento analítico do laboratório externo | C12: MED-11 | D12: Acreditação do laboratório | E12: 46032 | F12: 12 | G12: IPAC / laboratório | H12: Anexo técnico de acreditação | I12: =IF(E12="","",EDATE(E12,F12)) -> 46397 | J12: =IF(E12="","Por verificar",IF(I12<DataRef,"Vencido",IF(I12-DataRef<=45,"A vencer","Válido"))) -> A vencer

Sheet Parametros
A1: Codigo | B1: Valor | C1: Unidade | D1: Descricao
A2: KW_INJ | B2: 45 | C2: kW | D2: Potência média absorvida por máquina de injeção em marcha
A3: KW_SOP | B3: 55 | C3: kW | D3: Potência média absorvida por máquina ISBM em marcha
A4: KW_SER | B4: 18 | C4: kW | D4: Potência média por máquina de serigrafia (inclui cura UV/IR)
A5: KW_HFS | B5: 9 | C5: kW | D5: Potência média por máquina de hot foil
A6: AR_FRAC | B6: 0.19 | C6: fração | D6: Energia dos compressores de ar em proporção da energia dos processos
A7: FRIO_FRAC | B7: 0.1 | C7: fração | D7: Energia do chiller/torre em proporção da energia de injeção + sopro, a 15 °C
A8: FRIO_TEMP | B8: 0.05 | C8: 1/°C | D8: Aumento relativo da energia de arrefecimento por °C acima de 15 °C
A9: BASE_KWH | B9: 42000 | C9: kWh/mês | D9: Consumo base (iluminação, escritórios, armazéns, AVAC a 18 °C)
A10: AGUA_TORRE | B10: 1.45 | C10: m³/MWh | D10: Água de reposição da torre por MWh de injeção + sopro, a 15 °C
A11: AGUA_TEMP | B11: 0.045 | C11: 1/°C | D11: Aumento relativo da reposição da torre por °C acima de 15 °C
A12: AGUA_SAN | B12: 150 | C12: m³/mês | D12: Água sanitária e de limpeza (≈ 150 trabalhadores)
A13: G_FRASCO | B13: 22 | C13: g/un | D13: Massa média de um frasco soprado
... A25: GWP_R410A | B25: 2088 | C25: kgCO2e/kg | D25: GWP do R410A (chiller CH-01). CÓPIA do FE-05 do RG-SGA-19 (mestre dos fatores)

Sheet Dim_Mes
A1: Mes | B1: Ano | C1: Mes_Num | D1: Trimestre | E1: Temp_Media_C | F1: Dias_Uteis | G1: Periodo_Dataset | H1: Fatura_Eletricidade | I1: Energia_kWh | J1: Preco_Eletricidade_EUR_kWh | K1: Potencia_Contratada_kW | L1: Custo_Eletricidade_EUR | M1: Fatura_Agua | N1: Agua_m3 | O1: Tarifa_Agua_EUR_m3 | P1: Tarifa_Saneamento_EUR_m3 | Q1: Custo_Agua_EUR | R1: Custo_por_MWh_EUR | S1: Agua_Torre_m3 | T1: Agua_Consumida_m3 | U1: Agua_Descarregada_m3
A2: 45717 | B2: 2025 | C2: 3 | D2: 2025-T1 | E2: 13.2 | F2: 21 | G2: Pré-dataset | H2: FE-202503-8501 | I2: =SUMIFS(tbl_dados_ambientais[Valor],tbl_dados_ambientais[Mes],A2,tbl_dados_ambientais[Variavel],"ENE_TOTAL") -> 568941.28 | J2: 0.1266 | K2: 1350 | L2: =ROUND(I2*J2,0) -> 72028 | M2: FA-202503 | N2: =SUMIFS(tbl_dados_ambientais[Valor],tbl_dados_ambientais[Mes],A2,tbl_dados_ambientais[Variavel],"AGUA_TOTAL") -> 664.72 | O2: 1.62 | P2: 1.05 | Q2: =ROUND(N2*(O2+P2),0) -> 1775 | R2: =IFERROR(ROUND(L2/I2*1000,0),"") -> 127 | S2: =SUMIFS(tbl_dados_ambientais[Valor],tbl_dados_ambientais[Mes],A2,tbl_dados_ambientais[Variavel],"AGUA_USO",tbl_dados_ambientais[Processo],"UTL-FRIO") -> 516.73 | T2: =ROUND(S2*0.8,0) -> 413 | U2: =N2-T2 -> 251.72
A3: 45748 | B3: 2025 | C3: 4 | D3: 2025-T2 | E3: 15.2 | F3: 20 | G3: Pré-dataset | H3: FE-202504-7773 | I3: =SUMIFS(tbl_dados_ambientais[Valor],tbl_dados_ambientais[Mes],A3,tbl_dados_ambientais[Variavel],"ENE_TOTAL") -> 545353.91 | J3: 0.1155 | K3: 1350 | L3: =ROUND(I3*J3,0) -> 62988 | M3: FA-202504 | N3: =SUMIFS(tbl_dados_ambientais[Valor],tbl_dados_ambientais[Mes],A3,tbl_dados_ambientais[Variavel],"AGUA_TOTAL") -> 693.8 | O3: 1.62 | P3: 1.05 | Q3: =ROUND(N3*(O3+P3),0) -> 1852 | R3: =IFERROR(ROUND(L3/I3*1000,0),"") -> 115 | S3: =SUMIFS(tbl_dados_ambientais[Valor],tbl_dados_ambientais[Mes],A3,tbl_dados_ambientais[Variavel],"AGUA_USO",tbl_dados_ambientais[Processo],"UTL-FRIO") -> 544.68 | T3: =ROUND(S3*0.8,0) -> 436 | U3: =N3-T3 -> 257.8
A4: 45778 | B4: 2025 | C4: 5 | D4: 2025-T2 | E4: 16.8 | F4: 21 | G4: Pré-dataset | H4: FE-202505-7293 | I4: =SUMIFS(tbl_dados_ambientais[Valor],tbl_dados_ambientais[Mes],A4,tbl_dados_ambientais[Variavel],"ENE_TOTAL") -> 538026.29 | J4: 0.1094 | K4: 1350 | L4: =ROUND(I4*J4,0) -> 58860 | M4: FA-202505 | N4: =SUMIFS(tbl_dados_ambientais[Valor],tbl_dados_ambientais[Mes],A4,tbl_dados_ambientais[Variavel],"AGUA_TOTAL") -> 704.19 | O4: 1.62 | P4: 1.05 | Q4: =ROUND(N4*(O4+P4),0) -> 1880 | R4: =IFERROR(ROUND(L4/I4*1000,0),"") -> 109 | S4: =SUMIFS(tbl_dados_ambientais[Valor],tbl_dados_ambientais[Mes],A4,tbl_dados_ambientais[Variavel],"AGUA_USO",tbl_dados_ambientais[Processo],"UTL-FRIO") -> 567.25 | T4: =ROUND(S4*0.8,0) -> 454 | U4: =N4-T4 -> 250.19
A5: 45809 | B5: 2025 | C5: 6 | D5: 2025-T2 | E5: 21.2 | F5: 19 | G5: Pré-dataset | H5: FE-202506-8407 | I5: =SUMIFS(tbl_dados_ambientais[Valor],tbl_dados_ambientais[Mes],A5,tbl_dados_ambientais[Variavel],"ENE_TOTAL") -> 515423.14 | J5: 0.107 | K5: 1350 | L5: =ROUND(I5*J5,0) -> 55150 | M5: FA-202506 | N5: =SUMIFS(tbl_dados_ambientais[Valor],tbl_dados_ambientais[Mes],A5,tbl_dados_ambientais[Variavel],"AGUA_TOTAL") -> 724.54 | O5: 1.62 | P5: 1.05 | Q5: =ROUND(N5*(O5+P5),0) -> 1935 | R5: =IFERROR(ROUND(L5/I5*1000,0),"") -> 107 | S5: =SUMIFS(tbl_dados_ambientais[Valor],tbl_dados_ambientais[Mes],A5,tbl_dados_ambientais[Variavel],"AGUA_USO",tbl_dados_ambientais[Processo],"UTL-FRIO") -> 589.02 | T5: =ROUND(S5*0.8,0) -> 471 | U5: =N5-T5 -> 253.54
A6: 45839 | B6: 2025 | C6: 7 | D6: 2025-T3 | E6: 22.2 | F6: 23 | G6: Dataset de produção | H6: FE-202507-4684 | I6: =SUMIFS(tbl_dados_ambientais[Valor],tbl_dados_ambientais[Mes],A6,tbl_dados_ambientais[Variavel],"ENE_TOTAL") -> 620886.12 | J6: 0.1029 | K6: 1350 | L6: =ROUND(I6*J6,0) -> 63889 | M6: FA-202507 | N6: =SUMIFS(tbl_dados_ambientais[Valor],tbl_dados_ambientais[Mes],A6,tbl_dados_ambientais[Variavel],"AGUA_TOTAL") -> 934.86 | O6: 1.62 | P6: 1.05 | Q6: =ROUND(N6*(O6+P6),0) -> 2496 | R6: =IFERROR(ROUND(L6/I6*1000,0),"") -> 103 | S6: =SUMIFS(tbl_dados_ambientais[Valor],tbl_dados_ambientais[Mes],A6,tbl_dados_ambientais[Variavel],"AGUA_USO",tbl_dados_ambientais[Processo],"UTL-FRIO") -> 763.85 | T6: =ROUND(S6*0.8,0) -> 611 | U6: =N6-T6 -> 323.86
A7: 45870 | B7: 2025 | C7: 8 | D7: 2025-T3 | E7: 23.1 | F7: 20 | G7: Dataset de produção | H7: FE-202508-2456 | I7: =SUMIFS(tbl_dados_ambientais[Valor],tbl_dados_ambientais[Mes],A7,tbl_dados_ambientais[Variavel],"ENE_TOTAL") -> 586900.91 | J7: 0.103 | K7: 1350 | L7: =ROUND(I7*J7,0) -> 60451 | M7: FA-202508 | N7: =SUMIFS(tbl_dados_ambientais[Valor],tbl_dados_ambientais[Mes],A7,tbl_dados_ambientais[Variavel],"AGUA_TOTAL") -> 914.2 | O7: 1.62 | P7: 1.05 | Q7: =ROUND(N7*(O7+P7),0) -> 2441 | R7: =IFERROR(ROUND(L7/I7*1000,0),"") -> 103 | S7: =SUMIFS(tbl_dados_ambientais[Valor],tbl_dados_ambientais[Mes],A7,tbl_dados_ambientais[Variavel],"AGUA_USO",tbl_dados_ambientais[Processo],"UTL-FRIO") -> 778.07 | T7: =ROUND(S7*0.8,0) -> 622 | U7: =N7-T7 -> 292.2
A8: 45901 | B8: 2025 | C8: 9 | D8: 2025-T3 | E8: 20.9 | F8: 22 | G8: Dataset de produção | H8: FE-202509-3005 | I8: =SUMIFS(tbl_dados_ambientais[Valor],tbl_dados_ambientais[Mes],A8,tbl_dados_ambientais[Variavel],"ENE_TOTAL") -> 569448.28 | J8: 0.117 | K8: 1350 | L8: =ROUND(I8*J8,0) -> 66625 | M8: FA-202509 | N8: =SUMIFS(tbl_dados_ambientais[Valor],tbl_dados_ambientais[Mes],A8,tbl_dados_ambientais[Variavel],"AGUA_TOTAL") -> 854.7 | O8: 1.62 | P8: 1.05 | Q8: =ROUND(N8*(O8+P8),0) -> 2282 | R8: =IFERROR(ROUND(L8/I8*1000,0),"") -> 117 | S8: =SUMIFS(tbl_dados_ambientais[Valor],tbl_dados_ambientais[Mes],A8,tbl_dados_ambientais[Variavel],"AGUA_USO",tbl_dados_ambientais[Processo],"UTL-FRIO") -> 695.96 | T8: =ROUND(S8*0.8,0) -> 557 | U8: =N8-T8 -> 297.7
A9: 45931 | B9: 2025 | C9: 10 | D9: 2025-T4 | E9: 18.1 | F9: 22 | G9: Dataset de produção | H9: FE-202510-4189 | I9: =SUMIFS(tbl_dados_ambientais[Valor],tbl_dados_ambientais[Mes],A9,tbl_dados_ambientais[Variavel],"ENE_TOTAL") -> 568761.74 | J9: 0.1215 | K9: 1350 | L9: =ROUND(I9*J9,0) -> 69105 | M9: FA-202510 | N9: =SUMIFS(tbl_dados_ambientais[Valor],tbl_dados_ambientais[Mes],A9,tbl_dados_ambientais[Variavel],"AGUA_TOTAL") -> 793.45 | O9: 1.62 | P9: 1.05 | Q9: =ROUND(N9*(O9+P9),0) -> 2119 | R9: =IFERROR(ROUND(L9/I9*1000,0),"") -> 122 | S9: =SUMIFS(tbl_dados_ambientais[Valor],tbl_dados_ambientais[Mes],A9,tbl_dados_ambientais[Variavel],"AGUA_USO",tbl_dados_ambientais[Processo],"UTL-FRIO") -> 637.78 | T9: =ROUND(S9*0.8,0) -> 510 | U9: =N9-T9 -> 283.45
A10: 45962 | B10: 2025 | C10: 11 | D10: 2025-T4 | E10: 13.3 | F10: 19 | G10: Dataset de produção | H10: FE-202511-7676 | I10: =SUMIFS(tbl_dados_ambientais[Valor],tbl_dados_ambientais[Mes],A10,tbl_dados_ambientais[Variavel],"ENE_TOTAL") -> 561642.6 | J10: 0.1253 | K10: 1350 | L10: =ROUND(I10*J10,0) -> 70374 | M10: FA-202511 | N10: =SUMIFS(tbl_dados_ambientais[Valor],tbl_dados_ambientais[Mes],A10,tbl_dados_ambientais[Variavel],"AGUA_TOTAL") -> 629.21 | O10: 1.62 | P10: 1.05 | Q10: =ROUND(N10*(O10+P10),0) -> 1680 | R10: =IFERROR(ROUND(L10/I10*1000,0),"") -> 125 | S10: =SUMIFS(tbl_dados_ambientais[Valor],tbl_dados_ambientais[Mes],A10,tbl_dados_ambientais[Variavel],"AGUA_USO",tbl_dados_ambientais[Processo],"UTL-FRIO") -> 487.84 | T10: =ROUND(S10*0.8,0) -> 390 | U10: =N10-T10 -> 239.21
A11: 45992 | B11: 2025 | C11: 12 | D11: 2025-T4 | E11: 11.4 | F11: 20 | G11: Dataset de produção | H11: FE-202512-6121 | I11: =SUMIFS(tbl_dados_ambientais[Valor],tbl_dados_ambientais[Mes],A11,tbl_dados_ambientais[Variavel],"ENE_TOTAL") -> 582602.49 | J11: 0.1259 | K11: 1350 | L11: =ROUND(I11*J11,0) -> 73350 | M11: FA-202512 | N11: =SUMIFS(tbl_dados_ambientais[Valor],tbl_dados_ambientais[Mes],A11,tbl_dados_ambientais[Variavel],"AGUA_TOTAL") -> 628.99 | O11: 1.62 | P11: 1.05 | Q11: =ROUND(N11*(O11+P11),0) -> 1679 | R11: =IFERROR(ROUND(L11/I11*1000,0),"") -> 126 | S11: =SUMIFS(tbl_dados_ambientais[Valor],tbl_dados_ambientais[Mes],A11,tbl_dados_ambientais[Variavel],"AGUA_USO",tbl_dados_ambientais[Processo],"UTL-FRIO") -> 485.73 | T11: =ROUND(S11*0.8,0) -> 389 | U11: =N11-T11 -> 239.99
A12: 46023 | B12: 2026 | C12: 1 | D12: 2026-T1 | E12: 9.6 | F12: 21 | G12: Dataset de produção | H12: FE-202601-7519 | I12: =SUMIFS(tbl_dados_ambientais[Valor],tbl_dados_ambientais[Mes],A12,tbl_dados_ambientais[Variavel],"ENE_TOTAL") -> 567251.44 | J12: 0.1408 | K12: 1350 | L12: =ROUND(I12*J12,0) -> 79869 | M12: FA-202601 | N12: =SUMIFS(tbl_dados_ambientais[Valor],tbl_dados_ambientais[Mes],A12,tbl_dados_ambientais[Variavel],"AGUA_TOTAL") -> 589.01 | O12: 1.71 | P12: 1.11 | Q12: =ROUND(N12*(O12+P12),0) -> 1661 | R12: =IFERROR(ROUND(L12/I12*1000,0),"") -> 141 | S12: =SUMIFS(tbl_dados_ambientais[Valor],tbl_dados_ambientais[Mes],A12,tbl_dados_ambientais[Variavel],"AGUA_USO",tbl_dados_ambientais[Processo],"UTL-FRIO") -> 432.47 | T12: =ROUND(S12*0.8,0) -> 346 | U12: =N12-T12 -> 243.01
A13: 46054 | B13: 2026 | C13: 2 | D13: 2026-T1 | E13: 11.9 | F13: 20 | G13: Dataset de produção | H13: FE-202602-5999 | I13: =SUMIFS(tbl_dados_ambientais[Valor],tbl_dados_ambientais[Mes],A13,tbl_dados_ambientais[Variavel],"ENE_TOTAL") -> 527748.79 | J13: 0.1396 | K13: 1350 | L13: =ROUND(I13*J13,0) -> 73674 | M13: FA-202602 | N13: =SUMIFS(tbl_dados_ambientais[Valor],tbl_dados_ambientais[Mes],A13,tbl_dados_ambientais[Variavel],"AGUA_TOTAL") -> 565.5 | O13: 1.71 | P13: 1.11 | Q13: =ROUND(N13*(O13+P13),0) -> 1595 | R13: =IFERROR(ROUND(L13/I13*1000,0),"") -> 140 | S13: =SUMIFS(tbl_dados_ambientais[Valor],tbl_dados_ambientais[Mes],A13,tbl_dados_ambientais[Variavel],"AGUA_USO",tbl_dados_ambientais[Processo],"UTL-FRIO") -> 415.36 | T13: =ROUND(S13*0.8,0) -> 332 | U13: =N13-T13 -> 233.5
... A23: 46357 | B23: 2026 | C23: 12 | D23: 2026-T4 | E23: 11.1 | F23: 20 | G23: Dataset de produção | H23: FE-202612-2243 | I23: =SUMIFS(tbl_dados_ambientais[Valor],tbl_dados_ambientais[Mes],A23,tbl_dados_ambientais[Variavel],"ENE_TOTAL") -> 675973.18 | J23: 0.1368 | K23: 1350 | L23: =ROUND(I23*J23,0) -> 92473 | M23: FA-202612 | N23: =SUMIFS(tbl_dados_ambientais[Valor],tbl_dados_ambientais[Mes],A23,tbl_dados_ambientais[Variavel],"AGUA_TOTAL") -> 701.33 | O23: 1.71 | P23: 1.11 | Q23: =ROUND(N23*(O23+P23),0) -> 1978 | R23: =IFERROR(ROUND(L23/I23*1000,0),"") -> 137 | S23: =SUMIFS(tbl_dados_ambientais[Valor],tbl_dados_ambientais[Mes],A23,tbl_dados_ambientais[Variavel],"AGUA_USO",tbl_dados_ambientais[Processo],"UTL-FRIO") -> 554.61 | T23: =ROUND(S23*0.8,0) -> 444 | U23: =N23-T23 -> 257.33

Sheet Producao_Mensal
A1: Mes | B1: Processo | C1: Unid | D1: Rej | E1: Horas | F1: Setups | G1: Taxa_Rejeicao | H1: Fonte
A2: 45717 | B2: HFS | C2: 622911 | D2: 19932 | E2: 1330 | F2: 0 | G2: =IF(C2=0,"",D2/C2) -> 0.031998151 | H2: Reconstruído (pré-dataset, faturas e registos de turno)
A3: 45717 | B3: INJ | C3: 3127150 | D3: 73603 | E3: 3398.2 | F3: 40 | G3: =IF(C3=0,"",D3/C3) -> 0.023536767 | H3: Reconstruído (pré-dataset, faturas e registos de turno)
A4: 45717 | B4: SER | C4: 373701 | D4: 8279 | E4: 745.8 | F4: 0 | G4: =IF(C4=0,"",D4/C4) -> 0.022154075 | H4: Reconstruído (pré-dataset, faturas e registos de turno)
A5: 45717 | B5: SOP | C5: 2074828 | D5: 47637 | E5: 4230.2 | F5: 140 | G5: =IF(C5=0,"",D5/C5) -> 0.022959494 | H5: Reconstruído (pré-dataset, faturas e registos de turno)
A6: 45748 | B6: HFS | C6: 532950 | D6: 17717 | E6: 1137.9 | F6: 0 | G6: =IF(C6=0,"",D6/C6) -> 0.033243269 | H6: Reconstruído (pré-dataset, faturas e registos de turno)
A7: 45748 | B7: INJ | C7: 2949838 | D7: 63947 | E7: 3205.5 | F7: 38 | G7: =IF(C7=0,"",D7/C7) -> 0.02167814 | H7: Reconstruído (pré-dataset, faturas e registos de turno)
A8: 45748 | B8: SER | C8: 352528 | D8: 8115 | E8: 703.6 | F8: 0 | G8: =IF(C8=0,"",D8/C8) -> 0.023019448 | H8: Reconstruído (pré-dataset, faturas e registos de turno)
A9: 45748 | B9: SOP | C9: 1917166 | D9: 43191 | E9: 3908.8 | F9: 129 | G9: =IF(C9=0,"",D9/C9) -> 0.022528566 | H9: Reconstruído (pré-dataset, faturas e registos de turno)
A10: 45778 | B10: HFS | C10: 583006 | D10: 20556 | E10: 1244.8 | F10: 0 | G10: =IF(C10=0,"",D10/C10) -> 0.035258642 | H10: Reconstruído (pré-dataset, faturas e registos de turno)
A11: 45778 | B11: INJ | C11: 3081721 | D11: 70133 | E11: 3348.8 | F11: 39 | G11: =IF(C11=0,"",D11/C11) -> 0.022757738 | H11: Reconstruído (pré-dataset, faturas e registos de turno)
A12: 45778 | B12: SER | C12: 376251 | D12: 8782 | E12: 750.9 | F12: 0 | G12: =IF(C12=0,"",D12/C12) -> 0.023340802 | H12: Reconstruído (pré-dataset, faturas e registos de turno)
A13: 45778 | B13: SOP | C13: 1948876 | D13: 42207 | E13: 3973.4 | F13: 132 | G13: =IF(C13=0,"",D13/C13) -> 0.021657099 | H13: Reconstruído (pré-dataset, faturas e registos de turno)
... A89: 46357 | B89: SOP | C89: 2608256 | D89: 59893 | E89: 5342.6289 | F89: 176 | G89: =IF(C89=0,"",D89/C89) -> 0.022962853 | H89: Dataset de produção (silver)

Sheet Dados_Ambientais
A1: Mes | B1: Processo | C1: Variavel | D1: Descricao | E1: Valor | F1: Unidade | G1: Fonte | H1: Qualidade_Dado
A2: 45717 | B2: GER | C2: ENE_TOTAL | D2: Eletricidade total (fatura) | E2: 568941.28 | F2: kWh | G2: Fatura do comercializador | H2: Medido
A3: 45717 | B3: INJ | C3: ENE_PROC | D3: Eletricidade por processo/uso (rateio por horas de marcha) | E3: 150493.33 | F3: kWh | G3: Rateio por horas de marcha | H3: Estimado
A4: 45717 | B4: SOP | C4: ENE_PROC | D4: Eletricidade por processo/uso (rateio por horas de marcha) | E4: 233780.43 | F4: kWh | G4: Rateio por horas de marcha | H4: Estimado
A5: 45717 | B5: SER | C5: ENE_PROC | D5: Eletricidade por processo/uso (rateio por horas de marcha) | E5: 12915.26 | F5: kWh | G5: Rateio por horas de marcha | H5: Estimado
A6: 45717 | B6: HFS | C6: ENE_PROC | D6: Eletricidade por processo/uso (rateio por horas de marcha) | E6: 12304.15 | F6: kWh | G6: Rateio por horas de marcha | H6: Estimado
A7: 45717 | B7: UTL-AR | C7: ENE_PROC | D7: Eletricidade por processo/uso (rateio por horas de marcha) | E7: 78796.94 | F7: kWh | G7: Rateio por horas de marcha | H7: Estimado
A8: 45717 | B8: UTL-FRIO | C8: ENE_PROC | D8: Eletricidade por processo/uso (rateio por horas de marcha) | E8: 34764.66 | F8: kWh | G8: Rateio por horas de marcha | H8: Estimado
A9: 45717 | B9: GER | C9: ENE_PROC | D9: Eletricidade por processo/uso (rateio por horas de marcha) | E9: 45886.52 | F9: kWh | G9: Rateio por horas de marcha | H9: Estimado
A10: 45717 | B10: GER | C10: AGUA_TOTAL | D10: Água de rede total (fatura) | E10: 664.72 | F10: m³ | G10: Fatura da entidade gestora | H10: Medido
A11: 45717 | B11: UTL-FRIO | C11: AGUA_USO | D11: Água de reposição da torre de arrefecimento (estimativa) | E11: 516.73 | F11: m³ | G11: Balanço (fatura - sanitária) | H11: Estimado
A12: 45717 | B12: GER | C12: AGUA_USO | D12: Água sanitária e limpezas (estimativa) | E12: 147.99 | F12: m³ | G12: Estimativa por n.º de trabalhadores | H12: Estimado
A13: 45717 | B13: SOP | C13: SCRAP_KG | D13: Scrap plástico gerado (rejeitados + purgas de arranque) | E13: 1454.75 | F13: kg | G13: Pesagem na balança da área | H13: Medido
... A486: 45962 | B486: UTL-FRIO | C486: FGAS_KG | D486: Fuga de gás fluorado R410A (reposição após fuga) | E486: 3.2 | F486: kg | G486: Relatório do técnico certificado | H486: Medido

Sheet Residuos_Mensais
A1: Mes | B1: Codigo_LER | C1: Descricao | D1: Perigoso | E1: Quantidade_kg | F1: Operacao_Destino | G1: Operador | H1: Valorizado
A2: 45717 | B2: 07 02 13 | C2: Resíduos de plásticos (scrap não reintegrado) | D2: Não | E2: 1652.1 | F2: R3 | G2: OGR-01 Recicladora de plásticos | H2: =IF(LEFT(F2,1)="R","Sim","Não") -> Sim
A3: 45717 | B3: 15 01 01 | C3: Embalagens de papel e cartão | D3: Não | E3: 3270.2 | F3: R3 | G3: OGR-02 Gestor de papel/cartão | H3: =IF(LEFT(F3,1)="R","Sim","Não") -> Sim
A4: 45717 | B4: 15 01 02 | C4: Embalagens de plástico (filme, big bags, sacos) | D4: Não | E4: 1841.9 | F4: R3 | G4: OGR-01 Recicladora de plásticos | H4: =IF(LEFT(F4,1)="R","Sim","Não") -> Sim
A5: 45717 | B5: 15 01 03 | C5: Embalagens de madeira (paletes) | D5: Não | E5: 1117.9 | F5: R3 | G5: OGR-03 Recuperador de paletes | H5: =IF(LEFT(F5,1)="R","Sim","Não") -> Sim
A6: 45717 | B6: 07 02 13 | C6: Resíduo de foil (filme de suporte) | D6: Não | E6: 445.2 | F6: R13 | G6: OGR-01 Recicladora de plásticos | H6: =IF(LEFT(F6,1)="R","Sim","Não") -> Sim
A7: 45717 | B7: 20 03 01 | C7: Misturas de resíduos urbanos (indiferenciados) | D7: Não | E7: 2246.6 | F7: D1 | G7: OGR-04 Sistema municipal | H7: =IF(LEFT(F7,1)="R","Sim","Não") -> Não
A8: 45717 | B8: 17 04 05 | C8: Ferro e aço (sucata) | D8: Não | E8: 458.8 | F8: R4 | G8: OGR-05 Sucateiro licenciado | H8: =IF(LEFT(F8,1)="R","Sim","Não") -> Sim
A9: 45717 | B9: 08 03 12* | C9: Resíduos de tintas de impressão com substâncias perigosas | D9: Sim | E9: 24.3 | F9: R13 | G9: OGR-06 Operador de resíduos perigosos | H9: =IF(LEFT(F9,1)="R","Sim","Não") -> Sim
A10: 45717 | B10: 15 01 10* | C10: Embalagens contaminadas por substâncias perigosas | D10: Sim | E10: 44.1 | F10: R13 | G10: OGR-06 Operador de resíduos perigosos | H10: =IF(LEFT(F10,1)="R","Sim","Não") -> Sim
A11: 45717 | B11: 15 02 02* | C11: Absorventes e panos contaminados | D11: Sim | E11: 41.2 | F11: D15 | G11: OGR-06 Operador de resíduos perigosos | H11: =IF(LEFT(F11,1)="R","Sim","Não") -> Não
A12: 45717 | B12: 13 02 05* | C12: Óleos minerais de motores e lubrificação usados | D12: Sim | E12: 193.3 | F12: R13 | G12: OGR-07 Regenerador de óleos | H12: =IF(LEFT(F12,1)="R","Sim","Não") -> Sim
A13: 45717 | B13: 20 01 21* | C13: Lâmpadas fluorescentes | D13: Sim | E13: 0 | F13: R13 | G13: OGR-06 Operador de resíduos perigosos | H13: =IF(LEFT(F13,1)="R","Sim","Não") -> Sim
... A265: 46357 | B265: 20 01 21* | C265: Lâmpadas fluorescentes | D265: Sim | E265: 0 | F265: R13 | G265: OGR-06 Operador de resíduos perigosos | H265: =IF(LEFT(F265,1)="R","Sim","Não") -> Sim

Sheet Indicadores_Mensais
A1: INDICADORES AMBIENTAIS MENSAIS — calculados
A3: Mês | B3: Temp. (°C) | C3: Unid. INJ+SOP | D3: kWh total | E3: KPI-01 kWh/1.000 un | F3: m³ água | G3: KPI-02 m³/1.000 un | H3: Scrap (kg) | I3: KPI-03 kg/1.000 un | J3: KPI-04 % reintegração | K3: Resíduos (kg) | L3: KPI-05 % valorização | M3: KPI-07 perigosos (kg) | N3: Peças serigrafadas | O3: Solvente (kg) | P3: KPI-06 kg/1.000 peças | Q3: KPI-08 tCO2e (âmbito 2)
A4: =INDEX(Dim_Mes!$A$2:$A$23,1) -> 45717 | B4: =INDEX(Dim_Mes!$E$2:$E$23,1) -> 13.2 | C4: =SUMIFS(Producao_Mensal!$C$2:$C$89,Producao_Mensal!$A$2:$A$89,$A4,Producao_Mensal!$B$2:$B$89,"INJ")+SUMIFS(Producao_Mensal!$C$2:$C$89,Producao_Mensal!$A$2:$A$89,$A4,Producao_Mensal!$B$2:$B$89,"SOP") -> 5201978 | D4: =SUMIFS(Dados_Ambientais!$E$2:$E$486,Dados_Ambientais!$A$2:$A$486,$A4,Dados_Ambientais!$C$2:$C$486,"ENE_TOTAL") -> 568941.28 | E4: =D4/C4*1000 -> 109.37018 | F4: =SUMIFS(Dados_Ambientais!$E$2:$E$486,Dados_Ambientais!$A$2:$A$486,$A4,Dados_Ambientais!$C$2:$C$486,"AGUA_TOTAL") -> 664.72 | G4: =F4/C4*1000 -> 0.12778216 | H4: =SUMIFS(Dados_Ambientais!$E$2:$E$486,Dados_Ambientais!$A$2:$A$486,$A4,Dados_Ambientais!$C$2:$C$486,"SCRAP_KG") -> 2594.09 | I4: =H4/C4*1000 -> 0.49867377 | J4: =SUMIFS(Dados_Ambientais!$E$2:$E$486,Dados_Ambientais!$A$2:$A$486,$A4,Dados_Ambientais!$C$2:$C$486,"REGRIND_KG")/H4 -> 0.36311385 | K4: =SUMIFS(Residuos_Mensais!$E$2:$E$265,Residuos_Mensais!$A$2:$A$265,$A4) -> 11335.6 | L4: =SUMIFS(Residuos_Mensais!$E$2:$E$265,Residuos_Mensais!$A$2:$A$265,$A4,Residuos_Mensais!$H$2:$H$265,"Sim")/K4 -> 0.79817566 | M4: =SUMIFS(Residuos_Mensais!$E$2:$E$265,Residuos_Mensais!$A$2:$A$265,$A4,Residuos_Mensais!$D$2:$D$265,"Sim") -> 302.9 | N4: =SUMIFS(Producao_Mensal!$C$2:$C$89,Producao_Mensal!$A$2:$A$89,$A4,Producao_Mensal!$B$2:$B$89,"SER") -> 373701 | O4: =SUMIFS(Dados_Ambientais!$E$2:$E$486,Dados_Ambientais!$A$2:$A$486,$A4,Dados_Ambientais!$C$2:$C$486,"SOLVENTE_KG") -> 60.61 | P4: =O4/N4*1000 -> 0.16218849 | Q4: =D4*INDEX(Parametros!$B$2:$B$25,22)/1000 -> 62.583541
A5: =INDEX(Dim_Mes!$A$2:$A$23,2) -> 45748 | B5: =INDEX(Dim_Mes!$E$2:$E$23,2) -> 15.2 | C5: =SUMIFS(Producao_Mensal!$C$2:$C$89,Producao_Mensal!$A$2:$A$89,$A5,Producao_Mensal!$B$2:$B$89,"INJ")+SUMIFS(Producao_Mensal!$C$2:$C$89,Producao_Mensal!$A$2:$A$89,$A5,Producao_Mensal!$B$2:$B$89,"SOP") -> 4867004 | D5: =SUMIFS(Dados_Ambientais!$E$2:$E$486,Dados_Ambientais!$A$2:$A$486,$A5,Dados_Ambientais!$C$2:$C$486,"ENE_TOTAL") -> 545353.91 | E5: =D5/C5*1000 -> 112.05126 | F5: =SUMIFS(Dados_Ambientais!$E$2:$E$486,Dados_Ambientais!$A$2:$A$486,$A5,Dados_Ambientais!$C$2:$C$486,"AGUA_TOTAL") -> 693.8 | G5: =F5/C5*1000 -> 0.14255176 | H5: =SUMIFS(Dados_Ambientais!$E$2:$E$486,Dados_Ambientais!$A$2:$A$486,$A5,Dados_Ambientais!$C$2:$C$486,"SCRAP_KG") -> 2362.67 | I5: =H5/C5*1000 -> 0.48544649 | J5: =SUMIFS(Dados_Ambientais!$E$2:$E$486,Dados_Ambientais!$A$2:$A$486,$A5,Dados_Ambientais!$C$2:$C$486,"REGRIND_KG")/H5 -> 0.37189282 | K5: =SUMIFS(Residuos_Mensais!$E$2:$E$265,Residuos_Mensais!$A$2:$A$265,$A5) -> 10955.4 | L5: =SUMIFS(Residuos_Mensais!$E$2:$E$265,Residuos_Mensais!$A$2:$A$265,$A5,Residuos_Mensais!$H$2:$H$265,"Sim")/K5 -> 0.80010771 | M5: =SUMIFS(Residuos_Mensais!$E$2:$E$265,Residuos_Mensais!$A$2:$A$265,$A5,Residuos_Mensais!$D$2:$D$265,"Sim") -> 128.7 | N5: =SUMIFS(Producao_Mensal!$C$2:$C$89,Producao_Mensal!$A$2:$A$89,$A5,Producao_Mensal!$B$2:$B$89,"SER") -> 352528 | O5: =SUMIFS(Dados_Ambientais!$E$2:$E$486,Dados_Ambientais!$A$2:$A$486,$A5,Dados_Ambientais!$C$2:$C$486,"SOLVENTE_KG") -> 60.01 | P5: =O5/N5*1000 -> 0.17022761 | Q5: =D5*INDEX(Parametros!$B$2:$B$25,22)/1000 -> 59.98893
A6: =INDEX(Dim_Mes!$A$2:$A$23,3) -> 45778 | B6: =INDEX(Dim_Mes!$E$2:$E$23,3) -> 16.8 | C6: =SUMIFS(Producao_Mensal!$C$2:$C$89,Producao_Mensal!$A$2:$A$89,$A6,Producao_Mensal!$B$2:$B$89,"INJ")+SUMIFS(Producao_Mensal!$C$2:$C$89,Producao_Mensal!$A$2:$A$89,$A6,Producao_Mensal!$B$2:$B$89,"SOP") -> 5030597 | D6: =SUMIFS(Dados_Ambientais!$E$2:$E$486,Dados_Ambientais!$A$2:$A$486,$A6,Dados_Ambientais!$C$2:$C$486,"ENE_TOTAL") -> 538026.29 | E6: =D6/C6*1000 -> 106.95078 | F6: =SUMIFS(Dados_Ambientais!$E$2:$E$486,Dados_Ambientais!$A$2:$A$486,$A6,Dados_Ambientais!$C$2:$C$486,"AGUA_TOTAL") -> 704.19 | G6: =F6/C6*1000 -> 0.1399814 | H6: =SUMIFS(Dados_Ambientais!$E$2:$E$486,Dados_Ambientais!$A$2:$A$486,$A6,Dados_Ambientais!$C$2:$C$486,"SCRAP_KG") -> 2471.24 | I6: =H6/C6*1000 -> 0.49124189 | J6: =SUMIFS(Dados_Ambientais!$E$2:$E$486,Dados_Ambientais!$A$2:$A$486,$A6,Dados_Ambientais!$C$2:$C$486,"REGRIND_KG")/H6 -> 0.35957252 | K6: =SUMIFS(Residuos_Mensais!$E$2:$E$265,Residuos_Mensais!$A$2:$A$265,$A6) -> 10841.6 | L6: =SUMIFS(Residuos_Mensais!$E$2:$E$265,Residuos_Mensais!$A$2:$A$265,$A6,Residuos_Mensais!$H$2:$H$265,"Sim")/K6 -> 0.80657836 | M6: =SUMIFS(Residuos_Mensais!$E$2:$E$265,Residuos_Mensais!$A$2:$A$265,$A6,Residuos_Mensais!$D$2:$D$265,"Sim") -> 121.8 | N6: =SUMIFS(Producao_Mensal!$C$2:$C$89,Producao_Mensal!$A$2:$A$89,$A6,Producao_Mensal!$B$2:$B$89,"SER") -> 376251 | O6: =SUMIFS(Dados_Ambientais!$E$2:$E$486,Dados_Ambientais!$A$2:$A$486,$A6,Dados_Ambientais!$C$2:$C$486,"SOLVENTE_KG") -> 59.93 | P6: =O6/N6*1000 -> 0.15928197 | Q6: =D6*INDEX(Parametros!$B$2:$B$25,22)/1000 -> 59.182892
A7: =INDEX(Dim_Mes!$A$2:$A$23,4) -> 45809 | B7: =INDEX(Dim_Mes!$E$2:$E$23,4) -> 21.2 | C7: =SUMIFS(Producao_Mensal!$C$2:$C$89,Producao_Mensal!$A$2:$A$89,$A7,Producao_Mensal!$B$2:$B$89,"INJ")+SUMIFS(Producao_Mensal!$C$2:$C$89,Producao_Mensal!$A$2:$A$89,$A7,Producao_Mensal!$B$2:$B$89,"SOP") -> 4543947 | D7: =SUMIFS(Dados_Ambientais!$E$2:$E$486,Dados_Ambientais!$A$2:$A$486,$A7,Dados_Ambientais!$C$2:$C$486,"ENE_TOTAL") -> 515423.14 | E7: =D7/C7*1000 -> 113.43071 | F7: =SUMIFS(Dados_Ambientais!$E$2:$E$486,Dados_Ambientais!$A$2:$A$486,$A7,Dados_Ambientais!$C$2:$C$486,"AGUA_TOTAL") -> 724.54 | G7: =F7/C7*1000 -> 0.15945168 | H7: =SUMIFS(Dados_Ambientais!$E$2:$E$486,Dados_Ambientais!$A$2:$A$486,$A7,Dados_Ambientais!$C$2:$C$486,"SCRAP_KG") -> 2363.35 | I7: =H7/C7*1000 -> 0.5201095 | J7: =SUMIFS(Dados_Ambientais!$E$2:$E$486,Dados_Ambientais!$A$2:$A$486,$A7,Dados_Ambientais!$C$2:$C$486,"REGRIND_KG")/H7 -> 0.36229082 | K7: =SUMIFS(Residuos_Mensais!$E$2:$E$265,Residuos_Mensais!$A$2:$A$265,$A7) -> 11143.8 | L7: =SUMIFS(Residuos_Mensais!$E$2:$E$265,Residuos_Mensais!$A$2:$A$265,$A7,Residuos_Mensais!$H$2:$H$265,"Sim")/K7 -> 0.79317647 | M7: =SUMIFS(Residuos_Mensais!$E$2:$E$265,Residuos_Mensais!$A$2:$A$265,$A7,Residuos_Mensais!$D$2:$D$265,"Sim") -> 284.6 | N7: =SUMIFS(Producao_Mensal!$C$2:$C$89,Producao_Mensal!$A$2:$A$89,$A7,Producao_Mensal!$B$2:$B$89,"SER") -> 336762 | O7: =SUMIFS(Dados_Ambientais!$E$2:$E$486,Dados_Ambientais!$A$2:$A$486,$A7,Dados_Ambientais!$C$2:$C$486,"SOLVENTE_KG") -> 52.8 | P7: =O7/N7*1000 -> 0.15678729 | Q7: =D7*INDEX(Parametros!$B$2:$B$25,22)/1000 -> 56.696545
A8: =INDEX(Dim_Mes!$A$2:$A$23,5) -> 45839 | B8: =INDEX(Dim_Mes!$E$2:$E$23,5) -> 22.2 | C8: =SUMIFS(Producao_Mensal!$C$2:$C$89,Producao_Mensal!$A$2:$A$89,$A8,Producao_Mensal!$B$2:$B$89,"INJ")+SUMIFS(Producao_Mensal!$C$2:$C$89,Producao_Mensal!$A$2:$A$89,$A8,Producao_Mensal!$B$2:$B$89,"SOP") -> 5273074 | D8: =SUMIFS(Dados_Ambientais!$E$2:$E$486,Dados_Ambientais!$A$2:$A$486,$A8,Dados_Ambientais!$C$2:$C$486,"ENE_TOTAL") -> 620886.12 | E8: =D8/C8*1000 -> 117.74652 | F8: =SUMIFS(Dados_Ambientais!$E$2:$E$486,Dados_Ambientais!$A$2:$A$486,$A8,Dados_Ambientais!$C$2:$C$486,"AGUA_TOTAL") -> 934.86 | G8: =F8/C8*1000 -> 0.17728938 | H8: =SUMIFS(Dados_Ambientais!$E$2:$E$486,Dados_Ambientais!$A$2:$A$486,$A8,Dados_Ambientais!$C$2:$C$486,"SCRAP_KG") -> 2638.73 | I8: =H8/C8*1000 -> 0.50041589 | J8: =SUMIFS(Dados_Ambientais!$E$2:$E$486,Dados_Ambientais!$A$2:$A$486,$A8,Dados_Ambientais!$C$2:$C$486,"REGRIND_KG")/H8 -> 0.38126296 | K8: =SUMIFS(Residuos_Mensais!$E$2:$E$265,Residuos_Mensais!$A$2:$A$265,$A8) -> 11144.1 | L8: =SUMIFS(Residuos_Mensais!$E$2:$E$265,Residuos_Mensais!$A$2:$A$265,$A8,Residuos_Mensais!$H$2:$H$265,"Sim")/K8 -> 0.80305274 | M8: =SUMIFS(Residuos_Mensais!$E$2:$E$265,Residuos_Mensais!$A$2:$A$265,$A8,Residuos_Mensais!$D$2:$D$265,"Sim") -> 124.7 | N8: =SUMIFS(Producao_Mensal!$C$2:$C$89,Producao_Mensal!$A$2:$A$89,$A8,Producao_Mensal!$B$2:$B$89,"SER") -> 443480 | O8: =SUMIFS(Dados_Ambientais!$E$2:$E$486,Dados_Ambientais!$A$2:$A$486,$A8,Dados_Ambientais!$C$2:$C$486,"SOLVENTE_KG") -> 68.44 | P8: =O8/N8*1000 -> 0.15432489 | Q8: =D8*INDEX(Parametros!$B$2:$B$25,22)/1000 -> 68.297473
A9: =INDEX(Dim_Mes!$A$2:$A$23,6) -> 45870 | B9: =INDEX(Dim_Mes!$E$2:$E$23,6) -> 23.1 | C9: =SUMIFS(Producao_Mensal!$C$2:$C$89,Producao_Mensal!$A$2:$A$89,$A9,Producao_Mensal!$B$2:$B$89,"INJ")+SUMIFS(Producao_Mensal!$C$2:$C$89,Producao_Mensal!$A$2:$A$89,$A9,Producao_Mensal!$B$2:$B$89,"SOP") -> 5443656 | D9: =SUMIFS(Dados_Ambientais!$E$2:$E$486,Dados_Ambientais!$A$2:$A$486,$A9,Dados_Ambientais!$C$2:$C$486,"ENE_TOTAL") -> 586900.91 | E9: =D9/C9*1000 -> 107.81374 | F9: =SUMIFS(Dados_Ambientais!$E$2:$E$486,Dados_Ambientais!$A$2:$A$486,$A9,Dados_Ambientais!$C$2:$C$486,"AGUA_TOTAL") -> 914.2 | G9: =F9/C9*1000 -> 0.16793861 | H9: =SUMIFS(Dados_Ambientais!$E$2:$E$486,Dados_Ambientais!$A$2:$A$486,$A9,Dados_Ambientais!$C$2:$C$486,"SCRAP_KG") -> 2732.91 | I9: =H9/C9*1000 -> 0.50203576 | J9: =SUMIFS(Dados_Ambientais!$E$2:$E$486,Dados_Ambientais!$A$2:$A$486,$A9,Dados_Ambientais!$C$2:$C$486,"REGRIND_KG")/H9 -> 0.35900194 | K9: =SUMIFS(Residuos_Mensais!$E$2:$E$265,Residuos_Mensais!$A$2:$A$265,$A9) -> 11135.9 | L9: =SUMIFS(Residuos_Mensais!$E$2:$E$265,Residuos_Mensais!$A$2:$A$265,$A9,Residuos_Mensais!$H$2:$H$265,"Sim")/K9 -> 0.77814995 | M9: =SUMIFS(Residuos_Mensais!$E$2:$E$265,Residuos_Mensais!$A$2:$A$265,$A9,Residuos_Mensais!$D$2:$D$265,"Sim") -> 104.6 | N9: =SUMIFS(Producao_Mensal!$C$2:$C$89,Producao_Mensal!$A$2:$A$89,$A9,Producao_Mensal!$B$2:$B$89,"SER") -> 237760 | O9: =SUMIFS(Dados_Ambientais!$E$2:$E$486,Dados_Ambientais!$A$2:$A$486,$A9,Dados_Ambientais!$C$2:$C$486,"SOLVENTE_KG") -> 37.4 | P9: =O9/N9*1000 -> 0.15730148 | Q9: =D9*INDEX(Parametros!$B$2:$B$25,22)/1000 -> 64.5591
A10: =INDEX(Dim_Mes!$A$2:$A$23,7) -> 45901 | B10: =INDEX(Dim_Mes!$E$2:$E$23,7) -> 20.9 | C10: =SUMIFS(Producao_Mensal!$C$2:$C$89,Producao_Mensal!$A$2:$A$89,$A10,Producao_Mensal!$B$2:$B$89,"INJ")+SUMIFS(Producao_Mensal!$C$2:$C$89,Producao_Mensal!$A$2:$A$89,$A10,Producao_Mensal!$B$2:$B$89,"SOP") -> 5062893 | D10: =SUMIFS(Dados_Ambientais!$E$2:$E$486,Dados_Ambientais!$A$2:$A$486,$A10,Dados_Ambientais!$C$2:$C$486,"ENE_TOTAL") -> 569448.28 | E10: =D10/C10*1000 -> 112.47488 | F10: =SUMIFS(Dados_Ambientais!$E$2:$E$486,Dados_Ambientais!$A$2:$A$486,$A10,Dados_Ambientais!$C$2:$C$486,"AGUA_TOTAL") -> 854.7 | G10: =F10/C10*1000 -> 0.16881652 | H10: =SUMIFS(Dados_Ambientais!$E$2:$E$486,Dados_Ambientais!$A$2:$A$486,$A10,Dados_Ambientais!$C$2:$C$486,"SCRAP_KG") -> 2521.04 | I10: =H10/C10*1000 -> 0.49794455 | J10: =SUMIFS(Dados_Ambientais!$E$2:$E$486,Dados_Ambientais!$A$2:$A$486,$A10,Dados_Ambientais!$C$2:$C$486,"REGRIND_KG")/H10 -> 0.35465126 | K10: =SUMIFS(Residuos_Mensais!$E$2:$E$265,Residuos_Mensais!$A$2:$A$265,$A10) -> 11091.5 | L10: =SUMIFS(Residuos_Mensais!$E$2:$E$265,Residuos_Mensais!$A$2:$A$265,$A10,Residuos_Mensais!$H$2:$H$265,"Sim")/K10 -> 0.80853807 | M10: =SUMIFS(Residuos_Mensais!$E$2:$E$265,Residuos_Mensais!$A$2:$A$265,$A10,Residuos_Mensais!$D$2:$D$265,"Sim") -> 297.7 | N10: =SUMIFS(Producao_Mensal!$C$2:$C$89,Producao_Mensal!$A$2:$A$89,$A10,Producao_Mensal!$B$2:$B$89,"SER") -> 372292 | O10: =SUMIFS(Dados_Ambientais!$E$2:$E$486,Dados_Ambientais!$A$2:$A$486,$A10,Dados_Ambientais!$C$2:$C$486,"SOLVENTE_KG") -> 59.8 | P10: =O10/N10*1000 -> 0.1606266 | Q10: =D10*INDEX(Parametros!$B$2:$B$25,22)/1000 -> 62.639311
A11: =INDEX(Dim_Mes!$A$2:$A$23,8) -> 45931 | B11: =INDEX(Dim_Mes!$E$2:$E$23,8) -> 18.1 | C11: =SUMIFS(Producao_Mensal!$C$2:$C$89,Producao_Mensal!$A$2:$A$89,$A11,Producao_Mensal!$B$2:$B$89,"INJ")+SUMIFS(Producao_Mensal!$C$2:$C$89,Producao_Mensal!$A$2:$A$89,$A11,Producao_Mensal!$B$2:$B$89,"SOP") -> 5158725 | D11: =SUMIFS(Dados_Ambientais!$E$2:$E$486,Dados_Ambientais!$A$2:$A$486,$A11,Dados_Ambientais!$C$2:$C$486,"ENE_TOTAL") -> 568761.74 | E11: =D11/C11*1000 -> 110.25239 | F11: =SUMIFS(Dados_Ambientais!$E$2:$E$486,Dados_Ambientais!$A$2:$A$486,$A11,Dados_Ambientais!$C$2:$C$486,"AGUA_TOTAL") -> 793.45 | G11: =F11/C11*1000 -> 0.15380738 | H11: =SUMIFS(Dados_Ambientais!$E$2:$E$486,Dados_Ambientais!$A$2:$A$486,$A11,Dados_Ambientais!$C$2:$C$486,"SCRAP_KG") -> 2553.13 | I11: =H11/C11*1000 -> 0.49491493 | J11: =SUMIFS(Dados_Ambientais!$E$2:$E$486,Dados_Ambientais!$A$2:$A$486,$A11,Dados_Ambientais!$C$2:$C$486,"REGRIND_KG")/H11 -> 0.35674642 | K11: =SUMIFS(Residuos_Mensais!$E$2:$E$265,Residuos_Mensais!$A$2:$A$265,$A11) -> 11729.1 | L11: =SUMIFS(Residuos_Mensais!$E$2:$E$265,Residuos_Mensais!$A$2:$A$265,$A11,Residuos_Mensais!$H$2:$H$265,"Sim")/K11 -> 0.79946458 | M11: =SUMIFS(Residuos_Mensais!$E$2:$E$265,Residuos_Mensais!$A$2:$A$265,$A11,Residuos_Mensais!$D$2:$D$265,"Sim") -> 131.5 | N11: =SUMIFS(Producao_Mensal!$C$2:$C$89,Producao_Mensal!$A$2:$A$89,$A11,Producao_Mensal!$B$2:$B$89,"SER") -> 431440 | O11: =SUMIFS(Dados_Ambientais!$E$2:$E$486,Dados_Ambientais!$A$2:$A$486,$A11,Dados_Ambientais!$C$2:$C$486,"SOLVENTE_KG") -> 72.62 | P11: =O11/N11*1000 -> 0.16832004 | Q11: =D11*INDEX(Parametros!$B$2:$B$25,22)/1000 -> 62.563791
A12: =INDEX(Dim_Mes!$A$2:$A$23,9) -> 45962 | B12: =INDEX(Dim_Mes!$E$2:$E$23,9) -> 13.3 | C12: =SUMIFS(Producao_Mensal!$C$2:$C$89,Producao_Mensal!$A$2:$A$89,$A12,Producao_Mensal!$B$2:$B$89,"INJ")+SUMIFS(Producao_Mensal!$C$2:$C$89,Producao_Mensal!$A$2:$A$89,$A12,Producao_Mensal!$B$2:$B$89,"SOP") -> 4974090 | D12: =SUMIFS(Dados_Ambientais!$E$2:$E$486,Dados_Ambientais!$A$2:$A$486,$A12,Dados_Ambientais!$C$2:$C$486,"ENE_TOTAL") -> 561642.6 | E12: =D12/C12*1000 -> 112.91364 | F12: =SUMIFS(Dados_Ambientais!$E$2:$E$486,Dados_Ambientais!$A$2:$A$486,$A12,Dados_Ambientais!$C$2:$C$486,"AGUA_TOTAL") -> 629.21 | G12: =F12/C12*1000 -> 0.12649751 | H12: =SUMIFS(Dados_Ambientais!$E$2:$E$486,Dados_Ambientais!$A$2:$A$486,$A12,Dados_Ambientais!$C$2:$C$486,"SCRAP_KG") -> 2691.58 | I12: =H12/C12*1000 -> 0.54112008 | J12: =SUMIFS(Dados_Ambientais!$E$2:$E$486,Dados_Ambientais!$A$2:$A$486,$A12,Dados_Ambientais!$C$2:$C$486,"REGRIND_KG")/H12 -> 0.33164535 | K12: =SUMIFS(Residuos_Mensais!$E$2:$E$265,Residuos_Mensais!$A$2:$A$265,$A12) -> 11222 | L12: =SUMIFS(Residuos_Mensais!$E$2:$E$265,Residuos_Mensais!$A$2:$A$265,$A12,Residuos_Mensais!$H$2:$H$265,"Sim")/K12 -> 0.80852789 | M12: =SUMIFS(Residuos_Mensais!$E$2:$E$265,Residuos_Mensais!$A$2:$A$265,$A12,Residuos_Mensais!$D$2:$D$265,"Sim") -> 129.7 | N12: =SUMIFS(Producao_Mensal!$C$2:$C$89,Producao_Mensal!$A$2:$A$89,$A12,Producao_Mensal!$B$2:$B$89,"SER") -> 448497 | O12: =SUMIFS(Dados_Ambientais!$E$2:$E$486,Dados_Ambientais!$A$2:$A$486,$A12,Dados_Ambientais!$C$2:$C$486,"SOLVENTE_KG") -> 70.53 | P12: =O12/N12*1000 -> 0.15725858 | Q12: =D12*INDEX(Parametros!$B$2:$B$25,22)/1000 -> 61.780686
A13: =INDEX(Dim_Mes!$A$2:$A$23,10) -> 45992 | B13: =INDEX(Dim_Mes!$E$2:$E$23,10) -> 11.4 | C13: =SUMIFS(Producao_Mensal!$C$2:$C$89,Producao_Mensal!$A$2:$A$89,$A13,Producao_Mensal!$B$2:$B$89,"INJ")+SUMIFS(Producao_Mensal!$C$2:$C$89,Producao_Mensal!$A$2:$A$89,$A13,Producao_Mensal!$B$2:$B$89,"SOP") -> 5221940 | D13: =SUMIFS(Dados_Ambientais!$E$2:$E$486,Dados_Ambientais!$A$2:$A$486,$A13,Dados_Ambientais!$C$2:$C$486,"ENE_TOTAL") -> 582602.49 | E13: =D13/C13*1000 -> 111.56821 | F13: =SUMIFS(Dados_Ambientais!$E$2:$E$486,Dados_Ambientais!$A$2:$A$486,$A13,Dados_Ambientais!$C$2:$C$486,"AGUA_TOTAL") -> 628.99 | G13: =F13/C13*1000 -> 0.1204514 | H13: =SUMIFS(Dados_Ambientais!$E$2:$E$486,Dados_Ambientais!$A$2:$A$486,$A13,Dados_Ambientais!$C$2:$C$486,"SCRAP_KG") -> 2561.61 | I13: =H13/C13*1000 -> 0.49054757 | J13: =SUMIFS(Dados_Ambientais!$E$2:$E$486,Dados_Ambientais!$A$2:$A$486,$A13,Dados_Ambientais!$C$2:$C$486,"REGRIND_KG")/H13 -> 0.39097286 | K13: =SUMIFS(Residuos_Mensais!$E$2:$E$265,Residuos_Mensais!$A$2:$A$265,$A13) -> 11187 | L13: =SUMIFS(Residuos_Mensais!$E$2:$E$265,Residuos_Mensais!$A$2:$A$265,$A13,Residuos_Mensais!$H$2:$H$265,"Sim")/K13 -> 0.78297131 | M13: =SUMIFS(Residuos_Mensais!$E$2:$E$265,Residuos_Mensais!$A$2:$A$265,$A13,Residuos_Mensais!$D$2:$D$265,"Sim") -> 279.5 | N13: =SUMIFS(Producao_Mensal!$C$2:$C$89,Producao_Mensal!$A$2:$A$89,$A13,Producao_Mensal!$B$2:$B$89,"SER") -> 338785 | O13: =SUMIFS(Dados_Ambientais!$E$2:$E$486,Dados_Ambientais!$A$2:$A$486,$A13,Dados_Ambientais!$C$2:$C$486,"SOLVENTE_KG") -> 54.57 | P13: =O13/N13*1000 -> 0.16107561 | Q13: =D13*INDEX(Parametros!$B$2:$B$25,22)/1000 -> 64.086274
A14: =INDEX(Dim_Mes!$A$2:$A$23,11) -> 46023 | B14: =INDEX(Dim_Mes!$E$2:$E$23,11) -> 9.6 | C14: =SUMIFS(Producao_Mensal!$C$2:$C$89,Producao_Mensal!$A$2:$A$89,$A14,Producao_Mensal!$B$2:$B$89,"INJ")+SUMIFS(Producao_Mensal!$C$2:$C$89,Producao_Mensal!$A$2:$A$89,$A14,Producao_Mensal!$B$2:$B$89,"SOP") -> 5272284 | D14: =SUMIFS(Dados_Ambientais!$E$2:$E$486,Dados_Ambientais!$A$2:$A$486,$A14,Dados_Ambientais!$C$2:$C$486,"ENE_TOTAL") -> 567251.44 | E14: =D14/C14*1000 -> 107.59121 | F14: =SUMIFS(Dados_Ambientais!$E$2:$E$486,Dados_Ambientais!$A$2:$A$486,$A14,Dados_Ambientais!$C$2:$C$486,"AGUA_TOTAL") -> 589.01 | G14: =F14/C14*1000 -> 0.11171819 | H14: =SUMIFS(Dados_Ambientais!$E$2:$E$486,Dados_Ambientais!$A$2:$A$486,$A14,Dados_Ambientais!$C$2:$C$486,"SCRAP_KG") -> 2387.46 | I14: =H14/C14*1000 -> 0.45283221 | J14: =SUMIFS(Dados_Ambientais!$E$2:$E$486,Dados_Ambientais!$A$2:$A$486,$A14,Dados_Ambientais!$C$2:$C$486,"REGRIND_KG")/H14 -> 0.37455706 | K14: =SUMIFS(Residuos_Mensais!$E$2:$E$265,Residuos_Mensais!$A$2:$A$265,$A14) -> 10388.6 | L14: =SUMIFS(Residuos_Mensais!$E$2:$E$265,Residuos_Mensais!$A$2:$A$265,$A14,Residuos_Mensais!$H$2:$H$265,"Sim")/K14 -> 0.80764492 | M14: =SUMIFS(Residuos_Mensais!$E$2:$E$265,Residuos_Mensais!$A$2:$A$265,$A14,Residuos_Mensais!$D$2:$D$265,"Sim") -> 102.4 | N14: =SUMIFS(Producao_Mensal!$C$2:$C$89,Producao_Mensal!$A$2:$A$89,$A14,Producao_Mensal!$B$2:$B$89,"SER") -> 296927 | O14: =SUMIFS(Dados_Ambientais!$E$2:$E$486,Dados_Ambientais!$A$2:$A$486,$A14,Dados_Ambientais!$C$2:$C$486,"SOLVENTE_KG") -> 47.3 | P14: =O14/N14*1000 -> 0.15929841 | Q14: =D14*INDEX(Parametros!$B$2:$B$25,22)/1000 -> 62.397658
A15: =INDEX(Dim_Mes!$A$2:$A$23,12) -> 46054 | B15: =INDEX(Dim_Mes!$E$2:$E$23,12) -> 11.9 | C15: =SUMIFS(Producao_Mensal!$C$2:$C$89,Producao_Mensal!$A$2:$A$89,$A15,Producao_Mensal!$B$2:$B$89,"INJ")+SUMIFS(Producao_Mensal!$C$2:$C$89,Producao_Mensal!$A$2:$A$89,$A15,Producao_Mensal!$B$2:$B$89,"SOP") -> 4757334 | D15: =SUMIFS(Dados_Ambientais!$E$2:$E$486,Dados_Ambientais!$A$2:$A$486,$A15,Dados_Ambientais!$C$2:$C$486,"ENE_TOTAL") -> 527748.79 | E15: =D15/C15*1000 -> 110.93373 | F15: =SUMIFS(Dados_Ambientais!$E$2:$E$486,Dados_Ambientais!$A$2:$A$486,$A15,Dados_Ambientais!$C$2:$C$486,"AGUA_TOTAL") -> 565.5 | G15: =F15/C15*1000 -> 0.1188691 | H15: =SUMIFS(Dados_Ambientais!$E$2:$E$486,Dados_Ambientais!$A$2:$A$486,$A15,Dados_Ambientais!$C$2:$C$486,"SCRAP_KG") -> 2288.72 | I15: =H15/C15*1000 -> 0.48109298 | J15: =SUMIFS(Dados_Ambientais!$E$2:$E$486,Dados_Ambientais!$A$2:$A$486,$A15,Dados_Ambientais!$C$2:$C$486,"REGRIND_KG")/H15 -> 0.38429777 | K15: =SUMIFS(Residuos_Mensais!$E$2:$E$265,Residuos_Mensais!$A$2:$A$265,$A15) -> 10265.8 | L15: =SUMIFS(Residuos_Mensais!$E$2:$E$265,Residuos_Mensais!$A$2:$A$265,$A15,Residuos_Mensais!$H$2:$H$265,"Sim")/K15 -> 0.79586588 | M15: =SUMIFS(Residuos_Mensais!$E$2:$E$265,Residuos_Mensais!$A$2:$A$265,$A15,Residuos_Mensais!$D$2:$D$265,"Sim") -> 100.3 | N15: =SUMIFS(Producao_Mensal!$C$2:$C$89,Producao_Mensal!$A$2:$A$89,$A15,Producao_Mensal!$B$2:$B$89,"SER") -> 295268 | O15: =SUMIFS(Dados_Ambientais!$E$2:$E$486,Dados_Ambientais!$A$2:$A$486,$A15,Dados_Ambientais!$C$2:$C$486,"SOLVENTE_KG") -> 47.53 | P15: =O15/N15*1000 -> 0.1609724 | Q15: =D15*INDEX(Parametros!$B$2:$B$25,22)/1000 -> 58.052367
A16: =INDEX(Dim_Mes!$A$2:$A$23,13) -> 46082 | B16: =INDEX(Dim_Mes!$E$2:$E$23,13) -> 13.1 | C16: =SUMIFS(Producao_Mensal!$C$2:$C$89,Producao_Mensal!$A$2:$A$89,$A16,Producao_Mensal!$B$2:$B$89,"INJ")+SUMIFS(Producao_Mensal!$C$2:$C$89,Producao_Mensal!$A$2:$A$89,$A16,Producao_Mensal!$B$2:$B$89,"SOP") -> 5427071 | D16: =SUMIFS(Dados_Ambientais!$E$2:$E$486,Dados_Ambientais!$A$2:$A$486,$A16,Dados_Ambientais!$C$2:$C$486,"ENE_TOTAL") -> 590162.4 | E16: =D16/C16*1000 -> 108.74418 | F16: =SUMIFS(Dados_Ambientais!$E$2:$E$486,Dados_Ambientais!$A$2:$A$486,$A16,Dados_Ambientais!$C$2:$C$486,"AGUA_TOTAL") -> 714.87 | G16: =F16/C16*1000 -> 0.13172299 | H16: =SUMIFS(Dados_Ambientais!$E$2:$E$486,Dados_Ambientais!$A$2:$A$486,$A16,Dados_Ambientais!$C$2:$C$486,"SCRAP_KG") -> 2532.15 | I16: =H16/C16*1000 -> 0.46657764 | J16: =SUMIFS(Dados_Ambientais!$E$2:$E$486,Dados_Ambientais!$A$2:$A$486,$A16,Dados_Ambientais!$C$2:$C$486,"REGRIND_KG")/H16 -> 0.37487906 | K16: =SUMIFS(Residuos_Mensais!$E$2:$E$265,Residuos_Mensais!$A$2:$A$265,$A16) -> 10740.8 | L16: =SUMIFS(Residuos_Mensais!$E$2:$E$265,Residuos_Mensais!$A$2:$A$265,$A16,Residuos_Mensais!$H$2:$H$265,"Sim")/K16 -> 0.80002421 | M16: =SUMIFS(Residuos_Mensais!$E$2:$E$265,Residuos_Mensais!$A$2:$A$265,$A16,Residuos_Mensais!$D$2:$D$265,"Sim") -> 270.5 | N16: =SUMIFS(Producao_Mensal!$C$2:$C$89,Producao_Mensal!$A$2:$A$89,$A16,Producao_Mensal!$B$2:$B$89,"SER") -> 380216 | O16: =SUMIFS(Dados_Ambientais!$E$2:$E$486,Dados_Ambientais!$A$2:$A$486,$A16,Dados_Ambientais!$C$2:$C$486,"SOLVENTE_KG") -> 61.77 | P16: =O16/N16*1000 -> 0.16246029 | Q16: =D16*INDEX(Parametros!$B$2:$B$25,22)/1000 -> 64.917864
A17: =INDEX(Dim_Mes!$A$2:$A$23,14) -> 46113 | B17: =INDEX(Dim_Mes!$E$2:$E$23,14) -> 14.9 | C17: =SUMIFS(Producao_Mensal!$C$2:$C$89,Producao_Mensal!$A$2:$A$89,$A17,Producao_Mensal!$B$2:$B$89,"INJ")+SUMIFS(Producao_Mensal!$C$2:$C$89,Producao_Mensal!$A$2:$A$89,$A17,Producao_Mensal!$B$2:$B$89,"SOP") -> 4961953 | D17: =SUMIFS(Dados_Ambientais!$E$2:$E$486,Dados_Ambientais!$A$2:$A$486,$A17,Dados_Ambientais!$C$2:$C$486,"ENE_TOTAL") -> 554352.38 | E17: =D17/C17*1000 -> 111.7206 | F17: =SUMIFS(Dados_Ambientais!$E$2:$E$486,Dados_Ambientais!$A$2:$A$486,$A17,Dados_Ambientais!$C$2:$C$486,"AGUA_TOTAL") -> 673.72 | G17: =F17/C17*1000 -> 0.13577718 | H17: =SUMIFS(Dados_Ambientais!$E$2:$E$486,Dados_Ambientais!$A$2:$A$486,$A17,Dados_Ambientais!$C$2:$C$486,"SCRAP_KG") -> 2606.86 | I17: =H17/C17*1000 -> 0.52536975 | J17: =SUMIFS(Dados_Ambientais!$E$2:$E$486,Dados_Ambientais!$A$2:$A$486,$A17,Dados_Ambientais!$C$2:$C$486,"REGRIND_KG")/H17 -> 0.39404494 | K17: =SUMIFS(Residuos_Mensais!$E$2:$E$265,Residuos_Mensais!$A$2:$A$265,$A17) -> 10411.6 | L17: =SUMIFS(Residuos_Mensais!$E$2:$E$265,Residuos_Mensais!$A$2:$A$265,$A17,Residuos_Mensais!$H$2:$H$265,"Sim")/K17 -> 0.80604326 | M17: =SUMIFS(Residuos_Mensais!$E$2:$E$265,Residuos_Mensais!$A$2:$A$265,$A17,Residuos_Mensais!$D$2:$D$265,"Sim") -> 140.2 | N17: =SUMIFS(Producao_Mensal!$C$2:$C$89,Producao_Mensal!$A$2:$A$89,$A17,Producao_Mensal!$B$2:$B$89,"SER") -> 361694 | O17: =SUMIFS(Dados_Ambientais!$E$2:$E$486,Dados_Ambientais!$A$2:$A$486,$A17,Dados_Ambientais!$C$2:$C$486,"SOLVENTE_KG") -> 56.87 | P17: =O17/N17*1000 -> 0.15723236 | Q17: =D17*INDEX(Parametros!$B$2:$B$25,22)/1000 -> 60.978762
