Workbook
Name DataRef: Listas!$A$3
Name lst_DataReferencia: Listas!$A$3:$A$3
Name lst_Funcao: Listas!$C$3:$C$24
Name lst_Nivel: Listas!$F$3:$F$5
Name lst_Processo: Listas!$B$3:$B$18
Name lst_RACI: Listas!$G$3:$G$8
Name lst_Resultado: Listas!$E$3:$E$5
Name lst_SimNao: Listas!$D$3:$D$4

Sheet 00_LEIA-ME
A1: RG-SGA-08 — Matriz de Competências e Consciencialização Ambiental
A2: Sistema de Gestão Ambiental NP EN ISO 14001:2026 · Plasticom — Unidade 1 (Marinha Grande, Portugal) · Registo do SGA (fábrica simulada)
A4: CONTROLO DO DOCUMENTO (7.5 — informação documentada)
A5: Código do registo | B5: RG-SGA-08
A6: Título | B6: Matriz de Competências e Consciencialização Ambiental
A7: Versão / Revisão | B7: 01
A8: Data de emissão | B8: 46387
A9: Elaborado por | B9: Gestor(a) do SGA / EHS
A10: Aprovado por | B10: Diretor Geral
A11: Estado | B11: Em vigor
A12: Retenção | B12: 5 anos após substituição
A13: Localização | B13: Repositório controlado do SGA > Registos_SGA_Plasticom (versão eletrónica é a versão controlada; cópias impressas são não controladas)
A15: FINALIDADE E ÂMBITO
A16: Finalidade | B16: Definir, para cada função cujo trabalho afeta o desempenho ambiental, a competência necessária (Competência = Educação + Formação + Experiência + Soft skills), o tema crítico de consciencialização e a forma de avaliar a eficácia da formação (reação, aprendizagem, comportamento). Regista a formação individual para medir a cobertura e cruzar com o desempenho (ex.: NC, scrap, solvente por operador).
A17: Atividades do curso | B17: Atividade 4.1 — Definição da Matriz de Competências Ambientais (função selecionada: Operador de Serigrafia, AAS de COV). A frase 'Competência vs Consciencialização' está no documento Word.
A18: Requisitos ISO 14001:2026 | B18: 7.1 Recursos; 7.2 Competência; 7.3 Consciencialização (ISO 14001:2026)
A20: ESTRUTURA DO FICHEIRO
A21: Catalogo_Formacao | B21: Catálogo de ações de formação ambiental.
A22: Matriz_Competencias | B22: Matriz de competências ambientais por função (cruzando função × aspeto significativo).
A23: Registo_Formacao | B23: Registo individual de formação ambiental (1 linha por colaborador × formação).
A24: Resumo_Atividade_4_1 | B24: Ficha da Atividade 4.1 (Operador de Serigrafia), calculada a partir da matriz.
A25: Matriz_RACI | B25: Funções, responsabilidades e autoridades do SGA por processo (5.3), no formato RACI.
A26: Listas | B26: Domínios (listas de valores) usados na validação de dados das tabelas.
A27: Dicionario_Dados | B27: Descrição de cada coluna de cada tabela: tipo, origem (entrada/calculado), domínio, obrigatoriedade e chaves.
A29: CONVENÇÕES (prontas para análise de dados e machine learning)
A30: Tabelas | B30: Cada registo é uma Tabela Excel com nome próprio (tbl_*): uma linha = um registo, cabeçalho único, sem células mescladas. Ler com pandas (pd.read_excel(ficheiro, sheet_name=folha, header=<linha do cabeçalho - 1>)) ou Power BI (Obter Dados > Tabela).
A31: Cabeçalho cinzento | B31: Coluna CALCULADA por fórmula — não escrever por cima. As restantes colunas são de entrada.
A32: Validação | B32: Colunas com lista controlada só aceitam valores da folha Listas (evita categorias duplicadas por grafia diferente).
A33: Chaves | B33: IDs estáveis e únicos (PK) e referências a IDs de outros registos (FK) permitem juntar tabelas entre ficheiros — ver SGA-00_Indice_Modelo_Dados.xlsx.
A34: Datas e unidades | B34: Datas em formato data (aaaa-mm-dd); números como números; a unidade está no nome da coluna ou no dicionário. Data de referência do SGA: 2026-12-31 (fecho do ano).
A35: Dados simulados | B35: Fábrica simulada Plasticom. Dados operacionais derivados do dataset do projeto (datasets/silver); dados ambientais e de conformidade são simulação didática — confirmar aplicabilidade legal e números antes de uso real.
A37: LIGAÇÕES A OUTROS REGISTOS
A38: RG-SGA-03 Aspetos | B38: ID_Aspeto_AAS liga a função ao aspeto significativo que controla.
A39: Dataset da fábrica | B39: Os IDs de colaborador (OP-*, técnicos) são os do dataset (dim_operator), permitindo cruzar formação com defeitos e produtividade.

Sheet Catalogo_Formacao
A1: ID_Formacao | B1: Formacao | C1: Duracao_h | D1: Entidade | E1: Obrigatoria_Legal | F1: Reciclagem_Meses | G1: N_Registos
A2: FOR-01 | B2: Manuseamento seguro de produtos químicos (REACH/CLP, leitura de FDS e rótulos) | C2: 4 | D2: Interna (Gestor SGA) | E2: Não | F2: 24 | G2: =COUNTIF(tbl_registo_formacao[ID_Formacao],A2) -> 16
A3: FOR-02 | B3: Limpeza de ecrãs com solvente: método, dispensador de segurança e controlo de COV | C3: 2 | D3: Interna (chefe de serigrafia) | E3: Não | F3: 12 | G3: =COUNTIF(tbl_registo_formacao[ID_Formacao],A3) -> 6
A4: FOR-03 | B4: Resposta a derrames e uso do kit antipoluição (incl. pós-uso: registar, repor, selar) | C4: 2 | D4: Interna (Gestor SGA) | E4: Não | F4: 12 | G4: =COUNTIF(tbl_registo_formacao[ID_Formacao],A4) -> 17
A5: FOR-04 | B5: Segregação de resíduos e códigos LER; preenchimento de e-GAR | C5: 3 | D5: Interna (Gestor SGA) | E5: Não | F5: 24 | G5: =COUNTIF(tbl_registo_formacao[ID_Formacao],A5) -> 2
A6: FOR-05 | B6: Segregação de scrap por polímero/cor e reintegração (regrind) | C6: 1 | D6: Interna (Eng. de Processo) | E6: Não | F6: 24 | G6: =COUNTIF(tbl_registo_formacao[ID_Formacao],A6) -> 12
A7: FOR-06 | B7: Operation Clean Sweep: prevenção de perdas de granulado | C7: 1 | D7: Interna (Gestor SGA) | E7: Não | F7: 24 | G7: =COUNTIF(tbl_registo_formacao[ID_Formacao],A7) -> 15
A8: FOR-07 | B8: Certificação de técnico de gases fluorados (categoria I) | C8: 35 | D8: Entidade certificadora externa | E8: Sim | F8: 0 | G8: =COUNTIF(tbl_registo_formacao[ID_Formacao],A8) -> 2
A9: FOR-08 | B9: Deteção de fugas de ar comprimido por ultrassom | C9: 4 | D9: Fornecedor do equipamento | E9: Não | F9: 36 | G9: =COUNTIF(tbl_registo_formacao[ID_Formacao],A9) -> 6
A10: FOR-09 | B10: Condução de empilhadores e movimentação de químicos | C10: 16 | D10: Entidade formadora certificada | E10: Sim | F10: 60 | G10: =COUNTIF(tbl_registo_formacao[ID_Formacao],A10) -> 5
A11: FOR-10 | B11: Auditor interno ISO 14001:2026 (inclui ISO 19011) | C11: 21 | D11: Entidade formadora certificada | E11: Não | F11: 36 | G11: =COUNTIF(tbl_registo_formacao[ID_Formacao],A11) -> 3
A12: FOR-11 | B12: Sensibilização ambiental de acolhimento (política, aspetos significativos, emergência) | C12: 1 | D12: Interna (RH + SGA) | E12: Não | F12: 12 | G12: =COUNTIF(tbl_registo_formacao[ID_Formacao],A12) -> 31
A13: FOR-12 | B13: Operação da torre de arrefecimento e tratamento de água (biocidas) | C13: 4 | D13: Fornecedor do tratamento de água | E13: Não | F13: 24 | G13: =COUNTIF(tbl_registo_formacao[ID_Formacao],A13) -> 2
... A16: FOR-15 | B16: ADR 1.3 — preparação de expedições de resíduos perigosos | C16: 8 | D16: Entidade formadora externa | E16: Sim | F16: 60 | G16: =COUNTIF(tbl_registo_formacao[ID_Formacao],A16) -> 2

Sheet Matriz_Competencias
A1: MATRIZ DE COMPETÊNCIAS AMBIENTAIS — PLASTICOM
A2: Competência = Educação + Formação + Experiência + Soft skills · Consciencialização = entender o impacto das próprias ações · Cobertura calculada a partir do registo individual
A4: ID_Competencia | B4: Funcao | C4: Processo | D4: ID_Aspeto_AAS | E4: Aspeto_Significativo | F4: Educacao_Habilitacoes | G4: Formacao_Obrigatoria | H4: Formacao_Descricao | I4: Experiencia | J4: Soft_Skills | K4: Tema_Consciencializacao | L4: Consequencia_Desvio | M4: Avaliacao_Eficacia | N4: N_Colaboradores | O4: Registos_Aprovados | P4: Cobertura | Q4: Estado | R4: Selecionado_Atv_4_1
A5: COMP-01 | B5: Operador de Serigrafia | C5: SER | D5: AA-014 | E5: Emissão de COV na limpeza de ecrãs com solvente (AAS, IRA 40) | F5: 9.º ano de escolaridade | G5: FOR-01; FOR-02; FOR-03; FOR-11; FOR-13; FOR-14 | H5: =IFERROR(INDEX(tbl_formacoes[Formacao],MATCH(LEFT(G5,6),tbl_formacoes[ID_Formacao],0))&IF(LEN(G5)>6," (+ "&(LEN(G5)-LEN(SUBSTITUTE(G5,";","")))&" outras)",""),"") -> Manuseamento seguro de produtos químicos (REACH/CLP, leitura de FDS e rótulos) (+ 5 outras) | I5: 6 meses em decoração industrial com acompanhamento | J5: Rigor na dosagem; comunicação de desvios ao chefe de turno | K5: Deixar latas ou panos de solvente abertos aumenta as emissões de COV (poluição do ar), o consumo de solvente e o risco de incêndio e intoxicação; cada limpeza desnecessária gasta solvente e gera resíduo perigoso. | L5: Mais COV, mais resíduos 15 02 02* e 08 03 12*, desvio do objetivo OBJ-03. | M5: Aprendizagem: teste prático no posto. Comportamento: observação após 3 meses (latas fechadas, dispensador usado). | N5: =COUNTIF(tbl_registo_formacao[ID_Competencia],A5)/MAX(1,LEN(G5)-LEN(SUBSTITUTE(G5,";",""))+1) -> 6 | O5: =COUNTIFS(tbl_registo_formacao[ID_Competencia],A5,tbl_registo_formacao[Resultado],"Aprovado",tbl_registo_formacao[Valida],"Sim") -> 32 | P5: =IFERROR(O5/COUNTIF(tbl_registo_formacao[ID_Competencia],A5),"") -> 0.88888889 | Q5: =IF(P5="","",IF(P5>=1,"✓ OK",IF(P5>=0.8,"Parcial","Pendente"))) -> Parcial | R5: Sim
A6: COMP-02 | B6: Operador de Injeção | C6: INJ | D6: AA-007 | E6: Consumo de energia e geração de scrap na injeção | F6: 12.º ano ou experiência comprovada em moldação | G6: FOR-05; FOR-06; FOR-11 | H6: =IFERROR(INDEX(tbl_formacoes[Formacao],MATCH(LEFT(G6,6),tbl_formacoes[ID_Formacao],0))&IF(LEN(G6)>6," (+ "&(LEN(G6)-LEN(SUBSTITUTE(G6,";","")))&" outras)",""),"") -> Segregação de scrap por polímero/cor e reintegração (regrind) (+ 2 outras) | I6: 1 ano em moldação por injeção | J6: Atenção a alarmes; trabalho em equipa na passagem de turno | K6: Máquinas aquecidas em vazio e scrap misturado desperdiçam energia e polímero; granulado no chão pode chegar à rede pluvial. | L6: Mais kWh/1.000 un e mais scrap (OBJ-01, OBJ-02). | M6: Aprendizagem: questionário. Comportamento: auditoria às caixas de scrap segregado. | N6: =COUNTIF(tbl_registo_formacao[ID_Competencia],A6)/MAX(1,LEN(G6)-LEN(SUBSTITUTE(G6,";",""))+1) -> 6 | O6: =COUNTIFS(tbl_registo_formacao[ID_Competencia],A6,tbl_registo_formacao[Resultado],"Aprovado",tbl_registo_formacao[Valida],"Sim") -> 15 | P6: =IFERROR(O6/COUNTIF(tbl_registo_formacao[ID_Competencia],A6),"") -> 0.83333333 | Q6: =IF(P6="","",IF(P6>=1,"✓ OK",IF(P6>=0.8,"Parcial","Pendente"))) -> Parcial | R6: Não
A7: COMP-03 | B7: Operador de Sopro (ISBM) | C7: SOP | D7: AA-011 | E7: Geração de scrap e purgas de arranque no sopro | F7: 12.º ano ou experiência comprovada em moldação | G7: FOR-05; FOR-06; FOR-11 | H7: =IFERROR(INDEX(tbl_formacoes[Formacao],MATCH(LEFT(G7,6),tbl_formacoes[ID_Formacao],0))&IF(LEN(G7)>6," (+ "&(LEN(G7)-LEN(SUBSTITUTE(G7,";","")))&" outras)",""),"") -> Segregação de scrap por polímero/cor e reintegração (regrind) (+ 2 outras) | I7: 1 ano em sopro/ISBM | J7: Atenção a alarmes; registo rigoroso das purgas | K7: Cada arranque mal parametrizado gera kg de purga; a mistura de cores impede a reintegração. | L7: Mais scrap e polímero virgem (OBJ-02). | M7: Aprendizagem: questionário. Comportamento: registo de purgas por arranque. | N7: =COUNTIF(tbl_registo_formacao[ID_Competencia],A7)/MAX(1,LEN(G7)-LEN(SUBSTITUTE(G7,";",""))+1) -> 6 | O7: =COUNTIFS(tbl_registo_formacao[ID_Competencia],A7,tbl_registo_formacao[Resultado],"Aprovado",tbl_registo_formacao[Valida],"Sim") -> 13 | P7: =IFERROR(O7/COUNTIF(tbl_registo_formacao[ID_Competencia],A7),"") -> 0.72222222 | Q7: =IF(P7="","",IF(P7>=1,"✓ OK",IF(P7>=0.8,"Parcial","Pendente"))) -> Pendente | R7: Não
A8: COMP-04 | B8: Responsável de Armazém e Logística | C8: ARQ | D8: AA-005 | E8: Derrame de químicos no armazém; gestão de resíduos perigosos | F8: 12.º ano de escolaridade | G8: FOR-01; FOR-03; FOR-04; FOR-09; FOR-11; FOR-15 | H8: =IFERROR(INDEX(tbl_formacoes[Formacao],MATCH(LEFT(G8,6),tbl_formacoes[ID_Formacao],0))&IF(LEN(G8)>6," (+ "&(LEN(G8)-LEN(SUBSTITUTE(G8,";","")))&" outras)",""),"") -> Manuseamento seguro de produtos químicos (REACH/CLP, leitura de FDS e rótulos) (+ 5 outras) | I8: 2 anos em logística industrial | J8: Organização; capacidade de decisão em emergência | K8: Bidões fora de bacia, contentores sem identificação LER ou e-GAR incompletas geram contaminação do solo e coimas. | L8: Contaminação do solo e da água; NC legal (RGGR). | M8: Comportamento: resultado das rondas RON-01/02/07/08. | N8: =COUNTIF(tbl_registo_formacao[ID_Competencia],A8)/MAX(1,LEN(G8)-LEN(SUBSTITUTE(G8,";",""))+1) -> 2 | O8: =COUNTIFS(tbl_registo_formacao[ID_Competencia],A8,tbl_registo_formacao[Resultado],"Aprovado",tbl_registo_formacao[Valida],"Sim") -> 10 | P8: =IFERROR(O8/COUNTIF(tbl_registo_formacao[ID_Competencia],A8),"") -> 0.83333333 | Q8: =IF(P8="","",IF(P8>=1,"✓ OK",IF(P8>=0.8,"Parcial","Pendente"))) -> Parcial | R8: Não
A9: COMP-05 | B9: Técnico de Manutenção | C9: MAN | D9: AA-021 | E9: Fugas de ar comprimido, óleos usados e fugas de óleo hidráulico | F9: Curso profissional de eletromecânica (nível 4) | G9: FOR-01; FOR-03; FOR-08; FOR-11 | H9: =IFERROR(INDEX(tbl_formacoes[Formacao],MATCH(LEFT(G9,6),tbl_formacoes[ID_Formacao],0))&IF(LEN(G9)>6," (+ "&(LEN(G9)-LEN(SUBSTITUTE(G9,";","")))&" outras)",""),"") -> Manuseamento seguro de produtos químicos (REACH/CLP, leitura de FDS e rótulos) (+ 3 outras) | I9: 2 anos em manutenção industrial | J9: Diagnóstico; registo das intervenções | K9: Uma fuga de ar de 3 mm a 7 bar consome ≈ 3 kW nos compressores (≈ 3.000 €/ano em laboração contínua); óleo derramado é resíduo perigoso e contamina o solo. | L9: Mais energia (OBJ-01) e derrames. | M9: Comportamento: n.º de fugas etiquetadas e reparadas por campanha. | N9: =COUNTIF(tbl_registo_formacao[ID_Competencia],A9)/MAX(1,LEN(G9)-LEN(SUBSTITUTE(G9,";",""))+1) -> 6 | O9: =COUNTIFS(tbl_registo_formacao[ID_Competencia],A9,tbl_registo_formacao[Resultado],"Aprovado",tbl_registo_formacao[Valida],"Sim") -> 21 | P9: =IFERROR(O9/COUNTIF(tbl_registo_formacao[ID_Competencia],A9),"") -> 0.875 | Q9: =IF(P9="","",IF(P9>=1,"✓ OK",IF(P9>=0.8,"Parcial","Pendente"))) -> Parcial | R9: Não
A10: COMP-06 | B10: Técnico de Utilidades | C10: UTL | D10: AA-023 | E10: Água da torre de arrefecimento, purga com biocida e chiller (gás fluorado) | F10: Curso profissional de eletromecânica ou frio (nível 4) | G10: FOR-01; FOR-07; FOR-12; FOR-11 | H10: =IFERROR(INDEX(tbl_formacoes[Formacao],MATCH(LEFT(G10,6),tbl_formacoes[ID_Formacao],0))&IF(LEN(G10)>6," (+ "&(LEN(G10)-LEN(SUBSTITUTE(G10,";","")))&" outras)",""),"") -> Manuseamento seguro de produtos químicos (REACH/CLP, leitura de FDS e rótulos) (+ 3 outras) | I10: 3 anos em utilidades industriais | J10: Rigor no registo de leituras | K10: Purga mal regulada desperdiça água e descarrega biocida; uma fuga de R410A de 3 kg equivale a ≈ 6 tCO2e. | L10: Consumo de água (OBJ-05); emissões de GEE; NC legal (gases fluorados). | M10: Aprendizagem: certificado FOR-07 válido. Comportamento: registos de leituras e controlo de fugas. | N10: =COUNTIF(tbl_registo_formacao[ID_Competencia],A10)/MAX(1,LEN(G10)-LEN(SUBSTITUTE(G10,";",""))+1) -> 2 | O10: =COUNTIFS(tbl_registo_formacao[ID_Competencia],A10,tbl_registo_formacao[Resultado],"Aprovado",tbl_registo_formacao[Valida],"Sim") -> 5 | P10: =IFERROR(O10/COUNTIF(tbl_registo_formacao[ID_Competencia],A10),"") -> 0.625 | Q10: =IF(P10="","",IF(P10>=1,"✓ OK",IF(P10>=0.8,"Parcial","Pendente"))) -> Pendente | R10: Não
A11: COMP-07 | B11: Operador de Armazém / Empilhador | C11: REC | D11: AA-003 | E11: Perdas de granulado na descarga de big bags | F11: 9.º ano + carta de condução de empilhador | G11: FOR-06; FOR-09; FOR-03; FOR-11 | H11: =IFERROR(INDEX(tbl_formacoes[Formacao],MATCH(LEFT(G11,6),tbl_formacoes[ID_Formacao],0))&IF(LEN(G11)>6," (+ "&(LEN(G11)-LEN(SUBSTITUTE(G11,";","")))&" outras)",""),"") -> Operation Clean Sweep: prevenção de perdas de granulado (+ 3 outras) | I11: 6 meses em armazém | J11: Cuidado na movimentação | K11: Um big bag rasgado pode libertar milhares de grânulos que chegam às sarjetas e ao rio (microplásticos). | L11: Poluição por microplásticos; regulamento de granulados (OBJ-06). | M11: Comportamento: inspeção semanal das sarjetas. | N11: =COUNTIF(tbl_registo_formacao[ID_Competencia],A11)/MAX(1,LEN(G11)-LEN(SUBSTITUTE(G11,";",""))+1) -> 3 | O11: =COUNTIFS(tbl_registo_formacao[ID_Competencia],A11,tbl_registo_formacao[Resultado],"Aprovado",tbl_registo_formacao[Valida],"Sim") -> 10 | P11: =IFERROR(O11/COUNTIF(tbl_registo_formacao[ID_Competencia],A11),"") -> 0.83333333 | Q11: =IF(P11="","",IF(P11>=1,"✓ OK",IF(P11>=0.8,"Parcial","Pendente"))) -> Parcial | R11: Não
A12: COMP-08 | B12: Auditor Interno do SGA | C12: ADM | E12: Transversal (avaliação do SGA) | F12: Licenciatura ou 12.º ano + experiência em sistemas de gestão | G12: FOR-10 | H12: =IFERROR(INDEX(tbl_formacoes[Formacao],MATCH(LEFT(G12,6),tbl_formacoes[ID_Formacao],0))&IF(LEN(G12)>6," (+ "&(LEN(G12)-LEN(SUBSTITUTE(G12,";","")))&" outras)",""),"") -> Auditor interno ISO 14001:2026 (inclui ISO 19011) | I12: Participação em 2 auditorias como observador | J12: Imparcialidade; comunicação; escrita de constatações baseadas em evidência | K12: Uma constatação sem evidência objetiva ou sem requisito não gera melhoria e perde credibilidade. | L12: Auditorias ineficazes (9.2). | M12: Avaliação do auditor após cada auditoria (feedback do auditado). | N12: =COUNTIF(tbl_registo_formacao[ID_Competencia],A12)/MAX(1,LEN(G12)-LEN(SUBSTITUTE(G12,";",""))+1) -> 3 | O12: =COUNTIFS(tbl_registo_formacao[ID_Competencia],A12,tbl_registo_formacao[Resultado],"Aprovado",tbl_registo_formacao[Valida],"Sim") -> 3 | P12: =IFERROR(O12/COUNTIF(tbl_registo_formacao[ID_Competencia],A12),"") -> 1 | Q12: =IF(P12="","",IF(P12>=1,"✓ OK",IF(P12>=0.8,"Parcial","Pendente"))) -> ✓ OK | R12: Não

Sheet Registo_Formacao
A1: ID_Registo | B1: Colaborador | C1: ID_Competencia | D1: ID_Formacao | E1: Data_Realizacao | F1: Duracao_h | G1: Resultado | H1: Nota_Teste | I1: Nivel_Avaliado | J1: Reciclagem_Meses | K1: Validade | L1: Valida
A2: RF-0001 | B2: OP-SK-001 | C2: COMP-01 | D2: FOR-01 | E2: 46245 | F2: 4 | G2: Aprovado | H2: 77 | I2: Aprendizagem | J2: 24 | K2: =IF(OR(E2="",J2=0),"",EDATE(E2,J2)) -> 46976 | L2: =IF(G2<>"Aprovado","Não",IF(K2="","Sim",IF(K2>=DataRef,"Sim","Não"))) -> Sim
A3: RF-0002 | B3: OP-SK-001 | C3: COMP-01 | D3: FOR-02 | E3: 46105 | F3: 2 | G3: Aprovado | H3: 92 | I3: Aprendizagem | J3: 12 | K3: =IF(OR(E3="",J3=0),"",EDATE(E3,J3)) -> 46470 | L3: =IF(G3<>"Aprovado","Não",IF(K3="","Sim",IF(K3>=DataRef,"Sim","Não"))) -> Sim
A4: RF-0003 | B4: OP-SK-001 | C4: COMP-01 | D4: FOR-03 | E4: 46333 | F4: 2 | G4: Aprovado | H4: 95 | I4: Aprendizagem | J4: 12 | K4: =IF(OR(E4="",J4=0),"",EDATE(E4,J4)) -> 46698 | L4: =IF(G4<>"Aprovado","Não",IF(K4="","Sim",IF(K4>=DataRef,"Sim","Não"))) -> Sim
A5: RF-0004 | B5: OP-SK-001 | C5: COMP-01 | D5: FOR-11 | E5: 45998 | F5: 1 | G5: Aprovado | H5: 96 | I5: Comportamento | J5: 12 | K5: =IF(OR(E5="",J5=0),"",EDATE(E5,J5)) -> 46363 | L5: =IF(G5<>"Aprovado","Não",IF(K5="","Sim",IF(K5>=DataRef,"Sim","Não"))) -> Não
A6: RF-0005 | B6: OP-SK-002 | C6: COMP-01 | D6: FOR-01 | E6: 46103 | F6: 4 | G6: Aprovado | H6: 76 | I6: Comportamento | J6: 24 | K6: =IF(OR(E6="",J6=0),"",EDATE(E6,J6)) -> 46834 | L6: =IF(G6<>"Aprovado","Não",IF(K6="","Sim",IF(K6>=DataRef,"Sim","Não"))) -> Sim
A7: RF-0006 | B7: OP-SK-002 | C7: COMP-01 | D7: FOR-02 | E7: 46126 | F7: 2 | G7: Aprovado | H7: 88 | I7: Comportamento | J7: 12 | K7: =IF(OR(E7="",J7=0),"",EDATE(E7,J7)) -> 46491 | L7: =IF(G7<>"Aprovado","Não",IF(K7="","Sim",IF(K7>=DataRef,"Sim","Não"))) -> Sim
A8: RF-0007 | B8: OP-SK-002 | C8: COMP-01 | D8: FOR-03 | E8: 46197 | F8: 2 | G8: Aprovado | H8: 85 | I8: Aprendizagem | J8: 12 | K8: =IF(OR(E8="",J8=0),"",EDATE(E8,J8)) -> 46562 | L8: =IF(G8<>"Aprovado","Não",IF(K8="","Sim",IF(K8>=DataRef,"Sim","Não"))) -> Sim
A9: RF-0008 | B9: OP-SK-002 | C9: COMP-01 | D9: FOR-11 | E9: 46149 | F9: 1 | G9: Aprovado | H9: 86 | I9: Aprendizagem | J9: 12 | K9: =IF(OR(E9="",J9=0),"",EDATE(E9,J9)) -> 46514 | L9: =IF(G9<>"Aprovado","Não",IF(K9="","Sim",IF(K9>=DataRef,"Sim","Não"))) -> Sim
A10: RF-0009 | B10: OP-SK-003 | C10: COMP-01 | D10: FOR-01 | E10: 46000 | F10: 4 | G10: Aprovado | H10: 98 | I10: Comportamento | J10: 24 | K10: =IF(OR(E10="",J10=0),"",EDATE(E10,J10)) -> 46730 | L10: =IF(G10<>"Aprovado","Não",IF(K10="","Sim",IF(K10>=DataRef,"Sim","Não"))) -> Sim
A11: RF-0010 | B11: OP-SK-003 | C11: COMP-01 | D11: FOR-02 | E11: 46235 | F11: 2 | G11: Aprovado | H11: 98 | I11: Comportamento | J11: 12 | K11: =IF(OR(E11="",J11=0),"",EDATE(E11,J11)) -> 46600 | L11: =IF(G11<>"Aprovado","Não",IF(K11="","Sim",IF(K11>=DataRef,"Sim","Não"))) -> Sim
A12: RF-0011 | B12: OP-SK-003 | C12: COMP-01 | D12: FOR-03 | E12: 46314 | F12: 2 | G12: Aprovado | H12: 74 | I12: Aprendizagem | J12: 12 | K12: =IF(OR(E12="",J12=0),"",EDATE(E12,J12)) -> 46679 | L12: =IF(G12<>"Aprovado","Não",IF(K12="","Sim",IF(K12>=DataRef,"Sim","Não"))) -> Sim
A13: RF-0012 | B13: OP-SK-003 | C13: COMP-01 | D13: FOR-11 | E13: 46239 | F13: 1 | G13: Aprovado | H13: 90 | I13: Aprendizagem | J13: 12 | K13: =IF(OR(E13="",J13=0),"",EDATE(E13,J13)) -> 46604 | L13: =IF(G13<>"Aprovado","Não",IF(K13="","Sim",IF(K13>=DataRef,"Sim","Não"))) -> Sim
... A128: RF-0127 | B128: OP-SK-005 | C128: COMP-01 | D128: FOR-14 | E128: 46323 | F128: 2 | G128: Aprovado | H128: 88 | I128: Aprendizagem | J128: 12 | K128: =IF(OR(E128="",J128=0),"",EDATE(E128,J128)) -> 46688 | L128: =IF(G128<>"Aprovado","Não",IF(K128="","Sim",IF(K128>=DataRef,"Sim","Não"))) -> Sim
A129: RF-0128 | B129: OP-SK-T01 | C129: COMP-01 | D129: FOR-13 | F129: 8 | G129: Pendente | J129: 60 | K129: =IF(OR(E129="",J129=0),"",EDATE(E129,J129)) | L129: =IF(G129<>"Aprovado","Não",IF(K129="","Sim",IF(K129>=DataRef,"Sim","Não"))) -> Não
A130: RF-0129 | B130: OP-SK-T01 | C130: COMP-01 | D130: FOR-14 | F130: 2 | G130: Pendente | J130: 12 | K130: =IF(OR(E130="",J130=0),"",EDATE(E130,J130)) | L130: =IF(G130<>"Aprovado","Não",IF(K130="","Sim",IF(K130>=DataRef,"Sim","Não"))) -> Não
A131: RF-0130 | B131: ARM-001 | C131: COMP-04 | D131: FOR-15 | E131: 44691 | F131: 8 | G131: Aprovado | H131: 80 | I131: Aprendizagem | J131: 60 | K131: =IF(OR(E131="",J131=0),"",EDATE(E131,J131)) -> 46517 | L131: =IF(G131<>"Aprovado","Não",IF(K131="","Sim",IF(K131>=DataRef,"Sim","Não"))) -> Sim
A132: RF-0131 | B132: ARM-002 | C132: COMP-04 | D132: FOR-15 | E132: 44691 | F132: 8 | G132: Aprovado | H132: 80 | I132: Aprendizagem | J132: 60 | K132: =IF(OR(E132="",J132=0),"",EDATE(E132,J132)) -> 46517 | L132: =IF(G132<>"Aprovado","Não",IF(K132="","Sim",IF(K132>=DataRef,"Sim","Não"))) -> Sim

Sheet Resumo_Atividade_4_1
A1: ATIVIDADE 4.1 — MATRIZ DE COMPETÊNCIAS AMBIENTAIS (função selecionada)
A3: Função | B3: =INDEX(Matriz_Competencias!$B$5:$B$12,MATCH("COMP-01",Matriz_Competencias!$A$5:$A$12,0)) -> Operador de Serigrafia
A4: Aspeto Significativo | B4: =INDEX(Matriz_Competencias!$E$5:$E$12,MATCH("COMP-01",Matriz_Competencias!$A$5:$A$12,0)) -> Emissão de COV na limpeza de ecrãs com solvente (AAS, IRA 40)
A5: Educação (habilitações) | B5: =INDEX(Matriz_Competencias!$F$5:$F$12,MATCH("COMP-01",Matriz_Competencias!$A$5:$A$12,0)) -> 9.º ano de escolaridade
A6: Formação específica obrigatória (IDs) | B6: =INDEX(Matriz_Competencias!$G$5:$G$12,MATCH("COMP-01",Matriz_Competencias!$A$5:$A$12,0)) -> FOR-01; FOR-02; FOR-03; FOR-11; FOR-13; FOR-14
A7: Experiência | B7: =INDEX(Matriz_Competencias!$I$5:$I$12,MATCH("COMP-01",Matriz_Competencias!$A$5:$A$12,0)) -> 6 meses em decoração industrial com acompanhamento
A8: Soft skills | B8: =INDEX(Matriz_Competencias!$J$5:$J$12,MATCH("COMP-01",Matriz_Competencias!$A$5:$A$12,0)) -> Rigor na dosagem; comunicação de desvios ao chefe de turno
A9: Consciencialização (tema crítico) | B9: =INDEX(Matriz_Competencias!$K$5:$K$12,MATCH("COMP-01",Matriz_Competencias!$A$5:$A$12,0)) -> Deixar latas ou panos de solvente abertos aumenta as emissões de COV (poluição do ar), o consumo de solvente e o risco de incêndio e intoxicação; cada limpeza desnecessária gasta solvente e gera resíduo perigoso.
A10: Consequência de não cumprir | B10: =INDEX(Matriz_Competencias!$L$5:$L$12,MATCH("COMP-01",Matriz_Competencias!$A$5:$A$12,0)) -> Mais COV, mais resíduos 15 02 02* e 08 03 12*, desvio do objetivo OBJ-03.
A11: Avaliação da eficácia da formação | B11: =INDEX(Matriz_Competencias!$M$5:$M$12,MATCH("COMP-01",Matriz_Competencias!$A$5:$A$12,0)) -> Aprendizagem: teste prático no posto. Comportamento: observação após 3 meses (latas fechadas, dispensador usado).
A12: Cobertura atual da formação | B12: =INDEX(Matriz_Competencias!$P$5:$P$12,MATCH("COMP-01",Matriz_Competencias!$A$5:$A$12,0)) -> 0.88888889
A13: Estado | B13: =INDEX(Matriz_Competencias!$Q$5:$Q$12,MATCH("COMP-01",Matriz_Competencias!$A$5:$A$12,0)) -> Parcial
A15: Formações da função
A16: FOR-01 | B16: =INDEX(tbl_formacoes[Formacao],MATCH(A16,tbl_formacoes[ID_Formacao],0))&" — "&INDEX(tbl_formacoes[Duracao_h],MATCH(A16,tbl_formacoes[ID_Formacao],0))&" h" -> Manuseamento seguro de produtos químicos (REACH/CLP, leitura de FDS e rótulos) — 4 h
A17: FOR-02 | B17: =INDEX(tbl_formacoes[Formacao],MATCH(A17,tbl_formacoes[ID_Formacao],0))&" — "&INDEX(tbl_formacoes[Duracao_h],MATCH(A17,tbl_formacoes[ID_Formacao],0))&" h" -> Limpeza de ecrãs com solvente: método, dispensador de segurança e controlo de COV — 2 h
A18: FOR-03 | B18: =INDEX(tbl_formacoes[Formacao],MATCH(A18,tbl_formacoes[ID_Formacao],0))&" — "&INDEX(tbl_formacoes[Duracao_h],MATCH(A18,tbl_formacoes[ID_Formacao],0))&" h" -> Resposta a derrames e uso do kit antipoluição (incl. pós-uso: registar, repor, selar) — 2 h
A19: FOR-11 | B19: =INDEX(tbl_formacoes[Formacao],MATCH(A19,tbl_formacoes[ID_Formacao],0))&" — "&INDEX(tbl_formacoes[Duracao_h],MATCH(A19,tbl_formacoes[ID_Formacao],0))&" h" -> Sensibilização ambiental de acolhimento (política, aspetos significativos, emergência) — 1 h

Sheet Matriz_RACI
A1: FUNÇÕES, RESPONSABILIDADES E AUTORIDADES — MATRIZ RACI (5.3)
A2: R executa · A aprova e presta contas (um por processo) · C consultado · I informado · A gestão de topo mantém a responsabilidade final (5.1)
A4: ID_Processo | B4: Processo_SGA | C4: Clausula | D4: Diretor_Geral | E4: Diretor_Industrial | F4: Gestor_SGA | G4: Gerente_Producao | H4: Gerente_Manutencao | I4: Gerente_Qualidade | J4: Resp_Armazem_Logistica | K4: Resp_Compras | L4: Resp_RD | M4: Resp_RH | N4: Diretor_Financeiro | O4: Chefes_Turno | P4: Operadores | Q4: N_Aprovadores | R4: Controlo_RACI
A5: PS-01 | B5: Contexto e partes interessadas | C5: 4.1; 4.2 | D5: A | E5: C | F5: R | G5: C | H5: C | I5: C | J5: I | K5: C | L5: C | M5: I | N5: C | O5: I | P5: I | Q5: =IF(A5="","",(D5="A")+(D5="R/A")+(E5="A")+(E5="R/A")+(F5="A")+(F5="R/A")+(G5="A")+(G5="R/A")+(H5="A")+(H5="R/A")+(I5="A")+(I5="R/A")+(J5="A")+(J5="R/A")+(K5="A")+(K5="R/A")+(L5="A")+(L5="R/A")+(M5="A")+(M5="R/A")+(N5="A")+(N5="R/A")+(O5="A")+(O5="R/A")+(P5="A")+(P5="R/A")) -> 1 | R5: =IF(A5="","",IF(Q5=1,"OK",IF(Q5=0,"FALTA aprovador","Mais de um A"))) -> OK
A6: PS-02 | B6: Âmbito e política ambiental | C6: 4.3; 5.2 | D6: R/A | E6: C | F6: R | G6: I | H6: I | I6: I | J6: I | K6: I | L6: I | M6: I | N6: I | O6: I | P6: I | Q6: =IF(A6="","",(D6="A")+(D6="R/A")+(E6="A")+(E6="R/A")+(F6="A")+(F6="R/A")+(G6="A")+(G6="R/A")+(H6="A")+(H6="R/A")+(I6="A")+(I6="R/A")+(J6="A")+(J6="R/A")+(K6="A")+(K6="R/A")+(L6="A")+(L6="R/A")+(M6="A")+(M6="R/A")+(N6="A")+(N6="R/A")+(O6="A")+(O6="R/A")+(P6="A")+(P6="R/A")) -> 1 | R6: =IF(A6="","",IF(Q6=1,"OK",IF(Q6=0,"FALTA aprovador","Mais de um A"))) -> OK
A7: PS-03 | B7: Liderança, recursos e revisão pela gestão | C7: 5.1; 7.1; 9.3 | D7: R/A | E7: R | F7: R | G7: C | H7: C | I7: C | J7: I | K7: I | L7: I | M7: C | N7: C | O7: I | P7: — | Q7: =IF(A7="","",(D7="A")+(D7="R/A")+(E7="A")+(E7="R/A")+(F7="A")+(F7="R/A")+(G7="A")+(G7="R/A")+(H7="A")+(H7="R/A")+(I7="A")+(I7="R/A")+(J7="A")+(J7="R/A")+(K7="A")+(K7="R/A")+(L7="A")+(L7="R/A")+(M7="A")+(M7="R/A")+(N7="A")+(N7="R/A")+(O7="A")+(O7="R/A")+(P7="A")+(P7="R/A")) -> 1 | R7: =IF(A7="","",IF(Q7=1,"OK",IF(Q7=0,"FALTA aprovador","Mais de um A"))) -> OK
A8: PS-04 | B8: Aspetos e impactes ambientais | C8: 6.1.2 | D8: I | E8: A | F8: R | G8: C | H8: C | I8: C | J8: C | K8: C | L8: C | M8: — | N8: — | O8: C | P8: I | Q8: =IF(A8="","",(D8="A")+(D8="R/A")+(E8="A")+(E8="R/A")+(F8="A")+(F8="R/A")+(G8="A")+(G8="R/A")+(H8="A")+(H8="R/A")+(I8="A")+(I8="R/A")+(J8="A")+(J8="R/A")+(K8="A")+(K8="R/A")+(L8="A")+(L8="R/A")+(M8="A")+(M8="R/A")+(N8="A")+(N8="R/A")+(O8="A")+(O8="R/A")+(P8="A")+(P8="R/A")) -> 1 | R8: =IF(A8="","",IF(Q8=1,"OK",IF(Q8=0,"FALTA aprovador","Mais de um A"))) -> OK
A9: PS-05 | B9: Obrigações de conformidade e avaliação | C9: 6.1.3; 9.1.2 | D9: I | E9: A | F9: R | G9: C | H9: C | I9: C | J9: C | K9: C | L9: C | M9: C | N9: I | O9: I | P9: — | Q9: =IF(A9="","",(D9="A")+(D9="R/A")+(E9="A")+(E9="R/A")+(F9="A")+(F9="R/A")+(G9="A")+(G9="R/A")+(H9="A")+(H9="R/A")+(I9="A")+(I9="R/A")+(J9="A")+(J9="R/A")+(K9="A")+(K9="R/A")+(L9="A")+(L9="R/A")+(M9="A")+(M9="R/A")+(N9="A")+(N9="R/A")+(O9="A")+(O9="R/A")+(P9="A")+(P9="R/A")) -> 1 | R9: =IF(A9="","",IF(Q9=1,"OK",IF(Q9=0,"FALTA aprovador","Mais de um A"))) -> OK
A10: PS-06 | B10: Riscos e oportunidades e planeamento de ações | C10: 6.1.4; 6.1.5 | D10: A | E10: R | F10: R | G10: C | H10: C | I10: C | J10: C | K10: C | L10: C | M10: C | N10: C | O10: I | P10: — | Q10: =IF(A10="","",(D10="A")+(D10="R/A")+(E10="A")+(E10="R/A")+(F10="A")+(F10="R/A")+(G10="A")+(G10="R/A")+(H10="A")+(H10="R/A")+(I10="A")+(I10="R/A")+(J10="A")+(J10="R/A")+(K10="A")+(K10="R/A")+(L10="A")+(L10="R/A")+(M10="A")+(M10="R/A")+(N10="A")+(N10="R/A")+(O10="A")+(O10="R/A")+(P10="A")+(P10="R/A")) -> 1 | R10: =IF(A10="","",IF(Q10=1,"OK",IF(Q10=0,"FALTA aprovador","Mais de um A"))) -> OK
A11: PS-07 | B11: Objetivos ambientais e programas | C11: 6.2 | D11: A | E11: R | F11: R | G11: R | H11: R | I11: C | J11: C | K11: C | L11: C | M11: I | N11: C | O11: I | P11: I | Q11: =IF(A11="","",(D11="A")+(D11="R/A")+(E11="A")+(E11="R/A")+(F11="A")+(F11="R/A")+(G11="A")+(G11="R/A")+(H11="A")+(H11="R/A")+(I11="A")+(I11="R/A")+(J11="A")+(J11="R/A")+(K11="A")+(K11="R/A")+(L11="A")+(L11="R/A")+(M11="A")+(M11="R/A")+(N11="A")+(N11="R/A")+(O11="A")+(O11="R/A")+(P11="A")+(P11="R/A")) -> 1 | R11: =IF(A11="","",IF(Q11=1,"OK",IF(Q11=0,"FALTA aprovador","Mais de um A"))) -> OK
A12: PS-08 | B12: Planeamento de alterações | C12: 6.3 | D12: A | E12: R | F12: C | G12: C | H12: R | I12: C | J12: I | K12: C | L12: R | M12: C | N12: C | O12: I | P12: I | Q12: =IF(A12="","",(D12="A")+(D12="R/A")+(E12="A")+(E12="R/A")+(F12="A")+(F12="R/A")+(G12="A")+(G12="R/A")+(H12="A")+(H12="R/A")+(I12="A")+(I12="R/A")+(J12="A")+(J12="R/A")+(K12="A")+(K12="R/A")+(L12="A")+(L12="R/A")+(M12="A")+(M12="R/A")+(N12="A")+(N12="R/A")+(O12="A")+(O12="R/A")+(P12="A")+(P12="R/A")) -> 1 | R12: =IF(A12="","",IF(Q12=1,"OK",IF(Q12=0,"FALTA aprovador","Mais de um A"))) -> OK
A13: PS-09 | B13: Competência e consciencialização | C13: 7.2; 7.3 | D13: I | E13: A | F13: C | G13: C | H13: C | I13: C | J13: C | K13: C | L13: C | M13: R | N13: — | O13: R | P13: I | Q13: =IF(A13="","",(D13="A")+(D13="R/A")+(E13="A")+(E13="R/A")+(F13="A")+(F13="R/A")+(G13="A")+(G13="R/A")+(H13="A")+(H13="R/A")+(I13="A")+(I13="R/A")+(J13="A")+(J13="R/A")+(K13="A")+(K13="R/A")+(L13="A")+(L13="R/A")+(M13="A")+(M13="R/A")+(N13="A")+(N13="R/A")+(O13="A")+(O13="R/A")+(P13="A")+(P13="R/A")) -> 1 | R13: =IF(A13="","",IF(Q13=1,"OK",IF(Q13=0,"FALTA aprovador","Mais de um A"))) -> OK
A14: PS-10 | B14: Comunicação interna e externa | C14: 7.4 | D14: A | E14: C | F14: R | G14: C | H14: C | I14: C | J14: C | K14: C | L14: C | M14: C | N14: I | O14: R | P14: I | Q14: =IF(A14="","",(D14="A")+(D14="R/A")+(E14="A")+(E14="R/A")+(F14="A")+(F14="R/A")+(G14="A")+(G14="R/A")+(H14="A")+(H14="R/A")+(I14="A")+(I14="R/A")+(J14="A")+(J14="R/A")+(K14="A")+(K14="R/A")+(L14="A")+(L14="R/A")+(M14="A")+(M14="R/A")+(N14="A")+(N14="R/A")+(O14="A")+(O14="R/A")+(P14="A")+(P14="R/A")) -> 1 | R14: =IF(A14="","",IF(Q14=1,"OK",IF(Q14=0,"FALTA aprovador","Mais de um A"))) -> OK
A15: PS-11 | B15: Informação documentada | C15: 7.5 | D15: I | E15: A | F15: R | G15: C | H15: C | I15: C | J15: C | K15: C | L15: C | M15: C | N15: — | O15: I | P15: I | Q15: =IF(A15="","",(D15="A")+(D15="R/A")+(E15="A")+(E15="R/A")+(F15="A")+(F15="R/A")+(G15="A")+(G15="R/A")+(H15="A")+(H15="R/A")+(I15="A")+(I15="R/A")+(J15="A")+(J15="R/A")+(K15="A")+(K15="R/A")+(L15="A")+(L15="R/A")+(M15="A")+(M15="R/A")+(N15="A")+(N15="R/A")+(O15="A")+(O15="R/A")+(P15="A")+(P15="R/A")) -> 1 | R15: =IF(A15="","",IF(Q15=1,"OK",IF(Q15=0,"FALTA aprovador","Mais de um A"))) -> OK
A16: PS-12 | B16: Controlo operacional da produção (injeção, sopro, decoração) | C16: 8.1 | D16: I | E16: A | F16: C | G16: R | H16: C | I16: C | J16: — | K16: — | L16: C | M16: — | N16: — | O16: R | P16: R | Q16: =IF(A16="","",(D16="A")+(D16="R/A")+(E16="A")+(E16="R/A")+(F16="A")+(F16="R/A")+(G16="A")+(G16="R/A")+(H16="A")+(H16="R/A")+(I16="A")+(I16="R/A")+(J16="A")+(J16="R/A")+(K16="A")+(K16="R/A")+(L16="A")+(L16="R/A")+(M16="A")+(M16="R/A")+(N16="A")+(N16="R/A")+(O16="A")+(O16="R/A")+(P16="A")+(P16="R/A")) -> 1 | R16: =IF(A16="","",IF(Q16=1,"OK",IF(Q16=0,"FALTA aprovador","Mais de um A"))) -> OK
... A31: PS-27 | B31: Alegações ambientais de produto | C31: 7.4 | D31: A | E31: C | F31: R | G31: — | H31: — | I31: C | J31: — | K31: — | L31: R | M31: — | N31: C | O31: — | P31: — | Q31: =IF(A31="","",(D31="A")+(D31="R/A")+(E31="A")+(E31="R/A")+(F31="A")+(F31="R/A")+(G31="A")+(G31="R/A")+(H31="A")+(H31="R/A")+(I31="A")+(I31="R/A")+(J31="A")+(J31="R/A")+(K31="A")+(K31="R/A")+(L31="A")+(L31="R/A")+(M31="A")+(M31="R/A")+(N31="A")+(N31="R/A")+(O31="A")+(O31="R/A")+(P31="A")+(P31="R/A")) -> 1 | R31: =IF(A31="","",IF(Q31=1,"OK",IF(Q31=0,"FALTA aprovador","Mais de um A"))) -> OK
Q32: =IF(A32="","",(D32="A")+(D32="R/A")+(E32="A")+(E32="R/A")+(F32="A")+(F32="R/A")+(G32="A")+(G32="R/A")+(H32="A")+(H32="R/A")+(I32="A")+(I32="R/A")+(J32="A")+(J32="R/A")+(K32="A")+(K32="R/A")+(L32="A")+(L32="R/A")+(M32="A")+(M32="R/A")+(N32="A")+(N32="R/A")+(O32="A")+(O32="R/A")+(P32="A")+(P32="R/A")) | R32: =IF(A32="","",IF(Q32=1,"OK",IF(Q32=0,"FALTA aprovador","Mais de um A")))
Q33: =IF(A33="","",(D33="A")+(D33="R/A")+(E33="A")+(E33="R/A")+(F33="A")+(F33="R/A")+(G33="A")+(G33="R/A")+(H33="A")+(H33="R/A")+(I33="A")+(I33="R/A")+(J33="A")+(J33="R/A")+(K33="A")+(K33="R/A")+(L33="A")+(L33="R/A")+(M33="A")+(M33="R/A")+(N33="A")+(N33="R/A")+(O33="A")+(O33="R/A")+(P33="A")+(P33="R/A")) | R33: =IF(A33="","",IF(Q33=1,"OK",IF(Q33=0,"FALTA aprovador","Mais de um A")))
Q34: =IF(A34="","",(D34="A")+(D34="R/A")+(E34="A")+(E34="R/A")+(F34="A")+(F34="R/A")+(G34="A")+(G34="R/A")+(H34="A")+(H34="R/A")+(I34="A")+(I34="R/A")+(J34="A")+(J34="R/A")+(K34="A")+(K34="R/A")+(L34="A")+(L34="R/A")+(M34="A")+(M34="R/A")+(N34="A")+(N34="R/A")+(O34="A")+(O34="R/A")+(P34="A")+(P34="R/A")) | R34: =IF(A34="","",IF(Q34=1,"OK",IF(Q34=0,"FALTA aprovador","Mais de um A")))
Q35: =IF(A35="","",(D35="A")+(D35="R/A")+(E35="A")+(E35="R/A")+(F35="A")+(F35="R/A")+(G35="A")+(G35="R/A")+(H35="A")+(H35="R/A")+(I35="A")+(I35="R/A")+(J35="A")+(J35="R/A")+(K35="A")+(K35="R/A")+(L35="A")+(L35="R/A")+(M35="A")+(M35="R/A")+(N35="A")+(N35="R/A")+(O35="A")+(O35="R/A")+(P35="A")+(P35="R/A")) | R35: =IF(A35="","",IF(Q35=1,"OK",IF(Q35=0,"FALTA aprovador","Mais de um A")))
Q36: =IF(A36="","",(D36="A")+(D36="R/A")+(E36="A")+(E36="R/A")+(F36="A")+(F36="R/A")+(G36="A")+(G36="R/A")+(H36="A")+(H36="R/A")+(I36="A")+(I36="R/A")+(J36="A")+(J36="R/A")+(K36="A")+(K36="R/A")+(L36="A")+(L36="R/A")+(M36="A")+(M36="R/A")+(N36="A")+(N36="R/A")+(O36="A")+(O36="R/A")+(P36="A")+(P36="R/A")) | R36: =IF(A36="","",IF(Q36=1,"OK",IF(Q36=0,"FALTA aprovador","Mais de um A")))

Sheet Listas
A1: LISTAS CONTROLADAS (domínios de validação de dados) — editar aqui para alterar opções
A2: DataReferencia | B2: Processo | C2: Funcao | D2: SimNao | E2: Resultado | F2: Nivel | G2: RACI
A3: 46387 | B3: REC | C3: Diretor Geral (Gestão de Topo) | D3: Sim | E3: Aprovado | F3: Reação | G3: R
B4: ARQ | C4: Diretor Industrial | D4: Não | E4: Reprovado | F4: Aprendizagem | G4: A
B5: INJ | C5: Gestor do SGA / EHS (Responsável Ambiental) | E5: Pendente | F5: Comportamento | G5: C
B6: SOP | C6: Gerente de Produção | G6: I
B7: SER | C7: Gerente de Manutenção | G7: R/A
B8: HFS | C8: Gerente da Qualidade | G8: —
B9: MOA | C9: Responsável de Armazém e Logística
B10: UTL | C10: Responsável de Compras
B11: MAN | C11: Responsável de R&D
B12: PRS | C12: Responsável de Recursos Humanos
B13: EXP | C13: Diretor Financeiro
B14: LAB | C14: Operador de Serigrafia
B15: RD | C15: Operador de Injeção
B16: CMP | C16: Operador de Sopro (ISBM)
B17: ADM | C17: Operador de Hot Foil
B18: GER | C18: Técnico de Manutenção
C19: Técnico de Utilidades
C20: Operador de Armazém / Empilhador
C21: Chefe de Turno
C22: Auditor Interno do SGA
C23: Representante dos Trabalhadores (SST/Ambiente)
C24: Técnico de Qualidade/Ambiente

Sheet Dicionario_Dados
A1: Folha | B1: Tabela | C1: Coluna | D1: Tipo | E1: Origem | F1: Descricao | G1: Dominio_Unidade | H1: Obrigatorio | I1: Chave
A2: Catalogo_Formacao | B2: tbl_formacoes | C2: ID_Formacao | D2: Texto | E2: Entrada | F2: Identificador da ação de formação. | H2: Sim | I2: PK
A3: Catalogo_Formacao | B3: tbl_formacoes | C3: Formacao | D3: Texto | E3: Entrada | F3: Designação. | H3: Sim
A4: Catalogo_Formacao | B4: tbl_formacoes | C4: Duracao_h | D4: Inteiro | E4: Entrada | F4: Duração (horas). | H4: Sim
A5: Catalogo_Formacao | B5: tbl_formacoes | C5: Entidade | D5: Texto | E5: Entrada | F5: Entidade formadora. | H5: Sim
A6: Catalogo_Formacao | B6: tbl_formacoes | C6: Obrigatoria_Legal | D6: Texto | E6: Entrada | F6: Exigida por lei. | G6: Lista lst_SimNao | H6: Sim
A7: Catalogo_Formacao | B7: tbl_formacoes | C7: Reciclagem_Meses | D7: Inteiro | E7: Entrada | F7: Periodicidade de reciclagem (0 = certificação sem reciclagem). | H7: Sim
A8: Catalogo_Formacao | B8: tbl_formacoes | C8: N_Registos | D8: Inteiro | E8: Calculado (fórmula) | F8: N.º de registos individuais. | H8: Sim
A9: Matriz_Competencias | B9: tbl_competencias | C9: ID_Competencia | D9: Texto | E9: Entrada | F9: Identificador do perfil. | H9: Sim | I9: PK
A10: Matriz_Competencias | B10: tbl_competencias | C10: Funcao | D10: Texto | E10: Entrada | F10: Função operacional. | G10: Lista lst_Funcao | H10: Sim
A11: Matriz_Competencias | B11: tbl_competencias | C11: Processo | D11: Texto | E11: Entrada | F11: Processo. | G11: Lista lst_Processo | H11: Sim
A12: Matriz_Competencias | B12: tbl_competencias | C12: ID_Aspeto_AAS | D12: Texto | E12: Entrada | F12: Aspeto significativo associado. | H12: Não | I12: FK → RG-SGA-03
A13: Matriz_Competencias | B13: tbl_competencias | C13: Aspeto_Significativo | D13: Texto | E13: Entrada | F13: Aspeto ambiental significativo/relevante da função. | H13: Sim
A14: Matriz_Competencias | B14: tbl_competencias | C14: Educacao_Habilitacoes | D14: Texto | E14: Entrada | F14: Nível de educação exigido. | H14: Sim
A15: Matriz_Competencias | B15: tbl_competencias | C15: Formacao_Obrigatoria | D15: Texto | E15: Entrada | F15: Ações de formação obrigatórias (IDs). | H15: Sim | I15: FK → tbl_formacoes
A16: Matriz_Competencias | B16: tbl_competencias | C16: Formacao_Descricao | D16: Texto | E16: Calculado (fórmula) | F16: Primeira formação e n.º de outras. | H16: Sim
A17: Matriz_Competencias | B17: tbl_competencias | C17: Experiencia | D17: Texto | E17: Entrada | F17: Experiência mínima. | H17: Sim
A18: Matriz_Competencias | B18: tbl_competencias | C18: Soft_Skills | D18: Texto | E18: Entrada | F18: Competências comportamentais. | H18: Sim
A19: Matriz_Competencias | B19: tbl_competencias | C19: Tema_Consciencializacao | D19: Texto | E19: Entrada | F19: O que o colaborador precisa de saber sobre as consequências do seu trabalho (7.3). | H19: Sim
A20: Matriz_Competencias | B20: tbl_competencias | C20: Consequencia_Desvio | D20: Texto | E20: Entrada | F20: Consequência de não cumprir. | H20: Sim
A21: Matriz_Competencias | B21: tbl_competencias | C21: Avaliacao_Eficacia | D21: Texto | E21: Entrada | F21: Como se avalia a eficácia (reação, aprendizagem, comportamento). | H21: Sim
A22: Matriz_Competencias | B22: tbl_competencias | C22: N_Colaboradores | D22: Inteiro | E22: Calculado (fórmula) | F22: N.º de colaboradores no perfil (registos ÷ formações obrigatórias). | H22: Sim
A23: Matriz_Competencias | B23: tbl_competencias | C23: Registos_Aprovados | D23: Inteiro | E23: Calculado (fórmula) | F23: Registos de formação aprovados e válidos. | H23: Sim
A24: Matriz_Competencias | B24: tbl_competencias | C24: Cobertura | D24: Percentagem (fração 0-1) | E24: Calculado (fórmula) | F24: % de formações obrigatórias concluídas e válidas no perfil. | H24: Sim
A25: Matriz_Competencias | B25: tbl_competencias | C25: Estado | D25: Texto | E25: Calculado (fórmula) | F25: OK = 100%; Parcial ≥ 80%; Pendente < 80%. | H25: Sim
A26: Matriz_Competencias | B26: tbl_competencias | C26: Selecionado_Atv_4_1 | D26: Texto | E26: Entrada | F26: Função escolhida na Atividade 4.1. | G26: Lista lst_SimNao | H26: Sim
A27: Registo_Formacao | B27: tbl_registo_formacao | C27: ID_Registo | D27: Texto | E27: Entrada | F27: Identificador do registo. | H27: Sim | I27: PK
A28: Registo_Formacao | B28: tbl_registo_formacao | C28: Colaborador | D28: Texto | E28: Entrada | F28: ID do colaborador (dataset dim_operator ou interno). | H28: Sim | I28: FK → dim_operator
A29: Registo_Formacao | B29: tbl_registo_formacao | C29: ID_Competencia | D29: Texto | E29: Entrada | F29: Perfil de competência. | H29: Sim | I29: FK → tbl_competencias
A30: Registo_Formacao | B30: tbl_registo_formacao | C30: ID_Formacao | D30: Texto | E30: Entrada | F30: Formação. | H30: Sim | I30: FK → tbl_formacoes
A31: Registo_Formacao | B31: tbl_registo_formacao | C31: Data_Realizacao | D31: Data (aaaa-mm-dd) | E31: Entrada | F31: Data em que concluiu. | H31: Não
A32: Registo_Formacao | B32: tbl_registo_formacao | C32: Duracao_h | D32: Inteiro | E32: Entrada | F32: Horas. | H32: Sim
A33: Registo_Formacao | B33: tbl_registo_formacao | C33: Resultado | D33: Texto | E33: Entrada | F33: Resultado. | G33: Lista lst_Resultado | H33: Sim
A34: Registo_Formacao | B34: tbl_registo_formacao | C34: Nota_Teste | D34: Inteiro | E34: Entrada | F34: Nota do teste (0-100). | H34: Não
A35: Registo_Formacao | B35: tbl_registo_formacao | C35: Nivel_Avaliado | D35: Texto | E35: Entrada | F35: Nível de avaliação da eficácia (Kirkpatrick). | G35: Lista lst_Nivel | H35: Não
A36: Registo_Formacao | B36: tbl_registo_formacao | C36: Reciclagem_Meses | D36: Inteiro | E36: Entrada | F36: Periodicidade de reciclagem. | H36: Sim
A37: Registo_Formacao | B37: tbl_registo_formacao | C37: Validade | D37: Data (aaaa-mm-dd) | E37: Calculado (fórmula) | F37: Data de validade. | H37: Sim
A38: Registo_Formacao | B38: tbl_registo_formacao | C38: Valida | D38: Texto | E38: Calculado (fórmula) | F38: Válida na data de referência. | H38: Sim
A39: Matriz_RACI | B39: tbl_raci | C39: ID_Processo | D39: Texto | E39: Entrada | F39: Identificador. | H39: Sim | I39: PK
A40: Matriz_RACI | B40: tbl_raci | C40: Processo_SGA | D40: Texto | E40: Entrada | F40: Processo do SGA. | H40: Sim
...
