Workbook
Name DataRef: Listas!$A$3
Name esc_Fin_Limite: Listas!$E$49:$E$53
Name esc_Prob_Media: Listas!$F$44:$F$48
Name lst_DataReferencia: Listas!$A$3:$A$3
Name lst_Escala: Listas!$I$3:$I$7
Name lst_EstadoValidacao: Listas!$M$3:$M$5
Name lst_Etapa: Listas!$F$3:$F$7
Name lst_FEtapa: Listas!$U$3:$U$8
Name lst_FHorizonte: Listas!$V$3:$V$6
Name lst_FPilar: Listas!$S$3:$S$6
Name lst_FTipo: Listas!$W$3:$W$7
Name lst_FTopico: Listas!$T$3:$T$14
Name lst_Funcao: Listas!$R$3:$R$24
Name lst_Horizonte: Listas!$G$3:$G$5
Name lst_Metodo: Listas!$P$3:$P$8
Name lst_Natureza: Listas!$E$3:$E$4
Name lst_Parte: Listas!$O$3:$O$10
Name lst_Pilar: Listas!$B$3:$B$5
Name lst_Qualidade: Listas!$K$3:$K$5
Name lst_RelevanciaSetorial: Listas!$N$3:$N$5
Name lst_Rubrica: Listas!$J$3:$J$8
Name lst_SimNao: Listas!$H$3:$H$4
Name lst_TipoContributo: Listas!$Q$3:$Q$4
Name lst_TipoDado: Listas!$L$3:$L$6
Name lst_TipoIRO: Listas!$D$3:$D$6
Name lst_TopicoESRS: Listas!$C$3:$C$13
Name prm_Faturacao_EUR: Listas!$B$66
Name prm_Grav_DH: Listas!$B$62
Name prm_Limiar_Alto: Listas!$B$60
Name prm_Limiar_Baixo: Listas!$B$61
Name prm_Limiar_Financeiro: Listas!$B$59
Name prm_Limiar_Impacto: Listas!$B$58
Name prm_Meses_Rev_Material: Listas!$B$64
Name prm_Meses_Rev_Outros: Listas!$B$65
Name prm_Preco_Eletricidade: Listas!$B$67
Name prm_Preco_Polimero: Listas!$B$68
Name prm_Relev_Alerta: Listas!$B$63
Name prm_Trabalhadores: Listas!$B$69
Name SegmentaçãoDeDados_Etapa_Cadeia_Valor: #N/A
Name SegmentaçãoDeDados_Horizonte: #N/A
Name SegmentaçãoDeDados_Material: #N/A
Name SegmentaçãoDeDados_Pilar: #N/A
Name SegmentaçãoDeDados_Qualidade_Evidencia: #N/A
Name SegmentaçãoDeDados_Tipo_IRO: #N/A

Sheet 00_LEIA-ME
A1: RG-SGA-17 — Análise de Dupla Materialidade (DMA) — Plasticom
A2: Sistema de Gestão Ambiental NP EN ISO 14001:2026 · Plasticom — Unidade 1 (Marinha Grande, Portugal) · Registo do SGA (fábrica simulada)
A4: CONTROLO DO DOCUMENTO (7.5 — informação documentada)
A5: Código do registo | B5: RG-SGA-17
A6: Título | B6: Análise de Dupla Materialidade (DMA) — Plasticom
A7: Versão / Revisão | B7: 02
A8: Data de emissão | B8: 46289
A9: Elaborado por | B9: Gestor(a) do SGA / EHS
A10: Aprovado por | B10: Diretor Geral
A11: Estado | B11: Em vigor
A12: Retenção | B12: 5 anos após substituição
A13: Localização | B13: Repositório controlado do SGA > Registos_SGA_Plasticom (versão eletrónica é a versão controlada; cópias impressas são não controladas)
A15: FINALIDADE E ÂMBITO
A16: Finalidade | B16: Identificar e avaliar os temas de sustentabilidade materiais para a Plasticom nas duas perspetivas — impacto (efeitos da empresa sobre pessoas e ambiente, de dentro para fora) e financeira (efeitos dos temas sobre o desempenho e a posição financeira, de fora para dentro) — ao nível de cada impacto, risco e oportunidade (IRO), com critérios parametrizados, evidências rastreáveis, contributos das partes interessadas e ligação às decisões do SGA. Revisão 02: substitui a folha única 28_Dupla_Materialidade (12 temas, sem IRO nem evidências).
A17: Atividades do curso | B17: Complemento ESG do SGA (não é atividade do curso): dupla materialidade para priorizar temas, riscos e oportunidades de sustentabilidade.
A18: Requisitos ISO 14001:2026 | B18: 4.1 Contexto; 4.2 Partes interessadas; 6.1.1–6.1.4 Aspetos, obrigações, riscos e oportunidades (integração)
A20: ESTRUTURA DO FICHEIRO
A21: Painel | B21: Painel interativo: filtros, indicadores, matriz de dupla materialidade, gráfico dinâmico, ranking, resumo por tópico ESRS e tabela dinâmica com segmentações de dados.
A22: Temas | B22: Temas de sustentabilidade com a materialidade agregada a partir dos IRO (1 linha por tema).
A23: IRO | B23: Impactos, riscos e oportunidades (IRO) — unidade de avaliação da dupla materialidade (1 linha por IRO).
A24: Evidencias | B24: Evidências quantitativas e qualitativas que sustentam cada IRO (instantâneo dos registos do SGA à data da avaliação).
A25: Consultas | B25: Contributos das partes interessadas por tema (1 linha por contributo; formato longo para análise).
A26: Listas | B26: Domínios de validação e, abaixo, as tabelas de critérios (tbl_dma_escalas) e de parâmetros (tbl_dma_parametros) com os limiares lidos pelas fórmulas — alterar aqui recalcula toda a análise.
A27: Dicionario_Dados | B27: Descrição de cada coluna de cada tabela: tipo, origem (entrada/calculado), domínio, obrigatoriedade e chaves.
A29: CONVENÇÕES (prontas para análise de dados e machine learning)
A30: Tabelas | B30: Cada registo é uma Tabela Excel com nome próprio (tbl_*): uma linha = um registo, cabeçalho único, sem células mescladas. Ler com pandas (pd.read_excel(ficheiro, sheet_name=folha, header=<linha do cabeçalho - 1>)) ou Power BI (Obter Dados > Tabela).
A31: Cabeçalho cinzento | B31: Coluna CALCULADA por fórmula — não escrever por cima. As restantes colunas são de entrada.
A32: Validação | B32: Colunas com lista controlada só aceitam valores da folha Listas (evita categorias duplicadas por grafia diferente).
A33: Chaves | B33: IDs estáveis e únicos (PK) e referências a IDs de outros registos (FK) permitem juntar tabelas entre ficheiros — ver SGA-00_Indice_Modelo_Dados.xlsx.
A34: Datas e unidades | B34: Datas em formato data (aaaa-mm-dd); números como números; a unidade está no nome da coluna ou no dicionário. Data de referência do SGA: 2026-12-31 (fecho do ano).
A35: Dados simulados | B35: Fábrica simulada Plasticom. Dados operacionais derivados do dataset do projeto (datasets/silver); dados ambientais e de conformidade são simulação didática — confirmar aplicabilidade legal e números antes de uso real.
A37: LIGAÇÕES A OUTROS REGISTOS
A38: RG-SGA-01 Contexto | B38: IDs_Contexto → SWOT (SWT-*) e PESTEL (PES-*).
A39: RG-SGA-02 Riscos e oportunidades | B39: ID_RO → coluna 'ID RO (SGA)' e ID_Registo_Corporativo → coluna 'ID' de tbRiscos / tbOportunidades.
A40: RG-SGA-03 Aspetos | B40: IDs_Aspetos → tbl_aspetos (significância ISO 14001).
A41: RG-SGA-04 Legal | B41: ID_Legal → tbl_legal.
A42: RG-SGA-05 Objetivos e KPI | B42: ID_OBJ → tbl_objetivos; ID_KPI → tbl_kpi.
A43: RG-SGA-06 PAM | B43: ID_PAM → tbl_pam.
A44: RG-SGA-16 EMAS | B44: Evidências quantitativas (EMAS-*) — instantâneo à data da avaliação.
A45: RG-SGA-02 — avaliação corporativa | B45: Linha equivalente em tbRiscos / tbOportunidades: avaliação 5×5, inerente, BowTie e KRI.
...

Sheet Painel
A1: PAINEL DE DUPLA MATERIALIDADE — PLASTICOM
A2: Escolha os filtros nas células amarelas (lista pendente). Indicadores, matriz, resumo e gráfico recalculam-se. A tabela dinâmica no fim tem segmentações de dados (Dados > Atualizar tudo após editar as tabelas).
Z3: Dados auxiliares do gráfico (não editar)
A4: FILTROS ('(Todos)' = sem filtro · Pilar e Tópico aplicam-se a temas e IRO; Etapa, Horizonte e Tipo só aos IRO) | Z4: ID | AA4: Financeira (x) | AB4: Dupla materialidade | AC4: Material — impacto | AD4: Material — financeira | AE4: Não material
A5: Pilar | B5: Tópico ESRS | C5: Etapa da cadeia de valor | D5: Horizonte temporal | E5: Tipo de IRO | Z5: =IF(AND(INDEX(Temas!$A$5:$A$40,1)<>"",OR($A$6="(Todos)",INDEX(Temas!$B$5:$B$40,1)=$A$6),OR($B$6="(Todos)",INDEX(Temas!$C$5:$C$40,1)=$B$6)),INDEX(Temas!$A$5:$A$40,1),"") -> DM-01 | AA5: =IF(AND(INDEX(Temas!$A$5:$A$40,1)<>"",OR($A$6="(Todos)",INDEX(Temas!$B$5:$B$40,1)=$A$6),OR($B$6="(Todos)",INDEX(Temas!$C$5:$C$40,1)=$B$6)),N(INDEX(Temas!$Q$5:$Q$40,1)),NA()) -> 12 | AB5: =IF(AND(AND(INDEX(Temas!$A$5:$A$40,1)<>"",OR($A$6="(Todos)",INDEX(Temas!$B$5:$B$40,1)=$A$6),OR($B$6="(Todos)",INDEX(Temas!$C$5:$C$40,1)=$B$6)),INDEX(Temas!$T$5:$T$40,1)="Dupla materialidade"),N(INDEX(Temas!$P$5:$P$40,1)),NA()) -> 20 | AC5: =IF(AND(AND(INDEX(Temas!$A$5:$A$40,1)<>"",OR($A$6="(Todos)",INDEX(Temas!$B$5:$B$40,1)=$A$6),OR($B$6="(Todos)",INDEX(Temas!$C$5:$C$40,1)=$B$6)),INDEX(Temas!$T$5:$T$40,1)="Material — impacto"),N(INDEX(Temas!$P$5:$P$40,1)),NA()) -> #N/A | AD5: =IF(AND(AND(INDEX(Temas!$A$5:$A$40,1)<>"",OR($A$6="(Todos)",INDEX(Temas!$B$5:$B$40,1)=$A$6),OR($B$6="(Todos)",INDEX(Temas!$C$5:$C$40,1)=$B$6)),INDEX(Temas!$T$5:$T$40,1)="Material — financeira"),N(INDEX(Temas!$P$5:$P$40,1)),NA()) -> #N/A | AE5: =IF(AND(AND(INDEX(Temas!$A$5:$A$40,1)<>"",OR($A$6="(Todos)",INDEX(Temas!$B$5:$B$40,1)=$A$6),OR($B$6="(Todos)",INDEX(Temas!$C$5:$C$40,1)=$B$6)),INDEX(Temas!$T$5:$T$40,1)="Não material"),N(INDEX(Temas!$P$5:$P$40,1)),NA()) -> #N/A
A6: (Todos) | B6: (Todos) | C6: (Todos) | D6: (Todos) | E6: (Todos) | Z6: =IF(AND(INDEX(Temas!$A$5:$A$40,2)<>"",OR($A$6="(Todos)",INDEX(Temas!$B$5:$B$40,2)=$A$6),OR($B$6="(Todos)",INDEX(Temas!$C$5:$C$40,2)=$B$6)),INDEX(Temas!$A$5:$A$40,2),"") -> DM-02 | AA6: =IF(AND(INDEX(Temas!$A$5:$A$40,2)<>"",OR($A$6="(Todos)",INDEX(Temas!$B$5:$B$40,2)=$A$6),OR($B$6="(Todos)",INDEX(Temas!$C$5:$C$40,2)=$B$6)),N(INDEX(Temas!$Q$5:$Q$40,2)),NA()) -> 16 | AB6: =IF(AND(AND(INDEX(Temas!$A$5:$A$40,2)<>"",OR($A$6="(Todos)",INDEX(Temas!$B$5:$B$40,2)=$A$6),OR($B$6="(Todos)",INDEX(Temas!$C$5:$C$40,2)=$B$6)),INDEX(Temas!$T$5:$T$40,2)="Dupla materialidade"),N(INDEX(Temas!$P$5:$P$40,2)),NA()) -> 15 | AC6: =IF(AND(AND(INDEX(Temas!$A$5:$A$40,2)<>"",OR($A$6="(Todos)",INDEX(Temas!$B$5:$B$40,2)=$A$6),OR($B$6="(Todos)",INDEX(Temas!$C$5:$C$40,2)=$B$6)),INDEX(Temas!$T$5:$T$40,2)="Material — impacto"),N(INDEX(Temas!$P$5:$P$40,2)),NA()) -> #N/A | AD6: =IF(AND(AND(INDEX(Temas!$A$5:$A$40,2)<>"",OR($A$6="(Todos)",INDEX(Temas!$B$5:$B$40,2)=$A$6),OR($B$6="(Todos)",INDEX(Temas!$C$5:$C$40,2)=$B$6)),INDEX(Temas!$T$5:$T$40,2)="Material — financeira"),N(INDEX(Temas!$P$5:$P$40,2)),NA()) -> #N/A | AE6: =IF(AND(AND(INDEX(Temas!$A$5:$A$40,2)<>"",OR($A$6="(Todos)",INDEX(Temas!$B$5:$B$40,2)=$A$6),OR($B$6="(Todos)",INDEX(Temas!$C$5:$C$40,2)=$B$6)),INDEX(Temas!$T$5:$T$40,2)="Não material"),N(INDEX(Temas!$P$5:$P$40,2)),NA()) -> #N/A
A7: =IF(A6="(Todos)","*",A6) -> * | B7: =IF(B6="(Todos)","*",B6) -> * | C7: =IF(C6="(Todos)","*",C6) -> * | D7: =IF(D6="(Todos)","*",D6) -> * | E7: =IF(E6="(Todos)","*",E6) -> * | F7: ← critérios usados nas fórmulas | Z7: =IF(AND(INDEX(Temas!$A$5:$A$40,3)<>"",OR($A$6="(Todos)",INDEX(Temas!$B$5:$B$40,3)=$A$6),OR($B$6="(Todos)",INDEX(Temas!$C$5:$C$40,3)=$B$6)),INDEX(Temas!$A$5:$A$40,3),"") -> DM-03 | AA7: =IF(AND(INDEX(Temas!$A$5:$A$40,3)<>"",OR($A$6="(Todos)",INDEX(Temas!$B$5:$B$40,3)=$A$6),OR($B$6="(Todos)",INDEX(Temas!$C$5:$C$40,3)=$B$6)),N(INDEX(Temas!$Q$5:$Q$40,3)),NA()) -> 12 | AB7: =IF(AND(AND(INDEX(Temas!$A$5:$A$40,3)<>"",OR($A$6="(Todos)",INDEX(Temas!$B$5:$B$40,3)=$A$6),OR($B$6="(Todos)",INDEX(Temas!$C$5:$C$40,3)=$B$6)),INDEX(Temas!$T$5:$T$40,3)="Dupla materialidade"),N(INDEX(Temas!$P$5:$P$40,3)),NA()) -> #N/A | AC7: =IF(AND(AND(INDEX(Temas!$A$5:$A$40,3)<>"",OR($A$6="(Todos)",INDEX(Temas!$B$5:$B$40,3)=$A$6),OR($B$6="(Todos)",INDEX(Temas!$C$5:$C$40,3)=$B$6)),INDEX(Temas!$T$5:$T$40,3)="Material — impacto"),N(INDEX(Temas!$P$5:$P$40,3)),NA()) -> #N/A | AD7: =IF(AND(AND(INDEX(Temas!$A$5:$A$40,3)<>"",OR($A$6="(Todos)",INDEX(Temas!$B$5:$B$40,3)=$A$6),OR($B$6="(Todos)",INDEX(Temas!$C$5:$C$40,3)=$B$6)),INDEX(Temas!$T$5:$T$40,3)="Material — financeira"),N(INDEX(Temas!$P$5:$P$40,3)),NA()) -> 0 | AE7: =IF(AND(AND(INDEX(Temas!$A$5:$A$40,3)<>"",OR($A$6="(Todos)",INDEX(Temas!$B$5:$B$40,3)=$A$6),OR($B$6="(Todos)",INDEX(Temas!$C$5:$C$40,3)=$B$6)),INDEX(Temas!$T$5:$T$40,3)="Não material"),N(INDEX(Temas!$P$5:$P$40,3)),NA()) -> #N/A
Z8: =IF(AND(INDEX(Temas!$A$5:$A$40,4)<>"",OR($A$6="(Todos)",INDEX(Temas!$B$5:$B$40,4)=$A$6),OR($B$6="(Todos)",INDEX(Temas!$C$5:$C$40,4)=$B$6)),INDEX(Temas!$A$5:$A$40,4),"") -> DM-04 | AA8: =IF(AND(INDEX(Temas!$A$5:$A$40,4)<>"",OR($A$6="(Todos)",INDEX(Temas!$B$5:$B$40,4)=$A$6),OR($B$6="(Todos)",INDEX(Temas!$C$5:$C$40,4)=$B$6)),N(INDEX(Temas!$Q$5:$Q$40,4)),NA()) -> 4 | AB8: =IF(AND(AND(INDEX(Temas!$A$5:$A$40,4)<>"",OR($A$6="(Todos)",INDEX(Temas!$B$5:$B$40,4)=$A$6),OR($B$6="(Todos)",INDEX(Temas!$C$5:$C$40,4)=$B$6)),INDEX(Temas!$T$5:$T$40,4)="Dupla materialidade"),N(INDEX(Temas!$P$5:$P$40,4)),NA()) -> #N/A | AC8: =IF(AND(AND(INDEX(Temas!$A$5:$A$40,4)<>"",OR($A$6="(Todos)",INDEX(Temas!$B$5:$B$40,4)=$A$6),OR($B$6="(Todos)",INDEX(Temas!$C$5:$C$40,4)=$B$6)),INDEX(Temas!$T$5:$T$40,4)="Material — impacto"),N(INDEX(Temas!$P$5:$P$40,4)),NA()) -> 13.4 | AD8: =IF(AND(AND(INDEX(Temas!$A$5:$A$40,4)<>"",OR($A$6="(Todos)",INDEX(Temas!$B$5:$B$40,4)=$A$6),OR($B$6="(Todos)",INDEX(Temas!$C$5:$C$40,4)=$B$6)),INDEX(Temas!$T$5:$T$40,4)="Material — financeira"),N(INDEX(Temas!$P$5:$P$40,4)),NA()) -> #N/A | AE8: =IF(AND(AND(INDEX(Temas!$A$5:$A$40,4)<>"",OR($A$6="(Todos)",INDEX(Temas!$B$5:$B$40,4)=$A$6),OR($B$6="(Todos)",INDEX(Temas!$C$5:$C$40,4)=$B$6)),INDEX(Temas!$T$5:$T$40,4)="Não material"),N(INDEX(Temas!$P$5:$P$40,4)),NA()) -> #N/A
A9: INDICADORES (com filtros) | Z9: =IF(AND(INDEX(Temas!$A$5:$A$40,5)<>"",OR($A$6="(Todos)",INDEX(Temas!$B$5:$B$40,5)=$A$6),OR($B$6="(Todos)",INDEX(Temas!$C$5:$C$40,5)=$B$6)),INDEX(Temas!$A$5:$A$40,5),"") -> DM-05 | AA9: =IF(AND(INDEX(Temas!$A$5:$A$40,5)<>"",OR($A$6="(Todos)",INDEX(Temas!$B$5:$B$40,5)=$A$6),OR($B$6="(Todos)",INDEX(Temas!$C$5:$C$40,5)=$B$6)),N(INDEX(Temas!$Q$5:$Q$40,5)),NA()) -> 4 | AB9: =IF(AND(AND(INDEX(Temas!$A$5:$A$40,5)<>"",OR($A$6="(Todos)",INDEX(Temas!$B$5:$B$40,5)=$A$6),OR($B$6="(Todos)",INDEX(Temas!$C$5:$C$40,5)=$B$6)),INDEX(Temas!$T$5:$T$40,5)="Dupla materialidade"),N(INDEX(Temas!$P$5:$P$40,5)),NA()) -> #N/A | AC9: =IF(AND(AND(INDEX(Temas!$A$5:$A$40,5)<>"",OR($A$6="(Todos)",INDEX(Temas!$B$5:$B$40,5)=$A$6),OR($B$6="(Todos)",INDEX(Temas!$C$5:$C$40,5)=$B$6)),INDEX(Temas!$T$5:$T$40,5)="Material — impacto"),N(INDEX(Temas!$P$5:$P$40,5)),NA()) -> #N/A | AD9: =IF(AND(AND(INDEX(Temas!$A$5:$A$40,5)<>"",OR($A$6="(Todos)",INDEX(Temas!$B$5:$B$40,5)=$A$6),OR($B$6="(Todos)",INDEX(Temas!$C$5:$C$40,5)=$B$6)),INDEX(Temas!$T$5:$T$40,5)="Material — financeira"),N(INDEX(Temas!$P$5:$P$40,5)),NA()) -> #N/A | AE9: =IF(AND(AND(INDEX(Temas!$A$5:$A$40,5)<>"",OR($A$6="(Todos)",INDEX(Temas!$B$5:$B$40,5)=$A$6),OR($B$6="(Todos)",INDEX(Temas!$C$5:$C$40,5)=$B$6)),INDEX(Temas!$T$5:$T$40,5)="Não material"),N(INDEX(Temas!$P$5:$P$40,5)),NA()) -> 10
A10: Temas avaliados | B10: Dupla materialidade | C10: Material — impacto | D10: Material — financeira | E10: Não material | F10: IRO avaliados | G10: IRO materiais | H10: Efeito financeiro ponderado líquido (€/ano) | I10: IRO com evidência de qualidade Alta | J10: IRO aprovados pela Direção | Z10: =IF(AND(INDEX(Temas!$A$5:$A$40,6)<>"",OR($A$6="(Todos)",INDEX(Temas!$B$5:$B$40,6)=$A$6),OR($B$6="(Todos)",INDEX(Temas!$C$5:$C$40,6)=$B$6)),INDEX(Temas!$A$5:$A$40,6),"") -> DM-06 | AA10: =IF(AND(INDEX(Temas!$A$5:$A$40,6)<>"",OR($A$6="(Todos)",INDEX(Temas!$B$5:$B$40,6)=$A$6),OR($B$6="(Todos)",INDEX(Temas!$C$5:$C$40,6)=$B$6)),N(INDEX(Temas!$Q$5:$Q$40,6)),NA()) -> 12 | AB10: =IF(AND(AND(INDEX(Temas!$A$5:$A$40,6)<>"",OR($A$6="(Todos)",INDEX(Temas!$B$5:$B$40,6)=$A$6),OR($B$6="(Todos)",INDEX(Temas!$C$5:$C$40,6)=$B$6)),INDEX(Temas!$T$5:$T$40,6)="Dupla materialidade"),N(INDEX(Temas!$P$5:$P$40,6)),NA()) -> 18.4 | AC10: =IF(AND(AND(INDEX(Temas!$A$5:$A$40,6)<>"",OR($A$6="(Todos)",INDEX(Temas!$B$5:$B$40,6)=$A$6),OR($B$6="(Todos)",INDEX(Temas!$C$5:$C$40,6)=$B$6)),INDEX(Temas!$T$5:$T$40,6)="Material — impacto"),N(INDEX(Temas!$P$5:$P$40,6)),NA()) -> #N/A | AD10: =IF(AND(AND(INDEX(Temas!$A$5:$A$40,6)<>"",OR($A$6="(Todos)",INDEX(Temas!$B$5:$B$40,6)=$A$6),OR($B$6="(Todos)",INDEX(Temas!$C$5:$C$40,6)=$B$6)),INDEX(Temas!$T$5:$T$40,6)="Material — financeira"),N(INDEX(Temas!$P$5:$P$40,6)),NA()) -> #N/A | AE10: =IF(AND(AND(INDEX(Temas!$A$5:$A$40,6)<>"",OR($A$6="(Todos)",INDEX(Temas!$B$5:$B$40,6)=$A$6),OR($B$6="(Todos)",INDEX(Temas!$C$5:$C$40,6)=$B$6)),INDEX(Temas!$T$5:$T$40,6)="Não material"),N(INDEX(Temas!$P$5:$P$40,6)),NA()) -> #N/A
A11: =COUNTIFS(Temas!$B$5:$B$40,$A$7,Temas!$C$5:$C$40,$B$7) -> 24 | B11: =COUNTIFS(Temas!$B$5:$B$40,$A$7,Temas!$C$5:$C$40,$B$7,Temas!$T$5:$T$40,"Dupla materialidade") -> 6 | C11: =COUNTIFS(Temas!$B$5:$B$40,$A$7,Temas!$C$5:$C$40,$B$7,Temas!$T$5:$T$40,"Material — impacto") -> 4 | D11: =COUNTIFS(Temas!$B$5:$B$40,$A$7,Temas!$C$5:$C$40,$B$7,Temas!$T$5:$T$40,"Material — financeira") -> 6 | E11: =COUNTIFS(Temas!$B$5:$B$40,$A$7,Temas!$C$5:$C$40,$B$7,Temas!$T$5:$T$40,"Não material") -> 8 | F11: =COUNTIFS(IRO!$D$5:$D$91,$A$7,IRO!$E$5:$E$91,$B$7,IRO!$J$5:$J$91,$C$7,IRO!$K$5:$K$91,$D$7,IRO!$F$5:$F$91,$E$7) -> 57 | G11: =COUNTIFS(IRO!$D$5:$D$91,$A$7,IRO!$E$5:$E$91,$B$7,IRO!$J$5:$J$91,$C$7,IRO!$K$5:$K$91,$D$7,IRO!$F$5:$F$91,$E$7,IRO!$AC$5:$AC$91,"Sim") -> 27 | H11: =SUMIFS(IRO!$AA$5:$AA$91,IRO!$D$5:$D$91,$A$7,IRO!$E$5:$E$91,$B$7,IRO!$J$5:$J$91,$C$7,IRO!$K$5:$K$91,$D$7,IRO!$F$5:$F$91,$E$7) -> -863000 | I11: =IFERROR(COUNTIFS(IRO!$D$5:$D$91,$A$7,IRO!$E$5:$E$91,$B$7,IRO!$J$5:$J$91,$C$7,IRO!$K$5:$K$91,$D$7,IRO!$F$5:$F$91,$E$7,IRO!$AG$5:$AG$91,"Alta")/COUNTIFS(IRO!$D$5:$D$91,$A$7,IRO!$E$5:$E$91,$B$7,IRO!$J$5:$J$91,$C$7,IRO!$K$5:$K$91,$D$7,IRO!$F$5:$F$91,$E$7),0) -> 0.33333333 | J11: =IFERROR(COUNTIFS(IRO!$D$5:$D$91,$A$7,IRO!$E$5:$E$91,$B$7,IRO!$J$5:$J$91,$C$7,IRO!$K$5:$K$91,$D$7,IRO!$F$5:$F$91,$E$7,IRO!$AT$5:$AT$91,"Aprovado pela Direção")/COUNTIFS(IRO!$D$5:$D$91,$A$7,IRO!$E$5:$E$91,$B$7,IRO!$J$5:$J$91,$C$7,IRO!$K$5:$K$91,$D$7,IRO!$F$5:$F$91,$E$7),0) -> 0 | Z11: =IF(AND(INDEX(Temas!$A$5:$A$40,7)<>"",OR($A$6="(Todos)",INDEX(Temas!$B$5:$B$40,7)=$A$6),OR($B$6="(Todos)",INDEX(Temas!$C$5:$C$40,7)=$B$6)),INDEX(Temas!$A$5:$A$40,7),"") -> DM-07 | AA11: =IF(AND(INDEX(Temas!$A$5:$A$40,7)<>"",OR($A$6="(Todos)",INDEX(Temas!$B$5:$B$40,7)=$A$6),OR($B$6="(Todos)",INDEX(Temas!$C$5:$C$40,7)=$B$6)),N(INDEX(Temas!$Q$5:$Q$40,7)),NA()) -> 9 | AB11: =IF(AND(AND(INDEX(Temas!$A$5:$A$40,7)<>"",OR($A$6="(Todos)",INDEX(Temas!$B$5:$B$40,7)=$A$6),OR($B$6="(Todos)",INDEX(Temas!$C$5:$C$40,7)=$B$6)),INDEX(Temas!$T$5:$T$40,7)="Dupla materialidade"),N(INDEX(Temas!$P$5:$P$40,7)),NA()) -> #N/A | AC11: =IF(AND(AND(INDEX(Temas!$A$5:$A$40,7)<>"",OR($A$6="(Todos)",INDEX(Temas!$B$5:$B$40,7)=$A$6),OR($B$6="(Todos)",INDEX(Temas!$C$5:$C$40,7)=$B$6)),INDEX(Temas!$T$5:$T$40,7)="Material — impacto"),N(INDEX(Temas!$P$5:$P$40,7)),NA()) -> #N/A | AD11: =IF(AND(AND(INDEX(Temas!$A$5:$A$40,7)<>"",OR($A$6="(Todos)",INDEX(Temas!$B$5:$B$40,7)=$A$6),OR($B$6="(Todos)",INDEX(Temas!$C$5:$C$40,7)=$B$6)),INDEX(Temas!$T$5:$T$40,7)="Material — financeira"),N(INDEX(Temas!$P$5:$P$40,7)),NA()) -> #N/A | AE11: =IF(AND(AND(INDEX(Temas!$A$5:$A$40,7)<>"",OR($A$6="(Todos)",INDEX(Temas!$B$5:$B$40,7)=$A$6),OR($B$6="(Todos)",INDEX(Temas!$C$5:$C$40,7)=$B$6)),INDEX(Temas!$T$5:$T$40,7)="Não material"),N(INDEX(Temas!$P$5:$P$40,7)),NA()) -> 8
Z12: =IF(AND(INDEX(Temas!$A$5:$A$40,8)<>"",OR($A$6="(Todos)",INDEX(Temas!$B$5:$B$40,8)=$A$6),OR($B$6="(Todos)",INDEX(Temas!$C$5:$C$40,8)=$B$6)),INDEX(Temas!$A$5:$A$40,8),"") -> DM-08 | AA12: =IF(AND(INDEX(Temas!$A$5:$A$40,8)<>"",OR($A$6="(Todos)",INDEX(Temas!$B$5:$B$40,8)=$A$6),OR($B$6="(Todos)",INDEX(Temas!$C$5:$C$40,8)=$B$6)),N(INDEX(Temas!$Q$5:$Q$40,8)),NA()) -> 6 | AB12: =IF(AND(AND(INDEX(Temas!$A$5:$A$40,8)<>"",OR($A$6="(Todos)",INDEX(Temas!$B$5:$B$40,8)=$A$6),OR($B$6="(Todos)",INDEX(Temas!$C$5:$C$40,8)=$B$6)),INDEX(Temas!$T$5:$T$40,8)="Dupla materialidade"),N(INDEX(Temas!$P$5:$P$40,8)),NA()) -> #N/A | AC12: =IF(AND(AND(INDEX(Temas!$A$5:$A$40,8)<>"",OR($A$6="(Todos)",INDEX(Temas!$B$5:$B$40,8)=$A$6),OR($B$6="(Todos)",INDEX(Temas!$C$5:$C$40,8)=$B$6)),INDEX(Temas!$T$5:$T$40,8)="Material — impacto"),N(INDEX(Temas!$P$5:$P$40,8)),NA()) -> #N/A | AD12: =IF(AND(AND(INDEX(Temas!$A$5:$A$40,8)<>"",OR($A$6="(Todos)",INDEX(Temas!$B$5:$B$40,8)=$A$6),OR($B$6="(Todos)",INDEX(Temas!$C$5:$C$40,8)=$B$6)),INDEX(Temas!$T$5:$T$40,8)="Material — financeira"),N(INDEX(Temas!$P$5:$P$40,8)),NA()) -> #N/A | AE12: =IF(AND(AND(INDEX(Temas!$A$5:$A$40,8)<>"",OR($A$6="(Todos)",INDEX(Temas!$B$5:$B$40,8)=$A$6),OR($B$6="(Todos)",INDEX(Temas!$C$5:$C$40,8)=$B$6)),INDEX(Temas!$T$5:$T$40,8)="Não material"),N(INDEX(Temas!$P$5:$P$40,8)),NA()) -> 11.7
A13: MATRIZ DE DUPLA MATERIALIDADE — n.º de temas por banda (filtros Pilar e Tópico) | Z13: =IF(AND(INDEX(Temas!$A$5:$A$40,9)<>"",OR($A$6="(Todos)",INDEX(Temas!$B$5:$B$40,9)=$A$6),OR($B$6="(Todos)",INDEX(Temas!$C$5:$C$40,9)=$B$6)),INDEX(Temas!$A$5:$A$40,9),"") -> DM-09 | AA13: =IF(AND(INDEX(Temas!$A$5:$A$40,9)<>"",OR($A$6="(Todos)",INDEX(Temas!$B$5:$B$40,9)=$A$6),OR($B$6="(Todos)",INDEX(Temas!$C$5:$C$40,9)=$B$6)),N(INDEX(Temas!$Q$5:$Q$40,9)),NA()) -> 0 | AB13: =IF(AND(AND(INDEX(Temas!$A$5:$A$40,9)<>"",OR($A$6="(Todos)",INDEX(Temas!$B$5:$B$40,9)=$A$6),OR($B$6="(Todos)",INDEX(Temas!$C$5:$C$40,9)=$B$6)),INDEX(Temas!$T$5:$T$40,9)="Dupla materialidade"),N(INDEX(Temas!$P$5:$P$40,9)),NA()) -> #N/A | AC13: =IF(AND(AND(INDEX(Temas!$A$5:$A$40,9)<>"",OR($A$6="(Todos)",INDEX(Temas!$B$5:$B$40,9)=$A$6),OR($B$6="(Todos)",INDEX(Temas!$C$5:$C$40,9)=$B$6)),INDEX(Temas!$T$5:$T$40,9)="Material — impacto"),N(INDEX(Temas!$P$5:$P$40,9)),NA()) -> 14 | AD13: =IF(AND(AND(INDEX(Temas!$A$5:$A$40,9)<>"",OR($A$6="(Todos)",INDEX(Temas!$B$5:$B$40,9)=$A$6),OR($B$6="(Todos)",INDEX(Temas!$C$5:$C$40,9)=$B$6)),INDEX(Temas!$T$5:$T$40,9)="Material — financeira"),N(INDEX(Temas!$P$5:$P$40,9)),NA()) -> #N/A | AE13: =IF(AND(AND(INDEX(Temas!$A$5:$A$40,9)<>"",OR($A$6="(Todos)",INDEX(Temas!$B$5:$B$40,9)=$A$6),OR($B$6="(Todos)",INDEX(Temas!$C$5:$C$40,9)=$B$6)),INDEX(Temas!$T$5:$T$40,9)="Não material"),N(INDEX(Temas!$P$5:$P$40,9)),NA()) -> #N/A
A14: Impacto ↓ · Financeira → | B14: ="Sem IRO" -> Sem IRO | C14: ="Baixa (<"&prm_Limiar_Baixo&")" -> Baixa (<6) | D14: ="Monitorizar ("&prm_Limiar_Baixo&"–<"&prm_Limiar_Financeiro&")" -> Monitorizar (6–<12) | E14: ="Material ("&prm_Limiar_Financeiro&"–<"&prm_Limiar_Alto&")" -> Material (12–<18) | F14: ="Alta (≥"&prm_Limiar_Alto&")" -> Alta (≥18) | Z14: =IF(AND(INDEX(Temas!$A$5:$A$40,10)<>"",OR($A$6="(Todos)",INDEX(Temas!$B$5:$B$40,10)=$A$6),OR($B$6="(Todos)",INDEX(Temas!$C$5:$C$40,10)=$B$6)),INDEX(Temas!$A$5:$A$40,10),"") -> DM-10 | AA14: =IF(AND(INDEX(Temas!$A$5:$A$40,10)<>"",OR($A$6="(Todos)",INDEX(Temas!$B$5:$B$40,10)=$A$6),OR($B$6="(Todos)",INDEX(Temas!$C$5:$C$40,10)=$B$6)),N(INDEX(Temas!$Q$5:$Q$40,10)),NA()) -> 12 | AB14: =IF(AND(AND(INDEX(Temas!$A$5:$A$40,10)<>"",OR($A$6="(Todos)",INDEX(Temas!$B$5:$B$40,10)=$A$6),OR($B$6="(Todos)",INDEX(Temas!$C$5:$C$40,10)=$B$6)),INDEX(Temas!$T$5:$T$40,10)="Dupla materialidade"),N(INDEX(Temas!$P$5:$P$40,10)),NA()) -> 18.4 | AC14: =IF(AND(AND(INDEX(Temas!$A$5:$A$40,10)<>"",OR($A$6="(Todos)",INDEX(Temas!$B$5:$B$40,10)=$A$6),OR($B$6="(Todos)",INDEX(Temas!$C$5:$C$40,10)=$B$6)),INDEX(Temas!$T$5:$T$40,10)="Material — impacto"),N(INDEX(Temas!$P$5:$P$40,10)),NA()) -> #N/A | AD14: =IF(AND(AND(INDEX(Temas!$A$5:$A$40,10)<>"",OR($A$6="(Todos)",INDEX(Temas!$B$5:$B$40,10)=$A$6),OR($B$6="(Todos)",INDEX(Temas!$C$5:$C$40,10)=$B$6)),INDEX(Temas!$T$5:$T$40,10)="Material — financeira"),N(INDEX(Temas!$P$5:$P$40,10)),NA()) -> #N/A | AE14: =IF(AND(AND(INDEX(Temas!$A$5:$A$40,10)<>"",OR($A$6="(Todos)",INDEX(Temas!$B$5:$B$40,10)=$A$6),OR($B$6="(Todos)",INDEX(Temas!$C$5:$C$40,10)=$B$6)),INDEX(Temas!$T$5:$T$40,10)="Não material"),N(INDEX(Temas!$P$5:$P$40,10)),NA()) -> #N/A
A15: ="Alta (≥"&prm_Limiar_Alto&")" -> Alta (≥18) | B15: =COUNTIFS(Temas!$U$5:$U$40,4,Temas!$V$5:$V$40,0,Temas!$B$5:$B$40,$A$7,Temas!$C$5:$C$40,$B$7) -> 0 | C15: =COUNTIFS(Temas!$U$5:$U$40,4,Temas!$V$5:$V$40,1,Temas!$B$5:$B$40,$A$7,Temas!$C$5:$C$40,$B$7) -> 0 | D15: =COUNTIFS(Temas!$U$5:$U$40,4,Temas!$V$5:$V$40,2,Temas!$B$5:$B$40,$A$7,Temas!$C$5:$C$40,$B$7) -> 1 | E15: =COUNTIFS(Temas!$U$5:$U$40,4,Temas!$V$5:$V$40,3,Temas!$B$5:$B$40,$A$7,Temas!$C$5:$C$40,$B$7) -> 4 | F15: =COUNTIFS(Temas!$U$5:$U$40,4,Temas!$V$5:$V$40,4,Temas!$B$5:$B$40,$A$7,Temas!$C$5:$C$40,$B$7) -> 0 | G15: Vermelho = dupla materialidade · laranja = material numa dimensão · amarelo = monitorizar · verde = baixa · cinzento = sem IRO nessa dimensão | Z15: =IF(AND(INDEX(Temas!$A$5:$A$40,11)<>"",OR($A$6="(Todos)",INDEX(Temas!$B$5:$B$40,11)=$A$6),OR($B$6="(Todos)",INDEX(Temas!$C$5:$C$40,11)=$B$6)),INDEX(Temas!$A$5:$A$40,11),"") -> DM-11 | AA15: =IF(AND(INDEX(Temas!$A$5:$A$40,11)<>"",OR($A$6="(Todos)",INDEX(Temas!$B$5:$B$40,11)=$A$6),OR($B$6="(Todos)",INDEX(Temas!$C$5:$C$40,11)=$B$6)),N(INDEX(Temas!$Q$5:$Q$40,11)),NA()) -> 20 | AB15: =IF(AND(AND(INDEX(Temas!$A$5:$A$40,11)<>"",OR($A$6="(Todos)",INDEX(Temas!$B$5:$B$40,11)=$A$6),OR($B$6="(Todos)",INDEX(Temas!$C$5:$C$40,11)=$B$6)),INDEX(Temas!$T$5:$T$40,11)="Dupla materialidade"),N(INDEX(Temas!$P$5:$P$40,11)),NA()) -> 16.7 | AC15: =IF(AND(AND(INDEX(Temas!$A$5:$A$40,11)<>"",OR($A$6="(Todos)",INDEX(Temas!$B$5:$B$40,11)=$A$6),OR($B$6="(Todos)",INDEX(Temas!$C$5:$C$40,11)=$B$6)),INDEX(Temas!$T$5:$T$40,11)="Material — impacto"),N(INDEX(Temas!$P$5:$P$40,11)),NA()) -> #N/A | AD15: =IF(AND(AND(INDEX(Temas!$A$5:$A$40,11)<>"",OR($A$6="(Todos)",INDEX(Temas!$B$5:$B$40,11)=$A$6),OR($B$6="(Todos)",INDEX(Temas!$C$5:$C$40,11)=$B$6)),INDEX(Temas!$T$5:$T$40,11)="Material — financeira"),N(INDEX(Temas!$P$5:$P$40,11)),NA()) -> #N/A | AE15: =IF(AND(AND(INDEX(Temas!$A$5:$A$40,11)<>"",OR($A$6="(Todos)",INDEX(Temas!$B$5:$B$40,11)=$A$6),OR($B$6="(Todos)",INDEX(Temas!$C$5:$C$40,11)=$B$6)),INDEX(Temas!$T$5:$T$40,11)="Não material"),N(INDEX(Temas!$P$5:$P$40,11)),NA()) -> #N/A
A16: ="Material ("&prm_Limiar_Impacto&"–<"&prm_Limiar_Alto&")" -> Material (12–<18) | B16: =COUNTIFS(Temas!$U$5:$U$40,3,Temas!$V$5:$V$40,0,Temas!$B$5:$B$40,$A$7,Temas!$C$5:$C$40,$B$7) -> 2 | C16: =COUNTIFS(Temas!$U$5:$U$40,3,Temas!$V$5:$V$40,1,Temas!$B$5:$B$40,$A$7,Temas!$C$5:$C$40,$B$7) -> 1 | D16: =COUNTIFS(Temas!$U$5:$U$40,3,Temas!$V$5:$V$40,2,Temas!$B$5:$B$40,$A$7,Temas!$C$5:$C$40,$B$7) -> 0 | E16: =COUNTIFS(Temas!$U$5:$U$40,3,Temas!$V$5:$V$40,3,Temas!$B$5:$B$40,$A$7,Temas!$C$5:$C$40,$B$7) -> 1 | F16: =COUNTIFS(Temas!$U$5:$U$40,3,Temas!$V$5:$V$40,4,Temas!$B$5:$B$40,$A$7,Temas!$C$5:$C$40,$B$7) -> 1 | Z16: =IF(AND(INDEX(Temas!$A$5:$A$40,12)<>"",OR($A$6="(Todos)",INDEX(Temas!$B$5:$B$40,12)=$A$6),OR($B$6="(Todos)",INDEX(Temas!$C$5:$C$40,12)=$B$6)),INDEX(Temas!$A$5:$A$40,12),"") -> DM-12 | AA16: =IF(AND(INDEX(Temas!$A$5:$A$40,12)<>"",OR($A$6="(Todos)",INDEX(Temas!$B$5:$B$40,12)=$A$6),OR($B$6="(Todos)",INDEX(Temas!$C$5:$C$40,12)=$B$6)),N(INDEX(Temas!$Q$5:$Q$40,12)),NA()) -> 8 | AB16: =IF(AND(AND(INDEX(Temas!$A$5:$A$40,12)<>"",OR($A$6="(Todos)",INDEX(Temas!$B$5:$B$40,12)=$A$6),OR($B$6="(Todos)",INDEX(Temas!$C$5:$C$40,12)=$B$6)),INDEX(Temas!$T$5:$T$40,12)="Dupla materialidade"),N(INDEX(Temas!$P$5:$P$40,12)),NA()) -> #N/A | AC16: =IF(AND(AND(INDEX(Temas!$A$5:$A$40,12)<>"",OR($A$6="(Todos)",INDEX(Temas!$B$5:$B$40,12)=$A$6),OR($B$6="(Todos)",INDEX(Temas!$C$5:$C$40,12)=$B$6)),INDEX(Temas!$T$5:$T$40,12)="Material — impacto"),N(INDEX(Temas!$P$5:$P$40,12)),NA()) -> #N/A | AD16: =IF(AND(AND(INDEX(Temas!$A$5:$A$40,12)<>"",OR($A$6="(Todos)",INDEX(Temas!$B$5:$B$40,12)=$A$6),OR($B$6="(Todos)",INDEX(Temas!$C$5:$C$40,12)=$B$6)),INDEX(Temas!$T$5:$T$40,12)="Material — financeira"),N(INDEX(Temas!$P$5:$P$40,12)),NA()) -> #N/A | AE16: =IF(AND(AND(INDEX(Temas!$A$5:$A$40,12)<>"",OR($A$6="(Todos)",INDEX(Temas!$B$5:$B$40,12)=$A$6),OR($B$6="(Todos)",INDEX(Temas!$C$5:$C$40,12)=$B$6)),INDEX(Temas!$T$5:$T$40,12)="Não material"),N(INDEX(Temas!$P$5:$P$40,12)),NA()) -> 10
A17: ="Monitorizar ("&prm_Limiar_Baixo&"–<"&prm_Limiar_Impacto&")" -> Monitorizar (6–<12) | B17: =COUNTIFS(Temas!$U$5:$U$40,2,Temas!$V$5:$V$40,0,Temas!$B$5:$B$40,$A$7,Temas!$C$5:$C$40,$B$7) -> 1 | C17: =COUNTIFS(Temas!$U$5:$U$40,2,Temas!$V$5:$V$40,1,Temas!$B$5:$B$40,$A$7,Temas!$C$5:$C$40,$B$7) -> 1 | D17: =COUNTIFS(Temas!$U$5:$U$40,2,Temas!$V$5:$V$40,2,Temas!$B$5:$B$40,$A$7,Temas!$C$5:$C$40,$B$7) -> 5 | E17: =COUNTIFS(Temas!$U$5:$U$40,2,Temas!$V$5:$V$40,3,Temas!$B$5:$B$40,$A$7,Temas!$C$5:$C$40,$B$7) -> 2 | F17: =COUNTIFS(Temas!$U$5:$U$40,2,Temas!$V$5:$V$40,4,Temas!$B$5:$B$40,$A$7,Temas!$C$5:$C$40,$B$7) -> 1 | Z17: =IF(AND(INDEX(Temas!$A$5:$A$40,13)<>"",OR($A$6="(Todos)",INDEX(Temas!$B$5:$B$40,13)=$A$6),OR($B$6="(Todos)",INDEX(Temas!$C$5:$C$40,13)=$B$6)),INDEX(Temas!$A$5:$A$40,13),"") -> DM-13 | AA17: =IF(AND(INDEX(Temas!$A$5:$A$40,13)<>"",OR($A$6="(Todos)",INDEX(Temas!$B$5:$B$40,13)=$A$6),OR($B$6="(Todos)",INDEX(Temas!$C$5:$C$40,13)=$B$6)),N(INDEX(Temas!$Q$5:$Q$40,13)),NA()) -> 6 | AB17: =IF(AND(AND(INDEX(Temas!$A$5:$A$40,13)<>"",OR($A$6="(Todos)",INDEX(Temas!$B$5:$B$40,13)=$A$6),OR($B$6="(Todos)",INDEX(Temas!$C$5:$C$40,13)=$B$6)),INDEX(Temas!$T$5:$T$40,13)="Dupla materialidade"),N(INDEX(Temas!$P$5:$P$40,13)),NA()) -> #N/A | AC17: =IF(AND(AND(INDEX(Temas!$A$5:$A$40,13)<>"",OR($A$6="(Todos)",INDEX(Temas!$B$5:$B$40,13)=$A$6),OR($B$6="(Todos)",INDEX(Temas!$C$5:$C$40,13)=$B$6)),INDEX(Temas!$T$5:$T$40,13)="Material — impacto"),N(INDEX(Temas!$P$5:$P$40,13)),NA()) -> 20 | AD17: =IF(AND(AND(INDEX(Temas!$A$5:$A$40,13)<>"",OR($A$6="(Todos)",INDEX(Temas!$B$5:$B$40,13)=$A$6),OR($B$6="(Todos)",INDEX(Temas!$C$5:$C$40,13)=$B$6)),INDEX(Temas!$T$5:$T$40,13)="Material — financeira"),N(INDEX(Temas!$P$5:$P$40,13)),NA()) -> #N/A | AE17: =IF(AND(AND(INDEX(Temas!$A$5:$A$40,13)<>"",OR($A$6="(Todos)",INDEX(Temas!$B$5:$B$40,13)=$A$6),OR($B$6="(Todos)",INDEX(Temas!$C$5:$C$40,13)=$B$6)),INDEX(Temas!$T$5:$T$40,13)="Não material"),N(INDEX(Temas!$P$5:$P$40,13)),NA()) -> #N/A
A18: ="Baixa (<"&prm_Limiar_Baixo&")" -> Baixa (<6) | B18: =COUNTIFS(Temas!$U$5:$U$40,1,Temas!$V$5:$V$40,0,Temas!$B$5:$B$40,$A$7,Temas!$C$5:$C$40,$B$7) -> 1 | C18: =COUNTIFS(Temas!$U$5:$U$40,1,Temas!$V$5:$V$40,1,Temas!$B$5:$B$40,$A$7,Temas!$C$5:$C$40,$B$7) -> 0 | D18: =COUNTIFS(Temas!$U$5:$U$40,1,Temas!$V$5:$V$40,2,Temas!$B$5:$B$40,$A$7,Temas!$C$5:$C$40,$B$7) -> 0 | E18: =COUNTIFS(Temas!$U$5:$U$40,1,Temas!$V$5:$V$40,3,Temas!$B$5:$B$40,$A$7,Temas!$C$5:$C$40,$B$7) -> 1 | F18: =COUNTIFS(Temas!$U$5:$U$40,1,Temas!$V$5:$V$40,4,Temas!$B$5:$B$40,$A$7,Temas!$C$5:$C$40,$B$7) -> 0 | Z18: =IF(AND(INDEX(Temas!$A$5:$A$40,14)<>"",OR($A$6="(Todos)",INDEX(Temas!$B$5:$B$40,14)=$A$6),OR($B$6="(Todos)",INDEX(Temas!$C$5:$C$40,14)=$B$6)),INDEX(Temas!$A$5:$A$40,14),"") -> DM-14 | AA18: =IF(AND(INDEX(Temas!$A$5:$A$40,14)<>"",OR($A$6="(Todos)",INDEX(Temas!$B$5:$B$40,14)=$A$6),OR($B$6="(Todos)",INDEX(Temas!$C$5:$C$40,14)=$B$6)),N(INDEX(Temas!$Q$5:$Q$40,14)),NA()) -> 16 | AB18: =IF(AND(AND(INDEX(Temas!$A$5:$A$40,14)<>"",OR($A$6="(Todos)",INDEX(Temas!$B$5:$B$40,14)=$A$6),OR($B$6="(Todos)",INDEX(Temas!$C$5:$C$40,14)=$B$6)),INDEX(Temas!$T$5:$T$40,14)="Dupla materialidade"),N(INDEX(Temas!$P$5:$P$40,14)),NA()) -> #N/A | AC18: =IF(AND(AND(INDEX(Temas!$A$5:$A$40,14)<>"",OR($A$6="(Todos)",INDEX(Temas!$B$5:$B$40,14)=$A$6),OR($B$6="(Todos)",INDEX(Temas!$C$5:$C$40,14)=$B$6)),INDEX(Temas!$T$5:$T$40,14)="Material — impacto"),N(INDEX(Temas!$P$5:$P$40,14)),NA()) -> #N/A | AD18: =IF(AND(AND(INDEX(Temas!$A$5:$A$40,14)<>"",OR($A$6="(Todos)",INDEX(Temas!$B$5:$B$40,14)=$A$6),OR($B$6="(Todos)",INDEX(Temas!$C$5:$C$40,14)=$B$6)),INDEX(Temas!$T$5:$T$40,14)="Material — financeira"),N(INDEX(Temas!$P$5:$P$40,14)),NA()) -> 11.7 | AE18: =IF(AND(AND(INDEX(Temas!$A$5:$A$40,14)<>"",OR($A$6="(Todos)",INDEX(Temas!$B$5:$B$40,14)=$A$6),OR($B$6="(Todos)",INDEX(Temas!$C$5:$C$40,14)=$B$6)),INDEX(Temas!$T$5:$T$40,14)="Não material"),N(INDEX(Temas!$P$5:$P$40,14)),NA()) -> #N/A
A19: Sem IRO de impacto | B19: =COUNTIFS(Temas!$U$5:$U$40,0,Temas!$V$5:$V$40,0,Temas!$B$5:$B$40,$A$7,Temas!$C$5:$C$40,$B$7) -> 0 | C19: =COUNTIFS(Temas!$U$5:$U$40,0,Temas!$V$5:$V$40,1,Temas!$B$5:$B$40,$A$7,Temas!$C$5:$C$40,$B$7) -> 0 | D19: =COUNTIFS(Temas!$U$5:$U$40,0,Temas!$V$5:$V$40,2,Temas!$B$5:$B$40,$A$7,Temas!$C$5:$C$40,$B$7) -> 0 | E19: =COUNTIFS(Temas!$U$5:$U$40,0,Temas!$V$5:$V$40,3,Temas!$B$5:$B$40,$A$7,Temas!$C$5:$C$40,$B$7) -> 2 | F19: =COUNTIFS(Temas!$U$5:$U$40,0,Temas!$V$5:$V$40,4,Temas!$B$5:$B$40,$A$7,Temas!$C$5:$C$40,$B$7) -> 0 | Z19: =IF(AND(INDEX(Temas!$A$5:$A$40,15)<>"",OR($A$6="(Todos)",INDEX(Temas!$B$5:$B$40,15)=$A$6),OR($B$6="(Todos)",INDEX(Temas!$C$5:$C$40,15)=$B$6)),INDEX(Temas!$A$5:$A$40,15),"") -> DM-15 | AA19: =IF(AND(INDEX(Temas!$A$5:$A$40,15)<>"",OR($A$6="(Todos)",INDEX(Temas!$B$5:$B$40,15)=$A$6),OR($B$6="(Todos)",INDEX(Temas!$C$5:$C$40,15)=$B$6)),N(INDEX(Temas!$Q$5:$Q$40,15)),NA()) -> 9 | AB19: =IF(AND(AND(INDEX(Temas!$A$5:$A$40,15)<>"",OR($A$6="(Todos)",INDEX(Temas!$B$5:$B$40,15)=$A$6),OR($B$6="(Todos)",INDEX(Temas!$C$5:$C$40,15)=$B$6)),INDEX(Temas!$T$5:$T$40,15)="Dupla materialidade"),N(INDEX(Temas!$P$5:$P$40,15)),NA()) -> #N/A | AC19: =IF(AND(AND(INDEX(Temas!$A$5:$A$40,15)<>"",OR($A$6="(Todos)",INDEX(Temas!$B$5:$B$40,15)=$A$6),OR($B$6="(Todos)",INDEX(Temas!$C$5:$C$40,15)=$B$6)),INDEX(Temas!$T$5:$T$40,15)="Material — impacto"),N(INDEX(Temas!$P$5:$P$40,15)),NA()) -> #N/A | AD19: =IF(AND(AND(INDEX(Temas!$A$5:$A$40,15)<>"",OR($A$6="(Todos)",INDEX(Temas!$B$5:$B$40,15)=$A$6),OR($B$6="(Todos)",INDEX(Temas!$C$5:$C$40,15)=$B$6)),INDEX(Temas!$T$5:$T$40,15)="Material — financeira"),N(INDEX(Temas!$P$5:$P$40,15)),NA()) -> #N/A | AE19: =IF(AND(AND(INDEX(Temas!$A$5:$A$40,15)<>"",OR($A$6="(Todos)",INDEX(Temas!$B$5:$B$40,15)=$A$6),OR($B$6="(Todos)",INDEX(Temas!$C$5:$C$40,15)=$B$6)),INDEX(Temas!$T$5:$T$40,15)="Não material"),N(INDEX(Temas!$P$5:$P$40,15)),NA()) -> 10
Z20: =IF(AND(INDEX(Temas!$A$5:$A$40,16)<>"",OR($A$6="(Todos)",INDEX(Temas!$B$5:$B$40,16)=$A$6),OR($B$6="(Todos)",INDEX(Temas!$C$5:$C$40,16)=$B$6)),INDEX(Temas!$A$5:$A$40,16),"") -> DM-16 | AA20: =IF(AND(INDEX(Temas!$A$5:$A$40,16)<>"",OR($A$6="(Todos)",INDEX(Temas!$B$5:$B$40,16)=$A$6),OR($B$6="(Todos)",INDEX(Temas!$C$5:$C$40,16)=$B$6)),N(INDEX(Temas!$Q$5:$Q$40,16)),NA()) -> 0 | AB20: =IF(AND(AND(INDEX(Temas!$A$5:$A$40,16)<>"",OR($A$6="(Todos)",INDEX(Temas!$B$5:$B$40,16)=$A$6),OR($B$6="(Todos)",INDEX(Temas!$C$5:$C$40,16)=$B$6)),INDEX(Temas!$T$5:$T$40,16)="Dupla materialidade"),N(INDEX(Temas!$P$5:$P$40,16)),NA()) -> #N/A | AC20: =IF(AND(AND(INDEX(Temas!$A$5:$A$40,16)<>"",OR($A$6="(Todos)",INDEX(Temas!$B$5:$B$40,16)=$A$6),OR($B$6="(Todos)",INDEX(Temas!$C$5:$C$40,16)=$B$6)),INDEX(Temas!$T$5:$T$40,16)="Material — impacto"),N(INDEX(Temas!$P$5:$P$40,16)),NA()) -> #N/A | AD20: =IF(AND(AND(INDEX(Temas!$A$5:$A$40,16)<>"",OR($A$6="(Todos)",INDEX(Temas!$B$5:$B$40,16)=$A$6),OR($B$6="(Todos)",INDEX(Temas!$C$5:$C$40,16)=$B$6)),INDEX(Temas!$T$5:$T$40,16)="Material — financeira"),N(INDEX(Temas!$P$5:$P$40,16)),NA()) -> #N/A | AE20: =IF(AND(AND(INDEX(Temas!$A$5:$A$40,16)<>"",OR($A$6="(Todos)",INDEX(Temas!$B$5:$B$40,16)=$A$6),OR($B$6="(Todos)",INDEX(Temas!$C$5:$C$40,16)=$B$6)),INDEX(Temas!$T$5:$T$40,16)="Não material"),N(INDEX(Temas!$P$5:$P$40,16)),NA()) -> 4
A21: GRÁFICO — MATRIZ DE DUPLA MATERIALIDADE POR TEMA (dinâmico com os filtros Pilar e Tópico; rótulo = ID do tema) | Z21: =IF(AND(INDEX(Temas!$A$5:$A$40,17)<>"",OR($A$6="(Todos)",INDEX(Temas!$B$5:$B$40,17)=$A$6),OR($B$6="(Todos)",INDEX(Temas!$C$5:$C$40,17)=$B$6)),INDEX(Temas!$A$5:$A$40,17),"") -> DM-17 | AA21: =IF(AND(INDEX(Temas!$A$5:$A$40,17)<>"",OR($A$6="(Todos)",INDEX(Temas!$B$5:$B$40,17)=$A$6),OR($B$6="(Todos)",INDEX(Temas!$C$5:$C$40,17)=$B$6)),N(INDEX(Temas!$Q$5:$Q$40,17)),NA()) -> 0 | AB21: =IF(AND(AND(INDEX(Temas!$A$5:$A$40,17)<>"",OR($A$6="(Todos)",INDEX(Temas!$B$5:$B$40,17)=$A$6),OR($B$6="(Todos)",INDEX(Temas!$C$5:$C$40,17)=$B$6)),INDEX(Temas!$T$5:$T$40,17)="Dupla materialidade"),N(INDEX(Temas!$P$5:$P$40,17)),NA()) -> #N/A | AC21: =IF(AND(AND(INDEX(Temas!$A$5:$A$40,17)<>"",OR($A$6="(Todos)",INDEX(Temas!$B$5:$B$40,17)=$A$6),OR($B$6="(Todos)",INDEX(Temas!$C$5:$C$40,17)=$B$6)),INDEX(Temas!$T$5:$T$40,17)="Material — impacto"),N(INDEX(Temas!$P$5:$P$40,17)),NA()) -> #N/A | AD21: =IF(AND(AND(INDEX(Temas!$A$5:$A$40,17)<>"",OR($A$6="(Todos)",INDEX(Temas!$B$5:$B$40,17)=$A$6),OR($B$6="(Todos)",INDEX(Temas!$C$5:$C$40,17)=$B$6)),INDEX(Temas!$T$5:$T$40,17)="Material — financeira"),N(INDEX(Temas!$P$5:$P$40,17)),NA()) -> #N/A | AE21: =IF(AND(AND(INDEX(Temas!$A$5:$A$40,17)<>"",OR($A$6="(Todos)",INDEX(Temas!$B$5:$B$40,17)=$A$6),OR($B$6="(Todos)",INDEX(Temas!$C$5:$C$40,17)=$B$6)),INDEX(Temas!$T$5:$T$40,17)="Não material"),N(INDEX(Temas!$P$5:$P$40,17)),NA()) -> 6.7
Z22: =IF(AND(INDEX(Temas!$A$5:$A$40,18)<>"",OR($A$6="(Todos)",INDEX(Temas!$B$5:$B$40,18)=$A$6),OR($B$6="(Todos)",INDEX(Temas!$C$5:$C$40,18)=$B$6)),INDEX(Temas!$A$5:$A$40,18),"") -> DM-18 | AA22: =IF(AND(INDEX(Temas!$A$5:$A$40,18)<>"",OR($A$6="(Todos)",INDEX(Temas!$B$5:$B$40,18)=$A$6),OR($B$6="(Todos)",INDEX(Temas!$C$5:$C$40,18)=$B$6)),N(INDEX(Temas!$Q$5:$Q$40,18)),NA()) -> 0 | AB22: =IF(AND(AND(INDEX(Temas!$A$5:$A$40,18)<>"",OR($A$6="(Todos)",INDEX(Temas!$B$5:$B$40,18)=$A$6),OR($B$6="(Todos)",INDEX(Temas!$C$5:$C$40,18)=$B$6)),INDEX(Temas!$T$5:$T$40,18)="Dupla materialidade"),N(INDEX(Temas!$P$5:$P$40,18)),NA()) -> #N/A | AC22: =IF(AND(AND(INDEX(Temas!$A$5:$A$40,18)<>"",OR($A$6="(Todos)",INDEX(Temas!$B$5:$B$40,18)=$A$6),OR($B$6="(Todos)",INDEX(Temas!$C$5:$C$40,18)=$B$6)),INDEX(Temas!$T$5:$T$40,18)="Material — impacto"),N(INDEX(Temas!$P$5:$P$40,18)),NA()) -> 12.5 | AD22: =IF(AND(AND(INDEX(Temas!$A$5:$A$40,18)<>"",OR($A$6="(Todos)",INDEX(Temas!$B$5:$B$40,18)=$A$6),OR($B$6="(Todos)",INDEX(Temas!$C$5:$C$40,18)=$B$6)),INDEX(Temas!$T$5:$T$40,18)="Material — financeira"),N(INDEX(Temas!$P$5:$P$40,18)),NA()) -> #N/A | AE22: =IF(AND(AND(INDEX(Temas!$A$5:$A$40,18)<>"",OR($A$6="(Todos)",INDEX(Temas!$B$5:$B$40,18)=$A$6),OR($B$6="(Todos)",INDEX(Temas!$C$5:$C$40,18)=$B$6)),INDEX(Temas!$T$5:$T$40,18)="Não material"),N(INDEX(Temas!$P$5:$P$40,18)),NA()) -> #N/A
Z23: =IF(AND(INDEX(Temas!$A$5:$A$40,19)<>"",OR($A$6="(Todos)",INDEX(Temas!$B$5:$B$40,19)=$A$6),OR($B$6="(Todos)",INDEX(Temas!$C$5:$C$40,19)=$B$6)),INDEX(Temas!$A$5:$A$40,19),"") -> DM-19 | AA23: =IF(AND(INDEX(Temas!$A$5:$A$40,19)<>"",OR($A$6="(Todos)",INDEX(Temas!$B$5:$B$40,19)=$A$6),OR($B$6="(Todos)",INDEX(Temas!$C$5:$C$40,19)=$B$6)),N(INDEX(Temas!$Q$5:$Q$40,19)),NA()) -> 15 | AB23: =IF(AND(AND(INDEX(Temas!$A$5:$A$40,19)<>"",OR($A$6="(Todos)",INDEX(Temas!$B$5:$B$40,19)=$A$6),OR($B$6="(Todos)",INDEX(Temas!$C$5:$C$40,19)=$B$6)),INDEX(Temas!$T$5:$T$40,19)="Dupla materialidade"),N(INDEX(Temas!$P$5:$P$40,19)),NA()) -> 20 | AC23: =IF(AND(AND(INDEX(Temas!$A$5:$A$40,19)<>"",OR($A$6="(Todos)",INDEX(Temas!$B$5:$B$40,19)=$A$6),OR($B$6="(Todos)",INDEX(Temas!$C$5:$C$40,19)=$B$6)),INDEX(Temas!$T$5:$T$40,19)="Material — impacto"),N(INDEX(Temas!$P$5:$P$40,19)),NA()) -> #N/A | AD23: =IF(AND(AND(INDEX(Temas!$A$5:$A$40,19)<>"",OR($A$6="(Todos)",INDEX(Temas!$B$5:$B$40,19)=$A$6),OR($B$6="(Todos)",INDEX(Temas!$C$5:$C$40,19)=$B$6)),INDEX(Temas!$T$5:$T$40,19)="Material — financeira"),N(INDEX(Temas!$P$5:$P$40,19)),NA()) -> #N/A | AE23: =IF(AND(AND(INDEX(Temas!$A$5:$A$40,19)<>"",OR($A$6="(Todos)",INDEX(Temas!$B$5:$B$40,19)=$A$6),OR($B$6="(Todos)",INDEX(Temas!$C$5:$C$40,19)=$B$6)),INDEX(Temas!$T$5:$T$40,19)="Não material"),N(INDEX(Temas!$P$5:$P$40,19)),NA()) -> #N/A
Z24: =IF(AND(INDEX(Temas!$A$5:$A$40,20)<>"",OR($A$6="(Todos)",INDEX(Temas!$B$5:$B$40,20)=$A$6),OR($B$6="(Todos)",INDEX(Temas!$C$5:$C$40,20)=$B$6)),INDEX(Temas!$A$5:$A$40,20),"") -> DM-20 | AA24: =IF(AND(INDEX(Temas!$A$5:$A$40,20)<>"",OR($A$6="(Todos)",INDEX(Temas!$B$5:$B$40,20)=$A$6),OR($B$6="(Todos)",INDEX(Temas!$C$5:$C$40,20)=$B$6)),N(INDEX(Temas!$Q$5:$Q$40,20)),NA()) -> 9 | AB24: =IF(AND(AND(INDEX(Temas!$A$5:$A$40,20)<>"",OR($A$6="(Todos)",INDEX(Temas!$B$5:$B$40,20)=$A$6),OR($B$6="(Todos)",INDEX(Temas!$C$5:$C$40,20)=$B$6)),INDEX(Temas!$T$5:$T$40,20)="Dupla materialidade"),N(INDEX(Temas!$P$5:$P$40,20)),NA()) -> #N/A | AC24: =IF(AND(AND(INDEX(Temas!$A$5:$A$40,20)<>"",OR($A$6="(Todos)",INDEX(Temas!$B$5:$B$40,20)=$A$6),OR($B$6="(Todos)",INDEX(Temas!$C$5:$C$40,20)=$B$6)),INDEX(Temas!$T$5:$T$40,20)="Material — impacto"),N(INDEX(Temas!$P$5:$P$40,20)),NA()) -> #N/A | AD24: =IF(AND(AND(INDEX(Temas!$A$5:$A$40,20)<>"",OR($A$6="(Todos)",INDEX(Temas!$B$5:$B$40,20)=$A$6),OR($B$6="(Todos)",INDEX(Temas!$C$5:$C$40,20)=$B$6)),INDEX(Temas!$T$5:$T$40,20)="Material — financeira"),N(INDEX(Temas!$P$5:$P$40,20)),NA()) -> #N/A | AE24: =IF(AND(AND(INDEX(Temas!$A$5:$A$40,20)<>"",OR($A$6="(Todos)",INDEX(Temas!$B$5:$B$40,20)=$A$6),OR($B$6="(Todos)",INDEX(Temas!$C$5:$C$40,20)=$B$6)),INDEX(Temas!$T$5:$T$40,20)="Não material"),N(INDEX(Temas!$P$5:$P$40,20)),NA()) -> 7
Z25: =IF(AND(INDEX(Temas!$A$5:$A$40,21)<>"",OR($A$6="(Todos)",INDEX(Temas!$B$5:$B$40,21)=$A$6),OR($B$6="(Todos)",INDEX(Temas!$C$5:$C$40,21)=$B$6)),INDEX(Temas!$A$5:$A$40,21),"") -> DM-21 | AA25: =IF(AND(INDEX(Temas!$A$5:$A$40,21)<>"",OR($A$6="(Todos)",INDEX(Temas!$B$5:$B$40,21)=$A$6),OR($B$6="(Todos)",INDEX(Temas!$C$5:$C$40,21)=$B$6)),N(INDEX(Temas!$Q$5:$Q$40,21)),NA()) -> 12 | AB25: =IF(AND(AND(INDEX(Temas!$A$5:$A$40,21)<>"",OR($A$6="(Todos)",INDEX(Temas!$B$5:$B$40,21)=$A$6),OR($B$6="(Todos)",INDEX(Temas!$C$5:$C$40,21)=$B$6)),INDEX(Temas!$T$5:$T$40,21)="Dupla materialidade"),N(INDEX(Temas!$P$5:$P$40,21)),NA()) -> #N/A | AC25: =IF(AND(AND(INDEX(Temas!$A$5:$A$40,21)<>"",OR($A$6="(Todos)",INDEX(Temas!$B$5:$B$40,21)=$A$6),OR($B$6="(Todos)",INDEX(Temas!$C$5:$C$40,21)=$B$6)),INDEX(Temas!$T$5:$T$40,21)="Material — impacto"),N(INDEX(Temas!$P$5:$P$40,21)),NA()) -> #N/A | AD25: =IF(AND(AND(INDEX(Temas!$A$5:$A$40,21)<>"",OR($A$6="(Todos)",INDEX(Temas!$B$5:$B$40,21)=$A$6),OR($B$6="(Todos)",INDEX(Temas!$C$5:$C$40,21)=$B$6)),INDEX(Temas!$T$5:$T$40,21)="Material — financeira"),N(INDEX(Temas!$P$5:$P$40,21)),NA()) -> 2 | AE25: =IF(AND(AND(INDEX(Temas!$A$5:$A$40,21)<>"",OR($A$6="(Todos)",INDEX(Temas!$B$5:$B$40,21)=$A$6),OR($B$6="(Todos)",INDEX(Temas!$C$5:$C$40,21)=$B$6)),INDEX(Temas!$T$5:$T$40,21)="Não material"),N(INDEX(Temas!$P$5:$P$40,21)),NA()) -> #N/A
Z26: =IF(AND(INDEX(Temas!$A$5:$A$40,22)<>"",OR($A$6="(Todos)",INDEX(Temas!$B$5:$B$40,22)=$A$6),OR($B$6="(Todos)",INDEX(Temas!$C$5:$C$40,22)=$B$6)),INDEX(Temas!$A$5:$A$40,22),"") -> DM-22 | AA26: =IF(AND(INDEX(Temas!$A$5:$A$40,22)<>"",OR($A$6="(Todos)",INDEX(Temas!$B$5:$B$40,22)=$A$6),OR($B$6="(Todos)",INDEX(Temas!$C$5:$C$40,22)=$B$6)),N(INDEX(Temas!$Q$5:$Q$40,22)),NA()) -> 12 | AB26: =IF(AND(AND(INDEX(Temas!$A$5:$A$40,22)<>"",OR($A$6="(Todos)",INDEX(Temas!$B$5:$B$40,22)=$A$6),OR($B$6="(Todos)",INDEX(Temas!$C$5:$C$40,22)=$B$6)),INDEX(Temas!$T$5:$T$40,22)="Dupla materialidade"),N(INDEX(Temas!$P$5:$P$40,22)),NA()) -> #N/A | AC26: =IF(AND(AND(INDEX(Temas!$A$5:$A$40,22)<>"",OR($A$6="(Todos)",INDEX(Temas!$B$5:$B$40,22)=$A$6),OR($B$6="(Todos)",INDEX(Temas!$C$5:$C$40,22)=$B$6)),INDEX(Temas!$T$5:$T$40,22)="Material — impacto"),N(INDEX(Temas!$P$5:$P$40,22)),NA()) -> #N/A | AD26: =IF(AND(AND(INDEX(Temas!$A$5:$A$40,22)<>"",OR($A$6="(Todos)",INDEX(Temas!$B$5:$B$40,22)=$A$6),OR($B$6="(Todos)",INDEX(Temas!$C$5:$C$40,22)=$B$6)),INDEX(Temas!$T$5:$T$40,22)="Material — financeira"),N(INDEX(Temas!$P$5:$P$40,22)),NA()) -> 7.5 | AE26: =IF(AND(AND(INDEX(Temas!$A$5:$A$40,22)<>"",OR($A$6="(Todos)",INDEX(Temas!$B$5:$B$40,22)=$A$6),OR($B$6="(Todos)",INDEX(Temas!$C$5:$C$40,22)=$B$6)),INDEX(Temas!$T$5:$T$40,22)="Não material"),N(INDEX(Temas!$P$5:$P$40,22)),NA()) -> #N/A
Z27: =IF(AND(INDEX(Temas!$A$5:$A$40,23)<>"",OR($A$6="(Todos)",INDEX(Temas!$B$5:$B$40,23)=$A$6),OR($B$6="(Todos)",INDEX(Temas!$C$5:$C$40,23)=$B$6)),INDEX(Temas!$A$5:$A$40,23),"") -> DM-23 | AA27: =IF(AND(INDEX(Temas!$A$5:$A$40,23)<>"",OR($A$6="(Todos)",INDEX(Temas!$B$5:$B$40,23)=$A$6),OR($B$6="(Todos)",INDEX(Temas!$C$5:$C$40,23)=$B$6)),N(INDEX(Temas!$Q$5:$Q$40,23)),NA()) -> 20 | AB27: =IF(AND(AND(INDEX(Temas!$A$5:$A$40,23)<>"",OR($A$6="(Todos)",INDEX(Temas!$B$5:$B$40,23)=$A$6),OR($B$6="(Todos)",INDEX(Temas!$C$5:$C$40,23)=$B$6)),INDEX(Temas!$T$5:$T$40,23)="Dupla materialidade"),N(INDEX(Temas!$P$5:$P$40,23)),NA()) -> #N/A | AC27: =IF(AND(AND(INDEX(Temas!$A$5:$A$40,23)<>"",OR($A$6="(Todos)",INDEX(Temas!$B$5:$B$40,23)=$A$6),OR($B$6="(Todos)",INDEX(Temas!$C$5:$C$40,23)=$B$6)),INDEX(Temas!$T$5:$T$40,23)="Material — impacto"),N(INDEX(Temas!$P$5:$P$40,23)),NA()) -> #N/A | AD27: =IF(AND(AND(INDEX(Temas!$A$5:$A$40,23)<>"",OR($A$6="(Todos)",INDEX(Temas!$B$5:$B$40,23)=$A$6),OR($B$6="(Todos)",INDEX(Temas!$C$5:$C$40,23)=$B$6)),INDEX(Temas!$T$5:$T$40,23)="Material — financeira"),N(INDEX(Temas!$P$5:$P$40,23)),NA()) -> 10 | AE27: =IF(AND(AND(INDEX(Temas!$A$5:$A$40,23)<>"",OR($A$6="(Todos)",INDEX(Temas!$B$5:$B$40,23)=$A$6),OR($B$6="(Todos)",INDEX(Temas!$C$5:$C$40,23)=$B$6)),INDEX(Temas!$T$5:$T$40,23)="Não material"),N(INDEX(Temas!$P$5:$P$40,23)),NA()) -> #N/A
Z28: =IF(AND(INDEX(Temas!$A$5:$A$40,24)<>"",OR($A$6="(Todos)",INDEX(Temas!$B$5:$B$40,24)=$A$6),OR($B$6="(Todos)",INDEX(Temas!$C$5:$C$40,24)=$B$6)),INDEX(Temas!$A$5:$A$40,24),"") -> DM-24 | AA28: =IF(AND(INDEX(Temas!$A$5:$A$40,24)<>"",OR($A$6="(Todos)",INDEX(Temas!$B$5:$B$40,24)=$A$6),OR($B$6="(Todos)",INDEX(Temas!$C$5:$C$40,24)=$B$6)),N(INDEX(Temas!$Q$5:$Q$40,24)),NA()) -> 12 | AB28: =IF(AND(AND(INDEX(Temas!$A$5:$A$40,24)<>"",OR($A$6="(Todos)",INDEX(Temas!$B$5:$B$40,24)=$A$6),OR($B$6="(Todos)",INDEX(Temas!$C$5:$C$40,24)=$B$6)),INDEX(Temas!$T$5:$T$40,24)="Dupla materialidade"),N(INDEX(Temas!$P$5:$P$40,24)),NA()) -> #N/A | AC28: =IF(AND(AND(INDEX(Temas!$A$5:$A$40,24)<>"",OR($A$6="(Todos)",INDEX(Temas!$B$5:$B$40,24)=$A$6),OR($B$6="(Todos)",INDEX(Temas!$C$5:$C$40,24)=$B$6)),INDEX(Temas!$T$5:$T$40,24)="Material — impacto"),N(INDEX(Temas!$P$5:$P$40,24)),NA()) -> #N/A | AD28: =IF(AND(AND(INDEX(Temas!$A$5:$A$40,24)<>"",OR($A$6="(Todos)",INDEX(Temas!$B$5:$B$40,24)=$A$6),OR($B$6="(Todos)",INDEX(Temas!$C$5:$C$40,24)=$B$6)),INDEX(Temas!$T$5:$T$40,24)="Material — financeira"),N(INDEX(Temas!$P$5:$P$40,24)),NA()) -> 0 | AE28: =IF(AND(AND(INDEX(Temas!$A$5:$A$40,24)<>"",OR($A$6="(Todos)",INDEX(Temas!$B$5:$B$40,24)=$A$6),OR($B$6="(Todos)",INDEX(Temas!$C$5:$C$40,24)=$B$6)),INDEX(Temas!$T$5:$T$40,24)="Não material"),N(INDEX(Temas!$P$5:$P$40,24)),NA()) -> #N/A
Z29: =IF(AND(INDEX(Temas!$A$5:$A$40,25)<>"",OR($A$6="(Todos)",INDEX(Temas!$B$5:$B$40,25)=$A$6),OR($B$6="(Todos)",INDEX(Temas!$C$5:$C$40,25)=$B$6)),INDEX(Temas!$A$5:$A$40,25),"") | AA29: =IF(AND(INDEX(Temas!$A$5:$A$40,25)<>"",OR($A$6="(Todos)",INDEX(Temas!$B$5:$B$40,25)=$A$6),OR($B$6="(Todos)",INDEX(Temas!$C$5:$C$40,25)=$B$6)),N(INDEX(Temas!$Q$5:$Q$40,25)),NA()) -> #N/A | AB29: =IF(AND(AND(INDEX(Temas!$A$5:$A$40,25)<>"",OR($A$6="(Todos)",INDEX(Temas!$B$5:$B$40,25)=$A$6),OR($B$6="(Todos)",INDEX(Temas!$C$5:$C$40,25)=$B$6)),INDEX(Temas!$T$5:$T$40,25)="Dupla materialidade"),N(INDEX(Temas!$P$5:$P$40,25)),NA()) -> #N/A | AC29: =IF(AND(AND(INDEX(Temas!$A$5:$A$40,25)<>"",OR($A$6="(Todos)",INDEX(Temas!$B$5:$B$40,25)=$A$6),OR($B$6="(Todos)",INDEX(Temas!$C$5:$C$40,25)=$B$6)),INDEX(Temas!$T$5:$T$40,25)="Material — impacto"),N(INDEX(Temas!$P$5:$P$40,25)),NA()) -> #N/A | AD29: =IF(AND(AND(INDEX(Temas!$A$5:$A$40,25)<>"",OR($A$6="(Todos)",INDEX(Temas!$B$5:$B$40,25)=$A$6),OR($B$6="(Todos)",INDEX(Temas!$C$5:$C$40,25)=$B$6)),INDEX(Temas!$T$5:$T$40,25)="Material — financeira"),N(INDEX(Temas!$P$5:$P$40,25)),NA()) -> #N/A | AE29: =IF(AND(AND(INDEX(Temas!$A$5:$A$40,25)<>"",OR($A$6="(Todos)",INDEX(Temas!$B$5:$B$40,25)=$A$6),OR($B$6="(Todos)",INDEX(Temas!$C$5:$C$40,25)=$B$6)),INDEX(Temas!$T$5:$T$40,25)="Não material"),N(INDEX(Temas!$P$5:$P$40,25)),NA()) -> #N/A
Z30: =IF(AND(INDEX(Temas!$A$5:$A$40,26)<>"",OR($A$6="(Todos)",INDEX(Temas!$B$5:$B$40,26)=$A$6),OR($B$6="(Todos)",INDEX(Temas!$C$5:$C$40,26)=$B$6)),INDEX(Temas!$A$5:$A$40,26),"") | AA30: =IF(AND(INDEX(Temas!$A$5:$A$40,26)<>"",OR($A$6="(Todos)",INDEX(Temas!$B$5:$B$40,26)=$A$6),OR($B$6="(Todos)",INDEX(Temas!$C$5:$C$40,26)=$B$6)),N(INDEX(Temas!$Q$5:$Q$40,26)),NA()) -> #N/A | AB30: =IF(AND(AND(INDEX(Temas!$A$5:$A$40,26)<>"",OR($A$6="(Todos)",INDEX(Temas!$B$5:$B$40,26)=$A$6),OR($B$6="(Todos)",INDEX(Temas!$C$5:$C$40,26)=$B$6)),INDEX(Temas!$T$5:$T$40,26)="Dupla materialidade"),N(INDEX(Temas!$P$5:$P$40,26)),NA()) -> #N/A | AC30: =IF(AND(AND(INDEX(Temas!$A$5:$A$40,26)<>"",OR($A$6="(Todos)",INDEX(Temas!$B$5:$B$40,26)=$A$6),OR($B$6="(Todos)",INDEX(Temas!$C$5:$C$40,26)=$B$6)),INDEX(Temas!$T$5:$T$40,26)="Material — impacto"),N(INDEX(Temas!$P$5:$P$40,26)),NA()) -> #N/A | AD30: =IF(AND(AND(INDEX(Temas!$A$5:$A$40,26)<>"",OR($A$6="(Todos)",INDEX(Temas!$B$5:$B$40,26)=$A$6),OR($B$6="(Todos)",INDEX(Temas!$C$5:$C$40,26)=$B$6)),INDEX(Temas!$T$5:$T$40,26)="Material — financeira"),N(INDEX(Temas!$P$5:$P$40,26)),NA()) -> #N/A | AE30: =IF(AND(AND(INDEX(Temas!$A$5:$A$40,26)<>"",OR($A$6="(Todos)",INDEX(Temas!$B$5:$B$40,26)=$A$6),OR($B$6="(Todos)",INDEX(Temas!$C$5:$C$40,26)=$B$6)),INDEX(Temas!$T$5:$T$40,26)="Não material"),N(INDEX(Temas!$P$5:$P$40,26)),NA()) -> #N/A
Z31: =IF(AND(INDEX(Temas!$A$5:$A$40,27)<>"",OR($A$6="(Todos)",INDEX(Temas!$B$5:$B$40,27)=$A$6),OR($B$6="(Todos)",INDEX(Temas!$C$5:$C$40,27)=$B$6)),INDEX(Temas!$A$5:$A$40,27),"") | AA31: =IF(AND(INDEX(Temas!$A$5:$A$40,27)<>"",OR($A$6="(Todos)",INDEX(Temas!$B$5:$B$40,27)=$A$6),OR($B$6="(Todos)",INDEX(Temas!$C$5:$C$40,27)=$B$6)),N(INDEX(Temas!$Q$5:$Q$40,27)),NA()) -> #N/A | AB31: =IF(AND(AND(INDEX(Temas!$A$5:$A$40,27)<>"",OR($A$6="(Todos)",INDEX(Temas!$B$5:$B$40,27)=$A$6),OR($B$6="(Todos)",INDEX(Temas!$C$5:$C$40,27)=$B$6)),INDEX(Temas!$T$5:$T$40,27)="Dupla materialidade"),N(INDEX(Temas!$P$5:$P$40,27)),NA()) -> #N/A | AC31: =IF(AND(AND(INDEX(Temas!$A$5:$A$40,27)<>"",OR($A$6="(Todos)",INDEX(Temas!$B$5:$B$40,27)=$A$6),OR($B$6="(Todos)",INDEX(Temas!$C$5:$C$40,27)=$B$6)),INDEX(Temas!$T$5:$T$40,27)="Material — impacto"),N(INDEX(Temas!$P$5:$P$40,27)),NA()) -> #N/A | AD31: =IF(AND(AND(INDEX(Temas!$A$5:$A$40,27)<>"",OR($A$6="(Todos)",INDEX(Temas!$B$5:$B$40,27)=$A$6),OR($B$6="(Todos)",INDEX(Temas!$C$5:$C$40,27)=$B$6)),INDEX(Temas!$T$5:$T$40,27)="Material — financeira"),N(INDEX(Temas!$P$5:$P$40,27)),NA()) -> #N/A | AE31: =IF(AND(AND(INDEX(Temas!$A$5:$A$40,27)<>"",OR($A$6="(Todos)",INDEX(Temas!$B$5:$B$40,27)=$A$6),OR($B$6="(Todos)",INDEX(Temas!$C$5:$C$40,27)=$B$6)),INDEX(Temas!$T$5:$T$40,27)="Não material"),N(INDEX(Temas!$P$5:$P$40,27)),NA()) -> #N/A
Z32: =IF(AND(INDEX(Temas!$A$5:$A$40,28)<>"",OR($A$6="(Todos)",INDEX(Temas!$B$5:$B$40,28)=$A$6),OR($B$6="(Todos)",INDEX(Temas!$C$5:$C$40,28)=$B$6)),INDEX(Temas!$A$5:$A$40,28),"") | AA32: =IF(AND(INDEX(Temas!$A$5:$A$40,28)<>"",OR($A$6="(Todos)",INDEX(Temas!$B$5:$B$40,28)=$A$6),OR($B$6="(Todos)",INDEX(Temas!$C$5:$C$40,28)=$B$6)),N(INDEX(Temas!$Q$5:$Q$40,28)),NA()) -> #N/A | AB32: =IF(AND(AND(INDEX(Temas!$A$5:$A$40,28)<>"",OR($A$6="(Todos)",INDEX(Temas!$B$5:$B$40,28)=$A$6),OR($B$6="(Todos)",INDEX(Temas!$C$5:$C$40,28)=$B$6)),INDEX(Temas!$T$5:$T$40,28)="Dupla materialidade"),N(INDEX(Temas!$P$5:$P$40,28)),NA()) -> #N/A | AC32: =IF(AND(AND(INDEX(Temas!$A$5:$A$40,28)<>"",OR($A$6="(Todos)",INDEX(Temas!$B$5:$B$40,28)=$A$6),OR($B$6="(Todos)",INDEX(Temas!$C$5:$C$40,28)=$B$6)),INDEX(Temas!$T$5:$T$40,28)="Material — impacto"),N(INDEX(Temas!$P$5:$P$40,28)),NA()) -> #N/A | AD32: =IF(AND(AND(INDEX(Temas!$A$5:$A$40,28)<>"",OR($A$6="(Todos)",INDEX(Temas!$B$5:$B$40,28)=$A$6),OR($B$6="(Todos)",INDEX(Temas!$C$5:$C$40,28)=$B$6)),INDEX(Temas!$T$5:$T$40,28)="Material — financeira"),N(INDEX(Temas!$P$5:$P$40,28)),NA()) -> #N/A | AE32: =IF(AND(AND(INDEX(Temas!$A$5:$A$40,28)<>"",OR($A$6="(Todos)",INDEX(Temas!$B$5:$B$40,28)=$A$6),OR($B$6="(Todos)",INDEX(Temas!$C$5:$C$40,28)=$B$6)),INDEX(Temas!$T$5:$T$40,28)="Não material"),N(INDEX(Temas!$P$5:$P$40,28)),NA()) -> #N/A
Z33: =IF(AND(INDEX(Temas!$A$5:$A$40,29)<>"",OR($A$6="(Todos)",INDEX(Temas!$B$5:$B$40,29)=$A$6),OR($B$6="(Todos)",INDEX(Temas!$C$5:$C$40,29)=$B$6)),INDEX(Temas!$A$5:$A$40,29),"") | AA33: =IF(AND(INDEX(Temas!$A$5:$A$40,29)<>"",OR($A$6="(Todos)",INDEX(Temas!$B$5:$B$40,29)=$A$6),OR($B$6="(Todos)",INDEX(Temas!$C$5:$C$40,29)=$B$6)),N(INDEX(Temas!$Q$5:$Q$40,29)),NA()) -> #N/A | AB33: =IF(AND(AND(INDEX(Temas!$A$5:$A$40,29)<>"",OR($A$6="(Todos)",INDEX(Temas!$B$5:$B$40,29)=$A$6),OR($B$6="(Todos)",INDEX(Temas!$C$5:$C$40,29)=$B$6)),INDEX(Temas!$T$5:$T$40,29)="Dupla materialidade"),N(INDEX(Temas!$P$5:$P$40,29)),NA()) -> #N/A | AC33: =IF(AND(AND(INDEX(Temas!$A$5:$A$40,29)<>"",OR($A$6="(Todos)",INDEX(Temas!$B$5:$B$40,29)=$A$6),OR($B$6="(Todos)",INDEX(Temas!$C$5:$C$40,29)=$B$6)),INDEX(Temas!$T$5:$T$40,29)="Material — impacto"),N(INDEX(Temas!$P$5:$P$40,29)),NA()) -> #N/A | AD33: =IF(AND(AND(INDEX(Temas!$A$5:$A$40,29)<>"",OR($A$6="(Todos)",INDEX(Temas!$B$5:$B$40,29)=$A$6),OR($B$6="(Todos)",INDEX(Temas!$C$5:$C$40,29)=$B$6)),INDEX(Temas!$T$5:$T$40,29)="Material — financeira"),N(INDEX(Temas!$P$5:$P$40,29)),NA()) -> #N/A | AE33: =IF(AND(AND(INDEX(Temas!$A$5:$A$40,29)<>"",OR($A$6="(Todos)",INDEX(Temas!$B$5:$B$40,29)=$A$6),OR($B$6="(Todos)",INDEX(Temas!$C$5:$C$40,29)=$B$6)),INDEX(Temas!$T$5:$T$40,29)="Não material"),N(INDEX(Temas!$P$5:$P$40,29)),NA()) -> #N/A
Z34: =IF(AND(INDEX(Temas!$A$5:$A$40,30)<>"",OR($A$6="(Todos)",INDEX(Temas!$B$5:$B$40,30)=$A$6),OR($B$6="(Todos)",INDEX(Temas!$C$5:$C$40,30)=$B$6)),INDEX(Temas!$A$5:$A$40,30),"") | AA34: =IF(AND(INDEX(Temas!$A$5:$A$40,30)<>"",OR($A$6="(Todos)",INDEX(Temas!$B$5:$B$40,30)=$A$6),OR($B$6="(Todos)",INDEX(Temas!$C$5:$C$40,30)=$B$6)),N(INDEX(Temas!$Q$5:$Q$40,30)),NA()) -> #N/A | AB34: =IF(AND(AND(INDEX(Temas!$A$5:$A$40,30)<>"",OR($A$6="(Todos)",INDEX(Temas!$B$5:$B$40,30)=$A$6),OR($B$6="(Todos)",INDEX(Temas!$C$5:$C$40,30)=$B$6)),INDEX(Temas!$T$5:$T$40,30)="Dupla materialidade"),N(INDEX(Temas!$P$5:$P$40,30)),NA()) -> #N/A | AC34: =IF(AND(AND(INDEX(Temas!$A$5:$A$40,30)<>"",OR($A$6="(Todos)",INDEX(Temas!$B$5:$B$40,30)=$A$6),OR($B$6="(Todos)",INDEX(Temas!$C$5:$C$40,30)=$B$6)),INDEX(Temas!$T$5:$T$40,30)="Material — impacto"),N(INDEX(Temas!$P$5:$P$40,30)),NA()) -> #N/A | AD34: =IF(AND(AND(INDEX(Temas!$A$5:$A$40,30)<>"",OR($A$6="(Todos)",INDEX(Temas!$B$5:$B$40,30)=$A$6),OR($B$6="(Todos)",INDEX(Temas!$C$5:$C$40,30)=$B$6)),INDEX(Temas!$T$5:$T$40,30)="Material — financeira"),N(INDEX(Temas!$P$5:$P$40,30)),NA()) -> #N/A | AE34: =IF(AND(AND(INDEX(Temas!$A$5:$A$40,30)<>"",OR($A$6="(Todos)",INDEX(Temas!$B$5:$B$40,30)=$A$6),OR($B$6="(Todos)",INDEX(Temas!$C$5:$C$40,30)=$B$6)),INDEX(Temas!$T$5:$T$40,30)="Não material"),N(INDEX(Temas!$P$5:$P$40,30)),NA()) -> #N/A
Z35: =IF(AND(INDEX(Temas!$A$5:$A$40,31)<>"",OR($A$6="(Todos)",INDEX(Temas!$B$5:$B$40,31)=$A$6),OR($B$6="(Todos)",INDEX(Temas!$C$5:$C$40,31)=$B$6)),INDEX(Temas!$A$5:$A$40,31),"") | AA35: =IF(AND(INDEX(Temas!$A$5:$A$40,31)<>"",OR($A$6="(Todos)",INDEX(Temas!$B$5:$B$40,31)=$A$6),OR($B$6="(Todos)",INDEX(Temas!$C$5:$C$40,31)=$B$6)),N(INDEX(Temas!$Q$5:$Q$40,31)),NA()) -> #N/A | AB35: =IF(AND(AND(INDEX(Temas!$A$5:$A$40,31)<>"",OR($A$6="(Todos)",INDEX(Temas!$B$5:$B$40,31)=$A$6),OR($B$6="(Todos)",INDEX(Temas!$C$5:$C$40,31)=$B$6)),INDEX(Temas!$T$5:$T$40,31)="Dupla materialidade"),N(INDEX(Temas!$P$5:$P$40,31)),NA()) -> #N/A | AC35: =IF(AND(AND(INDEX(Temas!$A$5:$A$40,31)<>"",OR($A$6="(Todos)",INDEX(Temas!$B$5:$B$40,31)=$A$6),OR($B$6="(Todos)",INDEX(Temas!$C$5:$C$40,31)=$B$6)),INDEX(Temas!$T$5:$T$40,31)="Material — impacto"),N(INDEX(Temas!$P$5:$P$40,31)),NA()) -> #N/A | AD35: =IF(AND(AND(INDEX(Temas!$A$5:$A$40,31)<>"",OR($A$6="(Todos)",INDEX(Temas!$B$5:$B$40,31)=$A$6),OR($B$6="(Todos)",INDEX(Temas!$C$5:$C$40,31)=$B$6)),INDEX(Temas!$T$5:$T$40,31)="Material — financeira"),N(INDEX(Temas!$P$5:$P$40,31)),NA()) -> #N/A | AE35: =IF(AND(AND(INDEX(Temas!$A$5:$A$40,31)<>"",OR($A$6="(Todos)",INDEX(Temas!$B$5:$B$40,31)=$A$6),OR($B$6="(Todos)",INDEX(Temas!$C$5:$C$40,31)=$B$6)),INDEX(Temas!$T$5:$T$40,31)="Não material"),N(INDEX(Temas!$P$5:$P$40,31)),NA()) -> #N/A
Z36: =IF(AND(INDEX(Temas!$A$5:$A$40,32)<>"",OR($A$6="(Todos)",INDEX(Temas!$B$5:$B$40,32)=$A$6),OR($B$6="(Todos)",INDEX(Temas!$C$5:$C$40,32)=$B$6)),INDEX(Temas!$A$5:$A$40,32),"") | AA36: =IF(AND(INDEX(Temas!$A$5:$A$40,32)<>"",OR($A$6="(Todos)",INDEX(Temas!$B$5:$B$40,32)=$A$6),OR($B$6="(Todos)",INDEX(Temas!$C$5:$C$40,32)=$B$6)),N(INDEX(Temas!$Q$5:$Q$40,32)),NA()) -> #N/A | AB36: =IF(AND(AND(INDEX(Temas!$A$5:$A$40,32)<>"",OR($A$6="(Todos)",INDEX(Temas!$B$5:$B$40,32)=$A$6),OR($B$6="(Todos)",INDEX(Temas!$C$5:$C$40,32)=$B$6)),INDEX(Temas!$T$5:$T$40,32)="Dupla materialidade"),N(INDEX(Temas!$P$5:$P$40,32)),NA()) -> #N/A | AC36: =IF(AND(AND(INDEX(Temas!$A$5:$A$40,32)<>"",OR($A$6="(Todos)",INDEX(Temas!$B$5:$B$40,32)=$A$6),OR($B$6="(Todos)",INDEX(Temas!$C$5:$C$40,32)=$B$6)),INDEX(Temas!$T$5:$T$40,32)="Material — impacto"),N(INDEX(Temas!$P$5:$P$40,32)),NA()) -> #N/A | AD36: =IF(AND(AND(INDEX(Temas!$A$5:$A$40,32)<>"",OR($A$6="(Todos)",INDEX(Temas!$B$5:$B$40,32)=$A$6),OR($B$6="(Todos)",INDEX(Temas!$C$5:$C$40,32)=$B$6)),INDEX(Temas!$T$5:$T$40,32)="Material — financeira"),N(INDEX(Temas!$P$5:$P$40,32)),NA()) -> #N/A | AE36: =IF(AND(AND(INDEX(Temas!$A$5:$A$40,32)<>"",OR($A$6="(Todos)",INDEX(Temas!$B$5:$B$40,32)=$A$6),OR($B$6="(Todos)",INDEX(Temas!$C$5:$C$40,32)=$B$6)),INDEX(Temas!$T$5:$T$40,32)="Não material"),N(INDEX(Temas!$P$5:$P$40,32)),NA()) -> #N/A
Z37: =IF(AND(INDEX(Temas!$A$5:$A$40,33)<>"",OR($A$6="(Todos)",INDEX(Temas!$B$5:$B$40,33)=$A$6),OR($B$6="(Todos)",INDEX(Temas!$C$5:$C$40,33)=$B$6)),INDEX(Temas!$A$5:$A$40,33),"") | AA37: =IF(AND(INDEX(Temas!$A$5:$A$40,33)<>"",OR($A$6="(Todos)",INDEX(Temas!$B$5:$B$40,33)=$A$6),OR($B$6="(Todos)",INDEX(Temas!$C$5:$C$40,33)=$B$6)),N(INDEX(Temas!$Q$5:$Q$40,33)),NA()) -> #N/A | AB37: =IF(AND(AND(INDEX(Temas!$A$5:$A$40,33)<>"",OR($A$6="(Todos)",INDEX(Temas!$B$5:$B$40,33)=$A$6),OR($B$6="(Todos)",INDEX(Temas!$C$5:$C$40,33)=$B$6)),INDEX(Temas!$T$5:$T$40,33)="Dupla materialidade"),N(INDEX(Temas!$P$5:$P$40,33)),NA()) -> #N/A | AC37: =IF(AND(AND(INDEX(Temas!$A$5:$A$40,33)<>"",OR($A$6="(Todos)",INDEX(Temas!$B$5:$B$40,33)=$A$6),OR($B$6="(Todos)",INDEX(Temas!$C$5:$C$40,33)=$B$6)),INDEX(Temas!$T$5:$T$40,33)="Material — impacto"),N(INDEX(Temas!$P$5:$P$40,33)),NA()) -> #N/A | AD37: =IF(AND(AND(INDEX(Temas!$A$5:$A$40,33)<>"",OR($A$6="(Todos)",INDEX(Temas!$B$5:$B$40,33)=$A$6),OR($B$6="(Todos)",INDEX(Temas!$C$5:$C$40,33)=$B$6)),INDEX(Temas!$T$5:$T$40,33)="Material — financeira"),N(INDEX(Temas!$P$5:$P$40,33)),NA()) -> #N/A | AE37: =IF(AND(AND(INDEX(Temas!$A$5:$A$40,33)<>"",OR($A$6="(Todos)",INDEX(Temas!$B$5:$B$40,33)=$A$6),OR($B$6="(Todos)",INDEX(Temas!$C$5:$C$40,33)=$B$6)),INDEX(Temas!$T$5:$T$40,33)="Não material"),N(INDEX(Temas!$P$5:$P$40,33)),NA()) -> #N/A
Z38: =IF(AND(INDEX(Temas!$A$5:$A$40,34)<>"",OR($A$6="(Todos)",INDEX(Temas!$B$5:$B$40,34)=$A$6),OR($B$6="(Todos)",INDEX(Temas!$C$5:$C$40,34)=$B$6)),INDEX(Temas!$A$5:$A$40,34),"") | AA38: =IF(AND(INDEX(Temas!$A$5:$A$40,34)<>"",OR($A$6="(Todos)",INDEX(Temas!$B$5:$B$40,34)=$A$6),OR($B$6="(Todos)",INDEX(Temas!$C$5:$C$40,34)=$B$6)),N(INDEX(Temas!$Q$5:$Q$40,34)),NA()) -> #N/A | AB38: =IF(AND(AND(INDEX(Temas!$A$5:$A$40,34)<>"",OR($A$6="(Todos)",INDEX(Temas!$B$5:$B$40,34)=$A$6),OR($B$6="(Todos)",INDEX(Temas!$C$5:$C$40,34)=$B$6)),INDEX(Temas!$T$5:$T$40,34)="Dupla materialidade"),N(INDEX(Temas!$P$5:$P$40,34)),NA()) -> #N/A | AC38: =IF(AND(AND(INDEX(Temas!$A$5:$A$40,34)<>"",OR($A$6="(Todos)",INDEX(Temas!$B$5:$B$40,34)=$A$6),OR($B$6="(Todos)",INDEX(Temas!$C$5:$C$40,34)=$B$6)),INDEX(Temas!$T$5:$T$40,34)="Material — impacto"),N(INDEX(Temas!$P$5:$P$40,34)),NA()) -> #N/A | AD38: =IF(AND(AND(INDEX(Temas!$A$5:$A$40,34)<>"",OR($A$6="(Todos)",INDEX(Temas!$B$5:$B$40,34)=$A$6),OR($B$6="(Todos)",INDEX(Temas!$C$5:$C$40,34)=$B$6)),INDEX(Temas!$T$5:$T$40,34)="Material — financeira"),N(INDEX(Temas!$P$5:$P$40,34)),NA()) -> #N/A | AE38: =IF(AND(AND(INDEX(Temas!$A$5:$A$40,34)<>"",OR($A$6="(Todos)",INDEX(Temas!$B$5:$B$40,34)=$A$6),OR($B$6="(Todos)",INDEX(Temas!$C$5:$C$40,34)=$B$6)),INDEX(Temas!$T$5:$T$40,34)="Não material"),N(INDEX(Temas!$P$5:$P$40,34)),NA()) -> #N/A
