Workbook
Name DataRef: Listas!$A$3
Name lst_CE_Estado: Listas!$K$3:$K$5
Name lst_CE_Sentido: Listas!$I$3:$I$4
Name lst_CE_Tipo: Listas!$J$3:$J$9
Name lst_DataReferencia: Listas!$A$3:$A$3
Name lst_EstadoDoc: Listas!$E$3:$E$5
Name lst_Funcao: Listas!$C$3:$C$24
Name lst_OKNOK: Listas!$F$3:$F$4
Name lst_Processo: Listas!$H$3:$H$18
Name lst_SimNao: Listas!$G$3:$G$4
Name lst_Tipo: Listas!$B$3:$B$4
Name lst_TipoDoc: Listas!$D$3:$D$8

Sheet 00_LEIA-ME
A1: RG-SGA-09 — Comunicação Ambiental e Controlo da Informação Documentada
A2: Sistema de Gestão Ambiental NP EN ISO 14001:2026 · Plasticom — Unidade 1 (Marinha Grande, Portugal) · Registo do SGA (fábrica simulada)
A4: CONTROLO DO DOCUMENTO (7.5 — informação documentada)
A5: Código do registo | B5: RG-SGA-09
A6: Título | B6: Comunicação Ambiental e Controlo da Informação Documentada
A7: Versão / Revisão | B7: 01
A8: Data de emissão | B8: 46387
A9: Elaborado por | B9: Gestor(a) do SGA / EHS
A10: Aprovado por | B10: Diretor Geral
A11: Estado | B11: Em vigor
A12: Retenção | B12: 5 anos após substituição
A13: Localização | B13: Repositório controlado do SGA > Registos_SGA_Plasticom (versão eletrónica é a versão controlada; cópias impressas são não controladas)
A15: FINALIDADE E ÂMBITO
A16: Finalidade | B16: Planear as comunicações internas e externas pela regra dos 4 Q (O quê, A quem, Quando, Como) e medir o alcance; manter a lista mestra de documentos com estado (em vigor, obsoleto, em revisão) e registar verificações documentais no terreno com os elementos obrigatórios de controlo.
A17: Atividades do curso | B17: Atividade 4.2 — Planeamento da Comunicação (4 Q's, cenário COM-01: divulgar a nova Política Ambiental) e Controlo Documental (3 elementos obrigatórios). A reflexão 'Documento obsoleto vs em vigor' está no documento Word.
A18: Requisitos ISO 14001:2026 | B18: 7.4 Comunicação (ISO 14001:2026: permitir que os trabalhadores contribuam para a melhoria contínua); 7.5 Informação documentada (disponível / retida)
A20: ESTRUTURA DO FICHEIRO
A21: Matriz_Comunicacao | B21: Matriz de comunicação (regra dos 4 Q + porquê, responsável, evidência e alcance).
A22: Lista_Mestra | B22: Lista mestra de documentos e registos do SGA (estado, versão, aprovação, revisão).
A23: Elementos_Controlo | B23: Elementos obrigatórios de controlo documental (checklist).
A24: Verificacao_Documental | B24: Resultados de verificações documentais no terreno (formato longo: documento × elemento).
A25: Resumo_Atividade_4_2 | B25: Ficha da Atividade 4.2: os 4 Q do cenário COM-01 e os 3 elementos obrigatórios de controlo documental (calculado).
A26: Comunicacoes_Externas | B26: Registo de comunicações externas recebidas e enviadas (reclamações, pedidos, relatórios legais, questionários ESG) — 7.4.3.
A27: Listas | B27: Domínios (listas de valores) usados na validação de dados das tabelas.
A28: Dicionario_Dados | B28: Descrição de cada coluna de cada tabela: tipo, origem (entrada/calculado), domínio, obrigatoriedade e chaves.
A30: CONVENÇÕES (prontas para análise de dados e machine learning)
A31: Tabelas | B31: Cada registo é uma Tabela Excel com nome próprio (tbl_*): uma linha = um registo, cabeçalho único, sem células mescladas. Ler com pandas (pd.read_excel(ficheiro, sheet_name=folha, header=<linha do cabeçalho - 1>)) ou Power BI (Obter Dados > Tabela).
A32: Cabeçalho cinzento | B32: Coluna CALCULADA por fórmula — não escrever por cima. As restantes colunas são de entrada.
A33: Validação | B33: Colunas com lista controlada só aceitam valores da folha Listas (evita categorias duplicadas por grafia diferente).
A34: Chaves | B34: IDs estáveis e únicos (PK) e referências a IDs de outros registos (FK) permitem juntar tabelas entre ficheiros — ver SGA-00_Indice_Modelo_Dados.xlsx.
A35: Datas e unidades | B35: Datas em formato data (aaaa-mm-dd); números como números; a unidade está no nome da coluna ou no dicionário. Data de referência do SGA: 2026-12-31 (fecho do ano).
A36: Dados simulados | B36: Fábrica simulada Plasticom. Dados operacionais derivados do dataset do projeto (datasets/silver); dados ambientais e de conformidade são simulação didática — confirmar aplicabilidade legal e números antes de uso real.
A38: LIGAÇÕES A OUTROS REGISTOS
A39: RG-SGA-16 Kaizen | B39: COM-08 alimenta a caixa de sugestões.
A40: RG-SGA-07 NC | B40: Verificações NOK podem originar NC.

Sheet Matriz_Comunicacao
A1: MATRIZ DE COMUNICAÇÃO AMBIENTAL — REGRA DOS 4 Q
A2: O quê? · A quem? · Quando? · Como? — mais Porquê, Responsável, Evidência e Alcance (calculado)
A4: ID_Comunicacao | B4: Tipo | C4: Cenario | D4: O_Que_Mensagem | E4: A_Quem_Publico | F4: Quando_Momento | G4: Como_Canal | H4: Porque_Objetivo | I4: Responsavel | J4: Clausula | K4: Participacao_Feedback | L4: Evidencia | M4: Data_Prevista | N4: Data_Realizada | O4: Alcance_Previsto | P4: Alcance_Real | Q4: Taxa_Alcance | R4: Estado | S4: Selecionado_Atv_4_2
A5: COM-01 | B5: Interna | C5: Divulgar a nova Política Ambiental (rev. 02, 2026) | D5: O que muda na Política Ambiental rev. 02: 7 compromissos (incluindo perdas de granulado, biodiversidade e ciclo de vida) e o que cada trabalhador pode fazer no seu posto. | E5: Todos os trabalhadores dos 3 turnos, temporários e prestadores de serviços residentes (≈ 160 pessoas). | F5: Na semana seguinte à aprovação (22–26/06/2026); depois no acolhimento de cada novo trabalhador e sempre que a política for revista. | G5: Sessões de 10 min no início de cada turno (toolbox), cartaz A3 em cada área e na cantina, publicação no ecrã da entrada e intranet, e cópia no manual de acolhimento. | H5: Garantir que todos conhecem a política e o seu papel (7.3) e recolher ideias de melhoria (7.4, ISO 14001:2026). | I5: Gestor do SGA / EHS (Responsável Ambiental) | J5: 5.2; 7.3; 7.4 | K5: Caixa de sugestões e QR code no cartaz para ideias Kaizen; 3 perguntas de compreensão no fim da sessão. | L5: Folhas de presença por turno; fotografias dos cartazes; resultados do questionário. | M5: 46199 | N5: 46199 | O5: 160 | P5: 149 | Q5: =IF(O5=0,"",P5/O5) -> 0.93125 | R5: =IF(M5="","Por ocorrência",IF(N5<>"",IF(N5<=M5,"Realizada","Realizada c/ atraso"),IF(M5<DataRef,"Atrasada","Planeada"))) -> Realizada | S5: Sim
A6: COM-02 | B6: Interna | C6: Resultados ambientais mensais | D6: KPI de energia, água, scrap, resíduos e solvente; ações do PAM em atraso. | E6: Gerência, chefias de produção, qualidade, manutenção e SGA. | F6: Reunião mensal de desempenho (2.ª terça-feira). | G6: Painel Power BI e ata da reunião. | H6: Decidir com base em dados (9.1.1). | I6: Gestor do SGA / EHS (Responsável Ambiental) | J6: 7.4; 9.1.1 | K6: Decisões e responsáveis registados em ata. | L6: Atas mensais. | M6: 46273 | N6: 46273 | O6: 9 | P6: 9 | Q6: =IF(O6=0,"",P6/O6) -> 1 | R6: =IF(M6="","Por ocorrência",IF(N6<>"",IF(N6<=M6,"Realizada","Realizada c/ atraso"),IF(M6<DataRef,"Atrasada","Planeada"))) -> Realizada | S6: Não
A7: COM-03 | B7: Interna | C7: Alerta de desvio (solvente +15%) | D7: Desvio do consumo de solvente, práticas corretas e pedido de colaboração. | E7: Operadores e chefe de serigrafia (3 turnos). | F7: Imediatamente após a deteção do desvio. | G7: Toolbox de 10 min no posto e aviso no quadro da serigrafia. | H7: Conter o desvio (PAM-26-07) e envolver os operadores na investigação. | I7: Gestor do SGA / EHS (Responsável Ambiental) | J7: 7.4; 10.2 | K7: Operadores indicaram 3 causas prováveis (registadas no RG-SGA-13). | L7: Folha de presença; registo das sugestões. | M7: 46274 | N7: 46275 | O7: 7 | P7: 7 | Q7: =IF(O7=0,"",P7/O7) -> 1 | R7: =IF(M7="","Por ocorrência",IF(N7<>"",IF(N7<=M7,"Realizada","Realizada c/ atraso"),IF(M7<DataRef,"Atrasada","Planeada"))) -> Realizada c/ atraso | S7: Não
A8: COM-04 | B8: Externa | C8: Requisitos ambientais a fornecedores críticos | D8: Critérios ambientais de compra (certificação do conteúdo reciclado, ISO 14001, Operation Clean Sweep). | E8: 10 fornecedores de resina e masterbatch. | F8: Na homologação e na revisão anual. | G8: Carta de requisitos + questionário ESG online. | H8: Controlar/influenciar processos e produtos fornecidos externamente (8.1, ISO 14001:2026). | I8: Responsável de Compras | J8: 7.4; 8.1 | K8: Respostas ao questionário (RG-SGA-11). | L8: Questionários respondidos. | M8: 46203 | N8: 46218 | O8: 10 | P8: 8 | Q8: =IF(O8=0,"",P8/O8) -> 0.8 | R8: =IF(M8="","Por ocorrência",IF(N8<>"",IF(N8<=M8,"Realizada","Realizada c/ atraso"),IF(M8<DataRef,"Atrasada","Planeada"))) -> Realizada c/ atraso | S8: Não
A9: COM-05 | B9: Externa | C9: Resposta a reclamação da vizinhança (ruído) | D9: Receção da reclamação, medidas em curso e prazo da avaliação acústica. | E9: Reclamante e Junta de Freguesia. | F9: Resposta em ≤ 5 dias úteis; fecho após o relatório acústico. | G9: Carta/e-mail e contacto telefónico. | H9: Manter a relação com a comunidade (4.2) e demonstrar tratamento. | I9: Gestor do SGA / EHS (Responsável Ambiental) | J9: 7.4; 9.1.2 | K9: Pedido de feedback ao reclamante após a resposta. | L9: Registo de reclamação REC-2026-03. | M9: 46284 | N9: 46283 | O9: 2 | P9: 2 | Q9: =IF(O9=0,"",P9/O9) -> 1 | R9: =IF(M9="","Por ocorrência",IF(N9<>"",IF(N9<=M9,"Realizada","Realizada c/ atraso"),IF(M9<DataRef,"Atrasada","Planeada"))) -> Realizada | S9: Não
A10: COM-06 | B10: Externa | C10: Reporte a autoridades | D10: MIRR anual, controlo de fugas de gases fluorados, relatório SGCIE. | E10: APA / DGEG. | F10: Nos prazos legais (calendário RG-SGA-04). | G10: Plataformas SILiAmb e SGCIE. | H10: Cumprir obrigações de conformidade. | I10: Gestor do SGA / EHS (Responsável Ambiental) | J10: 6.1.3; 7.4 | K10: — | L10: Comprovativos de submissão. | M10: 46112 | N10: 46099 | O10: 1 | P10: 1 | Q10: =IF(O10=0,"",P10/O10) -> 1 | R10: =IF(M10="","Por ocorrência",IF(N10<>"",IF(N10<=M10,"Realizada","Realizada c/ atraso"),IF(M10<DataRef,"Atrasada","Planeada"))) -> Realizada | S10: Não
A11: COM-07 | B11: Externa | C11: Emergência ambiental com impacte externo | D11: Tipo de ocorrência, medidas tomadas e riscos para o exterior. | E11: 112 / bombeiros, entidade gestora de águas residuais, APA e vizinhos. | F11: Imediatamente (≤ 1 h) após ativação do plano de emergência. | G11: Telefone (lista de contactos da IT-SGA-01) e comunicado escrito posterior. | H11: Limitar consequências (8.2). | I11: Diretor Industrial | J11: 7.4; 8.2 | K11: Relatório pós-emergência. | L11: Registo de comunicações do incidente. | O11: 0 | P11: 0 | Q11: =IF(O11=0,"",P11/O11) | R11: =IF(M11="","Por ocorrência",IF(N11<>"",IF(N11<=M11,"Realizada","Realizada c/ atraso"),IF(M11<DataRef,"Atrasada","Planeada"))) -> Por ocorrência | S11: Não
A12: COM-08 | B12: Interna | C12: Caixa de sugestões ambientais (Kaizen) | D12: Convite a propor pequenas melhorias ambientais com poupança. | E12: Todos os trabalhadores. | F12: Permanente; revisão mensal das ideias. | G12: Caixa física + QR code; reconhecimento mensal da melhor ideia. | H12: Permitir que os trabalhadores contribuam para a melhoria contínua (7.4, ISO 14001:2026). | I12: Gerente de Produção | J12: 7.4; 10.1 | K12: Ideias registadas no RG-SGA-16. | L12: Registo de ideias KZ. | M12: 46295 | N12: 46296 | O12: 160 | P12: 142 | Q12: =IF(O12=0,"",P12/O12) -> 0.8875 | R12: =IF(M12="","Por ocorrência",IF(N12<>"",IF(N12<=M12,"Realizada","Realizada c/ atraso"),IF(M12<DataRef,"Atrasada","Planeada"))) -> Realizada c/ atraso | S12: Não

Sheet Lista_Mestra
A1: Codigo | B1: Titulo | C1: Tipo | D1: Versao | E1: Data_Aprovacao | F1: Aprovador | G1: Estado | H1: Substitui | I1: Localizacao | J1: Ponto_de_Uso | K1: Clausula | L1: Proxima_Revisao | M1: Alerta
A2: POL-SGA | B2: Política Ambiental | C2: Política | D2: 01 | E2: 45361 | F2: Diretor Geral | G2: Obsoleto | I2: Arquivo SGA (carimbo 'OBSOLETO') | J2: Retirada dos quadros em 26/06/2026 | K2: 5.2 | L2: =IF(OR(G2="Obsoleto",E2=""),"",EDATE(E2,24)) | M2: =IF(G2="Obsoleto","Retirar dos pontos de uso",IF(E2="","Sem aprovação",IF(L2<DataRef,"Revisão vencida",IF(G2="Em revisão","Em revisão","OK")))) -> Retirar dos pontos de uso
A3: POL-SGA | B3: Política Ambiental | C3: Política | D3: 02 | E3: 46192 | F3: Diretor Geral | G3: Em vigor | H3: rev. 01 | I3: Intranet; cartazes em todas as áreas | J3: Todas as áreas | K3: 5.2 | L3: =IF(OR(G3="Obsoleto",E3=""),"",EDATE(E3,24)) -> 46923 | M3: =IF(G3="Obsoleto","Retirar dos pontos de uso",IF(E3="","Sem aprovação",IF(L3<DataRef,"Revisão vencida",IF(G3="Em revisão","Em revisão","OK")))) -> OK
A4: PR-SGA-01 | B4: Identificação e avaliação de aspetos ambientais (base PR.G.01.01) | C4: Procedimento | D4: 01 | E4: 46157 | F4: Diretor Geral | G4: Em vigor | H4: rev. 00 | I4: Intranet SGA | J4: SGA; chefias | K4: 6.1.2 | L4: =IF(OR(G4="Obsoleto",E4=""),"",EDATE(E4,24)) -> 46888 | M4: =IF(G4="Obsoleto","Retirar dos pontos de uso",IF(E4="","Sem aprovação",IF(L4<DataRef,"Revisão vencida",IF(G4="Em revisão","Em revisão","OK")))) -> OK
A5: PR-SGA-02 | B5: Gestão de riscos e oportunidades (base PG-SGI-006) | C5: Procedimento | D5: 00 | E5: 46122 | F5: Diretor Geral | G5: Em vigor | I5: Intranet SGA | J5: SGA; chefias | K5: 6.1.4; 6.1.5 | L5: =IF(OR(G5="Obsoleto",E5=""),"",EDATE(E5,24)) -> 46853 | M5: =IF(G5="Obsoleto","Retirar dos pontos de uso",IF(E5="","Sem aprovação",IF(L5<DataRef,"Revisão vencida",IF(G5="Em revisão","Em revisão","OK")))) -> OK
A6: PR-SGA-03 | B6: Obrigações de conformidade e avaliação da conformidade | C6: Procedimento | D6: 00 | E6: 46122 | F6: Diretor Geral | G6: Em vigor | I6: Intranet SGA | J6: SGA | K6: 6.1.3; 9.1.2 | L6: =IF(OR(G6="Obsoleto",E6=""),"",EDATE(E6,24)) -> 46853 | M6: =IF(G6="Obsoleto","Retirar dos pontos de uso",IF(E6="","Sem aprovação",IF(L6<DataRef,"Revisão vencida",IF(G6="Em revisão","Em revisão","OK")))) -> OK
A7: PR-SGA-04 | B7: Gestão de resíduos | C7: Procedimento | D7: 02 | E7: 45981 | F7: Diretor Industrial | G7: Em vigor | H7: rev. 01 | I7: Intranet; parque de resíduos | J7: Armazém; produção | K7: 8.1 | L7: =IF(OR(G7="Obsoleto",E7=""),"",EDATE(E7,24)) -> 46711 | M7: =IF(G7="Obsoleto","Retirar dos pontos de uso",IF(E7="","Sem aprovação",IF(L7<DataRef,"Revisão vencida",IF(G7="Em revisão","Em revisão","OK")))) -> OK
A8: PR-SGA-05 | B8: Preparação e resposta a emergências | C8: Procedimento | D8: 01 | E8: 45935 | F8: Diretor Industrial | G8: Em revisão | H8: rev. 00 | I8: Intranet SGA | J8: Todas as áreas | K8: 8.2 | L8: =IF(OR(G8="Obsoleto",E8=""),"",EDATE(E8,24)) -> 46665 | M8: =IF(G8="Obsoleto","Retirar dos pontos de uso",IF(E8="","Sem aprovação",IF(L8<DataRef,"Revisão vencida",IF(G8="Em revisão","Em revisão","OK")))) -> Em revisão
A9: MAN-SGA-01 | B9: Manual do SGA — âmbito, estrutura e correspondência com a ISO 14001:2026 | C9: Manual | D9: 00 | E9: 46289 | F9: Diretor Geral | G9: Em vigor | I9: Documentos_SGA_Plasticom | J9: SGA; chefias; partes interessadas (âmbito) | K9: 4.3; 4.4 | L9: =IF(OR(G9="Obsoleto",E9=""),"",EDATE(E9,24)) -> 47020 | M9: =IF(G9="Obsoleto","Retirar dos pontos de uso",IF(E9="","Sem aprovação",IF(L9<DataRef,"Revisão vencida",IF(G9="Em revisão","Em revisão","OK")))) -> OK
A10: PR-SGA-06 | B10: Planeamento de alterações (gestão de mudanças) | C10: Procedimento | D10: 00 | E10: 46289 | F10: Diretor Geral | G10: Em vigor | I10: Documentos_SGA_Plasticom | J10: Todas as áreas | K10: 6.3 | L10: =IF(OR(G10="Obsoleto",E10=""),"",EDATE(E10,24)) -> 47020 | M10: =IF(G10="Obsoleto","Retirar dos pontos de uso",IF(E10="","Sem aprovação",IF(L10<DataRef,"Revisão vencida",IF(G10="Em revisão","Em revisão","OK")))) -> OK
A11: PR-SGA-07 | B11: Competência, consciencialização e comunicação | C11: Procedimento | D11: 00 | E11: 46289 | F11: Diretor Geral | G11: Em vigor | I11: Documentos_SGA_Plasticom | J11: RH; chefias; SGA | K11: 7.2; 7.3; 7.4 | L11: =IF(OR(G11="Obsoleto",E11=""),"",EDATE(E11,24)) -> 47020 | M11: =IF(G11="Obsoleto","Retirar dos pontos de uso",IF(E11="","Sem aprovação",IF(L11<DataRef,"Revisão vencida",IF(G11="Em revisão","Em revisão","OK")))) -> OK
A12: PR-SGA-08 | B12: Controlo da informação documentada | C12: Procedimento | D12: 00 | E12: 46289 | F12: Diretor Geral | G12: Em vigor | I12: Documentos_SGA_Plasticom | J12: SGA | K12: 7.5 | L12: =IF(OR(G12="Obsoleto",E12=""),"",EDATE(E12,24)) -> 47020 | M12: =IF(G12="Obsoleto","Retirar dos pontos de uso",IF(E12="","Sem aprovação",IF(L12<DataRef,"Revisão vencida",IF(G12="Em revisão","Em revisão","OK")))) -> OK
A13: PR-SGA-09 | B13: Controlo operacional e processos externos | C13: Procedimento | D13: 00 | E13: 46289 | F13: Diretor Geral | G13: Em vigor | I13: Documentos_SGA_Plasticom | J13: Produção; utilidades; compras | K13: 8.1 | L13: =IF(OR(G13="Obsoleto",E13=""),"",EDATE(E13,24)) -> 47020 | M13: =IF(G13="Obsoleto","Retirar dos pontos de uso",IF(E13="","Sem aprovação",IF(L13<DataRef,"Revisão vencida",IF(G13="Em revisão","Em revisão","OK")))) -> OK
A14: PR-SGA-10 | B14: Monitorização, medição, análise, avaliação e calibração | C14: Procedimento | D14: 00 | E14: 46289 | F14: Diretor Geral | G14: Em vigor | I14: Documentos_SGA_Plasticom | J14: SGA; manutenção | K14: 9.1.1 | L14: =IF(OR(G14="Obsoleto",E14=""),"",EDATE(E14,24)) -> 47020 | M14: =IF(G14="Obsoleto","Retirar dos pontos de uso",IF(E14="","Sem aprovação",IF(L14<DataRef,"Revisão vencida",IF(G14="Em revisão","Em revisão","OK")))) -> OK
A15: PR-SGA-11 | B15: Auditoria interna e revisão pela gestão | C15: Procedimento | D15: 00 | E15: 46289 | F15: Diretor Geral | G15: Em vigor | I15: Documentos_SGA_Plasticom | J15: SGA; gerência | K15: 9.2; 9.3 | L15: =IF(OR(G15="Obsoleto",E15=""),"",EDATE(E15,24)) -> 47020 | M15: =IF(G15="Obsoleto","Retirar dos pontos de uso",IF(E15="","Sem aprovação",IF(L15<DataRef,"Revisão vencida",IF(G15="Em revisão","Em revisão","OK")))) -> OK
A16: PR-SGA-12 | B16: Incidentes, não conformidades, ação corretiva e melhoria contínua | C16: Procedimento | D16: 00 | E16: 46289 | F16: Diretor Geral | G16: Em vigor | I16: Documentos_SGA_Plasticom | J16: Todas as áreas | K16: 10.1; 10.2 | L16: =IF(OR(G16="Obsoleto",E16=""),"",EDATE(E16,24)) -> 47020 | M16: =IF(G16="Obsoleto","Retirar dos pontos de uso",IF(E16="","Sem aprovação",IF(L16<DataRef,"Revisão vencida",IF(G16="Em revisão","Em revisão","OK")))) -> OK
A17: PR-SGA-13 | B17: Inventário de GEE e indicadores ESG ambientais | C17: Procedimento | D17: 00 | E17: 46289 | F17: Diretor Geral | G17: Em vigor | I17: Documentos_SGA_Plasticom | J17: SGA; finanças; compras | K17: 9.1.1; 6.2 | L17: =IF(OR(G17="Obsoleto",E17=""),"",EDATE(E17,24)) -> 47020 | M17: =IF(G17="Obsoleto","Retirar dos pontos de uso",IF(E17="","Sem aprovação",IF(L17<DataRef,"Revisão vencida",IF(G17="Em revisão","Em revisão","OK")))) -> OK
A18: PR-SGA-14 | B18: Alegações ambientais e declarações de produto | C18: Procedimento | D18: 00 | E18: 46289 | F18: Diretor Geral | G18: Em vigor | I18: Documentos_SGA_Plasticom | J18: R&D; comercial | K18: 7.4; 8.1 | L18: =IF(OR(G18="Obsoleto",E18=""),"",EDATE(E18,24)) -> 47020 | M18: =IF(G18="Obsoleto","Retirar dos pontos de uso",IF(E18="","Sem aprovação",IF(L18<DataRef,"Revisão vencida",IF(G18="Em revisão","Em revisão","OK")))) -> OK
A19: PR-SGA-15 | B19: Conceção para reciclagem e conformidade de embalagens (PPWR, RecyClass) | C19: Procedimento | D19: 00 | E19: 46289 | F19: Diretor Geral | G19: Em vigor | I19: Documentos_SGA_Plasticom | J19: R&D; qualidade; compras; comercial | K19: 8.1; 6.1.3 | L19: =IF(OR(G19="Obsoleto",E19=""),"",EDATE(E19,24)) -> 47020 | M19: =IF(G19="Obsoleto","Retirar dos pontos de uso",IF(E19="","Sem aprovação",IF(L19<DataRef,"Revisão vencida",IF(G19="Em revisão","Em revisão","OK")))) -> OK
A20: PR-SGA-16 | B20: Gestão de produtos químicos — REACH, CLP, SVHC e risco químico | C20: Procedimento | D20: 00 | E20: 46289 | F20: Diretor Geral | G20: Em vigor | I20: Documentos_SGA_Plasticom | J20: Engenharia; produção; manutenção; compras; armazém; R&D | K20: 6.1.3; 8.1; 9.1.2 | L20: =IF(OR(G20="Obsoleto",E20=""),"",EDATE(E20,24)) -> 47020 | M20: =IF(G20="Obsoleto","Retirar dos pontos de uso",IF(E20="","Sem aprovação",IF(L20<DataRef,"Revisão vencida",IF(G20="Em revisão","Em revisão","OK")))) -> OK
A21: PL-SGA-01 | B21: Plano de transição climática 2026–2030 | C21: Plano | D21: 00 | E21: 46310 | F21: Diretor Geral | G21: Em vigor | I21: Documentos_SGA_Plasticom | J21: Gerência | K21: 6.2; 4.1 | L21: =IF(OR(G21="Obsoleto",E21=""),"",EDATE(E21,24)) -> 47041 | M21: =IF(G21="Obsoleto","Retirar dos pontos de uso",IF(E21="","Sem aprovação",IF(L21<DataRef,"Revisão vencida",IF(G21="Em revisão","Em revisão","OK")))) -> OK
A22: IT-SGA-01 | B22: Resposta a derrames de produtos químicos | C22: Instrução de trabalho | D22: 01 | E22: 46324 | F22: Gestor do SGA | G22: Em vigor | H22: rev. 00 | I22: Junto a cada kit de derrame | J22: Armazém; serigrafia; injeção; manutenção | K22: 8.2 | L22: =IF(OR(G22="Obsoleto",E22=""),"",EDATE(E22,24)) -> 47055 | M22: =IF(G22="Obsoleto","Retirar dos pontos de uso",IF(E22="","Sem aprovação",IF(L22<DataRef,"Revisão vencida",IF(G22="Em revisão","Em revisão","OK")))) -> OK
A23: IT-SGA-02 | B23: Resposta a incêndio com retenção das águas de combate | C23: Instrução de trabalho | D23: 00 | E23: 46063 | F23: Diretor Industrial | G23: Em vigor | I23: Portaria; armazém de MP | J23: Chefes de turno; portaria | K23: 8.2 | L23: =IF(OR(G23="Obsoleto",E23=""),"",EDATE(E23,24)) -> 46793 | M23: =IF(G23="Obsoleto","Retirar dos pontos de uso",IF(E23="","Sem aprovação",IF(L23<DataRef,"Revisão vencida",IF(G23="Em revisão","Em revisão","OK")))) -> OK
A24: IT-SER-03 | B24: Limpeza de ecrãs e rodos na serigrafia | C24: Instrução de trabalho | D24: 02 | E24: 46336 | F24: Gerente de Produção | G24: Em vigor | H24: rev. 01 | I24: Posto SS-001 e SS-002 | J24: Serigrafia | K24: 8.1 | L24: =IF(OR(G24="Obsoleto",E24=""),"",EDATE(E24,24)) -> 47067 | M24: =IF(G24="Obsoleto","Retirar dos pontos de uso",IF(E24="","Sem aprovação",IF(L24<DataRef,"Revisão vencida",IF(G24="Em revisão","Em revisão","OK")))) -> OK
A25: RG-SGA-01 | B25: Contexto — PESTEL, SWOT, partes interessadas, 5 forças e TOWS (SGA e SGI) | C25: Registo | D25: 02 | E25: 46289 | F25: Diretor Geral | G25: Em vigor | I25: Registos_SGA_Plasticom | J25: SGA | K25: 4.1 | L25: =IF(OR(G25="Obsoleto",E25=""),"",EDATE(E25,24)) -> 47020 | M25: =IF(G25="Obsoleto","Retirar dos pontos de uso",IF(E25="","Sem aprovação",IF(L25<DataRef,"Revisão vencida",IF(G25="Em revisão","Em revisão","OK")))) -> OK
A26: RG-SGA-02 | B26: Riscos e oportunidades — registo corporativo (política, apetite, riscos, planos SGI, KRI, BowTie, auditorias SGI) | C26: Registo | D26: 03 | E26: 46289 | F26: Diretor Geral | G26: Em vigor | I26: Registos_SGA_Plasticom | J26: SGA | K26: 6.1.4 | L26: =IF(OR(G26="Obsoleto",E26=""),"",EDATE(E26,24)) -> 47020 | M26: =IF(G26="Obsoleto","Retirar dos pontos de uso",IF(E26="","Sem aprovação",IF(L26<DataRef,"Revisão vencida",IF(G26="Em revisão","Em revisão","OK")))) -> OK
A27: RG-SGA-03 | B27: Matriz de aspetos e impactes (Mod.G.07.00) | C27: Registo | D27: 01 | E27: 46288 | F27: Diretor Geral | G27: Em vigor | I27: Registos_SGA_Plasticom | J27: SGA | K27: 6.1.2 | L27: =IF(OR(G27="Obsoleto",E27=""),"",EDATE(E27,24)) -> 47019 | M27: =IF(G27="Obsoleto","Retirar dos pontos de uso",IF(E27="","Sem aprovação",IF(L27<DataRef,"Revisão vencida",IF(G27="Em revisão","Em revisão","OK")))) -> OK
A28: RG-SGA-04 | B28: Requisitos legais e conformidade (Mod.G.06.02) | C28: Registo | D28: 01 | E28: 46288 | F28: Diretor Geral | G28: Em vigor | I28: Registos_SGA_Plasticom | J28: SGA | K28: 6.1.3; 9.1.2 | L28: =IF(OR(G28="Obsoleto",E28=""),"",EDATE(E28,24)) -> 47019 | M28: =IF(G28="Obsoleto","Retirar dos pontos de uso",IF(E28="","Sem aprovação",IF(L28<DataRef,"Revisão vencida",IF(G28="Em revisão","Em revisão","OK")))) -> OK
A29: RG-SGA-05 | B29: Objetivos, metas e KPI | C29: Registo | D29: 01 | E29: 46288 | F29: Diretor Geral | G29: Em vigor | I29: Registos_SGA_Plasticom | J29: SGA | K29: 6.2 | L29: =IF(OR(G29="Obsoleto",E29=""),"",EDATE(E29,24)) -> 47019 | M29: =IF(G29="Obsoleto","Retirar dos pontos de uso",IF(E29="","Sem aprovação",IF(L29<DataRef,"Revisão vencida",IF(G29="Em revisão","Em revisão","OK")))) -> OK
A30: RG-SGA-06 | B30: Plano de Ações de Melhoria (Mod.G.10.00) | C30: Registo | D30: 01 | E30: 46288 | F30: Diretor Geral | G30: Em vigor | I30: Registos_SGA_Plasticom | J30: SGA | K30: 6.1.5; 10 | L30: =IF(OR(G30="Obsoleto",E30=""),"",EDATE(E30,24)) -> 47019 | M30: =IF(G30="Obsoleto","Retirar dos pontos de uso",IF(E30="","Sem aprovação",IF(L30<DataRef,"Revisão vencida",IF(G30="Em revisão","Em revisão","OK")))) -> OK
A31: RG-SGA-07 | B31: Não conformidades e incidentes (RNC) | C31: Registo | D31: 01 | E31: 46288 | F31: Diretor Geral | G31: Em vigor | I31: Registos_SGA_Plasticom | J31: SGA | K31: 10.2 | L31: =IF(OR(G31="Obsoleto",E31=""),"",EDATE(E31,24)) -> 47019 | M31: =IF(G31="Obsoleto","Retirar dos pontos de uso",IF(E31="","Sem aprovação",IF(L31<DataRef,"Revisão vencida",IF(G31="Em revisão","Em revisão","OK")))) -> OK
A32: RG-SGA-08 | B32: Matriz de competências | C32: Registo | D32: 01 | E32: 46288 | F32: Diretor Geral | G32: Em vigor | I32: Registos_SGA_Plasticom | J32: SGA; RH | K32: 7.2; 7.3 | L32: =IF(OR(G32="Obsoleto",E32=""),"",EDATE(E32,24)) -> 47019 | M32: =IF(G32="Obsoleto","Retirar dos pontos de uso",IF(E32="","Sem aprovação",IF(L32<DataRef,"Revisão vencida",IF(G32="Em revisão","Em revisão","OK")))) -> OK
A33: RG-SGA-09 | B33: Comunicação e controlo documental | C33: Registo | D33: 01 | E33: 46288 | F33: Diretor Geral | G33: Em vigor | I33: Registos_SGA_Plasticom | J33: SGA | K33: 7.4; 7.5 | L33: =IF(OR(G33="Obsoleto",E33=""),"",EDATE(E33,24)) -> 47019 | M33: =IF(G33="Obsoleto","Retirar dos pontos de uso",IF(E33="","Sem aprovação",IF(L33<DataRef,"Revisão vencida",IF(G33="Em revisão","Em revisão","OK")))) -> OK
A34: RG-SGA-10 | B34: Controlo operacional — rondas ambientais | C34: Registo | D34: 01 | E34: 46288 | F34: Diretor Geral | G34: Em vigor | I34: Registos_SGA_Plasticom | J34: SGA; produção | K34: 8.1 | L34: =IF(OR(G34="Obsoleto",E34=""),"",EDATE(E34,24)) -> 47019 | M34: =IF(G34="Obsoleto","Retirar dos pontos de uso",IF(E34="","Sem aprovação",IF(L34<DataRef,"Revisão vencida",IF(G34="Em revisão","Em revisão","OK")))) -> OK
A35: RG-SGA-11 | B35: Fornecedores e ciclo de vida | C35: Registo | D35: 01 | E35: 46288 | F35: Diretor Geral | G35: Em vigor | I35: Registos_SGA_Plasticom | J35: Compras | K35: 8.1 | L35: =IF(OR(G35="Obsoleto",E35=""),"",EDATE(E35,24)) -> 47019 | M35: =IF(G35="Obsoleto","Retirar dos pontos de uso",IF(E35="","Sem aprovação",IF(L35<DataRef,"Revisão vencida",IF(G35="Em revisão","Em revisão","OK")))) -> OK
A36: RG-SGA-12 | B36: Emergências ambientais | C36: Registo | D36: 01 | E36: 46288 | F36: Diretor Geral | G36: Em vigor | I36: Registos_SGA_Plasticom | J36: SGA | K36: 8.2 | L36: =IF(OR(G36="Obsoleto",E36=""),"",EDATE(E36,24)) -> 47019 | M36: =IF(G36="Obsoleto","Retirar dos pontos de uso",IF(E36="","Sem aprovação",IF(L36<DataRef,"Revisão vencida",IF(G36="Em revisão","Em revisão","OK")))) -> OK
... A45: RG-SGA-20 | B45: Reciclabilidade e conformidade de embalagens (RecyClass / PPWR) | C45: Registo | D45: 00 | E45: 46289 | F45: Diretor Geral | G45: Em vigor | I45: Registos_SGA_Plasticom | J45: R&D; qualidade; compras; comercial | K45: 8.1; 6.1.3; 7.4 | L45: =IF(OR(G45="Obsoleto",E45=""),"",EDATE(E45,24)) -> 47020 | M45: =IF(G45="Obsoleto","Retirar dos pontos de uso",IF(E45="","Sem aprovação",IF(L45<DataRef,"Revisão vencida",IF(G45="Em revisão","Em revisão","OK")))) -> OK

Sheet Elementos_Controlo
A1: ID_Elemento | B1: Elemento | C1: Obrigatorio_Atv_4_2 | D1: Porque
A2: EL-01 | B2: Identificação: título e código únicos | C2: Sim | D2: Garante que se sabe exatamente que documento é e que não é confundido com outro.
A3: EL-02 | B3: Estado de revisão: n.º de versão/revisão e data de emissão | C3: Sim | D3: Permite confirmar que é a versão mais recente (comparar com a lista mestra).
A4: EL-03 | B4: Aprovação: quem aprovou e quando (assinatura/validação eletrónica) | C4: Sim | D4: Só documentos aprovados por pessoa autorizada podem ser usados.
A5: EL-04 | B5: Indicação 'Em vigor' e distribuição controlada no ponto de uso | C5: Não | D5: A cópia no posto deve ser a da lista mestra; cópias impressas não controladas marcadas como tal.
A6: EL-05 | B6: Legibilidade, formato e meio adequados | C6: Não | D6: Documento legível e utilizável no local.
A7: EL-06 | B7: Proteção e retenção (obsoletos retirados ou identificados) | C7: Não | D7: Versões antigas retiradas dos pontos de uso ou carimbadas 'OBSOLETO'.

Sheet Verificacao_Documental
A1: ID_Verificacao | B1: Data | C1: Codigo_Documento | D1: Local | E1: Versao_Encontrada | F1: Versao_Em_Vigor | G1: Versao_Correta | H1: ID_Elemento | I1: Resultado | J1: Observacao
A2: VD-01 | B2: 46280 | C2: PR-SGA-04 | D2: Parque de resíduos | E2: 02 | F2: =IFERROR(INDEX(tbl_lista_mestra[Versao],MATCH(1,INDEX((tbl_lista_mestra[Codigo]=C2)*(tbl_lista_mestra[Estado]<>"Obsoleto"),0),0)),"") -> 02 | G2: =IF(F2="","?",IF(E2=F2,"Sim","Não")) -> Sim | H2: EL-01 | I2: OK
A3: VD-01 | B3: 46280 | C3: PR-SGA-04 | D3: Parque de resíduos | E3: 02 | F3: =IFERROR(INDEX(tbl_lista_mestra[Versao],MATCH(1,INDEX((tbl_lista_mestra[Codigo]=C3)*(tbl_lista_mestra[Estado]<>"Obsoleto"),0),0)),"") -> 02 | G3: =IF(F3="","?",IF(E3=F3,"Sim","Não")) -> Sim | H3: EL-02 | I3: OK
A4: VD-01 | B4: 46280 | C4: PR-SGA-04 | D4: Parque de resíduos | E4: 02 | F4: =IFERROR(INDEX(tbl_lista_mestra[Versao],MATCH(1,INDEX((tbl_lista_mestra[Codigo]=C4)*(tbl_lista_mestra[Estado]<>"Obsoleto"),0),0)),"") -> 02 | G4: =IF(F4="","?",IF(E4=F4,"Sim","Não")) -> Sim | H4: EL-03 | I4: OK
A5: VD-01 | B5: 46280 | C5: PR-SGA-04 | D5: Parque de resíduos | E5: 02 | F5: =IFERROR(INDEX(tbl_lista_mestra[Versao],MATCH(1,INDEX((tbl_lista_mestra[Codigo]=C5)*(tbl_lista_mestra[Estado]<>"Obsoleto"),0),0)),"") -> 02 | G5: =IF(F5="","?",IF(E5=F5,"Sim","Não")) -> Sim | H5: EL-04 | I5: OK
A6: VD-01 | B6: 46280 | C6: PR-SGA-04 | D6: Parque de resíduos | E6: 02 | F6: =IFERROR(INDEX(tbl_lista_mestra[Versao],MATCH(1,INDEX((tbl_lista_mestra[Codigo]=C6)*(tbl_lista_mestra[Estado]<>"Obsoleto"),0),0)),"") -> 02 | G6: =IF(F6="","?",IF(E6=F6,"Sim","Não")) -> Sim | H6: EL-05 | I6: OK
A7: VD-01 | B7: 46280 | C7: PR-SGA-04 | D7: Parque de resíduos | E7: 02 | F7: =IFERROR(INDEX(tbl_lista_mestra[Versao],MATCH(1,INDEX((tbl_lista_mestra[Codigo]=C7)*(tbl_lista_mestra[Estado]<>"Obsoleto"),0),0)),"") -> 02 | G7: =IF(F7="","?",IF(E7=F7,"Sim","Não")) -> Sim | H7: EL-06 | I7: OK
A8: VD-02 | B8: 46280 | C8: IT-SGA-01 | D8: Kit KIT-03 (injeção/serigrafia) | E8: 00 | F8: =IFERROR(INDEX(tbl_lista_mestra[Versao],MATCH(1,INDEX((tbl_lista_mestra[Codigo]=C8)*(tbl_lista_mestra[Estado]<>"Obsoleto"),0),0)),"") -> 01 | G8: =IF(F8="","?",IF(E8=F8,"Sim","Não")) -> Não | H8: EL-01 | I8: OK
A9: VD-02 | B9: 46280 | C9: IT-SGA-01 | D9: Kit KIT-03 (injeção/serigrafia) | E9: 00 | F9: =IFERROR(INDEX(tbl_lista_mestra[Versao],MATCH(1,INDEX((tbl_lista_mestra[Codigo]=C9)*(tbl_lista_mestra[Estado]<>"Obsoleto"),0),0)),"") -> 01 | G9: =IF(F9="","?",IF(E9=F9,"Sim","Não")) -> Não | H9: EL-02 | I9: OK
A10: VD-02 | B10: 46280 | C10: IT-SGA-01 | D10: Kit KIT-03 (injeção/serigrafia) | E10: 00 | F10: =IFERROR(INDEX(tbl_lista_mestra[Versao],MATCH(1,INDEX((tbl_lista_mestra[Codigo]=C10)*(tbl_lista_mestra[Estado]<>"Obsoleto"),0),0)),"") -> 01 | G10: =IF(F10="","?",IF(E10=F10,"Sim","Não")) -> Não | H10: EL-03 | I10: OK
A11: VD-02 | B11: 46280 | C11: IT-SGA-01 | D11: Kit KIT-03 (injeção/serigrafia) | E11: 00 | F11: =IFERROR(INDEX(tbl_lista_mestra[Versao],MATCH(1,INDEX((tbl_lista_mestra[Codigo]=C11)*(tbl_lista_mestra[Estado]<>"Obsoleto"),0),0)),"") -> 01 | G11: =IF(F11="","?",IF(E11=F11,"Sim","Não")) -> Não | H11: EL-04 | I11: OK
A12: VD-02 | B12: 46280 | C12: IT-SGA-01 | D12: Kit KIT-03 (injeção/serigrafia) | E12: 00 | F12: =IFERROR(INDEX(tbl_lista_mestra[Versao],MATCH(1,INDEX((tbl_lista_mestra[Codigo]=C12)*(tbl_lista_mestra[Estado]<>"Obsoleto"),0),0)),"") -> 01 | G12: =IF(F12="","?",IF(E12=F12,"Sim","Não")) -> Não | H12: EL-05 | I12: NOK | J12: Folha plastificada ilegível (manchas); conteúdo sem etapa pós-uso (ver NC-SGA-26-03).
A13: VD-02 | B13: 46280 | C13: IT-SGA-01 | D13: Kit KIT-03 (injeção/serigrafia) | E13: 00 | F13: =IFERROR(INDEX(tbl_lista_mestra[Versao],MATCH(1,INDEX((tbl_lista_mestra[Codigo]=C13)*(tbl_lista_mestra[Estado]<>"Obsoleto"),0),0)),"") -> 01 | G13: =IF(F13="","?",IF(E13=F13,"Sim","Não")) -> Não | H13: EL-06 | I13: OK
A14: VD-03 | B14: 46281 | C14: IT-SER-03 | D14: Posto SS-001 | E14: 00 | F14: =IFERROR(INDEX(tbl_lista_mestra[Versao],MATCH(1,INDEX((tbl_lista_mestra[Codigo]=C14)*(tbl_lista_mestra[Estado]<>"Obsoleto"),0),0)),"") -> 02 | G14: =IF(F14="","?",IF(E14=F14,"Sim","Não")) -> Não | H14: EL-01 | I14: OK
A15: VD-03 | B15: 46281 | C15: IT-SER-03 | D15: Posto SS-001 | E15: 00 | F15: =IFERROR(INDEX(tbl_lista_mestra[Versao],MATCH(1,INDEX((tbl_lista_mestra[Codigo]=C15)*(tbl_lista_mestra[Estado]<>"Obsoleto"),0),0)),"") -> 02 | G15: =IF(F15="","?",IF(E15=F15,"Sim","Não")) -> Não | H15: EL-02 | I15: NOK | J15: Versão 00 (obsoleta) no posto; a lista mestra indica rev. 01 em vigor. Retirada e substituída.
A16: VD-03 | B16: 46281 | C16: IT-SER-03 | D16: Posto SS-001 | E16: 00 | F16: =IFERROR(INDEX(tbl_lista_mestra[Versao],MATCH(1,INDEX((tbl_lista_mestra[Codigo]=C16)*(tbl_lista_mestra[Estado]<>"Obsoleto"),0),0)),"") -> 02 | G16: =IF(F16="","?",IF(E16=F16,"Sim","Não")) -> Não | H16: EL-03 | I16: OK
A17: VD-03 | B17: 46281 | C17: IT-SER-03 | D17: Posto SS-001 | E17: 00 | F17: =IFERROR(INDEX(tbl_lista_mestra[Versao],MATCH(1,INDEX((tbl_lista_mestra[Codigo]=C17)*(tbl_lista_mestra[Estado]<>"Obsoleto"),0),0)),"") -> 02 | G17: =IF(F17="","?",IF(E17=F17,"Sim","Não")) -> Não | H17: EL-04 | I17: NOK | J17: Versão 00 (obsoleta) no posto; a lista mestra indica rev. 01 em vigor. Retirada e substituída.
A18: VD-03 | B18: 46281 | C18: IT-SER-03 | D18: Posto SS-001 | E18: 00 | F18: =IFERROR(INDEX(tbl_lista_mestra[Versao],MATCH(1,INDEX((tbl_lista_mestra[Codigo]=C18)*(tbl_lista_mestra[Estado]<>"Obsoleto"),0),0)),"") -> 02 | G18: =IF(F18="","?",IF(E18=F18,"Sim","Não")) -> Não | H18: EL-05 | I18: OK
A19: VD-03 | B19: 46281 | C19: IT-SER-03 | D19: Posto SS-001 | E19: 00 | F19: =IFERROR(INDEX(tbl_lista_mestra[Versao],MATCH(1,INDEX((tbl_lista_mestra[Codigo]=C19)*(tbl_lista_mestra[Estado]<>"Obsoleto"),0),0)),"") -> 02 | G19: =IF(F19="","?",IF(E19=F19,"Sim","Não")) -> Não | H19: EL-06 | I19: NOK | J19: Versão 00 (obsoleta) no posto; a lista mestra indica rev. 01 em vigor. Retirada e substituída.
A20: VD-04 | B20: 46281 | C20: POL-SGA | D20: Cantina | E20: 02 | F20: =IFERROR(INDEX(tbl_lista_mestra[Versao],MATCH(1,INDEX((tbl_lista_mestra[Codigo]=C20)*(tbl_lista_mestra[Estado]<>"Obsoleto"),0),0)),"") -> 02 | G20: =IF(F20="","?",IF(E20=F20,"Sim","Não")) -> Sim | H20: EL-01 | I20: OK
A21: VD-04 | B21: 46281 | C21: POL-SGA | D21: Cantina | E21: 02 | F21: =IFERROR(INDEX(tbl_lista_mestra[Versao],MATCH(1,INDEX((tbl_lista_mestra[Codigo]=C21)*(tbl_lista_mestra[Estado]<>"Obsoleto"),0),0)),"") -> 02 | G21: =IF(F21="","?",IF(E21=F21,"Sim","Não")) -> Sim | H21: EL-02 | I21: OK
A22: VD-04 | B22: 46281 | C22: POL-SGA | D22: Cantina | E22: 02 | F22: =IFERROR(INDEX(tbl_lista_mestra[Versao],MATCH(1,INDEX((tbl_lista_mestra[Codigo]=C22)*(tbl_lista_mestra[Estado]<>"Obsoleto"),0),0)),"") -> 02 | G22: =IF(F22="","?",IF(E22=F22,"Sim","Não")) -> Sim | H22: EL-03 | I22: OK
A23: VD-04 | B23: 46281 | C23: POL-SGA | D23: Cantina | E23: 02 | F23: =IFERROR(INDEX(tbl_lista_mestra[Versao],MATCH(1,INDEX((tbl_lista_mestra[Codigo]=C23)*(tbl_lista_mestra[Estado]<>"Obsoleto"),0),0)),"") -> 02 | G23: =IF(F23="","?",IF(E23=F23,"Sim","Não")) -> Sim | H23: EL-04 | I23: OK
A24: VD-04 | B24: 46281 | C24: POL-SGA | D24: Cantina | E24: 02 | F24: =IFERROR(INDEX(tbl_lista_mestra[Versao],MATCH(1,INDEX((tbl_lista_mestra[Codigo]=C24)*(tbl_lista_mestra[Estado]<>"Obsoleto"),0),0)),"") -> 02 | G24: =IF(F24="","?",IF(E24=F24,"Sim","Não")) -> Sim | H24: EL-05 | I24: OK
A25: VD-04 | B25: 46281 | C25: POL-SGA | D25: Cantina | E25: 02 | F25: =IFERROR(INDEX(tbl_lista_mestra[Versao],MATCH(1,INDEX((tbl_lista_mestra[Codigo]=C25)*(tbl_lista_mestra[Estado]<>"Obsoleto"),0),0)),"") -> 02 | G25: =IF(F25="","?",IF(E25=F25,"Sim","Não")) -> Sim | H25: EL-06 | I25: OK
A26: VD-05 | B26: 46281 | C26: PR-SGA-05 | D26: Portaria | E26: 01 | F26: =IFERROR(INDEX(tbl_lista_mestra[Versao],MATCH(1,INDEX((tbl_lista_mestra[Codigo]=C26)*(tbl_lista_mestra[Estado]<>"Obsoleto"),0),0)),"") -> 01 | G26: =IF(F26="","?",IF(E26=F26,"Sim","Não")) -> Sim | H26: EL-01 | I26: OK
A27: VD-05 | B27: 46281 | C27: PR-SGA-05 | D27: Portaria | E27: 01 | F27: =IFERROR(INDEX(tbl_lista_mestra[Versao],MATCH(1,INDEX((tbl_lista_mestra[Codigo]=C27)*(tbl_lista_mestra[Estado]<>"Obsoleto"),0),0)),"") -> 01 | G27: =IF(F27="","?",IF(E27=F27,"Sim","Não")) -> Sim | H27: EL-02 | I27: OK
A28: VD-05 | B28: 46281 | C28: PR-SGA-05 | D28: Portaria | E28: 01 | F28: =IFERROR(INDEX(tbl_lista_mestra[Versao],MATCH(1,INDEX((tbl_lista_mestra[Codigo]=C28)*(tbl_lista_mestra[Estado]<>"Obsoleto"),0),0)),"") -> 01 | G28: =IF(F28="","?",IF(E28=F28,"Sim","Não")) -> Sim | H28: EL-03 | I28: NOK | J28: Cópia impressa sem assinatura de aprovação.
A29: VD-05 | B29: 46281 | C29: PR-SGA-05 | D29: Portaria | E29: 01 | F29: =IFERROR(INDEX(tbl_lista_mestra[Versao],MATCH(1,INDEX((tbl_lista_mestra[Codigo]=C29)*(tbl_lista_mestra[Estado]<>"Obsoleto"),0),0)),"") -> 01 | G29: =IF(F29="","?",IF(E29=F29,"Sim","Não")) -> Sim | H29: EL-04 | I29: OK
A30: VD-05 | B30: 46281 | C30: PR-SGA-05 | D30: Portaria | E30: 01 | F30: =IFERROR(INDEX(tbl_lista_mestra[Versao],MATCH(1,INDEX((tbl_lista_mestra[Codigo]=C30)*(tbl_lista_mestra[Estado]<>"Obsoleto"),0),0)),"") -> 01 | G30: =IF(F30="","?",IF(E30=F30,"Sim","Não")) -> Sim | H30: EL-05 | I30: OK
A31: VD-05 | B31: 46281 | C31: PR-SGA-05 | D31: Portaria | E31: 01 | F31: =IFERROR(INDEX(tbl_lista_mestra[Versao],MATCH(1,INDEX((tbl_lista_mestra[Codigo]=C31)*(tbl_lista_mestra[Estado]<>"Obsoleto"),0),0)),"") -> 01 | G31: =IF(F31="","?",IF(E31=F31,"Sim","Não")) -> Sim | H31: EL-06 | I31: OK

Sheet Resumo_Atividade_4_2
A1: ATIVIDADE 4.2 — COMUNICAÇÃO (4 Q) E CONTROLO DOCUMENTAL
A3: 1. COMUNICAÇÃO
A4: Cenário | B4: =INDEX(Matriz_Comunicacao!$C$5:$C$12,MATCH("COM-01",Matriz_Comunicacao!$A$5:$A$12,0)) -> Divulgar a nova Política Ambiental (rev. 02, 2026)
A5: O Quê? (mensagem) | B5: =INDEX(Matriz_Comunicacao!$D$5:$D$12,MATCH("COM-01",Matriz_Comunicacao!$A$5:$A$12,0)) -> O que muda na Política Ambiental rev. 02: 7 compromissos (incluindo perdas de granulado, biodiversidade e ciclo de vida) e o que cada trabalhador pode fazer no seu posto.
A6: A Quem? (público) | B6: =INDEX(Matriz_Comunicacao!$E$5:$E$12,MATCH("COM-01",Matriz_Comunicacao!$A$5:$A$12,0)) -> Todos os trabalhadores dos 3 turnos, temporários e prestadores de serviços residentes (≈ 160 pessoas).
A7: Quando? (momento) | B7: =INDEX(Matriz_Comunicacao!$F$5:$F$12,MATCH("COM-01",Matriz_Comunicacao!$A$5:$A$12,0)) -> Na semana seguinte à aprovação (22–26/06/2026); depois no acolhimento de cada novo trabalhador e sempre que a política for revista.
A8: Como? (canal) | B8: =INDEX(Matriz_Comunicacao!$G$5:$G$12,MATCH("COM-01",Matriz_Comunicacao!$A$5:$A$12,0)) -> Sessões de 10 min no início de cada turno (toolbox), cartaz A3 em cada área e na cantina, publicação no ecrã da entrada e intranet, e cópia no manual de acolhimento.
A9: Porquê? (objetivo) | B9: =INDEX(Matriz_Comunicacao!$H$5:$H$12,MATCH("COM-01",Matriz_Comunicacao!$A$5:$A$12,0)) -> Garantir que todos conhecem a política e o seu papel (7.3) e recolher ideias de melhoria (7.4, ISO 14001:2026).
A10: Responsável | B10: =INDEX(Matriz_Comunicacao!$I$5:$I$12,MATCH("COM-01",Matriz_Comunicacao!$A$5:$A$12,0)) -> Gestor do SGA / EHS (Responsável Ambiental)
A11: Participação / feedback | B11: =INDEX(Matriz_Comunicacao!$K$5:$K$12,MATCH("COM-01",Matriz_Comunicacao!$A$5:$A$12,0)) -> Caixa de sugestões e QR code no cartaz para ideias Kaizen; 3 perguntas de compreensão no fim da sessão.
A12: Evidência | B12: =INDEX(Matriz_Comunicacao!$L$5:$L$12,MATCH("COM-01",Matriz_Comunicacao!$A$5:$A$12,0)) -> Folhas de presença por turno; fotografias dos cartazes; resultados do questionário.
A13: Alcance atingido | B13: =INDEX(Matriz_Comunicacao!$Q$5:$Q$12,MATCH("COM-01",Matriz_Comunicacao!$A$5:$A$12,0)) -> 0.93125
A15: 2. CONTROLO DOCUMENTAL — 3 elementos obrigatórios (ex.: Procedimento de Resíduos PR-SGA-04)
A16: =INDEX(tbl_elementos[Elemento],1) -> Identificação: título e código únicos | B16: =INDEX(tbl_elementos[Porque],1) -> Garante que se sabe exatamente que documento é e que não é confundido com outro.
A17: =INDEX(tbl_elementos[Elemento],2) -> Estado de revisão: n.º de versão/revisão e data de emissão | B17: =INDEX(tbl_elementos[Porque],2) -> Permite confirmar que é a versão mais recente (comparar com a lista mestra).
A18: =INDEX(tbl_elementos[Elemento],3) -> Aprovação: quem aprovou e quando (assinatura/validação eletrónica) | B18: =INDEX(tbl_elementos[Porque],3) -> Só documentos aprovados por pessoa autorizada podem ser usados.

Sheet Comunicacoes_Externas
A1: REGISTO DE COMUNICAÇÕES EXTERNAS (7.4.3)
A2: Complementa a Matriz_Comunicacao (plano): aqui fica cada comunicação real, com prazo e resposta · Reclamações ligam a incidentes e NC
A4: ID_Com_Ext | B4: Data | C4: Sentido | D4: Parte_Interessada | E4: Canal | F4: Assunto | G4: Tipo | H4: Tema | I4: ID_Incidente | J4: Prazo_Resposta | K4: Data_Resposta_Envio | L4: Responsavel | M4: ID_NC | N4: ID_PAM | O4: Estado | P4: Dias_Resposta | Q4: No_Prazo
A5: COM-EXT-2025-01 | B5: 45744 | C5: Enviada | D5: APA / CCDR Centro | E5: SILiAmb | F5: Submissão do MIRR 2024 | G5: Relatório legal | H5: Resíduos | J5: 45747 | K5: 45744 | L5: Diretor Geral (Gestão de Topo) | O5: Fechada | P5: =IF(OR(K5="",C5="Enviada"),"",K5-B5) | Q5: =IF(J5="","",IF(K5="",IF(DataRef>J5,"Atrasada","Em curso"),IF(K5<=J5,"Sim","Não"))) -> Sim
A6: COM-EXT-2025-02 | B6: 45789 | C6: Recebida | D6: Clientes de cosmética (marcas UE) | E6: E-mail | F6: Questionário EcoVadis (marca A) | G6: Questionário ESG | H6: Clima; circularidade | J6: 45823 | K6: 45818 | L6: Diretor Geral (Gestão de Topo) | O6: Fechada | P6: =IF(OR(K6="",C6="Enviada"),"",K6-B6) -> 29 | Q6: =IF(J6="","",IF(K6="",IF(DataRef>J6,"Atrasada","Em curso"),IF(K6<=J6,"Sim","Não"))) -> Sim
A7: COM-EXT-2025-03 | B7: 45834 | C7: Recebida | D7: Comunidade / vizinhança | E7: Telefone | F7: Reclamação de odor a solvente | G7: Reclamação | H7: Ar | I7: INC-2025-04 | J7: 45841 | K7: 45838 | L7: Diretor Geral (Gestão de Topo) | O7: Fechada | P7: =IF(OR(K7="",C7="Enviada"),"",K7-B7) -> 4 | Q7: =IF(J7="","",IF(K7="",IF(DataRef>J7,"Atrasada","Em curso"),IF(K7<=J7,"Sim","Não"))) -> Sim
A8: COM-EXT-2025-04 | B8: 45838 | C8: Enviada | D8: Comunidade / vizinhança | E8: Carta | F8: Resposta ao reclamante com medidas tomadas | G8: Resposta | H8: Ar | I8: INC-2025-04 | K8: 45838 | L8: Diretor Geral (Gestão de Topo) | O8: Fechada | P8: =IF(OR(K8="",C8="Enviada"),"",K8-B8) | Q8: =IF(J8="","",IF(K8="",IF(DataRef>J8,"Atrasada","Em curso"),IF(K8<=J8,"Sim","Não")))
A9: COM-EXT-2025-05 | B9: 45881 | C9: Enviada | D9: Entidade gestora de água e saneamento | E9: E-mail + telefone | F9: Notificação de descarga anómala de biocida | G9: Notificação | H9: Água | I9: INC-2025-06 | J9: 45881 | K9: 45881 | L9: Gerente de Manutenção | O9: Fechada | P9: =IF(OR(K9="",C9="Enviada"),"",K9-B9) | Q9: =IF(J9="","",IF(K9="",IF(DataRef>J9,"Atrasada","Em curso"),IF(K9<=J9,"Sim","Não"))) -> Sim
A10: COM-EXT-2025-06 | B10: 45889 | C10: Recebida | D10: Entidade gestora de água e saneamento | E10: Ofício | F10: Pedido de boletim analítico extraordinário | G10: Pedido de informação | H10: Água | I10: INC-2025-06 | J10: 45905 | K10: 45902 | L10: Gerente de Manutenção | O10: Fechada | P10: =IF(OR(K10="",C10="Enviada"),"",K10-B10) -> 13 | Q10: =IF(J10="","",IF(K10="",IF(DataRef>J10,"Atrasada","Em curso"),IF(K10<=J10,"Sim","Não"))) -> Sim
A11: COM-EXT-2025-07 | B11: 45915 | C11: Recebida | D11: Clientes de cosmética (marcas UE) | E11: Portal CDP | F11: Questionário CDP Supply Chain (marca B) | G11: Questionário ESG | H11: Clima | J11: 45961 | K11: 45958 | L11: Diretor Geral (Gestão de Topo) | O11: Fechada | P11: =IF(OR(K11="",C11="Enviada"),"",K11-B11) -> 43 | Q11: =IF(J11="","",IF(K11="",IF(DataRef>J11,"Atrasada","Em curso"),IF(K11<=J11,"Sim","Não"))) -> Sim
A12: COM-EXT-2025-08 | B12: 45981 | C12: Enviada | D12: APA / CCDR Centro | E12: Plataforma F-gas | F12: Comunicação de fuga e reparação do CH-01 | G12: Relatório legal | H12: Clima | I12: INC-2025-07 | J12: 46022 | K12: 45989 | L12: Gerente de Manutenção | M12: NC-SGA-25-03 | O12: Fechada | P12: =IF(OR(K12="",C12="Enviada"),"",K12-B12) | Q12: =IF(J12="","",IF(K12="",IF(DataRef>J12,"Atrasada","Em curso"),IF(K12<=J12,"Sim","Não"))) -> Sim
A13: COM-EXT-2026-01 | B13: 46057 | C13: Enviada | D13: Câmara Municipal da Marinha Grande | E13: SIR / ePortugal | F13: Comunicação da substituição dos compressores (LEG-02) | G13: Notificação | H13: Licenciamento | K13: 46057 | L13: Diretor Industrial | O13: Fechada | P13: =IF(OR(K13="",C13="Enviada"),"",K13-B13) | Q13: =IF(J13="","",IF(K13="",IF(DataRef>J13,"Atrasada","Em curso"),IF(K13<=J13,"Sim","Não")))
A14: COM-EXT-2026-02 | B14: 46099 | C14: Enviada | D14: APA / CCDR Centro | E14: SILiAmb | F14: Submissão do MIRR 2025 | G14: Relatório legal | H14: Resíduos | J14: 46112 | K14: 46099 | L14: Diretor Geral (Gestão de Topo) | O14: Fechada | P14: =IF(OR(K14="",C14="Enviada"),"",K14-B14) | Q14: =IF(J14="","",IF(K14="",IF(DataRef>J14,"Atrasada","Em curso"),IF(K14<=J14,"Sim","Não"))) -> Sim
A15: COM-EXT-2026-03 | B15: 46106 | C15: Enviada | D15: APA / CCDR Centro | E15: E-mail | F15: Resultados da monitorização da chaminé FP1 | G15: Relatório legal | H15: Ar | J15: 46142 | K15: 46106 | L15: Diretor Geral (Gestão de Topo) | O15: Fechada | P15: =IF(OR(K15="",C15="Enviada"),"",K15-B15) | Q15: =IF(J15="","",IF(K15="",IF(DataRef>J15,"Atrasada","Em curso"),IF(K15<=J15,"Sim","Não"))) -> Sim
A16: COM-EXT-2026-04 | B16: 46121 | C16: Recebida | D16: Clientes alimentar e farmacêutico | E16: E-mail | F16: Pedido de declaração de ausência de PFAS e de conformidade para contacto alimentar | G16: Pedido de informação | H16: Substâncias | J16: 46142 | K16: 46139 | L16: Gerente da Qualidade | O16: Fechada | P16: =IF(OR(K16="",C16="Enviada"),"",K16-B16) -> 18 | Q16: =IF(J16="","",IF(K16="",IF(DataRef>J16,"Atrasada","Em curso"),IF(K16<=J16,"Sim","Não"))) -> Sim
A17: COM-EXT-2026-05 | B17: 46148 | C17: Recebida | D17: Clientes de cosmética (marcas UE) | E17: E-mail | F17: Pedido de declarações PPWR para 7 famílias | G17: Pedido de informação | H17: Embalagens | J17: 46234 | K17: 46378 | L17: Responsável de R&D | N17: PAM-26-10 | O17: Fechada | P17: =IF(OR(K17="",C17="Enviada"),"",K17-B17) -> 230 | Q17: =IF(J17="","",IF(K17="",IF(DataRef>J17,"Atrasada","Em curso"),IF(K17<=J17,"Sim","Não"))) -> Não
A18: COM-EXT-2026-06 | B18: 46162 | C18: Recebida | D18: Clientes de cosmética (marcas UE) | E18: E-mail | F18: Questionário EcoVadis (marca C) | G18: Questionário ESG | H18: Clima; circularidade | J18: 46193 | K18: 46191 | L18: Diretor Geral (Gestão de Topo) | O18: Fechada | P18: =IF(OR(K18="",C18="Enviada"),"",K18-B18) -> 29 | Q18: =IF(J18="","",IF(K18="",IF(DataRef>J18,"Atrasada","Em curso"),IF(K18<=J18,"Sim","Não"))) -> Sim
A19: COM-EXT-2026-07 | B19: 46178 | C19: Recebida | D19: Seguradora / banco | E19: Visita | F19: Visita de risco da seguradora: plano de retenção das águas de combate | G19: Pedido de informação | H19: Emergência | J19: 46208 | K19: 46205 | L19: Diretor Industrial | O19: Fechada | P19: =IF(OR(K19="",C19="Enviada"),"",K19-B19) -> 27 | Q19: =IF(J19="","",IF(K19="",IF(DataRef>J19,"Atrasada","Em curso"),IF(K19<=J19,"Sim","Não"))) -> Sim
A20: COM-EXT-2026-08 | B20: 46196 | C20: Recebida | D20: Comunidade / vizinhança | E20: Formulário do site | F20: Reclamação de ruído noturno (compressores) | G20: Reclamação | H20: Ruído | I20: INC-2026-06 | J20: 46203 | K20: 46202 | L20: Diretor Geral (Gestão de Topo) | M20: NC-SGA-26-01 | N20: PAM-26-03 | O20: Respondida | P20: =IF(OR(K20="",C20="Enviada"),"",K20-B20) -> 6 | Q20: =IF(J20="","",IF(K20="",IF(DataRef>J20,"Atrasada","Em curso"),IF(K20<=J20,"Sim","Não"))) -> Sim
A21: COM-EXT-2026-09 | B21: 46211 | C21: Recebida | D21: Comunidade / vizinhança | E21: Telefone | F21: Segunda reclamação de ruído noturno | G21: Reclamação | H21: Ruído | I21: INC-2026-07 | J21: 46218 | K21: 46220 | L21: Diretor Geral (Gestão de Topo) | M21: NC-SGA-26-01 | N21: PAM-26-03 | O21: Respondida | P21: =IF(OR(K21="",C21="Enviada"),"",K21-B21) -> 9 | Q21: =IF(J21="","",IF(K21="",IF(DataRef>J21,"Atrasada","Em curso"),IF(K21<=J21,"Sim","Não"))) -> Não
A22: COM-EXT-2026-10 | B22: 46220 | C22: Enviada | D22: Comunidade / vizinhança | E22: Carta + reunião | F22: Resposta: avaliação acústica acreditada contratada e prazo das medidas | G22: Resposta | H22: Ruído | I22: INC-2026-07 | K22: 46220 | L22: Diretor Geral (Gestão de Topo) | N22: PAM-26-03 | O22: Fechada | P22: =IF(OR(K22="",C22="Enviada"),"",K22-B22) | Q22: =IF(J22="","",IF(K22="",IF(DataRef>J22,"Atrasada","Em curso"),IF(K22<=J22,"Sim","Não")))
A23: COM-EXT-2026-11 | B23: 46246 | C23: Enviada | D23: Clientes de cosmética (marcas UE) | E23: Newsletter | F23: Informação sobre a aplicação do PPWR e o plano da Plasticom | G23: Informação voluntária | H23: Embalagens | K23: 46246 | L23: Responsável de R&D | N23: PAM-26-10 | O23: Fechada | P23: =IF(OR(K23="",C23="Enviada"),"",K23-B23) | Q23: =IF(J23="","",IF(K23="",IF(DataRef>J23,"Atrasada","Em curso"),IF(K23<=J23,"Sim","Não")))
A24: COM-EXT-2026-12 | B24: 46267 | C24: Recebida | D24: Associação setorial (plásticos) | E24: E-mail | F24: Pedido do relatório anual Operation Clean Sweep | G24: Pedido de informação | H24: Granulado | J24: 46310 | K24: 46307 | L24: Diretor Geral (Gestão de Topo) | N24: PAM-26-11 | O24: Fechada | P24: =IF(OR(K24="",C24="Enviada"),"",K24-B24) -> 40 | Q24: =IF(J24="","",IF(K24="",IF(DataRef>J24,"Atrasada","Em curso"),IF(K24<=J24,"Sim","Não"))) -> Sim
A25: COM-EXT-2026-13 | B25: 46275 | C25: Recebida | D25: APA / CCDR Centro | E25: Ofício | F25: Campanha de fiscalização de e-GAR/MIRR: pedido de listagem de guias de 2026 | G25: Pedido de informação | H25: Resíduos | J25: 46305 | K25: 46303 | L25: Responsável de Armazém e Logística | O25: Fechada | P25: =IF(OR(K25="",C25="Enviada"),"",K25-B25) -> 28 | Q25: =IF(J25="","",IF(K25="",IF(DataRef>J25,"Atrasada","Em curso"),IF(K25<=J25,"Sim","Não"))) -> Sim
A26: COM-EXT-2026-14 | B26: 46331 | C26: Enviada | D26: Comunidade / vizinhança | E26: Carta | F26: Informação: avaliação acústica conforme e medidas implementadas nos compressores | G26: Resposta | H26: Ruído | I26: INC-2026-07 | K26: 46331 | L26: Diretor Geral (Gestão de Topo) | M26: NC-SGA-26-01 | N26: PAM-26-03 | O26: Fechada | P26: =IF(OR(K26="",C26="Enviada"),"",K26-B26) | Q26: =IF(J26="","",IF(K26="",IF(DataRef>J26,"Atrasada","Em curso"),IF(K26<=J26,"Sim","Não")))
A27: COM-EXT-2026-15 | B27: 46338 | C27: Recebida | D27: Clientes de cosmética (marcas UE) | E27: Portal CDP | F27: Questionário CDP Supply Chain 2026 (marca B) | G27: Questionário ESG | H27: Clima | J27: 46371 | K27: 46366 | L27: Diretor Geral (Gestão de Topo) | O27: Fechada | P27: =IF(OR(K27="",C27="Enviada"),"",K27-B27) -> 28 | Q27: =IF(J27="","",IF(K27="",IF(DataRef>J27,"Atrasada","Em curso"),IF(K27<=J27,"Sim","Não"))) -> Sim
A28: COM-EXT-2026-16 | B28: 46370 | C28: Recebida | D28: APA / CCDR Centro | E28: Ofício | F28: Resultado da fiscalização de e-GAR/MIRR: sem desconformidades | G28: Notificação | H28: Resíduos | L28: Responsável de Armazém e Logística | O28: Fechada | P28: =IF(OR(K28="",C28="Enviada"),"",K28-B28) | Q28: =IF(J28="","",IF(K28="",IF(DataRef>J28,"Atrasada","Em curso"),IF(K28<=J28,"Sim","Não")))
P29: =IF(OR(K29="",C29="Enviada"),"",K29-B29) | Q29: =IF(J29="","",IF(K29="",IF(DataRef>J29,"Atrasada","Em curso"),IF(K29<=J29,"Sim","Não")))
P30: =IF(OR(K30="",C30="Enviada"),"",K30-B30) | Q30: =IF(J30="","",IF(K30="",IF(DataRef>J30,"Atrasada","Em curso"),IF(K30<=J30,"Sim","Não")))
P31: =IF(OR(K31="",C31="Enviada"),"",K31-B31) | Q31: =IF(J31="","",IF(K31="",IF(DataRef>J31,"Atrasada","Em curso"),IF(K31<=J31,"Sim","Não")))
P32: =IF(OR(K32="",C32="Enviada"),"",K32-B32) | Q32: =IF(J32="","",IF(K32="",IF(DataRef>J32,"Atrasada","Em curso"),IF(K32<=J32,"Sim","Não")))
P33: =IF(OR(K33="",C33="Enviada"),"",K33-B33) | Q33: =IF(J33="","",IF(K33="",IF(DataRef>J33,"Atrasada","Em curso"),IF(K33<=J33,"Sim","Não")))
P34: =IF(OR(K34="",C34="Enviada"),"",K34-B34) | Q34: =IF(J34="","",IF(K34="",IF(DataRef>J34,"Atrasada","Em curso"),IF(K34<=J34,"Sim","Não")))
P35: =IF(OR(K35="",C35="Enviada"),"",K35-B35) | Q35: =IF(J35="","",IF(K35="",IF(DataRef>J35,"Atrasada","Em curso"),IF(K35<=J35,"Sim","Não")))
P36: =IF(OR(K36="",C36="Enviada"),"",K36-B36) | Q36: =IF(J36="","",IF(K36="",IF(DataRef>J36,"Atrasada","Em curso"),IF(K36<=J36,"Sim","Não")))
P37: =IF(OR(K37="",C37="Enviada"),"",K37-B37) | Q37: =IF(J37="","",IF(K37="",IF(DataRef>J37,"Atrasada","Em curso"),IF(K37<=J37,"Sim","Não")))
P38: =IF(OR(K38="",C38="Enviada"),"",K38-B38) | Q38: =IF(J38="","",IF(K38="",IF(DataRef>J38,"Atrasada","Em curso"),IF(K38<=J38,"Sim","Não")))
P39: =IF(OR(K39="",C39="Enviada"),"",K39-B39) | Q39: =IF(J39="","",IF(K39="",IF(DataRef>J39,"Atrasada","Em curso"),IF(K39<=J39,"Sim","Não")))
P40: =IF(OR(K40="",C40="Enviada"),"",K40-B40) | Q40: =IF(J40="","",IF(K40="",IF(DataRef>J40,"Atrasada","Em curso"),IF(K40<=J40,"Sim","Não")))
... P68: =IF(OR(K68="",C68="Enviada"),"",K68-B68) | Q68: =IF(J68="","",IF(K68="",IF(DataRef>J68,"Atrasada","Em curso"),IF(K68<=J68,"Sim","Não")))

Sheet Listas
A1: LISTAS CONTROLADAS (domínios de validação de dados) — editar aqui para alterar opções
A2: DataReferencia | B2: Tipo | C2: Funcao | D2: TipoDoc | E2: EstadoDoc | F2: OKNOK | G2: SimNao | H2: Processo | I2: CE_Sentido | J2: CE_Tipo | K2: CE_Estado
A3: 46387 | B3: Interna | C3: Diretor Geral (Gestão de Topo) | D3: Política | E3: Em vigor | F3: OK | G3: Sim | H3: REC | I3: Recebida | J3: Reclamação | K3: Aberta
B4: Externa | C4: Diretor Industrial | D4: Procedimento | E4: Em revisão | F4: NOK | G4: Não | H4: ARQ | I4: Enviada | J4: Pedido de informação | K4: Respondida
C5: Gestor do SGA / EHS (Responsável Ambiental) | D5: Instrução de trabalho | E5: Obsoleto | H5: INJ | J5: Questionário ESG | K5: Fechada
C6: Gerente de Produção | D6: Registo | H6: SOP | J6: Notificação
C7: Gerente de Manutenção | D7: Plano | H7: SER | J7: Relatório legal
C8: Gerente da Qualidade | D8: Modelo | H8: HFS | J8: Resposta
C9: Responsável de Armazém e Logística | H9: MOA | J9: Informação voluntária
C10: Responsável de Compras | H10: UTL
C11: Responsável de R&D | H11: MAN
C12: Responsável de Recursos Humanos | H12: PRS
C13: Diretor Financeiro | H13: EXP
C14: Operador de Serigrafia | H14: LAB
C15: Operador de Injeção | H15: RD
C16: Operador de Sopro (ISBM) | H16: CMP
C17: Operador de Hot Foil | H17: ADM
C18: Técnico de Manutenção | H18: GER
C19: Técnico de Utilidades
C20: Operador de Armazém / Empilhador
C21: Chefe de Turno
C22: Auditor Interno do SGA
C23: Representante dos Trabalhadores (SST/Ambiente)
C24: Técnico de Qualidade/Ambiente

Sheet Dicionario_Dados
A1: Folha | B1: Tabela | C1: Coluna | D1: Tipo | E1: Origem | F1: Descricao | G1: Dominio_Unidade | H1: Obrigatorio | I1: Chave
A2: Matriz_Comunicacao | B2: tbl_comunicacao | C2: ID_Comunicacao | D2: Texto | E2: Entrada | F2: Identificador. | H2: Sim | I2: PK
A3: Matriz_Comunicacao | B3: tbl_comunicacao | C3: Tipo | D3: Texto | E3: Entrada | F3: Interna ou externa. | G3: Lista lst_Tipo | H3: Sim
A4: Matriz_Comunicacao | B4: tbl_comunicacao | C4: Cenario | D4: Texto | E4: Entrada | F4: Cenário de comunicação. | H4: Sim
A5: Matriz_Comunicacao | B5: tbl_comunicacao | C5: O_Que_Mensagem | D5: Texto | E5: Entrada | F5: O quê? (mensagem) | H5: Sim
A6: Matriz_Comunicacao | B6: tbl_comunicacao | C6: A_Quem_Publico | D6: Texto | E6: Entrada | F6: A quem? (público) | H6: Sim
A7: Matriz_Comunicacao | B7: tbl_comunicacao | C7: Quando_Momento | D7: Texto | E7: Entrada | F7: Quando? (momento) | H7: Sim
A8: Matriz_Comunicacao | B8: tbl_comunicacao | C8: Como_Canal | D8: Texto | E8: Entrada | F8: Como? (canal) | H8: Sim
A9: Matriz_Comunicacao | B9: tbl_comunicacao | C9: Porque_Objetivo | D9: Texto | E9: Entrada | F9: Porquê? (objetivo da comunicação) | H9: Sim
A10: Matriz_Comunicacao | B10: tbl_comunicacao | C10: Responsavel | D10: Texto | E10: Entrada | F10: Quem comunica. | G10: Lista lst_Funcao | H10: Sim
A11: Matriz_Comunicacao | B11: tbl_comunicacao | C11: Clausula | D11: Texto | E11: Entrada | F11: Requisito ISO. | H11: Sim
A12: Matriz_Comunicacao | B12: tbl_comunicacao | C12: Participacao_Feedback | D12: Texto | E12: Entrada | F12: Como se recolhe feedback/participação (7.4, 2026). | H12: Sim
A13: Matriz_Comunicacao | B13: tbl_comunicacao | C13: Evidencia | D13: Texto | E13: Entrada | F13: Registo que prova a comunicação. | H13: Sim
A14: Matriz_Comunicacao | B14: tbl_comunicacao | C14: Data_Prevista | D14: Data (aaaa-mm-dd) | E14: Entrada | F14: Data prevista. | H14: Não
A15: Matriz_Comunicacao | B15: tbl_comunicacao | C15: Data_Realizada | D15: Data (aaaa-mm-dd) | E15: Entrada | F15: Data realizada. | H15: Não
A16: Matriz_Comunicacao | B16: tbl_comunicacao | C16: Alcance_Previsto | D16: Inteiro | E16: Entrada | F16: N.º de destinatários previsto. | H16: Sim
A17: Matriz_Comunicacao | B17: tbl_comunicacao | C17: Alcance_Real | D17: Inteiro | E17: Entrada | F17: N.º de destinatários atingidos. | H17: Sim
A18: Matriz_Comunicacao | B18: tbl_comunicacao | C18: Taxa_Alcance | D18: Percentagem (fração 0-1) | E18: Calculado (fórmula) | F18: Alcance real ÷ previsto. | H18: Sim
A19: Matriz_Comunicacao | B19: tbl_comunicacao | C19: Estado | D19: Texto | E19: Calculado (fórmula) | F19: Estado calculado. | H19: Sim
A20: Matriz_Comunicacao | B20: tbl_comunicacao | C20: Selecionado_Atv_4_2 | D20: Texto | E20: Entrada | F20: Cenário da Atividade 4.2. | G20: Lista lst_SimNao | H20: Sim
A21: Lista_Mestra | B21: tbl_lista_mestra | C21: Codigo | D21: Texto | E21: Entrada | F21: Código do documento. | H21: Sim | I21: PK (com Versao)
A22: Lista_Mestra | B22: tbl_lista_mestra | C22: Titulo | D22: Texto | E22: Entrada | F22: Título. | H22: Sim
A23: Lista_Mestra | B23: tbl_lista_mestra | C23: Tipo | D23: Texto | E23: Entrada | F23: Tipo. | G23: Lista lst_TipoDoc | H23: Sim
A24: Lista_Mestra | B24: tbl_lista_mestra | C24: Versao | D24: Texto | E24: Entrada | F24: Versão/revisão. | H24: Sim
A25: Lista_Mestra | B25: tbl_lista_mestra | C25: Data_Aprovacao | D25: Data (aaaa-mm-dd) | E25: Entrada | F25: Data de aprovação. | H25: Não
A26: Lista_Mestra | B26: tbl_lista_mestra | C26: Aprovador | D26: Texto | E26: Entrada | F26: Quem aprovou. | H26: Não
A27: Lista_Mestra | B27: tbl_lista_mestra | C27: Estado | D27: Texto | E27: Entrada | F27: Em vigor / Em revisão / Obsoleto. | G27: Lista lst_EstadoDoc | H27: Sim
A28: Lista_Mestra | B28: tbl_lista_mestra | C28: Substitui | D28: Texto | E28: Entrada | F28: Versão substituída. | H28: Não
A29: Lista_Mestra | B29: tbl_lista_mestra | C29: Localizacao | D29: Texto | E29: Entrada | F29: Onde está disponível. | H29: Sim
A30: Lista_Mestra | B30: tbl_lista_mestra | C30: Ponto_de_Uso | D30: Texto | E30: Entrada | F30: Onde é usado. | H30: Sim
A31: Lista_Mestra | B31: tbl_lista_mestra | C31: Clausula | D31: Texto | E31: Entrada | F31: Requisito ISO. | H31: Sim
A32: Lista_Mestra | B32: tbl_lista_mestra | C32: Proxima_Revisao | D32: Data (aaaa-mm-dd) | E32: Calculado (fórmula) | F32: Revisão a cada 24 meses. | H32: Sim
A33: Lista_Mestra | B33: tbl_lista_mestra | C33: Alerta | D33: Texto | E33: Calculado (fórmula) | F33: Alerta automático. | H33: Sim
A34: Elementos_Controlo | B34: tbl_elementos | C34: ID_Elemento | D34: Texto | E34: Entrada | F34: Elemento de controlo. | H34: Sim | I34: PK
A35: Elementos_Controlo | B35: tbl_elementos | C35: Elemento | D35: Texto | E35: Entrada | F35: O que verificar no documento. | H35: Sim
