Workbook
Name DataRef: Listas!$A$3
Name lst_DataReferencia: Listas!$A$3:$A$3
Name lst_Frequencia: Listas!$E$3:$E$6
Name lst_Funcao: Listas!$C$3:$C$28
Name lst_Polaridade: Listas!$D$3:$D$4
Name lst_Processo: Listas!$B$3:$B$20

Sheet 00_LEIA-ME
A1: RG-SGQ-05 — Objetivos da Qualidade, KPI e Plano de Monitorização e Medição
A2: Sistema de Gestão da Qualidade NP EN ISO 9001:2026 · Plasticom — Unidade 1 (Marinha Grande, Portugal) · Registo do SGQ (fábrica simulada)
A4: CONTROLO DO DOCUMENTO (7.5 — informação documentada)
A5: Código do registo | B5: RG-SGQ-05
A6: Título | B6: Objetivos da Qualidade, KPI e Plano de Monitorização e Medição
A7: Versão / Revisão | B7: 01
A8: Data de emissão | B8: 46387
A9: Elaborado por | B9: Gerente da Qualidade
A10: Aprovado por | B10: Diretor Geral
A11: Estado | B11: Em vigor
A12: Retenção | B12: 5 anos após substituição
A13: Localização | B13: Repositório controlado do SGQ > Registos_SGQ_Plasticom (a versão eletrónica é a controlada; cópias impressas são não controladas). Proteção contra alterações não intencionais (7.5.3.2): edição só pelo dono do registo; histórico de versões no repositório.
A15: FINALIDADE E ÂMBITO
A16: Finalidade | B16: Base mensal de desempenho da qualidade 2025-07 a 2026-12 agregada do dataset (produção, lotes, vendas, reclamações, matérias-primas, fornecedores, CAPA, SPC) e 13 KPI mensais calculados por fórmula, com painel de estado face às metas, objetivos SMART com o plano 6.2.2 e o plano de monitorização e medição 9.1.1.
A17: Utilização / atividades | B17: Estabelecer objetivos da qualidade mensuráveis e o planeamento para os atingir; definir o que se monitoriza, como, quando se mede e quando se analisa; acompanhar os KPI mensais.
A18: Requisitos ISO 9001:2026 | B18: 6.2.1 a)–h) Objetivos da qualidade (disponíveis como informação documentada); 6.2.2 a)–e) planeamento; 9.1.1 a)–d) monitorização e medição (evidência dos resultados); 9.1.3 análise e avaliação; 5.1.1 e)
A20: REFERÊNCIAS DE BOAS PRÁTICAS APLICADAS (orientação — não são requisitos auditáveis da ISO 9001)
A21: ISO/TC 176 APG — Policy and objectives | B21: Objetivos mensuráveis, com responsável, prazo, recursos e método de avaliação — tbl_objetivos colunas 6.2.2 a)–e).
A22: Academy — cap. 157 (VoC → CTQ → KPI) e cap. 180 (DPU, DPMO, FPY) | B22: Ligação cliente → CTQ → KPI → meta; métricas de rendimento.
A23: iso9001help.co.uk — Monitoring and measurement | B23: Plano de monitorização com o quê/como/quando medir/quando analisar e registo da evidência.
A25: ESTRUTURA DO FICHEIRO
A26: Base_Mensal | B26: Base mensal de desempenho agregada do dataset (factos de entrada dos KPI).
A27: KPI_Mensal | B27: KPI mensais calculados por fórmula a partir da base mensal (9.1.1 — evidência dos resultados).
A28: Catalogo_KPI | B28: Catálogo de indicadores do SGQ (definição, meta, dono, fonte).
A29: Painel_KPI | B29: Painel calculado: último mês, média de 12 meses, tendência de 6 meses e estado face à meta de cada KPI mensal; gráficos.
A30: Objetivos_Qualidade | B30: Objetivos da qualidade e planeamento para os atingir (6.2.1 e 6.2.2).
A31: Plano_Monitorizacao | B31: Plano de monitorização, medição, análise e avaliação (9.1.1 a–d) — mesma estrutura do RG-SGA-13.
A32: Listas | B32: Domínios (listas de valores) usados na validação de dados das tabelas.
A33: Dicionario_Dados | B33: Descrição de cada coluna de cada tabela: tipo, origem (entrada/calculado), domínio, obrigatoriedade e chaves.
A35: CONVENÇÕES (prontas para análise de dados e machine learning)
A36: Tabelas | B36: Cada registo é uma Tabela Excel com nome próprio (tbl_*): uma linha = um registo, cabeçalho único, sem células mescladas. Ler com pandas (pd.read_excel(ficheiro, sheet_name=folha, header=<linha do cabeçalho - 1>)) ou Power BI (Obter Dados > Tabela).
A37: Cabeçalho cinzento | B37: Coluna CALCULADA por fórmula — não escrever por cima. As restantes colunas são de entrada.
A38: Validação | B38: Colunas com lista controlada só aceitam valores da folha Listas (evita categorias duplicadas por grafia diferente).
A39: Chaves | B39: IDs estáveis e únicos (PK) e referências a IDs de outros registos (FK) permitem juntar tabelas entre ficheiros do SGQ e do SGA — ver SGQ-00_Indice_Modelo_Dados.xlsx.
A40: Datas e unidades | B40: Datas em formato data (aaaa-mm-dd); números como números; a unidade está no nome da coluna ou no dicionário. Data de referência do SGQ: 2026-12-31.
A41: Dados | B41: Fábrica simulada Plasticom. Dados operacionais e de qualidade extraídos do dataset do projeto (datasets/silver e datasets/dim, período 2025-07-01 a 2026-12-31); os campos de gestão que o dataset não tem (datas de resposta, avaliações, decisões) são simulação didática coerente com esses dados.
A43: LIGAÇÕES A OUTROS REGISTOS
A44: RG-SGQ-03 Política | B44: Cada objetivo liga a um compromisso da política (6.2.1 a).
A45: RG-SGQ-04 | B45: KPI usados para avaliar a eficácia das ações de risco.
A46: RG-SGQ-15 / RG-SGQ-19 | B46: KPI semestrais (CSI, NPS) e custo da qualidade.
...

Sheet Base_Mensal
A1: BASE MENSAL DE DESEMPENHO DA QUALIDADE — dados do dataset
A2: 2025-07-01 a 2026-12-31 · Uma linha por mês · Linhas_OTIF é simulado (o dataset não tem data prometida)
A4: Mes | B4: Produzido | C4: Rejeitado | D4: OEE_Soma | E4: Ordens | F4: Lotes_Decididos | G4: Lotes_1a | H4: Lotes_Concessao | I4: Lotes_Rejeitados | J4: Expedido | K4: Vendas_EUR | L4: Linhas_Expedidas | M4: Reclamacoes | N4: Reclamacoes_Servico | O4: Qtd_Afetada | P4: Reclamacoes_Criticas | Q4: Reclamacoes_Resolvidas | R4: Dias_Resolucao_Soma | S4: Lotes_MP | T4: Lotes_MP_Aceites | U4: SCAR | V4: Dias_Resposta_SCAR_Soma | W4: CAPA_Com_Prazo | X4: CAPA_Fechadas_No_Prazo | Y4: CAPA_Eficazes | Z4: CAPA_Nao_Eficazes | AA4: Subgrupos_SPC | AB4: Subgrupos_Cpk_1 | AC4: Linhas_OTIF
A5: 2025-07 | B5: 6350668 | C5: 147226 | D5: 674.49277 | E5: 867 | F5: 446 | G5: 387 | H5: 5 | I5: 47 | J5: 2125724 | K5: 283228.32 | L5: 374 | M5: 1 | N5: 0 | O5: 36 | P5: 0 | Q5: 0 | R5: 0 | S5: 104 | T5: 91 | U5: 8 | V5: 67 | W5: 0 | X5: 0 | Y5: 2 | Z5: 1 | AA5: 16473 | AB5: 7660 | AC5: 365
A6: 2025-08 | B6: 6363215 | C6: 149045 | D6: 633.10554 | E6: 822 | F6: 434 | G6: 370 | H6: 10 | I6: 46 | J6: 2517293 | K6: 318985.93 | L6: 445 | M6: 14 | N6: 10 | O6: 795 | P6: 4 | Q6: 4 | R6: 55 | S6: 102 | T6: 97 | U6: 1 | V6: 4 | W6: 33 | X6: 11 | Y6: 9 | Z6: 11 | AA6: 16195 | AB6: 7453 | AC6: 428
A7: 2025-09 | B7: 6007651 | C7: 152258 | D7: 646.70451 | E7: 841 | F7: 437 | G7: 371 | H7: 11 | I7: 48 | J7: 2330795 | K7: 297387.18 | L7: 438 | M7: 9 | N7: 4 | O7: 492 | P7: 4 | Q7: 8 | R7: 192 | S7: 101 | T7: 88 | U7: 6 | V7: 36 | W7: 49 | X7: 25 | Y7: 9 | Z7: 12 | AA7: 15671 | AB7: 7436 | AC7: 420
A8: 2025-10 | B8: 6140692 | C8: 143964 | D8: 681.6514 | E8: 892 | F8: 494 | G8: 424 | H8: 15 | I8: 51 | J8: 2567553 | K8: 323233.56 | L8: 491 | M8: 14 | N8: 8 | O8: 439 | P8: 5 | Q8: 9 | R8: 143 | S8: 114 | T8: 107 | U8: 4 | V8: 25 | W8: 44 | X8: 15 | Y8: 13 | Z8: 13 | AA8: 16244 | AB8: 7569 | AC8: 472
A9: 2025-11 | B9: 5970750 | C9: 144066 | D9: 640.68827 | E9: 841 | F9: 439 | G9: 372 | H9: 6 | I9: 52 | J9: 2422140 | K9: 322056.36 | L9: 455 | M9: 10 | N9: 7 | O9: 333 | P9: 1 | Q9: 12 | R9: 235 | S9: 102 | T9: 92 | U9: 2 | V9: 13 | W9: 45 | X9: 24 | Y9: 11 | Z9: 9 | AA9: 15722 | AB9: 7357 | AC9: 434
A10: 2025-12 | B10: 6132928 | C10: 143227 | D10: 644.63287 | E10: 852 | F10: 442 | G10: 393 | H10: 5 | I10: 39 | J10: 2520321 | K10: 318200.07 | L10: 472 | M10: 23 | N10: 11 | O10: 1194 | P10: 5 | Q10: 12 | R10: 170 | S10: 116 | T10: 100 | U10: 7 | V10: 47 | W10: 56 | X10: 31 | Y10: 20 | Z10: 12 | AA10: 16252 | AB10: 7539 | AC10: 450
A11: 2026-01 | B11: 6038474 | C11: 141818 | D11: 625.90893 | E11: 817 | F11: 426 | G11: 368 | H11: 6 | I11: 49 | J11: 2719061 | K11: 318417.75 | L11: 480 | M11: 8 | N11: 4 | O11: 711 | P11: 3 | Q11: 11 | R11: 211 | S11: 103 | T11: 90 | U11: 6 | V11: 33 | W11: 39 | X11: 21 | Y11: 7 | Z11: 8 | AA11: 16273 | AB11: 7774 | AC11: 465
A12: 2026-02 | B12: 5579581 | C12: 127878 | D12: 582.32638 | E12: 757 | F12: 389 | G12: 330 | H12: 5 | I12: 51 | J12: 2195928 | K12: 295454 | L12: 397 | M12: 9 | N12: 5 | O12: 493 | P12: 3 | Q12: 9 | R12: 177 | S12: 92 | T12: 84 | U12: 2 | V12: 7 | W12: 30 | X12: 13 | Y12: 9 | Z12: 13 | AA12: 14704 | AB12: 6738 | AC12: 380
A13: 2026-03 | B13: 6350526 | C13: 159141 | D13: 651.15848 | E13: 851 | F13: 439 | G13: 375 | H13: 8 | I13: 49 | J13: 2259115 | K13: 291820.89 | L13: 430 | M13: 10 | N13: 4 | O13: 669 | P13: 2 | Q13: 12 | R13: 226 | S13: 99 | T13: 85 | U13: 7 | V13: 47 | W13: 37 | X13: 23 | Y13: 13 | Z13: 10 | AA13: 16342 | AB13: 7591 | AC13: 410
A14: 2026-04 | B14: 5787874 | C14: 143082 | D14: 619.96431 | E14: 831 | F14: 440 | G14: 390 | H14: 6 | I14: 36 | J14: 2593176 | K14: 312343.62 | L14: 458 | M14: 15 | N14: 6 | O14: 662 | P14: 5 | Q14: 10 | R14: 130 | S14: 104 | T14: 96 | U14: 5 | V14: 28 | W14: 56 | X14: 24 | Y14: 17 | Z14: 6 | AA14: 15617 | AB14: 7300 | AC14: 436
A15: 2026-05 | B15: 6169185 | C15: 151027 | D15: 669.52172 | E15: 877 | F15: 441 | G15: 373 | H15: 3 | I15: 59 | J15: 2456771 | K15: 295775.6 | L15: 454 | M15: 15 | N15: 12 | O15: 771 | P15: 1 | Q15: 9 | R15: 186 | S15: 112 | T15: 98 | U15: 6 | V15: 30 | W15: 43 | X15: 25 | Y15: 12 | Z15: 8 | AA15: 16148 | AB15: 7437 | AC15: 432
A16: 2026-06 | B16: 5838345 | C16: 134597 | D16: 619.3318 | E16: 816 | F16: 430 | G16: 371 | H16: 8 | I16: 47 | J16: 2475345 | K16: 332360.25 | L16: 449 | M16: 10 | N16: 4 | O16: 410 | P16: 2 | Q16: 10 | R16: 248 | S16: 102 | T16: 92 | U16: 4 | V16: 28 | W16: 37 | X16: 16 | Y16: 13 | Z16: 10 | AA16: 15707 | AB16: 7272 | AC16: 439
... A22: 2026-12 | B22: 7862818 | C22: 177003 | D22: 766.14211 | E22: 1026 | F22: 540 | G22: 459 | H22: 5 | I22: 71 | J22: 2855835 | K22: 376749.74 | L22: 518 | M22: 12 | N22: 4 | O22: 632 | P22: 4 | Q22: 13 | R22: 255 | S22: 103 | T22: 92 | U22: 4 | V22: 35 | W22: 56 | X22: 30 | Y22: 13 | Z22: 15 | AA22: 21234 | AB22: 9403 | AC22: 500

Sheet KPI_Mensal
A1: KPI MENSAIS DA QUALIDADE — calculados
A2: Todas as colunas são fórmulas sobre tbl_base_mensal · Metas e estado no Painel_KPI
A4: Mes | B4: Taxa_Rejeicao | C4: FPY_Lotes | D4: PPM_Cliente | E4: CPMU | F4: Reclamacoes_Servico | G4: Dias_Resolucao | H4: OEE | I4: Lotes_MP_Aceites | J4: Dias_Resposta_SCAR | K4: CAPA_No_Prazo | L4: CAPA_Eficacia | M4: Taxa_Concessao | N4: Pct_Cpk_1 | O4: OTIF
A5: 2025-07 | B5: =IFERROR(INDEX(tbl_base_mensal[Rejeitado],MATCH(A5,tbl_base_mensal[Mes],0))/INDEX(tbl_base_mensal[Produzido],MATCH(A5,tbl_base_mensal[Mes],0)),"") -> 0.023182758 | C5: =IFERROR(INDEX(tbl_base_mensal[Lotes_1a],MATCH(A5,tbl_base_mensal[Mes],0))/INDEX(tbl_base_mensal[Lotes_Decididos],MATCH(A5,tbl_base_mensal[Mes],0)),"") -> 0.867713 | D5: =IFERROR(INDEX(tbl_base_mensal[Qtd_Afetada],MATCH(A5,tbl_base_mensal[Mes],0))/INDEX(tbl_base_mensal[Expedido],MATCH(A5,tbl_base_mensal[Mes],0))*1000000,"") -> 16.935406 | E5: =IFERROR(INDEX(tbl_base_mensal[Reclamacoes],MATCH(A5,tbl_base_mensal[Mes],0))/INDEX(tbl_base_mensal[Expedido],MATCH(A5,tbl_base_mensal[Mes],0))*1000000,"") -> 0.47042796 | F5: =INDEX(tbl_base_mensal[Reclamacoes_Servico],MATCH(A5,tbl_base_mensal[Mes],0)) -> 0 | G5: =IFERROR(INDEX(tbl_base_mensal[Dias_Resolucao_Soma],MATCH(A5,tbl_base_mensal[Mes],0))/INDEX(tbl_base_mensal[Reclamacoes_Resolvidas],MATCH(A5,tbl_base_mensal[Mes],0)),"") | H5: =IFERROR(INDEX(tbl_base_mensal[OEE_Soma],MATCH(A5,tbl_base_mensal[Mes],0))/INDEX(tbl_base_mensal[Ordens],MATCH(A5,tbl_base_mensal[Mes],0)),"") -> 0.77796168 | I5: =IFERROR(INDEX(tbl_base_mensal[Lotes_MP_Aceites],MATCH(A5,tbl_base_mensal[Mes],0))/INDEX(tbl_base_mensal[Lotes_MP],MATCH(A5,tbl_base_mensal[Mes],0)),"") -> 0.875 | J5: =IFERROR(INDEX(tbl_base_mensal[Dias_Resposta_SCAR_Soma],MATCH(A5,tbl_base_mensal[Mes],0))/INDEX(tbl_base_mensal[SCAR],MATCH(A5,tbl_base_mensal[Mes],0)),"") -> 8.375 | K5: =IFERROR(INDEX(tbl_base_mensal[CAPA_Fechadas_No_Prazo],MATCH(A5,tbl_base_mensal[Mes],0))/INDEX(tbl_base_mensal[CAPA_Com_Prazo],MATCH(A5,tbl_base_mensal[Mes],0)),"") | L5: =IFERROR(INDEX(tbl_base_mensal[CAPA_Eficazes],MATCH(A5,tbl_base_mensal[Mes],0))/(INDEX(tbl_base_mensal[CAPA_Eficazes],MATCH(A5,tbl_base_mensal[Mes],0))+INDEX(tbl_base_mensal[CAPA_Nao_Eficazes],MATCH(A5,tbl_base_mensal[Mes],0))),"") -> 0.66666667 | M5: =IFERROR(INDEX(tbl_base_mensal[Lotes_Concessao],MATCH(A5,tbl_base_mensal[Mes],0))/INDEX(tbl_base_mensal[Lotes_Decididos],MATCH(A5,tbl_base_mensal[Mes],0)),"") -> 0.011210762 | N5: =IFERROR(INDEX(tbl_base_mensal[Subgrupos_Cpk_1],MATCH(A5,tbl_base_mensal[Mes],0))/INDEX(tbl_base_mensal[Subgrupos_SPC],MATCH(A5,tbl_base_mensal[Mes],0)),"") -> 0.46500334 | O5: =IFERROR(INDEX(tbl_base_mensal[Linhas_OTIF],MATCH(A5,tbl_base_mensal[Mes],0))/INDEX(tbl_base_mensal[Linhas_Expedidas],MATCH(A5,tbl_base_mensal[Mes],0)),"") -> 0.97593583
A6: 2025-08 | B6: =IFERROR(INDEX(tbl_base_mensal[Rejeitado],MATCH(A6,tbl_base_mensal[Mes],0))/INDEX(tbl_base_mensal[Produzido],MATCH(A6,tbl_base_mensal[Mes],0)),"") -> 0.023422908 | C6: =IFERROR(INDEX(tbl_base_mensal[Lotes_1a],MATCH(A6,tbl_base_mensal[Mes],0))/INDEX(tbl_base_mensal[Lotes_Decididos],MATCH(A6,tbl_base_mensal[Mes],0)),"") -> 0.85253456 | D6: =IFERROR(INDEX(tbl_base_mensal[Qtd_Afetada],MATCH(A6,tbl_base_mensal[Mes],0))/INDEX(tbl_base_mensal[Expedido],MATCH(A6,tbl_base_mensal[Mes],0))*1000000,"") -> 315.81544 | E6: =IFERROR(INDEX(tbl_base_mensal[Reclamacoes],MATCH(A6,tbl_base_mensal[Mes],0))/INDEX(tbl_base_mensal[Expedido],MATCH(A6,tbl_base_mensal[Mes],0))*1000000,"") -> 5.5615298 | F6: =INDEX(tbl_base_mensal[Reclamacoes_Servico],MATCH(A6,tbl_base_mensal[Mes],0)) -> 10 | G6: =IFERROR(INDEX(tbl_base_mensal[Dias_Resolucao_Soma],MATCH(A6,tbl_base_mensal[Mes],0))/INDEX(tbl_base_mensal[Reclamacoes_Resolvidas],MATCH(A6,tbl_base_mensal[Mes],0)),"") -> 13.75 | H6: =IFERROR(INDEX(tbl_base_mensal[OEE_Soma],MATCH(A6,tbl_base_mensal[Mes],0))/INDEX(tbl_base_mensal[Ordens],MATCH(A6,tbl_base_mensal[Mes],0)),"") -> 0.77020139 | I6: =IFERROR(INDEX(tbl_base_mensal[Lotes_MP_Aceites],MATCH(A6,tbl_base_mensal[Mes],0))/INDEX(tbl_base_mensal[Lotes_MP],MATCH(A6,tbl_base_mensal[Mes],0)),"") -> 0.95098039 | J6: =IFERROR(INDEX(tbl_base_mensal[Dias_Resposta_SCAR_Soma],MATCH(A6,tbl_base_mensal[Mes],0))/INDEX(tbl_base_mensal[SCAR],MATCH(A6,tbl_base_mensal[Mes],0)),"") -> 4 | K6: =IFERROR(INDEX(tbl_base_mensal[CAPA_Fechadas_No_Prazo],MATCH(A6,tbl_base_mensal[Mes],0))/INDEX(tbl_base_mensal[CAPA_Com_Prazo],MATCH(A6,tbl_base_mensal[Mes],0)),"") -> 0.33333333 | L6: =IFERROR(INDEX(tbl_base_mensal[CAPA_Eficazes],MATCH(A6,tbl_base_mensal[Mes],0))/(INDEX(tbl_base_mensal[CAPA_Eficazes],MATCH(A6,tbl_base_mensal[Mes],0))+INDEX(tbl_base_mensal[CAPA_Nao_Eficazes],MATCH(A6,tbl_base_mensal[Mes],0))),"") -> 0.45 | M6: =IFERROR(INDEX(tbl_base_mensal[Lotes_Concessao],MATCH(A6,tbl_base_mensal[Mes],0))/INDEX(tbl_base_mensal[Lotes_Decididos],MATCH(A6,tbl_base_mensal[Mes],0)),"") -> 0.023041475 | N6: =IFERROR(INDEX(tbl_base_mensal[Subgrupos_Cpk_1],MATCH(A6,tbl_base_mensal[Mes],0))/INDEX(tbl_base_mensal[Subgrupos_SPC],MATCH(A6,tbl_base_mensal[Mes],0)),"") -> 0.46020377 | O6: =IFERROR(INDEX(tbl_base_mensal[Linhas_OTIF],MATCH(A6,tbl_base_mensal[Mes],0))/INDEX(tbl_base_mensal[Linhas_Expedidas],MATCH(A6,tbl_base_mensal[Mes],0)),"") -> 0.96179775
A7: 2025-09 | B7: =IFERROR(INDEX(tbl_base_mensal[Rejeitado],MATCH(A7,tbl_base_mensal[Mes],0))/INDEX(tbl_base_mensal[Produzido],MATCH(A7,tbl_base_mensal[Mes],0)),"") -> 0.025344015 | C7: =IFERROR(INDEX(tbl_base_mensal[Lotes_1a],MATCH(A7,tbl_base_mensal[Mes],0))/INDEX(tbl_base_mensal[Lotes_Decididos],MATCH(A7,tbl_base_mensal[Mes],0)),"") -> 0.84897025 | D7: =IFERROR(INDEX(tbl_base_mensal[Qtd_Afetada],MATCH(A7,tbl_base_mensal[Mes],0))/INDEX(tbl_base_mensal[Expedido],MATCH(A7,tbl_base_mensal[Mes],0))*1000000,"") -> 211.08678 | E7: =IFERROR(INDEX(tbl_base_mensal[Reclamacoes],MATCH(A7,tbl_base_mensal[Mes],0))/INDEX(tbl_base_mensal[Expedido],MATCH(A7,tbl_base_mensal[Mes],0))*1000000,"") -> 3.8613434 | F7: =INDEX(tbl_base_mensal[Reclamacoes_Servico],MATCH(A7,tbl_base_mensal[Mes],0)) -> 4 | G7: =IFERROR(INDEX(tbl_base_mensal[Dias_Resolucao_Soma],MATCH(A7,tbl_base_mensal[Mes],0))/INDEX(tbl_base_mensal[Reclamacoes_Resolvidas],MATCH(A7,tbl_base_mensal[Mes],0)),"") -> 24 | H7: =IFERROR(INDEX(tbl_base_mensal[OEE_Soma],MATCH(A7,tbl_base_mensal[Mes],0))/INDEX(tbl_base_mensal[Ordens],MATCH(A7,tbl_base_mensal[Mes],0)),"") -> 0.76897088 | I7: =IFERROR(INDEX(tbl_base_mensal[Lotes_MP_Aceites],MATCH(A7,tbl_base_mensal[Mes],0))/INDEX(tbl_base_mensal[Lotes_MP],MATCH(A7,tbl_base_mensal[Mes],0)),"") -> 0.87128713 | J7: =IFERROR(INDEX(tbl_base_mensal[Dias_Resposta_SCAR_Soma],MATCH(A7,tbl_base_mensal[Mes],0))/INDEX(tbl_base_mensal[SCAR],MATCH(A7,tbl_base_mensal[Mes],0)),"") -> 6 | K7: =IFERROR(INDEX(tbl_base_mensal[CAPA_Fechadas_No_Prazo],MATCH(A7,tbl_base_mensal[Mes],0))/INDEX(tbl_base_mensal[CAPA_Com_Prazo],MATCH(A7,tbl_base_mensal[Mes],0)),"") -> 0.51020408 | L7: =IFERROR(INDEX(tbl_base_mensal[CAPA_Eficazes],MATCH(A7,tbl_base_mensal[Mes],0))/(INDEX(tbl_base_mensal[CAPA_Eficazes],MATCH(A7,tbl_base_mensal[Mes],0))+INDEX(tbl_base_mensal[CAPA_Nao_Eficazes],MATCH(A7,tbl_base_mensal[Mes],0))),"") -> 0.42857143 | M7: =IFERROR(INDEX(tbl_base_mensal[Lotes_Concessao],MATCH(A7,tbl_base_mensal[Mes],0))/INDEX(tbl_base_mensal[Lotes_Decididos],MATCH(A7,tbl_base_mensal[Mes],0)),"") -> 0.025171625 | N7: =IFERROR(INDEX(tbl_base_mensal[Subgrupos_Cpk_1],MATCH(A7,tbl_base_mensal[Mes],0))/INDEX(tbl_base_mensal[Subgrupos_SPC],MATCH(A7,tbl_base_mensal[Mes],0)),"") -> 0.47450705 | O7: =IFERROR(INDEX(tbl_base_mensal[Linhas_OTIF],MATCH(A7,tbl_base_mensal[Mes],0))/INDEX(tbl_base_mensal[Linhas_Expedidas],MATCH(A7,tbl_base_mensal[Mes],0)),"") -> 0.95890411
A8: 2025-10 | B8: =IFERROR(INDEX(tbl_base_mensal[Rejeitado],MATCH(A8,tbl_base_mensal[Mes],0))/INDEX(tbl_base_mensal[Produzido],MATCH(A8,tbl_base_mensal[Mes],0)),"") -> 0.023444263 | C8: =IFERROR(INDEX(tbl_base_mensal[Lotes_1a],MATCH(A8,tbl_base_mensal[Mes],0))/INDEX(tbl_base_mensal[Lotes_Decididos],MATCH(A8,tbl_base_mensal[Mes],0)),"") -> 0.8582996 | D8: =IFERROR(INDEX(tbl_base_mensal[Qtd_Afetada],MATCH(A8,tbl_base_mensal[Mes],0))/INDEX(tbl_base_mensal[Expedido],MATCH(A8,tbl_base_mensal[Mes],0))*1000000,"") -> 170.97992 | E8: =IFERROR(INDEX(tbl_base_mensal[Reclamacoes],MATCH(A8,tbl_base_mensal[Mes],0))/INDEX(tbl_base_mensal[Expedido],MATCH(A8,tbl_base_mensal[Mes],0))*1000000,"") -> 5.4526625 | F8: =INDEX(tbl_base_mensal[Reclamacoes_Servico],MATCH(A8,tbl_base_mensal[Mes],0)) -> 8 | G8: =IFERROR(INDEX(tbl_base_mensal[Dias_Resolucao_Soma],MATCH(A8,tbl_base_mensal[Mes],0))/INDEX(tbl_base_mensal[Reclamacoes_Resolvidas],MATCH(A8,tbl_base_mensal[Mes],0)),"") -> 15.888889 | H8: =IFERROR(INDEX(tbl_base_mensal[OEE_Soma],MATCH(A8,tbl_base_mensal[Mes],0))/INDEX(tbl_base_mensal[Ordens],MATCH(A8,tbl_base_mensal[Mes],0)),"") -> 0.76418318 | I8: =IFERROR(INDEX(tbl_base_mensal[Lotes_MP_Aceites],MATCH(A8,tbl_base_mensal[Mes],0))/INDEX(tbl_base_mensal[Lotes_MP],MATCH(A8,tbl_base_mensal[Mes],0)),"") -> 0.93859649 | J8: =IFERROR(INDEX(tbl_base_mensal[Dias_Resposta_SCAR_Soma],MATCH(A8,tbl_base_mensal[Mes],0))/INDEX(tbl_base_mensal[SCAR],MATCH(A8,tbl_base_mensal[Mes],0)),"") -> 6.25 | K8: =IFERROR(INDEX(tbl_base_mensal[CAPA_Fechadas_No_Prazo],MATCH(A8,tbl_base_mensal[Mes],0))/INDEX(tbl_base_mensal[CAPA_Com_Prazo],MATCH(A8,tbl_base_mensal[Mes],0)),"") -> 0.34090909 | L8: =IFERROR(INDEX(tbl_base_mensal[CAPA_Eficazes],MATCH(A8,tbl_base_mensal[Mes],0))/(INDEX(tbl_base_mensal[CAPA_Eficazes],MATCH(A8,tbl_base_mensal[Mes],0))+INDEX(tbl_base_mensal[CAPA_Nao_Eficazes],MATCH(A8,tbl_base_mensal[Mes],0))),"") -> 0.5 | M8: =IFERROR(INDEX(tbl_base_mensal[Lotes_Concessao],MATCH(A8,tbl_base_mensal[Mes],0))/INDEX(tbl_base_mensal[Lotes_Decididos],MATCH(A8,tbl_base_mensal[Mes],0)),"") -> 0.030364372 | N8: =IFERROR(INDEX(tbl_base_mensal[Subgrupos_Cpk_1],MATCH(A8,tbl_base_mensal[Mes],0))/INDEX(tbl_base_mensal[Subgrupos_SPC],MATCH(A8,tbl_base_mensal[Mes],0)),"") -> 0.46595666 | O8: =IFERROR(INDEX(tbl_base_mensal[Linhas_OTIF],MATCH(A8,tbl_base_mensal[Mes],0))/INDEX(tbl_base_mensal[Linhas_Expedidas],MATCH(A8,tbl_base_mensal[Mes],0)),"") -> 0.96130346
A9: 2025-11 | B9: =IFERROR(INDEX(tbl_base_mensal[Rejeitado],MATCH(A9,tbl_base_mensal[Mes],0))/INDEX(tbl_base_mensal[Produzido],MATCH(A9,tbl_base_mensal[Mes],0)),"") -> 0.024128627 | C9: =IFERROR(INDEX(tbl_base_mensal[Lotes_1a],MATCH(A9,tbl_base_mensal[Mes],0))/INDEX(tbl_base_mensal[Lotes_Decididos],MATCH(A9,tbl_base_mensal[Mes],0)),"") -> 0.84738041 | D9: =IFERROR(INDEX(tbl_base_mensal[Qtd_Afetada],MATCH(A9,tbl_base_mensal[Mes],0))/INDEX(tbl_base_mensal[Expedido],MATCH(A9,tbl_base_mensal[Mes],0))*1000000,"") -> 137.48173 | E9: =IFERROR(INDEX(tbl_base_mensal[Reclamacoes],MATCH(A9,tbl_base_mensal[Mes],0))/INDEX(tbl_base_mensal[Expedido],MATCH(A9,tbl_base_mensal[Mes],0))*1000000,"") -> 4.1285805 | F9: =INDEX(tbl_base_mensal[Reclamacoes_Servico],MATCH(A9,tbl_base_mensal[Mes],0)) -> 7 | G9: =IFERROR(INDEX(tbl_base_mensal[Dias_Resolucao_Soma],MATCH(A9,tbl_base_mensal[Mes],0))/INDEX(tbl_base_mensal[Reclamacoes_Resolvidas],MATCH(A9,tbl_base_mensal[Mes],0)),"") -> 19.583333 | H9: =IFERROR(INDEX(tbl_base_mensal[OEE_Soma],MATCH(A9,tbl_base_mensal[Mes],0))/INDEX(tbl_base_mensal[Ordens],MATCH(A9,tbl_base_mensal[Mes],0)),"") -> 0.76181721 | I9: =IFERROR(INDEX(tbl_base_mensal[Lotes_MP_Aceites],MATCH(A9,tbl_base_mensal[Mes],0))/INDEX(tbl_base_mensal[Lotes_MP],MATCH(A9,tbl_base_mensal[Mes],0)),"") -> 0.90196078 | J9: =IFERROR(INDEX(tbl_base_mensal[Dias_Resposta_SCAR_Soma],MATCH(A9,tbl_base_mensal[Mes],0))/INDEX(tbl_base_mensal[SCAR],MATCH(A9,tbl_base_mensal[Mes],0)),"") -> 6.5 | K9: =IFERROR(INDEX(tbl_base_mensal[CAPA_Fechadas_No_Prazo],MATCH(A9,tbl_base_mensal[Mes],0))/INDEX(tbl_base_mensal[CAPA_Com_Prazo],MATCH(A9,tbl_base_mensal[Mes],0)),"") -> 0.53333333 | L9: =IFERROR(INDEX(tbl_base_mensal[CAPA_Eficazes],MATCH(A9,tbl_base_mensal[Mes],0))/(INDEX(tbl_base_mensal[CAPA_Eficazes],MATCH(A9,tbl_base_mensal[Mes],0))+INDEX(tbl_base_mensal[CAPA_Nao_Eficazes],MATCH(A9,tbl_base_mensal[Mes],0))),"") -> 0.55 | M9: =IFERROR(INDEX(tbl_base_mensal[Lotes_Concessao],MATCH(A9,tbl_base_mensal[Mes],0))/INDEX(tbl_base_mensal[Lotes_Decididos],MATCH(A9,tbl_base_mensal[Mes],0)),"") -> 0.013667426 | N9: =IFERROR(INDEX(tbl_base_mensal[Subgrupos_Cpk_1],MATCH(A9,tbl_base_mensal[Mes],0))/INDEX(tbl_base_mensal[Subgrupos_SPC],MATCH(A9,tbl_base_mensal[Mes],0)),"") -> 0.46794301 | O9: =IFERROR(INDEX(tbl_base_mensal[Linhas_OTIF],MATCH(A9,tbl_base_mensal[Mes],0))/INDEX(tbl_base_mensal[Linhas_Expedidas],MATCH(A9,tbl_base_mensal[Mes],0)),"") -> 0.95384615
A10: 2025-12 | B10: =IFERROR(INDEX(tbl_base_mensal[Rejeitado],MATCH(A10,tbl_base_mensal[Mes],0))/INDEX(tbl_base_mensal[Produzido],MATCH(A10,tbl_base_mensal[Mes],0)),"") -> 0.023353772 | C10: =IFERROR(INDEX(tbl_base_mensal[Lotes_1a],MATCH(A10,tbl_base_mensal[Mes],0))/INDEX(tbl_base_mensal[Lotes_Decididos],MATCH(A10,tbl_base_mensal[Mes],0)),"") -> 0.88914027 | D10: =IFERROR(INDEX(tbl_base_mensal[Qtd_Afetada],MATCH(A10,tbl_base_mensal[Mes],0))/INDEX(tbl_base_mensal[Expedido],MATCH(A10,tbl_base_mensal[Mes],0))*1000000,"") -> 473.74918 | E10: =IFERROR(INDEX(tbl_base_mensal[Reclamacoes],MATCH(A10,tbl_base_mensal[Mes],0))/INDEX(tbl_base_mensal[Expedido],MATCH(A10,tbl_base_mensal[Mes],0))*1000000,"") -> 9.1258217 | F10: =INDEX(tbl_base_mensal[Reclamacoes_Servico],MATCH(A10,tbl_base_mensal[Mes],0)) -> 11 | G10: =IFERROR(INDEX(tbl_base_mensal[Dias_Resolucao_Soma],MATCH(A10,tbl_base_mensal[Mes],0))/INDEX(tbl_base_mensal[Reclamacoes_Resolvidas],MATCH(A10,tbl_base_mensal[Mes],0)),"") -> 14.166667 | H10: =IFERROR(INDEX(tbl_base_mensal[OEE_Soma],MATCH(A10,tbl_base_mensal[Mes],0))/INDEX(tbl_base_mensal[Ordens],MATCH(A10,tbl_base_mensal[Mes],0)),"") -> 0.75661135 | I10: =IFERROR(INDEX(tbl_base_mensal[Lotes_MP_Aceites],MATCH(A10,tbl_base_mensal[Mes],0))/INDEX(tbl_base_mensal[Lotes_MP],MATCH(A10,tbl_base_mensal[Mes],0)),"") -> 0.86206897 | J10: =IFERROR(INDEX(tbl_base_mensal[Dias_Resposta_SCAR_Soma],MATCH(A10,tbl_base_mensal[Mes],0))/INDEX(tbl_base_mensal[SCAR],MATCH(A10,tbl_base_mensal[Mes],0)),"") -> 6.7142857 | K10: =IFERROR(INDEX(tbl_base_mensal[CAPA_Fechadas_No_Prazo],MATCH(A10,tbl_base_mensal[Mes],0))/INDEX(tbl_base_mensal[CAPA_Com_Prazo],MATCH(A10,tbl_base_mensal[Mes],0)),"") -> 0.55357143 | L10: =IFERROR(INDEX(tbl_base_mensal[CAPA_Eficazes],MATCH(A10,tbl_base_mensal[Mes],0))/(INDEX(tbl_base_mensal[CAPA_Eficazes],MATCH(A10,tbl_base_mensal[Mes],0))+INDEX(tbl_base_mensal[CAPA_Nao_Eficazes],MATCH(A10,tbl_base_mensal[Mes],0))),"") -> 0.625 | M10: =IFERROR(INDEX(tbl_base_mensal[Lotes_Concessao],MATCH(A10,tbl_base_mensal[Mes],0))/INDEX(tbl_base_mensal[Lotes_Decididos],MATCH(A10,tbl_base_mensal[Mes],0)),"") -> 0.011312217 | N10: =IFERROR(INDEX(tbl_base_mensal[Subgrupos_Cpk_1],MATCH(A10,tbl_base_mensal[Mes],0))/INDEX(tbl_base_mensal[Subgrupos_SPC],MATCH(A10,tbl_base_mensal[Mes],0)),"") -> 0.46388137 | O10: =IFERROR(INDEX(tbl_base_mensal[Linhas_OTIF],MATCH(A10,tbl_base_mensal[Mes],0))/INDEX(tbl_base_mensal[Linhas_Expedidas],MATCH(A10,tbl_base_mensal[Mes],0)),"") -> 0.95338983
A11: 2026-01 | B11: =IFERROR(INDEX(tbl_base_mensal[Rejeitado],MATCH(A11,tbl_base_mensal[Mes],0))/INDEX(tbl_base_mensal[Produzido],MATCH(A11,tbl_base_mensal[Mes],0)),"") -> 0.023485735 | C11: =IFERROR(INDEX(tbl_base_mensal[Lotes_1a],MATCH(A11,tbl_base_mensal[Mes],0))/INDEX(tbl_base_mensal[Lotes_Decididos],MATCH(A11,tbl_base_mensal[Mes],0)),"") -> 0.86384977 | D11: =IFERROR(INDEX(tbl_base_mensal[Qtd_Afetada],MATCH(A11,tbl_base_mensal[Mes],0))/INDEX(tbl_base_mensal[Expedido],MATCH(A11,tbl_base_mensal[Mes],0))*1000000,"") -> 261.48733 | E11: =IFERROR(INDEX(tbl_base_mensal[Reclamacoes],MATCH(A11,tbl_base_mensal[Mes],0))/INDEX(tbl_base_mensal[Expedido],MATCH(A11,tbl_base_mensal[Mes],0))*1000000,"") -> 2.9421922 | F11: =INDEX(tbl_base_mensal[Reclamacoes_Servico],MATCH(A11,tbl_base_mensal[Mes],0)) -> 4 | G11: =IFERROR(INDEX(tbl_base_mensal[Dias_Resolucao_Soma],MATCH(A11,tbl_base_mensal[Mes],0))/INDEX(tbl_base_mensal[Reclamacoes_Resolvidas],MATCH(A11,tbl_base_mensal[Mes],0)),"") -> 19.181818 | H11: =IFERROR(INDEX(tbl_base_mensal[OEE_Soma],MATCH(A11,tbl_base_mensal[Mes],0))/INDEX(tbl_base_mensal[Ordens],MATCH(A11,tbl_base_mensal[Mes],0)),"") -> 0.7661064 | I11: =IFERROR(INDEX(tbl_base_mensal[Lotes_MP_Aceites],MATCH(A11,tbl_base_mensal[Mes],0))/INDEX(tbl_base_mensal[Lotes_MP],MATCH(A11,tbl_base_mensal[Mes],0)),"") -> 0.87378641 | J11: =IFERROR(INDEX(tbl_base_mensal[Dias_Resposta_SCAR_Soma],MATCH(A11,tbl_base_mensal[Mes],0))/INDEX(tbl_base_mensal[SCAR],MATCH(A11,tbl_base_mensal[Mes],0)),"") -> 5.5 | K11: =IFERROR(INDEX(tbl_base_mensal[CAPA_Fechadas_No_Prazo],MATCH(A11,tbl_base_mensal[Mes],0))/INDEX(tbl_base_mensal[CAPA_Com_Prazo],MATCH(A11,tbl_base_mensal[Mes],0)),"") -> 0.53846154 | L11: =IFERROR(INDEX(tbl_base_mensal[CAPA_Eficazes],MATCH(A11,tbl_base_mensal[Mes],0))/(INDEX(tbl_base_mensal[CAPA_Eficazes],MATCH(A11,tbl_base_mensal[Mes],0))+INDEX(tbl_base_mensal[CAPA_Nao_Eficazes],MATCH(A11,tbl_base_mensal[Mes],0))),"") -> 0.46666667 | M11: =IFERROR(INDEX(tbl_base_mensal[Lotes_Concessao],MATCH(A11,tbl_base_mensal[Mes],0))/INDEX(tbl_base_mensal[Lotes_Decididos],MATCH(A11,tbl_base_mensal[Mes],0)),"") -> 0.014084507 | N11: =IFERROR(INDEX(tbl_base_mensal[Subgrupos_Cpk_1],MATCH(A11,tbl_base_mensal[Mes],0))/INDEX(tbl_base_mensal[Subgrupos_SPC],MATCH(A11,tbl_base_mensal[Mes],0)),"") -> 0.47772384 | O11: =IFERROR(INDEX(tbl_base_mensal[Linhas_OTIF],MATCH(A11,tbl_base_mensal[Mes],0))/INDEX(tbl_base_mensal[Linhas_Expedidas],MATCH(A11,tbl_base_mensal[Mes],0)),"") -> 0.96875
A12: 2026-02 | B12: =IFERROR(INDEX(tbl_base_mensal[Rejeitado],MATCH(A12,tbl_base_mensal[Mes],0))/INDEX(tbl_base_mensal[Produzido],MATCH(A12,tbl_base_mensal[Mes],0)),"") -> 0.022918925 | C12: =IFERROR(INDEX(tbl_base_mensal[Lotes_1a],MATCH(A12,tbl_base_mensal[Mes],0))/INDEX(tbl_base_mensal[Lotes_Decididos],MATCH(A12,tbl_base_mensal[Mes],0)),"") -> 0.84832905 | D12: =IFERROR(INDEX(tbl_base_mensal[Qtd_Afetada],MATCH(A12,tbl_base_mensal[Mes],0))/INDEX(tbl_base_mensal[Expedido],MATCH(A12,tbl_base_mensal[Mes],0))*1000000,"") -> 224.50645 | E12: =IFERROR(INDEX(tbl_base_mensal[Reclamacoes],MATCH(A12,tbl_base_mensal[Mes],0))/INDEX(tbl_base_mensal[Expedido],MATCH(A12,tbl_base_mensal[Mes],0))*1000000,"") -> 4.098495 | F12: =INDEX(tbl_base_mensal[Reclamacoes_Servico],MATCH(A12,tbl_base_mensal[Mes],0)) -> 5 | G12: =IFERROR(INDEX(tbl_base_mensal[Dias_Resolucao_Soma],MATCH(A12,tbl_base_mensal[Mes],0))/INDEX(tbl_base_mensal[Reclamacoes_Resolvidas],MATCH(A12,tbl_base_mensal[Mes],0)),"") -> 19.666667 | H12: =IFERROR(INDEX(tbl_base_mensal[OEE_Soma],MATCH(A12,tbl_base_mensal[Mes],0))/INDEX(tbl_base_mensal[Ordens],MATCH(A12,tbl_base_mensal[Mes],0)),"") -> 0.76925546 | I12: =IFERROR(INDEX(tbl_base_mensal[Lotes_MP_Aceites],MATCH(A12,tbl_base_mensal[Mes],0))/INDEX(tbl_base_mensal[Lotes_MP],MATCH(A12,tbl_base_mensal[Mes],0)),"") -> 0.91304348 | J12: =IFERROR(INDEX(tbl_base_mensal[Dias_Resposta_SCAR_Soma],MATCH(A12,tbl_base_mensal[Mes],0))/INDEX(tbl_base_mensal[SCAR],MATCH(A12,tbl_base_mensal[Mes],0)),"") -> 3.5 | K12: =IFERROR(INDEX(tbl_base_mensal[CAPA_Fechadas_No_Prazo],MATCH(A12,tbl_base_mensal[Mes],0))/INDEX(tbl_base_mensal[CAPA_Com_Prazo],MATCH(A12,tbl_base_mensal[Mes],0)),"") -> 0.43333333 | L12: =IFERROR(INDEX(tbl_base_mensal[CAPA_Eficazes],MATCH(A12,tbl_base_mensal[Mes],0))/(INDEX(tbl_base_mensal[CAPA_Eficazes],MATCH(A12,tbl_base_mensal[Mes],0))+INDEX(tbl_base_mensal[CAPA_Nao_Eficazes],MATCH(A12,tbl_base_mensal[Mes],0))),"") -> 0.40909091 | M12: =IFERROR(INDEX(tbl_base_mensal[Lotes_Concessao],MATCH(A12,tbl_base_mensal[Mes],0))/INDEX(tbl_base_mensal[Lotes_Decididos],MATCH(A12,tbl_base_mensal[Mes],0)),"") -> 0.01285347 | N12: =IFERROR(INDEX(tbl_base_mensal[Subgrupos_Cpk_1],MATCH(A12,tbl_base_mensal[Mes],0))/INDEX(tbl_base_mensal[Subgrupos_SPC],MATCH(A12,tbl_base_mensal[Mes],0)),"") -> 0.45824266 | O12: =IFERROR(INDEX(tbl_base_mensal[Linhas_OTIF],MATCH(A12,tbl_base_mensal[Mes],0))/INDEX(tbl_base_mensal[Linhas_Expedidas],MATCH(A12,tbl_base_mensal[Mes],0)),"") -> 0.95717884
A13: 2026-03 | B13: =IFERROR(INDEX(tbl_base_mensal[Rejeitado],MATCH(A13,tbl_base_mensal[Mes],0))/INDEX(tbl_base_mensal[Produzido],MATCH(A13,tbl_base_mensal[Mes],0)),"") -> 0.025059499 | C13: =IFERROR(INDEX(tbl_base_mensal[Lotes_1a],MATCH(A13,tbl_base_mensal[Mes],0))/INDEX(tbl_base_mensal[Lotes_Decididos],MATCH(A13,tbl_base_mensal[Mes],0)),"") -> 0.85421412 | D13: =IFERROR(INDEX(tbl_base_mensal[Qtd_Afetada],MATCH(A13,tbl_base_mensal[Mes],0))/INDEX(tbl_base_mensal[Expedido],MATCH(A13,tbl_base_mensal[Mes],0))*1000000,"") -> 296.13366 | E13: =IFERROR(INDEX(tbl_base_mensal[Reclamacoes],MATCH(A13,tbl_base_mensal[Mes],0))/INDEX(tbl_base_mensal[Expedido],MATCH(A13,tbl_base_mensal[Mes],0))*1000000,"") -> 4.4265122 | F13: =INDEX(tbl_base_mensal[Reclamacoes_Servico],MATCH(A13,tbl_base_mensal[Mes],0)) -> 4 | G13: =IFERROR(INDEX(tbl_base_mensal[Dias_Resolucao_Soma],MATCH(A13,tbl_base_mensal[Mes],0))/INDEX(tbl_base_mensal[Reclamacoes_Resolvidas],MATCH(A13,tbl_base_mensal[Mes],0)),"") -> 18.833333 | H13: =IFERROR(INDEX(tbl_base_mensal[OEE_Soma],MATCH(A13,tbl_base_mensal[Mes],0))/INDEX(tbl_base_mensal[Ordens],MATCH(A13,tbl_base_mensal[Mes],0)),"") -> 0.7651686 | I13: =IFERROR(INDEX(tbl_base_mensal[Lotes_MP_Aceites],MATCH(A13,tbl_base_mensal[Mes],0))/INDEX(tbl_base_mensal[Lotes_MP],MATCH(A13,tbl_base_mensal[Mes],0)),"") -> 0.85858586 | J13: =IFERROR(INDEX(tbl_base_mensal[Dias_Resposta_SCAR_Soma],MATCH(A13,tbl_base_mensal[Mes],0))/INDEX(tbl_base_mensal[SCAR],MATCH(A13,tbl_base_mensal[Mes],0)),"") -> 6.7142857 | K13: =IFERROR(INDEX(tbl_base_mensal[CAPA_Fechadas_No_Prazo],MATCH(A13,tbl_base_mensal[Mes],0))/INDEX(tbl_base_mensal[CAPA_Com_Prazo],MATCH(A13,tbl_base_mensal[Mes],0)),"") -> 0.62162162 | L13: =IFERROR(INDEX(tbl_base_mensal[CAPA_Eficazes],MATCH(A13,tbl_base_mensal[Mes],0))/(INDEX(tbl_base_mensal[CAPA_Eficazes],MATCH(A13,tbl_base_mensal[Mes],0))+INDEX(tbl_base_mensal[CAPA_Nao_Eficazes],MATCH(A13,tbl_base_mensal[Mes],0))),"") -> 0.56521739 | M13: =IFERROR(INDEX(tbl_base_mensal[Lotes_Concessao],MATCH(A13,tbl_base_mensal[Mes],0))/INDEX(tbl_base_mensal[Lotes_Decididos],MATCH(A13,tbl_base_mensal[Mes],0)),"") -> 0.018223235 | N13: =IFERROR(INDEX(tbl_base_mensal[Subgrupos_Cpk_1],MATCH(A13,tbl_base_mensal[Mes],0))/INDEX(tbl_base_mensal[Subgrupos_SPC],MATCH(A13,tbl_base_mensal[Mes],0)),"") -> 0.46450863 | O13: =IFERROR(INDEX(tbl_base_mensal[Linhas_OTIF],MATCH(A13,tbl_base_mensal[Mes],0))/INDEX(tbl_base_mensal[Linhas_Expedidas],MATCH(A13,tbl_base_mensal[Mes],0)),"") -> 0.95348837
A14: 2026-04 | B14: =IFERROR(INDEX(tbl_base_mensal[Rejeitado],MATCH(A14,tbl_base_mensal[Mes],0))/INDEX(tbl_base_mensal[Produzido],MATCH(A14,tbl_base_mensal[Mes],0)),"") -> 0.024720994 | C14: =IFERROR(INDEX(tbl_base_mensal[Lotes_1a],MATCH(A14,tbl_base_mensal[Mes],0))/INDEX(tbl_base_mensal[Lotes_Decididos],MATCH(A14,tbl_base_mensal[Mes],0)),"") -> 0.88636364 | D14: =IFERROR(INDEX(tbl_base_mensal[Qtd_Afetada],MATCH(A14,tbl_base_mensal[Mes],0))/INDEX(tbl_base_mensal[Expedido],MATCH(A14,tbl_base_mensal[Mes],0))*1000000,"") -> 255.28541 | E14: =IFERROR(INDEX(tbl_base_mensal[Reclamacoes],MATCH(A14,tbl_base_mensal[Mes],0))/INDEX(tbl_base_mensal[Expedido],MATCH(A14,tbl_base_mensal[Mes],0))*1000000,"") -> 5.7844126 | F14: =INDEX(tbl_base_mensal[Reclamacoes_Servico],MATCH(A14,tbl_base_mensal[Mes],0)) -> 6 | G14: =IFERROR(INDEX(tbl_base_mensal[Dias_Resolucao_Soma],MATCH(A14,tbl_base_mensal[Mes],0))/INDEX(tbl_base_mensal[Reclamacoes_Resolvidas],MATCH(A14,tbl_base_mensal[Mes],0)),"") -> 13 | H14: =IFERROR(INDEX(tbl_base_mensal[OEE_Soma],MATCH(A14,tbl_base_mensal[Mes],0))/INDEX(tbl_base_mensal[Ordens],MATCH(A14,tbl_base_mensal[Mes],0)),"") -> 0.7460461 | I14: =IFERROR(INDEX(tbl_base_mensal[Lotes_MP_Aceites],MATCH(A14,tbl_base_mensal[Mes],0))/INDEX(tbl_base_mensal[Lotes_MP],MATCH(A14,tbl_base_mensal[Mes],0)),"") -> 0.92307692 | J14: =IFERROR(INDEX(tbl_base_mensal[Dias_Resposta_SCAR_Soma],MATCH(A14,tbl_base_mensal[Mes],0))/INDEX(tbl_base_mensal[SCAR],MATCH(A14,tbl_base_mensal[Mes],0)),"") -> 5.6 | K14: =IFERROR(INDEX(tbl_base_mensal[CAPA_Fechadas_No_Prazo],MATCH(A14,tbl_base_mensal[Mes],0))/INDEX(tbl_base_mensal[CAPA_Com_Prazo],MATCH(A14,tbl_base_mensal[Mes],0)),"") -> 0.42857143 | L14: =IFERROR(INDEX(tbl_base_mensal[CAPA_Eficazes],MATCH(A14,tbl_base_mensal[Mes],0))/(INDEX(tbl_base_mensal[CAPA_Eficazes],MATCH(A14,tbl_base_mensal[Mes],0))+INDEX(tbl_base_mensal[CAPA_Nao_Eficazes],MATCH(A14,tbl_base_mensal[Mes],0))),"") -> 0.73913043 | M14: =IFERROR(INDEX(tbl_base_mensal[Lotes_Concessao],MATCH(A14,tbl_base_mensal[Mes],0))/INDEX(tbl_base_mensal[Lotes_Decididos],MATCH(A14,tbl_base_mensal[Mes],0)),"") -> 0.013636364 | N14: =IFERROR(INDEX(tbl_base_mensal[Subgrupos_Cpk_1],MATCH(A14,tbl_base_mensal[Mes],0))/INDEX(tbl_base_mensal[Subgrupos_SPC],MATCH(A14,tbl_base_mensal[Mes],0)),"") -> 0.46743933 | O14: =IFERROR(INDEX(tbl_base_mensal[Linhas_OTIF],MATCH(A14,tbl_base_mensal[Mes],0))/INDEX(tbl_base_mensal[Linhas_Expedidas],MATCH(A14,tbl_base_mensal[Mes],0)),"") -> 0.95196507
A15: 2026-05 | B15: =IFERROR(INDEX(tbl_base_mensal[Rejeitado],MATCH(A15,tbl_base_mensal[Mes],0))/INDEX(tbl_base_mensal[Produzido],MATCH(A15,tbl_base_mensal[Mes],0)),"") -> 0.024480867 | C15: =IFERROR(INDEX(tbl_base_mensal[Lotes_1a],MATCH(A15,tbl_base_mensal[Mes],0))/INDEX(tbl_base_mensal[Lotes_Decididos],MATCH(A15,tbl_base_mensal[Mes],0)),"") -> 0.84580499 | D15: =IFERROR(INDEX(tbl_base_mensal[Qtd_Afetada],MATCH(A15,tbl_base_mensal[Mes],0))/INDEX(tbl_base_mensal[Expedido],MATCH(A15,tbl_base_mensal[Mes],0))*1000000,"") -> 313.82656 | E15: =IFERROR(INDEX(tbl_base_mensal[Reclamacoes],MATCH(A15,tbl_base_mensal[Mes],0))/INDEX(tbl_base_mensal[Expedido],MATCH(A15,tbl_base_mensal[Mes],0))*1000000,"") -> 6.1055752 | F15: =INDEX(tbl_base_mensal[Reclamacoes_Servico],MATCH(A15,tbl_base_mensal[Mes],0)) -> 12 | G15: =IFERROR(INDEX(tbl_base_mensal[Dias_Resolucao_Soma],MATCH(A15,tbl_base_mensal[Mes],0))/INDEX(tbl_base_mensal[Reclamacoes_Resolvidas],MATCH(A15,tbl_base_mensal[Mes],0)),"") -> 20.666667 | H15: =IFERROR(INDEX(tbl_base_mensal[OEE_Soma],MATCH(A15,tbl_base_mensal[Mes],0))/INDEX(tbl_base_mensal[Ordens],MATCH(A15,tbl_base_mensal[Mes],0)),"") -> 0.76342271 | I15: =IFERROR(INDEX(tbl_base_mensal[Lotes_MP_Aceites],MATCH(A15,tbl_base_mensal[Mes],0))/INDEX(tbl_base_mensal[Lotes_MP],MATCH(A15,tbl_base_mensal[Mes],0)),"") -> 0.875 | J15: =IFERROR(INDEX(tbl_base_mensal[Dias_Resposta_SCAR_Soma],MATCH(A15,tbl_base_mensal[Mes],0))/INDEX(tbl_base_mensal[SCAR],MATCH(A15,tbl_base_mensal[Mes],0)),"") -> 5 | K15: =IFERROR(INDEX(tbl_base_mensal[CAPA_Fechadas_No_Prazo],MATCH(A15,tbl_base_mensal[Mes],0))/INDEX(tbl_base_mensal[CAPA_Com_Prazo],MATCH(A15,tbl_base_mensal[Mes],0)),"") -> 0.58139535 | L15: =IFERROR(INDEX(tbl_base_mensal[CAPA_Eficazes],MATCH(A15,tbl_base_mensal[Mes],0))/(INDEX(tbl_base_mensal[CAPA_Eficazes],MATCH(A15,tbl_base_mensal[Mes],0))+INDEX(tbl_base_mensal[CAPA_Nao_Eficazes],MATCH(A15,tbl_base_mensal[Mes],0))),"") -> 0.6 | M15: =IFERROR(INDEX(tbl_base_mensal[Lotes_Concessao],MATCH(A15,tbl_base_mensal[Mes],0))/INDEX(tbl_base_mensal[Lotes_Decididos],MATCH(A15,tbl_base_mensal[Mes],0)),"") -> 0.0068027211 | N15: =IFERROR(INDEX(tbl_base_mensal[Subgrupos_Cpk_1],MATCH(A15,tbl_base_mensal[Mes],0))/INDEX(tbl_base_mensal[Subgrupos_SPC],MATCH(A15,tbl_base_mensal[Mes],0)),"") -> 0.46055239 | O15: =IFERROR(INDEX(tbl_base_mensal[Linhas_OTIF],MATCH(A15,tbl_base_mensal[Mes],0))/INDEX(tbl_base_mensal[Linhas_Expedidas],MATCH(A15,tbl_base_mensal[Mes],0)),"") -> 0.95154185
A16: 2026-06 | B16: =IFERROR(INDEX(tbl_base_mensal[Rejeitado],MATCH(A16,tbl_base_mensal[Mes],0))/INDEX(tbl_base_mensal[Produzido],MATCH(A16,tbl_base_mensal[Mes],0)),"") -> 0.023053965 | C16: =IFERROR(INDEX(tbl_base_mensal[Lotes_1a],MATCH(A16,tbl_base_mensal[Mes],0))/INDEX(tbl_base_mensal[Lotes_Decididos],MATCH(A16,tbl_base_mensal[Mes],0)),"") -> 0.8627907 | D16: =IFERROR(INDEX(tbl_base_mensal[Qtd_Afetada],MATCH(A16,tbl_base_mensal[Mes],0))/INDEX(tbl_base_mensal[Expedido],MATCH(A16,tbl_base_mensal[Mes],0))*1000000,"") -> 165.63348 | E16: =IFERROR(INDEX(tbl_base_mensal[Reclamacoes],MATCH(A16,tbl_base_mensal[Mes],0))/INDEX(tbl_base_mensal[Expedido],MATCH(A16,tbl_base_mensal[Mes],0))*1000000,"") -> 4.0398409 | F16: =INDEX(tbl_base_mensal[Reclamacoes_Servico],MATCH(A16,tbl_base_mensal[Mes],0)) -> 4 | G16: =IFERROR(INDEX(tbl_base_mensal[Dias_Resolucao_Soma],MATCH(A16,tbl_base_mensal[Mes],0))/INDEX(tbl_base_mensal[Reclamacoes_Resolvidas],MATCH(A16,tbl_base_mensal[Mes],0)),"") -> 24.8 | H16: =IFERROR(INDEX(tbl_base_mensal[OEE_Soma],MATCH(A16,tbl_base_mensal[Mes],0))/INDEX(tbl_base_mensal[Ordens],MATCH(A16,tbl_base_mensal[Mes],0)),"") -> 0.75898505 | I16: =IFERROR(INDEX(tbl_base_mensal[Lotes_MP_Aceites],MATCH(A16,tbl_base_mensal[Mes],0))/INDEX(tbl_base_mensal[Lotes_MP],MATCH(A16,tbl_base_mensal[Mes],0)),"") -> 0.90196078 | J16: =IFERROR(INDEX(tbl_base_mensal[Dias_Resposta_SCAR_Soma],MATCH(A16,tbl_base_mensal[Mes],0))/INDEX(tbl_base_mensal[SCAR],MATCH(A16,tbl_base_mensal[Mes],0)),"") -> 7 | K16: =IFERROR(INDEX(tbl_base_mensal[CAPA_Fechadas_No_Prazo],MATCH(A16,tbl_base_mensal[Mes],0))/INDEX(tbl_base_mensal[CAPA_Com_Prazo],MATCH(A16,tbl_base_mensal[Mes],0)),"") -> 0.43243243 | L16: =IFERROR(INDEX(tbl_base_mensal[CAPA_Eficazes],MATCH(A16,tbl_base_mensal[Mes],0))/(INDEX(tbl_base_mensal[CAPA_Eficazes],MATCH(A16,tbl_base_mensal[Mes],0))+INDEX(tbl_base_mensal[CAPA_Nao_Eficazes],MATCH(A16,tbl_base_mensal[Mes],0))),"") -> 0.56521739 | M16: =IFERROR(INDEX(tbl_base_mensal[Lotes_Concessao],MATCH(A16,tbl_base_mensal[Mes],0))/INDEX(tbl_base_mensal[Lotes_Decididos],MATCH(A16,tbl_base_mensal[Mes],0)),"") -> 0.018604651 | N16: =IFERROR(INDEX(tbl_base_mensal[Subgrupos_Cpk_1],MATCH(A16,tbl_base_mensal[Mes],0))/INDEX(tbl_base_mensal[Subgrupos_SPC],MATCH(A16,tbl_base_mensal[Mes],0)),"") -> 0.46297829 | O16: =IFERROR(INDEX(tbl_base_mensal[Linhas_OTIF],MATCH(A16,tbl_base_mensal[Mes],0))/INDEX(tbl_base_mensal[Linhas_Expedidas],MATCH(A16,tbl_base_mensal[Mes],0)),"") -> 0.97772829
... A22: 2026-12 | B22: =IFERROR(INDEX(tbl_base_mensal[Rejeitado],MATCH(A22,tbl_base_mensal[Mes],0))/INDEX(tbl_base_mensal[Produzido],MATCH(A22,tbl_base_mensal[Mes],0)),"") -> 0.022511395 | C22: =IFERROR(INDEX(tbl_base_mensal[Lotes_1a],MATCH(A22,tbl_base_mensal[Mes],0))/INDEX(tbl_base_mensal[Lotes_Decididos],MATCH(A22,tbl_base_mensal[Mes],0)),"") -> 0.85 | D22: =IFERROR(INDEX(tbl_base_mensal[Qtd_Afetada],MATCH(A22,tbl_base_mensal[Mes],0))/INDEX(tbl_base_mensal[Expedido],MATCH(A22,tbl_base_mensal[Mes],0))*1000000,"") -> 221.3013 | E22: =IFERROR(INDEX(tbl_base_mensal[Reclamacoes],MATCH(A22,tbl_base_mensal[Mes],0))/INDEX(tbl_base_mensal[Expedido],MATCH(A22,tbl_base_mensal[Mes],0))*1000000,"") -> 4.2019234 | F22: =INDEX(tbl_base_mensal[Reclamacoes_Servico],MATCH(A22,tbl_base_mensal[Mes],0)) -> 4 | G22: =IFERROR(INDEX(tbl_base_mensal[Dias_Resolucao_Soma],MATCH(A22,tbl_base_mensal[Mes],0))/INDEX(tbl_base_mensal[Reclamacoes_Resolvidas],MATCH(A22,tbl_base_mensal[Mes],0)),"") -> 19.615385 | H22: =IFERROR(INDEX(tbl_base_mensal[OEE_Soma],MATCH(A22,tbl_base_mensal[Mes],0))/INDEX(tbl_base_mensal[Ordens],MATCH(A22,tbl_base_mensal[Mes],0)),"") -> 0.7467272 | I22: =IFERROR(INDEX(tbl_base_mensal[Lotes_MP_Aceites],MATCH(A22,tbl_base_mensal[Mes],0))/INDEX(tbl_base_mensal[Lotes_MP],MATCH(A22,tbl_base_mensal[Mes],0)),"") -> 0.89320388 | J22: =IFERROR(INDEX(tbl_base_mensal[Dias_Resposta_SCAR_Soma],MATCH(A22,tbl_base_mensal[Mes],0))/INDEX(tbl_base_mensal[SCAR],MATCH(A22,tbl_base_mensal[Mes],0)),"") -> 8.75 | K22: =IFERROR(INDEX(tbl_base_mensal[CAPA_Fechadas_No_Prazo],MATCH(A22,tbl_base_mensal[Mes],0))/INDEX(tbl_base_mensal[CAPA_Com_Prazo],MATCH(A22,tbl_base_mensal[Mes],0)),"") -> 0.53571429 | L22: =IFERROR(INDEX(tbl_base_mensal[CAPA_Eficazes],MATCH(A22,tbl_base_mensal[Mes],0))/(INDEX(tbl_base_mensal[CAPA_Eficazes],MATCH(A22,tbl_base_mensal[Mes],0))+INDEX(tbl_base_mensal[CAPA_Nao_Eficazes],MATCH(A22,tbl_base_mensal[Mes],0))),"") -> 0.46428571 | M22: =IFERROR(INDEX(tbl_base_mensal[Lotes_Concessao],MATCH(A22,tbl_base_mensal[Mes],0))/INDEX(tbl_base_mensal[Lotes_Decididos],MATCH(A22,tbl_base_mensal[Mes],0)),"") -> 0.0092592593 | N22: =IFERROR(INDEX(tbl_base_mensal[Subgrupos_Cpk_1],MATCH(A22,tbl_base_mensal[Mes],0))/INDEX(tbl_base_mensal[Subgrupos_SPC],MATCH(A22,tbl_base_mensal[Mes],0)),"") -> 0.44282754 | O22: =IFERROR(INDEX(tbl_base_mensal[Linhas_OTIF],MATCH(A22,tbl_base_mensal[Mes],0))/INDEX(tbl_base_mensal[Linhas_Expedidas],MATCH(A22,tbl_base_mensal[Mes],0)),"") -> 0.96525097

Sheet Catalogo_KPI
A1: ID_KPI | B1: Nome | C1: Formula_Calculo | D1: Unidade | E1: Polaridade | F1: Frequencia | G1: Fonte_Dados | H1: Responsavel | I1: Meta | J1: Baseline | K1: ID_OBJ | L1: ID_MED | M1: Processo | N1: Coluna_Mensal
A2: KPI-Q-01 | B2: Taxa de rejeição interna | C2: Rejeitado ÷ produzido | D2: % | E2: Menor | F2: Mensal | G2: fact_production (RejectedQty, ProducedQty) | H2: Gerente de Produção | I2: 0.02 | J2: =IF(OR(A2="",N2="—"),"",IFERROR(AVERAGE(INDEX(KPI_Mensal!$A$5:$O$16,0,MATCH(N2,KPI_Mensal!$A$4:$O$4,0))),"")) -> 0.023883027 | K2: =IFERROR(INDEX(tbl_objetivos[ID_OBJ],MATCH(A2,tbl_objetivos[ID_KPI],0)),"") -> OBJ-Q-01 | L2: =IFERROR(INDEX(tbl_plano_monitorizacao[ID_MED],MATCH(A2,tbl_plano_monitorizacao[ID_KPI],0)),"") -> PMM-03 | M2: PCP | N2: Taxa_Rejeicao
A3: KPI-Q-02 | B3: Lotes aprovados à primeira (FPY de lote) | C3: Lotes 'Aprovado à primeira' ÷ lotes decididos | D3: % | E3: Maior | F3: Mensal | G3: disposição de lotes (frasco, tampa, decoração) | H3: Gerente da Qualidade | I3: 0.92 | J3: =IF(OR(A3="",N3="—"),"",IFERROR(AVERAGE(INDEX(KPI_Mensal!$A$5:$O$16,0,MATCH(N3,KPI_Mensal!$A$4:$O$4,0))),"")) -> 0.8604492 | K3: =IFERROR(INDEX(tbl_objetivos[ID_OBJ],MATCH(A3,tbl_objetivos[ID_KPI],0)),"") -> OBJ-Q-02 | L3: =IFERROR(INDEX(tbl_plano_monitorizacao[ID_MED],MATCH(A3,tbl_plano_monitorizacao[ID_KPI],0)),"") -> PMM-02 | M3: LAB | N3: FPY_Lotes
A4: KPI-Q-03 | B4: PPM de cliente | C4: Quantidade afetada reclamada ÷ quantidade expedida × 10⁶ | D4: ppm | E4: Menor | F4: Mensal | G4: reclamações (QtyAffected) e vendas (ShippedQty) | H4: Diretor Comercial | I4: 150 | J4: =IF(OR(A4="",N4="—"),"",IFERROR(AVERAGE(INDEX(KPI_Mensal!$A$5:$O$16,0,MATCH(N4,KPI_Mensal!$A$4:$O$4,0))),"")) -> 236.91011 | K4: =IFERROR(INDEX(tbl_objetivos[ID_OBJ],MATCH(A4,tbl_objetivos[ID_KPI],0)),"") | L4: =IFERROR(INDEX(tbl_plano_monitorizacao[ID_MED],MATCH(A4,tbl_plano_monitorizacao[ID_KPI],0)),"") | M4: COM | N4: PPM_Cliente
A5: KPI-Q-04 | B5: Reclamações por milhão de unidades expedidas (CPMU) | C5: N.º de reclamações ÷ unidades expedidas × 10⁶ | D5: rec./milhão | E5: Menor | F5: Mensal | G5: reclamações e vendas | H5: Diretor Comercial | I5: 3 | J5: =IF(OR(A5="",N5="—"),"",IFERROR(AVERAGE(INDEX(KPI_Mensal!$A$5:$O$16,0,MATCH(N5,KPI_Mensal!$A$4:$O$4,0))),"")) -> 4.6664495 | K5: =IFERROR(INDEX(tbl_objetivos[ID_OBJ],MATCH(A5,tbl_objetivos[ID_KPI],0)),"") -> OBJ-Q-03 | L5: =IFERROR(INDEX(tbl_plano_monitorizacao[ID_MED],MATCH(A5,tbl_plano_monitorizacao[ID_KPI],0)),"") -> PMM-08 | M5: COM | N5: CPMU
A6: KPI-Q-05 | B6: Reclamações de serviço / logística | C6: Contagem | D6: n.º | E6: Menor | F6: Mensal | G6: reclamações (atraso, quantidade, produto trocado, rótulo) | H6: Responsável de Armazém e Logística | I6: 5 | J6: =IF(OR(A6="",N6="—"),"",IFERROR(AVERAGE(INDEX(KPI_Mensal!$A$5:$O$16,0,MATCH(N6,KPI_Mensal!$A$4:$O$4,0))),"")) -> 6.25 | K6: =IFERROR(INDEX(tbl_objetivos[ID_OBJ],MATCH(A6,tbl_objetivos[ID_KPI],0)),"") | L6: =IFERROR(INDEX(tbl_plano_monitorizacao[ID_MED],MATCH(A6,tbl_plano_monitorizacao[ID_KPI],0)),"") | M6: EXP | N6: Reclamacoes_Servico
A7: KPI-Q-06 | B7: Tempo médio de resolução de reclamações | C7: Σ dias até resolução ÷ reclamações resolvidas | D7: dias | E7: Menor | F7: Mensal | G7: reclamações resolvidas no mês | H7: Diretor Comercial | I7: 20 | J7: =IF(OR(A7="",N7="—"),"",IFERROR(AVERAGE(INDEX(KPI_Mensal!$A$5:$O$16,0,MATCH(N7,KPI_Mensal!$A$4:$O$4,0))),"")) -> 18.503398 | K7: =IFERROR(INDEX(tbl_objetivos[ID_OBJ],MATCH(A7,tbl_objetivos[ID_KPI],0)),"") | L7: =IFERROR(INDEX(tbl_plano_monitorizacao[ID_MED],MATCH(A7,tbl_plano_monitorizacao[ID_KPI],0)),"") | M7: COM | N7: Dias_Resolucao
A8: KPI-Q-07 | B8: OEE médio | C8: Média do OEE das ordens do mês | D8: % | E8: Maior | F8: Mensal | G8: fact_production (OEE por ordem) | H8: Gerente de Produção | I8: 0.805 | J8: =IF(OR(A8="",N8="—"),"",IFERROR(AVERAGE(INDEX(KPI_Mensal!$A$5:$O$16,0,MATCH(N8,KPI_Mensal!$A$4:$O$4,0))),"")) -> 0.76406084 | K8: =IFERROR(INDEX(tbl_objetivos[ID_OBJ],MATCH(A8,tbl_objetivos[ID_KPI],0)),"") | L8: =IFERROR(INDEX(tbl_plano_monitorizacao[ID_MED],MATCH(A8,tbl_plano_monitorizacao[ID_KPI],0)),"") -> PMM-05 | M8: PCP | N8: OEE
A9: KPI-Q-08 | B9: Lotes de matéria-prima aceites sem derrogação | C9: Lotes 'Accepted' ÷ lotes recebidos | D9: % | E9: Maior | F9: Mensal | G9: disposição de lotes de MP | H9: Responsável de Compras | I9: 0.95 | J9: =IF(OR(A9="",N9="—"),"",IFERROR(AVERAGE(INDEX(KPI_Mensal!$A$5:$O$16,0,MATCH(N9,KPI_Mensal!$A$4:$O$4,0))),"")) -> 0.8954456 | K9: =IFERROR(INDEX(tbl_objetivos[ID_OBJ],MATCH(A9,tbl_objetivos[ID_KPI],0)),"") -> OBJ-Q-07 | L9: =IFERROR(INDEX(tbl_plano_monitorizacao[ID_MED],MATCH(A9,tbl_plano_monitorizacao[ID_KPI],0)),"") -> PMM-06 | M9: CMP | N9: Lotes_MP_Aceites
A10: KPI-Q-09 | B10: Tempo de resposta dos fornecedores a reclamações (SCAR) | C10: Média dos dias até resposta | D10: dias | E10: Menor | F10: Mensal | G10: reclamações a fornecedores | H10: Responsável de Compras | I10: 7 | J10: =IF(OR(A10="",N10="—"),"",IFERROR(AVERAGE(INDEX(KPI_Mensal!$A$5:$O$16,0,MATCH(N10,KPI_Mensal!$A$4:$O$4,0))),"")) -> 5.9294643 | K10: =IFERROR(INDEX(tbl_objetivos[ID_OBJ],MATCH(A10,tbl_objetivos[ID_KPI],0)),"") | L10: =IFERROR(INDEX(tbl_plano_monitorizacao[ID_MED],MATCH(A10,tbl_plano_monitorizacao[ID_KPI],0)),"") | M10: CMP | N10: Dias_Resposta_SCAR
A11: KPI-Q-10 | B11: CAPA fechadas no prazo | C11: CAPA com prazo no mês fechadas até ao prazo ÷ CAPA com prazo no mês | D11: % | E11: Maior | F11: Mensal | G11: CAPA com prazo no mês | H11: Gerente da Qualidade | I11: 0.85 | J11: =IF(OR(A11="",N11="—"),"",IFERROR(AVERAGE(INDEX(KPI_Mensal!$A$5:$O$16,0,MATCH(N11,KPI_Mensal!$A$4:$O$4,0))),"")) -> 0.48246972 | K11: =IFERROR(INDEX(tbl_objetivos[ID_OBJ],MATCH(A11,tbl_objetivos[ID_KPI],0)),"") -> OBJ-Q-05 | L11: =IFERROR(INDEX(tbl_plano_monitorizacao[ID_MED],MATCH(A11,tbl_plano_monitorizacao[ID_KPI],0)),"") | M11: QUA | N11: CAPA_No_Prazo
A12: KPI-Q-11 | B12: Eficácia das CAPA | C12: Eficazes ÷ (eficazes + não eficazes) | D12: % | E12: Maior | F12: Mensal | G12: CAPA fechadas no mês com eficácia avaliada | H12: Gerente da Qualidade | I12: 0.8 | J12: =IF(OR(A12="",N12="—"),"",IFERROR(AVERAGE(INDEX(KPI_Mensal!$A$5:$O$16,0,MATCH(N12,KPI_Mensal!$A$4:$O$4,0))),"")) -> 0.54713007 | K12: =IFERROR(INDEX(tbl_objetivos[ID_OBJ],MATCH(A12,tbl_objetivos[ID_KPI],0)),"") | L12: =IFERROR(INDEX(tbl_plano_monitorizacao[ID_MED],MATCH(A12,tbl_plano_monitorizacao[ID_KPI],0)),"") -> PMM-10 | M12: QUA | N12: CAPA_Eficacia
A13: KPI-Q-12 | B13: Lotes libertados por concessão | C13: Lotes 'Aprovado por concessão' ÷ lotes decididos | D13: % | E13: Menor | F13: Mensal | G13: disposição de lotes | H13: Gerente da Qualidade | I13: 0.01 | J13: =IF(OR(A13="",N13="—"),"",IFERROR(AVERAGE(INDEX(KPI_Mensal!$A$5:$O$16,0,MATCH(N13,KPI_Mensal!$A$4:$O$4,0))),"")) -> 0.016581069 | K13: =IFERROR(INDEX(tbl_objetivos[ID_OBJ],MATCH(A13,tbl_objetivos[ID_KPI],0)),"") | L13: =IFERROR(INDEX(tbl_plano_monitorizacao[ID_MED],MATCH(A13,tbl_plano_monitorizacao[ID_KPI],0)),"") | M13: LAB | N13: Taxa_Concessao
... A21: KPI-Q-20 | B21: Entregas completas e no prazo (OTIF) | C21: Linhas entregues completas e na data ÷ linhas | D21: % | E21: Maior | F21: Mensal | G21: ERP (simulado — o dataset não tem datas prometidas) | H21: Responsável de Armazém e Logística | I21: 0.97 | J21: =IF(OR(A21="",N21="—"),"",IFERROR(AVERAGE(INDEX(KPI_Mensal!$A$5:$O$16,0,MATCH(N21,KPI_Mensal!$A$4:$O$4,0))),"")) -> 0.9604858 | K21: =IFERROR(INDEX(tbl_objetivos[ID_OBJ],MATCH(A21,tbl_objetivos[ID_KPI],0)),"") -> OBJ-Q-08 | L21: =IFERROR(INDEX(tbl_plano_monitorizacao[ID_MED],MATCH(A21,tbl_plano_monitorizacao[ID_KPI],0)),"") | M21: EXP | N21: OTIF

Sheet Painel_KPI
A1: PAINEL DE KPI DA QUALIDADE — calculado
A2: Último mês = 2026-12 · Estado: verde cumpre a meta; vermelho não cumpre · Tendência = declive dos últimos 6 meses (por mês)
A4: ID_KPI | B4: KPI | C4: Meta | D4: Último mês | E4: Média 12 meses | F4: Tendência 6 m | G4: Polaridade | H4: Estado | I4: A melhorar?
A5: KPI-Q-01 | B5: Taxa de rejeição interna | C5: =INDEX(tbl_kpi[Meta],MATCH(A5,tbl_kpi[ID_KPI],0)) -> 0.02 | D5: =INDEX(tbl_kpi_mensal[Taxa_Rejeicao],18) -> 0.022511395 | E5: =AVERAGE(INDEX(tbl_kpi_mensal[Taxa_Rejeicao],7):INDEX(tbl_kpi_mensal[Taxa_Rejeicao],18)) -> 0.023383414 | F5: =SLOPE(INDEX(tbl_kpi_mensal[Taxa_Rejeicao],13):INDEX(tbl_kpi_mensal[Taxa_Rejeicao],18),{1;2;3;4;5;6}) -> -2.8825751e-06 | G5: =INDEX(tbl_kpi[Polaridade],MATCH(A5,tbl_kpi[ID_KPI],0)) -> Menor | H5: =IF(G5="Maior",IF(D5>=C5,"Cumpre","Não cumpre"),IF(D5<=C5,"Cumpre","Não cumpre")) -> Não cumpre | I5: =IF(G5="Maior",IF(F5>0,"A melhorar","A piorar"),IF(F5<0,"A melhorar","A piorar")) -> A melhorar
A6: KPI-Q-02 | B6: Lotes aprovados à primeira (FPY de lote) | C6: =INDEX(tbl_kpi[Meta],MATCH(A6,tbl_kpi[ID_KPI],0)) -> 0.92 | D6: =INDEX(tbl_kpi_mensal[FPY_Lotes],18) -> 0.85 | E6: =AVERAGE(INDEX(tbl_kpi_mensal[FPY_Lotes],7):INDEX(tbl_kpi_mensal[FPY_Lotes],18)) -> 0.85786631 | F6: =SLOPE(INDEX(tbl_kpi_mensal[FPY_Lotes],13):INDEX(tbl_kpi_mensal[FPY_Lotes],18),{1;2;3;4;5;6}) -> -7.0553385e-06 | G6: =INDEX(tbl_kpi[Polaridade],MATCH(A6,tbl_kpi[ID_KPI],0)) -> Maior | H6: =IF(G6="Maior",IF(D6>=C6,"Cumpre","Não cumpre"),IF(D6<=C6,"Cumpre","Não cumpre")) -> Não cumpre | I6: =IF(G6="Maior",IF(F6>0,"A melhorar","A piorar"),IF(F6<0,"A melhorar","A piorar")) -> A piorar
A7: KPI-Q-03 | B7: PPM de cliente | C7: =INDEX(tbl_kpi[Meta],MATCH(A7,tbl_kpi[ID_KPI],0)) -> 150 | D7: =INDEX(tbl_kpi_mensal[PPM_Cliente],18) -> 221.3013 | E7: =AVERAGE(INDEX(tbl_kpi_mensal[PPM_Cliente],7):INDEX(tbl_kpi_mensal[PPM_Cliente],18)) -> 237.84831 | F7: =SLOPE(INDEX(tbl_kpi_mensal[PPM_Cliente],13):INDEX(tbl_kpi_mensal[PPM_Cliente],18),{1;2;3;4;5;6}) -> 4.3628141 | G7: =INDEX(tbl_kpi[Polaridade],MATCH(A7,tbl_kpi[ID_KPI],0)) -> Menor | H7: =IF(G7="Maior",IF(D7>=C7,"Cumpre","Não cumpre"),IF(D7<=C7,"Cumpre","Não cumpre")) -> Não cumpre | I7: =IF(G7="Maior",IF(F7>0,"A melhorar","A piorar"),IF(F7<0,"A melhorar","A piorar")) -> A piorar
A8: KPI-Q-04 | B8: Reclamações por milhão de unidades expedidas (CPMU) | C8: =INDEX(tbl_kpi[Meta],MATCH(A8,tbl_kpi[ID_KPI],0)) -> 3 | D8: =INDEX(tbl_kpi_mensal[CPMU],18) -> 4.2019234 | E8: =AVERAGE(INDEX(tbl_kpi_mensal[CPMU],7):INDEX(tbl_kpi_mensal[CPMU],18)) -> 4.4303479 | F8: =SLOPE(INDEX(tbl_kpi_mensal[CPMU],13):INDEX(tbl_kpi_mensal[CPMU],18),{1;2;3;4;5;6}) -> 0.0085136775 | G8: =INDEX(tbl_kpi[Polaridade],MATCH(A8,tbl_kpi[ID_KPI],0)) -> Menor | H8: =IF(G8="Maior",IF(D8>=C8,"Cumpre","Não cumpre"),IF(D8<=C8,"Cumpre","Não cumpre")) -> Não cumpre | I8: =IF(G8="Maior",IF(F8>0,"A melhorar","A piorar"),IF(F8<0,"A melhorar","A piorar")) -> A piorar
A9: KPI-Q-05 | B9: Reclamações de serviço / logística | C9: =INDEX(tbl_kpi[Meta],MATCH(A9,tbl_kpi[ID_KPI],0)) -> 5 | D9: =INDEX(tbl_kpi_mensal[Reclamacoes_Servico],18) -> 4 | E9: =AVERAGE(INDEX(tbl_kpi_mensal[Reclamacoes_Servico],7):INDEX(tbl_kpi_mensal[Reclamacoes_Servico],18)) -> 5.6666667 | F9: =SLOPE(INDEX(tbl_kpi_mensal[Reclamacoes_Servico],13):INDEX(tbl_kpi_mensal[Reclamacoes_Servico],18),{1;2;3;4;5;6}) -> 0.25714286 | G9: =INDEX(tbl_kpi[Polaridade],MATCH(A9,tbl_kpi[ID_KPI],0)) -> Menor | H9: =IF(G9="Maior",IF(D9>=C9,"Cumpre","Não cumpre"),IF(D9<=C9,"Cumpre","Não cumpre")) -> Cumpre | I9: =IF(G9="Maior",IF(F9>0,"A melhorar","A piorar"),IF(F9<0,"A melhorar","A piorar")) -> A piorar
A10: KPI-Q-06 | B10: Tempo médio de resolução de reclamações | C10: =INDEX(tbl_kpi[Meta],MATCH(A10,tbl_kpi[ID_KPI],0)) -> 20 | D10: =INDEX(tbl_kpi_mensal[Dias_Resolucao],18) -> 19.615385 | E10: =AVERAGE(INDEX(tbl_kpi_mensal[Dias_Resolucao],7):INDEX(tbl_kpi_mensal[Dias_Resolucao],18)) -> 18.588705 | F10: =SLOPE(INDEX(tbl_kpi_mensal[Dias_Resolucao],13):INDEX(tbl_kpi_mensal[Dias_Resolucao],18),{1;2;3;4;5;6}) -> 0.35415358 | G10: =INDEX(tbl_kpi[Polaridade],MATCH(A10,tbl_kpi[ID_KPI],0)) -> Menor | H10: =IF(G10="Maior",IF(D10>=C10,"Cumpre","Não cumpre"),IF(D10<=C10,"Cumpre","Não cumpre")) -> Cumpre | I10: =IF(G10="Maior",IF(F10>0,"A melhorar","A piorar"),IF(F10<0,"A melhorar","A piorar")) -> A piorar
A11: KPI-Q-07 | B11: OEE médio | C11: =INDEX(tbl_kpi[Meta],MATCH(A11,tbl_kpi[ID_KPI],0)) -> 0.805 | D11: =INDEX(tbl_kpi_mensal[OEE],18) -> 0.7467272 | E11: =AVERAGE(INDEX(tbl_kpi_mensal[OEE],7):INDEX(tbl_kpi_mensal[OEE],18)) -> 0.75346607 | F11: =SLOPE(INDEX(tbl_kpi_mensal[OEE],13):INDEX(tbl_kpi_mensal[OEE],18),{1;2;3;4;5;6}) -> 0.0020364261 | G11: =INDEX(tbl_kpi[Polaridade],MATCH(A11,tbl_kpi[ID_KPI],0)) -> Maior | H11: =IF(G11="Maior",IF(D11>=C11,"Cumpre","Não cumpre"),IF(D11<=C11,"Cumpre","Não cumpre")) -> Não cumpre | I11: =IF(G11="Maior",IF(F11>0,"A melhorar","A piorar"),IF(F11<0,"A melhorar","A piorar")) -> A melhorar
A12: KPI-Q-08 | B12: Lotes de matéria-prima aceites sem derrogação | C12: =INDEX(tbl_kpi[Meta],MATCH(A12,tbl_kpi[ID_KPI],0)) -> 0.95 | D12: =INDEX(tbl_kpi_mensal[Lotes_MP_Aceites],18) -> 0.89320388 | E12: =AVERAGE(INDEX(tbl_kpi_mensal[Lotes_MP_Aceites],7):INDEX(tbl_kpi_mensal[Lotes_MP_Aceites],18)) -> 0.8996116 | F12: =SLOPE(INDEX(tbl_kpi_mensal[Lotes_MP_Aceites],13):INDEX(tbl_kpi_mensal[Lotes_MP_Aceites],18),{1;2;3;4;5;6}) -> -0.0081770453 | G12: =INDEX(tbl_kpi[Polaridade],MATCH(A12,tbl_kpi[ID_KPI],0)) -> Maior | H12: =IF(G12="Maior",IF(D12>=C12,"Cumpre","Não cumpre"),IF(D12<=C12,"Cumpre","Não cumpre")) -> Não cumpre | I12: =IF(G12="Maior",IF(F12>0,"A melhorar","A piorar"),IF(F12<0,"A melhorar","A piorar")) -> A piorar
A13: KPI-Q-09 | B13: Tempo de resposta dos fornecedores a reclamações (SCAR) | C13: =INDEX(tbl_kpi[Meta],MATCH(A13,tbl_kpi[ID_KPI],0)) -> 7 | D13: =INDEX(tbl_kpi_mensal[Dias_Resposta_SCAR],18) -> 8.75 | E13: =AVERAGE(INDEX(tbl_kpi_mensal[Dias_Resposta_SCAR],7):INDEX(tbl_kpi_mensal[Dias_Resposta_SCAR],18)) -> 6.3720238 | F13: =SLOPE(INDEX(tbl_kpi_mensal[Dias_Resposta_SCAR],13):INDEX(tbl_kpi_mensal[Dias_Resposta_SCAR],18),{1;2;3;4;5;6}) -> 0.0042857143 | G13: =INDEX(tbl_kpi[Polaridade],MATCH(A13,tbl_kpi[ID_KPI],0)) -> Menor | H13: =IF(G13="Maior",IF(D13>=C13,"Cumpre","Não cumpre"),IF(D13<=C13,"Cumpre","Não cumpre")) -> Não cumpre | I13: =IF(G13="Maior",IF(F13>0,"A melhorar","A piorar"),IF(F13<0,"A melhorar","A piorar")) -> A piorar
A14: KPI-Q-10 | B14: CAPA fechadas no prazo | C14: =INDEX(tbl_kpi[Meta],MATCH(A14,tbl_kpi[ID_KPI],0)) -> 0.85 | D14: =INDEX(tbl_kpi_mensal[CAPA_No_Prazo],18) -> 0.53571429 | E14: =AVERAGE(INDEX(tbl_kpi_mensal[CAPA_No_Prazo],7):INDEX(tbl_kpi_mensal[CAPA_No_Prazo],18)) -> 0.51785744 | F14: =SLOPE(INDEX(tbl_kpi_mensal[CAPA_No_Prazo],13):INDEX(tbl_kpi_mensal[CAPA_No_Prazo],18),{1;2;3;4;5;6}) -> -0.0038101162 | G14: =INDEX(tbl_kpi[Polaridade],MATCH(A14,tbl_kpi[ID_KPI],0)) -> Maior | H14: =IF(G14="Maior",IF(D14>=C14,"Cumpre","Não cumpre"),IF(D14<=C14,"Cumpre","Não cumpre")) -> Não cumpre | I14: =IF(G14="Maior",IF(F14>0,"A melhorar","A piorar"),IF(F14<0,"A melhorar","A piorar")) -> A piorar
A15: KPI-Q-11 | B15: Eficácia das CAPA | C15: =INDEX(tbl_kpi[Meta],MATCH(A15,tbl_kpi[ID_KPI],0)) -> 0.8 | D15: =INDEX(tbl_kpi_mensal[CAPA_Eficacia],18) -> 0.46428571 | E15: =AVERAGE(INDEX(tbl_kpi_mensal[CAPA_Eficacia],7):INDEX(tbl_kpi_mensal[CAPA_Eficacia],18)) -> 0.57220399 | F15: =SLOPE(INDEX(tbl_kpi_mensal[CAPA_Eficacia],13):INDEX(tbl_kpi_mensal[CAPA_Eficacia],18),{1;2;3;4;5;6}) -> -0.030042017 | G15: =INDEX(tbl_kpi[Polaridade],MATCH(A15,tbl_kpi[ID_KPI],0)) -> Maior | H15: =IF(G15="Maior",IF(D15>=C15,"Cumpre","Não cumpre"),IF(D15<=C15,"Cumpre","Não cumpre")) -> Não cumpre | I15: =IF(G15="Maior",IF(F15>0,"A melhorar","A piorar"),IF(F15<0,"A melhorar","A piorar")) -> A piorar
A16: KPI-Q-12 | B16: Lotes libertados por concessão | C16: =INDEX(tbl_kpi[Meta],MATCH(A16,tbl_kpi[ID_KPI],0)) -> 0.01 | D16: =INDEX(tbl_kpi_mensal[Taxa_Concessao],18) -> 0.0092592593 | E16: =AVERAGE(INDEX(tbl_kpi_mensal[Taxa_Concessao],7):INDEX(tbl_kpi_mensal[Taxa_Concessao],18)) -> 0.012126642 | F16: =SLOPE(INDEX(tbl_kpi_mensal[Taxa_Concessao],13):INDEX(tbl_kpi_mensal[Taxa_Concessao],18),{1;2;3;4;5;6}) -> -0.0013510055 | G16: =INDEX(tbl_kpi[Polaridade],MATCH(A16,tbl_kpi[ID_KPI],0)) -> Menor | H16: =IF(G16="Maior",IF(D16>=C16,"Cumpre","Não cumpre"),IF(D16<=C16,"Cumpre","Não cumpre")) -> Cumpre | I16: =IF(G16="Maior",IF(F16>0,"A melhorar","A piorar"),IF(F16<0,"A melhorar","A piorar")) -> A melhorar
A17: KPI-Q-13 | B17: Subgrupos SPC com Cpk ≥ 1,00 | C17: =INDEX(tbl_kpi[Meta],MATCH(A17,tbl_kpi[ID_KPI],0)) -> 0.7 | D17: =INDEX(tbl_kpi_mensal[Pct_Cpk_1],18) -> 0.44282754 | E17: =AVERAGE(INDEX(tbl_kpi_mensal[Pct_Cpk_1],7):INDEX(tbl_kpi_mensal[Pct_Cpk_1],18)) -> 0.44988948 | F17: =SLOPE(INDEX(tbl_kpi_mensal[Pct_Cpk_1],13):INDEX(tbl_kpi_mensal[Pct_Cpk_1],18),{1;2;3;4;5;6}) -> 0.0017741869 | G17: =INDEX(tbl_kpi[Polaridade],MATCH(A17,tbl_kpi[ID_KPI],0)) -> Maior | H17: =IF(G17="Maior",IF(D17>=C17,"Cumpre","Não cumpre"),IF(D17<=C17,"Cumpre","Não cumpre")) -> Não cumpre | I17: =IF(G17="Maior",IF(F17>0,"A melhorar","A piorar"),IF(F17<0,"A melhorar","A piorar")) -> A melhorar
