Workbook
Name DataRef: Listas!$A$3
Name lst_Classificacao: Listas!$E$3:$E$5
Name lst_CondicaoAmbiental: Listas!$C$3:$C$8
Name lst_Cruzamento: Listas!$O$3:$O$6
Name lst_DataReferencia: Listas!$A$3:$A$3
Name lst_Dimensao: Listas!$B$3:$B$8
Name lst_Direcao: Listas!$D$3:$D$6
Name lst_Escala13: Listas!$H$3:$H$5
Name lst_ESG: Listas!$M$3:$M$9
Name lst_Funcao: Listas!$N$3:$N$28
Name lst_Horizonte: Listas!$G$3:$G$5
Name lst_PI_Nivel: Listas!$Q$3:$Q$5
Name lst_PI_Obrig: Listas!$R$3:$R$6
Name lst_PI_Tipo: Listas!$P$3:$P$4
Name lst_Processo: Listas!$K$3:$K$20
Name lst_Quadrante: Listas!$I$3:$I$6
Name lst_SimNao: Listas!$J$3:$J$4
Name lst_Tema: Listas!$L$3:$L$15
Name lst_Tendencia: Listas!$F$3:$F$5

Sheet 00_LEIA-ME
A1: RG-SGQ-01 — Contexto da Organização — PESTEL, SWOT, Partes Interessadas, 5 Forças e TOWS (SGQ) · Âmbito
A2: Sistema de Gestão da Qualidade NP EN ISO 9001:2026 · Plasticom — Unidade 1 (Marinha Grande, Portugal) · Registo do SGQ (fábrica simulada)
A4: CONTROLO DO DOCUMENTO (7.5 — informação documentada)
A5: Código do registo | B5: RG-SGQ-01
A6: Título | B6: Contexto da Organização — PESTEL, SWOT, Partes Interessadas, 5 Forças e TOWS (SGQ) · Âmbito
A7: Versão / Revisão | B7: 01
A8: Data de emissão | B8: 46387
A9: Elaborado por | B9: Gerente da Qualidade
A10: Aprovado por | B10: Diretor Geral
A11: Estado | B11: Em vigor
A12: Retenção | B12: 5 anos após substituição
A13: Localização | B13: Repositório controlado do SGQ > Registos_SGQ_Plasticom (a versão eletrónica é a controlada; cópias impressas são não controladas). Proteção contra alterações não intencionais (7.5.3.2): edição só pelo dono do registo; histórico de versões no repositório.
A15: FINALIDADE E ÂMBITO
A16: Finalidade | B16: Registar, com evidência, as questões de contexto que afetam a capacidade da Plasticom de fornecer produtos conformes e aumentar a satisfação do cliente, os requisitos pertinentes das partes interessadas e a decisão sobre quais são tratados pelo SGQ, e o âmbito do SGQ. Base para os riscos e oportunidades (RG-SGQ-04) e para a revisão pela gestão (9.3.2 b, c). Estrutura igual à do RG-SGA-01 para consolidar o contexto do SGI num único modelo para a gestão de topo.
A17: Utilização / atividades | B17: Determinar e rever as questões externas (PESTEL) e internas/externas (SWOT) pertinentes para o SGQ, incluindo alterações climáticas; cruzamento estratégico (TOWS) e forças competitivas; partes interessadas e os requisitos que o SGQ trata; âmbito e aplicabilidade.
A18: Requisitos ISO 9001:2026 | B18: 4.1 Compreender a organização e o seu contexto (inclui determinar se as alterações climáticas são pertinentes); 4.2 Necessidades e expectativas das partes interessadas (a, b, c); 4.3 Âmbito do SGQ (disponível como informação documentada, com justificação de não aplicabilidade)
A20: REFERÊNCIAS DE BOAS PRÁTICAS APLICADAS (orientação — não são requisitos auditáveis da ISO 9001)
A21: ISO/TC 176 APG — Context of the organization | B21: O auditor procura evidência de que as questões são conhecidas, monitorizadas e usadas no planeamento, não um documento PESTEL isolado: colunas Efeito_no_SGQ, Fonte_Monitorizacao, Resposta_Estrategica, ID_RO e Proxima_Revisao.
A22: ISO/TC 176 APG — Climate change issues (Amd 1:2024) | B22: A determinação sobre as alterações climáticas é registada com a justificação (tbl_clima) e os fatores climáticos marcados em Condicao_Ambiental_ISO2026 = Clima.
A23: iso9001help.co.uk — Navigator Pro (Planning stage) | B23: Contexto → partes interessadas → âmbito como entradas encadeadas do planeamento do SGQ.
A25: ESTRUTURA DO FICHEIRO
A26: PESTEL | B26: Registo das questões externas (PESTEL) pertinentes para o SGQ, com a mesma estrutura do RG-SGA-01.
A27: SWOT | B27: Registo SWOT do SGQ (formato longo: um item por linha), com a mesma estrutura do RG-SGA-01. Prioritario marca 1 item por quadrante.
A28: Matriz_TOWS | B28: Cruzamento estratégico SWOT (TOWS) que liga o contexto aos objetivos da qualidade e aos riscos do SGI.
A29: Cinco_Forcas | B29: Cinco forças competitivas (Porter) com a lente da qualidade, ligadas aos riscos/oportunidades do RG-SGA-02.
A30: Vista_SWOT | B30: Quadro SWOT 2×2 para impressão, calculado por fórmulas a partir de tbl_swot (não editar aqui).
A31: Partes_Interessadas | B31: Partes interessadas pertinentes, os seus requisitos e a decisão de quais são tratados pelo SGQ (4.2 a–c), com a mesma estrutura do RG-SGA-01.
A32: Alteracoes_Climaticas | B32: Determinação documentada sobre se as alterações climáticas são uma questão pertinente (4.1) e requisitos das partes interessadas relacionados (4.2 Nota).
A33: Ambito_SGQ | B33: Âmbito do SGQ disponível como informação documentada (4.3).
A34: Aplicabilidade | B34: Cláusulas cuja aplicabilidade foi analisada e a justificação (4.3).
A35: Resumo_Contexto | B35: Resumo calculado: fatores por classificação e prioridade; requisitos tratados pelo SGQ.
A36: Listas | B36: Domínios (listas de valores) usados na validação de dados das tabelas.
A37: Dicionario_Dados | B37: Descrição de cada coluna de cada tabela: tipo, origem (entrada/calculado), domínio, obrigatoriedade e chaves.
A39: CONVENÇÕES (prontas para análise de dados e machine learning)
A40: Tabelas | B40: Cada registo é uma Tabela Excel com nome próprio (tbl_*): uma linha = um registo, cabeçalho único, sem células mescladas. Ler com pandas (pd.read_excel(ficheiro, sheet_name=folha, header=<linha do cabeçalho - 1>)) ou Power BI (Obter Dados > Tabela).
A41: Cabeçalho cinzento | B41: Coluna CALCULADA por fórmula — não escrever por cima. As restantes colunas são de entrada.
A42: Validação | B42: Colunas com lista controlada só aceitam valores da folha Listas (evita categorias duplicadas por grafia diferente).
A43: Chaves | B43: IDs estáveis e únicos (PK) e referências a IDs de outros registos (FK) permitem juntar tabelas entre ficheiros do SGQ e do SGA — ver SGQ-00_Indice_Modelo_Dados.xlsx.
A44: Datas e unidades | B44: Datas em formato data (aaaa-mm-dd); números como números; a unidade está no nome da coluna ou no dicionário. Data de referência do SGQ: 2026-12-31.
A45: Dados | B45: Fábrica simulada Plasticom. Dados operacionais e de qualidade extraídos do dataset do projeto (datasets/silver e datasets/dim, período 2025-07-01 a 2026-12-31); os campos de gestão que o dataset não tem (datas de resposta, avaliações, decisões) são simulação didática coerente com esses dados.
...

Sheet PESTEL
A1: PESTEL — QUESTÕES EXTERNAS PERTINENTES PARA O SGQ (4.1)
A2: Mesma estrutura do RG-SGA-01 tbl_pestel · Ambito = SGQ · Clima marcado em Condicao_Ambiental_ISO2026 · Rever na revisão pela gestão
A4: ID_PESTEL | B4: Dimensao | C4: Fator_Externo | D4: Descricao | E4: Condicao_Ambiental_ISO2026 | F4: Direcao_Efeito | G4: Efeito_no_SGQ | H4: Classificacao | I4: Tendencia | J4: Horizonte | K4: Probabilidade_1a3 | L4: Impacto_1a3 | M4: Score | N4: Prioridade | O4: Fonte_Monitorizacao | P4: Resposta_Estrategica | Q4: ID_SWOT | R4: ID_RO | S4: Parte_Interessada | T4: Tema | U4: ESG | V4: Dono | W4: Data_Avaliacao | X4: Proxima_Revisao | Y4: Ambito | Z4: IDs_Risco_SGI | AA4: ID_Contexto_SGI
A5: PESQ-01 | B5: Económico | C5: Entrada nos mercados alimentar e farmacêutico | D5: 4 clientes novos (CUST-015 a CUST-018) e 17 SKU lançados em jul/2026 (dataset desde 06/07/2026). | E5: Não aplicável | F5: Não aplicável | G5: Exige requisitos legais de produto (Reg. 10/2011, 21 CFR 211.132), validação de processos e rastreabilidade mais rigorosos. | H5: Oportunidade | I5: Crescente | J5: Curto (<1 ano) | K5: 3 | L5: 3 | M5: =IF(A5="","",K5*L5) -> 9 | N5: =IF(A5="","",IF(M5>=6,"Alta",IF(M5>=3,"Média","Baixa"))) -> Alta | O5: Revisão de requisitos (RG-SGQ-10) e projetos D&D (RG-SGQ-11) — trimestral | P5: Stage-gate de D&D com validação de processo e safe launch por SKU. | Q5: SWTQ-O01 | R5: O12 | S5: Clientes alimentar e farmacêutico | T5: Cliente / mercado | U5: S + G | V5: Responsável de R&D | W5: 46387 | X5: =IF(A5="","",EDATE(W5,12)) -> 46752 | Y5: SGQ | Z5: R12; O12 | AA5: SWT-F04
A6: PESQ-02 | B6: Legal | C6: Materiais em contacto com alimentos e embalagem farmacêutica | D6: Reg. (CE) 1935/2004, Reg. (UE) 10/2011, BPF (Reg. 2023/2006) e 21 CFR 211.132: migração EN 1186-3 por lote e anel de inviolabilidade. | E6: Não aplicável | F6: Não aplicável | G6: Um lote não conforme em alimentar/farma tem consequências legais e de saúde; aumenta o custo de avaliação (ensaios de migração). | H6: Risco | I6: Crescente | J6: Curto (<1 ano) | K6: 3 | L6: 3 | M6: =IF(A6="","",K6*L6) -> 9 | N6: =IF(A6="","",IF(M6>=6,"Alta",IF(M6>=3,"Média","Baixa"))) -> Alta | O6: Vigilância legal e normativa (RG-SGQ-08 Documentos_Externos) — mensal | P6: Plano de controlo com ensaio de migração por lote e validação do processo (8.5.1 f). | Q6: SWTQ-T02 | R6: R16 | S6: Autoridades (ASAE, INFARMED, DGAV) | T6: Legal / conformidade | U6: S + G | V6: Gerente da Qualidade | W6: 46387 | X6: =IF(A6="","",EDATE(W6,12)) -> 46752 | Y6: SGQ | Z6: R16; R33 | AA6: PES-18
A7: PESQ-03 | B7: Económico | C7: Clientes exigem Cpk ≥ 1,33, zero defeito e rastreabilidade | D7: Raio-X analítico: 190 grupos máquina × molde × característica com Cpk < 1,33; CPMU 4,5 reclamações por milhão. | E7: Não aplicável | F7: Não aplicável | G7: 0% dos grupos com Cpk ≥ 1,33: risco de reclamações e de perda de clientes. | H7: Risco | I7: Crescente | J7: Curto (<1 ano) | K7: 3 | L7: 3 | M7: =IF(A7="","",K7*L7) -> 9 | N7: =IF(A7="","",IF(M7>=6,"Alta",IF(M7>=3,"Média","Baixa"))) -> Alta | O7: KPI Cpk e PPM de cliente (RG-SGQ-05) — mensal | P7: Estudos de capacidade por Pareto e controlo estatístico nas características críticas (OBJ-Q-04). | Q7: SWTQ-T01 | R7: R17 | S7: Clientes de cosmética (marcas UE) | T7: Processo / capacidade | U7: S + G | V7: Gerente da Qualidade | W7: 46387 | X7: =IF(A7="","",EDATE(W7,12)) -> 46752 | Y7: SGQ | Z7: R16; R17 | AA7: SWT-T04; PES-18
A8: PESQ-04 | B8: Económico | C8: Pressão de preço e sazonalidade da procura (pico set–nov) | D8: Margem ≈ € 0,13/un; produção jul–set/2026 +30% face ao 1.º semestre. | E8: Não aplicável | F8: Não aplicável | G8: O pico aumenta turnos, operadores temporários e risco de defeito; pressão para aceitar concessões. | H8: Risco e Oportunidade | I8: Estável | J8: Curto (<1 ano) | K8: 2 | L8: 2 | M8: =IF(A8="","",K8*L8) -> 4 | N8: =IF(A8="","",IF(M8>=6,"Alta",IF(M8>=3,"Média","Baixa"))) -> Média | O8: Plano de capacidade e KPI de concessões (RG-SGQ-05) — mensal | P8: Planeamento de capacidade antes do pico e concessões só com aprovação do cliente. | R8: O14 | S8: Acionistas / Direção | T8: Cliente / mercado | U8: S + G | V8: Gerente de Produção | W8: 46387 | X8: =IF(A8="","",EDATE(W8,12)) -> 46752 | Y8: SGQ | Z8: O14; R23 | AA8: PES-20; SWT-O05
A9: PESQ-05 | B9: Económico | C9: Qualidade variável de resinas de fornecedores spot e de PCR/rPET | D9: Inspeção de receção: 1.896 lotes, 73 rejeitados e 117 aceites com derrogação; SUP-005 com 74,5% de lotes aceites. | E9: Recursos naturais | F9: Ambiente → Organização | G9: Lotes de matéria-prima fora de especificação passam à produção e geram defeito e scrap. | H9: Risco | I9: Crescente | J9: Médio (1-3 anos) | K9: 3 | L9: 2 | M9: =IF(A9="","",K9*L9) -> 6 | N9: =IF(A9="","",IF(M9>=6,"Alta",IF(M9>=3,"Média","Baixa"))) -> Alta | O9: Scorecard de fornecedores (RG-SGQ-12) — mensal | P9: Scorecard A–D, SCAR com 8D e qualificação de fontes alternativas (OBJ-Q-07). | Q9: SWTQ-T03 | R9: R13 | S9: Fornecedores de resinas e masterbatch | T9: Cadeia de valor / fornecedores | U9: S + G | V9: Responsável de Compras | W9: 46387 | X9: =IF(A9="","",EDATE(W9,12)) -> 46752 | Y9: SGQ | Z9: R13; R14; R36 | AA9: SWT-W02; SWT-T02; PES-03
A10: PESQ-06 | B10: Ambiental | C10: Ondas de calor na nave de produção | D10: Temperatura ambiente > 30 °C; julho/2026: alarme de temperatura dos moldes (INC-2026-08 do SGA). | E10: Clima | F10: Ambiente → Organização | G10: Aumenta a variação de peso/espessura no sopro de PET (condicionamento de preformas) e o tempo de ciclo; risco para a conformidade. | H10: Risco | I10: Crescente | J10: Médio (1-3 anos) | K10: 3 | L10: 2 | M10: =IF(A10="","",K10*L10) -> 6 | N10: =IF(A10="","",IF(M10>=6,"Alta",IF(M10>=3,"Média","Baixa"))) -> Alta | O10: Temperatura da nave e do chiller (RG-SGQ-02 Ambiente_Operacao) — diária no verão | P10: Janela de processo de verão validada e reforço do arrefecimento dos moldes. | Q10: SWTQ-T04 | R10: R34 | S10: Clientes de cosmética (marcas UE) | T10: Clima / GEE | U10: E + G | V10: Gerente de Manutenção | W10: 46387 | X10: =IF(A10="","",EDATE(W10,12)) -> 46752 | Y10: SGQ | Z10: R34 | AA10: PES-08; SWT-T01
A11: PESQ-07 | B11: Ambiental | C11: Disrupções da cadeia de abastecimento por eventos climáticos extremos | D11: Portos, transporte e fábricas de polímero (EUA, Singapura); paragens 'Raw Material Shortage' no dataset de paragens. | E11: Clima | F11: Ambiente → Organização | G11: A falta de matéria-prima interrompe ordens de produção e entregas (OTIF). | H11: Risco | I11: Crescente | J11: Médio (1-3 anos) | K11: 2 | L11: 3 | M11: =IF(A11="","",K11*L11) -> 6 | N11: =IF(A11="","",IF(M11>=6,"Alta",IF(M11>=3,"Média","Baixa"))) -> Alta | O11: Stock de segurança e fornecedores alternativos aprovados (RG-SGQ-12) — mensal | P11: Stock de segurança, segunda fonte aprovada e aviso ao cliente (8.2.1 e). | Q11: SWTQ-T04 | R11: R15 | S11: Clientes (todos) | T11: Cadeia de valor / fornecedores | U11: E + G | V11: Responsável de Compras | W11: 46387 | X11: =IF(A11="","",EDATE(W11,12)) -> 46752 | Y11: SGQ | Z11: R15; R34 | AA11: PES-19; SWT-T01
A12: PESQ-08 | B12: Social | C12: Clientes pedem pegada de carbono e conteúdo reciclado do produto | D12: Questionários ESG de CUST-001, CUST-011 e CUST-013 (requisitos relacionados com o clima — 4.2 Nota). | E12: Clima | F12: Organização → Ambiente | G12: O requisito do cliente passa a requisito de produto a rever em 8.2 (declarações PCR e PCF). | H12: Oportunidade | I12: Crescente | J12: Curto (<1 ano) | K12: 2 | L12: 3 | M12: =IF(A12="","",K12*L12) -> 6 | N12: =IF(A12="","",IF(M12>=6,"Alta",IF(M12>=3,"Média","Baixa"))) -> Alta | O12: Requisitos específicos de cliente (RG-SGQ-10) — semestral | P12: Tratar as declarações PCR/PCF como requisito de produto quando especificadas. | Q12: SWTQ-O02 | R12: O5 | S12: Clientes de cosmética (marcas UE) | T12: Produto / embalagem | U12: E + S + G | V12: Diretor Comercial | W12: 46387 | X12: =IF(A12="","",EDATE(W12,12)) -> 46752 | Y12: SGQ | Z12: O5; R33 | AA12: PES-04; SWT-O01
A13: PESQ-09 | B13: Tecnológico | C13: Visão artificial, sensores e analytics para prevenir defeitos | D13: 10 de 22 máquinas com deteção automática de defeitos. | E13: Não aplicável | F13: Não aplicável | G13: Permite passar da inspeção por amostragem AQL ao controlo em linha nas características críticas. | H13: Oportunidade | I13: Crescente | J13: Curto (<1 ano) | K13: 2 | L13: 3 | M13: =IF(A13="","",K13*L13) -> 6 | N13: =IF(A13="","",IF(M13>=6,"Alta",IF(M13>=3,"Média","Baixa"))) -> Alta | O13: Roadmap Quality 4.0 (RG-SGQ-19) — semestral | P13: Business case de visão artificial nas características críticas. | Q13: SWTQ-O03 | R13: O13 | S13: Acionistas / Direção | T13: Governação e dados | U13: G | V13: Gerente de Dados / TI | W13: 46387 | X13: =IF(A13="","",EDATE(W13,12)) -> 46752 | Y13: SGQ | Z13: O3; O13 | AA13: PES-06; SWT-O04
A14: PESQ-10 | B14: Legal | C14: PPWR (Reg. UE 2025/40) aplicável desde 12/08/2026 | D14: Só 9 de 22 famílias com dossier PPWR (NC-SGA-26-02). | E14: Recursos naturais | F14: Organização → Ambiente | G14: A documentação técnica e a declaração UE de conformidade passam a fazer parte das saídas do design e da libertação. | H14: Risco | I14: Crescente | J14: Curto (<1 ano) | K14: 3 | L14: 2 | M14: =IF(A14="","",K14*L14) -> 6 | N14: =IF(A14="","",IF(M14>=6,"Alta",IF(M14>=3,"Média","Baixa"))) -> Alta | O14: Matriz legal de produto (RG-SGA-20) e saídas de D&D (RG-SGQ-11) — mensal | P14: Dossier técnico por família como saída obrigatória do D&D. | Q14: SWTQ-T02 | R14: R33 | S14: Clientes (todos) | T14: Legal / conformidade | U14: E + G | V14: Responsável de R&D | W14: 46387 | X14: =IF(A14="","",EDATE(W14,12)) -> 46752 | Y14: SGQ | Z14: R33 | AA14: PES-12
A15: PESQ-11 | B15: Legal | C15: Transição para a ISO 9001:2026 (regras IAF, até set/2029) | D15: Novos requisitos: alterações climáticas (4.1/4.2), cultura da qualidade e ética (5.1.1 i, 7.3 e), oportunidades (6.1.3), contingência (8.2.1 e). | E15: Não aplicável | F15: Não aplicável | G15: Condiciona o programa de auditoria e o plano de transição (MOC-Q-26-01). | H15: Risco e Oportunidade | I15: Estável | J15: Médio (1-3 anos) | K15: 2 | L15: 2 | M15: =IF(A15="","",K15*L15) -> 4 | N15: =IF(A15="","",IF(M15>=6,"Alta",IF(M15>=3,"Média","Baixa"))) -> Média | O15: Plano de transição e programa de auditoria (RG-SGQ-16) — trimestral | P15: Plano de transição e auditoria interna às cláusulas novas antes da auditoria de certificação. | R15: O12 | S15: Organismo de certificação | T15: Legal / conformidade | U15: G | V15: Gerente da Qualidade | W15: 46387 | X15: =IF(A15="","",EDATE(W15,12)) -> 46752 | Y15: SGQ | Z15: O12 | AA15: PES-18
M16: =IF(A16="","",K16*L16) | N16: =IF(A16="","",IF(M16>=6,"Alta",IF(M16>=3,"Média","Baixa"))) | X16: =IF(A16="","",EDATE(W16,12))
M17: =IF(A17="","",K17*L17) | N17: =IF(A17="","",IF(M17>=6,"Alta",IF(M17>=3,"Média","Baixa"))) | X17: =IF(A17="","",EDATE(W17,12))
M18: =IF(A18="","",K18*L18) | N18: =IF(A18="","",IF(M18>=6,"Alta",IF(M18>=3,"Média","Baixa"))) | X18: =IF(A18="","",EDATE(W18,12))
M19: =IF(A19="","",K19*L19) | N19: =IF(A19="","",IF(M19>=6,"Alta",IF(M19>=3,"Média","Baixa"))) | X19: =IF(A19="","",EDATE(W19,12))
M20: =IF(A20="","",K20*L20) | N20: =IF(A20="","",IF(M20>=6,"Alta",IF(M20>=3,"Média","Baixa"))) | X20: =IF(A20="","",EDATE(W20,12))
M21: =IF(A21="","",K21*L21) | N21: =IF(A21="","",IF(M21>=6,"Alta",IF(M21>=3,"Média","Baixa"))) | X21: =IF(A21="","",EDATE(W21,12))

Sheet SWOT
A1: SWOT — QUESTÕES INTERNAS E EXTERNAS PERTINENTES PARA O SGQ (4.1)
A2: Mesma estrutura do RG-SGA-01 tbl_swot · Internas: valores, cultura, conhecimento, desempenho (4.1 Nota 3)
A4: ID_SWOT | B4: Quadrante | C4: Natureza | D4: Descricao | E4: Evidencia | F4: Implicacao_SGQ | G4: Processo | H4: Tema | I4: ID_PESTEL | J4: Converte_em | K4: ID_RO | L4: Prioritario | M4: Estrategia | N4: Indicador | O4: Data_Avaliacao | P4: Chave_Vista | Q4: Ambito | R4: IDs_Risco_SGI | S4: ID_Contexto_SGI
A5: SWTQ-F01 | B5: Força | C5: =IF(A5="","",IF(OR(B5="Força",B5="Fraqueza"),"Interno","Externo")) -> Interno | D5: Cultura de dados: 18 meses de OEE, SPC, AQL e rastreabilidade lote → ordem num data warehouse (bronze/silver/gold) com Power BI. | E5: Data warehouse medalhão e dashboards de produção e qualidade. | F5: Permite análise e avaliação baseada em evidência (9.1.3) e auditorias priorizadas pelo risco. | G5: TI | H5: Governação e dados | I5: PESQ-09 | J5: Oportunidade | K5: O3 | L5: Sim | M5: Controlo de dados e software (RG-SGQ-08) e painel de KPI (RG-SGQ-05). | N5: N.º de KPI da qualidade com dados automáticos | O5: 46387 | P5: =IF(A5="","",B5&"|"&COUNTIF(INDEX($B$5:$B$26,1):B5,B5)) -> Força|1 | Q5: SGQ | R5: O3; R26 | S5: SWT-F01; SWT-F05
A6: SWTQ-F02 | B6: Força | C6: =IF(A6="","",IF(OR(B6="Força",B6="Fraqueza"),"Interno","Externo")) -> Interno | D6: Sistema de medição adequado no peso das tampas (%GRR 3,5% da variação total; ndc 40). | E6: Estudo GRR-CAP-WEIGHT-001 (ago/2026). | F6: Decisões de conformidade confiáveis no peso; base para alargar o MSA a espessura, binário e inspeção visual. | G6: MET | H6: Medição / metrologia | J6: Oportunidade | L6: Não | M6: Alargar o MSA às restantes características críticas (plano MSA — RG-SGQ-09). | N6: % de características críticas com MSA aceite | O6: 46387 | P6: =IF(A6="","",B6&"|"&COUNTIF(INDEX($B$5:$B$26,1):B6,B6)) -> Força|2 | Q6: SGQ | R6: R17 | S6: SWT-F06
A7: SWTQ-F03 | B7: Força | C7: =IF(A7="","",IF(OR(B7="Força",B7="Fraqueza"),"Interno","Externo")) -> Interno | D7: Estratégia 2026–2028 aprovada: crescer em alimentar/farma e certificar o SGI (ISO 9001:2026 + ISO 14001:2026). | E7: Plano estratégico 2026–2028 aprovado pela Direção. | F7: Integra os requisitos do SGQ nos processos de negócio (5.1.1 b) e define prioridades de investimento. | G7: GES | H7: Governação e dados | I7: PESQ-01 | J7: Oportunidade | K7: O12 | L7: Não | M7: Revisão pela gestão semestral (RG-SGQ-17) com objetivos ligados à estratégia. | N7: % de objetivos da qualidade no prazo | O7: 46387 | P7: =IF(A7="","",B7&"|"&COUNTIF(INDEX($B$5:$B$26,1):B7,B7)) -> Força|3 | Q7: SGQ | R7: O12
A8: SWTQ-F04 | B8: Força | C8: =IF(A8="","",IF(OR(B8="Força",B8="Fraqueza"),"Interno","Externo")) -> Interno | D8: Causas-raiz conhecidas com evidência causal forte (IM-002 com MSA e DOE; SS-001 e M-SOP-007 respondem à intervenção). | E8: Estudos DOE/MSA; PFMEA (RG-SGQ-04). | F8: Ações de alta confiança reduzem rejeição, refação e reclamações. | G8: INJ | H8: Processo / capacidade | J8: Oportunidade | K8: O1 | L8: Não | M8: Replicar a janela validada da IM-002 e a manutenção por condição (O1, O2). | N8: Short shot IM-002 (DPMO) | O8: 46387 | P8: =IF(A8="","",B8&"|"&COUNTIF(INDEX($B$5:$B$26,1):B8,B8)) -> Força|4 | Q8: SGQ | R8: O1; O2 | S8: SWT-F06
A9: SWTQ-W01 | B9: Fraqueza | C9: =IF(A9="","",IF(OR(B9="Força",B9="Fraqueza"),"Interno","Externo")) -> Interno | D9: Desempenho da qualidade abaixo da meta: rejeição ≈ 2,4% (meta 2,0%), FPY 88,7% e 31% das CAPA não eficazes. | E9: Charter do projeto: FPY 0,887; CAPA vencidas 49%. | F9: Custo da não qualidade e reclamações; sistema de ação corretiva pouco eficaz. | G9: QUA | H9: Custo da qualidade | J9: Risco | K9: R20 | L9: Sim | M9: KPI mensais (RG-SGQ-05) e eficácia das CAPA (RG-SGQ-18). | N9: Taxa de rejeição; % de CAPA eficazes | O9: 46387 | P9: =IF(A9="","",B9&"|"&COUNTIF(INDEX($B$5:$B$26,1):B9,B9)) -> Fraqueza|1 | Q9: SGQ | R9: R20; R24 | S9: SWT-W03
A10: SWTQ-W02 | B10: Fraqueza | C10: =IF(A10="","",IF(OR(B10="Força",B10="Fraqueza"),"Interno","Externo")) -> Interno | D10: Cultura de produtividade: pressão por meta e prémio de defeito no turno 2 (fadiga, passagem de turno). | E10: Taxa de rejeição do turno 2 acima dos turnos 1 e 3 (raio-X analítico). | F10: Aumenta a rejeição em todos os processos e reduz o relato de problemas (cultura da qualidade, 5.1.1 i). | G10: PCP | H10: Cultura da qualidade | J10: Risco | K10: R9 | L10: Não | M10: Avaliação da cultura da qualidade (RG-SGQ-03) e KPI por turno. | N10: Rejeição do turno 2 vs. média da fábrica | O10: 46387 | P10: =IF(A10="","",B10&"|"&COUNTIF(INDEX($B$5:$B$26,1):B10,B10)) -> Fraqueza|2 | Q10: SGQ | R10: R9 | S10: PES-16
A11: SWTQ-W03 | B11: Fraqueza | C11: =IF(A11="","",IF(OR(B11="Força",B11="Fraqueza"),"Interno","Externo")) -> Interno | D11: Conhecimento crítico concentrado em poucas pessoas (afinação de moldes, DOE da IM-002, Gage R&R). | E11: 3 técnicos com > 10 anos concentram as afinações de molde. | F11: A saída de uma pessoa-chave põe em risco a afinação e a validação de processos. | G11: RH | H11: Conhecimento | J11: Risco | L11: Não | M11: Registo de conhecimento organizacional e polivalência (RG-SGQ-07). | N11: N.º de conhecimentos críticos com ≥ 2 detentores | O11: 46387 | P11: =IF(A11="","",B11&"|"&COUNTIF(INDEX($B$5:$B$26,1):B11,B11)) -> Fraqueza|3 | Q11: SGQ | R11: O1
A12: SWTQ-W04 | B12: Fraqueza | C12: =IF(A12="","",IF(OR(B12="Força",B12="Fraqueza"),"Interno","Externo")) -> Interno | D12: Frota com máquinas antigas (5 máquinas de 2011–2013) e 4 máquinas novas em 2026 por qualificar. | E12: Perfil de máquinas: ano de instalação e deteção automática. | F12: Máquinas antigas sem deteção automática e com mais paragens; máquinas novas exigem qualificação IQ/OQ/PQ. | G12: MAN | H12: Infraestrutura / equipamentos | J12: Risco | K12: R3 | L12: Não | M12: Plano de manutenção e qualificação de equipamento (RG-SGQ-02). | N12: MTBF das máquinas de 2011–2013 | O12: 46387 | P12: =IF(A12="","",B12&"|"&COUNTIF(INDEX($B$5:$B$26,1):B12,B12)) -> Fraqueza|4 | Q12: SGQ | R12: R3; R7 | S12: SWT-W07
A13: SWTQ-W05 | B13: Fraqueza | C13: =IF(A13="","",IF(OR(B13="Força",B13="Fraqueza"),"Interno","Externo")) -> Interno | D13: Operadores temporários no pico e indisponibilidade de operadores (maior causa de paragem não planeada). | E13: 6 operadores temporários; paragens por falta de operador. | F13: Pessoas sem competência validada nas características críticas; risco de erro humano (8.5.1 g). | G13: RH | H13: Pessoas / competências | J13: Risco | K13: R23 | L13: Não | M13: Matriz de competências e validação no posto (RG-SGQ-07). | N13: % de operadores validados nas características críticas | O13: 46387 | P13: =IF(A13="","",B13&"|"&COUNTIF(INDEX($B$5:$B$26,1):B13,B13)) -> Fraqueza|5 | Q13: SGQ | R13: R23; R10 | S13: SWT-W07
A14: SWTQ-O01 | B14: Oportunidade | C14: =IF(A14="","",IF(OR(B14="Força",B14="Fraqueza"),"Interno","Externo")) -> Externo | D14: Entrada em alimentar e farmacêutico: 4 clientes e 17 SKU novos em 2026. | E14: Dataset desde 06/07/2026; CUST-015 a CUST-018. | F14: Crescimento com requisitos mais exigentes: exige D&D, validação e rastreabilidade robustos. | G14: RD | H14: Cliente / mercado | I14: PESQ-01 | J14: Oportunidade | K14: O12 | L14: Sim | M14: Safe launch e stage-gate por SKU (RG-SGQ-11). | N14: FPY de lançamento | O14: 46387 | P14: =IF(A14="","",B14&"|"&COUNTIF(INDEX($B$5:$B$26,1):B14,B14)) -> Oportunidade|1 | Q14: SGQ | R14: R12; O12 | S14: SWT-F04
A15: SWTQ-O02 | B15: Oportunidade | C15: =IF(A15="","",IF(OR(B15="Força",B15="Fraqueza"),"Interno","Externo")) -> Externo | D15: Clientes valorizam declarações verificáveis de conteúdo reciclado e pegada de carbono do produto. | E15: Questionários ESG de CUST-001, CUST-011 e CUST-013. | F15: Diferenciação comercial se as declarações forem controladas como requisito de produto (8.2.2). | G15: COM | H15: Produto / embalagem | I15: PESQ-08 | J15: Oportunidade | K15: O5 | L15: Não | M15: Requisitos específicos de cliente com evidência de fornecedor (RG-SGQ-10; RG-SGA-19). | N15: % de pedidos PCR/PCF respondidos com evidência | O15: 46387 | P15: =IF(A15="","",B15&"|"&COUNTIF(INDEX($B$5:$B$26,1):B15,B15)) -> Oportunidade|2 | Q15: SGQ | R15: O5; R33 | S15: PES-04; SWT-O01
A16: SWTQ-O03 | B16: Oportunidade | C16: =IF(A16="","",IF(OR(B16="Força",B16="Fraqueza"),"Interno","Externo")) -> Externo | D16: Visão artificial, sensores e analytics para prevenir defeitos em vez de os inspecionar. | E16: Business case de visão (RG-SGA-02 O13); 10 de 22 máquinas com deteção automática. | F16: Menos escapes ao cliente e menor custo de avaliação. | G16: TI | H16: Governação e dados | I16: PESQ-09 | J16: Oportunidade | K16: O13 | L16: Não | M16: Business case de visão e painel de KRI (O13, O3). | N16: Custo de avaliação (€/mês) | O16: 46387 | P16: =IF(A16="","",B16&"|"&COUNTIF(INDEX($B$5:$B$26,1):B16,B16)) -> Oportunidade|3 | Q16: SGQ | R16: O3; O13 | S16: SWT-O04
A17: SWTQ-T01 | B17: Ameaça | C17: =IF(A17="","",IF(OR(B17="Força",B17="Fraqueza"),"Interno","Externo")) -> Externo | D17: Clientes exigem Cpk ≥ 1,33, zero defeito e rastreabilidade, com risco de reclamação e devolução. | E17: 190 grupos com Cpk < 1,33; CPMU 4,5. | F17: Reclamações, devoluções e perda de clientes se a capacidade não for demonstrada. | G17: QUA | H17: Processo / capacidade | I17: PESQ-03 | J17: Risco | K17: R17 | L17: Sim | M17: Estudos de capacidade por Pareto e SPC nas características críticas (OBJ-Q-04). | N17: % de subgrupos com Cpk ≥ 1,00 | O17: 46387 | P17: =IF(A17="","",B17&"|"&COUNTIF(INDEX($B$5:$B$26,1):B17,B17)) -> Ameaça|1 | Q17: SGQ | R17: R16; R17 | S17: SWT-T04
A18: SWTQ-T02 | B18: Ameaça | C18: =IF(A18="","",IF(OR(B18="Força",B18="Fraqueza"),"Interno","Externo")) -> Externo | D18: Requisitos legais de produto mais exigentes: materiais em contacto com alimentos, embalagem farmacêutica e PPWR. | E18: Reg. 1935/2004 e 10/2011; 21 CFR 211.132; Reg. (UE) 2025/40. | F18: Um lote não conforme tem consequências legais; novas saídas obrigatórias do D&D e da libertação. | G18: LAB | H18: Legal / conformidade | I18: PESQ-02 | J18: Risco | K18: R33 | L18: Não | M18: Vigilância legal de produto e dossier técnico por família. | N18: % de famílias com dossier PPWR | O18: 46387 | P18: =IF(A18="","",B18&"|"&COUNTIF(INDEX($B$5:$B$26,1):B18,B18)) -> Ameaça|2 | Q18: SGQ | R18: R16; R33 | S18: PES-12; PES-18
A19: SWTQ-T03 | B19: Ameaça | C19: =IF(A19="","",IF(OR(B19="Força",B19="Fraqueza"),"Interno","Externo")) -> Externo | D19: Qualidade variável de resinas spot e de PCR/rPET. | E19: SUP-005 com 74,5% de lotes aceites; 117 lotes aceites com derrogação. | F19: Defeitos e scrap por matéria-prima; derrogações sem análise de risco. | G19: CMP | H19: Cadeia de valor / fornecedores | I19: PESQ-05 | J19: Risco | K19: R13 | L19: Não | M19: Scorecard A–D e SCAR com 8D (RG-SGQ-12). | N19: % de lotes de MP aceites sem derrogação | O19: 46387 | P19: =IF(A19="","",B19&"|"&COUNTIF(INDEX($B$5:$B$26,1):B19,B19)) -> Ameaça|3 | Q19: SGQ | R19: R13; R14; R36 | S19: SWT-W02; SWT-T02
A20: SWTQ-T04 | B20: Ameaça | C20: =IF(A20="","",IF(OR(B20="Força",B20="Fraqueza"),"Interno","Externo")) -> Externo | D20: Ondas de calor e eventos climáticos extremos afetam a janela de processo e o abastecimento de resina. | E20: Alarme de temperatura dos moldes em jul/2026; paragens por falta de matéria-prima. | F20: Defeitos de sopro no verão e atrasos de entrega (OTIF). | G20: SOP | H20: Clima / GEE | I20: PESQ-06 | J20: Risco | K20: R34 | L20: Não | M20: Janela de processo de verão validada e stock de segurança de resina. | N20: Rejeição do sopro em jun–set; OTIF | O20: 46387 | P20: =IF(A20="","",B20&"|"&COUNTIF(INDEX($B$5:$B$26,1):B20,B20)) -> Ameaça|4 | Q20: SGQ | R20: R15; R34 | S20: SWT-T01
C21: =IF(A21="","",IF(OR(B21="Força",B21="Fraqueza"),"Interno","Externo")) | P21: =IF(A21="","",B21&"|"&COUNTIF(INDEX($B$5:$B$26,1):B21,B21))
C22: =IF(A22="","",IF(OR(B22="Força",B22="Fraqueza"),"Interno","Externo")) | P22: =IF(A22="","",B22&"|"&COUNTIF(INDEX($B$5:$B$26,1):B22,B22))
C23: =IF(A23="","",IF(OR(B23="Força",B23="Fraqueza"),"Interno","Externo")) | P23: =IF(A23="","",B23&"|"&COUNTIF(INDEX($B$5:$B$26,1):B23,B23))
C24: =IF(A24="","",IF(OR(B24="Força",B24="Fraqueza"),"Interno","Externo")) | P24: =IF(A24="","",B24&"|"&COUNTIF(INDEX($B$5:$B$26,1):B24,B24))
C25: =IF(A25="","",IF(OR(B25="Força",B25="Fraqueza"),"Interno","Externo")) | P25: =IF(A25="","",B25&"|"&COUNTIF(INDEX($B$5:$B$26,1):B25,B25))
C26: =IF(A26="","",IF(OR(B26="Força",B26="Fraqueza"),"Interno","Externo")) | P26: =IF(A26="","",B26&"|"&COUNTIF(INDEX($B$5:$B$26,1):B26,B26))

Sheet Matriz_TOWS
A1: MATRIZ TOWS — ESTRATÉGIAS CRUZADAS DO SGQ
A2: Mesma estrutura do RG-SGA-01 tbl_tows · Liga contexto → objetivos (RG-SGQ-05) → riscos (RG-SGA-02)
A4: ID_TOWS | B4: Cruzamento | C4: IDs_Origem | D4: Estrategia | E4: ID_Objetivo | F4: Prazo | G4: Dono | H4: KPI | I4: IDs_Risco_SGI
A5: TOWSQ-01 | B5: SO (Força+Oportunidade) | C5: SWTQ-F01; SWTQ-O03; PESQ-09 | D5: Usar o data warehouse e a visão artificial para passar da inspeção por amostragem ao controlo em linha das características críticas. | E5: OBJ-Q-02 | F5: 46568 | G5: Gerente de Dados / TI | H5: Lotes aprovados à primeira (≥ 92%) | I5: O3; O13
A6: TOWSQ-02 | B6: SO (Força+Oportunidade) | C6: SWTQ-F03; SWTQ-O01 | D6: Crescer em alimentar/farma com safe launch e validação de processos antes da produção em série. | F6: 46477 | G6: Responsável de R&D | H6: FPY de lançamento ≥ meta de safe launch | I6: R12; O12
A7: TOWSQ-03 | B7: ST (Força+Ameaça) | C7: SWTQ-F02; SWTQ-T02 | D7: Alargar o MSA às características críticas de alimentar/farma (migração, binário, anel) para decisões de libertação fiáveis. | E7: OBJ-Q-04 | F7: 46568 | G7: Gerente da Qualidade | H7: % de características críticas com MSA aceite | I7: R16; R17
A8: TOWSQ-04 | B8: WO (Fraqueza+Oportunidade) | C8: SWTQ-W02; SWTQ-O01 | D8: Programa de cultura da qualidade (gemba walks, relato sem culpa) ligado ao crescimento em alimentar/farma. | F8: 46568 | G8: Diretor Geral (Gestão de Topo) | H8: Rejeição do turno 2 vs. média da fábrica | I8: R9
A9: TOWSQ-05 | B9: WT (Fraqueza+Ameaça) | C9: SWTQ-W01; SWTQ-T01 | D9: Tratar primeiro as causas-raiz de maior evidência (IM-002, ISBM-003, SS-001, M-SOP-007) e os estudos de capacidade por Pareto. | E9: OBJ-Q-04 | F9: 46477 | G9: Gerente da Qualidade | H9: % de subgrupos com Cpk ≥ 1,00 (≥ 70%) | I9: R4; R1; R7; R2; R17
A10: TOWSQ-06 | B10: WT (Fraqueza+Ameaça) | C10: SWTQ-W05; SWTQ-T03; PESQ-04 | D10: Antes do pico set–nov: validar a competência dos temporários nas características críticas e bloquear MP sem aceitação. | E10: OBJ-Q-07 | F10: 46326 | G10: Gerente de Produção | H10: Lotes de MP aceites sem derrogação (≥ 95%) | I10: R23; R13

Sheet Cinco_Forcas
A1: CINCO FORÇAS COMPETITIVAS (PORTER) — LENTE DA QUALIDADE
A2: Mesma estrutura do RG-SGA-01 tbl_cinco_forcas
A4: ID_Forca | B4: Forca_Competitiva | C4: Cenario_Evidencias | D4: Tendencia | E4: Impacto_Organizacao | F4: Classificacao | G4: IDs_Risco_SGI | H4: Como_Monitorizar | I4: Data_Avaliacao
A5: CFQ-01 | B5: Poder negocial dos clientes | C5: Clientes exigem Cpk ≥ 1,33, zero defeito, aprovação prévia de alterações (farma) e plano de contingência; 18 clientes, CPMU 4,5. | D5: Crescente | E5: Reclamações, auditorias de cliente e perda de encomendas se a capacidade não for demonstrada. | F5: Risco | G5: R16; R17 | H5: Inquérito de satisfação ISO 10004 e reclamações (RG-SGQ-15) | I5: 46387
A6: CFQ-02 | B6: Poder negocial dos fornecedores | C6: Resinas concentradas em poucos petroquímicos; SUP-005 spot com 74,5% de lotes aceites; PCR com oferta limitada. | D6: Estável | E6: Pouca alavanca para exigir certificados e 8D; risco de derrogações. | F6: Risco | G6: R13; R14; R36 | H6: Scorecard semestral e SCAR (RG-SGQ-12) | I6: 46387
A7: CFQ-03 | B7: Ameaça de novos entrantes | C7: Barreira baixa em frascos simples; alta em alimentar/farma (validação, BPF, rastreabilidade). | D7: Estável | E7: A qualidade demonstrada (certificação, validação de processos) é barreira de entrada. | F7: Oportunidade | G7: O12 | H7: Relatório trimestral de mercado | I7: 46387
A8: CFQ-04 | B8: Ameaça de produtos substitutos | C8: Vidro, alumínio e recargas; clientes pedem monomaterial e PCR. | D8: Crescente | E8: Novos materiais exigem requalificação do processo e novos critérios de aceitação. | F8: Risco | G8: R14 | H8: Revisão de requisitos (RG-SGQ-10) | I8: 46387
A9: CFQ-05 | B9: Rivalidade entre concorrentes | C9: Concorrência por preço (≈ € 0,13/un); diferenciação por qualidade e serviço (OTIF). | D9: Crescente | E9: Reduzir o custo da não qualidade preserva a margem. | F9: Oportunidade | G9: O11; O4 | H9: Custo da qualidade mensal (RG-SGQ-19) | I9: 46387

Sheet Vista_SWOT
A1: ANÁLISE SWOT DO SGQ — PLASTICOM (vista calculada)
A2: Itens marcados com ► são prioritários para o planeamento (6.1). Editar a folha SWOT; esta vista atualiza sozinha.
A4: FORÇAS (internas, positivas) | B4: FRAQUEZAS (internas, negativas)
A5: =IFERROR(IF(INDEX(SWOT!$L$5:$L$26,MATCH("Força|1",SWOT!$P$5:$P$26,0))="Sim","► ","• ")&INDEX(SWOT!$A$5:$A$26,MATCH("Força|1",SWOT!$P$5:$P$26,0))&" — "&INDEX(SWOT!$D$5:$D$26,MATCH("Força|1",SWOT!$P$5:$P$26,0)),"") -> ► SWTQ-F01 — Cultura de dados: 18 meses de OEE, SPC, AQL e rastreabilidade lote → ordem num data warehouse (bronze/silver/gold) com Power BI. | B5: =IFERROR(IF(INDEX(SWOT!$L$5:$L$26,MATCH("Fraqueza|1",SWOT!$P$5:$P$26,0))="Sim","► ","• ")&INDEX(SWOT!$A$5:$A$26,MATCH("Fraqueza|1",SWOT!$P$5:$P$26,0))&" — "&INDEX(SWOT!$D$5:$D$26,MATCH("Fraqueza|1",SWOT!$P$5:$P$26,0)),"") -> ► SWTQ-W01 — Desempenho da qualidade abaixo da meta: rejeição ≈ 2,4% (meta 2,0%), FPY 88,7% e 31% das CAPA não eficazes.
A6: =IFERROR(IF(INDEX(SWOT!$L$5:$L$26,MATCH("Força|2",SWOT!$P$5:$P$26,0))="Sim","► ","• ")&INDEX(SWOT!$A$5:$A$26,MATCH("Força|2",SWOT!$P$5:$P$26,0))&" — "&INDEX(SWOT!$D$5:$D$26,MATCH("Força|2",SWOT!$P$5:$P$26,0)),"") -> • SWTQ-F02 — Sistema de medição adequado no peso das tampas (%GRR 3,5% da variação total; ndc 40). | B6: =IFERROR(IF(INDEX(SWOT!$L$5:$L$26,MATCH("Fraqueza|2",SWOT!$P$5:$P$26,0))="Sim","► ","• ")&INDEX(SWOT!$A$5:$A$26,MATCH("Fraqueza|2",SWOT!$P$5:$P$26,0))&" — "&INDEX(SWOT!$D$5:$D$26,MATCH("Fraqueza|2",SWOT!$P$5:$P$26,0)),"") -> • SWTQ-W02 — Cultura de produtividade: pressão por meta e prémio de defeito no turno 2 (fadiga, passagem de turno).
A7: =IFERROR(IF(INDEX(SWOT!$L$5:$L$26,MATCH("Força|3",SWOT!$P$5:$P$26,0))="Sim","► ","• ")&INDEX(SWOT!$A$5:$A$26,MATCH("Força|3",SWOT!$P$5:$P$26,0))&" — "&INDEX(SWOT!$D$5:$D$26,MATCH("Força|3",SWOT!$P$5:$P$26,0)),"") -> • SWTQ-F03 — Estratégia 2026–2028 aprovada: crescer em alimentar/farma e certificar o SGI (ISO 9001:2026 + ISO 14001:2026). | B7: =IFERROR(IF(INDEX(SWOT!$L$5:$L$26,MATCH("Fraqueza|3",SWOT!$P$5:$P$26,0))="Sim","► ","• ")&INDEX(SWOT!$A$5:$A$26,MATCH("Fraqueza|3",SWOT!$P$5:$P$26,0))&" — "&INDEX(SWOT!$D$5:$D$26,MATCH("Fraqueza|3",SWOT!$P$5:$P$26,0)),"") -> • SWTQ-W03 — Conhecimento crítico concentrado em poucas pessoas (afinação de moldes, DOE da IM-002, Gage R&R).
A8: =IFERROR(IF(INDEX(SWOT!$L$5:$L$26,MATCH("Força|4",SWOT!$P$5:$P$26,0))="Sim","► ","• ")&INDEX(SWOT!$A$5:$A$26,MATCH("Força|4",SWOT!$P$5:$P$26,0))&" — "&INDEX(SWOT!$D$5:$D$26,MATCH("Força|4",SWOT!$P$5:$P$26,0)),"") -> • SWTQ-F04 — Causas-raiz conhecidas com evidência causal forte (IM-002 com MSA e DOE; SS-001 e M-SOP-007 respondem à intervenção). | B8: =IFERROR(IF(INDEX(SWOT!$L$5:$L$26,MATCH("Fraqueza|4",SWOT!$P$5:$P$26,0))="Sim","► ","• ")&INDEX(SWOT!$A$5:$A$26,MATCH("Fraqueza|4",SWOT!$P$5:$P$26,0))&" — "&INDEX(SWOT!$D$5:$D$26,MATCH("Fraqueza|4",SWOT!$P$5:$P$26,0)),"") -> • SWTQ-W04 — Frota com máquinas antigas (5 máquinas de 2011–2013) e 4 máquinas novas em 2026 por qualificar.
A9: =IFERROR(IF(INDEX(SWOT!$L$5:$L$26,MATCH("Força|5",SWOT!$P$5:$P$26,0))="Sim","► ","• ")&INDEX(SWOT!$A$5:$A$26,MATCH("Força|5",SWOT!$P$5:$P$26,0))&" — "&INDEX(SWOT!$D$5:$D$26,MATCH("Força|5",SWOT!$P$5:$P$26,0)),"") | B9: =IFERROR(IF(INDEX(SWOT!$L$5:$L$26,MATCH("Fraqueza|5",SWOT!$P$5:$P$26,0))="Sim","► ","• ")&INDEX(SWOT!$A$5:$A$26,MATCH("Fraqueza|5",SWOT!$P$5:$P$26,0))&" — "&INDEX(SWOT!$D$5:$D$26,MATCH("Fraqueza|5",SWOT!$P$5:$P$26,0)),"") -> • SWTQ-W05 — Operadores temporários no pico e indisponibilidade de operadores (maior causa de paragem não planeada).
A10: =IFERROR(IF(INDEX(SWOT!$L$5:$L$26,MATCH("Força|6",SWOT!$P$5:$P$26,0))="Sim","► ","• ")&INDEX(SWOT!$A$5:$A$26,MATCH("Força|6",SWOT!$P$5:$P$26,0))&" — "&INDEX(SWOT!$D$5:$D$26,MATCH("Força|6",SWOT!$P$5:$P$26,0)),"") | B10: =IFERROR(IF(INDEX(SWOT!$L$5:$L$26,MATCH("Fraqueza|6",SWOT!$P$5:$P$26,0))="Sim","► ","• ")&INDEX(SWOT!$A$5:$A$26,MATCH("Fraqueza|6",SWOT!$P$5:$P$26,0))&" — "&INDEX(SWOT!$D$5:$D$26,MATCH("Fraqueza|6",SWOT!$P$5:$P$26,0)),"")
A11: =IFERROR(IF(INDEX(SWOT!$L$5:$L$26,MATCH("Força|7",SWOT!$P$5:$P$26,0))="Sim","► ","• ")&INDEX(SWOT!$A$5:$A$26,MATCH("Força|7",SWOT!$P$5:$P$26,0))&" — "&INDEX(SWOT!$D$5:$D$26,MATCH("Força|7",SWOT!$P$5:$P$26,0)),"") | B11: =IFERROR(IF(INDEX(SWOT!$L$5:$L$26,MATCH("Fraqueza|7",SWOT!$P$5:$P$26,0))="Sim","► ","• ")&INDEX(SWOT!$A$5:$A$26,MATCH("Fraqueza|7",SWOT!$P$5:$P$26,0))&" — "&INDEX(SWOT!$D$5:$D$26,MATCH("Fraqueza|7",SWOT!$P$5:$P$26,0)),"")
A13: OPORTUNIDADES (externas, positivas) | B13: AMEAÇAS (externas, negativas)
A14: =IFERROR(IF(INDEX(SWOT!$L$5:$L$26,MATCH("Oportunidade|1",SWOT!$P$5:$P$26,0))="Sim","► ","• ")&INDEX(SWOT!$A$5:$A$26,MATCH("Oportunidade|1",SWOT!$P$5:$P$26,0))&" — "&INDEX(SWOT!$D$5:$D$26,MATCH("Oportunidade|1",SWOT!$P$5:$P$26,0)),"") -> ► SWTQ-O01 — Entrada em alimentar e farmacêutico: 4 clientes e 17 SKU novos em 2026. | B14: =IFERROR(IF(INDEX(SWOT!$L$5:$L$26,MATCH("Ameaça|1",SWOT!$P$5:$P$26,0))="Sim","► ","• ")&INDEX(SWOT!$A$5:$A$26,MATCH("Ameaça|1",SWOT!$P$5:$P$26,0))&" — "&INDEX(SWOT!$D$5:$D$26,MATCH("Ameaça|1",SWOT!$P$5:$P$26,0)),"") -> ► SWTQ-T01 — Clientes exigem Cpk ≥ 1,33, zero defeito e rastreabilidade, com risco de reclamação e devolução.
A15: =IFERROR(IF(INDEX(SWOT!$L$5:$L$26,MATCH("Oportunidade|2",SWOT!$P$5:$P$26,0))="Sim","► ","• ")&INDEX(SWOT!$A$5:$A$26,MATCH("Oportunidade|2",SWOT!$P$5:$P$26,0))&" — "&INDEX(SWOT!$D$5:$D$26,MATCH("Oportunidade|2",SWOT!$P$5:$P$26,0)),"") -> • SWTQ-O02 — Clientes valorizam declarações verificáveis de conteúdo reciclado e pegada de carbono do produto. | B15: =IFERROR(IF(INDEX(SWOT!$L$5:$L$26,MATCH("Ameaça|2",SWOT!$P$5:$P$26,0))="Sim","► ","• ")&INDEX(SWOT!$A$5:$A$26,MATCH("Ameaça|2",SWOT!$P$5:$P$26,0))&" — "&INDEX(SWOT!$D$5:$D$26,MATCH("Ameaça|2",SWOT!$P$5:$P$26,0)),"") -> • SWTQ-T02 — Requisitos legais de produto mais exigentes: materiais em contacto com alimentos, embalagem farmacêutica e PPWR.
A16: =IFERROR(IF(INDEX(SWOT!$L$5:$L$26,MATCH("Oportunidade|3",SWOT!$P$5:$P$26,0))="Sim","► ","• ")&INDEX(SWOT!$A$5:$A$26,MATCH("Oportunidade|3",SWOT!$P$5:$P$26,0))&" — "&INDEX(SWOT!$D$5:$D$26,MATCH("Oportunidade|3",SWOT!$P$5:$P$26,0)),"") -> • SWTQ-O03 — Visão artificial, sensores e analytics para prevenir defeitos em vez de os inspecionar. | B16: =IFERROR(IF(INDEX(SWOT!$L$5:$L$26,MATCH("Ameaça|3",SWOT!$P$5:$P$26,0))="Sim","► ","• ")&INDEX(SWOT!$A$5:$A$26,MATCH("Ameaça|3",SWOT!$P$5:$P$26,0))&" — "&INDEX(SWOT!$D$5:$D$26,MATCH("Ameaça|3",SWOT!$P$5:$P$26,0)),"") -> • SWTQ-T03 — Qualidade variável de resinas spot e de PCR/rPET.
A17: =IFERROR(IF(INDEX(SWOT!$L$5:$L$26,MATCH("Oportunidade|4",SWOT!$P$5:$P$26,0))="Sim","► ","• ")&INDEX(SWOT!$A$5:$A$26,MATCH("Oportunidade|4",SWOT!$P$5:$P$26,0))&" — "&INDEX(SWOT!$D$5:$D$26,MATCH("Oportunidade|4",SWOT!$P$5:$P$26,0)),"") | B17: =IFERROR(IF(INDEX(SWOT!$L$5:$L$26,MATCH("Ameaça|4",SWOT!$P$5:$P$26,0))="Sim","► ","• ")&INDEX(SWOT!$A$5:$A$26,MATCH("Ameaça|4",SWOT!$P$5:$P$26,0))&" — "&INDEX(SWOT!$D$5:$D$26,MATCH("Ameaça|4",SWOT!$P$5:$P$26,0)),"") -> • SWTQ-T04 — Ondas de calor e eventos climáticos extremos afetam a janela de processo e o abastecimento de resina.
A18: =IFERROR(IF(INDEX(SWOT!$L$5:$L$26,MATCH("Oportunidade|5",SWOT!$P$5:$P$26,0))="Sim","► ","• ")&INDEX(SWOT!$A$5:$A$26,MATCH("Oportunidade|5",SWOT!$P$5:$P$26,0))&" — "&INDEX(SWOT!$D$5:$D$26,MATCH("Oportunidade|5",SWOT!$P$5:$P$26,0)),"") | B18: =IFERROR(IF(INDEX(SWOT!$L$5:$L$26,MATCH("Ameaça|5",SWOT!$P$5:$P$26,0))="Sim","► ","• ")&INDEX(SWOT!$A$5:$A$26,MATCH("Ameaça|5",SWOT!$P$5:$P$26,0))&" — "&INDEX(SWOT!$D$5:$D$26,MATCH("Ameaça|5",SWOT!$P$5:$P$26,0)),"")
A19: =IFERROR(IF(INDEX(SWOT!$L$5:$L$26,MATCH("Oportunidade|6",SWOT!$P$5:$P$26,0))="Sim","► ","• ")&INDEX(SWOT!$A$5:$A$26,MATCH("Oportunidade|6",SWOT!$P$5:$P$26,0))&" — "&INDEX(SWOT!$D$5:$D$26,MATCH("Oportunidade|6",SWOT!$P$5:$P$26,0)),"") | B19: =IFERROR(IF(INDEX(SWOT!$L$5:$L$26,MATCH("Ameaça|6",SWOT!$P$5:$P$26,0))="Sim","► ","• ")&INDEX(SWOT!$A$5:$A$26,MATCH("Ameaça|6",SWOT!$P$5:$P$26,0))&" — "&INDEX(SWOT!$D$5:$D$26,MATCH("Ameaça|6",SWOT!$P$5:$P$26,0)),"")
A20: =IFERROR(IF(INDEX(SWOT!$L$5:$L$26,MATCH("Oportunidade|7",SWOT!$P$5:$P$26,0))="Sim","► ","• ")&INDEX(SWOT!$A$5:$A$26,MATCH("Oportunidade|7",SWOT!$P$5:$P$26,0))&" — "&INDEX(SWOT!$D$5:$D$26,MATCH("Oportunidade|7",SWOT!$P$5:$P$26,0)),"") | B20: =IFERROR(IF(INDEX(SWOT!$L$5:$L$26,MATCH("Ameaça|7",SWOT!$P$5:$P$26,0))="Sim","► ","• ")&INDEX(SWOT!$A$5:$A$26,MATCH("Ameaça|7",SWOT!$P$5:$P$26,0))&" — "&INDEX(SWOT!$D$5:$D$26,MATCH("Ameaça|7",SWOT!$P$5:$P$26,0)),"")

Sheet Partes_Interessadas
A1: PARTES INTERESSADAS — REQUISITOS PERTINENTES E DECISÃO DE TRATAMENTO PELO SGQ (4.2)
A2: Mesma estrutura do RG-SGA-01 tbl_partes_interessadas · 4.2 c): quais requisitos se tratam no SGQ · Requisitos legais ligam ao RG-SGA-04
A4: ID_PI | B4: Parte_Interessada | C4: Tipo | D4: Categoria | E4: Necessidades_Expectativas | F4: Condicao_Ambiental | G4: Relevante | H4: Tratado_pelo_SGQ | I4: Tipo_Obrigacao | J4: IDs_Legal | K4: Como_Monitorizar | L4: Frequencia | M4: Influencia | N4: Interesse | O4: Estrategia | P4: ID_RO | Q4: Dono | R4: Data_Revisao | S4: IDs_Risco_SGI | T4: Percepcao_Risco | U4: Fonte_Requisito | V4: Justificacao_Tratamento | W4: Registo_Evidencia | X4: ID_PI_SGI
A5: PIQ-01 | B5: Clientes de cosmética (marcas UE) | C5: Externa | D5: Clientes B2B | E5: Produto conforme à especificação e ao artwork aprovado; entrega OTIF; resposta a reclamações em ≤ 10 dias úteis. | F5: Não aplicável | G5: Sim | H5: Sim | I5: Contratual (cliente) | K5: Reclamações, OTIF e inquérito de satisfação (RG-SGQ-15) | L5: Por encomenda | M5: Alta | N5: Alta | O5: =IF(A5="","",IF(AND(M5="Alta",N5="Alta"),"Gerir de perto",IF(M5="Alta","Manter satisfeita",IF(N5="Alta","Manter informada","Monitorizar")))) -> Gerir de perto | P5: R16 | Q5: Diretor Comercial | R5: 46387 | S5: R16; R17; R18 | T5: Um lote fora de especificação é visto como falha evitável (risco imposto ao cliente). | U5: Contrato / especificação / acordo de qualidade | V5: Requisito do cliente — núcleo do SGQ (8.2, 8.6, 9.1.2). | W5: RG-SGQ-10; RG-SGQ-15 | X5: PI-04
A6: PIQ-02 | B6: Clientes de cosmética (marcas UE) | C6: Externa | D6: Clientes B2B | E6: Declaração de conteúdo reciclado e pegada de carbono do produto. | F6: Clima | G6: Sim | H6: Sim | I6: Contratual (cliente) | J6: LEG-18 | K6: Questionários ESG e pedidos de cotação | L6: Semestral | M6: Alta | N6: Média | O6: =IF(A6="","",IF(AND(M6="Alta",N6="Alta"),"Gerir de perto",IF(M6="Alta","Manter satisfeita",IF(N6="Alta","Manter informada","Monitorizar")))) -> Manter satisfeita | P6: O5 | Q6: Diretor Comercial | R6: 46387 | S6: O5; R33 | T6: Uma declaração sem evidência é vista como greenwashing. | U6: Questionários ESG / pedidos de cotação | V6: Tratado como requisito de produto quando consta da especificação (8.2.2). | W6: RG-SGQ-10; RG-SGA-19 | X6: PI-04
A7: PIQ-03 | B7: Clientes alimentares (CUST-015, CUST-016) | C7: Externa | D7: Clientes B2B (novas linhas 2026) | E7: Conformidade com Reg. (CE) 1935/2004, Reg. (UE) 10/2011 e BPF (Reg. 2023/2006); declaração de conformidade por lote. | F7: Não aplicável | G7: Sim | H7: Sim | I7: Legal | J7: LEG-17 | K7: Ensaio de migração por lote e auditorias de cliente | L7: Por lote | M7: Alta | N7: Alta | O7: =IF(A7="","",IF(AND(M7="Alta",N7="Alta"),"Gerir de perto",IF(M7="Alta","Manter satisfeita",IF(N7="Alta","Manter informada","Monitorizar")))) -> Gerir de perto | P7: R16 | Q7: Gerente da Qualidade | R7: 46387 | S7: R16; R33 | T7: Um lote não conforme em contacto com alimentos é risco para a saúde, sem tolerância. | U7: Legislação + especificação | V7: Requisito legal aplicável ao produto (8.2.2 a1). | W7: RG-SGQ-10; RG-SGQ-13 (ensaio de migração) | X7: PI-05
A8: PIQ-04 | B8: Clientes farmacêuticos (CUST-017, CUST-018) | C8: Externa | D8: Clientes B2B (novas linhas 2026) | E8: Rastreabilidade ao lote de resina, anel de inviolabilidade (21 CFR 211.132), notificação prévia de alterações e auditoria ao fornecedor. | F8: Não aplicável | G8: Sim | H8: Sim | I8: Contratual (cliente) | J8: LEG-20 | K8: Acordo de qualidade e auditorias de cliente | L8: Por alteração | M8: Alta | N8: Alta | O8: =IF(A8="","",IF(AND(M8="Alta",N8="Alta"),"Gerir de perto",IF(M8="Alta","Manter satisfeita",IF(N8="Alta","Manter informada","Monitorizar")))) -> Gerir de perto | P8: R16 | Q8: Gerente da Qualidade | R8: 46387 | S8: R16; R17; R18 | T8: Uma alteração não comunicada é vista como quebra de confiança no fornecedor. | U8: Acordo de qualidade farmacêutico | V8: Requisito contratual; alterações sujeitas a aprovação do cliente (8.5.6). | W8: RG-SGQ-06; RG-SGQ-13 | X8: PI-05
A9: PIQ-05 | B9: Clientes (todos) | C9: Externa | D9: Clientes B2B | E9: Informação sobre ações de contingência em caso de disrupção no fornecimento. | F9: Clima | G9: Sim | H9: Sim | I9: Contratual (cliente) | K9: Comunicação com o cliente (RG-SGQ-08 Comunicacao_Cliente) | L9: Por ocorrência | M9: Alta | N9: Média | O9: =IF(A9="","",IF(AND(M9="Alta",N9="Alta"),"Gerir de perto",IF(M9="Alta","Manter satisfeita",IF(N9="Alta","Manter informada","Monitorizar")))) -> Manter satisfeita | P9: R15 | Q9: Diretor Comercial | R9: 46387 | S9: R15; R34 | T9: Esperam aviso antecipado, não surpresas na entrega. | U9: Acordo de qualidade / contrato | V9: Novo em 2026 (8.2.1 e). | W9: RG-SGQ-08 Comunicacao_Cliente | X9: PI-04
A10: PIQ-06 | B10: Acionistas / Direção | C10: Interna | D10: Gestão de topo | E10: Redução do custo da não qualidade e cumprimento dos objetivos; certificação ISO 9001:2026. | F10: Não aplicável | G10: Sim | H10: Sim | I10: Voluntária (compromisso assumido) | K10: Revisão pela gestão; painel mensal de KPI | L10: Trimestral | M10: Alta | N10: Alta | O10: =IF(A10="","",IF(AND(M10="Alta",N10="Alta"),"Gerir de perto",IF(M10="Alta","Manter satisfeita",IF(N10="Alta","Manter informada","Monitorizar")))) -> Gerir de perto | P10: O12 | Q10: Diretor Geral (Gestão de Topo) | R10: 46387 | S10: R24; O3; O4 | T10: Esperam retorno dos investimentos e menor custo da não qualidade. | U10: Plano estratégico | V10: Objetivos da qualidade (6.2) e revisão pela gestão (9.3). | W10: RG-SGQ-05; RG-SGQ-17; RG-SGQ-19 | X10: PI-03
A11: PIQ-07 | B11: Colaboradores | C11: Interna | D11: Trabalhadores próprios (3 turnos) | E11: Instruções claras, formação e condições para fazer bem à primeira; não serem culpabilizados por falhas do sistema. | F11: Não aplicável | G11: Sim | H11: Sim | I11: Voluntária (compromisso assumido) | K11: Inquérito de cultura da qualidade; gemba walks | L11: Semestral | M11: Média | N11: Alta | O11: =IF(A11="","",IF(AND(M11="Alta",N11="Alta"),"Gerir de perto",IF(M11="Alta","Manter satisfeita",IF(N11="Alta","Manter informada","Monitorizar")))) -> Manter informada | P11: R9 | Q11: Responsável de Recursos Humanos | R11: 46387 | S11: R9; R23 | T11: Sentem pressão por meta; o relato de problemas é visto como risco pessoal. | U11: Inquérito interno / comissão de trabalhadores | V11: Competência, consciencialização e ambiente dos processos (7.1.4, 7.2, 7.3). | W11: RG-SGQ-07; RG-SGQ-03 | X11: PI-01
A12: PIQ-08 | B12: Fornecedores de resinas e masterbatch | C12: Externa | D12: Cadeia de abastecimento | E12: Especificações e critérios de aceitação claros; feedback do desempenho; previsões de encomenda. | F12: Não aplicável | G12: Sim | H12: Sim | I12: Contratual (cliente) | K12: Scorecard e reunião de fornecedor (RG-SGQ-12) | L12: Trimestral | M12: Média | N12: Média | O12: =IF(A12="","",IF(AND(M12="Alta",N12="Alta"),"Gerir de perto",IF(M12="Alta","Manter satisfeita",IF(N12="Alta","Manter informada","Monitorizar")))) -> Monitorizar | P12: R13 | Q12: Responsável de Compras | R12: 46387 | S12: R13; R14 | T12: O fornecedor spot vê a relação como transacional. | U12: Reuniões de fornecedor | V12: Informação para fornecedores externos (8.4.3). | W12: RG-SGQ-12 | X12: PI-06
A13: PIQ-09 | B13: Organismo de certificação | C13: Externa | D13: Avaliação da conformidade | E13: Conformidade com a ISO 9001:2026 e regras de transição IAF (transição até set/2029). | F13: Não aplicável | G13: Sim | H13: Sim | I13: Voluntária (compromisso assumido) | K13: Auditorias externas e plano de transição | L13: Anual | M13: Alta | N13: Baixa | O13: =IF(A13="","",IF(AND(M13="Alta",N13="Alta"),"Gerir de perto",IF(M13="Alta","Manter satisfeita",IF(N13="Alta","Manter informada","Monitorizar")))) -> Manter satisfeita | P13: O12 | Q13: Gerente da Qualidade | R13: 46387 | S13: O12 | T13: Espera evidência de que o sistema funciona, não documentos isolados. | U13: Regras IAF / contrato de certificação | V13: Condiciona o programa de auditoria e o plano de transição. | W13: RG-SGQ-16; RG-SGQ-06 (MOC-Q-26-01)
A14: PIQ-10 | B14: Autoridades (ASAE, INFARMED, DGAV) | C14: Externa | D14: Autoridades de produto | E14: Cumprimento dos requisitos legais de materiais em contacto com alimentos e de embalagem de medicamentos. | F14: Não aplicável | G14: Sim | H14: Sim | I14: Legal | J14: LEG-17; LEG-20 | K14: Vigilância legal (RG-SGQ-08 Documentos_Externos) | L14: Mensal | M14: Alta | N14: Média | O14: =IF(A14="","",IF(AND(M14="Alta",N14="Alta"),"Gerir de perto",IF(M14="Alta","Manter satisfeita",IF(N14="Alta","Manter informada","Monitorizar")))) -> Manter satisfeita | P14: R16 | Q14: Gerente da Qualidade | R14: 46387 | S14: R16; R33 | T14: A não conformidade de produto é vista como dano à saúde pública, sem margem de tolerância. | U14: Legislação | V14: Requisito legal (8.2.2 a1, 8.5.5 a). | W14: RG-SGQ-08 Documentos_Externos | X14: PI-08
A15: PIQ-11 | B15: Laboratórios externos (calibração e ensaios) | C15: Externa | D15: Prestadores de serviço | E15: Pedidos de calibração com gama, pontos e incerteza definidos; equipamentos entregues limpos. | F15: Não aplicável | G15: Sim | H15: Sim | I15: Contratual (cliente) | K15: Avaliação de processos externos (RG-SGQ-12) | L15: Anual | M15: Baixa | N15: Média | O15: =IF(A15="","",IF(AND(M15="Alta",N15="Alta"),"Gerir de perto",IF(M15="Alta","Manter satisfeita",IF(N15="Alta","Manter informada","Monitorizar")))) -> Monitorizar | Q15: Gerente da Qualidade | R15: 46387 | U15: Contrato de prestação | V15: Processo externo controlado (8.4) e rastreabilidade metrológica (7.1.5.2). | W15: RG-SGQ-09; RG-SGQ-12
A16: PIQ-12 | B16: Transportadores | C16: Externa | D16: Prestadores de serviço | E16: Guias e etiquetas corretas; paletes estáveis; janelas de carga cumpridas. | F16: Não aplicável | G16: Sim | H16: Sim | I16: Contratual (cliente) | K16: OTIF e reclamações de serviço | L16: Mensal | M16: Baixa | N16: Média | O16: =IF(A16="","",IF(AND(M16="Alta",N16="Alta"),"Gerir de perto",IF(M16="Alta","Manter satisfeita",IF(N16="Alta","Manter informada","Monitorizar")))) -> Monitorizar | Q16: Responsável de Armazém e Logística | R16: 46387 | U16: Contrato de transporte | V16: Preservação e atividades de entrega (8.5.4, 8.5.5). | W16: RG-SGQ-13
A17: PIQ-13 | B17: Consumidor final | C17: Externa | D17: Utilizador do produto | E17: Embalagem segura (sem fugas, inviolabilidade evidente) e informação legível. | F17: Não aplicável | G17: Sim | H17: Sim | I17: Voluntária (compromisso assumido) | K17: Reclamações com origem no consumidor (via cliente) | L17: Anual | M17: Baixa | N17: Alta | O17: =IF(A17="","",IF(AND(M17="Alta",N17="Alta"),"Gerir de perto",IF(M17="Alta","Manter satisfeita",IF(N17="Alta","Manter informada","Monitorizar")))) -> Manter informada | P17: R16 | Q17: Responsável de R&D | R17: 46387 | S17: R16 | T17: Uma fuga ou tampa violada é vista como risco para a saúde. | U17: Requisito não definido pelo cliente mas necessário ao uso (8.2.3 b) | V17: Tratado através das características críticas do plano de controlo. | W17: RG-SGQ-13
A18: PIQ-14 | B18: Comunidade / vizinhança | C18: Externa | D18: Recetores sensíveis | E18: Ausência de ruído e odores. | F18: Não aplicável | G18: Não | H18: Não | I18: — | K18: Tratado pelo SGA (canal de reclamações) | L18: — | M18: Baixa | N18: Média | O18: =IF(A18="","",IF(AND(M18="Alta",N18="Alta"),"Gerir de perto",IF(M18="Alta","Manter satisfeita",IF(N18="Alta","Manter informada","Monitorizar")))) -> Monitorizar | Q18: Gestor do SGA / EHS (Responsável Ambiental) | R18: 46387 | S18: R30; R34 | U18: Reclamações | V18: Tratado pelo SGA (RG-SGA-01/07); não afeta a conformidade do produto. | X18: PI-11
O19: =IF(A19="","",IF(AND(M19="Alta",N19="Alta"),"Gerir de perto",IF(M19="Alta","Manter satisfeita",IF(N19="Alta","Manter informada","Monitorizar"))))
O20: =IF(A20="","",IF(AND(M20="Alta",N20="Alta"),"Gerir de perto",IF(M20="Alta","Manter satisfeita",IF(N20="Alta","Manter informada","Monitorizar"))))
O21: =IF(A21="","",IF(AND(M21="Alta",N21="Alta"),"Gerir de perto",IF(M21="Alta","Manter satisfeita",IF(N21="Alta","Manter informada","Monitorizar"))))
O22: =IF(A22="","",IF(AND(M22="Alta",N22="Alta"),"Gerir de perto",IF(M22="Alta","Manter satisfeita",IF(N22="Alta","Manter informada","Monitorizar"))))
O23: =IF(A23="","",IF(AND(M23="Alta",N23="Alta"),"Gerir de perto",IF(M23="Alta","Manter satisfeita",IF(N23="Alta","Manter informada","Monitorizar"))))
O24: =IF(A24="","",IF(AND(M24="Alta",N24="Alta"),"Gerir de perto",IF(M24="Alta","Manter satisfeita",IF(N24="Alta","Manter informada","Monitorizar"))))

Sheet Alteracoes_Climaticas
A1: DETERMINAÇÃO SOBRE AS ALTERAÇÕES CLIMÁTICAS (4.1 e 4.2 — ISO 9001:2026)
A2: A norma exige determinar SE é pertinente; a resposta e a justificação ficam aqui como evidência
A4: ID_Clima | B4: Pergunta | C4: Resposta | D4: Justificacao | E4: Ligacoes
A5: CLI-01 | B5: A mudança climática é uma questão pertinente para o SGQ? (4.1) | C5: Sim | D5: Afeta a capacidade de entregar produto conforme (temperatura de processo) e a continuidade do fornecimento. | E5: PESQ-06; PESQ-07
A6: CLI-02 | B6: Efeito físico no processo | C6: Sim | D6: Ondas de calor alteram a janela de processo do sopro de PET (condicionamento de preformas) e o arrefecimento dos moldes. | E6: PESQ-06; SWTQ-T04
A7: CLI-03 | B7: Efeito na cadeia de abastecimento | C7: Sim | D7: Eventos extremos nos portos e fábricas de polímero (EUA, Singapura) causam atrasos de resina. | E7: PESQ-07
A8: CLI-04 | B8: Requisitos de partes interessadas relacionados com o clima (4.2 Nota) | C8: Sim | D8: Clientes pedem pegada de carbono e conteúdo reciclado; tratados como requisito de produto quando especificados. | E8: PESQ-08; PIQ-02; PIQ-05
A9: CLI-05 | B9: Riscos e oportunidades resultantes (6.1) | C9: Sim | D9: Tratados no registo corporativo RG-SGA-02 (R34, O5) e na vista da qualidade RG-SGQ-04. | E9: R34; O5
A10: CLI-06 | B10: Revisão da determinação | C10: Sim | D10: Revista anualmente na revisão pela gestão e sempre que houver evento climático com impacto em produto ou entrega. | E10: RG-SGQ-17

Sheet Ambito_SGQ
A1: ÂMBITO DO SISTEMA DE GESTÃO DA QUALIDADE (4.3)
A2: Tipos de produtos e serviços cobertos · Justificação de requisitos não aplicáveis · Aprovado pela Direção
A4: Elemento | B4: Conteudo
A5: Declaração de âmbito | B5: Conceção, desenvolvimento e fabrico de embalagens plásticas rígidas — frascos soprados (ISBM) em PET, PETG, rPET, PP, PE e PVC, potes e tampas injetadas (incluindo tampas com anel de inviolabilidade e tampas de encaixe) — e decoração por serigrafia e hot foil stamping, para os setores da cosmética, higiene pessoal, alimentar e farmacêutico.
A6: Tipos de produtos cobertos (4.3) | B6: Frascos (famílias FR, FA alimentar, FP farmacêutico), potes (PT), tampas (TR rosca, TF flip top, TE farma inviolável, TP pote, TA alimentar) e peças decoradas.
A7: Serviços cobertos | B7: Apoio técnico ao cliente no desenvolvimento de embalagem, gestão de artwork e decoração personalizada.
A8: Localização | B8: Plasticom — Unidade 1, Zona Industrial da Marinha Grande, Portugal (instalação única; sem locais remotos).
A9: Processos incluídos | B9: Todos os processos do mapa de processos (RG-SGQ-02 tbl_processos): 3 de gestão, 10 de realização e 5 de suporte.
A10: Processos subcontratados controlados pelo SGQ (8.4.1 c) | B10: Calibração de equipamentos (laboratório acreditado), ensaios de migração de confirmação (laboratório externo acreditado), reparação e reforma de moldes, transporte para o cliente.
A11: Questões externas e internas consideradas (4.3 a) | B11: 11 fatores PESTEL (tbl_pestel), 16 itens SWOT (tbl_swot), 5 forças competitivas (tbl_cinco_forcas) e a determinação sobre alterações climáticas (tbl_clima).
A12: Requisitos das partes interessadas considerados (4.3 b) | B12: 14 requisitos pertinentes de 13 partes interessadas; 13 tratados pelo SGQ (tbl_partes_interessadas, coluna Tratado_pelo_SGQ).
A13: Requisitos não aplicáveis (4.3) | B13: Nenhum. Todos os requisitos da ISO 9001:2026 são aplicáveis: a Plasticom projeta os seus produtos (8.3 aplicável), usa moldes e artwork de clientes (8.5.3 aplicável) e mede com rastreabilidade metrológica (7.1.5.2 aplicável).
A14: Integração | B14: O SGQ integra-se com o SGA (ISO 14001:2026) num sistema de gestão integrado (SGI): registo de riscos único (RG-SGA-02) e contexto com a MESMA estrutura no RG-SGA-01 e no RG-SGQ-01 (tbl_pestel, tbl_swot, tbl_tows, tbl_cinco_forcas, tbl_partes_interessadas), consolidável pela coluna Ambito.
A15: Aprovação | B15: Diretor Geral, 28/09/2026 — revisto na revisão pela gestão (RG-SGQ-17).

Sheet Aplicabilidade
A1: Clausula | B1: Titulo | C1: Decisao | D1: Justificacao
