Workbook
Name DataRef: Listas!$A$3
Name lst_Area: Listas!$H$3:$H$7
Name lst_DataReferencia: Listas!$A$3:$A$3
Name lst_Estado: Listas!$B$3:$B$5
Name lst_EstadoRel: Listas!$G$3:$G$4
Name lst_Funcao: Listas!$C$3:$C$29
Name lst_Processo: Listas!$D$3:$D$20
Name lst_RACI: Listas!$E$3:$E$6
Name lst_TipoRelato: Listas!$F$3:$F$7

Sheet 00_LEIA-ME
A1: RG-SGQ-03 — Liderança, Política da Qualidade, Funções e Cultura da Qualidade
A2: Sistema de Gestão da Qualidade NP EN ISO 9001:2026 · Plasticom — Unidade 1 (Marinha Grande, Portugal) · Registo do SGQ (fábrica simulada)
A4: CONTROLO DO DOCUMENTO (7.5 — informação documentada)
A5: Código do registo | B5: RG-SGQ-03
A6: Título | B6: Liderança, Política da Qualidade, Funções e Cultura da Qualidade
A7: Versão / Revisão | B7: 01
A8: Data de emissão | B8: 46387
A9: Elaborado por | B9: Gerente da Qualidade
A10: Aprovado por | B10: Diretor Geral
A11: Estado | B11: Em vigor
A12: Retenção | B12: 5 anos após substituição
A13: Localização | B13: Repositório controlado do SGQ > Registos_SGQ_Plasticom (a versão eletrónica é a controlada; cópias impressas são não controladas). Proteção contra alterações não intencionais (7.5.3.2): edição só pelo dono do registo; histórico de versões no repositório.
A15: FINALIDADE E ÂMBITO
A16: Finalidade | B16: Registo único das evidências de liderança exigidas pela ISO 9001:2026, da política da qualidade aprovada (disponível como informação documentada), da matriz RACI e de autoridades, da autoavaliação da cultura da qualidade (ISO 10010) por área, das gemba walks da direção e do canal de relatos de integridade.
A17: Utilização / atividades | B17: Evidenciar a liderança e o compromisso da gestão de topo, a política da qualidade, as funções e autoridades e o estado da cultura da qualidade e do comportamento ético.
A18: Requisitos ISO 9001:2026 | B18: 5.1.1 a)–l) (2026: i) cultura da qualidade e comportamento ético; l) prestar contas); 5.1.2 Foco no cliente; 5.2 Política da qualidade; 5.3 a)–f); 7.3 e) consciencialização da cultura e ética; 7.1.4
A20: REFERÊNCIAS DE BOAS PRÁTICAS APLICADAS (orientação — não são requisitos auditáveis da ISO 9001)
A21: ISO 10010:2022 — Quality culture | B21: Autoavaliação da maturidade da cultura por dimensão e área (tbl_cultura), com lacuna face à meta e ações.
A22: ISO/TC 176 APG — Top management / Policy and objectives | B22: O auditor entrevista a gestão de topo e procura evidência de envolvimento direto (não delegado): LID-nn com evidência objetiva.
A23: Academy — cap. 10–13 (Liderança, Ética ASQ) | B23: Código de ética e cultura justa: relatos de integridade tratados como falha do sistema.
A25: ESTRUTURA DO FICHEIRO
A26: Politica_Qualidade | B26: Política da qualidade POL-SGQ-01 rev. 01 (formato de afixação) — 5.2.
A27: Verificacao_Politica | B27: Verificação da política face a 5.2.1 a)–e) e 5.2.2 a)–d).
A28: Lideranca_Compromisso | B28: Evidências de liderança e compromisso (5.1.1 a–l) e de foco no cliente (5.1.2 a–c).
A29: Funcoes_Autoridades | B29: Responsabilidades e autoridades atribuídas pela gestão de topo (5.3 a–f) e autoridades de libertação e de NC.
A30: Matriz_RACI | B30: Matriz RACI das atividades do SGQ (R executa, A aprova, C consultado, I informado).
A31: Cultura_Qualidade | B31: Autoavaliação da cultura da qualidade e do comportamento ético (ISO 10010), inquérito de junho/2026 por área.
A32: Respondentes | B32: N.º de respondentes do inquérito de cultura por área (pesos da média ponderada).
A33: Gemba_Walks | B33: Gemba walks da gestão de topo (evidência de 5.1.1 f, h, i).
A34: Relatos_Integridade | B34: Canal de relatos de integridade e comportamento ético relativos à qualidade (5.1.1 i).
A35: Listas | B35: Domínios (listas de valores) usados na validação de dados das tabelas.
A36: Dicionario_Dados | B36: Descrição de cada coluna de cada tabela: tipo, origem (entrada/calculado), domínio, obrigatoriedade e chaves.
A38: CONVENÇÕES (prontas para análise de dados e machine learning)
A39: Tabelas | B39: Cada registo é uma Tabela Excel com nome próprio (tbl_*): uma linha = um registo, cabeçalho único, sem células mescladas. Ler com pandas (pd.read_excel(ficheiro, sheet_name=folha, header=<linha do cabeçalho - 1>)) ou Power BI (Obter Dados > Tabela).
A40: Cabeçalho cinzento | B40: Coluna CALCULADA por fórmula — não escrever por cima. As restantes colunas são de entrada.
A41: Validação | B41: Colunas com lista controlada só aceitam valores da folha Listas (evita categorias duplicadas por grafia diferente).
A42: Chaves | B42: IDs estáveis e únicos (PK) e referências a IDs de outros registos (FK) permitem juntar tabelas entre ficheiros do SGQ e do SGA — ver SGQ-00_Indice_Modelo_Dados.xlsx.
A43: Datas e unidades | B43: Datas em formato data (aaaa-mm-dd); números como números; a unidade está no nome da coluna ou no dicionário. Data de referência do SGQ: 2026-12-31.
A44: Dados | B44: Fábrica simulada Plasticom. Dados operacionais e de qualidade extraídos do dataset do projeto (datasets/silver e datasets/dim, período 2025-07-01 a 2026-12-31); os campos de gestão que o dataset não tem (datas de resposta, avaliações, decisões) são simulação didática coerente com esses dados.
A46: LIGAÇÕES A OUTROS REGISTOS
...

Sheet Politica_Qualidade
A1: PLASTICOM | B1: POLÍTICA DA QUALIDADE | F1: POL-SGQ-01
B2: Plasticom — Unidade 1 (Marinha Grande, Portugal) · NP EN ISO 9001:2026 | F2: Rev. 01 · 31/12/2026
A5: Propósito | B5: A Plasticom projeta e fabrica embalagens plásticas para cosmética, alimentar e farmacêutico. Para cumprir o nosso propósito — proteger o que os nossos clientes colocam nas mãos das pessoas — comprometemo-nos a:
B6: 1. Cumprir os requisitos dos clientes e os requisitos legais e regulamentares aplicáveis aos nossos produtos, incluindo os de materiais em contacto com alimentos e de embalagem farmacêutica.
B7: 2. Fazer bem à primeira: controlar os processos pela variação (capacidade, SPC e prevenção do erro humano) e não pela inspeção.
B8: 3. Ouvir o cliente — reclamações, satisfação e requisitos futuros — e responder com rapidez e transparência, incluindo em situações de disrupção.
B9: 4. Escolher e desenvolver fornecedores que partilhem estes compromissos.
B10: 5. Promover uma cultura da qualidade e um comportamento ético em que ninguém é pressionado a libertar produto duvidoso e em que relatar um problema é reconhecido.
B11: 6. Gerir riscos e oportunidades, incluindo os associados às alterações climáticas, para garantir a continuidade do fornecimento.
B12: 7. Melhorar continuamente a eficácia do sistema de gestão da qualidade, com objetivos mensuráveis revistos pela gestão.
A13: Divulgação | B13: Esta política é comunicada a todos os colaboradores, está disponível às partes interessadas em plasticom.pt e é revista anualmente na revisão pela gestão.
A14: Aprovação | B14: Marinha Grande, 28 de setembro de 2026 — Diretor Geral

Sheet Verificacao_Politica
A1: VERIFICAÇÃO DA POLÍTICA DA QUALIDADE (5.2)
A4: Requisito | B4: Descricao | C4: Evidencia | D4: Estado
A5: 5.2.1 a) | B5: Apropriada ao propósito e ao contexto da organização | C5: Propósito e setores explícitos na introdução | D5: Evidenciado
A6: 5.2.1 b) | B6: Proporciona um enquadramento para os objetivos da qualidade | C6: Cada objetivo OBJ-Q-nn liga a um compromisso (RG-SGQ-05 coluna Compromisso_Politica) | D6: Evidenciado
A7: 5.2.1 c) | B7: Inclui o compromisso de cumprir os requisitos aplicáveis | C7: Compromisso 1 | D7: Evidenciado
A8: 5.2.1 d) | B8: Inclui o compromisso de melhoria contínua do SGQ | C8: Compromisso 7 | D8: Evidenciado
A9: 5.2.1 e) | B9: Tem em conta o contexto e apoia a orientação estratégica (novo 2026) | C9: Compromissos 1, 5 e 6 ligados às fatores PESQ-01, SWTQ-W02 e PESQ-06/07 (RG-SGQ-01) | D9: Evidenciado
A10: 5.2.2 a) | B10: Disponível como informação documentada | C10: POL-SGQ-01 rev. 01 na lista mestra (RG-SGQ-08) | D10: Evidenciado
A11: 5.2.2 b) | B11: Comunicada dentro da organização | C11: Afixada nos 4 pavilhões; sessão de consciencialização CON-26-01 (RG-SGQ-07) | D11: Evidenciado
A12: 5.2.2 c) | B12: Disponível às partes interessadas, conforme apropriado | C12: Publicada no site; anexa aos acordos de qualidade | D12: Evidenciado
A13: 5.2.2 d) | B13: Implementada, compreendida e aplicada | C13: Entrevistas na auditoria AUD-Q-26-03: 7 de 10 operadores explicam o compromisso 2 | D13: Parcial

Sheet Lideranca_Compromisso
A1: LIDERANÇA E COMPROMISSO DA GESTÃO DE TOPO (5.1)
A2: ISO 9001:2026 acrescenta i) cultura da qualidade e comportamento ético e l) prestar contas pela eficácia
A4: ID | B4: Alinea | C4: Compromisso | D4: Como_Demonstra | E4: Evidencia | F4: Responsavel | G4: Estado | H4: Frequencia | I4: Novo_2026
A5: LID-01 | B5: 5.1.1 a) | C5: Política e objetivos estabelecidos e compatíveis com a estratégia | D5: Aprovação da política e dos objetivos 2026 na revisão pela gestão | E5: Ata RPG-2026-01; RG-SGQ-05 | F5: Diretor Geral (Gestão de Topo) | G5: Evidenciado | H5: Anual | I5: =IF(OR(B5="5.1.1 i)",B5="5.1.1 l)"),"Sim","Não") -> Não
A6: LID-02 | B6: 5.1.1 b) | C6: Integração dos requisitos do SGQ nos processos de negócio | D6: Revisão de requisitos no ERP bloqueia encomendas sem especificação aprovada; KPI da qualidade no bónus da chefia | E6: RG-SGQ-10; sistema de incentivos 2026 | F6: Diretor Geral (Gestão de Topo) | G6: Parcial | H6: Anual | I6: =IF(OR(B6="5.1.1 i)",B6="5.1.1 l)"),"Sim","Não") -> Não
A7: LID-03 | B7: 5.1.1 c) | C7: Recursos necessários disponíveis | D7: Orçamento 2026: visão artificial HF-001, 2 inspetores adicionais no pico, calibração acreditada | E7: Orçamento 2026; decisões RPG-2026-01 D03–D05 | F7: Diretor Geral (Gestão de Topo) | G7: Evidenciado | H7: Anual | I7: =IF(OR(B7="5.1.1 i)",B7="5.1.1 l)"),"Sim","Não") -> Não
A8: LID-04 | B8: 5.1.1 d) | C8: Comunicar a importância de uma gestão da qualidade eficaz | D8: Reunião trimestral com todos os turnos; mensagem do DG no lançamento das linhas alimentar/farma | E8: Atas das reuniões gerais T1–T3/2026 | F8: Diretor Geral (Gestão de Topo) | G8: Evidenciado | H8: Trimestral | I8: =IF(OR(B8="5.1.1 i)",B8="5.1.1 l)"),"Sim","Não") -> Não
A9: LID-05 | B9: 5.1.1 e) | C9: Assegurar que o SGQ atinge os resultados pretendidos | D9: Painel mensal de KPI revisto no comité de direção | E9: RG-SGQ-05 Painel; atas do comité | F9: Diretor Industrial | G9: Evidenciado | H9: Mensal | I9: =IF(OR(B9="5.1.1 i)",B9="5.1.1 l)"),"Sim","Não") -> Não
A10: LID-06 | B10: 5.1.1 f) | C10: Envolver, orientar e apoiar as pessoas | D10: Gemba walks semanais da direção (tbl_gemba); caixa de sugestões com resposta em 15 dias | E10: RG-SGQ-03 tbl_gemba; RG-SGQ-19 sugestões | F10: Diretor Industrial | G10: Evidenciado | H10: Semanal | I10: =IF(OR(B10="5.1.1 i)",B10="5.1.1 l)"),"Sim","Não") -> Não
A11: LID-07 | B11: 5.1.1 g) | C11: Promover a melhoria contínua | D11: Patrocínio dos projetos DMAIC IM-002, SMED e visão artificial | E11: RG-SGQ-19 tbl_projetos | F11: Diretor Geral (Gestão de Topo) | G11: Evidenciado | H11: Trimestral | I11: =IF(OR(B11="5.1.1 i)",B11="5.1.1 l)"),"Sim","Não") -> Não
A12: LID-08 | B12: 5.1.1 h) | C12: Apoiar outras funções de gestão a demonstrar liderança | D12: Chefes de turno com objetivos de qualidade e formação em liderança de equipas | E12: RG-SGQ-07 FOR-Q-12 | F12: Diretor Industrial | G12: Parcial | H12: Semestral | I12: =IF(OR(B12="5.1.1 i)",B12="5.1.1 l)"),"Sim","Não") -> Não
A13: LID-09 | B13: 5.1.1 i) | C13: Promover a cultura da qualidade e o comportamento ético (novo 2026) | D13: Código de conduta com cláusula 'nunca libertar produto duvidoso'; canal de relato; avaliação ISO 10010 da cultura | E13: RG-SGQ-03 tbl_cultura, tbl_relatos_etica | F13: Diretor Geral (Gestão de Topo) | G13: Parcial | H13: Semestral | I13: =IF(OR(B13="5.1.1 i)",B13="5.1.1 l)"),"Sim","Não") -> Sim
A14: LID-10 | B14: 5.1.1 j) | C14: Promover a abordagem por processos | D14: Donos de processo nomeados com KPI (RG-SGQ-02) | E14: RG-SGQ-02 tbl_processos | F14: Gerente da Qualidade | G14: Evidenciado | H14: Anual | I14: =IF(OR(B14="5.1.1 i)",B14="5.1.1 l)"),"Sim","Não") -> Não
A15: LID-11 | B15: 5.1.1 k) | C15: Promover o pensamento baseado em riscos e em oportunidades | D15: Registo de riscos corporativo único com donos de risco da direção | E15: RG-SGA-02; RG-SGQ-04 | F15: Diretor Geral (Gestão de Topo) | G15: Evidenciado | H15: Trimestral | I15: =IF(OR(B15="5.1.1 i)",B15="5.1.1 l)"),"Sim","Não") -> Não
A16: LID-12 | B16: 5.1.1 l) | C16: Prestar contas pela eficácia do SGQ | D16: DG assina a conclusão sobre a eficácia do SGQ na ata da revisão pela gestão | E16: RG-SGQ-17 Ata | F16: Diretor Geral (Gestão de Topo) | G16: Evidenciado | H16: Anual | I16: =IF(OR(B16="5.1.1 i)",B16="5.1.1 l)"),"Sim","Não") -> Sim
... A19: LID-15 | B19: 5.1.2 c) | C19: Foco no aumento da satisfação do cliente | D19: Inquérito semestral; objetivo de CSI e NPS; visita anual aos 5 maiores clientes | E19: RG-SGQ-15; RG-SGQ-05 OBJ-Q-06 | F19: Diretor Comercial | G19: Evidenciado | H19: Semestral | I19: =IF(OR(B19="5.1.1 i)",B19="5.1.1 l)"),"Sim","Não") -> Não

Sheet Funcoes_Autoridades
A1: ID | B1: Referencia | C1: Responsabilidade_Autoridade | D1: Atribuida_a | E1: Evidencia_Atribuicao
A2: AUT-01 | B2: 5.3 a) | C2: Assegurar que o SGQ está conforme com a ISO 9001:2026 | D2: Gerente da Qualidade | E2: Nomeação escrita do DG (02/01/2026)
A3: AUT-02 | B3: 5.3 b) | C3: Reportar o desempenho do SGQ à gestão de topo | D3: Gerente da Qualidade | E3: Relatório mensal de KPI e entradas da revisão pela gestão
A4: AUT-03 | B4: 5.3 c) | C4: Assegurar que os processos produzem as saídas pretendidas | D4: Donos de processo (RG-SGQ-02) | E4: Descrição de funções atualizada em 2026
A5: AUT-04 | B5: 5.3 d) | C5: Promover o foco no cliente em toda a organização | D5: Diretor Comercial | E5: Descrição de funções
A6: AUT-05 | B6: 5.3 e) | C6: Reportar oportunidades de melhoria | D6: Gerente da Qualidade | E6: Revisão pela gestão; carteira de projetos
A7: AUT-06 | B7: 5.3 f) | C7: Manter a integridade do SGQ quando se planeiam e implementam alterações | D7: Gerente da Qualidade | E7: Aprovação obrigatória no pedido de alteração MOC (RG-SGQ-06)
A8: AUT-07 | B8: 8.6 / 8.7 | C8: Autoridade para libertar lotes e decidir sobre saídas não conformes | D8: Técnico(a) da Qualidade / Inspetor(a) (lotes conformes); Gerente da Qualidade (concessões) | E8: Matriz de autoridades de libertação
A9: AUT-08 | B9: 8.7 | C9: Autoridade para parar a linha por problema de qualidade | D9: Qualquer operador ou inspetor (andon) | E9: Instrução IT-GER-01 'Parar para corrigir'
A10: AUT-09 | B10: 8.7.1 d) | C10: Autoridade para pedir concessão ao cliente | D10: Diretor Comercial + Gerente da Qualidade | E10: Formulário de concessão; aceitação escrita do cliente

Sheet Matriz_RACI
A1: MATRIZ RACI DO SGQ (5.3)
A2: Legenda das colunas no comentário de cada cabeçalho · R = executa · A = aprova (um só) · C = consultado · I = informado
A4: ID_Processo | B4: Processo_SGQ | C4: Clausula | D4: Diretor_Geral | E4: Diretor_Industrial | F4: Gerente_Producao | G4: Gerente_Manutencao | H4: Gerente_Qualidade | I4: Resp_Armazem_Logistica | J4: Resp_Compras | K4: Resp_RD | L4: Resp_RH | M4: Chefes_Turno | N4: Operadores | O4: Diretor_Comercial | P4: Gestor_Cliente_KAM | Q4: Planeador_Producao | R4: Gerente_Dados_TI | S4: Engenheiro_Processo | T4: Inspetores_Qualidade | U4: Tecnico_Metrologia | V4: Tecnico_Manutencao | W4: Auditor_Interno_SGQ | X4: Gestor_Documental | Y4: N_Aprovadores | Z4: Controlo_RACI
A5: RACI-Q-01 | B5: Rever a política e os objetivos da qualidade | C5: 5.2; 6.2 | D5: A | E5: R | F5: C | H5: R | L5: I | O5: C | Y5: =IF(A5="","",COUNTIF(D5:X5,"A")) -> 1 | Z5: =IF(A5="","",IF(COUNTIF(D5:X5,"A")<>1,"1 A obrigatório",IF(COUNTIF(D5:X5,"R")=0,"Falta R","OK"))) -> OK
A6: RACI-Q-02 | B6: Revisão de requisitos e aceitação de encomendas | C6: 8.2 | F6: C | H6: C | K6: C | O6: A | P6: R | Y6: =IF(A6="","",COUNTIF(D6:X6,"A")) -> 1 | Z6: =IF(A6="","",IF(COUNTIF(D6:X6,"A")<>1,"1 A obrigatório",IF(COUNTIF(D6:X6,"R")=0,"Falta R","OK"))) -> OK
A7: RACI-Q-03 | B7: Design e desenvolvimento de novos produtos | C7: 8.3 | E7: A | F7: C | H7: C | J7: C | K7: R | O7: C | Y7: =IF(A7="","",COUNTIF(D7:X7,"A")) -> 1 | Z7: =IF(A7="","",IF(COUNTIF(D7:X7,"A")<>1,"1 A obrigatório",IF(COUNTIF(D7:X7,"R")=0,"Falta R","OK"))) -> OK
A8: RACI-Q-04 | B8: Aprovação e avaliação de fornecedores | C8: 8.4 | E8: I | H8: R | J8: A | K8: C | Y8: =IF(A8="","",COUNTIF(D8:X8,"A")) -> 1 | Z8: =IF(A8="","",IF(COUNTIF(D8:X8,"A")<>1,"1 A obrigatório",IF(COUNTIF(D8:X8,"R")=0,"Falta R","OK"))) -> OK
A9: RACI-Q-05 | B9: Planeamento da produção | C9: 8.1; 8.5.1 | F9: A | G9: C | O9: C | Q9: R | Y9: =IF(A9="","",COUNTIF(D9:X9,"A")) -> 1 | Z9: =IF(A9="","",IF(COUNTIF(D9:X9,"A")<>1,"1 A obrigatório",IF(COUNTIF(D9:X9,"R")=0,"Falta R","OK"))) -> OK
A10: RACI-Q-06 | B10: Setup e arranque de ordem de fabrico | C10: 8.5.1 | F10: A | M10: R | N10: R | T10: C | Y10: =IF(A10="","",COUNTIF(D10:X10,"A")) -> 1 | Z10: =IF(A10="","",IF(COUNTIF(D10:X10,"A")<>1,"1 A obrigatório",IF(COUNTIF(D10:X10,"R")=0,"Falta R","OK"))) -> OK
A11: RACI-Q-07 | B11: Inspeção e libertação de lote | C11: 8.6 | F11: I | H11: A | I11: I | T11: R | Y11: =IF(A11="","",COUNTIF(D11:X11,"A")) -> 1 | Z11: =IF(A11="","",IF(COUNTIF(D11:X11,"A")<>1,"1 A obrigatório",IF(COUNTIF(D11:X11,"R")=0,"Falta R","OK"))) -> OK
A12: RACI-Q-08 | B12: Decisão sobre saída não conforme / concessão | C12: 8.7 | D12: I | F12: C | H12: A | O12: C | T12: R | Y12: =IF(A12="","",COUNTIF(D12:X12,"A")) -> 1 | Z12: =IF(A12="","",IF(COUNTIF(D12:X12,"A")<>1,"1 A obrigatório",IF(COUNTIF(D12:X12,"R")=0,"Falta R","OK"))) -> OK
A13: RACI-Q-09 | B13: Tratamento de reclamação de cliente (8D) | C13: 9.1.2; 10.2 | F13: C | H13: A | O13: I | P13: R | T13: C | Y13: =IF(A13="","",COUNTIF(D13:X13,"A")) -> 1 | Z13: =IF(A13="","",IF(COUNTIF(D13:X13,"A")<>1,"1 A obrigatório",IF(COUNTIF(D13:X13,"R")=0,"Falta R","OK"))) -> OK
A14: RACI-Q-10 | B14: Calibração e MSA | C14: 7.1.5 | H14: A | T14: C | U14: R | Y14: =IF(A14="","",COUNTIF(D14:X14,"A")) -> 1 | Z14: =IF(A14="","",IF(COUNTIF(D14:X14,"A")<>1,"1 A obrigatório",IF(COUNTIF(D14:X14,"R")=0,"Falta R","OK"))) -> OK
A15: RACI-Q-11 | B15: Planeamento de alterações (MOC) | C15: 6.3; 8.5.6 | E15: A | H15: R | K15: C | L15: C | O15: C | S15: R | Y15: =IF(A15="","",COUNTIF(D15:X15,"A")) -> 1 | Z15: =IF(A15="","",IF(COUNTIF(D15:X15,"A")<>1,"1 A obrigatório",IF(COUNTIF(D15:X15,"R")=0,"Falta R","OK"))) -> OK
A16: RACI-Q-12 | B16: Auditoria interna | C16: 9.2 | D16: I | H16: A | W16: R | Y16: =IF(A16="","",COUNTIF(D16:X16,"A")) -> 1 | Z16: =IF(A16="","",IF(COUNTIF(D16:X16,"A")<>1,"1 A obrigatório",IF(COUNTIF(D16:X16,"R")=0,"Falta R","OK"))) -> OK
A17: RACI-Q-13 | B17: Revisão pela gestão | C17: 9.3 | D17: A | E17: R | H17: R | J17: C | L17: C | O17: C | Y17: =IF(A17="","",COUNTIF(D17:X17,"A")) -> 1 | Z17: =IF(A17="","",IF(COUNTIF(D17:X17,"A")<>1,"1 A obrigatório",IF(COUNTIF(D17:X17,"R")=0,"Falta R","OK"))) -> OK
A18: RACI-Q-14 | B18: Formação e avaliação de competências | C18: 7.2; 7.3 | F18: R | H18: C | L18: A | N18: I | Y18: =IF(A18="","",COUNTIF(D18:X18,"A")) -> 1 | Z18: =IF(A18="","",IF(COUNTIF(D18:X18,"A")<>1,"1 A obrigatório",IF(COUNTIF(D18:X18,"R")=0,"Falta R","OK"))) -> OK
A19: RACI-Q-15 | B19: Manutenção de máquinas e moldes | C19: 7.1.3 | F19: C | G19: A | H19: I | V19: R | Y19: =IF(A19="","",COUNTIF(D19:X19,"A")) -> 1 | Z19: =IF(A19="","",IF(COUNTIF(D19:X19,"A")<>1,"1 A obrigatório",IF(COUNTIF(D19:X19,"R")=0,"Falta R","OK"))) -> OK
A20: RACI-Q-16 | B20: Controlo de documentos e registos | C20: 7.5 | H20: A | R20: C | X20: R | Y20: =IF(A20="","",COUNTIF(D20:X20,"A")) -> 1 | Z20: =IF(A20="","",IF(COUNTIF(D20:X20,"A")<>1,"1 A obrigatório",IF(COUNTIF(D20:X20,"R")=0,"Falta R","OK"))) -> OK

Sheet Cultura_Qualidade
A1: CULTURA DA QUALIDADE E COMPORTAMENTO ÉTICO — AUTOAVALIAÇÃO ISO 10010 (jun/2026)
A2: Evidência de 5.1.1 i) e 7.3 e) · Escala 1–5 · 149 respondentes (folha Respondentes) · Média ponderada, lacuna e nível calculados
A4: ID_Dimensao | B4: Dimensao | C4: Afirmacao_Avaliada | D4: Produção | E4: Qualidade | F4: Manutenção | G4: Comercial | H4: Logística | I4: Media_Ponderada | J4: Meta | K4: Lacuna | L4: Area_Mais_Fraca | M4: Nivel_Maturidade
A5: CUL-01 | B5: Propósito, visão e valores partilhados | C5: As pessoas conhecem o propósito e os valores e agem de acordo | D5: 3.1 | E5: 3.9 | F5: 3.4 | G5: 3.8 | H5: 3.2 | I5: =SUMPRODUCT(D5:H5,Respondentes!$B$2:$F$2)/SUM(Respondentes!$B$2:$F$2) -> 3.2469799 | J5: 3.5 | K5: =J5-I5 -> 0.25302013 | L5: =INDEX($D$4:$H$4,MATCH(MIN(D5:H5),D5:H5,0)) -> Produção | M5: =IF(I5>=4.5,"5-Excelência",IF(I5>=3.5,"4-Proativa",IF(I5>=2.5,"3-Definida",IF(I5>=1.5,"2-Reativa","1-Inicial")))) -> 3-Definida
A6: CUL-02 | B6: Liderança e exemplo da gestão | C6: A gestão decide a favor da qualidade mesmo sob pressão de prazo | D6: 2.6 | E6: 3.3 | F6: 3 | G6: 3.4 | H6: 2.9 | I6: =SUMPRODUCT(D6:H6,Respondentes!$B$2:$F$2)/SUM(Respondentes!$B$2:$F$2) -> 2.7785235 | J6: 3.5 | K6: =J6-I6 -> 0.72147651 | L6: =INDEX($D$4:$H$4,MATCH(MIN(D6:H6),D6:H6,0)) -> Produção | M6: =IF(I6>=4.5,"5-Excelência",IF(I6>=3.5,"4-Proativa",IF(I6>=2.5,"3-Definida",IF(I6>=1.5,"2-Reativa","1-Inicial")))) -> 3-Definida
A7: CUL-03 | B7: Foco no cliente | C7: Cada pessoa sabe quem é o cliente do seu trabalho e o que ele valoriza | D7: 2.9 | E7: 3.8 | F7: 2.8 | G7: 4.2 | H7: 3.3 | I7: =SUMPRODUCT(D7:H7,Respondentes!$B$2:$F$2)/SUM(Respondentes!$B$2:$F$2) -> 3.0899329 | J7: 3.5 | K7: =J7-I7 -> 0.41006711 | L7: =INDEX($D$4:$H$4,MATCH(MIN(D7:H7),D7:H7,0)) -> Manutenção | M7: =IF(I7>=4.5,"5-Excelência",IF(I7>=3.5,"4-Proativa",IF(I7>=2.5,"3-Definida",IF(I7>=1.5,"2-Reativa","1-Inicial")))) -> 3-Definida
A8: CUL-04 | B8: Envolvimento e empoderamento das pessoas | C8: As pessoas podem parar a linha e propor melhorias | D8: 2.7 | E8: 3.6 | F8: 3.3 | G8: 3.5 | H8: 2.8 | I8: =SUMPRODUCT(D8:H8,Respondentes!$B$2:$F$2)/SUM(Respondentes!$B$2:$F$2) -> 2.8892617 | J8: 3.5 | K8: =J8-I8 -> 0.61073826 | L8: =INDEX($D$4:$H$4,MATCH(MIN(D8:H8),D8:H8,0)) -> Produção | M8: =IF(I8>=4.5,"5-Excelência",IF(I8>=3.5,"4-Proativa",IF(I8>=2.5,"3-Definida",IF(I8>=1.5,"2-Reativa","1-Inicial")))) -> 3-Definida
A9: CUL-05 | B9: Decisões baseadas em evidência | C9: Decisões apoiadas em dados (SPC, AQL, KPI) e não em opinião | D9: 3 | E9: 4.1 | F9: 3.5 | G9: 3.1 | H9: 2.7 | I9: =SUMPRODUCT(D9:H9,Respondentes!$B$2:$F$2)/SUM(Respondentes!$B$2:$F$2) -> 3.1053691 | J9: 3.5 | K9: =J9-I9 -> 0.39463087 | L9: =INDEX($D$4:$H$4,MATCH(MIN(D9:H9),D9:H9,0)) -> Logística | M9: =IF(I9>=4.5,"5-Excelência",IF(I9>=3.5,"4-Proativa",IF(I9>=2.5,"3-Definida",IF(I9>=1.5,"2-Reativa","1-Inicial")))) -> 3-Definida
A10: CUL-06 | B10: Aprendizagem e melhoria | C10: Os erros são analisados pela causa do sistema e as lições partilhadas | D10: 2.5 | E10: 3.2 | F10: 3.1 | G10: 3 | H10: 2.6 | I10: =SUMPRODUCT(D10:H10,Respondentes!$B$2:$F$2)/SUM(Respondentes!$B$2:$F$2) -> 2.6550336 | J10: 3.5 | K10: =J10-I10 -> 0.84496644 | L10: =INDEX($D$4:$H$4,MATCH(MIN(D10:H10),D10:H10,0)) -> Produção | M10: =IF(I10>=4.5,"5-Excelência",IF(I10>=3.5,"4-Proativa",IF(I10>=2.5,"3-Definida",IF(I10>=1.5,"2-Reativa","1-Inicial")))) -> 3-Definida
A11: CUL-07 | B11: Comportamento ético e integridade | C11: Ninguém é pressionado a aceitar, registar ou libertar algo não conforme | D11: 2.8 | E11: 3.4 | F11: 3.5 | G11: 3.6 | H11: 3.1 | I11: =SUMPRODUCT(D11:H11,Respondentes!$B$2:$F$2)/SUM(Respondentes!$B$2:$F$2) -> 2.9986577 | J11: 3.5 | K11: =J11-I11 -> 0.50134228 | L11: =INDEX($D$4:$H$4,MATCH(MIN(D11:H11),D11:H11,0)) -> Produção | M11: =IF(I11>=4.5,"5-Excelência",IF(I11>=3.5,"4-Proativa",IF(I11>=2.5,"3-Definida",IF(I11>=1.5,"2-Reativa","1-Inicial")))) -> 3-Definida
A12: CUL-08 | B12: Comunicação aberta | C12: Os problemas sobem rapidamente sem medo de culpa | D12: 2.4 | E12: 3.3 | F12: 3 | G12: 3.4 | H12: 2.7 | I12: =SUMPRODUCT(D12:H12,Respondentes!$B$2:$F$2)/SUM(Respondentes!$B$2:$F$2) -> 2.6255034 | J12: 3.5 | K12: =J12-I12 -> 0.87449664 | L12: =INDEX($D$4:$H$4,MATCH(MIN(D12:H12),D12:H12,0)) -> Produção | M12: =IF(I12>=4.5,"5-Excelência",IF(I12>=3.5,"4-Proativa",IF(I12>=2.5,"3-Definida",IF(I12>=1.5,"2-Reativa","1-Inicial")))) -> 3-Definida

Sheet Respondentes
A1: Área | B1: Produção | C1: Qualidade | D1: Manutenção | E1: Comercial | F1: Logística | G1: Total
A2: Respondentes | B2: 96 | C2: 12 | D2: 14 | E2: 9 | F2: 18 | G2: =SUM(B2:F2) -> 149

Sheet Gemba_Walks
A1: ID_Gemba | B1: Data | C1: Lider | D1: Processo | E1: Tema | F1: Observacao | G1: Acao_Decidida | H1: Ligacao
A2: GW-26-01 | B2: 46176 | C2: Diretor Geral (Gestão de Topo) | D2: SOP | E2: Arranque da linha farmacêutica ISBM-009 | F2: Instruções da linha nova ainda em rascunho no posto | G2: Aprovar IT-SOP-03 antes da produção de série | H2: MOC-Q-26-03
A3: GW-26-02 | B3: 46190 | C3: Diretor Industrial | D3: INJ | E3: Turno 2 — passagem de turno | F3: Passagem verbal, sem registo do estado dos moldes | G3: Checklist de passagem de turno | H3: PAQ-26-08
A4: GW-26-03 | B4: 46204 | C4: Gerente da Qualidade | D4: LAB | E4: Libertação de lotes no pico | F4: Fila de lotes a aguardar decisão; pressão para libertar sem leak test | G4: Reforçar inspetor no turno 2 em jul–nov | H4: RPG-2026-01 D04
A5: GW-26-04 | B5: 46218 | C5: Diretor Geral (Gestão de Topo) | D5: EXP | E5: Expedição — reclamações de produto trocado | F5: Etiquetas manuais sem leitura de código de barras na carga | G5: Leitura obrigatória na carga (poka-yoke) | H5: CAPA-Q-26-02
A6: GW-26-05 | B6: 46232 | C6: Diretor Industrial | D6: SER | E6: SS-001 — aderência | F6: Ensaio de aderência feito só no fim do lote | G6: Ensaio no arranque + meio do lote | H6: PC-DEC-01 rev. 03
A7: GW-26-06 | B7: 46246 | C7: Gerente da Qualidade | D7: REC | E7: Receção de resina SUP-005 | F7: Lote em quarentena usado por engano (etiqueta caída) | G7: Zona de quarentena fechada e bloqueio no ERP | H7: CAPA-Q-26-05
A8: GW-26-07 | B8: 46260 | C8: Diretor Geral (Gestão de Topo) | D8: INJ | E8: Novas máquinas IM-007/IM-008 | F8: Operador temporário sozinho na IM-008 sem validação | G8: Tutor obrigatório até validação no posto | H8: RG-SGQ-07
A9: GW-26-08 | B9: 46274 | C9: Diretor Comercial | D9: LAB | E9: Visita com cliente CUST-017 (farma) | F9: Cliente pediu evidência do ensaio do anel de inviolabilidade por lote | G9: Anexar resultado ao certificado de lote | H9: RG-SGQ-13
A10: GW-26-09 | B10: 46288 | C10: Diretor Industrial | D10: MAN | E10: Moldes — contadores de ciclos | F10: Contadores não registados no MES | G10: Integrar contadores (O2) | H10: O2
A11: GW-26-10 | B11: 46302 | C11: Gerente da Qualidade | D11: COM | E11: Revisão de encomendas após CAPA-Q-26-13 | F11: Checklist no ERP usada em todas as encomendas observadas | G11: Manter; medir exceções mensalmente | H11: CAPA-Q-26-13
A12: GW-26-11 | B12: 46316 | C12: Diretor Geral (Gestão de Topo) | D12: SOP | E12: Pico de encomendas — linhas ISBM-009/010 | F12: Peso fora do alvo no arranque do turno 3; ajuste sem registo | G12: Registo obrigatório de ajustes no MES | H12: CON-Q-26-18
A13: GW-26-12 | B13: 46330 | C13: Diretor Industrial | D13: LAB | E13: Libertação de lotes com o 2.º inspetor | F13: Fila de lotes reduzida para < 4 h | G13: Manter reforço até ao fim do pico | H13: MOC-Q-26-14
... A16: GW-26-15 | B16: 46372 | C16: Diretor Geral (Gestão de Topo) | D16: INJ | E16: Balanço do ano nas IM-007/008 | F16: Operadores validados; instruções no HMI (SUG-26-07) | G16: Partilhar prática com a injeção antiga | H16: SUG-26-07

Sheet Relatos_Integridade
A1: RELATOS DE INTEGRIDADE E COMPORTAMENTO ÉTICO (5.1.1 i)
A2: Canal confidencial · Nenhum relator é penalizado · Casos confirmados alimentam a revisão pela gestão
A4: ID_Relato | B4: Data | C4: Tipo | D4: Descricao | E4: Origem | F4: Investigacao | G4: Resultado_Acao | H4: Estado | I4: Dias
A5: REL-26-01 | B5: 46092 | C5: Pressão para libertar | D5: Chefe de turno pediu para registar o lote como aprovado antes do fim do leak test para cumprir a expedição. | E5: Anónimo | F5: Investigado | G5: Confirmado. Lote retido até ensaio; conversa com a chefia; regra 'sem ensaio, sem etiqueta verde' reforçada. | H5: Fechado | I5: =IF(B5="","",DataRef-B5) -> 295
A6: REL-26-02 | B6: 46148 | C6: Registo incorreto | D6: Medições de peso copiadas do turno anterior num posto do sopro. | E6: Inspetor(a) | F6: Investigado | G6: Confirmado num posto (ISBM-006). Formação em integridade de dados; recolha automática do peso da balança para o MES (O3). | H6: Fechado | I6: =IF(B6="","",DataRef-B6) -> 239
A7: REL-26-03 | B7: 46225 | C7: Concessão sem autorização | D7: Lote de tampas com rosca marginal expedido 'por concessão' sem acordo do cliente. | E7: Gestor(a) de cliente | F7: Investigado | G7: Confirmado. Cliente informado (8.7.1 c); concessão formal obtida a posteriori; autoridades de concessão clarificadas (AUT-09). | H7: Fechado | I7: =IF(B7="","",DataRef-B7) -> 162
A8: REL-26-04 | B8: 46280 | C8: Segurança do produto | D8: Operador relatou fragmento de palete de madeira perto da linha alimentar. | E8: Operador(a) | F8: Em análise | G8: Zona de embalagem alimentar a rever (AMB-04); reconhecimento público do relato. | H8: Aberto | I8: =IF(B8="","",DataRef-B8) -> 107
I9: =IF(B9="","",DataRef-B9)
I10: =IF(B10="","",DataRef-B10)
I11: =IF(B11="","",DataRef-B11)
I12: =IF(B12="","",DataRef-B12)
I13: =IF(B13="","",DataRef-B13)

Sheet Listas
A1: LISTAS CONTROLADAS (domínios de validação de dados) — editar aqui para alterar opções
A2: DataReferencia | B2: Estado | C2: Funcao | D2: Processo | E2: RACI | F2: TipoRelato | G2: EstadoRel | H2: Area
A3: 46387 | B3: Evidenciado | C3: Diretor Geral (Gestão de Topo) | D3: GES | E3: R | F3: Pressão para libertar | G3: Aberto | H3: Produção
B4: Parcial | C4: Diretor Industrial | D4: QUA | E4: A | F4: Registo incorreto | G4: Fechado | H4: Qualidade
B5: Por evidenciar | C5: Gerente da Qualidade | D5: COM | E5: C | F5: Concessão sem autorização | H5: Manutenção
C6: Gerente de Produção | D6: RD | E6: I | F6: Segurança do produto | H6: Comercial
C7: Gerente de Manutenção | D7: PCP | F7: Outro | H7: Logística
C8: Diretor Comercial | D8: CMP
C9: Responsável de Compras | D9: REC
C10: Responsável de R&D | D10: INJ
C11: Responsável de Armazém e Logística | D11: SOP
C12: Responsável de Recursos Humanos | D12: SER
C13: Gerente de Dados / TI | D13: HFS
C14: Técnico(a) da Qualidade / Inspetor(a) | D14: LAB
C15: Técnico(a) de Laboratório | D15: EXP
C16: Engenheiro(a) de Processo | D16: MAN
C17: Chefe de Turno | D17: MET
C18: Operador(a) de Injeção | D18: RH
C19: Operador(a) de Sopro (ISBM) | D19: TI
C20: Operador(a) de Serigrafia | D20: DOC
C21: Operador(a) de Hot Foil
C22: Técnico(a) de Manutenção
C23: Técnico(a) de Metrologia
C24: Auditor(a) Interno(a) do SGQ
C25: Gestor(a) de Cliente (Key Account)
C26: Planeador(a) de Produção
C27: Operador(a) de Armazém / Empilhador
C28: Gestor do SGA / EHS (Responsável Ambiental)
C29: Donos de processo (RG-SGQ-02)

Sheet Dicionario_Dados
A1: Folha | B1: Tabela | C1: Coluna | D1: Tipo | E1: Origem | F1: Descricao | G1: Dominio_Unidade | H1: Obrigatorio | I1: Chave
A2: Verificacao_Politica | B2: tbl_verif_politica | C2: Requisito | D2: Texto | E2: Entrada | F2: Alínea da ISO 9001:2026. | H2: Sim | I2: PK
A3: Verificacao_Politica | B3: tbl_verif_politica | C3: Descricao | D3: Texto | E3: Entrada | F3: O que a política deve cumprir. | H3: Sim
A4: Verificacao_Politica | B4: tbl_verif_politica | C4: Evidencia | D4: Texto | E4: Entrada | F4: Onde/como está cumprido. | H4: Sim
A5: Verificacao_Politica | B5: tbl_verif_politica | C5: Estado | D5: Texto | E5: Entrada | F5: Estado da evidência. | G5: Lista lst_Estado | H5: Sim
A6: Lideranca_Compromisso | B6: tbl_lideranca | C6: ID | D6: Texto | E6: Entrada | F6: ID da evidência de liderança. | H6: Sim | I6: PK
A7: Lideranca_Compromisso | B7: tbl_lideranca | C7: Alinea | D7: Texto | E7: Entrada | F7: 5.1.1 a)–l) ou 5.1.2 a)–c). | H7: Sim
A8: Lideranca_Compromisso | B8: tbl_lideranca | C8: Compromisso | D8: Texto | E8: Entrada | F8: O que a norma exige da gestão de topo. | H8: Sim
A9: Lideranca_Compromisso | B9: tbl_lideranca | C9: Como_Demonstra | D9: Texto | E9: Entrada | F9: Como a gestão de topo o demonstra na Plasticom. | H9: Sim
A10: Lideranca_Compromisso | B10: tbl_lideranca | C10: Evidencia | D10: Texto | E10: Entrada | F10: Evidência objetiva (registo, ata). | H10: Sim
A11: Lideranca_Compromisso | B11: tbl_lideranca | C11: Responsavel | D11: Texto | E11: Entrada | F11: Membro da gestão de topo. | G11: Lista lst_Funcao | H11: Sim
A12: Lideranca_Compromisso | B12: tbl_lideranca | C12: Estado | D12: Texto | E12: Entrada | F12: Estado da evidência. | G12: Lista lst_Estado | H12: Sim
A13: Lideranca_Compromisso | B13: tbl_lideranca | C13: Frequencia | D13: Texto | E13: Entrada | F13: Frequência. | H13: Sim
A14: Lideranca_Compromisso | B14: tbl_lideranca | C14: Novo_2026 | D14: Texto | E14: Calculado (fórmula) | F14: Requisito novo na edição 2026. | H14: Sim
A15: Funcoes_Autoridades | B15: tbl_autoridades | C15: ID | D15: Texto | E15: Entrada | F15: ID da autoridade. | H15: Sim | I15: PK
A16: Funcoes_Autoridades | B16: tbl_autoridades | C16: Referencia | D16: Texto | E16: Entrada | F16: Cláusula. | H16: Sim
A17: Funcoes_Autoridades | B17: tbl_autoridades | C17: Responsabilidade_Autoridade | D17: Texto | E17: Entrada | F17: Responsabilidade e autoridade atribuída. | H17: Sim
A18: Funcoes_Autoridades | B18: tbl_autoridades | C18: Atribuida_a | D18: Texto | E18: Entrada | F18: Função. | H18: Sim
A19: Funcoes_Autoridades | B19: tbl_autoridades | C19: Evidencia_Atribuicao | D19: Texto | E19: Entrada | F19: Como foi atribuída e comunicada. | H19: Sim
A20: Matriz_RACI | B20: tbl_raci | C20: ID_Processo | D20: Texto | E20: Entrada | F20: Linha da matriz. | G20: RACI-Q-nn | H20: Sim | I20: PK
A21: Matriz_RACI | B21: tbl_raci | C21: Processo_SGQ | D21: Texto | E21: Entrada | F21: Atividade / processo do SGQ (equivale a Processo_SGA). | H21: Sim
A22: Matriz_RACI | B22: tbl_raci | C22: Clausula | D22: Texto | E22: Entrada | F22: Cláusula ISO 9001:2026. | H22: Sim
A23: Matriz_RACI | B23: tbl_raci | C23: Diretor_Geral | D23: Texto | E23: Entrada | F23: Diretor Geral (Gestão de Topo) (DG) | G23: Lista lst_RACI | H23: Não
A24: Matriz_RACI | B24: tbl_raci | C24: Diretor_Industrial | D24: Texto | E24: Entrada | F24: Diretor Industrial (DIND) | G24: Lista lst_RACI | H24: Não
A25: Matriz_RACI | B25: tbl_raci | C25: Gerente_Producao | D25: Texto | E25: Entrada | F25: Gerente de Produção (GPROD) | G25: Lista lst_RACI | H25: Não
A26: Matriz_RACI | B26: tbl_raci | C26: Gerente_Manutencao | D26: Texto | E26: Entrada | F26: Gerente de Manutenção (GMAN) | G26: Lista lst_RACI | H26: Não
A27: Matriz_RACI | B27: tbl_raci | C27: Gerente_Qualidade | D27: Texto | E27: Entrada | F27: Gerente da Qualidade (GQ) | G27: Lista lst_RACI | H27: Não
A28: Matriz_RACI | B28: tbl_raci | C28: Resp_Armazem_Logistica | D28: Texto | E28: Entrada | F28: Responsável de Armazém e Logística (LOG) | G28: Lista lst_RACI | H28: Não
A29: Matriz_RACI | B29: tbl_raci | C29: Resp_Compras | D29: Texto | E29: Entrada | F29: Responsável de Compras (CMP) | G29: Lista lst_RACI | H29: Não
A30: Matriz_RACI | B30: tbl_raci | C30: Resp_RD | D30: Texto | E30: Entrada | F30: Responsável de R&D (RD) | G30: Lista lst_RACI | H30: Não
A31: Matriz_RACI | B31: tbl_raci | C31: Resp_RH | D31: Texto | E31: Entrada | F31: Responsável de Recursos Humanos (RH) | G31: Lista lst_RACI | H31: Não
A32: Matriz_RACI | B32: tbl_raci | C32: Chefes_Turno | D32: Texto | E32: Entrada | F32: Chefe de Turno (CT) | G32: Lista lst_RACI | H32: Não
A33: Matriz_RACI | B33: tbl_raci | C33: Operadores | D33: Texto | E33: Entrada | F33: Operadores (OPER) | G33: Lista lst_RACI | H33: Não
A34: Matriz_RACI | B34: tbl_raci | C34: Diretor_Comercial | D34: Texto | E34: Entrada | F34: Diretor Comercial (DCOM) | G34: Lista lst_RACI | H34: Não
... A43: Matriz_RACI | B43: tbl_raci | C43: Gestor_Documental | D43: Texto | E43: Entrada | F43: Gestor(a) documental (DOC) | G43: Lista lst_RACI | H43: Não
A44: Matriz_RACI | B44: tbl_raci | C44: N_Aprovadores | D44: Inteiro | E44: Calculado (fórmula) | F44: Número de funções com A (deve ser 1). | H44: Sim
A45: Matriz_RACI | B45: tbl_raci | C45: Controlo_RACI | D45: Texto | E45: Calculado (fórmula) | F45: Exatamente um A (aprova) e pelo menos um R (executa). | H45: Sim
A46: Cultura_Qualidade | B46: tbl_cultura | C46: ID_Dimensao | D46: Texto | E46: Entrada | F46: Dimensão da cultura (ISO 10010). | H46: Sim | I46: PK
A47: Cultura_Qualidade | B47: tbl_cultura | C47: Dimensao | D47: Texto | E47: Entrada | F47: Dimensão. | H47: Sim
A48: Cultura_Qualidade | B48: tbl_cultura | C48: Afirmacao_Avaliada | D48: Texto | E48: Entrada | F48: Afirmação do inquérito (escala 1–5). | H48: Sim
...
